{"schema_version":"collector.vnext.raw","schema_contract":null,"schema_contract_version":null,"payload_contract_version":null,"record_type":"market.orderbook.diff","record_id":"collector_main-market-orderbook-diff-000000000093","collector_id":"collector_main","collector_role":"production","host_name":"MAIN-PC","session_id":"collector_main-sess-20260314T201436Z-61c8c9bf","stream_session_id":"collector_main-stream-bitflyer-board_ws-20260314T201622Z-ef233542","exchange":"bitflyer","market":"spot","symbol":"BTC_JPY","instrument_id":"bitflyer.spot.BTC_JPY","channel":"board_ws","transport":"websocket","source_event_id":null,"source_sequence":null,"sequence_id":93,"exchange_ts":null,"collector_ts":"2026-03-14T20:16:24Z","ingest_ts":"2026-03-14T20:16:24Z","event_ts":"2026-03-14T20:16:24Z","quality_flags":[],"is_partial":false,"is_reconstructed":false,"confidence_score":1.0,"payload":{"provider":"bitflyer_ws_board","exchange":"bitflyer","transport":"websocket","channel":"lightning_board_BTC_JPY","received_ts":"2026-03-14T20:16:24.914377Z","subscription_id":null,"message_id":null,"source_sequence":null,"raw_message_meta":{"raw_channel":"lightning_board_BTC_JPY","subscription_channel":"lightning_board_BTC_JPY","recv_timeout_sec":10,"ssl_verify":false,"socket_url":"wss://ws.lightstream.bitflyer.com/json-rpc"},"source_payload":{"mid_price":11307008.0,"bids":[{"price":11304182.0,"size":0.04333839}],"asks":[]}}}
{"schema_version":"collector.vnext.raw","schema_contract":null,"schema_contract_version":null,"payload_contract_version":null,"record_type":"market.orderbook.diff","record_id":"collector_main-market-orderbook-diff-000000000095","collector_id":"collector_main","collector_role":"production","host_name":"MAIN-PC","session_id":"collector_main-sess-20260314T201436Z-61c8c9bf","stream_session_id":"collector_main-stream-bitflyer-board_ws-20260314T201622Z-ef233542","exchange":"bitflyer","market":"spot","symbol":"BTC_JPY","instrument_id":"bitflyer.spot.BTC_JPY","channel":"board_ws","transport":"websocket","source_event_id":null,"source_sequence":null,"sequence_id":95,"exchange_ts":null,"collector_ts":"2026-03-14T20:16:25Z","ingest_ts":"2026-03-14T20:16:25Z","event_ts":"2026-03-14T20:16:25Z","quality_flags":[],"is_partial":false,"is_reconstructed":false,"confidence_score":1.0,"payload":{"provider":"bitflyer_ws_board","exchange":"bitflyer","transport":"websocket","channel":"lightning_board_BTC_JPY","received_ts":"2026-03-14T20:16:25.021635Z","subscription_id":null,"message_id":null,"source_sequence":null,"raw_message_meta":{"raw_channel":"lightning_board_BTC_JPY","subscription_channel":"lightning_board_BTC_JPY","recv_timeout_sec":10,"ssl_verify":false,"socket_url":"wss://ws.lightstream.bitflyer.com/json-rpc"},"source_payload":{"mid_price":11307008.0,"bids":[{"price":11304182.0,"size":0.0},{"price":11302322.0,"size":0.0}],"asks":[{"price":11325591.0,"size":0.0}]}}}
{"schema_version":"collector.vnext.raw","schema_contract":null,"schema_contract_version":null,"payload_contract_version":null,"record_type":"market.orderbook.diff","record_id":"collector_main-market-orderbook-diff-000000000097","collector_id":"collector_main","collector_role":"production","host_name":"MAIN-PC","session_id":"collector_main-sess-20260314T201436Z-61c8c9bf","stream_session_id":"collector_main-stream-bitflyer-board_ws-20260314T201622Z-ef233542","exchange":"bitflyer","market":"spot","symbol":"BTC_JPY","instrument_id":"bitflyer.spot.BTC_JPY","channel":"board_ws","transport":"websocket","source_event_id":null,"source_sequence":null,"sequence_id":97,"exchange_ts":null,"collector_ts":"2026-03-14T20:16:25Z","ingest_ts":"2026-03-14T20:16:25Z","event_ts":"2026-03-14T20:16:25Z","quality_flags":[],"is_partial":false,"is_reconstructed":false,"confidence_score":1.0,"payload":{"provider":"bitflyer_ws_board","exchange":"bitflyer","transport":"websocket","channel":"lightning_board_BTC_JPY","received_ts":"2026-03-14T20:16:25.123912Z","subscription_id":null,"message_id":null,"source_sequence":null,"raw_message_meta":{"raw_channel":"lightning_board_BTC_JPY","subscription_channel":"lightning_board_BTC_JPY","recv_timeout_sec":10,"ssl_verify":false,"socket_url":"wss://ws.lightstream.bitflyer.com/json-rpc"},"source_payload":{"mid_price":11307008.0,"bids":[{"price":11302485.0,"size":0.1275},{"price":11303085.0,"size":0.0},{"price":11304183.0,"size":0.0464603}],"asks":[{"price":11325590.0,"size":0.0096964}]}}}
{"schema_version":"collector.vnext.raw","schema_contract":null,"schema_contract_version":null,"payload_contract_version":null,"record_type":"market.orderbook.diff","record_id":"collector_main-market-orderbook-diff-000000000099","collector_id":"collector_main","collector_role":"production","host_name":"MAIN-PC","session_id":"collector_main-sess-20260314T201436Z-61c8c9bf","stream_session_id":"collector_main-stream-bitflyer-board_ws-20260314T201622Z-ef233542","exchange":"bitflyer","market":"spot","symbol":"BTC_JPY","instrument_id":"bitflyer.spot.BTC_JPY","channel":"board_ws","transport":"websocket","source_event_id":null,"source_sequence":null,"sequence_id":99,"exchange_ts":null,"collector_ts":"2026-03-14T20:16:25Z","ingest_ts":"2026-03-14T20:16:25Z","event_ts":"2026-03-14T20:16:25Z","quality_flags":[],"is_partial":false,"is_reconstructed":false,"confidence_score":1.0,"payload":{"provider":"bitflyer_ws_board","exchange":"bitflyer","transport":"websocket","channel":"lightning_board_BTC_JPY","received_ts":"2026-03-14T20:16:25.240606Z","subscription_id":null,"message_id":null,"source_sequence":null,"raw_message_meta":{"raw_channel":"lightning_board_BTC_JPY","subscription_channel":"lightning_board_BTC_JPY","recv_timeout_sec":10,"ssl_verify":false,"socket_url":"wss://ws.lightstream.bitflyer.com/json-rpc"},"source_payload":{"mid_price":11307008.0,"bids":[{"price":11304183.0,"size":0.0},{"price":11303085.0,"size":0.05562185}],"asks":[]}}}
{"schema_version":"collector.vnext.raw","schema_contract":null,"schema_contract_version":null,"payload_contract_version":null,"record_type":"market.orderbook.diff","record_id":"collector_main-market-orderbook-diff-000000000101","collector_id":"collector_main","collector_role":"production","host_name":"MAIN-PC","session_id":"collector_main-sess-20260314T201436Z-61c8c9bf","stream_session_id":"collector_main-stream-bitflyer-board_ws-20260314T201622Z-ef233542","exchange":"bitflyer","market":"spot","symbol":"BTC_JPY","instrument_id":"bitflyer.spot.BTC_JPY","channel":"board_ws","transport":"websocket","source_event_id":null,"source_sequence":null,"sequence_id":101,"exchange_ts":null,"collector_ts":"2026-03-14T20:16:25Z","ingest_ts":"2026-03-14T20:16:25Z","event_ts":"2026-03-14T20:16:25Z","quality_flags":[],"is_partial":false,"is_reconstructed":false,"confidence_score":1.0,"payload":{"provider":"bitflyer_ws_board","exchange":"bitflyer","transport":"websocket","channel":"lightning_board_BTC_JPY","received_ts":"2026-03-14T20:16:25.360312Z","subscription_id":null,"message_id":null,"source_sequence":null,"raw_message_meta":{"raw_channel":"lightning_board_BTC_JPY","subscription_channel":"lightning_board_BTC_JPY","recv_timeout_sec":10,"ssl_verify":false,"socket_url":"wss://ws.lightstream.bitflyer.com/json-rpc"},"source_payload":{"mid_price":11307008.0,"bids":[{"price":11302485.0,"size":0.0},{"price":11303050.0,"size":0.1275},{"price":11302520.0,"size":0.0176933}],"asks":[{"price":11321551.0,"size":0.0},{"price":11321549.0,"size":0.0435352}]}}}
{"schema_version":"collector.vnext.raw","schema_contract":null,"schema_contract_version":null,"payload_contract_version":null,"record_type":"market.orderbook.diff","record_id":"collector_main-market-orderbook-diff-000000000103","collector_id":"collector_main","collector_role":"production","host_name":"MAIN-PC","session_id":"collector_main-sess-20260314T201436Z-61c8c9bf","stream_session_id":"collector_main-stream-bitflyer-board_ws-20260314T201622Z-ef233542","exchange":"bitflyer","market":"spot","symbol":"BTC_JPY","instrument_id":"bitflyer.spot.BTC_JPY","channel":"board_ws","transport":"websocket","source_event_id":null,"source_sequence":null,"sequence_id":103,"exchange_ts":null,"collector_ts":"2026-03-14T20:16:25Z","ingest_ts":"2026-03-14T20:16:25Z","event_ts":"2026-03-14T20:16:25Z","quality_flags":[],"is_partial":false,"is_reconstructed":false,"confidence_score":1.0,"payload":{"provider":"bitflyer_ws_board","exchange":"bitflyer","transport":"websocket","channel":"lightning_board_BTC_JPY","received_ts":"2026-03-14T20:16:25.470265Z","subscription_id":null,"message_id":null,"source_sequence":null,"raw_message_meta":{"raw_channel":"lightning_board_BTC_JPY","subscription_channel":"lightning_board_BTC_JPY","recv_timeout_sec":10,"ssl_verify":false,"socket_url":"wss://ws.lightstream.bitflyer.com/json-rpc"},"source_payload":{"mid_price":11307008.0,"bids":[],"asks":[{"price":11325590.0,"size":0.0}]}}}
{"schema_version":"collector.vnext.raw","schema_contract":null,"schema_contract_version":null,"payload_contract_version":null,"record_type":"market.orderbook.diff","record_id":"collector_main-market-orderbook-diff-000000000105","collector_id":"collector_main","collector_role":"production","host_name":"MAIN-PC","session_id":"collector_main-sess-20260314T201436Z-61c8c9bf","stream_session_id":"collector_main-stream-bitflyer-board_ws-20260314T201622Z-ef233542","exchange":"bitflyer","market":"spot","symbol":"BTC_JPY","instrument_id":"bitflyer.spot.BTC_JPY","channel":"board_ws","transport":"websocket","source_event_id":null,"source_sequence":null,"sequence_id":105,"exchange_ts":null,"collector_ts":"2026-03-14T20:16:25Z","ingest_ts":"2026-03-14T20:16:25Z","event_ts":"2026-03-14T20:16:25Z","quality_flags":[],"is_partial":false,"is_reconstructed":false,"confidence_score":1.0,"payload":{"provider":"bitflyer_ws_board","exchange":"bitflyer","transport":"websocket","channel":"lightning_board_BTC_JPY","received_ts":"2026-03-14T20:16:25.571471Z","subscription_id":null,"message_id":null,"source_sequence":null,"raw_message_meta":{"raw_channel":"lightning_board_BTC_JPY","subscription_channel":"lightning_board_BTC_JPY","recv_timeout_sec":10,"ssl_verify":false,"socket_url":"wss://ws.lightstream.bitflyer.com/json-rpc"},"source_payload":{"mid_price":11307008.0,"bids":[{"price":11303050.0,"size":0.0}],"asks":[{"price":11325589.0,"size":0.0096964}]}}}
{"schema_version":"collector.vnext.raw","schema_contract":null,"schema_contract_version":null,"payload_contract_version":null,"record_type":"market.orderbook.diff","record_id":"collector_main-market-orderbook-diff-000000000107","collector_id":"collector_main","collector_role":"production","host_name":"MAIN-PC","session_id":"collector_main-sess-20260314T201436Z-61c8c9bf","stream_session_id":"collector_main-stream-bitflyer-board_ws-20260314T201622Z-ef233542","exchange":"bitflyer","market":"spot","symbol":"BTC_JPY","instrument_id":"bitflyer.spot.BTC_JPY","channel":"board_ws","transport":"websocket","source_event_id":null,"source_sequence":null,"sequence_id":107,"exchange_ts":null,"collector_ts":"2026-03-14T20:16:25Z","ingest_ts":"2026-03-14T20:16:25Z","event_ts":"2026-03-14T20:16:25Z","quality_flags":[],"is_partial":false,"is_reconstructed":false,"confidence_score":1.0,"payload":{"provider":"bitflyer_ws_board","exchange":"bitflyer","transport":"websocket","channel":"lightning_board_BTC_JPY","received_ts":"2026-03-14T20:16:25.676223Z","subscription_id":null,"message_id":null,"source_sequence":null,"raw_message_meta":{"raw_channel":"lightning_board_BTC_JPY","subscription_channel":"lightning_board_BTC_JPY","recv_timeout_sec":10,"ssl_verify":false,"socket_url":"wss://ws.lightstream.bitflyer.com/json-rpc"},"source_payload":{"mid_price":11307008.0,"bids":[{"price":11303615.0,"size":0.1275}],"asks":[]}}}
{"schema_version":"collector.vnext.raw","schema_contract":null,"schema_contract_version":null,"payload_contract_version":null,"record_type":"market.orderbook.diff","record_id":"collector_main-market-orderbook-diff-000000000109","collector_id":"collector_main","collector_role":"production","host_name":"MAIN-PC","session_id":"collector_main-sess-20260314T201436Z-61c8c9bf","stream_session_id":"collector_main-stream-bitflyer-board_ws-20260314T201622Z-ef233542","exchange":"bitflyer","market":"spot","symbol":"BTC_JPY","instrument_id":"bitflyer.spot.BTC_JPY","channel":"board_ws","transport":"websocket","source_event_id":null,"source_sequence":null,"sequence_id":109,"exchange_ts":null,"collector_ts":"2026-03-14T20:16:25Z","ingest_ts":"2026-03-14T20:16:25Z","event_ts":"2026-03-14T20:16:25Z","quality_flags":[],"is_partial":false,"is_reconstructed":false,"confidence_score":1.0,"payload":{"provider":"bitflyer_ws_board","exchange":"bitflyer","transport":"websocket","channel":"lightning_board_BTC_JPY","received_ts":"2026-03-14T20:16:25.772052Z","subscription_id":null,"message_id":null,"source_sequence":null,"raw_message_meta":{"raw_channel":"lightning_board_BTC_JPY","subscription_channel":"lightning_board_BTC_JPY","recv_timeout_sec":10,"ssl_verify":false,"socket_url":"wss://ws.lightstream.bitflyer.com/json-rpc"},"source_payload":{"mid_price":11307008.0,"bids":[{"price":11260242.0,"size":0.002}],"asks":[]}}}
{"schema_version":"collector.vnext.raw","schema_contract":null,"schema_contract_version":null,"payload_contract_version":null,"record_type":"market.orderbook.diff","record_id":"collector_main-market-orderbook-diff-000000000111","collector_id":"collector_main","collector_role":"production","host_name":"MAIN-PC","session_id":"collector_main-sess-20260314T201436Z-61c8c9bf","stream_session_id":"collector_main-stream-bitflyer-board_ws-20260314T201622Z-ef233542","exchange":"bitflyer","market":"spot","symbol":"BTC_JPY","instrument_id":"bitflyer.spot.BTC_JPY","channel":"board_ws","transport":"websocket","source_event_id":null,"source_sequence":null,"sequence_id":111,"exchange_ts":null,"collector_ts":"2026-03-14T20:16:25Z","ingest_ts":"2026-03-14T20:16:25Z","event_ts":"2026-03-14T20:16:25Z","quality_flags":[],"is_partial":false,"is_reconstructed":false,"confidence_score":1.0,"payload":{"provider":"bitflyer_ws_board","exchange":"bitflyer","transport":"websocket","channel":"lightning_board_BTC_JPY","received_ts":"2026-03-14T20:16:25.877378Z","subscription_id":null,"message_id":null,"source_sequence":null,"raw_message_meta":{"raw_channel":"lightning_board_BTC_JPY","subscription_channel":"lightning_board_BTC_JPY","recv_timeout_sec":10,"ssl_verify":false,"socket_url":"wss://ws.lightstream.bitflyer.com/json-rpc"},"source_payload":{"mid_price":11307008.0,"bids":[{"price":11303615.0,"size":0.0},{"price":11303085.0,"size":0.0},{"price":11304181.0,"size":0.1275},{"price":11303616.0,"size":0.04873708}],"asks":[]}}}
{"schema_version":"collector.vnext.raw","schema_contract":null,"schema_contract_version":null,"payload_contract_version":null,"record_type":"market.orderbook.diff","record_id":"collector_main-market-orderbook-diff-000000000113","collector_id":"collector_main","collector_role":"production","host_name":"MAIN-PC","session_id":"collector_main-sess-20260314T201436Z-61c8c9bf","stream_session_id":"collector_main-stream-bitflyer-board_ws-20260314T201622Z-ef233542","exchange":"bitflyer","market":"spot","symbol":"BTC_JPY","instrument_id":"bitflyer.spot.BTC_JPY","channel":"board_ws","transport":"websocket","source_event_id":null,"source_sequence":null,"sequence_id":113,"exchange_ts":null,"collector_ts":"2026-03-14T20:16:26Z","ingest_ts":"2026-03-14T20:16:26Z","event_ts":"2026-03-14T20:16:26Z","quality_flags":[],"is_partial":false,"is_reconstructed":false,"confidence_score":1.0,"payload":{"provider":"bitflyer_ws_board","exchange":"bitflyer","transport":"websocket","channel":"lightning_board_BTC_JPY","received_ts":"2026-03-14T20:16:26.125222Z","subscription_id":null,"message_id":null,"source_sequence":null,"raw_message_meta":{"raw_channel":"lightning_board_BTC_JPY","subscription_channel":"lightning_board_BTC_JPY","recv_timeout_sec":10,"ssl_verify":false,"socket_url":"wss://ws.lightstream.bitflyer.com/json-rpc"},"source_payload":{"mid_price":11307008.0,"bids":[{"price":11304181.0,"size":0.0},{"price":11303616.0,"size":0.0}],"asks":[]}}}
{"schema_version":"collector.vnext.raw","schema_contract":null,"schema_contract_version":null,"payload_contract_version":null,"record_type":"market.orderbook.diff","record_id":"collector_main-market-orderbook-diff-000000000115","collector_id":"collector_main","collector_role":"production","host_name":"MAIN-PC","session_id":"collector_main-sess-20260314T201436Z-61c8c9bf","stream_session_id":"collector_main-stream-bitflyer-board_ws-20260314T201622Z-ef233542","exchange":"bitflyer","market":"spot","symbol":"BTC_JPY","instrument_id":"bitflyer.spot.BTC_JPY","channel":"board_ws","transport":"websocket","source_event_id":null,"source_sequence":null,"sequence_id":115,"exchange_ts":null,"collector_ts":"2026-03-14T20:16:26Z","ingest_ts":"2026-03-14T20:16:26Z","event_ts":"2026-03-14T20:16:26Z","quality_flags":[],"is_partial":false,"is_reconstructed":false,"confidence_score":1.0,"payload":{"provider":"bitflyer_ws_board","exchange":"bitflyer","transport":"websocket","channel":"lightning_board_BTC_JPY","received_ts":"2026-03-14T20:16:26.250498Z","subscription_id":null,"message_id":null,"source_sequence":null,"raw_message_meta":{"raw_channel":"lightning_board_BTC_JPY","subscription_channel":"lightning_board_BTC_JPY","recv_timeout_sec":10,"ssl_verify":false,"socket_url":"wss://ws.lightstream.bitflyer.com/json-rpc"},"source_payload":{"mid_price":11307008.0,"bids":[{"price":11304746.0,"size":0.0},{"price":11304182.0,"size":0.0},{"price":11302520.0,"size":0.0}],"asks":[]}}}
{"schema_version":"collector.vnext.raw","schema_contract":null,"schema_contract_version":null,"payload_contract_version":null,"record_type":"market.orderbook.snapshot","record_id":"collector_main-market-orderbook-snapshot-000000000117","collector_id":"collector_main","collector_role":"production","host_name":"MAIN-PC","session_id":"collector_main-sess-20260314T201436Z-61c8c9bf","stream_session_id":"collector_main-stream-bitflyer-board_ws-20260314T201622Z-ef233542","exchange":"bitflyer","market":"spot","symbol":"BTC_JPY","instrument_id":"bitflyer.spot.BTC_JPY","channel":"board_ws","transport":"websocket","source_event_id":null,"source_sequence":null,"sequence_id":117,"exchange_ts":null,"collector_ts":"2026-03-14T20:16:26Z","ingest_ts":"2026-03-14T20:16:26Z","event_ts":"2026-03-14T20:16:26Z","quality_flags":[],"is_partial":false,"is_reconstructed":false,"confidence_score":1.0,"payload":{"provider":"bitflyer_ws_board_snapshot","exchange":"bitflyer","transport":"websocket","channel":"lightning_board_snapshot_BTC_JPY","received_ts":"2026-03-14T20:16:26.360368Z","subscription_id":null,"message_id":null,"source_sequence":null,"raw_message_meta":{"raw_channel":"lightning_board_snapshot_BTC_JPY","subscription_channel":"lightning_board_snapshot_BTC_JPY","recv_timeout_sec":10,"ssl_verify":false,"socket_url":"wss://ws.lightstream.bitflyer.com/json-rpc"},"source_payload":{"mid_price":11307008.0,"bids":[{"price":11304739.0,"size":0.0099986},{"price":11303085.0,"size":0.05344678},{"price":11303084.0,"size":0.014448},{"price":11302772.0,"size":0.014988},{"price":11302287.0,"size":0.02},{"price":11302286.0,"size":0.014652},{"price":11301920.0,"size":0.02},{"price":11301919.0,"size":0.01554},{"price":11301012.0,"size":0.52},{"price":11300748.0,"size":0.2},{"price":11300171.0,"size":0.0536544},{"price":11299148.0,"size":0.05},{"price":11298751.0,"size":0.5},{"price":11297986.0,"size":0.0531},{"price":11297568.0,"size":0.01},{"price":11297452.0,"size":0.05},{"price":11296068.0,"size":2.97376189},{"price":11294808.0,"size":0.001},{"price":11294795.0,"size":0.0099986},{"price":11293270.0,"size":0.0801},{"price":11292244.0,"size":0.048},{"price":11289443.0,"size":0.04},{"price":11287378.0,"size":1.50015},{"price":11286651.0,"size":0.98403398},{"price":11283324.0,"size":0.3118},{"price":11282857.0,"size":0.002},{"price":11280562.0,"size":0.3089},{"price":11280205.0,"size":0.001},{"price":11279435.0,"size":0.17274976},{"price":11279434.0,"size":0.6},{"price":11279282.0,"size":0.0015},{"price":11278334.0,"size":0.002},{"price":11277877.0,"size":0.002},{"price":11277800.0,"size":0.2689},{"price":11277748.0,"size":0.0966561},{"price":11277602.0,"size":0.005},{"price":11275102.0,"size":0.01},{"price":11275038.0,"size":0.2726},{"price":11275000.0,"size":0.001},{"price":11274595.0,"size":1.484},{"price":11274588.0,"size":0.0047},{"price":11274485.0,"size":0.002},{"price":11273811.0,"size":0.002},{"price":11271093.0,"size":0.002},{"price":11271000.0,"size":0.003},{"price":11270000.0,"size":0.106},{"price":11269288.0,"size":0.002},{"price":11268871.0,"size":0.281},{"price":11268411.0,"size":0.01},{"price":11267701.0,"size":0.002},{"price":11266666.0,"size":0.04},{"price":11265879.0,"size":0.6},{"price":11265000.0,"size":0.02},{"price":11264765.0,"size":0.002},{"price":11264309.0,"size":0.002},{"price":11263999.0,"size":1.966},{"price":11263000.0,"size":0.006},{"price":11262564.0,"size":0.0015},{"price":11260917.0,"size":0.002},{"price":11260242.0,"size":0.002},{"price":11260000.0,"size":0.3565},{"price":11257537.0,"size":0.001},{"price":11257525.0,"size":0.002},{"price":11257000.0,"size":0.001},{"price":11255200.0,"size":0.001},{"price":11255115.0,"size":0.00377},{"price":11254133.0,"size":0.002},{"price":11253628.0,"size":2.036},{"price":11253000.0,"size":0.03189},{"price":11251000.0,"size":0.0131},{"price":11250741.0,"size":0.002},{"price":11250250.0,"size":0.00105},{"price":11250200.0,"size":0.001},{"price":11250100.0,"size":0.015},{"price":11250005.0,"size":0.001},{"price":11250001.0,"size":0.00104},{"price":11250000.0,"size":0.76834},{"price":11247349.0,"size":0.002},{"price":11246544.0,"size":0.0015},{"price":11246203.0,"size":0.001},{"price":11245141.0,"size":0.0031},{"price":11245000.0,"size":0.05},{"price":11244444.0,"size":0.04},{"price":11244243.0,"size":0.01},{"price":11240200.0,"size":0.001},{"price":11240000.0,"size":0.007304},{"price":11236190.0,"size":0.01},{"price":11235200.0,"size":0.001},{"price":11234869.0,"size":0.001},{"price":11232000.0,"size":0.089},{"price":11231243.0,"size":0.01},{"price":11231000.0,"size":0.105},{"price":11230200.0,"size":0.001},{"price":11230000.0,"size":0.0308},{"price":11228423.0,"size":1.951},{"price":11224500.0,"size":0.06},{"price":11224355.0,"size":0.0015},{"price":11223968.0,"size":0.001},{"price":11223535.0,"size":0.001},{"price":11223344.0,"size":0.01},{"price":11223000.0,"size":0.1},{"price":11222222.0,"size":0.092525},{"price":11221459.0,"size":0.1393},{"price":11221120.0,"size":0.011},{"price":11220200.0,"size":0.001},{"price":11220001.0,"size":0.004457},{"price":11220000.0,"size":0.321},{"price":11219517.0,"size":0.01},{"price":11219000.0,"size":0.1},{"price":11215200.0,"size":0.001},{"price":11215000.0,"size":0.02},{"price":11212358.0,"size":1.2},{"price":11212201.0,"size":0.001},{"price":11211800.0,"size":0.001},{"price":11211111.0,"size":0.06},{"price":11210200.0,"size":0.001},{"price":11210000.0,"size":0.10622},{"price":11208032.0,"size":0.01},{"price":11207755.0,"size":0.0015},{"price":11206000.0,"size":0.09015},{"price":11205200.0,"size":0.001},{"price":11204578.0,"size":0.002},{"price":11203931.0,"size":1.0},{"price":11201000.0,"size":0.01},{"price":11200867.0,"size":0.001},{"price":11200800.0,"size":0.05},{"price":11200425.0,"size":0.1},{"price":11200200.0,"size":0.001},{"price":11200198.0,"size":0.003},{"price":11200150.0,"size":0.002},{"price":11200002.0,"size":0.001},{"price":11200001.0,"size":0.01104},{"price":11200000.0,"size":1.35988728},{"price":11198508.0,"size":0.05},{"price":11198243.0,"size":0.01},{"price":11197134.0,"size":2.0},{"price":11197000.0,"size":0.0085},{"price":11195692.0,"size":0.0015},{"price":11194090.0,"size":0.03},{"price":11190770.0,"size":0.0309},{"price":11190000.0,"size":0.0010016},{"price":11189555.0,"size":0.5},{"price":11189533.0,"size":0.001},{"price":11188629.0,"size":0.01},{"price":11188382.0,"size":0.001},{"price":11185000.0,"size":0.0085},{"price":11180043.0,"size":0.972},{"price":11180000.0,"size":0.23215},{"price":11178973.0,"size":0.0015},{"price":11178199.0,"size":0.001},{"price":11170000.0,"size":0.001},{"price":11169662.0,"size":0.01},{"price":11169593.0,"size":0.001},{"price":11169243.0,"size":0.01},{"price":11166865.0,"size":0.001},{"price":11164029.0,"size":0.001},{"price":11160854.0,"size":0.1},{"price":11160000.0,"size":0.02376},{"price":11156269.0,"size":0.01},{"price":11155531.0,"size":0.001},{"price":11155377.0,"size":0.00636009},{"price":11153999.0,"size":0.00101},{"price":11151000.0,"size":0.001},{"price":11150250.0,"size":0.00175},{"price":11150005.0,"size":0.001},{"price":11150001.0,"size":0.00104},{"price":11150000.0,"size":0.6398956},{"price":11148000.0,"size":0.08963},{"price":11144197.0,"size":0.001},{"price":11144000.0,"size":0.0897},{"price":11140000.0,"size":0.2},{"price":11136243.0,"size":0.01},{"price":11136155.0,"size":0.02},{"price":11135869.0,"size":0.1},{"price":11130000.0,"size":0.116},{"price":11129979.0,"size":0.0053908},{"price":11126388.0,"size":0.02},{"price":11124900.0,"size":0.00133},{"price":11121090.0,"size":0.1},{"price":11120000.0,"size":0.0033},{"price":11118078.0,"size":0.01},{"price":11111800.0,"size":0.001},{"price":11111111.0,"size":0.2919257},{"price":11111000.0,"size":0.003},{"price":11110594.0,"size":0.001},{"price":11110000.0,"size":0.056937},{"price":11109662.0,"size":0.01},{"price":11108008.0,"size":0.01},{"price":11106000.0,"size":0.2},{"price":11105000.0,"size":0.02},{"price":11101297.0,"size":0.001},{"price":11100005.0,"size":0.001},{"price":11100001.0,"size":0.01104},{"price":11100000.0,"size":2.7475049},{"price":11099141.0,"size":0.01},{"price":11096243.0,"size":0.01},{"price":11094090.0,"size":0.01},{"price":11088888.0,"size":0.001},{"price":11085245.0,"size":0.001},{"price":11080200.0,"size":0.001},{"price":11080000.0,"size":0.0223},{"price":11075100.0,"size":0.003},{"price":11071558.0,"size":1.0},{"price":11070200.0,"size":0.001},{"price":11070000.0,"size":0.0902},{"price":11065200.0,"size":0.001},{"price":11064370.0,"size":0.00497091},{"price":11060200.0,"size":0.001},{"price":11060000.0,"size":0.145},{"price":11059689.0,"size":0.009},{"price":11056428.0,"size":0.002},{"price":11055500.0,"size":0.02},{"price":11055200.0,"size":0.001},{"price":11055100.0,"size":0.003},{"price":11050200.0,"size":0.001},{"price":11050005.0,"size":0.001},{"price":11050002.0,"size":0.001},{"price":11050001.0,"size":0.00104},{"price":11050000.0,"size":0.43176147},{"price":11046420.0,"size":0.2},{"price":11044243.0,"size":0.01},{"price":11041380.0,"size":0.01},{"price":11040200.0,"size":0.001},{"price":11040000.0,"size":0.00877181},{"price":11035865.0,"size":0.1},{"price":11035200.0,"size":0.001},{"price":11035000.0,"size":0.0013},{"price":11030200.0,"size":0.001},{"price":11030000.0,"size":0.025},{"price":11025500.0,"size":0.009531},{"price":11025200.0,"size":0.001},{"price":11025000.0,"size":0.71497},{"price":11020772.0,"size":0.014},{"price":11020200.0,"size":0.002},{"price":11020000.0,"size":0.005},{"price":11015200.0,"size":0.001},{"price":11012000.0,"size":0.1},{"price":11011800.0,"size":0.001},{"price":11011000.0,"size":0.001},{"price":11010200.0,"size":0.001},{"price":11010000.0,"size":0.347},{"price":11007277.0,"size":0.01},{"price":11006000.0,"size":0.2},{"price":11005200.0,"size":0.001},{"price":11004890.0,"size":0.001535},{"price":11003000.0,"size":0.0155},{"price":11001000.0,"size":0.013},{"price":11000500.0,"size":0.05117658},{"price":11000200.0,"size":0.001},{"price":11000002.0,"size":0.004},{"price":11000001.0,"size":0.02604},{"price":11000000.0,"size":5.47323365},{"price":10999999.0,"size":0.003},{"price":10999000.0,"size":0.001},{"price":10996855.0,"size":0.0011},{"price":10995200.0,"size":0.001},{"price":10994499.0,"size":0.00169176},{"price":10990200.0,"size":0.001},{"price":10990000.0,"size":0.10219},{"price":10989001.0,"size":0.00197},{"price":10988999.0,"size":0.001},{"price":10988324.0,"size":0.002},{"price":10987654.0,"size":0.001},{"price":10985200.0,"size":0.001},{"price":10985150.0,"size":0.01},{"price":10980500.0,"size":0.005},{"price":10980200.0,"size":0.001},{"price":10980002.0,"size":0.4},{"price":10980000.0,"size":0.028},{"price":10975200.0,"size":0.001},{"price":10975000.0,"size":0.1},{"price":10971261.0,"size":0.001},{"price":10971243.0,"size":0.01},{"price":10970375.0,"size":1.9},{"price":10970200.0,"size":0.001},{"price":10970000.0,"size":0.09304},{"price":10966600.0,"size":0.001003},{"price":10965200.0,"size":0.001},{"price":10960200.0,"size":0.001},{"price":10960000.0,"size":0.0083},{"price":10956673.0,"size":0.01},{"price":10955200.0,"size":0.001},{"price":10954950.0,"size":0.001},{"price":10950500.0,"size":0.005},{"price":10950001.0,"size":0.00204},{"price":10950000.0,"size":0.5485028},{"price":10949550.0,"size":0.01870657},{"price":10949172.0,"size":0.1},{"price":10948000.0,"size":0.1},{"price":10945243.0,"size":0.01},{"price":10941000.0,"size":0.001},{"price":10940402.0,"size":0.001},{"price":10940200.0,"size":0.001},{"price":10940000.0,"size":0.331},{"price":10938243.0,"size":0.01},{"price":10936200.0,"size":0.00137},{"price":10935200.0,"size":0.001},{"price":10930200.0,"size":0.002},{"price":10930000.0,"size":0.0193},{"price":10925200.0,"size":0.002}],"asks":[{"price":11309277.0,"size":0.04353519},{"price":11309278.0,"size":0.1898},{"price":11309329.0,"size":0.02},{"price":11309888.0,"size":0.02},{"price":11309889.0,"size":0.005},{"price":11310000.0,"size":0.006},{"price":11310444.0,"size":0.02},{"price":11311006.0,"size":0.2729},{"price":11311208.0,"size":0.0099999},{"price":11311364.0,"size":0.015192},{"price":11311888.0,"size":0.014784},{"price":11312720.0,"size":0.4199},{"price":11313658.0,"size":0.01},{"price":11313768.0,"size":0.258},{"price":11313957.0,"size":0.014772},{"price":11315713.0,"size":0.57608123},{"price":11316530.0,"size":0.2806},{"price":11317135.0,"size":0.0536544},{"price":11318050.0,"size":0.002},{"price":11318545.0,"size":0.053},{"price":11318640.0,"size":0.01},{"price":11319292.0,"size":0.2857},{"price":11320000.0,"size":0.02},{"price":11321549.0,"size":0.0435352},{"price":11322000.0,"size":0.005},{"price":11323556.0,"size":1.189881},{"price":11323581.0,"size":1.189881},{"price":11325589.0,"size":0.0096964},{"price":11328050.0,"size":0.002},{"price":11329436.0,"size":0.0015},{"price":11331059.0,"size":0.001},{"price":11340000.0,"size":0.13586406},{"price":11340647.0,"size":0.001},{"price":11342956.0,"size":1.60199848},{"price":11342957.0,"size":0.01},{"price":11343223.0,"size":1.928},{"price":11345875.0,"size":1.489},{"price":11346154.0,"size":0.0015},{"price":11348000.0,"size":0.1999},{"price":11349700.0,"size":0.001},{"price":11350000.0,"size":0.022},{"price":11353877.0,"size":0.001},{"price":11354939.0,"size":0.01},{"price":11355555.0,"size":0.001},{"price":11358323.0,"size":2.018},{"price":11359242.0,"size":0.0011},{"price":11359700.0,"size":0.001},{"price":11362692.0,"size":0.0015},{"price":11365211.0,"size":0.001},{"price":11369700.0,"size":0.001},{"price":11370000.0,"size":0.1},{"price":11372478.0,"size":1.943},{"price":11376000.0,"size":0.02},{"price":11376545.0,"size":0.001},{"price":11377000.0,"size":0.2287},{"price":11377269.0,"size":0.002},{"price":11379700.0,"size":0.001},{"price":11379865.0,"size":0.03},{"price":11380000.0,"size":0.0223},{"price":11380324.0,"size":0.002},{"price":11381766.0,"size":0.4},{"price":11382386.0,"size":0.0015},{"price":11385000.0,"size":0.2548},{"price":11385403.0,"size":0.002},{"price":11385664.0,"size":0.002},{"price":11387072.0,"size":0.01},{"price":11387354.0,"size":0.002},{"price":11387879.0,"size":0.001},{"price":11388885.0,"size":0.03},{"price":11389700.0,"size":0.001},{"price":11390000.0,"size":0.2488},{"price":11390050.0,"size":0.001},{"price":11392387.0,"size":1.0},{"price":11394939.0,"size":0.01},{"price":11395000.0,"size":0.06},{"price":11395775.0,"size":0.01},{"price":11396555.0,"size":0.03},{"price":11398444.0,"size":0.001995},{"price":11399213.0,"size":0.001},{"price":11399673.0,"size":0.0015},{"price":11399700.0,"size":0.001},{"price":11400000.0,"size":0.5525},{"price":11405000.0,"size":0.0275},{"price":11406336.0,"size":1.0},{"price":11408700.0,"size":0.001},{"price":11409415.0,"size":0.055},{"price":11410000.0,"size":0.03},{"price":11410547.0,"size":0.001},{"price":11410853.0,"size":0.002},{"price":11412000.0,"size":0.0878},{"price":11415000.0,"size":0.002},{"price":11415141.0,"size":0.0041},{"price":11417481.0,"size":0.0015},{"price":11418700.0,"size":0.001},{"price":11420000.0,"size":0.401},{"price":11421268.0,"size":0.05},{"price":11421881.0,"size":0.001},{"price":11423339.0,"size":2.0},{"price":11424296.0,"size":0.002},{"price":11424941.0,"size":0.972},{"price":11425000.0,"size":0.049},{"price":11426426.0,"size":0.002},{"price":11428121.0,"size":0.002},{"price":11428700.0,"size":0.001},{"price":11429302.0,"size":0.01},{"price":11432718.0,"size":0.002},{"price":11433211.0,"size":0.03},{"price":11433215.0,"size":0.001},{"price":11433333.0,"size":0.001},{"price":11437315.0,"size":0.002},{"price":11438525.0,"size":0.0011},{"price":11438700.0,"size":0.001},{"price":11439557.0,"size":0.001},{"price":11440000.0,"size":0.1038},{"price":11441911.0,"size":0.002},{"price":11443629.0,"size":0.002},{"price":11444549.0,"size":0.001},{"price":11446508.0,"size":0.001},{"price":11447000.0,"size":0.01},{"price":11447071.0,"size":0.002},{"price":11448000.0,"size":0.0875},{"price":11448700.0,"size":0.001},{"price":11450000.0,"size":0.258},{"price":11451105.0,"size":0.002},{"price":11453321.0,"size":0.03},{"price":11455702.0,"size":0.002},{"price":11455883.0,"size":0.001},{"price":11458700.0,"size":0.001},{"price":11458988.0,"size":0.01},{"price":11460000.0,"size":0.01702},{"price":11460299.0,"size":0.002},{"price":11464896.0,"size":0.002},{"price":11467217.0,"size":0.001},{"price":11468700.0,"size":0.001},{"price":11470000.0,"size":0.01},{"price":11471000.0,"size":0.01},{"price":11475000.0,"size":0.0028},{"price":11478431.0,"size":0.002},{"price":11478551.0,"size":0.001},{"price":11478700.0,"size":0.001},{"price":11480000.0,"size":0.12491},{"price":11485000.0,"size":0.01},{"price":11486555.0,"size":0.03},{"price":11487685.0,"size":0.01},{"price":11488000.0,"size":0.102},{"price":11488700.0,"size":0.001},{"price":11489885.0,"size":0.001},{"price":11490841.0,"size":0.002},{"price":11495450.0,"size":0.002},{"price":11495850.0,"size":0.001},{"price":11498700.0,"size":0.001},{"price":11498917.0,"size":0.002},{"price":11499000.0,"size":0.01},{"price":11500000.0,"size":0.66859519},{"price":11501219.0,"size":0.001},{"price":11502377.0,"size":0.002},{"price":11502800.0,"size":0.00132},{"price":11503108.0,"size":0.0198},{"price":11505000.0,"size":0.0028},{"price":11505001.0,"size":0.002},{"price":11505836.0,"size":0.003},{"price":11508431.0,"size":0.047},{"price":11508700.0,"size":0.001},{"price":11508888.0,"size":0.02},{"price":11510000.0,"size":0.0976},{"price":11512553.0,"size":0.001},{"price":11513633.0,"size":0.08},{"price":11514332.0,"size":0.02},{"price":11518700.0,"size":0.001},{"price":11518992.0,"size":0.002},{"price":11519855.0,"size":0.01},{"price":11520000.0,"size":0.001},{"price":11522423.0,"size":0.97},{"price":11523211.0,"size":0.01},{"price":11523887.0,"size":0.001},{"price":11524999.0,"size":0.001},{"price":11528700.0,"size":0.001},{"price":11529852.0,"size":0.01},{"price":11530000.0,"size":0.261},{"price":11533985.0,"size":0.002},{"price":11534084.0,"size":0.001},{"price":11535321.0,"size":0.01},{"price":11538666.0,"size":0.002},{"price":11538700.0,"size":0.001},{"price":11540000.0,"size":0.0048},{"price":11540357.0,"size":0.002},{"price":11541011.0,"size":0.005},{"price":11541109.0,"size":0.01},{"price":11544663.0,"size":0.002},{"price":11545262.0,"size":0.002},{"price":11546541.0,"size":0.01},{"price":11548144.0,"size":0.002},{"price":11548700.0,"size":0.001},{"price":11550000.0,"size":0.014},{"price":11551109.0,"size":0.01},{"price":11551625.0,"size":0.002},{"price":11552111.0,"size":0.01},{"price":11553687.0,"size":0.1},{"price":11555106.0,"size":0.002},{"price":11555115.0,"size":0.001},{"price":11556000.0,"size":0.1},{"price":11558587.0,"size":0.002},{"price":11558700.0,"size":0.001},{"price":11559855.0,"size":0.01},{"price":11560831.0,"size":0.0198},{"price":11561109.0,"size":0.01},{"price":11562000.0,"size":0.087},{"price":11562068.0,"size":0.002},{"price":11565548.0,"size":0.002},{"price":11566139.0,"size":0.0228},{"price":11566551.0,"size":0.01},{"price":11568700.0,"size":0.001},{"price":11569029.0,"size":0.002},{"price":11570196.0,"size":0.002},{"price":11571109.0,"size":0.01},{"price":11572510.0,"size":0.002},{"price":11573211.0,"size":0.01},{"price":11574840.0,"size":0.002},{"price":11575991.0,"size":0.001},{"price":11578700.0,"size":0.001},{"price":11579484.0,"size":0.002},{"price":11579851.0,"size":0.01},{"price":11580000.0,"size":0.7735},{"price":11581109.0,"size":0.01},{"price":11584128.0,"size":0.002},{"price":11585000.0,"size":0.002},{"price":11586532.0,"size":0.01},{"price":11587498.0,"size":0.0198},{"price":11588700.0,"size":0.001},{"price":11589612.0,"size":0.012},{"price":11590000.0,"size":0.1},{"price":11590749.0,"size":0.002},{"price":11591109.0,"size":0.01},{"price":11593211.0,"size":0.01},{"price":11596753.0,"size":0.002},{"price":11598555.0,"size":0.01},{"price":11598700.0,"size":0.001},{"price":11599999.0,"size":0.001},{"price":11600000.0,"size":3.6141},{"price":11601109.0,"size":0.02},{"price":11606655.0,"size":0.01},{"price":11610000.0,"size":0.302},{"price":11611109.0,"size":0.01},{"price":11613321.0,"size":0.01},{"price":11620000.0,"size":1.35441682},{"price":11621011.0,"size":0.01},{"price":11621109.0,"size":0.01},{"price":11623096.0,"size":0.008},{"price":11629000.0,"size":0.1},{"price":11630000.0,"size":0.201},{"price":11631059.0,"size":0.01},{"price":11631479.0,"size":0.01},{"price":11631773.0,"size":0.00386871},{"price":11635950.0,"size":0.001},{"price":11638259.0,"size":0.001},{"price":11639700.0,"size":0.001},{"price":11640000.0,"size":1.0},{"price":11640820.0,"size":0.01},{"price":11645040.0,"size":1.7},{"price":11645295.0,"size":0.05},{"price":11647158.0,"size":0.05},{"price":11649900.0,"size":0.02906},{"price":11649999.0,"size":0.001},{"price":11650000.0,"size":0.593},{"price":11651059.0,"size":0.01},{"price":11653658.0,"size":0.008},{"price":11654321.0,"size":0.001},{"price":11659700.0,"size":0.001},{"price":11661479.0,"size":0.01},{"price":11666000.0,"size":0.001},{"price":11666666.0,"size":0.013},{"price":11669700.0,"size":0.001},{"price":11671059.0,"size":0.01},{"price":11672562.0,"size":0.0198},{"price":11679224.0,"size":0.012},{"price":11680000.0,"size":0.004},{"price":11685000.0,"size":0.003},{"price":11688000.0,"size":0.001},{"price":11689732.0,"size":0.01},{"price":11690330.0,"size":0.0198},{"price":11691059.0,"size":0.01},{"price":11692558.0,"size":0.01},{"price":11698800.0,"size":0.00131},{"price":11699000.0,"size":0.001},{"price":11699631.0,"size":0.001},{"price":11699998.0,"size":0.01},{"price":11699999.0,"size":0.001},{"price":11700000.0,"size":1.03762841},{"price":11701059.0,"size":0.01},{"price":11720000.0,"size":0.1},{"price":11721059.0,"size":0.01},{"price":11725000.0,"size":0.005},{"price":11726791.0,"size":0.01},{"price":11730000.0,"size":0.9382},{"price":11740000.0,"size":0.101},{"price":11741059.0,"size":0.01},{"price":11748937.0,"size":0.001},{"price":11749999.0,"size":0.001},{"price":11750000.0,"size":0.90537866},{"price":11750050.0,"size":0.2}]}}}
{"schema_version":"collector.vnext.raw","schema_contract":null,"schema_contract_version":null,"payload_contract_version":null,"record_type":"market.orderbook.diff","record_id":"collector_main-market-orderbook-diff-000000000061","collector_id":"collector_main","collector_role":"production","host_name":"MAIN-PC","session_id":"collector_main-sess-20260314T201641Z-5a4853e4","stream_session_id":"collector_main-stream-bitflyer-board_ws-20260314T201739Z-d055dc6b","exchange":"bitflyer","market":"spot","symbol":"BTC_JPY","instrument_id":"bitflyer.spot.BTC_JPY","channel":"board_ws","transport":"websocket","source_event_id":null,"source_sequence":null,"sequence_id":61,"exchange_ts":null,"collector_ts":"2026-03-14T20:17:39Z","ingest_ts":"2026-03-14T20:17:39Z","event_ts":"2026-03-14T20:17:39Z","quality_flags":[],"is_partial":false,"is_reconstructed":false,"confidence_score":1.0,"payload":{"provider":"bitflyer_ws_board","exchange":"bitflyer","transport":"websocket","channel":"lightning_board_BTC_JPY","received_ts":"2026-03-14T20:17:39.502063Z","subscription_id":null,"message_id":null,"source_sequence":null,"raw_message_meta":{"raw_channel":"lightning_board_BTC_JPY","subscription_channel":"lightning_board_BTC_JPY","recv_timeout_sec":10,"ssl_verify":false,"socket_url":"wss://ws.lightstream.bitflyer.com/json-rpc"},"source_payload":{"mid_price":11308753.0,"bids":[],"asks":[{"price":11312149.0,"size":0.0},{"price":11312148.0,"size":0.0},{"price":11312146.0,"size":0.04587421}]}}}
{"schema_version":"collector.vnext.raw","schema_contract":null,"schema_contract_version":null,"payload_contract_version":null,"record_type":"market.orderbook.diff","record_id":"collector_main-market-orderbook-diff-000000000065","collector_id":"collector_main","collector_role":"production","host_name":"MAIN-PC","session_id":"collector_main-sess-20260314T201641Z-5a4853e4","stream_session_id":"collector_main-stream-bitflyer-board_ws-20260314T201739Z-d055dc6b","exchange":"bitflyer","market":"spot","symbol":"BTC_JPY","instrument_id":"bitflyer.spot.BTC_JPY","channel":"board_ws","transport":"websocket","source_event_id":null,"source_sequence":null,"sequence_id":65,"exchange_ts":null,"collector_ts":"2026-03-14T20:17:39Z","ingest_ts":"2026-03-14T20:17:39Z","event_ts":"2026-03-14T20:17:39Z","quality_flags":[],"is_partial":false,"is_reconstructed":false,"confidence_score":1.0,"payload":{"provider":"bitflyer_ws_board","exchange":"bitflyer","transport":"websocket","channel":"lightning_board_BTC_JPY","received_ts":"2026-03-14T20:17:39.611611Z","subscription_id":null,"message_id":null,"source_sequence":null,"raw_message_meta":{"raw_channel":"lightning_board_BTC_JPY","subscription_channel":"lightning_board_BTC_JPY","recv_timeout_sec":10,"ssl_verify":false,"socket_url":"wss://ws.lightstream.bitflyer.com/json-rpc"},"source_payload":{"mid_price":11308753.0,"bids":[{"price":11307078.0,"size":0.0}],"asks":[]}}}
{"schema_version":"collector.vnext.raw","schema_contract":null,"schema_contract_version":null,"payload_contract_version":null,"record_type":"market.orderbook.diff","record_id":"collector_main-market-orderbook-diff-000000000067","collector_id":"collector_main","collector_role":"production","host_name":"MAIN-PC","session_id":"collector_main-sess-20260314T201641Z-5a4853e4","stream_session_id":"collector_main-stream-bitflyer-board_ws-20260314T201739Z-d055dc6b","exchange":"bitflyer","market":"spot","symbol":"BTC_JPY","instrument_id":"bitflyer.spot.BTC_JPY","channel":"board_ws","transport":"websocket","source_event_id":null,"source_sequence":null,"sequence_id":67,"exchange_ts":null,"collector_ts":"2026-03-14T20:17:39Z","ingest_ts":"2026-03-14T20:17:39Z","event_ts":"2026-03-14T20:17:39Z","quality_flags":[],"is_partial":false,"is_reconstructed":false,"confidence_score":1.0,"payload":{"provider":"bitflyer_ws_board","exchange":"bitflyer","transport":"websocket","channel":"lightning_board_BTC_JPY","received_ts":"2026-03-14T20:17:39.704073Z","subscription_id":null,"message_id":null,"source_sequence":null,"raw_message_meta":{"raw_channel":"lightning_board_BTC_JPY","subscription_channel":"lightning_board_BTC_JPY","recv_timeout_sec":10,"ssl_verify":false,"socket_url":"wss://ws.lightstream.bitflyer.com/json-rpc"},"source_payload":{"mid_price":11308753.0,"bids":[],"asks":[{"price":11312148.0,"size":0.02},{"price":11312147.0,"size":0.0}]}}}
{"schema_version":"collector.vnext.raw","schema_contract":null,"schema_contract_version":null,"payload_contract_version":null,"record_type":"market.orderbook.diff","record_id":"collector_main-market-orderbook-diff-000000000069","collector_id":"collector_main","collector_role":"production","host_name":"MAIN-PC","session_id":"collector_main-sess-20260314T201641Z-5a4853e4","stream_session_id":"collector_main-stream-bitflyer-board_ws-20260314T201739Z-d055dc6b","exchange":"bitflyer","market":"spot","symbol":"BTC_JPY","instrument_id":"bitflyer.spot.BTC_JPY","channel":"board_ws","transport":"websocket","source_event_id":null,"source_sequence":null,"sequence_id":69,"exchange_ts":null,"collector_ts":"2026-03-14T20:17:39Z","ingest_ts":"2026-03-14T20:17:39Z","event_ts":"2026-03-14T20:17:39Z","quality_flags":[],"is_partial":false,"is_reconstructed":false,"confidence_score":1.0,"payload":{"provider":"bitflyer_ws_board","exchange":"bitflyer","transport":"websocket","channel":"lightning_board_BTC_JPY","received_ts":"2026-03-14T20:17:39.823860Z","subscription_id":null,"message_id":null,"source_sequence":null,"raw_message_meta":{"raw_channel":"lightning_board_BTC_JPY","subscription_channel":"lightning_board_BTC_JPY","recv_timeout_sec":10,"ssl_verify":false,"socket_url":"wss://ws.lightstream.bitflyer.com/json-rpc"},"source_payload":{"mid_price":11308753.0,"bids":[],"asks":[{"price":11312145.0,"size":0.02},{"price":11428121.0,"size":0.002}]}}}
{"schema_version":"collector.vnext.raw","schema_contract":null,"schema_contract_version":null,"payload_contract_version":null,"record_type":"market.orderbook.diff","record_id":"collector_main-market-orderbook-diff-000000000071","collector_id":"collector_main","collector_role":"production","host_name":"MAIN-PC","session_id":"collector_main-sess-20260314T201641Z-5a4853e4","stream_session_id":"collector_main-stream-bitflyer-board_ws-20260314T201739Z-d055dc6b","exchange":"bitflyer","market":"spot","symbol":"BTC_JPY","instrument_id":"bitflyer.spot.BTC_JPY","channel":"board_ws","transport":"websocket","source_event_id":null,"source_sequence":null,"sequence_id":71,"exchange_ts":null,"collector_ts":"2026-03-14T20:17:39Z","ingest_ts":"2026-03-14T20:17:39Z","event_ts":"2026-03-14T20:17:39Z","quality_flags":[],"is_partial":false,"is_reconstructed":false,"confidence_score":1.0,"payload":{"provider":"bitflyer_ws_board","exchange":"bitflyer","transport":"websocket","channel":"lightning_board_BTC_JPY","received_ts":"2026-03-14T20:17:39.929075Z","subscription_id":null,"message_id":null,"source_sequence":null,"raw_message_meta":{"raw_channel":"lightning_board_BTC_JPY","subscription_channel":"lightning_board_BTC_JPY","recv_timeout_sec":10,"ssl_verify":false,"socket_url":"wss://ws.lightstream.bitflyer.com/json-rpc"},"source_payload":{"mid_price":11308753.0,"bids":[{"price":11306248.0,"size":0.0099986}],"asks":[{"price":11312148.0,"size":0.0}]}}}
{"schema_version":"collector.vnext.raw","schema_contract":null,"schema_contract_version":null,"payload_contract_version":null,"record_type":"market.orderbook.diff","record_id":"collector_main-market-orderbook-diff-000000000073","collector_id":"collector_main","collector_role":"production","host_name":"MAIN-PC","session_id":"collector_main-sess-20260314T201641Z-5a4853e4","stream_session_id":"collector_main-stream-bitflyer-board_ws-20260314T201739Z-d055dc6b","exchange":"bitflyer","market":"spot","symbol":"BTC_JPY","instrument_id":"bitflyer.spot.BTC_JPY","channel":"board_ws","transport":"websocket","source_event_id":null,"source_sequence":null,"sequence_id":73,"exchange_ts":null,"collector_ts":"2026-03-14T20:17:40Z","ingest_ts":"2026-03-14T20:17:40Z","event_ts":"2026-03-14T20:17:40Z","quality_flags":[],"is_partial":false,"is_reconstructed":false,"confidence_score":1.0,"payload":{"provider":"bitflyer_ws_board","exchange":"bitflyer","transport":"websocket","channel":"lightning_board_BTC_JPY","received_ts":"2026-03-14T20:17:40.032615Z","subscription_id":null,"message_id":null,"source_sequence":null,"raw_message_meta":{"raw_channel":"lightning_board_BTC_JPY","subscription_channel":"lightning_board_BTC_JPY","recv_timeout_sec":10,"ssl_verify":false,"socket_url":"wss://ws.lightstream.bitflyer.com/json-rpc"},"source_payload":{"mid_price":11308753.0,"bids":[],"asks":[{"price":11312146.0,"size":0.02},{"price":11312147.0,"size":0.02},{"price":11312144.0,"size":0.04769239}]}}}
{"schema_version":"collector.vnext.raw","schema_contract":null,"schema_contract_version":null,"payload_contract_version":null,"record_type":"market.orderbook.diff","record_id":"collector_main-market-orderbook-diff-000000000075","collector_id":"collector_main","collector_role":"production","host_name":"MAIN-PC","session_id":"collector_main-sess-20260314T201641Z-5a4853e4","stream_session_id":"collector_main-stream-bitflyer-board_ws-20260314T201739Z-d055dc6b","exchange":"bitflyer","market":"spot","symbol":"BTC_JPY","instrument_id":"bitflyer.spot.BTC_JPY","channel":"board_ws","transport":"websocket","source_event_id":null,"source_sequence":null,"sequence_id":75,"exchange_ts":null,"collector_ts":"2026-03-14T20:17:40Z","ingest_ts":"2026-03-14T20:17:40Z","event_ts":"2026-03-14T20:17:40Z","quality_flags":[],"is_partial":false,"is_reconstructed":false,"confidence_score":1.0,"payload":{"provider":"bitflyer_ws_board","exchange":"bitflyer","transport":"websocket","channel":"lightning_board_BTC_JPY","received_ts":"2026-03-14T20:17:40.128390Z","subscription_id":null,"message_id":null,"source_sequence":null,"raw_message_meta":{"raw_channel":"lightning_board_BTC_JPY","subscription_channel":"lightning_board_BTC_JPY","recv_timeout_sec":10,"ssl_verify":false,"socket_url":"wss://ws.lightstream.bitflyer.com/json-rpc"},"source_payload":{"mid_price":11308753.0,"bids":[],"asks":[{"price":11312146.0,"size":0.0},{"price":11312147.0,"size":0.0}]}}}
{"schema_version":"collector.vnext.raw","schema_contract":null,"schema_contract_version":null,"payload_contract_version":null,"record_type":"market.orderbook.diff","record_id":"collector_main-market-orderbook-diff-000000000077","collector_id":"collector_main","collector_role":"production","host_name":"MAIN-PC","session_id":"collector_main-sess-20260314T201641Z-5a4853e4","stream_session_id":"collector_main-stream-bitflyer-board_ws-20260314T201739Z-d055dc6b","exchange":"bitflyer","market":"spot","symbol":"BTC_JPY","instrument_id":"bitflyer.spot.BTC_JPY","channel":"board_ws","transport":"websocket","source_event_id":null,"source_sequence":null,"sequence_id":77,"exchange_ts":null,"collector_ts":"2026-03-14T20:17:40Z","ingest_ts":"2026-03-14T20:17:40Z","event_ts":"2026-03-14T20:17:40Z","quality_flags":[],"is_partial":false,"is_reconstructed":false,"confidence_score":1.0,"payload":{"provider":"bitflyer_ws_board","exchange":"bitflyer","transport":"websocket","channel":"lightning_board_BTC_JPY","received_ts":"2026-03-14T20:17:40.344765Z","subscription_id":null,"message_id":null,"source_sequence":null,"raw_message_meta":{"raw_channel":"lightning_board_BTC_JPY","subscription_channel":"lightning_board_BTC_JPY","recv_timeout_sec":10,"ssl_verify":false,"socket_url":"wss://ws.lightstream.bitflyer.com/json-rpc"},"source_payload":{"mid_price":11308753.0,"bids":[],"asks":[{"price":13869000.0,"size":0.001},{"price":11312143.0,"size":0.02},{"price":11312145.0,"size":0.0}]}}}
{"schema_version":"collector.vnext.raw","schema_contract":null,"schema_contract_version":null,"payload_contract_version":null,"record_type":"market.orderbook.diff","record_id":"collector_main-market-orderbook-diff-000000000079","collector_id":"collector_main","collector_role":"production","host_name":"MAIN-PC","session_id":"collector_main-sess-20260314T201641Z-5a4853e4","stream_session_id":"collector_main-stream-bitflyer-board_ws-20260314T201739Z-d055dc6b","exchange":"bitflyer","market":"spot","symbol":"BTC_JPY","instrument_id":"bitflyer.spot.BTC_JPY","channel":"board_ws","transport":"websocket","source_event_id":null,"source_sequence":null,"sequence_id":79,"exchange_ts":null,"collector_ts":"2026-03-14T20:17:40Z","ingest_ts":"2026-03-14T20:17:40Z","event_ts":"2026-03-14T20:17:40Z","quality_flags":[],"is_partial":false,"is_reconstructed":false,"confidence_score":1.0,"payload":{"provider":"bitflyer_ws_board","exchange":"bitflyer","transport":"websocket","channel":"lightning_board_BTC_JPY","received_ts":"2026-03-14T20:17:40.438567Z","subscription_id":null,"message_id":null,"source_sequence":null,"raw_message_meta":{"raw_channel":"lightning_board_BTC_JPY","subscription_channel":"lightning_board_BTC_JPY","recv_timeout_sec":10,"ssl_verify":false,"socket_url":"wss://ws.lightstream.bitflyer.com/json-rpc"},"source_payload":{"mid_price":11308753.0,"bids":[{"price":11300672.0,"size":0.0}],"asks":[{"price":13877500.0,"size":0.001}]}}}
{"schema_version":"collector.vnext.raw","schema_contract":null,"schema_contract_version":null,"payload_contract_version":null,"record_type":"market.orderbook.diff","record_id":"collector_main-market-orderbook-diff-000000000081","collector_id":"collector_main","collector_role":"production","host_name":"MAIN-PC","session_id":"collector_main-sess-20260314T201641Z-5a4853e4","stream_session_id":"collector_main-stream-bitflyer-board_ws-20260314T201739Z-d055dc6b","exchange":"bitflyer","market":"spot","symbol":"BTC_JPY","instrument_id":"bitflyer.spot.BTC_JPY","channel":"board_ws","transport":"websocket","source_event_id":null,"source_sequence":null,"sequence_id":81,"exchange_ts":null,"collector_ts":"2026-03-14T20:17:40Z","ingest_ts":"2026-03-14T20:17:40Z","event_ts":"2026-03-14T20:17:40Z","quality_flags":[],"is_partial":false,"is_reconstructed":false,"confidence_score":1.0,"payload":{"provider":"bitflyer_ws_board","exchange":"bitflyer","transport":"websocket","channel":"lightning_board_BTC_JPY","received_ts":"2026-03-14T20:17:40.549649Z","subscription_id":null,"message_id":null,"source_sequence":null,"raw_message_meta":{"raw_channel":"lightning_board_BTC_JPY","subscription_channel":"lightning_board_BTC_JPY","recv_timeout_sec":10,"ssl_verify":false,"socket_url":"wss://ws.lightstream.bitflyer.com/json-rpc"},"source_payload":{"mid_price":11308753.0,"bids":[],"asks":[{"price":11544663.0,"size":0.002},{"price":11312144.0,"size":0.0},{"price":13886000.0,"size":0.001}]}}}
{"schema_version":"collector.vnext.raw","schema_contract":null,"schema_contract_version":null,"payload_contract_version":null,"record_type":"market.orderbook.diff","record_id":"collector_main-market-orderbook-diff-000000000083","collector_id":"collector_main","collector_role":"production","host_name":"MAIN-PC","session_id":"collector_main-sess-20260314T201641Z-5a4853e4","stream_session_id":"collector_main-stream-bitflyer-board_ws-20260314T201739Z-d055dc6b","exchange":"bitflyer","market":"spot","symbol":"BTC_JPY","instrument_id":"bitflyer.spot.BTC_JPY","channel":"board_ws","transport":"websocket","source_event_id":null,"source_sequence":null,"sequence_id":83,"exchange_ts":null,"collector_ts":"2026-03-14T20:17:40Z","ingest_ts":"2026-03-14T20:17:40Z","event_ts":"2026-03-14T20:17:40Z","quality_flags":[],"is_partial":false,"is_reconstructed":false,"confidence_score":1.0,"payload":{"provider":"bitflyer_ws_board","exchange":"bitflyer","transport":"websocket","channel":"lightning_board_BTC_JPY","received_ts":"2026-03-14T20:17:40.657155Z","subscription_id":null,"message_id":null,"source_sequence":null,"raw_message_meta":{"raw_channel":"lightning_board_BTC_JPY","subscription_channel":"lightning_board_BTC_JPY","recv_timeout_sec":10,"ssl_verify":false,"socket_url":"wss://ws.lightstream.bitflyer.com/json-rpc"},"source_payload":{"mid_price":11308753.0,"bids":[{"price":11300232.0,"size":0.0531}],"asks":[{"price":11312142.0,"size":0.04629379}]}}}
{"schema_version":"collector.vnext.raw","schema_contract":null,"schema_contract_version":null,"payload_contract_version":null,"record_type":"market.orderbook.diff","record_id":"collector_main-market-orderbook-diff-000000000085","collector_id":"collector_main","collector_role":"production","host_name":"MAIN-PC","session_id":"collector_main-sess-20260314T201641Z-5a4853e4","stream_session_id":"collector_main-stream-bitflyer-board_ws-20260314T201739Z-d055dc6b","exchange":"bitflyer","market":"spot","symbol":"BTC_JPY","instrument_id":"bitflyer.spot.BTC_JPY","channel":"board_ws","transport":"websocket","source_event_id":null,"source_sequence":null,"sequence_id":85,"exchange_ts":null,"collector_ts":"2026-03-14T20:17:40Z","ingest_ts":"2026-03-14T20:17:40Z","event_ts":"2026-03-14T20:17:40Z","quality_flags":[],"is_partial":false,"is_reconstructed":false,"confidence_score":1.0,"payload":{"provider":"bitflyer_ws_board","exchange":"bitflyer","transport":"websocket","channel":"lightning_board_BTC_JPY","received_ts":"2026-03-14T20:17:40.767159Z","subscription_id":null,"message_id":null,"source_sequence":null,"raw_message_meta":{"raw_channel":"lightning_board_BTC_JPY","subscription_channel":"lightning_board_BTC_JPY","recv_timeout_sec":10,"ssl_verify":false,"socket_url":"wss://ws.lightstream.bitflyer.com/json-rpc"},"source_payload":{"mid_price":11308753.0,"bids":[],"asks":[{"price":11312143.0,"size":0.0}]}}}
{"schema_version":"collector.vnext.raw","schema_contract":null,"schema_contract_version":null,"payload_contract_version":null,"record_type":"market.orderbook.diff","record_id":"collector_main-market-orderbook-diff-000000000087","collector_id":"collector_main","collector_role":"production","host_name":"MAIN-PC","session_id":"collector_main-sess-20260314T201641Z-5a4853e4","stream_session_id":"collector_main-stream-bitflyer-board_ws-20260314T201739Z-d055dc6b","exchange":"bitflyer","market":"spot","symbol":"BTC_JPY","instrument_id":"bitflyer.spot.BTC_JPY","channel":"board_ws","transport":"websocket","source_event_id":null,"source_sequence":null,"sequence_id":87,"exchange_ts":null,"collector_ts":"2026-03-14T20:17:40Z","ingest_ts":"2026-03-14T20:17:40Z","event_ts":"2026-03-14T20:17:40Z","quality_flags":[],"is_partial":false,"is_reconstructed":false,"confidence_score":1.0,"payload":{"provider":"bitflyer_ws_board","exchange":"bitflyer","transport":"websocket","channel":"lightning_board_BTC_JPY","received_ts":"2026-03-14T20:17:40.929343Z","subscription_id":null,"message_id":null,"source_sequence":null,"raw_message_meta":{"raw_channel":"lightning_board_BTC_JPY","subscription_channel":"lightning_board_BTC_JPY","recv_timeout_sec":10,"ssl_verify":false,"socket_url":"wss://ws.lightstream.bitflyer.com/json-rpc"},"source_payload":{"mid_price":11308753.0,"bids":[],"asks":[{"price":11432718.0,"size":0.002},{"price":11312142.0,"size":0.0}]}}}
{"schema_version":"collector.vnext.raw","schema_contract":null,"schema_contract_version":null,"payload_contract_version":null,"record_type":"market.orderbook.diff","record_id":"collector_main-market-orderbook-diff-000000000089","collector_id":"collector_main","collector_role":"production","host_name":"MAIN-PC","session_id":"collector_main-sess-20260314T201641Z-5a4853e4","stream_session_id":"collector_main-stream-bitflyer-board_ws-20260314T201739Z-d055dc6b","exchange":"bitflyer","market":"spot","symbol":"BTC_JPY","instrument_id":"bitflyer.spot.BTC_JPY","channel":"board_ws","transport":"websocket","source_event_id":null,"source_sequence":null,"sequence_id":89,"exchange_ts":null,"collector_ts":"2026-03-14T20:17:41Z","ingest_ts":"2026-03-14T20:17:41Z","event_ts":"2026-03-14T20:17:41Z","quality_flags":[],"is_partial":false,"is_reconstructed":false,"confidence_score":1.0,"payload":{"provider":"bitflyer_ws_board","exchange":"bitflyer","transport":"websocket","channel":"lightning_board_BTC_JPY","received_ts":"2026-03-14T20:17:41.049483Z","subscription_id":null,"message_id":null,"source_sequence":null,"raw_message_meta":{"raw_channel":"lightning_board_BTC_JPY","subscription_channel":"lightning_board_BTC_JPY","recv_timeout_sec":10,"ssl_verify":false,"socket_url":"wss://ws.lightstream.bitflyer.com/json-rpc"},"source_payload":{"mid_price":11308753.0,"bids":[],"asks":[{"price":11312150.0,"size":0.04806535}]}}}
{"schema_version":"collector.vnext.raw","schema_contract":null,"schema_contract_version":null,"payload_contract_version":null,"record_type":"market.orderbook.diff","record_id":"collector_main-market-orderbook-diff-000000000091","collector_id":"collector_main","collector_role":"production","host_name":"MAIN-PC","session_id":"collector_main-sess-20260314T201641Z-5a4853e4","stream_session_id":"collector_main-stream-bitflyer-board_ws-20260314T201739Z-d055dc6b","exchange":"bitflyer","market":"spot","symbol":"BTC_JPY","instrument_id":"bitflyer.spot.BTC_JPY","channel":"board_ws","transport":"websocket","source_event_id":null,"source_sequence":null,"sequence_id":91,"exchange_ts":null,"collector_ts":"2026-03-14T20:17:41Z","ingest_ts":"2026-03-14T20:17:41Z","event_ts":"2026-03-14T20:17:41Z","quality_flags":[],"is_partial":false,"is_reconstructed":false,"confidence_score":1.0,"payload":{"provider":"bitflyer_ws_board","exchange":"bitflyer","transport":"websocket","channel":"lightning_board_BTC_JPY","received_ts":"2026-03-14T20:17:41.164033Z","subscription_id":null,"message_id":null,"source_sequence":null,"raw_message_meta":{"raw_channel":"lightning_board_BTC_JPY","subscription_channel":"lightning_board_BTC_JPY","recv_timeout_sec":10,"ssl_verify":false,"socket_url":"wss://ws.lightstream.bitflyer.com/json-rpc"},"source_payload":{"mid_price":11308753.0,"bids":[],"asks":[{"price":11317394.0,"size":0.0}]}}}
{"schema_version":"collector.vnext.raw","schema_contract":null,"schema_contract_version":null,"payload_contract_version":null,"record_type":"market.orderbook.diff","record_id":"collector_main-market-orderbook-diff-000000000093","collector_id":"collector_main","collector_role":"production","host_name":"MAIN-PC","session_id":"collector_main-sess-20260314T201641Z-5a4853e4","stream_session_id":"collector_main-stream-bitflyer-board_ws-20260314T201739Z-d055dc6b","exchange":"bitflyer","market":"spot","symbol":"BTC_JPY","instrument_id":"bitflyer.spot.BTC_JPY","channel":"board_ws","transport":"websocket","source_event_id":null,"source_sequence":null,"sequence_id":93,"exchange_ts":null,"collector_ts":"2026-03-14T20:17:41Z","ingest_ts":"2026-03-14T20:17:41Z","event_ts":"2026-03-14T20:17:41Z","quality_flags":[],"is_partial":false,"is_reconstructed":false,"confidence_score":1.0,"payload":{"provider":"bitflyer_ws_board","exchange":"bitflyer","transport":"websocket","channel":"lightning_board_BTC_JPY","received_ts":"2026-03-14T20:17:41.295296Z","subscription_id":null,"message_id":null,"source_sequence":null,"raw_message_meta":{"raw_channel":"lightning_board_BTC_JPY","subscription_channel":"lightning_board_BTC_JPY","recv_timeout_sec":10,"ssl_verify":false,"socket_url":"wss://ws.lightstream.bitflyer.com/json-rpc"},"source_payload":{"mid_price":11308753.0,"bids":[],"asks":[{"price":11317393.0,"size":0.57598029}]}}}
{"schema_version":"collector.vnext.raw","schema_contract":null,"schema_contract_version":null,"payload_contract_version":null,"record_type":"market.orderbook.diff","record_id":"collector_main-market-orderbook-diff-000000000095","collector_id":"collector_main","collector_role":"production","host_name":"MAIN-PC","session_id":"collector_main-sess-20260314T201641Z-5a4853e4","stream_session_id":"collector_main-stream-bitflyer-board_ws-20260314T201739Z-d055dc6b","exchange":"bitflyer","market":"spot","symbol":"BTC_JPY","instrument_id":"bitflyer.spot.BTC_JPY","channel":"board_ws","transport":"websocket","source_event_id":null,"source_sequence":null,"sequence_id":95,"exchange_ts":null,"collector_ts":"2026-03-14T20:17:41Z","ingest_ts":"2026-03-14T20:17:41Z","event_ts":"2026-03-14T20:17:41Z","quality_flags":[],"is_partial":false,"is_reconstructed":false,"confidence_score":1.0,"payload":{"provider":"bitflyer_ws_board","exchange":"bitflyer","transport":"websocket","channel":"lightning_board_BTC_JPY","received_ts":"2026-03-14T20:17:41.391604Z","subscription_id":null,"message_id":null,"source_sequence":null,"raw_message_meta":{"raw_channel":"lightning_board_BTC_JPY","subscription_channel":"lightning_board_BTC_JPY","recv_timeout_sec":10,"ssl_verify":false,"socket_url":"wss://ws.lightstream.bitflyer.com/json-rpc"},"source_payload":{"mid_price":11308753.0,"bids":[{"price":11301664.0,"size":0.0}],"asks":[]}}}
{"schema_version":"collector.vnext.raw","schema_contract":null,"schema_contract_version":null,"payload_contract_version":null,"record_type":"market.orderbook.snapshot","record_id":"collector_main-market-orderbook-snapshot-000000000097","collector_id":"collector_main","collector_role":"production","host_name":"MAIN-PC","session_id":"collector_main-sess-20260314T201641Z-5a4853e4","stream_session_id":"collector_main-stream-bitflyer-board_ws-20260314T201739Z-d055dc6b","exchange":"bitflyer","market":"spot","symbol":"BTC_JPY","instrument_id":"bitflyer.spot.BTC_JPY","channel":"board_ws","transport":"websocket","source_event_id":null,"source_sequence":null,"sequence_id":97,"exchange_ts":null,"collector_ts":"2026-03-14T20:17:41Z","ingest_ts":"2026-03-14T20:17:41Z","event_ts":"2026-03-14T20:17:41Z","quality_flags":[],"is_partial":false,"is_reconstructed":false,"confidence_score":1.0,"payload":{"provider":"bitflyer_ws_board_snapshot","exchange":"bitflyer","transport":"websocket","channel":"lightning_board_snapshot_BTC_JPY","received_ts":"2026-03-14T20:17:41.483539Z","subscription_id":null,"message_id":null,"source_sequence":null,"raw_message_meta":{"raw_channel":"lightning_board_snapshot_BTC_JPY","subscription_channel":"lightning_board_snapshot_BTC_JPY","recv_timeout_sec":10,"ssl_verify":false,"socket_url":"wss://ws.lightstream.bitflyer.com/json-rpc"},"source_payload":{"mid_price":11308753.0,"bids":[{"price":11307506.0,"size":0.1275},{"price":11307276.0,"size":0.04328686},{"price":11307275.0,"size":0.1275},{"price":11306248.0,"size":0.0099986},{"price":11305021.0,"size":0.0176894},{"price":11304986.0,"size":0.015156},{"price":11304593.0,"size":0.01554},{"price":11304145.0,"size":0.015324},{"price":11303562.0,"size":0.01446},{"price":11301402.0,"size":0.05},{"price":11301012.0,"size":0.5},{"price":11300836.0,"size":0.05},{"price":11300367.0,"size":0.2},{"price":11300232.0,"size":0.0531},{"price":11300171.0,"size":0.0536544},{"price":11298853.0,"size":2.97365301},{"price":11298751.0,"size":0.5},{"price":11297568.0,"size":0.01},{"price":11296910.0,"size":0.0099986},{"price":11295725.0,"size":0.001},{"price":11293270.0,"size":0.0801},{"price":11289443.0,"size":0.04},{"price":11287379.0,"size":0.2999171},{"price":11287378.0,"size":1.50015},{"price":11286875.0,"size":0.6},{"price":11286651.0,"size":0.98403398},{"price":11286086.0,"size":0.273},{"price":11285569.0,"size":1.484},{"price":11283324.0,"size":0.3118},{"price":11280562.0,"size":0.3089},{"price":11280205.0,"size":0.001},{"price":11279435.0,"size":0.17274976},{"price":11279282.0,"size":0.0015},{"price":11277800.0,"size":0.2689},{"price":11277748.0,"size":0.0966561},{"price":11277602.0,"size":0.005},{"price":11275102.0,"size":0.01},{"price":11275000.0,"size":0.001},{"price":11274588.0,"size":0.0047},{"price":11271000.0,"size":0.003},{"price":11270766.0,"size":0.6},{"price":11270000.0,"size":0.106},{"price":11268871.0,"size":0.281},{"price":11268411.0,"size":0.01},{"price":11266666.0,"size":0.04},{"price":11265000.0,"size":0.02},{"price":11263999.0,"size":1.966},{"price":11263000.0,"size":0.006},{"price":11262564.0,"size":0.0015},{"price":11260000.0,"size":0.3565},{"price":11257537.0,"size":0.001},{"price":11257000.0,"size":0.001},{"price":11255200.0,"size":0.001},{"price":11255115.0,"size":0.00377},{"price":11253628.0,"size":2.036},{"price":11253000.0,"size":0.03189},{"price":11251000.0,"size":0.0131},{"price":11250250.0,"size":0.00105},{"price":11250200.0,"size":0.001},{"price":11250100.0,"size":0.015},{"price":11250005.0,"size":0.001},{"price":11250001.0,"size":0.00104},{"price":11250000.0,"size":0.76834},{"price":11246544.0,"size":0.0015},{"price":11246203.0,"size":0.001},{"price":11245141.0,"size":0.0031},{"price":11245000.0,"size":0.05},{"price":11244444.0,"size":0.04},{"price":11244243.0,"size":0.01},{"price":11240200.0,"size":0.001},{"price":11240000.0,"size":0.007304},{"price":11236190.0,"size":0.01},{"price":11235200.0,"size":0.001},{"price":11234869.0,"size":0.001},{"price":11232000.0,"size":0.089},{"price":11231243.0,"size":0.01},{"price":11231000.0,"size":0.105},{"price":11230200.0,"size":0.001},{"price":11230000.0,"size":0.0308},{"price":11228423.0,"size":1.951},{"price":11224500.0,"size":0.06},{"price":11224355.0,"size":0.0015},{"price":11223968.0,"size":0.001},{"price":11223535.0,"size":0.001},{"price":11223344.0,"size":0.01},{"price":11223000.0,"size":0.1},{"price":11222222.0,"size":0.092525},{"price":11221459.0,"size":0.1393},{"price":11221120.0,"size":0.011},{"price":11220200.0,"size":0.001},{"price":11220001.0,"size":0.004457},{"price":11220000.0,"size":0.321},{"price":11219517.0,"size":0.01},{"price":11219000.0,"size":0.1},{"price":11215200.0,"size":0.001},{"price":11215000.0,"size":0.02},{"price":11212358.0,"size":1.2},{"price":11212201.0,"size":0.001},{"price":11211800.0,"size":0.001},{"price":11211111.0,"size":0.06},{"price":11210200.0,"size":0.001},{"price":11210000.0,"size":0.10622},{"price":11208032.0,"size":0.01},{"price":11207755.0,"size":0.0015},{"price":11206000.0,"size":0.09015},{"price":11205200.0,"size":0.001},{"price":11204578.0,"size":0.002},{"price":11203931.0,"size":1.0},{"price":11201000.0,"size":0.01},{"price":11200867.0,"size":0.001},{"price":11200800.0,"size":0.05},{"price":11200425.0,"size":0.1},{"price":11200200.0,"size":0.001},{"price":11200198.0,"size":0.003},{"price":11200150.0,"size":0.002},{"price":11200002.0,"size":0.001},{"price":11200001.0,"size":0.01104},{"price":11200000.0,"size":1.35988728},{"price":11198508.0,"size":0.05},{"price":11198243.0,"size":0.01},{"price":11197134.0,"size":2.0},{"price":11197000.0,"size":0.0085},{"price":11195692.0,"size":0.0015},{"price":11194090.0,"size":0.03},{"price":11190770.0,"size":0.0309},{"price":11190000.0,"size":0.0010016},{"price":11189555.0,"size":0.5},{"price":11189533.0,"size":0.001},{"price":11188629.0,"size":0.01},{"price":11188382.0,"size":0.001},{"price":11185000.0,"size":0.0085},{"price":11180043.0,"size":0.972},{"price":11180000.0,"size":0.23215},{"price":11178973.0,"size":0.0015},{"price":11178199.0,"size":0.001},{"price":11170000.0,"size":0.001},{"price":11169662.0,"size":0.01},{"price":11169593.0,"size":0.001},{"price":11169243.0,"size":0.01},{"price":11166865.0,"size":0.001},{"price":11164029.0,"size":0.001},{"price":11160854.0,"size":0.1},{"price":11160000.0,"size":0.02376},{"price":11156269.0,"size":0.01},{"price":11155531.0,"size":0.001},{"price":11155377.0,"size":0.00636009},{"price":11153999.0,"size":0.00101},{"price":11151000.0,"size":0.001},{"price":11150250.0,"size":0.00175},{"price":11150005.0,"size":0.001},{"price":11150001.0,"size":0.00104},{"price":11150000.0,"size":0.6398956},{"price":11148000.0,"size":0.08963},{"price":11144197.0,"size":0.001},{"price":11144000.0,"size":0.0897},{"price":11140000.0,"size":0.2},{"price":11136243.0,"size":0.01},{"price":11136155.0,"size":0.02},{"price":11135869.0,"size":0.1},{"price":11130000.0,"size":0.116},{"price":11129979.0,"size":0.0053908},{"price":11126388.0,"size":0.02},{"price":11124900.0,"size":0.00133},{"price":11121090.0,"size":0.1},{"price":11120000.0,"size":0.0033},{"price":11118078.0,"size":0.01},{"price":11111800.0,"size":0.001},{"price":11111111.0,"size":0.2919257},{"price":11111000.0,"size":0.003},{"price":11110594.0,"size":0.001},{"price":11110000.0,"size":0.056937},{"price":11109662.0,"size":0.01},{"price":11108008.0,"size":0.01},{"price":11106000.0,"size":0.2},{"price":11105000.0,"size":0.02},{"price":11101297.0,"size":0.001},{"price":11100005.0,"size":0.001},{"price":11100001.0,"size":0.01104},{"price":11100000.0,"size":2.7475049},{"price":11099141.0,"size":0.01},{"price":11096243.0,"size":0.01},{"price":11094090.0,"size":0.01},{"price":11088888.0,"size":0.001},{"price":11085245.0,"size":0.001},{"price":11080200.0,"size":0.001},{"price":11080000.0,"size":0.0223},{"price":11075100.0,"size":0.003},{"price":11071558.0,"size":1.0},{"price":11070200.0,"size":0.001},{"price":11070000.0,"size":0.0902},{"price":11065200.0,"size":0.001},{"price":11064370.0,"size":0.00497091},{"price":11060200.0,"size":0.001},{"price":11060000.0,"size":0.145},{"price":11059689.0,"size":0.009},{"price":11056428.0,"size":0.002},{"price":11055500.0,"size":0.02},{"price":11055200.0,"size":0.001},{"price":11055100.0,"size":0.003},{"price":11050200.0,"size":0.001},{"price":11050005.0,"size":0.001},{"price":11050002.0,"size":0.001},{"price":11050001.0,"size":0.00104},{"price":11050000.0,"size":0.43176147},{"price":11046420.0,"size":0.2},{"price":11044243.0,"size":0.01},{"price":11041380.0,"size":0.01},{"price":11040200.0,"size":0.001},{"price":11040000.0,"size":0.00877181},{"price":11035865.0,"size":0.1},{"price":11035200.0,"size":0.001},{"price":11035000.0,"size":0.0013},{"price":11030200.0,"size":0.001},{"price":11030000.0,"size":0.025},{"price":11025500.0,"size":0.009531},{"price":11025200.0,"size":0.001},{"price":11025000.0,"size":0.71497},{"price":11020772.0,"size":0.014},{"price":11020200.0,"size":0.002},{"price":11020000.0,"size":0.005},{"price":11015200.0,"size":0.001},{"price":11012000.0,"size":0.1},{"price":11011800.0,"size":0.001},{"price":11011000.0,"size":0.001},{"price":11010200.0,"size":0.001},{"price":11010000.0,"size":0.347},{"price":11007277.0,"size":0.01},{"price":11006000.0,"size":0.2},{"price":11005200.0,"size":0.001},{"price":11004890.0,"size":0.001535},{"price":11003000.0,"size":0.0155},{"price":11001000.0,"size":0.013},{"price":11000500.0,"size":0.05117658},{"price":11000200.0,"size":0.001},{"price":11000002.0,"size":0.004},{"price":11000001.0,"size":0.02604},{"price":11000000.0,"size":5.47323365},{"price":10999999.0,"size":0.003},{"price":10999000.0,"size":0.001},{"price":10996855.0,"size":0.0011},{"price":10995200.0,"size":0.001},{"price":10994499.0,"size":0.00169176},{"price":10990200.0,"size":0.001},{"price":10990000.0,"size":0.10219},{"price":10989001.0,"size":0.00197},{"price":10988999.0,"size":0.001},{"price":10988324.0,"size":0.002},{"price":10987654.0,"size":0.001},{"price":10985200.0,"size":0.001},{"price":10985150.0,"size":0.01},{"price":10980500.0,"size":0.005},{"price":10980200.0,"size":0.001},{"price":10980002.0,"size":0.4},{"price":10980000.0,"size":0.028},{"price":10975200.0,"size":0.001},{"price":10975000.0,"size":0.1},{"price":10971261.0,"size":0.001},{"price":10971243.0,"size":0.01},{"price":10970375.0,"size":1.9},{"price":10970200.0,"size":0.001},{"price":10970000.0,"size":0.09304},{"price":10966600.0,"size":0.001003},{"price":10965200.0,"size":0.001},{"price":10960200.0,"size":0.001},{"price":10960000.0,"size":0.0083},{"price":10956673.0,"size":0.01},{"price":10955200.0,"size":0.001},{"price":10954950.0,"size":0.001},{"price":10950500.0,"size":0.005},{"price":10950001.0,"size":0.00204},{"price":10950000.0,"size":0.5485028},{"price":10949550.0,"size":0.01870657},{"price":10949172.0,"size":0.1},{"price":10948000.0,"size":0.1},{"price":10945243.0,"size":0.01},{"price":10941000.0,"size":0.001},{"price":10940402.0,"size":0.001},{"price":10940200.0,"size":0.001},{"price":10940000.0,"size":0.331},{"price":10938243.0,"size":0.01},{"price":10936200.0,"size":0.00137},{"price":10935200.0,"size":0.001},{"price":10930200.0,"size":0.002},{"price":10930000.0,"size":0.0193},{"price":10925200.0,"size":0.002},{"price":10924451.0,"size":0.0012},{"price":10920509.0,"size":0.01},{"price":10920200.0,"size":0.002},{"price":10920000.0,"size":0.52},{"price":10915200.0,"size":0.001},{"price":10914000.0,"size":0.005},{"price":10911800.0,"size":0.001},{"price":10910500.0,"size":0.005},{"price":10910200.0,"size":0.003},{"price":10910000.0,"size":0.005},{"price":10908243.0,"size":0.01},{"price":10906308.0,"size":0.013},{"price":10905200.0,"size":0.001},{"price":10903000.0,"size":0.027},{"price":10900200.0,"size":0.002}],"asks":[{"price":11310000.0,"size":0.0551},{"price":11312150.0,"size":0.04806535},{"price":11312151.0,"size":0.02},{"price":11312152.0,"size":0.015288},{"price":11312667.0,"size":0.02},{"price":11312668.0,"size":0.1275},{"price":11312720.0,"size":0.4199},{"price":11313699.0,"size":0.01},{"price":11313768.0,"size":0.258},{"price":11313957.0,"size":0.014772},{"price":11316530.0,"size":0.2806},{"price":11317135.0,"size":0.0536544},{"price":11317393.0,"size":0.57598029},{"price":11318050.0,"size":0.002},{"price":11318546.0,"size":0.053},{"price":11318640.0,"size":0.01},{"price":11319292.0,"size":0.2857},{"price":11320000.0,"size":0.02},{"price":11320593.0,"size":0.0050023},{"price":11322000.0,"size":0.005},{"price":11322054.0,"size":0.2675},{"price":11323556.0,"size":1.189881},{"price":11323581.0,"size":1.189881},{"price":11324633.0,"size":0.0050023},{"price":11328050.0,"size":0.002},{"price":11329436.0,"size":0.0015},{"price":11331059.0,"size":0.001},{"price":11333064.0,"size":1.489},{"price":11340000.0,"size":0.13586406},{"price":11340647.0,"size":0.001},{"price":11342956.0,"size":1.60199848},{"price":11342957.0,"size":0.01},{"price":11343223.0,"size":1.928},{"price":11346154.0,"size":0.0015},{"price":11348000.0,"size":0.1999},{"price":11349700.0,"size":0.001},{"price":11350000.0,"size":0.022},{"price":11353877.0,"size":0.001},{"price":11354939.0,"size":0.01},{"price":11355555.0,"size":0.001},{"price":11358323.0,"size":2.018},{"price":11359242.0,"size":0.0011},{"price":11359700.0,"size":0.001},{"price":11362692.0,"size":0.0015},{"price":11365211.0,"size":0.001},{"price":11369700.0,"size":0.001},{"price":11370000.0,"size":0.1},{"price":11372478.0,"size":1.943},{"price":11376000.0,"size":0.02},{"price":11376545.0,"size":0.001},{"price":11377000.0,"size":0.2287},{"price":11377269.0,"size":0.002},{"price":11379700.0,"size":0.001},{"price":11379865.0,"size":0.03},{"price":11380000.0,"size":0.0223},{"price":11380324.0,"size":0.002},{"price":11381766.0,"size":0.4},{"price":11382386.0,"size":0.0015},{"price":11385000.0,"size":0.2548},{"price":11385403.0,"size":0.002},{"price":11385664.0,"size":0.002},{"price":11386197.0,"size":0.002},{"price":11387072.0,"size":0.01},{"price":11387354.0,"size":0.002},{"price":11387879.0,"size":0.001},{"price":11388885.0,"size":0.03},{"price":11389700.0,"size":0.001},{"price":11390000.0,"size":0.2488},{"price":11390050.0,"size":0.001},{"price":11392387.0,"size":1.0},{"price":11394939.0,"size":0.01},{"price":11395000.0,"size":0.06},{"price":11395775.0,"size":0.01},{"price":11396555.0,"size":0.03},{"price":11398444.0,"size":0.001995},{"price":11399213.0,"size":0.001},{"price":11399673.0,"size":0.0015},{"price":11399700.0,"size":0.001},{"price":11400000.0,"size":0.5525},{"price":11405000.0,"size":0.0275},{"price":11406336.0,"size":1.0},{"price":11408700.0,"size":0.001},{"price":11409415.0,"size":0.055},{"price":11410000.0,"size":0.03},{"price":11410547.0,"size":0.001},{"price":11410853.0,"size":0.002},{"price":11412000.0,"size":0.0878},{"price":11415000.0,"size":0.002},{"price":11415141.0,"size":0.0041},{"price":11417481.0,"size":0.0015},{"price":11418700.0,"size":0.001},{"price":11420000.0,"size":0.401},{"price":11421268.0,"size":0.05},{"price":11421881.0,"size":0.001},{"price":11423339.0,"size":2.0},{"price":11424296.0,"size":0.002},{"price":11424941.0,"size":0.972},{"price":11425000.0,"size":0.049},{"price":11426426.0,"size":0.002},{"price":11428121.0,"size":0.002},{"price":11428700.0,"size":0.001},{"price":11429302.0,"size":0.01},{"price":11432718.0,"size":0.002},{"price":11433211.0,"size":0.03},{"price":11433215.0,"size":0.001},{"price":11433333.0,"size":0.001},{"price":11438525.0,"size":0.0011},{"price":11438700.0,"size":0.001},{"price":11439557.0,"size":0.001},{"price":11440000.0,"size":0.1038},{"price":11443629.0,"size":0.002},{"price":11444549.0,"size":0.001},{"price":11447000.0,"size":0.01},{"price":11447071.0,"size":0.002},{"price":11448000.0,"size":0.0875},{"price":11448700.0,"size":0.001},{"price":11450000.0,"size":0.258},{"price":11453321.0,"size":0.03},{"price":11455883.0,"size":0.001},{"price":11458700.0,"size":0.001},{"price":11458988.0,"size":0.01},{"price":11460000.0,"size":0.01702},{"price":11467217.0,"size":0.001},{"price":11468700.0,"size":0.001},{"price":11470000.0,"size":0.01},{"price":11471000.0,"size":0.01},{"price":11475000.0,"size":0.0028},{"price":11478431.0,"size":0.002},{"price":11478551.0,"size":0.001},{"price":11478700.0,"size":0.001},{"price":11480000.0,"size":0.12491},{"price":11485000.0,"size":0.01},{"price":11486555.0,"size":0.03},{"price":11487685.0,"size":0.01},{"price":11488000.0,"size":0.102},{"price":11488700.0,"size":0.001},{"price":11489885.0,"size":0.001},{"price":11495850.0,"size":0.001},{"price":11498700.0,"size":0.001},{"price":11498917.0,"size":0.002},{"price":11499000.0,"size":0.01},{"price":11500000.0,"size":0.66859519},{"price":11501219.0,"size":0.001},{"price":11502377.0,"size":0.002},{"price":11502800.0,"size":0.00132},{"price":11503108.0,"size":0.0198},{"price":11505000.0,"size":0.0028},{"price":11505001.0,"size":0.002},{"price":11505836.0,"size":0.003},{"price":11508431.0,"size":0.047},{"price":11508700.0,"size":0.001},{"price":11508888.0,"size":0.02},{"price":11510000.0,"size":0.0976},{"price":11512553.0,"size":0.001},{"price":11513633.0,"size":0.08},{"price":11514332.0,"size":0.02},{"price":11518700.0,"size":0.001},{"price":11519855.0,"size":0.01},{"price":11520000.0,"size":0.001},{"price":11522423.0,"size":0.97},{"price":11523211.0,"size":0.01},{"price":11523887.0,"size":0.001},{"price":11524999.0,"size":0.001},{"price":11528700.0,"size":0.001},{"price":11529852.0,"size":0.01},{"price":11530000.0,"size":0.261},{"price":11533985.0,"size":0.002},{"price":11534084.0,"size":0.001},{"price":11535321.0,"size":0.01},{"price":11538666.0,"size":0.002},{"price":11538700.0,"size":0.001},{"price":11540000.0,"size":0.0048},{"price":11541011.0,"size":0.005},{"price":11541109.0,"size":0.01},{"price":11544663.0,"size":0.002},{"price":11546541.0,"size":0.01},{"price":11548700.0,"size":0.001},{"price":11550000.0,"size":0.014},{"price":11551109.0,"size":0.01},{"price":11552111.0,"size":0.01},{"price":11553687.0,"size":0.1},{"price":11555115.0,"size":0.001},{"price":11556000.0,"size":0.1},{"price":11558700.0,"size":0.001},{"price":11559855.0,"size":0.01},{"price":11560831.0,"size":0.0198},{"price":11561109.0,"size":0.01},{"price":11562000.0,"size":0.087},{"price":11566139.0,"size":0.0228},{"price":11566551.0,"size":0.01},{"price":11568700.0,"size":0.001},{"price":11571109.0,"size":0.01},{"price":11573211.0,"size":0.01},{"price":11578700.0,"size":0.001},{"price":11579851.0,"size":0.01},{"price":11580000.0,"size":0.7735},{"price":11581109.0,"size":0.01},{"price":11585000.0,"size":0.002},{"price":11586532.0,"size":0.01},{"price":11587498.0,"size":0.0198},{"price":11588700.0,"size":0.001},{"price":11589612.0,"size":0.012},{"price":11590000.0,"size":0.1},{"price":11590749.0,"size":0.002},{"price":11591109.0,"size":0.01},{"price":11593211.0,"size":0.01},{"price":11598555.0,"size":0.01},{"price":11598700.0,"size":0.001},{"price":11599999.0,"size":0.001},{"price":11600000.0,"size":3.6141},{"price":11601109.0,"size":0.02},{"price":11606655.0,"size":0.01},{"price":11610000.0,"size":0.302},{"price":11611109.0,"size":0.01},{"price":11613321.0,"size":0.01},{"price":11620000.0,"size":1.35441682},{"price":11621011.0,"size":0.01},{"price":11621109.0,"size":0.01},{"price":11623096.0,"size":0.008},{"price":11629000.0,"size":0.1},{"price":11630000.0,"size":0.201},{"price":11631059.0,"size":0.01},{"price":11631479.0,"size":0.01},{"price":11631773.0,"size":0.00386871},{"price":11635950.0,"size":0.001},{"price":11638259.0,"size":0.001},{"price":11639700.0,"size":0.001},{"price":11640000.0,"size":1.0},{"price":11640820.0,"size":0.01},{"price":11645040.0,"size":1.7},{"price":11645295.0,"size":0.05},{"price":11647158.0,"size":0.05},{"price":11649900.0,"size":0.02906},{"price":11649999.0,"size":0.001},{"price":11650000.0,"size":0.593},{"price":11651059.0,"size":0.01},{"price":11653658.0,"size":0.008},{"price":11654321.0,"size":0.001},{"price":11659700.0,"size":0.001},{"price":11661479.0,"size":0.01},{"price":11666000.0,"size":0.001},{"price":11666666.0,"size":0.013},{"price":11669700.0,"size":0.001},{"price":11671059.0,"size":0.01},{"price":11672562.0,"size":0.0198},{"price":11679224.0,"size":0.012},{"price":11680000.0,"size":0.004},{"price":11685000.0,"size":0.003},{"price":11688000.0,"size":0.001},{"price":11689732.0,"size":0.01},{"price":11690330.0,"size":0.0198},{"price":11691059.0,"size":0.01},{"price":11692558.0,"size":0.01},{"price":11698800.0,"size":0.00131},{"price":11699000.0,"size":0.001},{"price":11699631.0,"size":0.001},{"price":11699998.0,"size":0.01},{"price":11699999.0,"size":0.001},{"price":11700000.0,"size":1.03762841},{"price":11701059.0,"size":0.01},{"price":11720000.0,"size":0.1},{"price":11721059.0,"size":0.01},{"price":11725000.0,"size":0.005},{"price":11726791.0,"size":0.01},{"price":11730000.0,"size":0.9382},{"price":11740000.0,"size":0.101},{"price":11741059.0,"size":0.01},{"price":11748937.0,"size":0.001},{"price":11749999.0,"size":0.001},{"price":11750000.0,"size":0.90537866},{"price":11750050.0,"size":0.2},{"price":11751151.0,"size":0.01},{"price":11755000.0,"size":0.001},{"price":11757860.0,"size":1.82},{"price":11759999.0,"size":0.001},{"price":11760000.0,"size":0.001},{"price":11761059.0,"size":0.02},{"price":11765432.0,"size":0.001},{"price":11768000.0,"size":0.01},{"price":11768836.0,"size":0.012},{"price":11770000.0,"size":0.25464896},{"price":11771059.0,"size":0.01755555},{"price":11772000.0,"size":0.002},{"price":11775000.0,"size":0.11593},{"price":11775222.0,"size":0.001657},{"price":11775577.0,"size":0.00013523},{"price":11775800.0,"size":0.001},{"price":11775900.0,"size":0.2},{"price":11775989.0,"size":0.005},{"price":11777000.0,"size":0.5956},{"price":11777777.0,"size":0.0067},{"price":11778541.0,"size":0.001},{"price":11779000.0,"size":0.001},{"price":11779807.0,"size":0.001},{"price":11780000.0,"size":0.77298},{"price":11780800.0,"size":0.1},{"price":11781059.0,"size":0.01},{"price":11781238.0,"size":0.008},{"price":11785000.0,"size":0.055},{"price":11785040.0,"size":0.01}]}}}
{"schema_version":"collector.vnext.raw","schema_contract":null,"schema_contract_version":null,"payload_contract_version":null,"record_type":"market.orderbook.diff","record_id":"collector_main-market-orderbook-diff-000000000061","collector_id":"collector_main","collector_role":"production","host_name":"MAIN-PC","session_id":"collector_main-sess-20260314T201756Z-8e914e93","stream_session_id":"collector_main-stream-bitflyer-board_ws-20260314T201802Z-46763b2e","exchange":"bitflyer","market":"spot","symbol":"BTC_JPY","instrument_id":"bitflyer.spot.BTC_JPY","channel":"board_ws","transport":"websocket","source_event_id":null,"source_sequence":null,"sequence_id":61,"exchange_ts":null,"collector_ts":"2026-03-14T20:18:02Z","ingest_ts":"2026-03-14T20:18:02Z","event_ts":"2026-03-14T20:18:02Z","quality_flags":[],"is_partial":false,"is_reconstructed":false,"confidence_score":1.0,"payload":{"provider":"bitflyer_ws_board","exchange":"bitflyer","transport":"websocket","channel":"lightning_board_BTC_JPY","received_ts":"2026-03-14T20:18:02.131488Z","subscription_id":null,"message_id":null,"source_sequence":null,"raw_message_meta":{"raw_channel":"lightning_board_BTC_JPY","subscription_channel":"lightning_board_BTC_JPY","recv_timeout_sec":10,"ssl_verify":false,"socket_url":"wss://ws.lightstream.bitflyer.com/json-rpc"},"source_payload":{"mid_price":11310087.0,"bids":[{"price":11307507.0,"size":0.04070017},{"price":11305666.0,"size":0.014544},{"price":11303562.0,"size":0.0}],"asks":[{"price":11310000.0,"size":0.0},{"price":11318963.0,"size":0.57592559},{"price":11312150.0,"size":0.0},{"price":11312665.0,"size":0.0}]}}}
{"schema_version":"collector.vnext.raw","schema_contract":null,"schema_contract_version":null,"payload_contract_version":null,"record_type":"market.orderbook.diff","record_id":"collector_main-market-orderbook-diff-000000000065","collector_id":"collector_main","collector_role":"production","host_name":"MAIN-PC","session_id":"collector_main-sess-20260314T201756Z-8e914e93","stream_session_id":"collector_main-stream-bitflyer-board_ws-20260314T201802Z-46763b2e","exchange":"bitflyer","market":"spot","symbol":"BTC_JPY","instrument_id":"bitflyer.spot.BTC_JPY","channel":"board_ws","transport":"websocket","source_event_id":null,"source_sequence":null,"sequence_id":65,"exchange_ts":null,"collector_ts":"2026-03-14T20:18:02Z","ingest_ts":"2026-03-14T20:18:02Z","event_ts":"2026-03-14T20:18:02Z","quality_flags":[],"is_partial":false,"is_reconstructed":false,"confidence_score":1.0,"payload":{"provider":"bitflyer_ws_board","exchange":"bitflyer","transport":"websocket","channel":"lightning_board_BTC_JPY","received_ts":"2026-03-14T20:18:02.258587Z","subscription_id":null,"message_id":null,"source_sequence":null,"raw_message_meta":{"raw_channel":"lightning_board_BTC_JPY","subscription_channel":"lightning_board_BTC_JPY","recv_timeout_sec":10,"ssl_verify":false,"socket_url":"wss://ws.lightstream.bitflyer.com/json-rpc"},"source_payload":{"mid_price":11310085.0,"bids":[{"price":11301402.0,"size":0.0},{"price":11293270.0,"size":0.0}],"asks":[{"price":11312666.0,"size":0.0},{"price":11312720.0,"size":0.0},{"price":11312667.0,"size":0.0},{"price":11312664.0,"size":0.04755253}]}}}
{"schema_version":"collector.vnext.raw","schema_contract":null,"schema_contract_version":null,"payload_contract_version":null,"record_type":"market.orderbook.diff","record_id":"collector_main-market-orderbook-diff-000000000067","collector_id":"collector_main","collector_role":"production","host_name":"MAIN-PC","session_id":"collector_main-sess-20260314T201756Z-8e914e93","stream_session_id":"collector_main-stream-bitflyer-board_ws-20260314T201802Z-46763b2e","exchange":"bitflyer","market":"spot","symbol":"BTC_JPY","instrument_id":"bitflyer.spot.BTC_JPY","channel":"board_ws","transport":"websocket","source_event_id":null,"source_sequence":null,"sequence_id":67,"exchange_ts":null,"collector_ts":"2026-03-14T20:18:02Z","ingest_ts":"2026-03-14T20:18:02Z","event_ts":"2026-03-14T20:18:02Z","quality_flags":[],"is_partial":false,"is_reconstructed":false,"confidence_score":1.0,"payload":{"provider":"bitflyer_ws_board","exchange":"bitflyer","transport":"websocket","channel":"lightning_board_BTC_JPY","received_ts":"2026-03-14T20:18:02.391584Z","subscription_id":null,"message_id":null,"source_sequence":null,"raw_message_meta":{"raw_channel":"lightning_board_BTC_JPY","subscription_channel":"lightning_board_BTC_JPY","recv_timeout_sec":10,"ssl_verify":false,"socket_url":"wss://ws.lightstream.bitflyer.com/json-rpc"},"source_payload":{"mid_price":11310085.0,"bids":[{"price":11307275.0,"size":0.0},{"price":11299950.0,"size":0.0801},{"price":11282137.0,"size":0.002}],"asks":[{"price":11312668.0,"size":0.0},{"price":11320698.0,"size":0.0}]}}}
{"schema_version":"collector.vnext.raw","schema_contract":null,"schema_contract_version":null,"payload_contract_version":null,"record_type":"market.orderbook.diff","record_id":"collector_main-market-orderbook-diff-000000000069","collector_id":"collector_main","collector_role":"production","host_name":"MAIN-PC","session_id":"collector_main-sess-20260314T201756Z-8e914e93","stream_session_id":"collector_main-stream-bitflyer-board_ws-20260314T201802Z-46763b2e","exchange":"bitflyer","market":"spot","symbol":"BTC_JPY","instrument_id":"bitflyer.spot.BTC_JPY","channel":"board_ws","transport":"websocket","source_event_id":null,"source_sequence":null,"sequence_id":69,"exchange_ts":null,"collector_ts":"2026-03-14T20:18:02Z","ingest_ts":"2026-03-14T20:18:02Z","event_ts":"2026-03-14T20:18:02Z","quality_flags":[],"is_partial":false,"is_reconstructed":false,"confidence_score":1.0,"payload":{"provider":"bitflyer_ws_board","exchange":"bitflyer","transport":"websocket","channel":"lightning_board_BTC_JPY","received_ts":"2026-03-14T20:18:02.516802Z","subscription_id":null,"message_id":null,"source_sequence":null,"raw_message_meta":{"raw_channel":"lightning_board_BTC_JPY","subscription_channel":"lightning_board_BTC_JPY","recv_timeout_sec":10,"ssl_verify":false,"socket_url":"wss://ws.lightstream.bitflyer.com/json-rpc"},"source_payload":{"mid_price":11310071.0,"bids":[],"asks":[{"price":11312636.0,"size":0.00908554}]}}}
{"schema_version":"collector.vnext.raw","schema_contract":null,"schema_contract_version":null,"payload_contract_version":null,"record_type":"market.orderbook.diff","record_id":"collector_main-market-orderbook-diff-000000000071","collector_id":"collector_main","collector_role":"production","host_name":"MAIN-PC","session_id":"collector_main-sess-20260314T201756Z-8e914e93","stream_session_id":"collector_main-stream-bitflyer-board_ws-20260314T201802Z-46763b2e","exchange":"bitflyer","market":"spot","symbol":"BTC_JPY","instrument_id":"bitflyer.spot.BTC_JPY","channel":"board_ws","transport":"websocket","source_event_id":null,"source_sequence":null,"sequence_id":71,"exchange_ts":null,"collector_ts":"2026-03-14T20:18:02Z","ingest_ts":"2026-03-14T20:18:02Z","event_ts":"2026-03-14T20:18:02Z","quality_flags":[],"is_partial":false,"is_reconstructed":false,"confidence_score":1.0,"payload":{"provider":"bitflyer_ws_board","exchange":"bitflyer","transport":"websocket","channel":"lightning_board_BTC_JPY","received_ts":"2026-03-14T20:18:02.609720Z","subscription_id":null,"message_id":null,"source_sequence":null,"raw_message_meta":{"raw_channel":"lightning_board_BTC_JPY","subscription_channel":"lightning_board_BTC_JPY","recv_timeout_sec":10,"ssl_verify":false,"socket_url":"wss://ws.lightstream.bitflyer.com/json-rpc"},"source_payload":{"mid_price":11310071.0,"bids":[{"price":11297486.0,"size":0.0},{"price":11306248.0,"size":0.0}],"asks":[{"price":11312667.0,"size":0.0},{"price":11324738.0,"size":0.0},{"price":11313768.0,"size":0.0},{"price":11312664.0,"size":0.0},{"price":11321634.0,"size":0.0551},{"price":11319398.0,"size":0.4199},{"price":11326372.0,"size":0.0050023}]}}}
{"schema_version":"collector.vnext.raw","schema_contract":null,"schema_contract_version":null,"payload_contract_version":null,"record_type":"market.orderbook.diff","record_id":"collector_main-market-orderbook-diff-000000000073","collector_id":"collector_main","collector_role":"production","host_name":"MAIN-PC","session_id":"collector_main-sess-20260314T201756Z-8e914e93","stream_session_id":"collector_main-stream-bitflyer-board_ws-20260314T201802Z-46763b2e","exchange":"bitflyer","market":"spot","symbol":"BTC_JPY","instrument_id":"bitflyer.spot.BTC_JPY","channel":"board_ws","transport":"websocket","source_event_id":null,"source_sequence":null,"sequence_id":73,"exchange_ts":null,"collector_ts":"2026-03-14T20:18:02Z","ingest_ts":"2026-03-14T20:18:02Z","event_ts":"2026-03-14T20:18:02Z","quality_flags":[],"is_partial":false,"is_reconstructed":false,"confidence_score":1.0,"payload":{"provider":"bitflyer_ws_board","exchange":"bitflyer","transport":"websocket","channel":"lightning_board_BTC_JPY","received_ts":"2026-03-14T20:18:02.719603Z","subscription_id":null,"message_id":null,"source_sequence":null,"raw_message_meta":{"raw_channel":"lightning_board_BTC_JPY","subscription_channel":"lightning_board_BTC_JPY","recv_timeout_sec":10,"ssl_verify":false,"socket_url":"wss://ws.lightstream.bitflyer.com/json-rpc"},"source_payload":{"mid_price":11310240.0,"bids":[{"price":11305701.0,"size":0.0176884},{"price":11307845.0,"size":0.1275},{"price":11300232.0,"size":0.0}],"asks":[{"price":11313767.0,"size":0.0},{"price":11316327.0,"size":0.1275}]}}}
{"schema_version":"collector.vnext.raw","schema_contract":null,"schema_contract_version":null,"payload_contract_version":null,"record_type":"market.orderbook.diff","record_id":"collector_main-market-orderbook-diff-000000000075","collector_id":"collector_main","collector_role":"production","host_name":"MAIN-PC","session_id":"collector_main-sess-20260314T201756Z-8e914e93","stream_session_id":"collector_main-stream-bitflyer-board_ws-20260314T201802Z-46763b2e","exchange":"bitflyer","market":"spot","symbol":"BTC_JPY","instrument_id":"bitflyer.spot.BTC_JPY","channel":"board_ws","transport":"websocket","source_event_id":null,"source_sequence":null,"sequence_id":75,"exchange_ts":null,"collector_ts":"2026-03-14T20:18:02Z","ingest_ts":"2026-03-14T20:18:02Z","event_ts":"2026-03-14T20:18:02Z","quality_flags":[],"is_partial":false,"is_reconstructed":false,"confidence_score":1.0,"payload":{"provider":"bitflyer_ws_board","exchange":"bitflyer","transport":"websocket","channel":"lightning_board_BTC_JPY","received_ts":"2026-03-14T20:18:02.844640Z","subscription_id":null,"message_id":null,"source_sequence":null,"raw_message_meta":{"raw_channel":"lightning_board_BTC_JPY","subscription_channel":"lightning_board_BTC_JPY","recv_timeout_sec":10,"ssl_verify":false,"socket_url":"wss://ws.lightstream.bitflyer.com/json-rpc"},"source_payload":{"mid_price":11310240.0,"bids":[{"price":11307548.0,"size":0.0099986},{"price":11298302.0,"size":0.0099986}],"asks":[{"price":11312635.0,"size":0.04768167},{"price":11324816.0,"size":0.269},{"price":11318546.0,"size":0.0},{"price":11316485.0,"size":0.7}]}}}
{"schema_version":"collector.vnext.raw","schema_contract":null,"schema_contract_version":null,"payload_contract_version":null,"record_type":"market.orderbook.diff","record_id":"collector_main-market-orderbook-diff-000000000077","collector_id":"collector_main","collector_role":"production","host_name":"MAIN-PC","session_id":"collector_main-sess-20260314T201756Z-8e914e93","stream_session_id":"collector_main-stream-bitflyer-board_ws-20260314T201802Z-46763b2e","exchange":"bitflyer","market":"spot","symbol":"BTC_JPY","instrument_id":"bitflyer.spot.BTC_JPY","channel":"board_ws","transport":"websocket","source_event_id":null,"source_sequence":null,"sequence_id":77,"exchange_ts":null,"collector_ts":"2026-03-14T20:18:02Z","ingest_ts":"2026-03-14T20:18:02Z","event_ts":"2026-03-14T20:18:02Z","quality_flags":[],"is_partial":false,"is_reconstructed":false,"confidence_score":1.0,"payload":{"provider":"bitflyer_ws_board","exchange":"bitflyer","transport":"websocket","channel":"lightning_board_BTC_JPY","received_ts":"2026-03-14T20:18:02.954458Z","subscription_id":null,"message_id":null,"source_sequence":null,"raw_message_meta":{"raw_channel":"lightning_board_BTC_JPY","subscription_channel":"lightning_board_BTC_JPY","recv_timeout_sec":10,"ssl_verify":false,"socket_url":"wss://ws.lightstream.bitflyer.com/json-rpc"},"source_payload":{"mid_price":11310240.0,"bids":[{"price":11307507.0,"size":0.0},{"price":11307846.0,"size":0.04366674},{"price":11301666.0,"size":0.053}],"asks":[{"price":11324816.0,"size":0.0}]}}}
{"schema_version":"collector.vnext.raw","schema_contract":null,"schema_contract_version":null,"payload_contract_version":null,"record_type":"market.orderbook.diff","record_id":"collector_main-market-orderbook-diff-000000000079","collector_id":"collector_main","collector_role":"production","host_name":"MAIN-PC","session_id":"collector_main-sess-20260314T201756Z-8e914e93","stream_session_id":"collector_main-stream-bitflyer-board_ws-20260314T201802Z-46763b2e","exchange":"bitflyer","market":"spot","symbol":"BTC_JPY","instrument_id":"bitflyer.spot.BTC_JPY","channel":"board_ws","transport":"websocket","source_event_id":null,"source_sequence":null,"sequence_id":79,"exchange_ts":null,"collector_ts":"2026-03-14T20:18:03Z","ingest_ts":"2026-03-14T20:18:03Z","event_ts":"2026-03-14T20:18:03Z","quality_flags":[],"is_partial":false,"is_reconstructed":false,"confidence_score":1.0,"payload":{"provider":"bitflyer_ws_board","exchange":"bitflyer","transport":"websocket","channel":"lightning_board_BTC_JPY","received_ts":"2026-03-14T20:18:03.063074Z","subscription_id":null,"message_id":null,"source_sequence":null,"raw_message_meta":{"raw_channel":"lightning_board_BTC_JPY","subscription_channel":"lightning_board_BTC_JPY","recv_timeout_sec":10,"ssl_verify":false,"socket_url":"wss://ws.lightstream.bitflyer.com/json-rpc"},"source_payload":{"mid_price":11310240.0,"bids":[{"price":11304145.0,"size":0.0}],"asks":[{"price":11326372.0,"size":0.0},{"price":11321641.0,"size":0.0527}]}}}
{"schema_version":"collector.vnext.raw","schema_contract":null,"schema_contract_version":null,"payload_contract_version":null,"record_type":"market.orderbook.diff","record_id":"collector_main-market-orderbook-diff-000000000081","collector_id":"collector_main","collector_role":"production","host_name":"MAIN-PC","session_id":"collector_main-sess-20260314T201756Z-8e914e93","stream_session_id":"collector_main-stream-bitflyer-board_ws-20260314T201802Z-46763b2e","exchange":"bitflyer","market":"spot","symbol":"BTC_JPY","instrument_id":"bitflyer.spot.BTC_JPY","channel":"board_ws","transport":"websocket","source_event_id":null,"source_sequence":null,"sequence_id":81,"exchange_ts":null,"collector_ts":"2026-03-14T20:18:03Z","ingest_ts":"2026-03-14T20:18:03Z","event_ts":"2026-03-14T20:18:03Z","quality_flags":[],"is_partial":false,"is_reconstructed":false,"confidence_score":1.0,"payload":{"provider":"bitflyer_ws_board","exchange":"bitflyer","transport":"websocket","channel":"lightning_board_BTC_JPY","received_ts":"2026-03-14T20:18:03.174081Z","subscription_id":null,"message_id":null,"source_sequence":null,"raw_message_meta":{"raw_channel":"lightning_board_BTC_JPY","subscription_channel":"lightning_board_BTC_JPY","recv_timeout_sec":10,"ssl_verify":false,"socket_url":"wss://ws.lightstream.bitflyer.com/json-rpc"},"source_payload":{"mid_price":11310240.0,"bids":[{"price":11306564.0,"size":0.015564}],"asks":[{"price":11326549.0,"size":0.0039923},{"price":11317028.0,"size":0.015792},{"price":11313768.0,"size":0.2647},{"price":11321641.0,"size":0.0}]}}}
{"schema_version":"collector.vnext.raw","schema_contract":null,"schema_contract_version":null,"payload_contract_version":null,"record_type":"market.orderbook.diff","record_id":"collector_main-market-orderbook-diff-000000000083","collector_id":"collector_main","collector_role":"production","host_name":"MAIN-PC","session_id":"collector_main-sess-20260314T201756Z-8e914e93","stream_session_id":"collector_main-stream-bitflyer-board_ws-20260314T201802Z-46763b2e","exchange":"bitflyer","market":"spot","symbol":"BTC_JPY","instrument_id":"bitflyer.spot.BTC_JPY","channel":"board_ws","transport":"websocket","source_event_id":null,"source_sequence":null,"sequence_id":83,"exchange_ts":null,"collector_ts":"2026-03-14T20:18:03Z","ingest_ts":"2026-03-14T20:18:03Z","event_ts":"2026-03-14T20:18:03Z","quality_flags":[],"is_partial":false,"is_reconstructed":false,"confidence_score":1.0,"payload":{"provider":"bitflyer_ws_board","exchange":"bitflyer","transport":"websocket","channel":"lightning_board_BTC_JPY","received_ts":"2026-03-14T20:18:03.317184Z","subscription_id":null,"message_id":null,"source_sequence":null,"raw_message_meta":{"raw_channel":"lightning_board_BTC_JPY","subscription_channel":"lightning_board_BTC_JPY","recv_timeout_sec":10,"ssl_verify":false,"socket_url":"wss://ws.lightstream.bitflyer.com/json-rpc"},"source_payload":{"mid_price":11310240.0,"bids":[{"price":11301666.0,"size":0.0},{"price":11304593.0,"size":0.0}],"asks":[{"price":11312635.0,"size":0.13498167}]}}}
{"schema_version":"collector.vnext.raw","schema_contract":null,"schema_contract_version":null,"payload_contract_version":null,"record_type":"market.orderbook.diff","record_id":"collector_main-market-orderbook-diff-000000000085","collector_id":"collector_main","collector_role":"production","host_name":"MAIN-PC","session_id":"collector_main-sess-20260314T201756Z-8e914e93","stream_session_id":"collector_main-stream-bitflyer-board_ws-20260314T201802Z-46763b2e","exchange":"bitflyer","market":"spot","symbol":"BTC_JPY","instrument_id":"bitflyer.spot.BTC_JPY","channel":"board_ws","transport":"websocket","source_event_id":null,"source_sequence":null,"sequence_id":85,"exchange_ts":null,"collector_ts":"2026-03-14T20:18:03Z","ingest_ts":"2026-03-14T20:18:03Z","event_ts":"2026-03-14T20:18:03Z","quality_flags":[],"is_partial":false,"is_reconstructed":false,"confidence_score":1.0,"payload":{"provider":"bitflyer_ws_board","exchange":"bitflyer","transport":"websocket","channel":"lightning_board_BTC_JPY","received_ts":"2026-03-14T20:18:03.407591Z","subscription_id":null,"message_id":null,"source_sequence":null,"raw_message_meta":{"raw_channel":"lightning_board_BTC_JPY","subscription_channel":"lightning_board_BTC_JPY","recv_timeout_sec":10,"ssl_verify":false,"socket_url":"wss://ws.lightstream.bitflyer.com/json-rpc"},"source_payload":{"mid_price":11310240.0,"bids":[{"price":11305701.0,"size":0.0}],"asks":[{"price":11321634.0,"size":0.0},{"price":11321652.0,"size":0.0529}]}}}
{"schema_version":"collector.vnext.raw","schema_contract":null,"schema_contract_version":null,"payload_contract_version":null,"record_type":"market.orderbook.diff","record_id":"collector_main-market-orderbook-diff-000000000087","collector_id":"collector_main","collector_role":"production","host_name":"MAIN-PC","session_id":"collector_main-sess-20260314T201756Z-8e914e93","stream_session_id":"collector_main-stream-bitflyer-board_ws-20260314T201802Z-46763b2e","exchange":"bitflyer","market":"spot","symbol":"BTC_JPY","instrument_id":"bitflyer.spot.BTC_JPY","channel":"board_ws","transport":"websocket","source_event_id":null,"source_sequence":null,"sequence_id":87,"exchange_ts":null,"collector_ts":"2026-03-14T20:18:03Z","ingest_ts":"2026-03-14T20:18:03Z","event_ts":"2026-03-14T20:18:03Z","quality_flags":[],"is_partial":false,"is_reconstructed":false,"confidence_score":1.0,"payload":{"provider":"bitflyer_ws_board","exchange":"bitflyer","transport":"websocket","channel":"lightning_board_BTC_JPY","received_ts":"2026-03-14T20:18:03.517456Z","subscription_id":null,"message_id":null,"source_sequence":null,"raw_message_meta":{"raw_channel":"lightning_board_BTC_JPY","subscription_channel":"lightning_board_BTC_JPY","recv_timeout_sec":10,"ssl_verify":false,"socket_url":"wss://ws.lightstream.bitflyer.com/json-rpc"},"source_payload":{"mid_price":11310240.0,"bids":[{"price":11300563.0,"size":0.0531}],"asks":[{"price":11322508.0,"size":0.0050023}]}}}
{"schema_version":"collector.vnext.raw","schema_contract":null,"schema_contract_version":null,"payload_contract_version":null,"record_type":"market.orderbook.diff","record_id":"collector_main-market-orderbook-diff-000000000089","collector_id":"collector_main","collector_role":"production","host_name":"MAIN-PC","session_id":"collector_main-sess-20260314T201756Z-8e914e93","stream_session_id":"collector_main-stream-bitflyer-board_ws-20260314T201802Z-46763b2e","exchange":"bitflyer","market":"spot","symbol":"BTC_JPY","instrument_id":"bitflyer.spot.BTC_JPY","channel":"board_ws","transport":"websocket","source_event_id":null,"source_sequence":null,"sequence_id":89,"exchange_ts":null,"collector_ts":"2026-03-14T20:18:03Z","ingest_ts":"2026-03-14T20:18:03Z","event_ts":"2026-03-14T20:18:03Z","quality_flags":[],"is_partial":false,"is_reconstructed":false,"confidence_score":1.0,"payload":{"provider":"bitflyer_ws_board","exchange":"bitflyer","transport":"websocket","channel":"lightning_board_BTC_JPY","received_ts":"2026-03-14T20:18:03.641590Z","subscription_id":null,"message_id":null,"source_sequence":null,"raw_message_meta":{"raw_channel":"lightning_board_BTC_JPY","subscription_channel":"lightning_board_BTC_JPY","recv_timeout_sec":10,"ssl_verify":false,"socket_url":"wss://ws.lightstream.bitflyer.com/json-rpc"},"source_payload":{"mid_price":11310240.0,"bids":[{"price":11304594.0,"size":0.0}],"asks":[{"price":11316485.0,"size":0.0}]}}}
{"schema_version":"collector.vnext.raw","schema_contract":null,"schema_contract_version":null,"payload_contract_version":null,"record_type":"market.orderbook.diff","record_id":"collector_main-market-orderbook-diff-000000000091","collector_id":"collector_main","collector_role":"production","host_name":"MAIN-PC","session_id":"collector_main-sess-20260314T201756Z-8e914e93","stream_session_id":"collector_main-stream-bitflyer-board_ws-20260314T201802Z-46763b2e","exchange":"bitflyer","market":"spot","symbol":"BTC_JPY","instrument_id":"bitflyer.spot.BTC_JPY","channel":"board_ws","transport":"websocket","source_event_id":null,"source_sequence":null,"sequence_id":91,"exchange_ts":null,"collector_ts":"2026-03-14T20:18:03Z","ingest_ts":"2026-03-14T20:18:03Z","event_ts":"2026-03-14T20:18:03Z","quality_flags":[],"is_partial":false,"is_reconstructed":false,"confidence_score":1.0,"payload":{"provider":"bitflyer_ws_board","exchange":"bitflyer","transport":"websocket","channel":"lightning_board_BTC_JPY","received_ts":"2026-03-14T20:18:03.767595Z","subscription_id":null,"message_id":null,"source_sequence":null,"raw_message_meta":{"raw_channel":"lightning_board_BTC_JPY","subscription_channel":"lightning_board_BTC_JPY","recv_timeout_sec":10,"ssl_verify":false,"socket_url":"wss://ws.lightstream.bitflyer.com/json-rpc"},"source_payload":{"mid_price":11310240.0,"bids":[{"price":11277614.0,"size":0.002},{"price":11304146.0,"size":0.0}],"asks":[]}}}
{"schema_version":"collector.vnext.raw","schema_contract":null,"schema_contract_version":null,"payload_contract_version":null,"record_type":"market.orderbook.diff","record_id":"collector_main-market-orderbook-diff-000000000093","collector_id":"collector_main","collector_role":"production","host_name":"MAIN-PC","session_id":"collector_main-sess-20260314T201756Z-8e914e93","stream_session_id":"collector_main-stream-bitflyer-board_ws-20260314T201802Z-46763b2e","exchange":"bitflyer","market":"spot","symbol":"BTC_JPY","instrument_id":"bitflyer.spot.BTC_JPY","channel":"board_ws","transport":"websocket","source_event_id":null,"source_sequence":null,"sequence_id":93,"exchange_ts":null,"collector_ts":"2026-03-14T20:18:03Z","ingest_ts":"2026-03-14T20:18:03Z","event_ts":"2026-03-14T20:18:03Z","quality_flags":[],"is_partial":false,"is_reconstructed":false,"confidence_score":1.0,"payload":{"provider":"bitflyer_ws_board","exchange":"bitflyer","transport":"websocket","channel":"lightning_board_BTC_JPY","received_ts":"2026-03-14T20:18:03.900689Z","subscription_id":null,"message_id":null,"source_sequence":null,"raw_message_meta":{"raw_channel":"lightning_board_BTC_JPY","subscription_channel":"lightning_board_BTC_JPY","recv_timeout_sec":10,"ssl_verify":false,"socket_url":"wss://ws.lightstream.bitflyer.com/json-rpc"},"source_payload":{"mid_price":11310240.0,"bids":[],"asks":[{"price":11312636.0,"size":0.0}]}}}
{"schema_version":"collector.vnext.raw","schema_contract":null,"schema_contract_version":null,"payload_contract_version":null,"record_type":"market.orderbook.diff","record_id":"collector_main-market-orderbook-diff-000000000095","collector_id":"collector_main","collector_role":"production","host_name":"MAIN-PC","session_id":"collector_main-sess-20260314T201756Z-8e914e93","stream_session_id":"collector_main-stream-bitflyer-board_ws-20260314T201802Z-46763b2e","exchange":"bitflyer","market":"spot","symbol":"BTC_JPY","instrument_id":"bitflyer.spot.BTC_JPY","channel":"board_ws","transport":"websocket","source_event_id":null,"source_sequence":null,"sequence_id":95,"exchange_ts":null,"collector_ts":"2026-03-14T20:18:04Z","ingest_ts":"2026-03-14T20:18:04Z","event_ts":"2026-03-14T20:18:04Z","quality_flags":[],"is_partial":false,"is_reconstructed":false,"confidence_score":1.0,"payload":{"provider":"bitflyer_ws_board","exchange":"bitflyer","transport":"websocket","channel":"lightning_board_BTC_JPY","received_ts":"2026-03-14T20:18:04.021273Z","subscription_id":null,"message_id":null,"source_sequence":null,"raw_message_meta":{"raw_channel":"lightning_board_BTC_JPY","subscription_channel":"lightning_board_BTC_JPY","recv_timeout_sec":10,"ssl_verify":false,"socket_url":"wss://ws.lightstream.bitflyer.com/json-rpc"},"source_payload":{"mid_price":11310240.0,"bids":[],"asks":[{"price":11312635.0,"size":0.0873}]}}}
{"schema_version":"collector.vnext.raw","schema_contract":null,"schema_contract_version":null,"payload_contract_version":null,"record_type":"market.orderbook.diff","record_id":"collector_main-market-orderbook-diff-000000000097","collector_id":"collector_main","collector_role":"production","host_name":"MAIN-PC","session_id":"collector_main-sess-20260314T201756Z-8e914e93","stream_session_id":"collector_main-stream-bitflyer-board_ws-20260314T201802Z-46763b2e","exchange":"bitflyer","market":"spot","symbol":"BTC_JPY","instrument_id":"bitflyer.spot.BTC_JPY","channel":"board_ws","transport":"websocket","source_event_id":null,"source_sequence":null,"sequence_id":97,"exchange_ts":null,"collector_ts":"2026-03-14T20:18:04Z","ingest_ts":"2026-03-14T20:18:04Z","event_ts":"2026-03-14T20:18:04Z","quality_flags":[],"is_partial":false,"is_reconstructed":false,"confidence_score":1.0,"payload":{"provider":"bitflyer_ws_board","exchange":"bitflyer","transport":"websocket","channel":"lightning_board_BTC_JPY","received_ts":"2026-03-14T20:18:04.134436Z","subscription_id":null,"message_id":null,"source_sequence":null,"raw_message_meta":{"raw_channel":"lightning_board_BTC_JPY","subscription_channel":"lightning_board_BTC_JPY","recv_timeout_sec":10,"ssl_verify":false,"socket_url":"wss://ws.lightstream.bitflyer.com/json-rpc"},"source_payload":{"mid_price":11310240.0,"bids":[],"asks":[{"price":11313231.0,"size":0.00908554},{"price":11313767.0,"size":0.04843832}]}}}
{"schema_version":"collector.vnext.raw","schema_contract":null,"schema_contract_version":null,"payload_contract_version":null,"record_type":"market.orderbook.diff","record_id":"collector_main-market-orderbook-diff-000000000099","collector_id":"collector_main","collector_role":"production","host_name":"MAIN-PC","session_id":"collector_main-sess-20260314T201756Z-8e914e93","stream_session_id":"collector_main-stream-bitflyer-board_ws-20260314T201802Z-46763b2e","exchange":"bitflyer","market":"spot","symbol":"BTC_JPY","instrument_id":"bitflyer.spot.BTC_JPY","channel":"board_ws","transport":"websocket","source_event_id":null,"source_sequence":null,"sequence_id":99,"exchange_ts":null,"collector_ts":"2026-03-14T20:18:04Z","ingest_ts":"2026-03-14T20:18:04Z","event_ts":"2026-03-14T20:18:04Z","quality_flags":[],"is_partial":false,"is_reconstructed":false,"confidence_score":1.0,"payload":{"provider":"bitflyer_ws_board","exchange":"bitflyer","transport":"websocket","channel":"lightning_board_BTC_JPY","received_ts":"2026-03-14T20:18:04.238662Z","subscription_id":null,"message_id":null,"source_sequence":null,"raw_message_meta":{"raw_channel":"lightning_board_BTC_JPY","subscription_channel":"lightning_board_BTC_JPY","recv_timeout_sec":10,"ssl_verify":false,"socket_url":"wss://ws.lightstream.bitflyer.com/json-rpc"},"source_payload":{"mid_price":11310240.0,"bids":[{"price":11297568.0,"size":0.0},{"price":11304585.0,"size":0.01},{"price":11273657.0,"size":0.002}],"asks":[{"price":11313767.0,"size":0.0},{"price":11314407.0,"size":0.0},{"price":11312634.0,"size":0.04823326}]}}}
{"schema_version":"collector.vnext.raw","schema_contract":null,"schema_contract_version":null,"payload_contract_version":null,"record_type":"market.orderbook.diff","record_id":"collector_main-market-orderbook-diff-000000000101","collector_id":"collector_main","collector_role":"production","host_name":"MAIN-PC","session_id":"collector_main-sess-20260314T201756Z-8e914e93","stream_session_id":"collector_main-stream-bitflyer-board_ws-20260314T201802Z-46763b2e","exchange":"bitflyer","market":"spot","symbol":"BTC_JPY","instrument_id":"bitflyer.spot.BTC_JPY","channel":"board_ws","transport":"websocket","source_event_id":null,"source_sequence":null,"sequence_id":101,"exchange_ts":null,"collector_ts":"2026-03-14T20:18:04Z","ingest_ts":"2026-03-14T20:18:04Z","event_ts":"2026-03-14T20:18:04Z","quality_flags":[],"is_partial":false,"is_reconstructed":false,"confidence_score":1.0,"payload":{"provider":"bitflyer_ws_board","exchange":"bitflyer","transport":"websocket","channel":"lightning_board_BTC_JPY","received_ts":"2026-03-14T20:18:04.457266Z","subscription_id":null,"message_id":null,"source_sequence":null,"raw_message_meta":{"raw_channel":"lightning_board_BTC_JPY","subscription_channel":"lightning_board_BTC_JPY","recv_timeout_sec":10,"ssl_verify":false,"socket_url":"wss://ws.lightstream.bitflyer.com/json-rpc"},"source_payload":{"mid_price":11310240.0,"bids":[],"asks":[{"price":11321652.0,"size":0.0}]}}}
{"schema_version":"collector.vnext.raw","schema_contract":null,"schema_contract_version":null,"payload_contract_version":null,"record_type":"market.orderbook.diff","record_id":"collector_main-market-orderbook-diff-000000000103","collector_id":"collector_main","collector_role":"production","host_name":"MAIN-PC","session_id":"collector_main-sess-20260314T201756Z-8e914e93","stream_session_id":"collector_main-stream-bitflyer-board_ws-20260314T201802Z-46763b2e","exchange":"bitflyer","market":"spot","symbol":"BTC_JPY","instrument_id":"bitflyer.spot.BTC_JPY","channel":"board_ws","transport":"websocket","source_event_id":null,"source_sequence":null,"sequence_id":103,"exchange_ts":null,"collector_ts":"2026-03-14T20:18:04Z","ingest_ts":"2026-03-14T20:18:04Z","event_ts":"2026-03-14T20:18:04Z","quality_flags":[],"is_partial":false,"is_reconstructed":false,"confidence_score":1.0,"payload":{"provider":"bitflyer_ws_board","exchange":"bitflyer","transport":"websocket","channel":"lightning_board_BTC_JPY","received_ts":"2026-03-14T20:18:04.673660Z","subscription_id":null,"message_id":null,"source_sequence":null,"raw_message_meta":{"raw_channel":"lightning_board_BTC_JPY","subscription_channel":"lightning_board_BTC_JPY","recv_timeout_sec":10,"ssl_verify":false,"socket_url":"wss://ws.lightstream.bitflyer.com/json-rpc"},"source_payload":{"mid_price":11310240.0,"bids":[],"asks":[{"price":11321874.0,"size":0.0527}]}}}
{"schema_version":"collector.vnext.raw","schema_contract":null,"schema_contract_version":null,"payload_contract_version":null,"record_type":"market.orderbook.diff","record_id":"collector_main-market-orderbook-diff-000000000105","collector_id":"collector_main","collector_role":"production","host_name":"MAIN-PC","session_id":"collector_main-sess-20260314T201756Z-8e914e93","stream_session_id":"collector_main-stream-bitflyer-board_ws-20260314T201802Z-46763b2e","exchange":"bitflyer","market":"spot","symbol":"BTC_JPY","instrument_id":"bitflyer.spot.BTC_JPY","channel":"board_ws","transport":"websocket","source_event_id":null,"source_sequence":null,"sequence_id":105,"exchange_ts":null,"collector_ts":"2026-03-14T20:18:05Z","ingest_ts":"2026-03-14T20:18:05Z","event_ts":"2026-03-14T20:18:05Z","quality_flags":[],"is_partial":false,"is_reconstructed":false,"confidence_score":1.0,"payload":{"provider":"bitflyer_ws_board","exchange":"bitflyer","transport":"websocket","channel":"lightning_board_BTC_JPY","received_ts":"2026-03-14T20:18:05.097283Z","subscription_id":null,"message_id":null,"source_sequence":null,"raw_message_meta":{"raw_channel":"lightning_board_BTC_JPY","subscription_channel":"lightning_board_BTC_JPY","recv_timeout_sec":10,"ssl_verify":false,"socket_url":"wss://ws.lightstream.bitflyer.com/json-rpc"},"source_payload":{"mid_price":11310240.0,"bids":[{"price":11273091.0,"size":0.002}],"asks":[]}}}
{"schema_version":"collector.vnext.raw","schema_contract":null,"schema_contract_version":null,"payload_contract_version":null,"record_type":"market.orderbook.diff","record_id":"collector_main-market-orderbook-diff-000000000107","collector_id":"collector_main","collector_role":"production","host_name":"MAIN-PC","session_id":"collector_main-sess-20260314T201756Z-8e914e93","stream_session_id":"collector_main-stream-bitflyer-board_ws-20260314T201802Z-46763b2e","exchange":"bitflyer","market":"spot","symbol":"BTC_JPY","instrument_id":"bitflyer.spot.BTC_JPY","channel":"board_ws","transport":"websocket","source_event_id":null,"source_sequence":null,"sequence_id":107,"exchange_ts":null,"collector_ts":"2026-03-14T20:18:06Z","ingest_ts":"2026-03-14T20:18:06Z","event_ts":"2026-03-14T20:18:06Z","quality_flags":[],"is_partial":false,"is_reconstructed":false,"confidence_score":1.0,"payload":{"provider":"bitflyer_ws_board","exchange":"bitflyer","transport":"websocket","channel":"lightning_board_BTC_JPY","received_ts":"2026-03-14T20:18:06.000739Z","subscription_id":null,"message_id":null,"source_sequence":null,"raw_message_meta":{"raw_channel":"lightning_board_BTC_JPY","subscription_channel":"lightning_board_BTC_JPY","recv_timeout_sec":10,"ssl_verify":false,"socket_url":"wss://ws.lightstream.bitflyer.com/json-rpc"},"source_payload":{"mid_price":11310240.0,"bids":[],"asks":[{"price":12000000.0,"size":4.62370915}]}}}
{"schema_version":"collector.vnext.raw","schema_contract":null,"schema_contract_version":null,"payload_contract_version":null,"record_type":"market.orderbook.diff","record_id":"collector_main-market-orderbook-diff-000000000109","collector_id":"collector_main","collector_role":"production","host_name":"MAIN-PC","session_id":"collector_main-sess-20260314T201756Z-8e914e93","stream_session_id":"collector_main-stream-bitflyer-board_ws-20260314T201802Z-46763b2e","exchange":"bitflyer","market":"spot","symbol":"BTC_JPY","instrument_id":"bitflyer.spot.BTC_JPY","channel":"board_ws","transport":"websocket","source_event_id":null,"source_sequence":null,"sequence_id":109,"exchange_ts":null,"collector_ts":"2026-03-14T20:18:06Z","ingest_ts":"2026-03-14T20:18:06Z","event_ts":"2026-03-14T20:18:06Z","quality_flags":[],"is_partial":false,"is_reconstructed":false,"confidence_score":1.0,"payload":{"provider":"bitflyer_ws_board","exchange":"bitflyer","transport":"websocket","channel":"lightning_board_BTC_JPY","received_ts":"2026-03-14T20:18:06.141832Z","subscription_id":null,"message_id":null,"source_sequence":null,"raw_message_meta":{"raw_channel":"lightning_board_BTC_JPY","subscription_channel":"lightning_board_BTC_JPY","recv_timeout_sec":10,"ssl_verify":false,"socket_url":"wss://ws.lightstream.bitflyer.com/json-rpc"},"source_payload":{"mid_price":11310240.0,"bids":[{"price":11268568.0,"size":0.002}],"asks":[]}}}
{"schema_version":"collector.vnext.raw","schema_contract":null,"schema_contract_version":null,"payload_contract_version":null,"record_type":"market.orderbook.diff","record_id":"collector_main-market-orderbook-diff-000000000111","collector_id":"collector_main","collector_role":"production","host_name":"MAIN-PC","session_id":"collector_main-sess-20260314T201756Z-8e914e93","stream_session_id":"collector_main-stream-bitflyer-board_ws-20260314T201802Z-46763b2e","exchange":"bitflyer","market":"spot","symbol":"BTC_JPY","instrument_id":"bitflyer.spot.BTC_JPY","channel":"board_ws","transport":"websocket","source_event_id":null,"source_sequence":null,"sequence_id":111,"exchange_ts":null,"collector_ts":"2026-03-14T20:18:06Z","ingest_ts":"2026-03-14T20:18:06Z","event_ts":"2026-03-14T20:18:06Z","quality_flags":[],"is_partial":false,"is_reconstructed":false,"confidence_score":1.0,"payload":{"provider":"bitflyer_ws_board","exchange":"bitflyer","transport":"websocket","channel":"lightning_board_BTC_JPY","received_ts":"2026-03-14T20:18:06.455042Z","subscription_id":null,"message_id":null,"source_sequence":null,"raw_message_meta":{"raw_channel":"lightning_board_BTC_JPY","subscription_channel":"lightning_board_BTC_JPY","recv_timeout_sec":10,"ssl_verify":false,"socket_url":"wss://ws.lightstream.bitflyer.com/json-rpc"},"source_payload":{"mid_price":11310240.0,"bids":[{"price":11270265.0,"size":0.002},{"price":11307548.0,"size":0.0}],"asks":[]}}}
{"schema_version":"collector.vnext.raw","schema_contract":null,"schema_contract_version":null,"payload_contract_version":null,"record_type":"market.orderbook.snapshot","record_id":"collector_main-market-orderbook-snapshot-000000000113","collector_id":"collector_main","collector_role":"production","host_name":"MAIN-PC","session_id":"collector_main-sess-20260314T201756Z-8e914e93","stream_session_id":"collector_main-stream-bitflyer-board_ws-20260314T201802Z-46763b2e","exchange":"bitflyer","market":"spot","symbol":"BTC_JPY","instrument_id":"bitflyer.spot.BTC_JPY","channel":"board_ws","transport":"websocket","source_event_id":null,"source_sequence":null,"sequence_id":113,"exchange_ts":null,"collector_ts":"2026-03-14T20:18:06Z","ingest_ts":"2026-03-14T20:18:06Z","event_ts":"2026-03-14T20:18:06Z","quality_flags":[],"is_partial":false,"is_reconstructed":false,"confidence_score":1.0,"payload":{"provider":"bitflyer_ws_board_snapshot","exchange":"bitflyer","transport":"websocket","channel":"lightning_board_snapshot_BTC_JPY","received_ts":"2026-03-14T20:18:06.518168Z","subscription_id":null,"message_id":null,"source_sequence":null,"raw_message_meta":{"raw_channel":"lightning_board_snapshot_BTC_JPY","subscription_channel":"lightning_board_snapshot_BTC_JPY","recv_timeout_sec":10,"ssl_verify":false,"socket_url":"wss://ws.lightstream.bitflyer.com/json-rpc"},"source_payload":{"mid_price":11310240.0,"bids":[{"price":11307846.0,"size":0.04366674},{"price":11307845.0,"size":0.1275},{"price":11307506.0,"size":0.1275},{"price":11306564.0,"size":0.015564},{"price":11305666.0,"size":0.014544},{"price":11305313.0,"size":0.014424},{"price":11304986.0,"size":0.015156},{"price":11304585.0,"size":0.01},{"price":11304182.0,"size":0.02},{"price":11303617.0,"size":0.02},{"price":11302157.0,"size":0.2},{"price":11301012.0,"size":0.5},{"price":11300563.0,"size":0.0531},{"price":11300171.0,"size":0.0536544},{"price":11299950.0,"size":0.0801},{"price":11298853.0,"size":2.97346673},{"price":11298751.0,"size":0.5},{"price":11298302.0,"size":0.0099986},{"price":11297444.0,"size":0.1},{"price":11296217.0,"size":0.001},{"price":11287379.0,"size":0.2999171},{"price":11287378.0,"size":1.50015},{"price":11286875.0,"size":0.6},{"price":11286651.0,"size":0.98403398},{"price":11286086.0,"size":0.273},{"price":11285569.0,"size":1.484},{"price":11283324.0,"size":0.3118},{"price":11282137.0,"size":0.002},{"price":11280562.0,"size":0.3089},{"price":11280441.0,"size":0.002},{"price":11280205.0,"size":0.001},{"price":11279435.0,"size":0.17274976},{"price":11279282.0,"size":0.0015},{"price":11277800.0,"size":0.2689},{"price":11277748.0,"size":0.0966561},{"price":11277614.0,"size":0.002},{"price":11277602.0,"size":0.005},{"price":11277049.0,"size":0.002},{"price":11275102.0,"size":0.01},{"price":11275000.0,"size":0.001},{"price":11274588.0,"size":0.0047},{"price":11273657.0,"size":0.002},{"price":11273091.0,"size":0.002},{"price":11271000.0,"size":0.003},{"price":11270766.0,"size":0.6},{"price":11270265.0,"size":0.002},{"price":11270000.0,"size":0.106},{"price":11268871.0,"size":0.281},{"price":11268568.0,"size":0.002},{"price":11268411.0,"size":0.01},{"price":11266666.0,"size":0.04},{"price":11265000.0,"size":0.02},{"price":11263999.0,"size":1.966},{"price":11263000.0,"size":0.006},{"price":11262564.0,"size":0.0015},{"price":11260000.0,"size":0.3565},{"price":11257537.0,"size":0.001},{"price":11257000.0,"size":0.001},{"price":11255200.0,"size":0.001},{"price":11255115.0,"size":0.00377},{"price":11253628.0,"size":2.036},{"price":11253000.0,"size":0.03189},{"price":11251000.0,"size":0.0131},{"price":11250250.0,"size":0.00105},{"price":11250200.0,"size":0.001},{"price":11250100.0,"size":0.015},{"price":11250005.0,"size":0.001},{"price":11250001.0,"size":0.00104},{"price":11250000.0,"size":0.76834},{"price":11246544.0,"size":0.0015},{"price":11246203.0,"size":0.001},{"price":11245141.0,"size":0.0031},{"price":11245000.0,"size":0.05},{"price":11244444.0,"size":0.04},{"price":11244243.0,"size":0.01},{"price":11240200.0,"size":0.001},{"price":11240000.0,"size":0.007304},{"price":11236190.0,"size":0.01},{"price":11235200.0,"size":0.001},{"price":11234869.0,"size":0.001},{"price":11232000.0,"size":0.089},{"price":11231243.0,"size":0.01},{"price":11231000.0,"size":0.105},{"price":11230200.0,"size":0.001},{"price":11230000.0,"size":0.0308},{"price":11228423.0,"size":1.951},{"price":11224500.0,"size":0.06},{"price":11224355.0,"size":0.0015},{"price":11223968.0,"size":0.001},{"price":11223535.0,"size":0.001},{"price":11223344.0,"size":0.01},{"price":11223000.0,"size":0.1},{"price":11222222.0,"size":0.092525},{"price":11221459.0,"size":0.1393},{"price":11221120.0,"size":0.011},{"price":11220200.0,"size":0.001},{"price":11220001.0,"size":0.004457},{"price":11220000.0,"size":0.321},{"price":11219517.0,"size":0.01},{"price":11219000.0,"size":0.1},{"price":11218079.0,"size":1.79},{"price":11215200.0,"size":0.001},{"price":11215000.0,"size":0.02},{"price":11212358.0,"size":1.2},{"price":11212201.0,"size":0.001},{"price":11211800.0,"size":0.001},{"price":11211111.0,"size":0.06},{"price":11210200.0,"size":0.001},{"price":11210000.0,"size":0.10622},{"price":11208032.0,"size":0.01},{"price":11207755.0,"size":0.0015},{"price":11206000.0,"size":0.09015},{"price":11205200.0,"size":0.001},{"price":11204578.0,"size":0.002},{"price":11203931.0,"size":1.0},{"price":11201000.0,"size":0.01},{"price":11200867.0,"size":0.001},{"price":11200800.0,"size":0.05},{"price":11200425.0,"size":0.1},{"price":11200200.0,"size":0.001},{"price":11200198.0,"size":0.003},{"price":11200150.0,"size":0.002},{"price":11200002.0,"size":0.001},{"price":11200001.0,"size":0.01104},{"price":11200000.0,"size":1.35988728},{"price":11198508.0,"size":0.05},{"price":11198243.0,"size":0.01},{"price":11197134.0,"size":2.0},{"price":11197000.0,"size":0.0085},{"price":11195692.0,"size":0.0015},{"price":11194090.0,"size":0.03},{"price":11190770.0,"size":0.0309},{"price":11190000.0,"size":0.0010016},{"price":11189555.0,"size":0.5},{"price":11189533.0,"size":0.001},{"price":11188629.0,"size":0.01},{"price":11188382.0,"size":0.001},{"price":11185000.0,"size":0.0085},{"price":11180043.0,"size":0.972},{"price":11180000.0,"size":0.23215},{"price":11178973.0,"size":0.0015},{"price":11178199.0,"size":0.001},{"price":11170000.0,"size":0.001},{"price":11169662.0,"size":0.01},{"price":11169593.0,"size":0.001},{"price":11169243.0,"size":0.01},{"price":11166865.0,"size":0.001},{"price":11164029.0,"size":0.001},{"price":11160854.0,"size":0.1},{"price":11160000.0,"size":0.02376},{"price":11156269.0,"size":0.01},{"price":11155531.0,"size":0.001},{"price":11155377.0,"size":0.00636009},{"price":11153999.0,"size":0.00101},{"price":11151000.0,"size":0.001},{"price":11150250.0,"size":0.00175},{"price":11150005.0,"size":0.001},{"price":11150001.0,"size":0.00104},{"price":11150000.0,"size":0.6398956},{"price":11148000.0,"size":0.08963},{"price":11144197.0,"size":0.001},{"price":11144000.0,"size":0.0897},{"price":11140000.0,"size":0.2},{"price":11136243.0,"size":0.01},{"price":11136155.0,"size":0.02},{"price":11135869.0,"size":0.1},{"price":11130000.0,"size":0.116},{"price":11129979.0,"size":0.0053908},{"price":11126388.0,"size":0.02},{"price":11124900.0,"size":0.00133},{"price":11121090.0,"size":0.1},{"price":11120000.0,"size":0.0033},{"price":11118078.0,"size":0.01},{"price":11111800.0,"size":0.001},{"price":11111111.0,"size":0.2919257},{"price":11111000.0,"size":0.003},{"price":11110594.0,"size":0.001},{"price":11110000.0,"size":0.056937},{"price":11109662.0,"size":0.01},{"price":11108008.0,"size":0.01},{"price":11106000.0,"size":0.2},{"price":11105000.0,"size":0.02},{"price":11101297.0,"size":0.001},{"price":11100005.0,"size":0.001},{"price":11100001.0,"size":0.01104},{"price":11100000.0,"size":2.7475049},{"price":11099141.0,"size":0.01},{"price":11096243.0,"size":0.01},{"price":11094090.0,"size":0.01},{"price":11088888.0,"size":0.001},{"price":11085245.0,"size":0.001},{"price":11080200.0,"size":0.001},{"price":11080000.0,"size":0.0223},{"price":11075100.0,"size":0.003},{"price":11071558.0,"size":1.0},{"price":11070200.0,"size":0.001},{"price":11070000.0,"size":0.0902},{"price":11065200.0,"size":0.001},{"price":11064370.0,"size":0.00497091},{"price":11060200.0,"size":0.001},{"price":11060000.0,"size":0.145},{"price":11059689.0,"size":0.009},{"price":11056428.0,"size":0.002},{"price":11055500.0,"size":0.02},{"price":11055200.0,"size":0.001},{"price":11055100.0,"size":0.003},{"price":11050200.0,"size":0.001},{"price":11050005.0,"size":0.001},{"price":11050002.0,"size":0.001},{"price":11050001.0,"size":0.00104},{"price":11050000.0,"size":0.43176147},{"price":11046420.0,"size":0.2},{"price":11044243.0,"size":0.01},{"price":11041380.0,"size":0.01},{"price":11040200.0,"size":0.001},{"price":11040000.0,"size":0.00877181},{"price":11035865.0,"size":0.1},{"price":11035200.0,"size":0.001},{"price":11035000.0,"size":0.0013},{"price":11030200.0,"size":0.001},{"price":11030000.0,"size":0.025},{"price":11025500.0,"size":0.009531},{"price":11025200.0,"size":0.001},{"price":11025000.0,"size":0.71497},{"price":11020772.0,"size":0.014},{"price":11020200.0,"size":0.002},{"price":11020000.0,"size":0.005},{"price":11015200.0,"size":0.001},{"price":11012000.0,"size":0.1},{"price":11011800.0,"size":0.001},{"price":11011000.0,"size":0.001},{"price":11010200.0,"size":0.001},{"price":11010000.0,"size":0.347},{"price":11007277.0,"size":0.01},{"price":11006000.0,"size":0.2},{"price":11005200.0,"size":0.001},{"price":11004890.0,"size":0.001535},{"price":11003000.0,"size":0.0155},{"price":11001000.0,"size":0.013},{"price":11000500.0,"size":0.05117658},{"price":11000200.0,"size":0.001},{"price":11000002.0,"size":0.004},{"price":11000001.0,"size":0.02604},{"price":11000000.0,"size":5.47323365},{"price":10999999.0,"size":0.003},{"price":10999000.0,"size":0.001},{"price":10996855.0,"size":0.0011},{"price":10995200.0,"size":0.001},{"price":10994499.0,"size":0.00169176},{"price":10990200.0,"size":0.001},{"price":10990000.0,"size":0.10219},{"price":10989001.0,"size":0.00197},{"price":10988999.0,"size":0.001},{"price":10988324.0,"size":0.002},{"price":10987654.0,"size":0.001},{"price":10985200.0,"size":0.001},{"price":10985150.0,"size":0.01},{"price":10980500.0,"size":0.005},{"price":10980200.0,"size":0.001},{"price":10980002.0,"size":0.4},{"price":10980000.0,"size":0.028},{"price":10975200.0,"size":0.001},{"price":10975000.0,"size":0.1},{"price":10971261.0,"size":0.001},{"price":10971243.0,"size":0.01},{"price":10970375.0,"size":1.9},{"price":10970200.0,"size":0.001},{"price":10970000.0,"size":0.09304},{"price":10966600.0,"size":0.001003},{"price":10965200.0,"size":0.001},{"price":10960200.0,"size":0.001},{"price":10960000.0,"size":0.0083},{"price":10956673.0,"size":0.01},{"price":10955200.0,"size":0.001},{"price":10954950.0,"size":0.001},{"price":10950500.0,"size":0.005},{"price":10950001.0,"size":0.00204},{"price":10950000.0,"size":0.5485028},{"price":10949550.0,"size":0.01870657},{"price":10949172.0,"size":0.1},{"price":10948000.0,"size":0.1},{"price":10945243.0,"size":0.01},{"price":10941000.0,"size":0.001},{"price":10940402.0,"size":0.001},{"price":10940200.0,"size":0.001},{"price":10940000.0,"size":0.331},{"price":10938243.0,"size":0.01},{"price":10936200.0,"size":0.00137},{"price":10935200.0,"size":0.001},{"price":10930200.0,"size":0.002},{"price":10930000.0,"size":0.0193},{"price":10925200.0,"size":0.002},{"price":10924451.0,"size":0.0012},{"price":10920509.0,"size":0.01},{"price":10920200.0,"size":0.002},{"price":10920000.0,"size":0.52},{"price":10915200.0,"size":0.001},{"price":10914000.0,"size":0.005},{"price":10911800.0,"size":0.001},{"price":10910500.0,"size":0.005}],"asks":[{"price":11312634.0,"size":0.04823326},{"price":11312635.0,"size":0.0873},{"price":11313231.0,"size":0.00908554},{"price":11313768.0,"size":0.2647},{"price":11313957.0,"size":0.014772},{"price":11316327.0,"size":0.1275},{"price":11316530.0,"size":0.2806},{"price":11317028.0,"size":0.015792},{"price":11317135.0,"size":0.0536544},{"price":11318050.0,"size":0.002},{"price":11318640.0,"size":0.01},{"price":11318963.0,"size":0.57592559},{"price":11319292.0,"size":0.2857},{"price":11319398.0,"size":0.4199},{"price":11320000.0,"size":0.02},{"price":11321874.0,"size":0.0527},{"price":11322000.0,"size":0.005},{"price":11322054.0,"size":0.2675},{"price":11322508.0,"size":0.0050023},{"price":11323556.0,"size":1.189881},{"price":11323581.0,"size":1.189881},{"price":11326549.0,"size":0.0039923},{"price":11328050.0,"size":0.002},{"price":11329436.0,"size":0.0015},{"price":11331059.0,"size":0.001},{"price":11333064.0,"size":1.489},{"price":11340000.0,"size":0.13586406},{"price":11340647.0,"size":0.001},{"price":11342956.0,"size":1.60199848},{"price":11342957.0,"size":0.01},{"price":11343223.0,"size":1.928},{"price":11346154.0,"size":0.0015},{"price":11348000.0,"size":0.1999},{"price":11349700.0,"size":0.001},{"price":11350000.0,"size":0.022},{"price":11353877.0,"size":0.001},{"price":11354939.0,"size":0.01},{"price":11355555.0,"size":0.001},{"price":11358323.0,"size":2.018},{"price":11359242.0,"size":0.0011},{"price":11359700.0,"size":0.001},{"price":11362692.0,"size":0.0015},{"price":11365211.0,"size":0.001},{"price":11369700.0,"size":0.001},{"price":11370000.0,"size":0.1},{"price":11372478.0,"size":1.943},{"price":11376000.0,"size":0.02},{"price":11376545.0,"size":0.001},{"price":11377000.0,"size":0.2287},{"price":11377269.0,"size":0.002},{"price":11379700.0,"size":0.001},{"price":11379865.0,"size":0.03},{"price":11380000.0,"size":0.0223},{"price":11380324.0,"size":0.002},{"price":11381766.0,"size":0.4},{"price":11382386.0,"size":0.0015},{"price":11385000.0,"size":0.2548},{"price":11385403.0,"size":0.002},{"price":11385664.0,"size":0.002},{"price":11386197.0,"size":0.002},{"price":11387072.0,"size":0.01},{"price":11387354.0,"size":0.002},{"price":11387879.0,"size":0.001},{"price":11388885.0,"size":0.03},{"price":11389700.0,"size":0.001},{"price":11390000.0,"size":0.2488},{"price":11390050.0,"size":0.001},{"price":11392387.0,"size":1.0},{"price":11394939.0,"size":0.01},{"price":11395000.0,"size":0.06},{"price":11395775.0,"size":0.01},{"price":11396555.0,"size":0.03},{"price":11398444.0,"size":0.001995},{"price":11399213.0,"size":0.001},{"price":11399673.0,"size":0.0015},{"price":11399700.0,"size":0.001},{"price":11400000.0,"size":0.5525},{"price":11405000.0,"size":0.0275},{"price":11406336.0,"size":1.0},{"price":11408700.0,"size":0.001},{"price":11409415.0,"size":0.055},{"price":11410000.0,"size":0.03},{"price":11410547.0,"size":0.001},{"price":11410853.0,"size":0.002},{"price":11412000.0,"size":0.0878},{"price":11415000.0,"size":0.002},{"price":11415141.0,"size":0.0041},{"price":11417481.0,"size":0.0015},{"price":11418700.0,"size":0.001},{"price":11420000.0,"size":0.401},{"price":11421268.0,"size":0.05},{"price":11421881.0,"size":0.001},{"price":11423339.0,"size":2.0},{"price":11424296.0,"size":0.002},{"price":11424941.0,"size":0.972},{"price":11425000.0,"size":0.049},{"price":11426426.0,"size":0.002},{"price":11428121.0,"size":0.002},{"price":11428700.0,"size":0.001},{"price":11429302.0,"size":0.01},{"price":11432718.0,"size":0.002},{"price":11433211.0,"size":0.03},{"price":11433215.0,"size":0.001},{"price":11433333.0,"size":0.001},{"price":11437315.0,"size":0.002},{"price":11438525.0,"size":0.0011},{"price":11438700.0,"size":0.001},{"price":11439557.0,"size":0.001},{"price":11440000.0,"size":0.1038},{"price":11441911.0,"size":0.002},{"price":11443629.0,"size":0.002},{"price":11444549.0,"size":0.001},{"price":11446508.0,"size":0.001},{"price":11447000.0,"size":0.01},{"price":11447071.0,"size":0.002},{"price":11448000.0,"size":0.0875},{"price":11448700.0,"size":0.001},{"price":11450000.0,"size":0.258},{"price":11451105.0,"size":0.002},{"price":11453321.0,"size":0.03},{"price":11455702.0,"size":0.002},{"price":11455883.0,"size":0.001},{"price":11458700.0,"size":0.001},{"price":11458988.0,"size":0.01},{"price":11460000.0,"size":0.01702},{"price":11460299.0,"size":0.002},{"price":11464896.0,"size":0.002},{"price":11467217.0,"size":0.001},{"price":11468700.0,"size":0.001},{"price":11470000.0,"size":0.01},{"price":11471000.0,"size":0.01},{"price":11475000.0,"size":0.0028},{"price":11478431.0,"size":0.002},{"price":11478551.0,"size":0.001},{"price":11478700.0,"size":0.001},{"price":11480000.0,"size":0.12491},{"price":11485000.0,"size":0.01},{"price":11486555.0,"size":0.03},{"price":11487685.0,"size":0.01},{"price":11488000.0,"size":0.102},{"price":11488700.0,"size":0.001},{"price":11489885.0,"size":0.001},{"price":11490841.0,"size":0.002},{"price":11495450.0,"size":0.002},{"price":11495850.0,"size":0.001},{"price":11498700.0,"size":0.001},{"price":11498917.0,"size":0.002},{"price":11499000.0,"size":0.01},{"price":11500000.0,"size":0.66859519},{"price":11501219.0,"size":0.001},{"price":11502377.0,"size":0.002},{"price":11502800.0,"size":0.00132},{"price":11503108.0,"size":0.0198},{"price":11505000.0,"size":0.0028},{"price":11505001.0,"size":0.002},{"price":11505836.0,"size":0.003},{"price":11508431.0,"size":0.047},{"price":11508700.0,"size":0.001},{"price":11508888.0,"size":0.02},{"price":11510000.0,"size":0.0976},{"price":11512553.0,"size":0.001},{"price":11513633.0,"size":0.08},{"price":11514332.0,"size":0.02},{"price":11518700.0,"size":0.001},{"price":11518992.0,"size":0.002},{"price":11519855.0,"size":0.01},{"price":11520000.0,"size":0.001},{"price":11522423.0,"size":0.97},{"price":11523211.0,"size":0.01},{"price":11523887.0,"size":0.001},{"price":11524999.0,"size":0.001},{"price":11528700.0,"size":0.001},{"price":11529852.0,"size":0.01},{"price":11530000.0,"size":0.261},{"price":11533985.0,"size":0.002},{"price":11534084.0,"size":0.001},{"price":11535321.0,"size":0.01},{"price":11538666.0,"size":0.002},{"price":11538700.0,"size":0.001},{"price":11540000.0,"size":0.0048},{"price":11540357.0,"size":0.002},{"price":11541011.0,"size":0.005},{"price":11541109.0,"size":0.01},{"price":11544663.0,"size":0.002},{"price":11545262.0,"size":0.002},{"price":11546541.0,"size":0.01},{"price":11548144.0,"size":0.002},{"price":11548700.0,"size":0.001},{"price":11550000.0,"size":0.014},{"price":11551109.0,"size":0.01},{"price":11551625.0,"size":0.002},{"price":11552111.0,"size":0.01},{"price":11553687.0,"size":0.1},{"price":11555106.0,"size":0.002},{"price":11555115.0,"size":0.001},{"price":11556000.0,"size":0.1},{"price":11558587.0,"size":0.002},{"price":11558700.0,"size":0.001},{"price":11559855.0,"size":0.01},{"price":11560831.0,"size":0.0198},{"price":11561109.0,"size":0.01},{"price":11562000.0,"size":0.087},{"price":11562068.0,"size":0.002},{"price":11565548.0,"size":0.002},{"price":11566139.0,"size":0.0228},{"price":11566551.0,"size":0.01},{"price":11568700.0,"size":0.001},{"price":11569029.0,"size":0.002},{"price":11570196.0,"size":0.002},{"price":11571109.0,"size":0.01},{"price":11572510.0,"size":0.002},{"price":11573211.0,"size":0.01},{"price":11574840.0,"size":0.002},{"price":11575991.0,"size":0.001},{"price":11578700.0,"size":0.001},{"price":11579484.0,"size":0.002},{"price":11579851.0,"size":0.01},{"price":11580000.0,"size":0.7735},{"price":11581109.0,"size":0.01},{"price":11584128.0,"size":0.002},{"price":11585000.0,"size":0.002},{"price":11586532.0,"size":0.01},{"price":11587498.0,"size":0.0198},{"price":11588700.0,"size":0.001},{"price":11589612.0,"size":0.012},{"price":11590000.0,"size":0.1},{"price":11590749.0,"size":0.002},{"price":11591109.0,"size":0.01},{"price":11593211.0,"size":0.01},{"price":11596753.0,"size":0.002},{"price":11598555.0,"size":0.01},{"price":11598700.0,"size":0.001},{"price":11599999.0,"size":0.001},{"price":11600000.0,"size":3.6141},{"price":11601109.0,"size":0.02},{"price":11606655.0,"size":0.01},{"price":11610000.0,"size":0.302},{"price":11611109.0,"size":0.01},{"price":11613321.0,"size":0.01},{"price":11620000.0,"size":1.35441682},{"price":11621011.0,"size":0.01},{"price":11621109.0,"size":0.01},{"price":11623096.0,"size":0.008},{"price":11629000.0,"size":0.1},{"price":11630000.0,"size":0.201},{"price":11631059.0,"size":0.01},{"price":11631479.0,"size":0.01},{"price":11631773.0,"size":0.00386871},{"price":11635950.0,"size":0.001},{"price":11638259.0,"size":0.001},{"price":11639700.0,"size":0.001},{"price":11640000.0,"size":1.0},{"price":11640820.0,"size":0.01},{"price":11645040.0,"size":1.7},{"price":11645295.0,"size":0.05},{"price":11647158.0,"size":0.05},{"price":11649900.0,"size":0.02906},{"price":11649999.0,"size":0.001},{"price":11650000.0,"size":0.593},{"price":11651059.0,"size":0.01},{"price":11653658.0,"size":0.008},{"price":11654321.0,"size":0.001},{"price":11659700.0,"size":0.001},{"price":11661479.0,"size":0.01},{"price":11666000.0,"size":0.001},{"price":11666666.0,"size":0.013},{"price":11669700.0,"size":0.001},{"price":11671059.0,"size":0.01},{"price":11672562.0,"size":0.0198},{"price":11679224.0,"size":0.012},{"price":11680000.0,"size":0.004},{"price":11685000.0,"size":0.003},{"price":11688000.0,"size":0.001},{"price":11689732.0,"size":0.01},{"price":11690330.0,"size":0.0198},{"price":11691059.0,"size":0.01},{"price":11692558.0,"size":0.01},{"price":11698800.0,"size":0.00131},{"price":11699000.0,"size":0.001},{"price":11699631.0,"size":0.001},{"price":11699998.0,"size":0.01},{"price":11699999.0,"size":0.001},{"price":11700000.0,"size":1.03762841},{"price":11701059.0,"size":0.01},{"price":11720000.0,"size":0.1},{"price":11721059.0,"size":0.01},{"price":11725000.0,"size":0.005},{"price":11726791.0,"size":0.01},{"price":11730000.0,"size":0.9382},{"price":11740000.0,"size":0.101},{"price":11741059.0,"size":0.01},{"price":11748937.0,"size":0.001},{"price":11749999.0,"size":0.001},{"price":11750000.0,"size":0.90537866},{"price":11750050.0,"size":0.2},{"price":11751151.0,"size":0.01},{"price":11755000.0,"size":0.001},{"price":11757860.0,"size":1.82},{"price":11759999.0,"size":0.001},{"price":11760000.0,"size":0.001}]}}}
{"schema_version":"collector.vnext.raw","schema_contract":null,"schema_contract_version":null,"payload_contract_version":null,"record_type":"market.orderbook.diff","record_id":"collector_main-market-orderbook-diff-000000000061","collector_id":"collector_main","collector_role":"production","host_name":"MAIN-PC","session_id":"collector_main-sess-20260314T201821Z-d6b39d6f","stream_session_id":"collector_main-stream-bitflyer-board_ws-20260314T202111Z-741228e4","exchange":"bitflyer","market":"spot","symbol":"BTC_JPY","instrument_id":"bitflyer.spot.BTC_JPY","channel":"board_ws","transport":"websocket","source_event_id":null,"source_sequence":null,"sequence_id":61,"exchange_ts":null,"collector_ts":"2026-03-14T20:21:12Z","ingest_ts":"2026-03-14T20:21:12Z","event_ts":"2026-03-14T20:21:12Z","quality_flags":[],"is_partial":false,"is_reconstructed":false,"confidence_score":1.0,"payload":{"provider":"bitflyer_ws_board","exchange":"bitflyer","transport":"websocket","channel":"lightning_board_BTC_JPY","received_ts":"2026-03-14T20:21:12.085072Z","subscription_id":null,"message_id":null,"source_sequence":null,"raw_message_meta":{"raw_channel":"lightning_board_BTC_JPY","subscription_channel":"lightning_board_BTC_JPY","recv_timeout_sec":10,"ssl_verify":false,"socket_url":"wss://ws.lightstream.bitflyer.com/json-rpc"},"source_payload":{"mid_price":11312770.0,"bids":[{"price":11307115.0,"size":0.0},{"price":11308813.0,"size":0.0},{"price":11308343.0,"size":0.05160298},{"price":11307679.0,"size":0.1275}],"asks":[{"price":11315779.0,"size":0.05632588}]}}}
{"schema_version":"collector.vnext.raw","schema_contract":null,"schema_contract_version":null,"payload_contract_version":null,"record_type":"market.orderbook.diff","record_id":"collector_main-market-orderbook-diff-000000000065","collector_id":"collector_main","collector_role":"production","host_name":"MAIN-PC","session_id":"collector_main-sess-20260314T201821Z-d6b39d6f","stream_session_id":"collector_main-stream-bitflyer-board_ws-20260314T202111Z-741228e4","exchange":"bitflyer","market":"spot","symbol":"BTC_JPY","instrument_id":"bitflyer.spot.BTC_JPY","channel":"board_ws","transport":"websocket","source_event_id":null,"source_sequence":null,"sequence_id":65,"exchange_ts":null,"collector_ts":"2026-03-14T20:21:12Z","ingest_ts":"2026-03-14T20:21:12Z","event_ts":"2026-03-14T20:21:12Z","quality_flags":[],"is_partial":false,"is_reconstructed":false,"confidence_score":1.0,"payload":{"provider":"bitflyer_ws_board","exchange":"bitflyer","transport":"websocket","channel":"lightning_board_BTC_JPY","received_ts":"2026-03-14T20:21:12.191146Z","subscription_id":null,"message_id":null,"source_sequence":null,"raw_message_meta":{"raw_channel":"lightning_board_BTC_JPY","subscription_channel":"lightning_board_BTC_JPY","recv_timeout_sec":10,"ssl_verify":false,"socket_url":"wss://ws.lightstream.bitflyer.com/json-rpc"},"source_payload":{"mid_price":11312770.0,"bids":[{"price":11307115.0,"size":0.02}],"asks":[{"price":11451105.0,"size":0.002}]}}}
{"schema_version":"collector.vnext.raw","schema_contract":null,"schema_contract_version":null,"payload_contract_version":null,"record_type":"market.orderbook.diff","record_id":"collector_main-market-orderbook-diff-000000000067","collector_id":"collector_main","collector_role":"production","host_name":"MAIN-PC","session_id":"collector_main-sess-20260314T201821Z-d6b39d6f","stream_session_id":"collector_main-stream-bitflyer-board_ws-20260314T202111Z-741228e4","exchange":"bitflyer","market":"spot","symbol":"BTC_JPY","instrument_id":"bitflyer.spot.BTC_JPY","channel":"board_ws","transport":"websocket","source_event_id":null,"source_sequence":null,"sequence_id":67,"exchange_ts":null,"collector_ts":"2026-03-14T20:21:12Z","ingest_ts":"2026-03-14T20:21:12Z","event_ts":"2026-03-14T20:21:12Z","quality_flags":[],"is_partial":false,"is_reconstructed":false,"confidence_score":1.0,"payload":{"provider":"bitflyer_ws_board","exchange":"bitflyer","transport":"websocket","channel":"lightning_board_BTC_JPY","received_ts":"2026-03-14T20:21:12.296304Z","subscription_id":null,"message_id":null,"source_sequence":null,"raw_message_meta":{"raw_channel":"lightning_board_BTC_JPY","subscription_channel":"lightning_board_BTC_JPY","recv_timeout_sec":10,"ssl_verify":false,"socket_url":"wss://ws.lightstream.bitflyer.com/json-rpc"},"source_payload":{"mid_price":11312770.0,"bids":[{"price":11307679.0,"size":0.0},{"price":11307114.0,"size":0.0}],"asks":[{"price":11324976.0,"size":0.0}]}}}
{"schema_version":"collector.vnext.raw","schema_contract":null,"schema_contract_version":null,"payload_contract_version":null,"record_type":"market.orderbook.diff","record_id":"collector_main-market-orderbook-diff-000000000069","collector_id":"collector_main","collector_role":"production","host_name":"MAIN-PC","session_id":"collector_main-sess-20260314T201821Z-d6b39d6f","stream_session_id":"collector_main-stream-bitflyer-board_ws-20260314T202111Z-741228e4","exchange":"bitflyer","market":"spot","symbol":"BTC_JPY","instrument_id":"bitflyer.spot.BTC_JPY","channel":"board_ws","transport":"websocket","source_event_id":null,"source_sequence":null,"sequence_id":69,"exchange_ts":null,"collector_ts":"2026-03-14T20:21:12Z","ingest_ts":"2026-03-14T20:21:12Z","event_ts":"2026-03-14T20:21:12Z","quality_flags":[],"is_partial":false,"is_reconstructed":false,"confidence_score":1.0,"payload":{"provider":"bitflyer_ws_board","exchange":"bitflyer","transport":"websocket","channel":"lightning_board_BTC_JPY","received_ts":"2026-03-14T20:21:12.453800Z","subscription_id":null,"message_id":null,"source_sequence":null,"raw_message_meta":{"raw_channel":"lightning_board_BTC_JPY","subscription_channel":"lightning_board_BTC_JPY","recv_timeout_sec":10,"ssl_verify":false,"socket_url":"wss://ws.lightstream.bitflyer.com/json-rpc"},"source_payload":{"mid_price":11312770.0,"bids":[],"asks":[{"price":11324998.0,"size":0.2}]}}}
{"schema_version":"collector.vnext.raw","schema_contract":null,"schema_contract_version":null,"payload_contract_version":null,"record_type":"market.orderbook.diff","record_id":"collector_main-market-orderbook-diff-000000000071","collector_id":"collector_main","collector_role":"production","host_name":"MAIN-PC","session_id":"collector_main-sess-20260314T201821Z-d6b39d6f","stream_session_id":"collector_main-stream-bitflyer-board_ws-20260314T202111Z-741228e4","exchange":"bitflyer","market":"spot","symbol":"BTC_JPY","instrument_id":"bitflyer.spot.BTC_JPY","channel":"board_ws","transport":"websocket","source_event_id":null,"source_sequence":null,"sequence_id":71,"exchange_ts":null,"collector_ts":"2026-03-14T20:21:12Z","ingest_ts":"2026-03-14T20:21:12Z","event_ts":"2026-03-14T20:21:12Z","quality_flags":[],"is_partial":false,"is_reconstructed":false,"confidence_score":1.0,"payload":{"provider":"bitflyer_ws_board","exchange":"bitflyer","transport":"websocket","channel":"lightning_board_BTC_JPY","received_ts":"2026-03-14T20:21:12.547792Z","subscription_id":null,"message_id":null,"source_sequence":null,"raw_message_meta":{"raw_channel":"lightning_board_BTC_JPY","subscription_channel":"lightning_board_BTC_JPY","recv_timeout_sec":10,"ssl_verify":false,"socket_url":"wss://ws.lightstream.bitflyer.com/json-rpc"},"source_payload":{"mid_price":11312770.0,"bids":[{"price":11307680.0,"size":0.02},{"price":11307114.0,"size":0.1275},{"price":11307115.0,"size":0.0}],"asks":[{"price":11329019.0,"size":0.0},{"price":11329041.0,"size":0.002851}]}}}
{"schema_version":"collector.vnext.raw","schema_contract":null,"schema_contract_version":null,"payload_contract_version":null,"record_type":"market.orderbook.diff","record_id":"collector_main-market-orderbook-diff-000000000073","collector_id":"collector_main","collector_role":"production","host_name":"MAIN-PC","session_id":"collector_main-sess-20260314T201821Z-d6b39d6f","stream_session_id":"collector_main-stream-bitflyer-board_ws-20260314T202111Z-741228e4","exchange":"bitflyer","market":"spot","symbol":"BTC_JPY","instrument_id":"bitflyer.spot.BTC_JPY","channel":"board_ws","transport":"websocket","source_event_id":null,"source_sequence":null,"sequence_id":73,"exchange_ts":null,"collector_ts":"2026-03-14T20:21:12Z","ingest_ts":"2026-03-14T20:21:12Z","event_ts":"2026-03-14T20:21:12Z","quality_flags":[],"is_partial":false,"is_reconstructed":false,"confidence_score":1.0,"payload":{"provider":"bitflyer_ws_board","exchange":"bitflyer","transport":"websocket","channel":"lightning_board_BTC_JPY","received_ts":"2026-03-14T20:21:12.673286Z","subscription_id":null,"message_id":null,"source_sequence":null,"raw_message_meta":{"raw_channel":"lightning_board_BTC_JPY","subscription_channel":"lightning_board_BTC_JPY","recv_timeout_sec":10,"ssl_verify":false,"socket_url":"wss://ws.lightstream.bitflyer.com/json-rpc"},"source_payload":{"mid_price":11312770.0,"bids":[{"price":11304852.0,"size":0.02},{"price":11307680.0,"size":0.0},{"price":11307116.0,"size":0.02}],"asks":[]}}}
{"schema_version":"collector.vnext.raw","schema_contract":null,"schema_contract_version":null,"payload_contract_version":null,"record_type":"market.orderbook.diff","record_id":"collector_main-market-orderbook-diff-000000000075","collector_id":"collector_main","collector_role":"production","host_name":"MAIN-PC","session_id":"collector_main-sess-20260314T201821Z-d6b39d6f","stream_session_id":"collector_main-stream-bitflyer-board_ws-20260314T202111Z-741228e4","exchange":"bitflyer","market":"spot","symbol":"BTC_JPY","instrument_id":"bitflyer.spot.BTC_JPY","channel":"board_ws","transport":"websocket","source_event_id":null,"source_sequence":null,"sequence_id":75,"exchange_ts":null,"collector_ts":"2026-03-14T20:21:12Z","ingest_ts":"2026-03-14T20:21:12Z","event_ts":"2026-03-14T20:21:12Z","quality_flags":[],"is_partial":false,"is_reconstructed":false,"confidence_score":1.0,"payload":{"provider":"bitflyer_ws_board","exchange":"bitflyer","transport":"websocket","channel":"lightning_board_BTC_JPY","received_ts":"2026-03-14T20:21:12.830287Z","subscription_id":null,"message_id":null,"source_sequence":null,"raw_message_meta":{"raw_channel":"lightning_board_BTC_JPY","subscription_channel":"lightning_board_BTC_JPY","recv_timeout_sec":10,"ssl_verify":false,"socket_url":"wss://ws.lightstream.bitflyer.com/json-rpc"},"source_payload":{"mid_price":11312770.0,"bids":[{"price":11308344.0,"size":0.02},{"price":11307679.0,"size":0.1275},{"price":11307116.0,"size":0.0}],"asks":[]}}}
{"schema_version":"collector.vnext.raw","schema_contract":null,"schema_contract_version":null,"payload_contract_version":null,"record_type":"market.orderbook.diff","record_id":"collector_main-market-orderbook-diff-000000000077","collector_id":"collector_main","collector_role":"production","host_name":"MAIN-PC","session_id":"collector_main-sess-20260314T201821Z-d6b39d6f","stream_session_id":"collector_main-stream-bitflyer-board_ws-20260314T202111Z-741228e4","exchange":"bitflyer","market":"spot","symbol":"BTC_JPY","instrument_id":"bitflyer.spot.BTC_JPY","channel":"board_ws","transport":"websocket","source_event_id":null,"source_sequence":null,"sequence_id":77,"exchange_ts":null,"collector_ts":"2026-03-14T20:21:12Z","ingest_ts":"2026-03-14T20:21:12Z","event_ts":"2026-03-14T20:21:12Z","quality_flags":[],"is_partial":false,"is_reconstructed":false,"confidence_score":1.0,"payload":{"provider":"bitflyer_ws_board","exchange":"bitflyer","transport":"websocket","channel":"lightning_board_BTC_JPY","received_ts":"2026-03-14T20:21:12.933271Z","subscription_id":null,"message_id":null,"source_sequence":null,"raw_message_meta":{"raw_channel":"lightning_board_BTC_JPY","subscription_channel":"lightning_board_BTC_JPY","recv_timeout_sec":10,"ssl_verify":false,"socket_url":"wss://ws.lightstream.bitflyer.com/json-rpc"},"source_payload":{"mid_price":11312770.0,"bids":[{"price":11307115.0,"size":0.02}],"asks":[]}}}
{"schema_version":"collector.vnext.raw","schema_contract":null,"schema_contract_version":null,"payload_contract_version":null,"record_type":"market.orderbook.diff","record_id":"collector_main-market-orderbook-diff-000000000079","collector_id":"collector_main","collector_role":"production","host_name":"MAIN-PC","session_id":"collector_main-sess-20260314T201821Z-d6b39d6f","stream_session_id":"collector_main-stream-bitflyer-board_ws-20260314T202111Z-741228e4","exchange":"bitflyer","market":"spot","symbol":"BTC_JPY","instrument_id":"bitflyer.spot.BTC_JPY","channel":"board_ws","transport":"websocket","source_event_id":null,"source_sequence":null,"sequence_id":79,"exchange_ts":null,"collector_ts":"2026-03-14T20:21:13Z","ingest_ts":"2026-03-14T20:21:13Z","event_ts":"2026-03-14T20:21:13Z","quality_flags":[],"is_partial":false,"is_reconstructed":false,"confidence_score":1.0,"payload":{"provider":"bitflyer_ws_board","exchange":"bitflyer","transport":"websocket","channel":"lightning_board_BTC_JPY","received_ts":"2026-03-14T20:21:13.032762Z","subscription_id":null,"message_id":null,"source_sequence":null,"raw_message_meta":{"raw_channel":"lightning_board_BTC_JPY","subscription_channel":"lightning_board_BTC_JPY","recv_timeout_sec":10,"ssl_verify":false,"socket_url":"wss://ws.lightstream.bitflyer.com/json-rpc"},"source_payload":{"mid_price":11312770.0,"bids":[{"price":11307114.0,"size":0.0},{"price":11308343.0,"size":0.0},{"price":11307679.0,"size":0.0}],"asks":[]}}}
{"schema_version":"collector.vnext.raw","schema_contract":null,"schema_contract_version":null,"payload_contract_version":null,"record_type":"market.orderbook.diff","record_id":"collector_main-market-orderbook-diff-000000000081","collector_id":"collector_main","collector_role":"production","host_name":"MAIN-PC","session_id":"collector_main-sess-20260314T201821Z-d6b39d6f","stream_session_id":"collector_main-stream-bitflyer-board_ws-20260314T202111Z-741228e4","exchange":"bitflyer","market":"spot","symbol":"BTC_JPY","instrument_id":"bitflyer.spot.BTC_JPY","channel":"board_ws","transport":"websocket","source_event_id":null,"source_sequence":null,"sequence_id":81,"exchange_ts":null,"collector_ts":"2026-03-14T20:21:13Z","ingest_ts":"2026-03-14T20:21:13Z","event_ts":"2026-03-14T20:21:13Z","quality_flags":[],"is_partial":false,"is_reconstructed":false,"confidence_score":1.0,"payload":{"provider":"bitflyer_ws_board","exchange":"bitflyer","transport":"websocket","channel":"lightning_board_BTC_JPY","received_ts":"2026-03-14T20:21:13.141796Z","subscription_id":null,"message_id":null,"source_sequence":null,"raw_message_meta":{"raw_channel":"lightning_board_BTC_JPY","subscription_channel":"lightning_board_BTC_JPY","recv_timeout_sec":10,"ssl_verify":false,"socket_url":"wss://ws.lightstream.bitflyer.com/json-rpc"},"source_payload":{"mid_price":11312770.0,"bids":[{"price":11308345.0,"size":0.05160511}],"asks":[]}}}
{"schema_version":"collector.vnext.raw","schema_contract":null,"schema_contract_version":null,"payload_contract_version":null,"record_type":"market.orderbook.diff","record_id":"collector_main-market-orderbook-diff-000000000083","collector_id":"collector_main","collector_role":"production","host_name":"MAIN-PC","session_id":"collector_main-sess-20260314T201821Z-d6b39d6f","stream_session_id":"collector_main-stream-bitflyer-board_ws-20260314T202111Z-741228e4","exchange":"bitflyer","market":"spot","symbol":"BTC_JPY","instrument_id":"bitflyer.spot.BTC_JPY","channel":"board_ws","transport":"websocket","source_event_id":null,"source_sequence":null,"sequence_id":83,"exchange_ts":null,"collector_ts":"2026-03-14T20:21:13Z","ingest_ts":"2026-03-14T20:21:13Z","event_ts":"2026-03-14T20:21:13Z","quality_flags":[],"is_partial":false,"is_reconstructed":false,"confidence_score":1.0,"payload":{"provider":"bitflyer_ws_board","exchange":"bitflyer","transport":"websocket","channel":"lightning_board_BTC_JPY","received_ts":"2026-03-14T20:21:13.251810Z","subscription_id":null,"message_id":null,"source_sequence":null,"raw_message_meta":{"raw_channel":"lightning_board_BTC_JPY","subscription_channel":"lightning_board_BTC_JPY","recv_timeout_sec":10,"ssl_verify":false,"socket_url":"wss://ws.lightstream.bitflyer.com/json-rpc"},"source_payload":{"mid_price":11312770.0,"bids":[{"price":11308032.0,"size":0.0},{"price":11308344.0,"size":0.0},{"price":11307115.0,"size":0.0},{"price":11307114.0,"size":0.1275}],"asks":[]}}}
{"schema_version":"collector.vnext.raw","schema_contract":null,"schema_contract_version":null,"payload_contract_version":null,"record_type":"market.orderbook.diff","record_id":"collector_main-market-orderbook-diff-000000000085","collector_id":"collector_main","collector_role":"production","host_name":"MAIN-PC","session_id":"collector_main-sess-20260314T201821Z-d6b39d6f","stream_session_id":"collector_main-stream-bitflyer-board_ws-20260314T202111Z-741228e4","exchange":"bitflyer","market":"spot","symbol":"BTC_JPY","instrument_id":"bitflyer.spot.BTC_JPY","channel":"board_ws","transport":"websocket","source_event_id":null,"source_sequence":null,"sequence_id":85,"exchange_ts":null,"collector_ts":"2026-03-14T20:21:13Z","ingest_ts":"2026-03-14T20:21:13Z","event_ts":"2026-03-14T20:21:13Z","quality_flags":[],"is_partial":false,"is_reconstructed":false,"confidence_score":1.0,"payload":{"provider":"bitflyer_ws_board","exchange":"bitflyer","transport":"websocket","channel":"lightning_board_BTC_JPY","received_ts":"2026-03-14T20:21:13.485263Z","subscription_id":null,"message_id":null,"source_sequence":null,"raw_message_meta":{"raw_channel":"lightning_board_BTC_JPY","subscription_channel":"lightning_board_BTC_JPY","recv_timeout_sec":10,"ssl_verify":false,"socket_url":"wss://ws.lightstream.bitflyer.com/json-rpc"},"source_payload":{"mid_price":11312770.0,"bids":[{"price":11308345.0,"size":0.0},{"price":11307679.0,"size":0.1275},{"price":11308343.0,"size":0.04979153},{"price":11307115.0,"size":0.02}],"asks":[{"price":11455702.0,"size":0.002}]}}}
{"schema_version":"collector.vnext.raw","schema_contract":null,"schema_contract_version":null,"payload_contract_version":null,"record_type":"market.orderbook.diff","record_id":"collector_main-market-orderbook-diff-000000000087","collector_id":"collector_main","collector_role":"production","host_name":"MAIN-PC","session_id":"collector_main-sess-20260314T201821Z-d6b39d6f","stream_session_id":"collector_main-stream-bitflyer-board_ws-20260314T202111Z-741228e4","exchange":"bitflyer","market":"spot","symbol":"BTC_JPY","instrument_id":"bitflyer.spot.BTC_JPY","channel":"board_ws","transport":"websocket","source_event_id":null,"source_sequence":null,"sequence_id":87,"exchange_ts":null,"collector_ts":"2026-03-14T20:21:13Z","ingest_ts":"2026-03-14T20:21:13Z","event_ts":"2026-03-14T20:21:13Z","quality_flags":[],"is_partial":false,"is_reconstructed":false,"confidence_score":1.0,"payload":{"provider":"bitflyer_ws_board","exchange":"bitflyer","transport":"websocket","channel":"lightning_board_BTC_JPY","received_ts":"2026-03-14T20:21:13.689000Z","subscription_id":null,"message_id":null,"source_sequence":null,"raw_message_meta":{"raw_channel":"lightning_board_BTC_JPY","subscription_channel":"lightning_board_BTC_JPY","recv_timeout_sec":10,"ssl_verify":false,"socket_url":"wss://ws.lightstream.bitflyer.com/json-rpc"},"source_payload":{"mid_price":11312770.0,"bids":[{"price":11307114.0,"size":0.0}],"asks":[]}}}
{"schema_version":"collector.vnext.raw","schema_contract":null,"schema_contract_version":null,"payload_contract_version":null,"record_type":"market.orderbook.diff","record_id":"collector_main-market-orderbook-diff-000000000089","collector_id":"collector_main","collector_role":"production","host_name":"MAIN-PC","session_id":"collector_main-sess-20260314T201821Z-d6b39d6f","stream_session_id":"collector_main-stream-bitflyer-board_ws-20260314T202111Z-741228e4","exchange":"bitflyer","market":"spot","symbol":"BTC_JPY","instrument_id":"bitflyer.spot.BTC_JPY","channel":"board_ws","transport":"websocket","source_event_id":null,"source_sequence":null,"sequence_id":89,"exchange_ts":null,"collector_ts":"2026-03-14T20:21:13Z","ingest_ts":"2026-03-14T20:21:13Z","event_ts":"2026-03-14T20:21:13Z","quality_flags":[],"is_partial":false,"is_reconstructed":false,"confidence_score":1.0,"payload":{"provider":"bitflyer_ws_board","exchange":"bitflyer","transport":"websocket","channel":"lightning_board_BTC_JPY","received_ts":"2026-03-14T20:21:13.804073Z","subscription_id":null,"message_id":null,"source_sequence":null,"raw_message_meta":{"raw_channel":"lightning_board_BTC_JPY","subscription_channel":"lightning_board_BTC_JPY","recv_timeout_sec":10,"ssl_verify":false,"socket_url":"wss://ws.lightstream.bitflyer.com/json-rpc"},"source_payload":{"mid_price":11312770.0,"bids":[{"price":11308032.0,"size":0.0176847}],"asks":[]}}}
{"schema_version":"collector.vnext.raw","schema_contract":null,"schema_contract_version":null,"payload_contract_version":null,"record_type":"market.orderbook.diff","record_id":"collector_main-market-orderbook-diff-000000000091","collector_id":"collector_main","collector_role":"production","host_name":"MAIN-PC","session_id":"collector_main-sess-20260314T201821Z-d6b39d6f","stream_session_id":"collector_main-stream-bitflyer-board_ws-20260314T202111Z-741228e4","exchange":"bitflyer","market":"spot","symbol":"BTC_JPY","instrument_id":"bitflyer.spot.BTC_JPY","channel":"board_ws","transport":"websocket","source_event_id":null,"source_sequence":null,"sequence_id":91,"exchange_ts":null,"collector_ts":"2026-03-14T20:21:14Z","ingest_ts":"2026-03-14T20:21:14Z","event_ts":"2026-03-14T20:21:14Z","quality_flags":[],"is_partial":false,"is_reconstructed":false,"confidence_score":1.0,"payload":{"provider":"bitflyer_ws_board","exchange":"bitflyer","transport":"websocket","channel":"lightning_board_BTC_JPY","received_ts":"2026-03-14T20:21:14.033644Z","subscription_id":null,"message_id":null,"source_sequence":null,"raw_message_meta":{"raw_channel":"lightning_board_BTC_JPY","subscription_channel":"lightning_board_BTC_JPY","recv_timeout_sec":10,"ssl_verify":false,"socket_url":"wss://ws.lightstream.bitflyer.com/json-rpc"},"source_payload":{"mid_price":11312770.0,"bids":[{"price":11307115.0,"size":0.0},{"price":11308811.0,"size":0.1275},{"price":11307679.0,"size":0.0}],"asks":[]}}}
{"schema_version":"collector.vnext.raw","schema_contract":null,"schema_contract_version":null,"payload_contract_version":null,"record_type":"market.orderbook.diff","record_id":"collector_main-market-orderbook-diff-000000000093","collector_id":"collector_main","collector_role":"production","host_name":"MAIN-PC","session_id":"collector_main-sess-20260314T201821Z-d6b39d6f","stream_session_id":"collector_main-stream-bitflyer-board_ws-20260314T202111Z-741228e4","exchange":"bitflyer","market":"spot","symbol":"BTC_JPY","instrument_id":"bitflyer.spot.BTC_JPY","channel":"board_ws","transport":"websocket","source_event_id":null,"source_sequence":null,"sequence_id":93,"exchange_ts":null,"collector_ts":"2026-03-14T20:21:14Z","ingest_ts":"2026-03-14T20:21:14Z","event_ts":"2026-03-14T20:21:14Z","quality_flags":[],"is_partial":false,"is_reconstructed":false,"confidence_score":1.0,"payload":{"provider":"bitflyer_ws_board","exchange":"bitflyer","transport":"websocket","channel":"lightning_board_BTC_JPY","received_ts":"2026-03-14T20:21:14.205479Z","subscription_id":null,"message_id":null,"source_sequence":null,"raw_message_meta":{"raw_channel":"lightning_board_BTC_JPY","subscription_channel":"lightning_board_BTC_JPY","recv_timeout_sec":10,"ssl_verify":false,"socket_url":"wss://ws.lightstream.bitflyer.com/json-rpc"},"source_payload":{"mid_price":11312770.0,"bids":[{"price":11308811.0,"size":0.0},{"price":11308343.0,"size":0.0}],"asks":[]}}}
{"schema_version":"collector.vnext.raw","schema_contract":null,"schema_contract_version":null,"payload_contract_version":null,"record_type":"market.orderbook.diff","record_id":"collector_main-market-orderbook-diff-000000000095","collector_id":"collector_main","collector_role":"production","host_name":"MAIN-PC","session_id":"collector_main-sess-20260314T201821Z-d6b39d6f","stream_session_id":"collector_main-stream-bitflyer-board_ws-20260314T202111Z-741228e4","exchange":"bitflyer","market":"spot","symbol":"BTC_JPY","instrument_id":"bitflyer.spot.BTC_JPY","channel":"board_ws","transport":"websocket","source_event_id":null,"source_sequence":null,"sequence_id":95,"exchange_ts":null,"collector_ts":"2026-03-14T20:21:14Z","ingest_ts":"2026-03-14T20:21:14Z","event_ts":"2026-03-14T20:21:14Z","quality_flags":[],"is_partial":false,"is_reconstructed":false,"confidence_score":1.0,"payload":{"provider":"bitflyer_ws_board","exchange":"bitflyer","transport":"websocket","channel":"lightning_board_BTC_JPY","received_ts":"2026-03-14T20:21:14.314356Z","subscription_id":null,"message_id":null,"source_sequence":null,"raw_message_meta":{"raw_channel":"lightning_board_BTC_JPY","subscription_channel":"lightning_board_BTC_JPY","recv_timeout_sec":10,"ssl_verify":false,"socket_url":"wss://ws.lightstream.bitflyer.com/json-rpc"},"source_payload":{"mid_price":11312770.0,"bids":[{"price":11309376.0,"size":0.1275},{"price":11308812.0,"size":0.04466328}],"asks":[]}}}
{"schema_version":"collector.vnext.raw","schema_contract":null,"schema_contract_version":null,"payload_contract_version":null,"record_type":"market.orderbook.diff","record_id":"collector_main-market-orderbook-diff-000000000097","collector_id":"collector_main","collector_role":"production","host_name":"MAIN-PC","session_id":"collector_main-sess-20260314T201821Z-d6b39d6f","stream_session_id":"collector_main-stream-bitflyer-board_ws-20260314T202111Z-741228e4","exchange":"bitflyer","market":"spot","symbol":"BTC_JPY","instrument_id":"bitflyer.spot.BTC_JPY","channel":"board_ws","transport":"websocket","source_event_id":null,"source_sequence":null,"sequence_id":97,"exchange_ts":null,"collector_ts":"2026-03-14T20:21:14Z","ingest_ts":"2026-03-14T20:21:14Z","event_ts":"2026-03-14T20:21:14Z","quality_flags":[],"is_partial":false,"is_reconstructed":false,"confidence_score":1.0,"payload":{"provider":"bitflyer_ws_board","exchange":"bitflyer","transport":"websocket","channel":"lightning_board_BTC_JPY","received_ts":"2026-03-14T20:21:14.431657Z","subscription_id":null,"message_id":null,"source_sequence":null,"raw_message_meta":{"raw_channel":"lightning_board_BTC_JPY","subscription_channel":"lightning_board_BTC_JPY","recv_timeout_sec":10,"ssl_verify":false,"socket_url":"wss://ws.lightstream.bitflyer.com/json-rpc"},"source_payload":{"mid_price":11312771.0,"bids":[{"price":11308812.0,"size":0.0},{"price":11309763.0,"size":0.04192574},{"price":11309376.0,"size":0.0},{"price":11299225.0,"size":0.0},{"price":11309762.0,"size":0.0}],"asks":[{"price":11316324.0,"size":0.0}]}}}
{"schema_version":"collector.vnext.raw","schema_contract":null,"schema_contract_version":null,"payload_contract_version":null,"record_type":"market.orderbook.diff","record_id":"collector_main-market-orderbook-diff-000000000099","collector_id":"collector_main","collector_role":"production","host_name":"MAIN-PC","session_id":"collector_main-sess-20260314T201821Z-d6b39d6f","stream_session_id":"collector_main-stream-bitflyer-board_ws-20260314T202111Z-741228e4","exchange":"bitflyer","market":"spot","symbol":"BTC_JPY","instrument_id":"bitflyer.spot.BTC_JPY","channel":"board_ws","transport":"websocket","source_event_id":null,"source_sequence":null,"sequence_id":99,"exchange_ts":null,"collector_ts":"2026-03-14T20:21:14Z","ingest_ts":"2026-03-14T20:21:14Z","event_ts":"2026-03-14T20:21:14Z","quality_flags":[],"is_partial":false,"is_reconstructed":false,"confidence_score":1.0,"payload":{"provider":"bitflyer_ws_board","exchange":"bitflyer","transport":"websocket","channel":"lightning_board_BTC_JPY","received_ts":"2026-03-14T20:21:14.531051Z","subscription_id":null,"message_id":null,"source_sequence":null,"raw_message_meta":{"raw_channel":"lightning_board_BTC_JPY","subscription_channel":"lightning_board_BTC_JPY","recv_timeout_sec":10,"ssl_verify":false,"socket_url":"wss://ws.lightstream.bitflyer.com/json-rpc"},"source_payload":{"mid_price":11312771.0,"bids":[{"price":11307114.0,"size":0.0},{"price":11308032.0,"size":0.0}],"asks":[]}}}
{"schema_version":"collector.vnext.raw","schema_contract":null,"schema_contract_version":null,"payload_contract_version":null,"record_type":"market.orderbook.diff","record_id":"collector_main-market-orderbook-diff-000000000101","collector_id":"collector_main","collector_role":"production","host_name":"MAIN-PC","session_id":"collector_main-sess-20260314T201821Z-d6b39d6f","stream_session_id":"collector_main-stream-bitflyer-board_ws-20260314T202111Z-741228e4","exchange":"bitflyer","market":"spot","symbol":"BTC_JPY","instrument_id":"bitflyer.spot.BTC_JPY","channel":"board_ws","transport":"websocket","source_event_id":null,"source_sequence":null,"sequence_id":101,"exchange_ts":null,"collector_ts":"2026-03-14T20:21:14Z","ingest_ts":"2026-03-14T20:21:14Z","event_ts":"2026-03-14T20:21:14Z","quality_flags":[],"is_partial":false,"is_reconstructed":false,"confidence_score":1.0,"payload":{"provider":"bitflyer_ws_board","exchange":"bitflyer","transport":"websocket","channel":"lightning_board_BTC_JPY","received_ts":"2026-03-14T20:21:14.657304Z","subscription_id":null,"message_id":null,"source_sequence":null,"raw_message_meta":{"raw_channel":"lightning_board_BTC_JPY","subscription_channel":"lightning_board_BTC_JPY","recv_timeout_sec":10,"ssl_verify":false,"socket_url":"wss://ws.lightstream.bitflyer.com/json-rpc"},"source_payload":{"mid_price":11312061.0,"bids":[{"price":11309763.0,"size":0.0},{"price":11308343.0,"size":0.0544579}],"asks":[{"price":11460299.0,"size":0.002}]}}}
{"schema_version":"collector.vnext.raw","schema_contract":null,"schema_contract_version":null,"payload_contract_version":null,"record_type":"market.orderbook.diff","record_id":"collector_main-market-orderbook-diff-000000000103","collector_id":"collector_main","collector_role":"production","host_name":"MAIN-PC","session_id":"collector_main-sess-20260314T201821Z-d6b39d6f","stream_session_id":"collector_main-stream-bitflyer-board_ws-20260314T202111Z-741228e4","exchange":"bitflyer","market":"spot","symbol":"BTC_JPY","instrument_id":"bitflyer.spot.BTC_JPY","channel":"board_ws","transport":"websocket","source_event_id":null,"source_sequence":null,"sequence_id":103,"exchange_ts":null,"collector_ts":"2026-03-14T20:21:14Z","ingest_ts":"2026-03-14T20:21:14Z","event_ts":"2026-03-14T20:21:14Z","quality_flags":[],"is_partial":false,"is_reconstructed":false,"confidence_score":1.0,"payload":{"provider":"bitflyer_ws_board","exchange":"bitflyer","transport":"websocket","channel":"lightning_board_BTC_JPY","received_ts":"2026-03-14T20:21:14.767198Z","subscription_id":null,"message_id":null,"source_sequence":null,"raw_message_meta":{"raw_channel":"lightning_board_BTC_JPY","subscription_channel":"lightning_board_BTC_JPY","recv_timeout_sec":10,"ssl_verify":false,"socket_url":"wss://ws.lightstream.bitflyer.com/json-rpc"},"source_payload":{"mid_price":11313218.0,"bids":[{"price":11310658.0,"size":0.0099986},{"price":11299901.0,"size":0.0099986}],"asks":[{"price":11316544.0,"size":0.00908554},{"price":11316323.0,"size":0.0}]}}}
{"schema_version":"collector.vnext.raw","schema_contract":null,"schema_contract_version":null,"payload_contract_version":null,"record_type":"market.orderbook.diff","record_id":"collector_main-market-orderbook-diff-000000000105","collector_id":"collector_main","collector_role":"production","host_name":"MAIN-PC","session_id":"collector_main-sess-20260314T201821Z-d6b39d6f","stream_session_id":"collector_main-stream-bitflyer-board_ws-20260314T202111Z-741228e4","exchange":"bitflyer","market":"spot","symbol":"BTC_JPY","instrument_id":"bitflyer.spot.BTC_JPY","channel":"board_ws","transport":"websocket","source_event_id":null,"source_sequence":null,"sequence_id":105,"exchange_ts":null,"collector_ts":"2026-03-14T20:21:14Z","ingest_ts":"2026-03-14T20:21:14Z","event_ts":"2026-03-14T20:21:14Z","quality_flags":[],"is_partial":false,"is_reconstructed":false,"confidence_score":1.0,"payload":{"provider":"bitflyer_ws_board","exchange":"bitflyer","transport":"websocket","channel":"lightning_board_BTC_JPY","received_ts":"2026-03-14T20:21:14.892260Z","subscription_id":null,"message_id":null,"source_sequence":null,"raw_message_meta":{"raw_channel":"lightning_board_BTC_JPY","subscription_channel":"lightning_board_BTC_JPY","recv_timeout_sec":10,"ssl_verify":false,"socket_url":"wss://ws.lightstream.bitflyer.com/json-rpc"},"source_payload":{"mid_price":11313218.0,"bids":[{"price":11307114.0,"size":0.1275}],"asks":[]}}}
{"schema_version":"collector.vnext.raw","schema_contract":null,"schema_contract_version":null,"payload_contract_version":null,"record_type":"market.orderbook.diff","record_id":"collector_main-market-orderbook-diff-000000000107","collector_id":"collector_main","collector_role":"production","host_name":"MAIN-PC","session_id":"collector_main-sess-20260314T201821Z-d6b39d6f","stream_session_id":"collector_main-stream-bitflyer-board_ws-20260314T202111Z-741228e4","exchange":"bitflyer","market":"spot","symbol":"BTC_JPY","instrument_id":"bitflyer.spot.BTC_JPY","channel":"board_ws","transport":"websocket","source_event_id":null,"source_sequence":null,"sequence_id":107,"exchange_ts":null,"collector_ts":"2026-03-14T20:21:15Z","ingest_ts":"2026-03-14T20:21:15Z","event_ts":"2026-03-14T20:21:15Z","quality_flags":[],"is_partial":false,"is_reconstructed":false,"confidence_score":1.0,"payload":{"provider":"bitflyer_ws_board","exchange":"bitflyer","transport":"websocket","channel":"lightning_board_BTC_JPY","received_ts":"2026-03-14T20:21:15.007131Z","subscription_id":null,"message_id":null,"source_sequence":null,"raw_message_meta":{"raw_channel":"lightning_board_BTC_JPY","subscription_channel":"lightning_board_BTC_JPY","recv_timeout_sec":10,"ssl_verify":false,"socket_url":"wss://ws.lightstream.bitflyer.com/json-rpc"},"source_payload":{"mid_price":11313218.0,"bids":[{"price":11308746.0,"size":0.1275}],"asks":[]}}}
{"schema_version":"collector.vnext.raw","schema_contract":null,"schema_contract_version":null,"payload_contract_version":null,"record_type":"market.orderbook.diff","record_id":"collector_main-market-orderbook-diff-000000000109","collector_id":"collector_main","collector_role":"production","host_name":"MAIN-PC","session_id":"collector_main-sess-20260314T201821Z-d6b39d6f","stream_session_id":"collector_main-stream-bitflyer-board_ws-20260314T202111Z-741228e4","exchange":"bitflyer","market":"spot","symbol":"BTC_JPY","instrument_id":"bitflyer.spot.BTC_JPY","channel":"board_ws","transport":"websocket","source_event_id":null,"source_sequence":null,"sequence_id":109,"exchange_ts":null,"collector_ts":"2026-03-14T20:21:15Z","ingest_ts":"2026-03-14T20:21:15Z","event_ts":"2026-03-14T20:21:15Z","quality_flags":[],"is_partial":false,"is_reconstructed":false,"confidence_score":1.0,"payload":{"provider":"bitflyer_ws_board","exchange":"bitflyer","transport":"websocket","channel":"lightning_board_BTC_JPY","received_ts":"2026-03-14T20:21:15.126471Z","subscription_id":null,"message_id":null,"source_sequence":null,"raw_message_meta":{"raw_channel":"lightning_board_BTC_JPY","subscription_channel":"lightning_board_BTC_JPY","recv_timeout_sec":10,"ssl_verify":false,"socket_url":"wss://ws.lightstream.bitflyer.com/json-rpc"},"source_payload":{"mid_price":11313218.0,"bids":[{"price":11308032.0,"size":0.0176847},{"price":11298710.0,"size":0.066}],"asks":[]}}}
{"schema_version":"collector.vnext.raw","schema_contract":null,"schema_contract_version":null,"payload_contract_version":null,"record_type":"market.orderbook.diff","record_id":"collector_main-market-orderbook-diff-000000000111","collector_id":"collector_main","collector_role":"production","host_name":"MAIN-PC","session_id":"collector_main-sess-20260314T201821Z-d6b39d6f","stream_session_id":"collector_main-stream-bitflyer-board_ws-20260314T202111Z-741228e4","exchange":"bitflyer","market":"spot","symbol":"BTC_JPY","instrument_id":"bitflyer.spot.BTC_JPY","channel":"board_ws","transport":"websocket","source_event_id":null,"source_sequence":null,"sequence_id":111,"exchange_ts":null,"collector_ts":"2026-03-14T20:21:15Z","ingest_ts":"2026-03-14T20:21:15Z","event_ts":"2026-03-14T20:21:15Z","quality_flags":[],"is_partial":false,"is_reconstructed":false,"confidence_score":1.0,"payload":{"provider":"bitflyer_ws_board","exchange":"bitflyer","transport":"websocket","channel":"lightning_board_BTC_JPY","received_ts":"2026-03-14T20:21:15.241006Z","subscription_id":null,"message_id":null,"source_sequence":null,"raw_message_meta":{"raw_channel":"lightning_board_BTC_JPY","subscription_channel":"lightning_board_BTC_JPY","recv_timeout_sec":10,"ssl_verify":false,"socket_url":"wss://ws.lightstream.bitflyer.com/json-rpc"},"source_payload":{"mid_price":11313218.0,"bids":[{"price":11307115.0,"size":0.02},{"price":11308343.0,"size":0.0}],"asks":[{"price":11316543.0,"size":0.02}]}}}
{"schema_version":"collector.vnext.raw","schema_contract":null,"schema_contract_version":null,"payload_contract_version":null,"record_type":"market.orderbook.diff","record_id":"collector_main-market-orderbook-diff-000000000113","collector_id":"collector_main","collector_role":"production","host_name":"MAIN-PC","session_id":"collector_main-sess-20260314T201821Z-d6b39d6f","stream_session_id":"collector_main-stream-bitflyer-board_ws-20260314T202111Z-741228e4","exchange":"bitflyer","market":"spot","symbol":"BTC_JPY","instrument_id":"bitflyer.spot.BTC_JPY","channel":"board_ws","transport":"websocket","source_event_id":null,"source_sequence":null,"sequence_id":113,"exchange_ts":null,"collector_ts":"2026-03-14T20:21:15Z","ingest_ts":"2026-03-14T20:21:15Z","event_ts":"2026-03-14T20:21:15Z","quality_flags":[],"is_partial":false,"is_reconstructed":false,"confidence_score":1.0,"payload":{"provider":"bitflyer_ws_board","exchange":"bitflyer","transport":"websocket","channel":"lightning_board_BTC_JPY","received_ts":"2026-03-14T20:21:15.346355Z","subscription_id":null,"message_id":null,"source_sequence":null,"raw_message_meta":{"raw_channel":"lightning_board_BTC_JPY","subscription_channel":"lightning_board_BTC_JPY","recv_timeout_sec":10,"ssl_verify":false,"socket_url":"wss://ws.lightstream.bitflyer.com/json-rpc"},"source_payload":{"mid_price":11313218.0,"bids":[{"price":11308747.0,"size":0.05198319},{"price":11307114.0,"size":0.0}],"asks":[]}}}
{"schema_version":"collector.vnext.raw","schema_contract":null,"schema_contract_version":null,"payload_contract_version":null,"record_type":"market.orderbook.diff","record_id":"collector_main-market-orderbook-diff-000000000115","collector_id":"collector_main","collector_role":"production","host_name":"MAIN-PC","session_id":"collector_main-sess-20260314T201821Z-d6b39d6f","stream_session_id":"collector_main-stream-bitflyer-board_ws-20260314T202111Z-741228e4","exchange":"bitflyer","market":"spot","symbol":"BTC_JPY","instrument_id":"bitflyer.spot.BTC_JPY","channel":"board_ws","transport":"websocket","source_event_id":null,"source_sequence":null,"sequence_id":115,"exchange_ts":null,"collector_ts":"2026-03-14T20:21:15Z","ingest_ts":"2026-03-14T20:21:15Z","event_ts":"2026-03-14T20:21:15Z","quality_flags":[],"is_partial":false,"is_reconstructed":false,"confidence_score":1.0,"payload":{"provider":"bitflyer_ws_board","exchange":"bitflyer","transport":"websocket","channel":"lightning_board_BTC_JPY","received_ts":"2026-03-14T20:21:15.548989Z","subscription_id":null,"message_id":null,"source_sequence":null,"raw_message_meta":{"raw_channel":"lightning_board_BTC_JPY","subscription_channel":"lightning_board_BTC_JPY","recv_timeout_sec":10,"ssl_verify":false,"socket_url":"wss://ws.lightstream.bitflyer.com/json-rpc"},"source_payload":{"mid_price":11313218.0,"bids":[{"price":11307115.0,"size":0.0}],"asks":[]}}}
{"schema_version":"collector.vnext.raw","schema_contract":null,"schema_contract_version":null,"payload_contract_version":null,"record_type":"market.orderbook.diff","record_id":"collector_main-market-orderbook-diff-000000000117","collector_id":"collector_main","collector_role":"production","host_name":"MAIN-PC","session_id":"collector_main-sess-20260314T201821Z-d6b39d6f","stream_session_id":"collector_main-stream-bitflyer-board_ws-20260314T202111Z-741228e4","exchange":"bitflyer","market":"spot","symbol":"BTC_JPY","instrument_id":"bitflyer.spot.BTC_JPY","channel":"board_ws","transport":"websocket","source_event_id":null,"source_sequence":null,"sequence_id":117,"exchange_ts":null,"collector_ts":"2026-03-14T20:21:15Z","ingest_ts":"2026-03-14T20:21:15Z","event_ts":"2026-03-14T20:21:15Z","quality_flags":[],"is_partial":false,"is_reconstructed":false,"confidence_score":1.0,"payload":{"provider":"bitflyer_ws_board","exchange":"bitflyer","transport":"websocket","channel":"lightning_board_BTC_JPY","received_ts":"2026-03-14T20:21:15.686051Z","subscription_id":null,"message_id":null,"source_sequence":null,"raw_message_meta":{"raw_channel":"lightning_board_BTC_JPY","subscription_channel":"lightning_board_BTC_JPY","recv_timeout_sec":10,"ssl_verify":false,"socket_url":"wss://ws.lightstream.bitflyer.com/json-rpc"},"source_payload":{"mid_price":11313218.0,"bids":[{"price":11309258.0,"size":0.1275},{"price":11308032.0,"size":0.0}],"asks":[]}}}
{"schema_version":"collector.vnext.raw","schema_contract":null,"schema_contract_version":null,"payload_contract_version":null,"record_type":"market.orderbook.diff","record_id":"collector_main-market-orderbook-diff-000000000119","collector_id":"collector_main","collector_role":"production","host_name":"MAIN-PC","session_id":"collector_main-sess-20260314T201821Z-d6b39d6f","stream_session_id":"collector_main-stream-bitflyer-board_ws-20260314T202111Z-741228e4","exchange":"bitflyer","market":"spot","symbol":"BTC_JPY","instrument_id":"bitflyer.spot.BTC_JPY","channel":"board_ws","transport":"websocket","source_event_id":null,"source_sequence":null,"sequence_id":119,"exchange_ts":null,"collector_ts":"2026-03-14T20:21:15Z","ingest_ts":"2026-03-14T20:21:15Z","event_ts":"2026-03-14T20:21:15Z","quality_flags":[],"is_partial":false,"is_reconstructed":false,"confidence_score":1.0,"payload":{"provider":"bitflyer_ws_board","exchange":"bitflyer","transport":"websocket","channel":"lightning_board_BTC_JPY","received_ts":"2026-03-14T20:21:15.830136Z","subscription_id":null,"message_id":null,"source_sequence":null,"raw_message_meta":{"raw_channel":"lightning_board_BTC_JPY","subscription_channel":"lightning_board_BTC_JPY","recv_timeout_sec":10,"ssl_verify":false,"socket_url":"wss://ws.lightstream.bitflyer.com/json-rpc"},"source_payload":{"mid_price":11313218.0,"bids":[{"price":11309258.0,"size":0.0},{"price":11308747.0,"size":0.0},{"price":11308746.0,"size":0.0}],"asks":[{"price":11464896.0,"size":0.002}]}}}
{"schema_version":"collector.vnext.raw","schema_contract":null,"schema_contract_version":null,"payload_contract_version":null,"record_type":"market.orderbook.diff","record_id":"collector_main-market-orderbook-diff-000000000121","collector_id":"collector_main","collector_role":"production","host_name":"MAIN-PC","session_id":"collector_main-sess-20260314T201821Z-d6b39d6f","stream_session_id":"collector_main-stream-bitflyer-board_ws-20260314T202111Z-741228e4","exchange":"bitflyer","market":"spot","symbol":"BTC_JPY","instrument_id":"bitflyer.spot.BTC_JPY","channel":"board_ws","transport":"websocket","source_event_id":null,"source_sequence":null,"sequence_id":121,"exchange_ts":null,"collector_ts":"2026-03-14T20:21:15Z","ingest_ts":"2026-03-14T20:21:15Z","event_ts":"2026-03-14T20:21:15Z","quality_flags":[],"is_partial":false,"is_reconstructed":false,"confidence_score":1.0,"payload":{"provider":"bitflyer_ws_board","exchange":"bitflyer","transport":"websocket","channel":"lightning_board_BTC_JPY","received_ts":"2026-03-14T20:21:15.953807Z","subscription_id":null,"message_id":null,"source_sequence":null,"raw_message_meta":{"raw_channel":"lightning_board_BTC_JPY","subscription_channel":"lightning_board_BTC_JPY","recv_timeout_sec":10,"ssl_verify":false,"socket_url":"wss://ws.lightstream.bitflyer.com/json-rpc"},"source_payload":{"mid_price":11313218.0,"bids":[{"price":11309259.0,"size":0.0},{"price":11308659.0,"size":0.014436}],"asks":[]}}}
{"schema_version":"collector.vnext.raw","schema_contract":null,"schema_contract_version":null,"payload_contract_version":null,"record_type":"market.orderbook.diff","record_id":"collector_main-market-orderbook-diff-000000000123","collector_id":"collector_main","collector_role":"production","host_name":"MAIN-PC","session_id":"collector_main-sess-20260314T201821Z-d6b39d6f","stream_session_id":"collector_main-stream-bitflyer-board_ws-20260314T202111Z-741228e4","exchange":"bitflyer","market":"spot","symbol":"BTC_JPY","instrument_id":"bitflyer.spot.BTC_JPY","channel":"board_ws","transport":"websocket","source_event_id":null,"source_sequence":null,"sequence_id":123,"exchange_ts":null,"collector_ts":"2026-03-14T20:21:16Z","ingest_ts":"2026-03-14T20:21:16Z","event_ts":"2026-03-14T20:21:16Z","quality_flags":[],"is_partial":false,"is_reconstructed":false,"confidence_score":1.0,"payload":{"provider":"bitflyer_ws_board","exchange":"bitflyer","transport":"websocket","channel":"lightning_board_BTC_JPY","received_ts":"2026-03-14T20:21:16.063276Z","subscription_id":null,"message_id":null,"source_sequence":null,"raw_message_meta":{"raw_channel":"lightning_board_BTC_JPY","subscription_channel":"lightning_board_BTC_JPY","recv_timeout_sec":10,"ssl_verify":false,"socket_url":"wss://ws.lightstream.bitflyer.com/json-rpc"},"source_payload":{"mid_price":11313218.0,"bids":[{"price":11308343.0,"size":0.05419788}],"asks":[]}}}
{"schema_version":"collector.vnext.raw","schema_contract":null,"schema_contract_version":null,"payload_contract_version":null,"record_type":"market.orderbook.diff","record_id":"collector_main-market-orderbook-diff-000000000125","collector_id":"collector_main","collector_role":"production","host_name":"MAIN-PC","session_id":"collector_main-sess-20260314T201821Z-d6b39d6f","stream_session_id":"collector_main-stream-bitflyer-board_ws-20260314T202111Z-741228e4","exchange":"bitflyer","market":"spot","symbol":"BTC_JPY","instrument_id":"bitflyer.spot.BTC_JPY","channel":"board_ws","transport":"websocket","source_event_id":null,"source_sequence":null,"sequence_id":125,"exchange_ts":null,"collector_ts":"2026-03-14T20:21:16Z","ingest_ts":"2026-03-14T20:21:16Z","event_ts":"2026-03-14T20:21:16Z","quality_flags":[],"is_partial":false,"is_reconstructed":false,"confidence_score":1.0,"payload":{"provider":"bitflyer_ws_board","exchange":"bitflyer","transport":"websocket","channel":"lightning_board_BTC_JPY","received_ts":"2026-03-14T20:21:16.172882Z","subscription_id":null,"message_id":null,"source_sequence":null,"raw_message_meta":{"raw_channel":"lightning_board_BTC_JPY","subscription_channel":"lightning_board_BTC_JPY","recv_timeout_sec":10,"ssl_verify":false,"socket_url":"wss://ws.lightstream.bitflyer.com/json-rpc"},"source_payload":{"mid_price":11313218.0,"bids":[{"price":11306996.0,"size":0.1275},{"price":11298710.0,"size":0.0},{"price":11308343.0,"size":0.0}],"asks":[]}}}
{"schema_version":"collector.vnext.raw","schema_contract":null,"schema_contract_version":null,"payload_contract_version":null,"record_type":"market.orderbook.diff","record_id":"collector_main-market-orderbook-diff-000000000127","collector_id":"collector_main","collector_role":"production","host_name":"MAIN-PC","session_id":"collector_main-sess-20260314T201821Z-d6b39d6f","stream_session_id":"collector_main-stream-bitflyer-board_ws-20260314T202111Z-741228e4","exchange":"bitflyer","market":"spot","symbol":"BTC_JPY","instrument_id":"bitflyer.spot.BTC_JPY","channel":"board_ws","transport":"websocket","source_event_id":null,"source_sequence":null,"sequence_id":127,"exchange_ts":null,"collector_ts":"2026-03-14T20:21:16Z","ingest_ts":"2026-03-14T20:21:16Z","event_ts":"2026-03-14T20:21:16Z","quality_flags":[],"is_partial":false,"is_reconstructed":false,"confidence_score":1.0,"payload":{"provider":"bitflyer_ws_board","exchange":"bitflyer","transport":"websocket","channel":"lightning_board_BTC_JPY","received_ts":"2026-03-14T20:21:16.282749Z","subscription_id":null,"message_id":null,"source_sequence":null,"raw_message_meta":{"raw_channel":"lightning_board_BTC_JPY","subscription_channel":"lightning_board_BTC_JPY","recv_timeout_sec":10,"ssl_verify":false,"socket_url":"wss://ws.lightstream.bitflyer.com/json-rpc"},"source_payload":{"mid_price":11313218.0,"bids":[{"price":11307030.0,"size":0.0176863},{"price":11308660.0,"size":0.05248282}],"asks":[]}}}
{"schema_version":"collector.vnext.raw","schema_contract":null,"schema_contract_version":null,"payload_contract_version":null,"record_type":"market.orderbook.diff","record_id":"collector_main-market-orderbook-diff-000000000129","collector_id":"collector_main","collector_role":"production","host_name":"MAIN-PC","session_id":"collector_main-sess-20260314T201821Z-d6b39d6f","stream_session_id":"collector_main-stream-bitflyer-board_ws-20260314T202111Z-741228e4","exchange":"bitflyer","market":"spot","symbol":"BTC_JPY","instrument_id":"bitflyer.spot.BTC_JPY","channel":"board_ws","transport":"websocket","source_event_id":null,"source_sequence":null,"sequence_id":129,"exchange_ts":null,"collector_ts":"2026-03-14T20:21:16Z","ingest_ts":"2026-03-14T20:21:16Z","event_ts":"2026-03-14T20:21:16Z","quality_flags":[],"is_partial":false,"is_reconstructed":false,"confidence_score":1.0,"payload":{"provider":"bitflyer_ws_board","exchange":"bitflyer","transport":"websocket","channel":"lightning_board_BTC_JPY","received_ts":"2026-03-14T20:21:16.375327Z","subscription_id":null,"message_id":null,"source_sequence":null,"raw_message_meta":{"raw_channel":"lightning_board_BTC_JPY","subscription_channel":"lightning_board_BTC_JPY","recv_timeout_sec":10,"ssl_verify":false,"socket_url":"wss://ws.lightstream.bitflyer.com/json-rpc"},"source_payload":{"mid_price":11313218.0,"bids":[{"price":11308693.0,"size":0.1275},{"price":11306996.0,"size":0.0}],"asks":[]}}}
{"schema_version":"collector.vnext.raw","schema_contract":null,"schema_contract_version":null,"payload_contract_version":null,"record_type":"market.orderbook.diff","record_id":"collector_main-market-orderbook-diff-000000000131","collector_id":"collector_main","collector_role":"production","host_name":"MAIN-PC","session_id":"collector_main-sess-20260314T201821Z-d6b39d6f","stream_session_id":"collector_main-stream-bitflyer-board_ws-20260314T202111Z-741228e4","exchange":"bitflyer","market":"spot","symbol":"BTC_JPY","instrument_id":"bitflyer.spot.BTC_JPY","channel":"board_ws","transport":"websocket","source_event_id":null,"source_sequence":null,"sequence_id":131,"exchange_ts":null,"collector_ts":"2026-03-14T20:21:16Z","ingest_ts":"2026-03-14T20:21:16Z","event_ts":"2026-03-14T20:21:16Z","quality_flags":[],"is_partial":false,"is_reconstructed":false,"confidence_score":1.0,"payload":{"provider":"bitflyer_ws_board","exchange":"bitflyer","transport":"websocket","channel":"lightning_board_BTC_JPY","received_ts":"2026-03-14T20:21:16.589281Z","subscription_id":null,"message_id":null,"source_sequence":null,"raw_message_meta":{"raw_channel":"lightning_board_BTC_JPY","subscription_channel":"lightning_board_BTC_JPY","recv_timeout_sec":10,"ssl_verify":false,"socket_url":"wss://ws.lightstream.bitflyer.com/json-rpc"},"source_payload":{"mid_price":11313218.0,"bids":[{"price":11308660.0,"size":0.0},{"price":11308693.0,"size":0.0}],"asks":[]}}}
{"schema_version":"collector.vnext.raw","schema_contract":null,"schema_contract_version":null,"payload_contract_version":null,"record_type":"market.orderbook.diff","record_id":"collector_main-market-orderbook-diff-000000000133","collector_id":"collector_main","collector_role":"production","host_name":"MAIN-PC","session_id":"collector_main-sess-20260314T201821Z-d6b39d6f","stream_session_id":"collector_main-stream-bitflyer-board_ws-20260314T202111Z-741228e4","exchange":"bitflyer","market":"spot","symbol":"BTC_JPY","instrument_id":"bitflyer.spot.BTC_JPY","channel":"board_ws","transport":"websocket","source_event_id":null,"source_sequence":null,"sequence_id":133,"exchange_ts":null,"collector_ts":"2026-03-14T20:21:16Z","ingest_ts":"2026-03-14T20:21:16Z","event_ts":"2026-03-14T20:21:16Z","quality_flags":[],"is_partial":false,"is_reconstructed":false,"confidence_score":1.0,"payload":{"provider":"bitflyer_ws_board","exchange":"bitflyer","transport":"websocket","channel":"lightning_board_BTC_JPY","received_ts":"2026-03-14T20:21:16.720223Z","subscription_id":null,"message_id":null,"source_sequence":null,"raw_message_meta":{"raw_channel":"lightning_board_BTC_JPY","subscription_channel":"lightning_board_BTC_JPY","recv_timeout_sec":10,"ssl_verify":false,"socket_url":"wss://ws.lightstream.bitflyer.com/json-rpc"},"source_payload":{"mid_price":11313218.0,"bids":[{"price":11308694.0,"size":0.0},{"price":11309258.0,"size":0.0},{"price":11296448.0,"size":0.0}],"asks":[]}}}
