{"schema_version":"collector.vnext.raw","schema_contract":null,"schema_contract_version":null,"payload_contract_version":null,"record_type":"market.orderbook.snapshot","record_id":"collector_main-market-orderbook-snapshot-000000000135","collector_id":"collector_main","collector_role":"production","host_name":"MAIN-PC","session_id":"collector_main-sess-20260314T201821Z-d6b39d6f","stream_session_id":"collector_main-stream-bitflyer-board_ws-20260314T202111Z-741228e4","exchange":"bitflyer","market":"spot","symbol":"BTC_JPY","instrument_id":"bitflyer.spot.BTC_JPY","channel":"board_ws","transport":"websocket","source_event_id":null,"source_sequence":null,"sequence_id":135,"exchange_ts":null,"collector_ts":"2026-03-14T20:21:16Z","ingest_ts":"2026-03-14T20:21:16Z","event_ts":"2026-03-14T20:21:16Z","quality_flags":[],"is_partial":false,"is_reconstructed":false,"confidence_score":1.0,"payload":{"provider":"bitflyer_ws_board_snapshot","exchange":"bitflyer","transport":"websocket","channel":"lightning_board_snapshot_BTC_JPY","received_ts":"2026-03-14T20:21:16.860609Z","subscription_id":null,"message_id":null,"source_sequence":null,"raw_message_meta":{"raw_channel":"lightning_board_snapshot_BTC_JPY","subscription_channel":"lightning_board_snapshot_BTC_JPY","recv_timeout_sec":10,"ssl_verify":false,"socket_url":"wss://ws.lightstream.bitflyer.com/json-rpc"},"source_payload":{"mid_price":11313218.0,"bids":[{"price":11310658.0,"size":0.0099986},{"price":11308660.0,"size":0.05364819},{"price":11308659.0,"size":0.014436},{"price":11308342.0,"size":0.014712},{"price":11307997.0,"size":0.014412},{"price":11307030.0,"size":0.0176863},{"price":11306996.0,"size":0.1275},{"price":11306995.0,"size":0.02},{"price":11306994.0,"size":0.015744},{"price":11306590.0,"size":0.02},{"price":11306589.0,"size":0.2},{"price":11304852.0,"size":0.02},{"price":11304588.0,"size":0.02},{"price":11304587.0,"size":0.5},{"price":11304585.0,"size":0.01},{"price":11302830.0,"size":0.05},{"price":11302664.0,"size":0.0525312},{"price":11302264.0,"size":0.05},{"price":11302033.0,"size":0.053},{"price":11301606.0,"size":0.5},{"price":11301012.0,"size":2.67454924},{"price":11300649.0,"size":0.001},{"price":11300093.0,"size":0.3429849},{"price":11299950.0,"size":0.0801},{"price":11299901.0,"size":0.0099986},{"price":11297444.0,"size":0.1},{"price":11288003.0,"size":0.309},{"price":11287193.0,"size":0.002},{"price":11286088.0,"size":0.18915459},{"price":11285264.0,"size":0.29858071},{"price":11285263.0,"size":1.484},{"price":11285241.0,"size":0.3032},{"price":11283799.0,"size":0.002},{"price":11282479.0,"size":0.3019},{"price":11280405.0,"size":0.002},{"price":11280205.0,"size":0.001},{"price":11279717.0,"size":0.2947},{"price":11279282.0,"size":0.0015},{"price":11277748.0,"size":0.0966561},{"price":11277602.0,"size":0.005},{"price":11277271.0,"size":0.6},{"price":11277011.0,"size":0.002},{"price":11275102.0,"size":0.01},{"price":11275000.0,"size":0.001},{"price":11274621.0,"size":0.6},{"price":11274588.0,"size":0.0047},{"price":11273617.0,"size":0.002},{"price":11271000.0,"size":0.003},{"price":11270223.0,"size":0.002},{"price":11270000.0,"size":0.106},{"price":11268871.0,"size":0.281},{"price":11268411.0,"size":0.01},{"price":11266829.0,"size":1.968},{"price":11266666.0,"size":0.04},{"price":11265000.0,"size":0.02},{"price":11263435.0,"size":0.002},{"price":11263000.0,"size":0.006},{"price":11262564.0,"size":0.0015},{"price":11262476.0,"size":1.79},{"price":11260041.0,"size":0.002},{"price":11260000.0,"size":0.3565},{"price":11257537.0,"size":0.001},{"price":11257000.0,"size":0.001},{"price":11256647.0,"size":0.002},{"price":11255200.0,"size":0.001},{"price":11255115.0,"size":0.00377},{"price":11253628.0,"size":2.036},{"price":11253000.0,"size":0.03189},{"price":11251000.0,"size":0.0131},{"price":11250250.0,"size":0.00105},{"price":11250200.0,"size":0.001},{"price":11250100.0,"size":0.015},{"price":11250005.0,"size":0.001},{"price":11250001.0,"size":0.00104},{"price":11250000.0,"size":0.76834},{"price":11246544.0,"size":0.0015},{"price":11246203.0,"size":0.001},{"price":11245141.0,"size":0.0031},{"price":11245000.0,"size":0.05},{"price":11244444.0,"size":0.04},{"price":11244243.0,"size":0.01},{"price":11240200.0,"size":0.001},{"price":11240000.0,"size":0.007304},{"price":11236190.0,"size":0.01},{"price":11235200.0,"size":0.001},{"price":11234869.0,"size":0.001},{"price":11232000.0,"size":0.089},{"price":11231243.0,"size":0.01},{"price":11231000.0,"size":0.105},{"price":11230200.0,"size":0.001},{"price":11230000.0,"size":0.0308},{"price":11228423.0,"size":1.951},{"price":11224500.0,"size":0.06},{"price":11224355.0,"size":0.0015},{"price":11223968.0,"size":0.001},{"price":11223535.0,"size":0.001},{"price":11223344.0,"size":0.01},{"price":11223000.0,"size":0.1},{"price":11222222.0,"size":0.092525},{"price":11221459.0,"size":0.1393},{"price":11221120.0,"size":0.011},{"price":11220200.0,"size":0.001},{"price":11220001.0,"size":0.004457},{"price":11220000.0,"size":0.321},{"price":11219517.0,"size":0.01},{"price":11219000.0,"size":0.1},{"price":11215200.0,"size":0.001},{"price":11215000.0,"size":0.02},{"price":11212358.0,"size":1.2},{"price":11212201.0,"size":0.001},{"price":11211800.0,"size":0.001},{"price":11211111.0,"size":0.06},{"price":11210200.0,"size":0.001},{"price":11210000.0,"size":0.10622},{"price":11208032.0,"size":0.01},{"price":11207755.0,"size":0.0015},{"price":11206000.0,"size":0.09015},{"price":11205200.0,"size":0.001},{"price":11204578.0,"size":0.002},{"price":11203931.0,"size":1.0},{"price":11201000.0,"size":0.01},{"price":11200867.0,"size":0.001},{"price":11200800.0,"size":0.05},{"price":11200425.0,"size":0.1},{"price":11200200.0,"size":0.001},{"price":11200198.0,"size":0.003},{"price":11200150.0,"size":0.002},{"price":11200002.0,"size":0.001},{"price":11200001.0,"size":0.01104},{"price":11200000.0,"size":1.35988728},{"price":11198508.0,"size":0.05},{"price":11198243.0,"size":0.01},{"price":11197134.0,"size":2.993},{"price":11197000.0,"size":0.0085},{"price":11195692.0,"size":0.0015},{"price":11194090.0,"size":0.03},{"price":11190770.0,"size":0.0309},{"price":11190000.0,"size":0.0010016},{"price":11189555.0,"size":0.5},{"price":11189533.0,"size":0.001},{"price":11188629.0,"size":0.01},{"price":11188382.0,"size":0.001},{"price":11185000.0,"size":0.0085},{"price":11180043.0,"size":0.972},{"price":11180000.0,"size":0.23215},{"price":11178973.0,"size":0.0015},{"price":11178199.0,"size":0.001},{"price":11170000.0,"size":0.001},{"price":11169662.0,"size":0.01},{"price":11169593.0,"size":0.001},{"price":11169243.0,"size":0.01},{"price":11166865.0,"size":0.001},{"price":11164029.0,"size":0.001},{"price":11160854.0,"size":0.1},{"price":11160000.0,"size":0.02376},{"price":11156269.0,"size":0.01},{"price":11155531.0,"size":0.001},{"price":11155377.0,"size":0.00636009},{"price":11153999.0,"size":0.00101},{"price":11151000.0,"size":0.001},{"price":11150250.0,"size":0.00175},{"price":11150005.0,"size":0.001},{"price":11150001.0,"size":0.00104},{"price":11150000.0,"size":0.6398956},{"price":11148000.0,"size":0.08963},{"price":11144197.0,"size":0.001},{"price":11144000.0,"size":0.0897},{"price":11140000.0,"size":0.2},{"price":11136243.0,"size":0.01},{"price":11136155.0,"size":0.02},{"price":11135869.0,"size":0.1},{"price":11130000.0,"size":0.116},{"price":11129979.0,"size":0.0053908},{"price":11126388.0,"size":0.02},{"price":11124900.0,"size":0.00133},{"price":11121090.0,"size":0.1},{"price":11120000.0,"size":0.0033},{"price":11118078.0,"size":0.01},{"price":11111800.0,"size":0.001},{"price":11111111.0,"size":0.2919257},{"price":11111000.0,"size":0.003},{"price":11110594.0,"size":0.001},{"price":11110000.0,"size":0.056937},{"price":11109662.0,"size":0.01},{"price":11108008.0,"size":0.01},{"price":11106000.0,"size":0.2},{"price":11105000.0,"size":0.02},{"price":11101297.0,"size":0.001},{"price":11100005.0,"size":0.001},{"price":11100001.0,"size":0.01104},{"price":11100000.0,"size":1.7472049},{"price":11099141.0,"size":0.01},{"price":11096243.0,"size":0.01},{"price":11094090.0,"size":0.01},{"price":11088888.0,"size":0.001},{"price":11085245.0,"size":0.001},{"price":11080200.0,"size":0.001},{"price":11080000.0,"size":0.0223},{"price":11075100.0,"size":0.003},{"price":11071558.0,"size":1.0},{"price":11070200.0,"size":0.001},{"price":11070000.0,"size":0.0902},{"price":11065200.0,"size":0.001},{"price":11064370.0,"size":0.00497091},{"price":11060200.0,"size":0.001},{"price":11060000.0,"size":0.145},{"price":11059689.0,"size":0.009},{"price":11056428.0,"size":0.002},{"price":11055500.0,"size":0.02},{"price":11055200.0,"size":0.001},{"price":11055100.0,"size":0.003},{"price":11050200.0,"size":0.001},{"price":11050005.0,"size":0.001},{"price":11050002.0,"size":0.001},{"price":11050001.0,"size":0.00104},{"price":11050000.0,"size":0.43176147},{"price":11046420.0,"size":0.2},{"price":11044243.0,"size":0.01},{"price":11041380.0,"size":0.01},{"price":11040200.0,"size":0.001},{"price":11040000.0,"size":0.00777181},{"price":11035865.0,"size":0.1},{"price":11035200.0,"size":0.001},{"price":11035000.0,"size":0.0013},{"price":11030200.0,"size":0.001},{"price":11030000.0,"size":0.025},{"price":11025500.0,"size":0.009531},{"price":11025200.0,"size":0.001},{"price":11025000.0,"size":0.71497},{"price":11020772.0,"size":0.014},{"price":11020200.0,"size":0.002},{"price":11020000.0,"size":0.005},{"price":11015200.0,"size":0.001},{"price":11012000.0,"size":0.1},{"price":11011800.0,"size":0.001},{"price":11010200.0,"size":0.001},{"price":11010000.0,"size":0.347},{"price":11007277.0,"size":0.01},{"price":11006000.0,"size":0.2},{"price":11005200.0,"size":0.001},{"price":11004890.0,"size":0.001535},{"price":11003000.0,"size":0.0155},{"price":11001000.0,"size":0.013},{"price":11000500.0,"size":0.05117658},{"price":11000200.0,"size":0.001},{"price":11000002.0,"size":0.004},{"price":11000001.0,"size":0.02604},{"price":11000000.0,"size":4.55923365},{"price":10999999.0,"size":0.003},{"price":10999000.0,"size":0.001},{"price":10996855.0,"size":0.0011},{"price":10995200.0,"size":0.001},{"price":10994499.0,"size":0.00169176},{"price":10990200.0,"size":0.001},{"price":10990000.0,"size":0.10219},{"price":10989001.0,"size":0.00197},{"price":10988999.0,"size":0.001},{"price":10988324.0,"size":0.002},{"price":10987654.0,"size":0.001},{"price":10985200.0,"size":0.001},{"price":10985150.0,"size":0.01},{"price":10980500.0,"size":0.005},{"price":10980200.0,"size":0.001},{"price":10980002.0,"size":0.4},{"price":10980000.0,"size":0.028},{"price":10975200.0,"size":0.001},{"price":10975000.0,"size":0.1},{"price":10971261.0,"size":0.001},{"price":10971243.0,"size":0.01},{"price":10970375.0,"size":1.9},{"price":10970200.0,"size":0.001},{"price":10970000.0,"size":0.09304},{"price":10966600.0,"size":0.001003},{"price":10965200.0,"size":0.001},{"price":10960200.0,"size":0.001},{"price":10960000.0,"size":0.0083},{"price":10956673.0,"size":0.01},{"price":10955200.0,"size":0.001},{"price":10954950.0,"size":0.001},{"price":10950500.0,"size":0.005},{"price":10950001.0,"size":0.00204},{"price":10950000.0,"size":0.5485028},{"price":10949550.0,"size":0.01870657},{"price":10949172.0,"size":0.1},{"price":10948000.0,"size":0.1},{"price":10945243.0,"size":0.01},{"price":10940402.0,"size":0.001},{"price":10940200.0,"size":0.001},{"price":10940000.0,"size":0.331},{"price":10938243.0,"size":0.01},{"price":10936200.0,"size":0.00137},{"price":10935200.0,"size":0.001},{"price":10930200.0,"size":0.002},{"price":10930000.0,"size":0.0193},{"price":10925200.0,"size":0.002},{"price":10924451.0,"size":0.0012},{"price":10920509.0,"size":0.01},{"price":10920200.0,"size":0.002},{"price":10920000.0,"size":0.52},{"price":10915200.0,"size":0.001}],"asks":[{"price":11315779.0,"size":0.05632588},{"price":11315780.0,"size":0.1958},{"price":11316321.0,"size":0.02},{"price":11316322.0,"size":0.005},{"price":11316543.0,"size":0.02},{"price":11316544.0,"size":0.00908554},{"price":11317636.0,"size":0.02},{"price":11317637.0,"size":0.285},{"price":11318050.0,"size":0.002},{"price":11318668.0,"size":0.02},{"price":11318876.0,"size":0.02},{"price":11319398.0,"size":0.4199},{"price":11319467.0,"size":0.015432},{"price":11319751.0,"size":0.015288},{"price":11320000.0,"size":0.02},{"price":11320281.0,"size":0.015},{"price":11320399.0,"size":0.2775},{"price":11320832.0,"size":0.0551232},{"price":11321446.0,"size":0.01},{"price":11322000.0,"size":0.005},{"price":11322701.0,"size":0.0529},{"price":11323103.0,"size":0.57573796},{"price":11323161.0,"size":0.2662},{"price":11324837.0,"size":0.01},{"price":11324998.0,"size":0.2},{"price":11325923.0,"size":0.2764},{"price":11328050.0,"size":0.002},{"price":11329041.0,"size":0.002851},{"price":11329436.0,"size":0.0015},{"price":11331059.0,"size":0.001},{"price":11338261.0,"size":0.6106705},{"price":11338262.0,"size":1.489},{"price":11340000.0,"size":0.13586406},{"price":11340646.0,"size":0.33149392},{"price":11340647.0,"size":0.001},{"price":11342955.0,"size":0.33696233},{"price":11342956.0,"size":1.60199848},{"price":11342957.0,"size":0.01},{"price":11346154.0,"size":0.0015},{"price":11348000.0,"size":0.1999},{"price":11348521.0,"size":1.928},{"price":11349700.0,"size":0.001},{"price":11350000.0,"size":0.022},{"price":11353877.0,"size":0.001},{"price":11354939.0,"size":0.01},{"price":11355555.0,"size":0.001},{"price":11359242.0,"size":0.0011},{"price":11359700.0,"size":0.001},{"price":11362692.0,"size":0.0015},{"price":11365211.0,"size":0.001},{"price":11369700.0,"size":0.001},{"price":11370000.0,"size":0.1},{"price":11372478.0,"size":1.943},{"price":11376000.0,"size":0.02},{"price":11376545.0,"size":0.001},{"price":11377000.0,"size":0.2287},{"price":11377269.0,"size":0.002},{"price":11379471.0,"size":2.018},{"price":11379700.0,"size":0.001},{"price":11379865.0,"size":0.03},{"price":11380000.0,"size":0.0223},{"price":11380324.0,"size":0.002},{"price":11381766.0,"size":0.4},{"price":11382386.0,"size":0.0015},{"price":11385000.0,"size":0.2548},{"price":11385403.0,"size":0.002},{"price":11385664.0,"size":0.002},{"price":11386197.0,"size":0.002},{"price":11387072.0,"size":0.01},{"price":11387354.0,"size":0.002},{"price":11387879.0,"size":0.001},{"price":11388885.0,"size":0.03},{"price":11389700.0,"size":0.001},{"price":11390000.0,"size":0.2488},{"price":11390050.0,"size":0.001},{"price":11392387.0,"size":1.0},{"price":11394939.0,"size":0.01},{"price":11395000.0,"size":0.06},{"price":11395775.0,"size":0.01},{"price":11396555.0,"size":0.03},{"price":11398444.0,"size":0.001995},{"price":11399213.0,"size":0.001},{"price":11399673.0,"size":0.0015},{"price":11399700.0,"size":0.001},{"price":11400000.0,"size":0.5225},{"price":11405000.0,"size":0.0275},{"price":11406336.0,"size":1.0},{"price":11408700.0,"size":0.001},{"price":11409415.0,"size":0.055},{"price":11410000.0,"size":0.03},{"price":11410547.0,"size":0.001},{"price":11410853.0,"size":0.002},{"price":11412000.0,"size":0.0878},{"price":11415000.0,"size":0.002},{"price":11415141.0,"size":0.0041},{"price":11417481.0,"size":0.0015},{"price":11418700.0,"size":0.001},{"price":11420000.0,"size":0.401},{"price":11421268.0,"size":0.05},{"price":11421881.0,"size":0.001},{"price":11423339.0,"size":2.0},{"price":11424296.0,"size":0.002},{"price":11424941.0,"size":0.972},{"price":11425000.0,"size":0.049},{"price":11426426.0,"size":0.002},{"price":11428121.0,"size":0.002},{"price":11428700.0,"size":0.001},{"price":11429302.0,"size":0.01},{"price":11432718.0,"size":0.002},{"price":11433211.0,"size":0.03},{"price":11433215.0,"size":0.001},{"price":11433333.0,"size":0.001},{"price":11437315.0,"size":0.002},{"price":11438525.0,"size":0.0011},{"price":11438700.0,"size":0.001},{"price":11439557.0,"size":0.001},{"price":11440000.0,"size":0.1038},{"price":11441911.0,"size":0.002},{"price":11443629.0,"size":0.002},{"price":11444549.0,"size":0.001},{"price":11446508.0,"size":0.001},{"price":11447000.0,"size":0.01},{"price":11447071.0,"size":0.002},{"price":11448000.0,"size":0.0875},{"price":11448700.0,"size":0.001},{"price":11450000.0,"size":0.258},{"price":11451105.0,"size":0.002},{"price":11453321.0,"size":0.03},{"price":11455702.0,"size":0.002},{"price":11455883.0,"size":0.001},{"price":11458700.0,"size":0.001},{"price":11458988.0,"size":0.01},{"price":11460000.0,"size":0.01702},{"price":11460299.0,"size":0.002},{"price":11464896.0,"size":0.002},{"price":11467217.0,"size":0.001},{"price":11468700.0,"size":0.001},{"price":11470000.0,"size":0.01},{"price":11471000.0,"size":0.01},{"price":11475000.0,"size":0.0028},{"price":11478431.0,"size":0.002},{"price":11478551.0,"size":0.001},{"price":11478700.0,"size":0.001},{"price":11480000.0,"size":0.12491},{"price":11485000.0,"size":0.01},{"price":11486555.0,"size":0.03},{"price":11487685.0,"size":0.01},{"price":11488000.0,"size":0.102},{"price":11488700.0,"size":0.001},{"price":11489885.0,"size":0.001},{"price":11495850.0,"size":0.001},{"price":11498700.0,"size":0.001},{"price":11498917.0,"size":0.002},{"price":11499000.0,"size":0.01},{"price":11500000.0,"size":0.69859519},{"price":11501219.0,"size":0.001},{"price":11502377.0,"size":0.002},{"price":11502800.0,"size":0.00132},{"price":11503108.0,"size":0.0198},{"price":11505000.0,"size":0.0028},{"price":11505001.0,"size":0.002},{"price":11505836.0,"size":0.003},{"price":11508431.0,"size":0.047},{"price":11508700.0,"size":0.001},{"price":11508888.0,"size":0.02},{"price":11510000.0,"size":0.0976},{"price":11512553.0,"size":0.001},{"price":11513633.0,"size":0.08},{"price":11514332.0,"size":0.02},{"price":11518700.0,"size":0.001},{"price":11519855.0,"size":0.01},{"price":11520000.0,"size":0.001},{"price":11522423.0,"size":0.97},{"price":11523211.0,"size":0.01},{"price":11523887.0,"size":0.001},{"price":11524999.0,"size":0.001},{"price":11528700.0,"size":0.001},{"price":11529852.0,"size":0.01},{"price":11530000.0,"size":0.261},{"price":11533985.0,"size":0.002},{"price":11534084.0,"size":0.001},{"price":11535321.0,"size":0.01},{"price":11538666.0,"size":0.002},{"price":11538700.0,"size":0.001},{"price":11540000.0,"size":0.0048},{"price":11541011.0,"size":0.005},{"price":11541109.0,"size":0.01},{"price":11544663.0,"size":0.002},{"price":11546541.0,"size":0.01},{"price":11548144.0,"size":0.002},{"price":11548700.0,"size":0.001},{"price":11550000.0,"size":0.014},{"price":11551109.0,"size":0.01},{"price":11551625.0,"size":0.002},{"price":11552111.0,"size":0.01},{"price":11553687.0,"size":0.1},{"price":11555106.0,"size":0.002},{"price":11555115.0,"size":0.001},{"price":11556000.0,"size":0.1},{"price":11558587.0,"size":0.002},{"price":11558700.0,"size":0.001},{"price":11559855.0,"size":0.01},{"price":11560831.0,"size":0.0198},{"price":11561109.0,"size":0.01},{"price":11562000.0,"size":0.087},{"price":11562068.0,"size":0.002},{"price":11565548.0,"size":0.002},{"price":11566139.0,"size":0.0228},{"price":11566551.0,"size":0.01},{"price":11568700.0,"size":0.001},{"price":11569029.0,"size":0.002},{"price":11571109.0,"size":0.01},{"price":11572510.0,"size":0.002},{"price":11573211.0,"size":0.01},{"price":11575991.0,"size":0.001},{"price":11578700.0,"size":0.001},{"price":11579851.0,"size":0.01},{"price":11580000.0,"size":0.7735},{"price":11581109.0,"size":0.01},{"price":11585000.0,"size":0.002},{"price":11586532.0,"size":0.01},{"price":11587498.0,"size":0.0198},{"price":11588700.0,"size":0.001},{"price":11589612.0,"size":0.012},{"price":11590000.0,"size":0.1},{"price":11590749.0,"size":0.002},{"price":11591109.0,"size":0.01},{"price":11593211.0,"size":0.01},{"price":11598555.0,"size":0.01},{"price":11598700.0,"size":0.001},{"price":11599999.0,"size":0.001},{"price":11600000.0,"size":3.6141},{"price":11601109.0,"size":0.02},{"price":11606655.0,"size":0.01},{"price":11610000.0,"size":0.302},{"price":11611109.0,"size":0.01},{"price":11613321.0,"size":0.01},{"price":11620000.0,"size":1.35441682},{"price":11621011.0,"size":0.01},{"price":11621109.0,"size":0.01},{"price":11623096.0,"size":0.008},{"price":11629000.0,"size":0.1},{"price":11630000.0,"size":0.201},{"price":11631059.0,"size":0.01},{"price":11631479.0,"size":0.01},{"price":11631773.0,"size":0.00386871},{"price":11635950.0,"size":0.001},{"price":11638259.0,"size":0.001},{"price":11639700.0,"size":0.001},{"price":11640000.0,"size":1.0},{"price":11640820.0,"size":0.01},{"price":11645040.0,"size":1.7},{"price":11645295.0,"size":0.05},{"price":11647158.0,"size":0.05},{"price":11649900.0,"size":0.02906},{"price":11649999.0,"size":0.001},{"price":11650000.0,"size":0.593},{"price":11651059.0,"size":0.01},{"price":11653658.0,"size":0.008},{"price":11654321.0,"size":0.001},{"price":11659700.0,"size":0.001},{"price":11661479.0,"size":0.01},{"price":11666000.0,"size":0.001},{"price":11666666.0,"size":0.013},{"price":11669700.0,"size":0.001},{"price":11671059.0,"size":0.01},{"price":11672562.0,"size":0.0198},{"price":11679224.0,"size":0.012},{"price":11680000.0,"size":0.004},{"price":11685000.0,"size":0.003},{"price":11688000.0,"size":0.001},{"price":11689732.0,"size":0.01},{"price":11690330.0,"size":0.0198},{"price":11691059.0,"size":0.01},{"price":11692558.0,"size":0.01},{"price":11698800.0,"size":0.00131},{"price":11699000.0,"size":0.001},{"price":11699631.0,"size":0.001},{"price":11699998.0,"size":0.01},{"price":11699999.0,"size":0.001},{"price":11700000.0,"size":1.03762841},{"price":11701059.0,"size":0.01},{"price":11720000.0,"size":0.1},{"price":11721059.0,"size":0.01},{"price":11725000.0,"size":0.005},{"price":11726791.0,"size":0.01},{"price":11730000.0,"size":0.9382},{"price":11740000.0,"size":0.101},{"price":11741059.0,"size":0.01},{"price":11748937.0,"size":0.001},{"price":11749999.0,"size":0.001},{"price":11750000.0,"size":0.90537866},{"price":11750050.0,"size":0.2},{"price":11751151.0,"size":0.01},{"price":11755000.0,"size":0.001},{"price":11757860.0,"size":1.82},{"price":11759999.0,"size":0.001},{"price":11760000.0,"size":0.001},{"price":11761059.0,"size":0.02},{"price":11765432.0,"size":0.001}]}}}
{"schema_version":"collector.vnext.raw","schema_contract":null,"schema_contract_version":null,"payload_contract_version":null,"record_type":"market.orderbook.diff","record_id":"collector_main-market-orderbook-diff-000000000061","collector_id":"collector_main","collector_role":"production","host_name":"MAIN-PC","session_id":"collector_main-sess-20260314T202131Z-dc226056","stream_session_id":"collector_main-stream-bitflyer-board_ws-20260314T202406Z-40175e62","exchange":"bitflyer","market":"spot","symbol":"BTC_JPY","instrument_id":"bitflyer.spot.BTC_JPY","channel":"board_ws","transport":"websocket","source_event_id":null,"source_sequence":null,"sequence_id":61,"exchange_ts":null,"collector_ts":"2026-03-14T20:24:06Z","ingest_ts":"2026-03-14T20:24:06Z","event_ts":"2026-03-14T20:24:06Z","quality_flags":[],"is_partial":false,"is_reconstructed":false,"confidence_score":1.0,"payload":{"provider":"bitflyer_ws_board","exchange":"bitflyer","transport":"websocket","channel":"lightning_board_BTC_JPY","received_ts":"2026-03-14T20:24:06.940111Z","subscription_id":null,"message_id":null,"source_sequence":null,"raw_message_meta":{"raw_channel":"lightning_board_BTC_JPY","subscription_channel":"lightning_board_BTC_JPY","recv_timeout_sec":10,"ssl_verify":false,"socket_url":"wss://ws.lightstream.bitflyer.com/json-rpc"},"source_payload":{"mid_price":11315677.0,"bids":[{"price":11312520.0,"size":0.0},{"price":11312484.0,"size":0.0537526}],"asks":[{"price":11317520.0,"size":0.0},{"price":11317148.0,"size":0.2077},{"price":11327359.0,"size":0.0}]}}}
{"schema_version":"collector.vnext.raw","schema_contract":null,"schema_contract_version":null,"payload_contract_version":null,"record_type":"market.orderbook.diff","record_id":"collector_main-market-orderbook-diff-000000000065","collector_id":"collector_main","collector_role":"production","host_name":"MAIN-PC","session_id":"collector_main-sess-20260314T202131Z-dc226056","stream_session_id":"collector_main-stream-bitflyer-board_ws-20260314T202406Z-40175e62","exchange":"bitflyer","market":"spot","symbol":"BTC_JPY","instrument_id":"bitflyer.spot.BTC_JPY","channel":"board_ws","transport":"websocket","source_event_id":null,"source_sequence":null,"sequence_id":65,"exchange_ts":null,"collector_ts":"2026-03-14T20:24:07Z","ingest_ts":"2026-03-14T20:24:07Z","event_ts":"2026-03-14T20:24:07Z","quality_flags":[],"is_partial":false,"is_reconstructed":false,"confidence_score":1.0,"payload":{"provider":"bitflyer_ws_board","exchange":"bitflyer","transport":"websocket","channel":"lightning_board_BTC_JPY","received_ts":"2026-03-14T20:24:07.067937Z","subscription_id":null,"message_id":null,"source_sequence":null,"raw_message_meta":{"raw_channel":"lightning_board_BTC_JPY","subscription_channel":"lightning_board_BTC_JPY","recv_timeout_sec":10,"ssl_verify":false,"socket_url":"wss://ws.lightstream.bitflyer.com/json-rpc"},"source_payload":{"mid_price":11315677.0,"bids":[{"price":11304461.0,"size":0.0},{"price":11312484.0,"size":0.0},{"price":11312521.0,"size":0.05114852}],"asks":[{"price":11319418.0,"size":0.015168}]}}}
{"schema_version":"collector.vnext.raw","schema_contract":null,"schema_contract_version":null,"payload_contract_version":null,"record_type":"market.orderbook.snapshot","record_id":"collector_main-market-orderbook-snapshot-000000000067","collector_id":"collector_main","collector_role":"production","host_name":"MAIN-PC","session_id":"collector_main-sess-20260314T202131Z-dc226056","stream_session_id":"collector_main-stream-bitflyer-board_ws-20260314T202406Z-40175e62","exchange":"bitflyer","market":"spot","symbol":"BTC_JPY","instrument_id":"bitflyer.spot.BTC_JPY","channel":"board_ws","transport":"websocket","source_event_id":null,"source_sequence":null,"sequence_id":67,"exchange_ts":null,"collector_ts":"2026-03-14T20:24:07Z","ingest_ts":"2026-03-14T20:24:07Z","event_ts":"2026-03-14T20:24:07Z","quality_flags":[],"is_partial":false,"is_reconstructed":false,"confidence_score":1.0,"payload":{"provider":"bitflyer_ws_board_snapshot","exchange":"bitflyer","transport":"websocket","channel":"lightning_board_snapshot_BTC_JPY","received_ts":"2026-03-14T20:24:07.095129Z","subscription_id":null,"message_id":null,"source_sequence":null,"raw_message_meta":{"raw_channel":"lightning_board_snapshot_BTC_JPY","subscription_channel":"lightning_board_snapshot_BTC_JPY","recv_timeout_sec":10,"ssl_verify":false,"socket_url":"wss://ws.lightstream.bitflyer.com/json-rpc"},"source_payload":{"mid_price":11315677.0,"bids":[{"price":11314207.0,"size":0.001},{"price":11312521.0,"size":0.05114852},{"price":11312185.0,"size":0.014772},{"price":11311564.0,"size":0.0176792},{"price":11311529.0,"size":0.02},{"price":11311528.0,"size":0.014472},{"price":11311148.0,"size":0.02},{"price":11311147.0,"size":0.014412},{"price":11309226.0,"size":0.1275},{"price":11309225.0,"size":0.1275},{"price":11308450.0,"size":0.05},{"price":11308411.0,"size":0.2},{"price":11308136.0,"size":0.5},{"price":11307884.0,"size":0.05},{"price":11307133.0,"size":0.5},{"price":11305643.0,"size":0.0530064},{"price":11304854.0,"size":2.97155792},{"price":11304585.0,"size":0.01},{"price":11302471.0,"size":0.001},{"price":11299950.0,"size":0.0801},{"price":11297444.0,"size":0.1},{"price":11291323.0,"size":0.31183619},{"price":11291322.0,"size":0.312},{"price":11291187.0,"size":0.6},{"price":11290357.0,"size":0.002},{"price":11288560.0,"size":0.2886},{"price":11286090.0,"size":0.18915459},{"price":11286089.0,"size":0.3060516},{"price":11285830.0,"size":0.002},{"price":11285798.0,"size":0.3026},{"price":11285264.0,"size":0.29858071},{"price":11285263.0,"size":1.484},{"price":11283036.0,"size":0.2958},{"price":11281303.0,"size":0.002},{"price":11280205.0,"size":0.001},{"price":11279282.0,"size":0.0015},{"price":11277748.0,"size":0.0966561},{"price":11277602.0,"size":0.005},{"price":11277271.0,"size":0.6},{"price":11276776.0,"size":0.002},{"price":11275102.0,"size":0.01},{"price":11275000.0,"size":0.001},{"price":11274588.0,"size":0.0047},{"price":11272249.0,"size":0.002},{"price":11271000.0,"size":0.003},{"price":11270000.0,"size":0.106},{"price":11268871.0,"size":0.281},{"price":11268411.0,"size":0.01},{"price":11267722.0,"size":0.002},{"price":11266829.0,"size":1.966},{"price":11266666.0,"size":0.04},{"price":11265000.0,"size":0.02},{"price":11263195.0,"size":0.002},{"price":11263000.0,"size":0.006},{"price":11262564.0,"size":0.0015},{"price":11260000.0,"size":0.3565},{"price":11258668.0,"size":0.002},{"price":11257537.0,"size":0.001},{"price":11257000.0,"size":0.001},{"price":11255200.0,"size":0.001},{"price":11255115.0,"size":0.00377},{"price":11254141.0,"size":0.002},{"price":11253628.0,"size":2.036},{"price":11253000.0,"size":0.03189},{"price":11251000.0,"size":0.0131},{"price":11250250.0,"size":0.00105},{"price":11250200.0,"size":0.001},{"price":11250100.0,"size":0.015},{"price":11250005.0,"size":0.001},{"price":11250001.0,"size":0.00104},{"price":11250000.0,"size":0.76834},{"price":11249614.0,"size":0.002},{"price":11246544.0,"size":0.0015},{"price":11246203.0,"size":0.001},{"price":11245141.0,"size":0.0031},{"price":11245000.0,"size":0.05},{"price":11244444.0,"size":0.04},{"price":11244243.0,"size":0.01},{"price":11240200.0,"size":0.001},{"price":11240000.0,"size":0.007304},{"price":11236190.0,"size":0.01},{"price":11235200.0,"size":0.001},{"price":11234869.0,"size":0.001},{"price":11232000.0,"size":0.089},{"price":11231243.0,"size":0.01},{"price":11231000.0,"size":0.105},{"price":11230200.0,"size":0.001},{"price":11230000.0,"size":0.0308},{"price":11228423.0,"size":1.951},{"price":11224500.0,"size":0.06},{"price":11224355.0,"size":0.0015},{"price":11223968.0,"size":0.001},{"price":11223535.0,"size":0.001},{"price":11223344.0,"size":0.01},{"price":11223000.0,"size":0.1},{"price":11222222.0,"size":0.092525},{"price":11221459.0,"size":0.1393},{"price":11221120.0,"size":0.011},{"price":11220756.0,"size":1.79},{"price":11220200.0,"size":0.001},{"price":11220001.0,"size":0.004457},{"price":11220000.0,"size":0.321},{"price":11219517.0,"size":0.01},{"price":11219000.0,"size":0.1},{"price":11215200.0,"size":0.001},{"price":11215000.0,"size":0.02},{"price":11212358.0,"size":1.2},{"price":11212201.0,"size":0.001},{"price":11211800.0,"size":0.001},{"price":11211111.0,"size":0.06},{"price":11210200.0,"size":0.001},{"price":11210000.0,"size":0.10622},{"price":11208032.0,"size":0.01},{"price":11207755.0,"size":0.0015},{"price":11206000.0,"size":0.09015},{"price":11205200.0,"size":0.001},{"price":11204578.0,"size":0.002},{"price":11203931.0,"size":1.0},{"price":11201000.0,"size":0.01},{"price":11200867.0,"size":0.001},{"price":11200800.0,"size":0.05},{"price":11200425.0,"size":0.1},{"price":11200200.0,"size":0.001},{"price":11200198.0,"size":0.003},{"price":11200150.0,"size":0.002},{"price":11200002.0,"size":0.001},{"price":11200001.0,"size":0.01104},{"price":11200000.0,"size":1.35988728},{"price":11198508.0,"size":0.05},{"price":11198243.0,"size":0.01},{"price":11197134.0,"size":2.993},{"price":11197000.0,"size":0.0085},{"price":11195692.0,"size":0.0015},{"price":11194090.0,"size":0.03},{"price":11190770.0,"size":0.0309},{"price":11190000.0,"size":0.0010016},{"price":11189555.0,"size":0.5},{"price":11189533.0,"size":0.001},{"price":11188629.0,"size":0.01},{"price":11188382.0,"size":0.001},{"price":11185000.0,"size":0.0085},{"price":11180043.0,"size":0.972},{"price":11180000.0,"size":0.23215},{"price":11178973.0,"size":0.0015},{"price":11178199.0,"size":0.001},{"price":11170000.0,"size":0.001},{"price":11169662.0,"size":0.01},{"price":11169593.0,"size":0.001},{"price":11169243.0,"size":0.01},{"price":11166865.0,"size":0.001},{"price":11164029.0,"size":0.001},{"price":11160854.0,"size":0.1},{"price":11160000.0,"size":0.02376},{"price":11156269.0,"size":0.01},{"price":11155531.0,"size":0.001},{"price":11155377.0,"size":0.00636009},{"price":11153999.0,"size":0.00101},{"price":11151000.0,"size":0.001},{"price":11150250.0,"size":0.00175},{"price":11150005.0,"size":0.001},{"price":11150001.0,"size":0.00104},{"price":11150000.0,"size":0.6398956},{"price":11148000.0,"size":0.08963},{"price":11144197.0,"size":0.001},{"price":11144000.0,"size":0.0897},{"price":11140000.0,"size":0.2},{"price":11136243.0,"size":0.01},{"price":11136155.0,"size":0.02},{"price":11135869.0,"size":0.1},{"price":11130000.0,"size":0.116},{"price":11129979.0,"size":0.0053908},{"price":11126388.0,"size":0.02},{"price":11124900.0,"size":0.00133},{"price":11121090.0,"size":0.1},{"price":11120000.0,"size":0.0033},{"price":11118078.0,"size":0.01},{"price":11111800.0,"size":0.001},{"price":11111111.0,"size":0.2919257},{"price":11111000.0,"size":0.003},{"price":11110594.0,"size":0.001},{"price":11110000.0,"size":0.056937},{"price":11109662.0,"size":0.01},{"price":11108008.0,"size":0.01},{"price":11106000.0,"size":0.2},{"price":11105000.0,"size":0.02},{"price":11101297.0,"size":0.001},{"price":11100005.0,"size":0.001},{"price":11100001.0,"size":0.01104},{"price":11100000.0,"size":1.7472049},{"price":11099141.0,"size":0.01},{"price":11096243.0,"size":0.01},{"price":11094090.0,"size":0.01},{"price":11088888.0,"size":0.001},{"price":11085245.0,"size":0.001},{"price":11080200.0,"size":0.001},{"price":11080000.0,"size":0.0223},{"price":11075100.0,"size":0.003},{"price":11071558.0,"size":1.0},{"price":11070200.0,"size":0.001},{"price":11070000.0,"size":0.0902},{"price":11065200.0,"size":0.001},{"price":11064370.0,"size":0.00497091},{"price":11060200.0,"size":0.001},{"price":11060000.0,"size":0.145},{"price":11059689.0,"size":0.009},{"price":11056428.0,"size":0.002},{"price":11055500.0,"size":0.02},{"price":11055200.0,"size":0.001},{"price":11055100.0,"size":0.003},{"price":11050200.0,"size":0.001},{"price":11050005.0,"size":0.001},{"price":11050002.0,"size":0.001},{"price":11050001.0,"size":0.00104},{"price":11050000.0,"size":0.43176147},{"price":11046420.0,"size":0.2},{"price":11044243.0,"size":0.01},{"price":11041380.0,"size":0.01},{"price":11040200.0,"size":0.001},{"price":11040000.0,"size":0.00777181},{"price":11035865.0,"size":0.1},{"price":11035200.0,"size":0.001},{"price":11035000.0,"size":0.0013},{"price":11030200.0,"size":0.001},{"price":11030000.0,"size":0.025},{"price":11025500.0,"size":0.009531},{"price":11025200.0,"size":0.001},{"price":11025000.0,"size":0.71497},{"price":11020772.0,"size":0.014},{"price":11020200.0,"size":0.002},{"price":11020000.0,"size":0.005},{"price":11015200.0,"size":0.001},{"price":11012000.0,"size":0.1},{"price":11011800.0,"size":0.001},{"price":11010200.0,"size":0.001},{"price":11010000.0,"size":0.347},{"price":11007277.0,"size":0.01},{"price":11006000.0,"size":0.2},{"price":11005200.0,"size":0.001},{"price":11004890.0,"size":0.001535},{"price":11003000.0,"size":0.0155},{"price":11001000.0,"size":0.013},{"price":11000500.0,"size":0.05117658},{"price":11000200.0,"size":0.001},{"price":11000002.0,"size":0.004},{"price":11000001.0,"size":0.02604},{"price":11000000.0,"size":4.55923365},{"price":10999999.0,"size":0.003},{"price":10999000.0,"size":0.001},{"price":10996855.0,"size":0.0011},{"price":10995200.0,"size":0.001},{"price":10994499.0,"size":0.00169176},{"price":10990200.0,"size":0.001},{"price":10990000.0,"size":0.10219},{"price":10989001.0,"size":0.00197},{"price":10988999.0,"size":0.001},{"price":10988324.0,"size":0.002},{"price":10987654.0,"size":0.001},{"price":10985200.0,"size":0.001},{"price":10985150.0,"size":0.01},{"price":10980500.0,"size":0.005},{"price":10980200.0,"size":0.001},{"price":10980002.0,"size":0.4},{"price":10980000.0,"size":0.028},{"price":10975200.0,"size":0.001},{"price":10975000.0,"size":0.1},{"price":10971261.0,"size":0.001},{"price":10971243.0,"size":0.01},{"price":10970375.0,"size":1.9},{"price":10970200.0,"size":0.001},{"price":10970000.0,"size":0.09304},{"price":10966600.0,"size":0.001003},{"price":10965200.0,"size":0.001},{"price":10960200.0,"size":0.001},{"price":10960000.0,"size":0.0083},{"price":10956673.0,"size":0.01},{"price":10955200.0,"size":0.001},{"price":10954950.0,"size":0.001},{"price":10950500.0,"size":0.005},{"price":10950001.0,"size":0.00204},{"price":10950000.0,"size":0.5485028},{"price":10949550.0,"size":0.01870657},{"price":10949172.0,"size":0.1},{"price":10948000.0,"size":0.1},{"price":10945243.0,"size":0.01},{"price":10940402.0,"size":0.001},{"price":10940200.0,"size":0.001},{"price":10940000.0,"size":0.331},{"price":10938243.0,"size":0.01},{"price":10936200.0,"size":0.00137},{"price":10935200.0,"size":0.001},{"price":10930200.0,"size":0.002},{"price":10930000.0,"size":0.0193},{"price":10925200.0,"size":0.002},{"price":10924451.0,"size":0.0012},{"price":10920509.0,"size":0.01},{"price":10920200.0,"size":0.002},{"price":10920000.0,"size":0.52},{"price":10915200.0,"size":0.001},{"price":10914000.0,"size":0.005},{"price":10911800.0,"size":0.001}],"asks":[{"price":11317148.0,"size":0.2077},{"price":11317519.0,"size":0.005},{"price":11318049.0,"size":0.03811882},{"price":11318050.0,"size":0.002},{"price":11318668.0,"size":0.02},{"price":11318876.0,"size":0.02},{"price":11319397.0,"size":0.02},{"price":11319398.0,"size":0.4199},{"price":11319418.0,"size":0.015168},{"price":11319647.0,"size":0.3067},{"price":11319751.0,"size":0.015288},{"price":11320000.0,"size":0.02},{"price":11320281.0,"size":0.015},{"price":11320297.0,"size":0.00908554},{"price":11321675.0,"size":0.01},{"price":11322000.0,"size":0.005},{"price":11322409.0,"size":0.2893},{"price":11323782.0,"size":0.0526176},{"price":11324640.0,"size":0.57562484},{"price":11324837.0,"size":0.01},{"price":11325171.0,"size":0.2951},{"price":11326973.0,"size":0.0039988},{"price":11327933.0,"size":0.2824},{"price":11328050.0,"size":0.002},{"price":11329436.0,"size":0.0015},{"price":11331018.0,"size":0.0031358},{"price":11331059.0,"size":0.001},{"price":11338261.0,"size":0.6106705},{"price":11338262.0,"size":1.489},{"price":11340000.0,"size":0.13586406},{"price":11340647.0,"size":0.001},{"price":11342956.0,"size":1.60199848},{"price":11342957.0,"size":0.01},{"price":11346154.0,"size":0.0015},{"price":11348000.0,"size":0.1999},{"price":11348521.0,"size":1.928},{"price":11349700.0,"size":0.001},{"price":11350000.0,"size":0.022},{"price":11353877.0,"size":0.001},{"price":11354939.0,"size":0.01},{"price":11355555.0,"size":0.001},{"price":11359242.0,"size":0.0011},{"price":11359700.0,"size":0.001},{"price":11362692.0,"size":0.0015},{"price":11365211.0,"size":0.001},{"price":11369700.0,"size":0.001},{"price":11370000.0,"size":0.1},{"price":11372478.0,"size":1.943},{"price":11376000.0,"size":0.02},{"price":11376545.0,"size":0.001},{"price":11377000.0,"size":0.2287},{"price":11377269.0,"size":0.002},{"price":11379471.0,"size":2.018},{"price":11379700.0,"size":0.001},{"price":11379865.0,"size":0.03},{"price":11380000.0,"size":0.0223},{"price":11380324.0,"size":0.002},{"price":11381766.0,"size":0.4},{"price":11382386.0,"size":0.0015},{"price":11385000.0,"size":0.2548},{"price":11385403.0,"size":0.002},{"price":11385664.0,"size":0.002},{"price":11386197.0,"size":0.002},{"price":11387072.0,"size":0.01},{"price":11387354.0,"size":0.002},{"price":11387879.0,"size":0.001},{"price":11388885.0,"size":0.03},{"price":11389700.0,"size":0.001},{"price":11390000.0,"size":0.2488},{"price":11390050.0,"size":0.001},{"price":11392387.0,"size":1.0},{"price":11394939.0,"size":0.01},{"price":11395000.0,"size":0.06},{"price":11395775.0,"size":0.01},{"price":11396555.0,"size":0.03},{"price":11398444.0,"size":0.001995},{"price":11399213.0,"size":0.001},{"price":11399673.0,"size":0.0015},{"price":11399700.0,"size":0.001},{"price":11400000.0,"size":0.5225},{"price":11405000.0,"size":0.0275},{"price":11406336.0,"size":1.0},{"price":11408700.0,"size":0.001},{"price":11409415.0,"size":0.055},{"price":11410000.0,"size":0.03},{"price":11410547.0,"size":0.001},{"price":11410853.0,"size":0.002},{"price":11412000.0,"size":0.0878},{"price":11415000.0,"size":0.002},{"price":11415141.0,"size":0.0041},{"price":11417481.0,"size":0.0015},{"price":11418700.0,"size":0.001},{"price":11420000.0,"size":0.401},{"price":11421268.0,"size":0.05},{"price":11421881.0,"size":0.001},{"price":11423339.0,"size":2.0},{"price":11424296.0,"size":0.002},{"price":11424941.0,"size":0.972},{"price":11425000.0,"size":0.049},{"price":11426426.0,"size":0.002},{"price":11428121.0,"size":0.002},{"price":11428700.0,"size":0.001},{"price":11429302.0,"size":0.01},{"price":11432718.0,"size":0.002},{"price":11433211.0,"size":0.03},{"price":11433215.0,"size":0.001},{"price":11433333.0,"size":0.001},{"price":11437315.0,"size":0.002},{"price":11438525.0,"size":0.0011},{"price":11438700.0,"size":0.001},{"price":11439557.0,"size":0.001},{"price":11440000.0,"size":0.1038},{"price":11441911.0,"size":0.002},{"price":11444549.0,"size":0.001},{"price":11446508.0,"size":0.001},{"price":11447000.0,"size":0.01},{"price":11448000.0,"size":0.0875},{"price":11448700.0,"size":0.001},{"price":11450000.0,"size":0.258},{"price":11451105.0,"size":0.002},{"price":11453321.0,"size":0.03},{"price":11455702.0,"size":0.002},{"price":11455883.0,"size":0.001},{"price":11458700.0,"size":0.001},{"price":11458988.0,"size":0.01},{"price":11460000.0,"size":0.01702},{"price":11460299.0,"size":0.002},{"price":11464896.0,"size":0.002},{"price":11467217.0,"size":0.001},{"price":11468700.0,"size":0.001},{"price":11470000.0,"size":0.01},{"price":11471000.0,"size":0.01},{"price":11475000.0,"size":0.0028},{"price":11478551.0,"size":0.001},{"price":11478700.0,"size":0.001},{"price":11480000.0,"size":0.12491},{"price":11485000.0,"size":0.01},{"price":11486555.0,"size":0.03},{"price":11487685.0,"size":0.01},{"price":11488000.0,"size":0.102},{"price":11488700.0,"size":0.001},{"price":11489885.0,"size":0.001},{"price":11490841.0,"size":0.002},{"price":11495450.0,"size":0.002},{"price":11495850.0,"size":0.001},{"price":11498700.0,"size":0.001},{"price":11499000.0,"size":0.01},{"price":11500000.0,"size":0.69859519},{"price":11501219.0,"size":0.001},{"price":11502800.0,"size":0.00132},{"price":11503108.0,"size":0.0198},{"price":11505000.0,"size":0.0028},{"price":11505001.0,"size":0.002},{"price":11505836.0,"size":0.001},{"price":11508431.0,"size":0.047},{"price":11508700.0,"size":0.001},{"price":11508888.0,"size":0.02},{"price":11510000.0,"size":0.0976},{"price":11512553.0,"size":0.001},{"price":11513633.0,"size":0.08},{"price":11514332.0,"size":0.02},{"price":11518700.0,"size":0.001},{"price":11518992.0,"size":0.002},{"price":11519855.0,"size":0.01},{"price":11520000.0,"size":0.001},{"price":11522423.0,"size":0.97},{"price":11523211.0,"size":0.01},{"price":11523887.0,"size":0.001},{"price":11524999.0,"size":0.001},{"price":11528700.0,"size":0.001},{"price":11529852.0,"size":0.01},{"price":11530000.0,"size":0.261},{"price":11534084.0,"size":0.001},{"price":11535321.0,"size":0.01},{"price":11538700.0,"size":0.001},{"price":11540000.0,"size":0.0048},{"price":11540357.0,"size":0.002},{"price":11541011.0,"size":0.005},{"price":11541109.0,"size":0.01},{"price":11545262.0,"size":0.002},{"price":11546541.0,"size":0.01},{"price":11548700.0,"size":0.001},{"price":11550000.0,"size":0.014},{"price":11551109.0,"size":0.01},{"price":11552111.0,"size":0.01},{"price":11553687.0,"size":0.1},{"price":11555115.0,"size":0.001},{"price":11556000.0,"size":0.1},{"price":11558700.0,"size":0.001},{"price":11559855.0,"size":0.01},{"price":11560831.0,"size":0.0198},{"price":11561109.0,"size":0.01},{"price":11562000.0,"size":0.087},{"price":11566139.0,"size":0.0228},{"price":11566551.0,"size":0.01},{"price":11568700.0,"size":0.001},{"price":11570196.0,"size":0.002},{"price":11571109.0,"size":0.01},{"price":11573211.0,"size":0.01},{"price":11574840.0,"size":0.002},{"price":11578700.0,"size":0.001},{"price":11579484.0,"size":0.002},{"price":11579851.0,"size":0.01},{"price":11580000.0,"size":0.7735},{"price":11581109.0,"size":0.01},{"price":11584128.0,"size":0.002},{"price":11585000.0,"size":0.002},{"price":11586532.0,"size":0.01},{"price":11587498.0,"size":0.0198},{"price":11588700.0,"size":0.001},{"price":11589612.0,"size":0.012},{"price":11590000.0,"size":0.1},{"price":11590749.0,"size":0.002},{"price":11591109.0,"size":0.01},{"price":11593211.0,"size":0.01},{"price":11596753.0,"size":0.002},{"price":11598555.0,"size":0.01},{"price":11598700.0,"size":0.001},{"price":11599999.0,"size":0.001},{"price":11600000.0,"size":3.6141},{"price":11601109.0,"size":0.02},{"price":11606655.0,"size":0.01},{"price":11610000.0,"size":0.302},{"price":11611109.0,"size":0.01},{"price":11613321.0,"size":0.01},{"price":11620000.0,"size":1.35441682},{"price":11621011.0,"size":0.01},{"price":11621109.0,"size":0.01},{"price":11623096.0,"size":0.008},{"price":11629000.0,"size":0.1},{"price":11630000.0,"size":0.201},{"price":11631059.0,"size":0.01},{"price":11631479.0,"size":0.01},{"price":11631773.0,"size":0.00386871},{"price":11635950.0,"size":0.001},{"price":11638259.0,"size":0.001},{"price":11639700.0,"size":0.001},{"price":11640000.0,"size":1.0},{"price":11640820.0,"size":0.01},{"price":11645040.0,"size":1.7},{"price":11645295.0,"size":0.05},{"price":11647158.0,"size":0.05},{"price":11649900.0,"size":0.02906},{"price":11649999.0,"size":0.001},{"price":11650000.0,"size":0.593},{"price":11651059.0,"size":0.01},{"price":11653658.0,"size":0.008},{"price":11654321.0,"size":0.001},{"price":11659700.0,"size":0.001},{"price":11661479.0,"size":0.01},{"price":11666000.0,"size":0.001},{"price":11666666.0,"size":0.013},{"price":11669700.0,"size":0.001},{"price":11671059.0,"size":0.01},{"price":11672562.0,"size":0.0198},{"price":11679224.0,"size":0.012},{"price":11680000.0,"size":0.004},{"price":11685000.0,"size":0.003},{"price":11688000.0,"size":0.001},{"price":11689732.0,"size":0.01},{"price":11690330.0,"size":0.0198},{"price":11691059.0,"size":0.01},{"price":11692558.0,"size":0.01},{"price":11698800.0,"size":0.00131},{"price":11699000.0,"size":0.001},{"price":11699631.0,"size":0.001},{"price":11699998.0,"size":0.01},{"price":11699999.0,"size":0.001},{"price":11700000.0,"size":1.03762841},{"price":11701059.0,"size":0.01},{"price":11720000.0,"size":0.1},{"price":11721059.0,"size":0.01},{"price":11725000.0,"size":0.005},{"price":11726791.0,"size":0.01},{"price":11730000.0,"size":0.9382},{"price":11740000.0,"size":0.101},{"price":11741059.0,"size":0.01},{"price":11748937.0,"size":0.001},{"price":11749999.0,"size":0.001},{"price":11750000.0,"size":0.90537866},{"price":11750050.0,"size":0.2},{"price":11751151.0,"size":0.01},{"price":11755000.0,"size":0.001},{"price":11757860.0,"size":1.82},{"price":11759999.0,"size":0.001},{"price":11760000.0,"size":0.001},{"price":11761059.0,"size":0.02},{"price":11765432.0,"size":0.001},{"price":11768000.0,"size":0.01},{"price":11768836.0,"size":0.012},{"price":11770000.0,"size":0.25464896},{"price":11771059.0,"size":0.01755555},{"price":11772000.0,"size":0.002},{"price":11775000.0,"size":0.11593},{"price":11775222.0,"size":0.001657},{"price":11775577.0,"size":0.00013523},{"price":11775800.0,"size":0.001},{"price":11775900.0,"size":0.2},{"price":11775989.0,"size":0.005},{"price":11777000.0,"size":0.5956}]}}}
{"schema_version":"collector.vnext.raw","schema_contract":null,"schema_contract_version":null,"payload_contract_version":null,"record_type":"market.orderbook.diff","record_id":"collector_main-market-orderbook-diff-000000000061","collector_id":"collector_main","collector_role":"production","host_name":"MAIN-PC","session_id":"collector_main-sess-20260314T202422Z-8fdf264f","stream_session_id":"collector_main-stream-bitflyer-board_ws-20260314T202455Z-7c8f3ac8","exchange":"bitflyer","market":"spot","symbol":"BTC_JPY","instrument_id":"bitflyer.spot.BTC_JPY","channel":"board_ws","transport":"websocket","source_event_id":null,"source_sequence":null,"sequence_id":61,"exchange_ts":null,"collector_ts":"2026-03-14T20:24:55Z","ingest_ts":"2026-03-14T20:24:55Z","event_ts":"2026-03-14T20:24:55Z","quality_flags":[],"is_partial":false,"is_reconstructed":false,"confidence_score":1.0,"payload":{"provider":"bitflyer_ws_board","exchange":"bitflyer","transport":"websocket","channel":"lightning_board_BTC_JPY","received_ts":"2026-03-14T20:24:55.596432Z","subscription_id":null,"message_id":null,"source_sequence":null,"raw_message_meta":{"raw_channel":"lightning_board_BTC_JPY","subscription_channel":"lightning_board_BTC_JPY","recv_timeout_sec":10,"ssl_verify":false,"socket_url":"wss://ws.lightstream.bitflyer.com/json-rpc"},"source_payload":{"mid_price":11314763.0,"bids":[{"price":11314207.0,"size":0.0},{"price":11313163.0,"size":0.0},{"price":11311118.0,"size":0.0},{"price":11309670.0,"size":0.0},{"price":11302984.0,"size":0.0},{"price":11309635.0,"size":0.05031799},{"price":11301012.0,"size":2.97141947}],"asks":[{"price":11330262.0,"size":0.0}]}}}
{"schema_version":"collector.vnext.raw","schema_contract":null,"schema_contract_version":null,"payload_contract_version":null,"record_type":"market.orderbook.diff","record_id":"collector_main-market-orderbook-diff-000000000065","collector_id":"collector_main","collector_role":"production","host_name":"MAIN-PC","session_id":"collector_main-sess-20260314T202422Z-8fdf264f","stream_session_id":"collector_main-stream-bitflyer-board_ws-20260314T202455Z-7c8f3ac8","exchange":"bitflyer","market":"spot","symbol":"BTC_JPY","instrument_id":"bitflyer.spot.BTC_JPY","channel":"board_ws","transport":"websocket","source_event_id":null,"source_sequence":null,"sequence_id":65,"exchange_ts":null,"collector_ts":"2026-03-14T20:24:55Z","ingest_ts":"2026-03-14T20:24:55Z","event_ts":"2026-03-14T20:24:55Z","quality_flags":[],"is_partial":false,"is_reconstructed":false,"confidence_score":1.0,"payload":{"provider":"bitflyer_ws_board","exchange":"bitflyer","transport":"websocket","channel":"lightning_board_BTC_JPY","received_ts":"2026-03-14T20:24:55.719159Z","subscription_id":null,"message_id":null,"source_sequence":null,"raw_message_meta":{"raw_channel":"lightning_board_BTC_JPY","subscription_channel":"lightning_board_BTC_JPY","recv_timeout_sec":10,"ssl_verify":false,"socket_url":"wss://ws.lightstream.bitflyer.com/json-rpc"},"source_payload":{"mid_price":11314763.0,"bids":[{"price":11300898.0,"size":0.001},{"price":11268291.0,"size":0.002}],"asks":[{"price":11329104.0,"size":0.001},{"price":11318964.0,"size":0.0}]}}}
{"schema_version":"collector.vnext.raw","schema_contract":null,"schema_contract_version":null,"payload_contract_version":null,"record_type":"market.orderbook.diff","record_id":"collector_main-market-orderbook-diff-000000000067","collector_id":"collector_main","collector_role":"production","host_name":"MAIN-PC","session_id":"collector_main-sess-20260314T202422Z-8fdf264f","stream_session_id":"collector_main-stream-bitflyer-board_ws-20260314T202455Z-7c8f3ac8","exchange":"bitflyer","market":"spot","symbol":"BTC_JPY","instrument_id":"bitflyer.spot.BTC_JPY","channel":"board_ws","transport":"websocket","source_event_id":null,"source_sequence":null,"sequence_id":67,"exchange_ts":null,"collector_ts":"2026-03-14T20:24:55Z","ingest_ts":"2026-03-14T20:24:55Z","event_ts":"2026-03-14T20:24:55Z","quality_flags":[],"is_partial":false,"is_reconstructed":false,"confidence_score":1.0,"payload":{"provider":"bitflyer_ws_board","exchange":"bitflyer","transport":"websocket","channel":"lightning_board_BTC_JPY","received_ts":"2026-03-14T20:24:55.860142Z","subscription_id":null,"message_id":null,"source_sequence":null,"raw_message_meta":{"raw_channel":"lightning_board_BTC_JPY","subscription_channel":"lightning_board_BTC_JPY","recv_timeout_sec":10,"ssl_verify":false,"socket_url":"wss://ws.lightstream.bitflyer.com/json-rpc"},"source_payload":{"mid_price":11315311.0,"bids":[{"price":11311747.0,"size":0.0099986},{"price":11291711.0,"size":0.002},{"price":11309262.0,"size":0.0176828},{"price":11307884.0,"size":0.0},{"price":11308450.0,"size":0.0},{"price":11310651.0,"size":0.0}],"asks":[]}}}
{"schema_version":"collector.vnext.raw","schema_contract":null,"schema_contract_version":null,"payload_contract_version":null,"record_type":"market.orderbook.diff","record_id":"collector_main-market-orderbook-diff-000000000069","collector_id":"collector_main","collector_role":"production","host_name":"MAIN-PC","session_id":"collector_main-sess-20260314T202422Z-8fdf264f","stream_session_id":"collector_main-stream-bitflyer-board_ws-20260314T202455Z-7c8f3ac8","exchange":"bitflyer","market":"spot","symbol":"BTC_JPY","instrument_id":"bitflyer.spot.BTC_JPY","channel":"board_ws","transport":"websocket","source_event_id":null,"source_sequence":null,"sequence_id":69,"exchange_ts":null,"collector_ts":"2026-03-14T20:24:55Z","ingest_ts":"2026-03-14T20:24:55Z","event_ts":"2026-03-14T20:24:55Z","quality_flags":[],"is_partial":false,"is_reconstructed":false,"confidence_score":1.0,"payload":{"provider":"bitflyer_ws_board","exchange":"bitflyer","transport":"websocket","channel":"lightning_board_BTC_JPY","received_ts":"2026-03-14T20:24:55.954184Z","subscription_id":null,"message_id":null,"source_sequence":null,"raw_message_meta":{"raw_channel":"lightning_board_BTC_JPY","subscription_channel":"lightning_board_BTC_JPY","recv_timeout_sec":10,"ssl_verify":false,"socket_url":"wss://ws.lightstream.bitflyer.com/json-rpc"},"source_payload":{"mid_price":11314007.0,"bids":[{"price":11309637.0,"size":0.014616},{"price":11311747.0,"size":0.0},{"price":11308924.0,"size":0.0},{"price":11306838.0,"size":0.2}],"asks":[{"price":11326217.0,"size":0.0},{"price":11324797.0,"size":0.0029305},{"price":11318377.0,"size":0.1275}]}}}
{"schema_version":"collector.vnext.raw","schema_contract":null,"schema_contract_version":null,"payload_contract_version":null,"record_type":"market.orderbook.diff","record_id":"collector_main-market-orderbook-diff-000000000071","collector_id":"collector_main","collector_role":"production","host_name":"MAIN-PC","session_id":"collector_main-sess-20260314T202422Z-8fdf264f","stream_session_id":"collector_main-stream-bitflyer-board_ws-20260314T202455Z-7c8f3ac8","exchange":"bitflyer","market":"spot","symbol":"BTC_JPY","instrument_id":"bitflyer.spot.BTC_JPY","channel":"board_ws","transport":"websocket","source_event_id":null,"source_sequence":null,"sequence_id":71,"exchange_ts":null,"collector_ts":"2026-03-14T20:24:56Z","ingest_ts":"2026-03-14T20:24:56Z","event_ts":"2026-03-14T20:24:56Z","quality_flags":[],"is_partial":false,"is_reconstructed":false,"confidence_score":1.0,"payload":{"provider":"bitflyer_ws_board","exchange":"bitflyer","transport":"websocket","channel":"lightning_board_BTC_JPY","received_ts":"2026-03-14T20:24:56.111190Z","subscription_id":null,"message_id":null,"source_sequence":null,"raw_message_meta":{"raw_channel":"lightning_board_BTC_JPY","subscription_channel":"lightning_board_BTC_JPY","recv_timeout_sec":10,"ssl_verify":false,"socket_url":"wss://ws.lightstream.bitflyer.com/json-rpc"},"source_payload":{"mid_price":11314007.0,"bids":[{"price":11309226.0,"size":0.02},{"price":11309225.0,"size":0.0}],"asks":[{"price":11319834.0,"size":0.7},{"price":11329104.0,"size":0.0}]}}}
{"schema_version":"collector.vnext.raw","schema_contract":null,"schema_contract_version":null,"payload_contract_version":null,"record_type":"market.orderbook.diff","record_id":"collector_main-market-orderbook-diff-000000000073","collector_id":"collector_main","collector_role":"production","host_name":"MAIN-PC","session_id":"collector_main-sess-20260314T202422Z-8fdf264f","stream_session_id":"collector_main-stream-bitflyer-board_ws-20260314T202455Z-7c8f3ac8","exchange":"bitflyer","market":"spot","symbol":"BTC_JPY","instrument_id":"bitflyer.spot.BTC_JPY","channel":"board_ws","transport":"websocket","source_event_id":null,"source_sequence":null,"sequence_id":73,"exchange_ts":null,"collector_ts":"2026-03-14T20:24:56Z","ingest_ts":"2026-03-14T20:24:56Z","event_ts":"2026-03-14T20:24:56Z","quality_flags":[],"is_partial":false,"is_reconstructed":false,"confidence_score":1.0,"payload":{"provider":"bitflyer_ws_board","exchange":"bitflyer","transport":"websocket","channel":"lightning_board_BTC_JPY","received_ts":"2026-03-14T20:24:56.219718Z","subscription_id":null,"message_id":null,"source_sequence":null,"raw_message_meta":{"raw_channel":"lightning_board_BTC_JPY","subscription_channel":"lightning_board_BTC_JPY","recv_timeout_sec":10,"ssl_verify":false,"socket_url":"wss://ws.lightstream.bitflyer.com/json-rpc"},"source_payload":{"mid_price":11314392.0,"bids":[{"price":11310407.0,"size":0.014688},{"price":11309635.0,"size":0.0}],"asks":[{"price":11328291.0,"size":0.001},{"price":11318875.0,"size":0.0}]}}}
{"schema_version":"collector.vnext.raw","schema_contract":null,"schema_contract_version":null,"payload_contract_version":null,"record_type":"market.orderbook.diff","record_id":"collector_main-market-orderbook-diff-000000000075","collector_id":"collector_main","collector_role":"production","host_name":"MAIN-PC","session_id":"collector_main-sess-20260314T202422Z-8fdf264f","stream_session_id":"collector_main-stream-bitflyer-board_ws-20260314T202455Z-7c8f3ac8","exchange":"bitflyer","market":"spot","symbol":"BTC_JPY","instrument_id":"bitflyer.spot.BTC_JPY","channel":"board_ws","transport":"websocket","source_event_id":null,"source_sequence":null,"sequence_id":75,"exchange_ts":null,"collector_ts":"2026-03-14T20:24:56Z","ingest_ts":"2026-03-14T20:24:56Z","event_ts":"2026-03-14T20:24:56Z","quality_flags":[],"is_partial":false,"is_reconstructed":false,"confidence_score":1.0,"payload":{"provider":"bitflyer_ws_board","exchange":"bitflyer","transport":"websocket","channel":"lightning_board_BTC_JPY","received_ts":"2026-03-14T20:24:56.330725Z","subscription_id":null,"message_id":null,"source_sequence":null,"raw_message_meta":{"raw_channel":"lightning_board_BTC_JPY","subscription_channel":"lightning_board_BTC_JPY","recv_timeout_sec":10,"ssl_verify":false,"socket_url":"wss://ws.lightstream.bitflyer.com/json-rpc"},"source_payload":{"mid_price":11314007.0,"bids":[{"price":11309638.0,"size":0.04259018},{"price":11310407.0,"size":0.0}],"asks":[{"price":11318376.0,"size":0.03470197},{"price":11318876.0,"size":0.02},{"price":11330695.0,"size":0.0},{"price":11318377.0,"size":0.0709}]}}}
{"schema_version":"collector.vnext.raw","schema_contract":null,"schema_contract_version":null,"payload_contract_version":null,"record_type":"market.orderbook.diff","record_id":"collector_main-market-orderbook-diff-000000000077","collector_id":"collector_main","collector_role":"production","host_name":"MAIN-PC","session_id":"collector_main-sess-20260314T202422Z-8fdf264f","stream_session_id":"collector_main-stream-bitflyer-board_ws-20260314T202455Z-7c8f3ac8","exchange":"bitflyer","market":"spot","symbol":"BTC_JPY","instrument_id":"bitflyer.spot.BTC_JPY","channel":"board_ws","transport":"websocket","source_event_id":null,"source_sequence":null,"sequence_id":77,"exchange_ts":null,"collector_ts":"2026-03-14T20:24:56Z","ingest_ts":"2026-03-14T20:24:56Z","event_ts":"2026-03-14T20:24:56Z","quality_flags":[],"is_partial":false,"is_reconstructed":false,"confidence_score":1.0,"payload":{"provider":"bitflyer_ws_board","exchange":"bitflyer","transport":"websocket","channel":"lightning_board_BTC_JPY","received_ts":"2026-03-14T20:24:56.455836Z","subscription_id":null,"message_id":null,"source_sequence":null,"raw_message_meta":{"raw_channel":"lightning_board_BTC_JPY","subscription_channel":"lightning_board_BTC_JPY","recv_timeout_sec":10,"ssl_verify":false,"socket_url":"wss://ws.lightstream.bitflyer.com/json-rpc"},"source_payload":{"mid_price":11314007.0,"bids":[{"price":11298963.0,"size":0.30996699},{"price":11309637.0,"size":0.0},{"price":11309636.0,"size":0.014808}],"asks":[{"price":11323570.0,"size":0.33025099},{"price":11324797.0,"size":0.0},{"price":11324247.0,"size":0.0039988}]}}}
{"schema_version":"collector.vnext.raw","schema_contract":null,"schema_contract_version":null,"payload_contract_version":null,"record_type":"market.orderbook.diff","record_id":"collector_main-market-orderbook-diff-000000000079","collector_id":"collector_main","collector_role":"production","host_name":"MAIN-PC","session_id":"collector_main-sess-20260314T202422Z-8fdf264f","stream_session_id":"collector_main-stream-bitflyer-board_ws-20260314T202455Z-7c8f3ac8","exchange":"bitflyer","market":"spot","symbol":"BTC_JPY","instrument_id":"bitflyer.spot.BTC_JPY","channel":"board_ws","transport":"websocket","source_event_id":null,"source_sequence":null,"sequence_id":79,"exchange_ts":null,"collector_ts":"2026-03-14T20:24:56Z","ingest_ts":"2026-03-14T20:24:56Z","event_ts":"2026-03-14T20:24:56Z","quality_flags":[],"is_partial":false,"is_reconstructed":false,"confidence_score":1.0,"payload":{"provider":"bitflyer_ws_board","exchange":"bitflyer","transport":"websocket","channel":"lightning_board_BTC_JPY","received_ts":"2026-03-14T20:24:56.594570Z","subscription_id":null,"message_id":null,"source_sequence":null,"raw_message_meta":{"raw_channel":"lightning_board_BTC_JPY","subscription_channel":"lightning_board_BTC_JPY","recv_timeout_sec":10,"ssl_verify":false,"socket_url":"wss://ws.lightstream.bitflyer.com/json-rpc"},"source_payload":{"mid_price":11314008.0,"bids":[{"price":11309227.0,"size":0.0},{"price":11309640.0,"size":0.014844}],"asks":[{"price":11319647.0,"size":0.2962}]}}}
{"schema_version":"collector.vnext.raw","schema_contract":null,"schema_contract_version":null,"payload_contract_version":null,"record_type":"market.orderbook.diff","record_id":"collector_main-market-orderbook-diff-000000000081","collector_id":"collector_main","collector_role":"production","host_name":"MAIN-PC","session_id":"collector_main-sess-20260314T202422Z-8fdf264f","stream_session_id":"collector_main-stream-bitflyer-board_ws-20260314T202455Z-7c8f3ac8","exchange":"bitflyer","market":"spot","symbol":"BTC_JPY","instrument_id":"bitflyer.spot.BTC_JPY","channel":"board_ws","transport":"websocket","source_event_id":null,"source_sequence":null,"sequence_id":81,"exchange_ts":null,"collector_ts":"2026-03-14T20:24:56Z","ingest_ts":"2026-03-14T20:24:56Z","event_ts":"2026-03-14T20:24:56Z","quality_flags":[],"is_partial":false,"is_reconstructed":false,"confidence_score":1.0,"payload":{"provider":"bitflyer_ws_board","exchange":"bitflyer","transport":"websocket","channel":"lightning_board_BTC_JPY","received_ts":"2026-03-14T20:24:56.703302Z","subscription_id":null,"message_id":null,"source_sequence":null,"raw_message_meta":{"raw_channel":"lightning_board_BTC_JPY","subscription_channel":"lightning_board_BTC_JPY","recv_timeout_sec":10,"ssl_verify":false,"socket_url":"wss://ws.lightstream.bitflyer.com/json-rpc"},"source_payload":{"mid_price":11314008.0,"bids":[{"price":11309226.0,"size":0.0},{"price":11304688.0,"size":0.0}],"asks":[{"price":11324965.0,"size":0.0}]}}}
{"schema_version":"collector.vnext.raw","schema_contract":null,"schema_contract_version":null,"payload_contract_version":null,"record_type":"market.orderbook.diff","record_id":"collector_main-market-orderbook-diff-000000000083","collector_id":"collector_main","collector_role":"production","host_name":"MAIN-PC","session_id":"collector_main-sess-20260314T202422Z-8fdf264f","stream_session_id":"collector_main-stream-bitflyer-board_ws-20260314T202455Z-7c8f3ac8","exchange":"bitflyer","market":"spot","symbol":"BTC_JPY","instrument_id":"bitflyer.spot.BTC_JPY","channel":"board_ws","transport":"websocket","source_event_id":null,"source_sequence":null,"sequence_id":83,"exchange_ts":null,"collector_ts":"2026-03-14T20:24:56Z","ingest_ts":"2026-03-14T20:24:56Z","event_ts":"2026-03-14T20:24:56Z","quality_flags":[],"is_partial":false,"is_reconstructed":false,"confidence_score":1.0,"payload":{"provider":"bitflyer_ws_board","exchange":"bitflyer","transport":"websocket","channel":"lightning_board_BTC_JPY","received_ts":"2026-03-14T20:24:56.812832Z","subscription_id":null,"message_id":null,"source_sequence":null,"raw_message_meta":{"raw_channel":"lightning_board_BTC_JPY","subscription_channel":"lightning_board_BTC_JPY","recv_timeout_sec":10,"ssl_verify":false,"socket_url":"wss://ws.lightstream.bitflyer.com/json-rpc"},"source_payload":{"mid_price":11314008.0,"bids":[{"price":11309638.0,"size":0.0},{"price":11309641.0,"size":0.04549174}],"asks":[{"price":11322201.0,"size":0.0529}]}}}
{"schema_version":"collector.vnext.raw","schema_contract":null,"schema_contract_version":null,"payload_contract_version":null,"record_type":"market.orderbook.diff","record_id":"collector_main-market-orderbook-diff-000000000085","collector_id":"collector_main","collector_role":"production","host_name":"MAIN-PC","session_id":"collector_main-sess-20260314T202422Z-8fdf264f","stream_session_id":"collector_main-stream-bitflyer-board_ws-20260314T202455Z-7c8f3ac8","exchange":"bitflyer","market":"spot","symbol":"BTC_JPY","instrument_id":"bitflyer.spot.BTC_JPY","channel":"board_ws","transport":"websocket","source_event_id":null,"source_sequence":null,"sequence_id":85,"exchange_ts":null,"collector_ts":"2026-03-14T20:24:56Z","ingest_ts":"2026-03-14T20:24:56Z","event_ts":"2026-03-14T20:24:56Z","quality_flags":[],"is_partial":false,"is_reconstructed":false,"confidence_score":1.0,"payload":{"provider":"bitflyer_ws_board","exchange":"bitflyer","transport":"websocket","channel":"lightning_board_BTC_JPY","received_ts":"2026-03-14T20:24:56.954247Z","subscription_id":null,"message_id":null,"source_sequence":null,"raw_message_meta":{"raw_channel":"lightning_board_BTC_JPY","subscription_channel":"lightning_board_BTC_JPY","recv_timeout_sec":10,"ssl_verify":false,"socket_url":"wss://ws.lightstream.bitflyer.com/json-rpc"},"source_payload":{"mid_price":11314008.0,"bids":[{"price":11309262.0,"size":0.0},{"price":11302769.0,"size":0.053},{"price":11287184.0,"size":0.002}],"asks":[{"price":11320861.0,"size":0.0}]}}}
{"schema_version":"collector.vnext.raw","schema_contract":null,"schema_contract_version":null,"payload_contract_version":null,"record_type":"market.orderbook.diff","record_id":"collector_main-market-orderbook-diff-000000000087","collector_id":"collector_main","collector_role":"production","host_name":"MAIN-PC","session_id":"collector_main-sess-20260314T202422Z-8fdf264f","stream_session_id":"collector_main-stream-bitflyer-board_ws-20260314T202455Z-7c8f3ac8","exchange":"bitflyer","market":"spot","symbol":"BTC_JPY","instrument_id":"bitflyer.spot.BTC_JPY","channel":"board_ws","transport":"websocket","source_event_id":null,"source_sequence":null,"sequence_id":87,"exchange_ts":null,"collector_ts":"2026-03-14T20:24:57Z","ingest_ts":"2026-03-14T20:24:57Z","event_ts":"2026-03-14T20:24:57Z","quality_flags":[],"is_partial":false,"is_reconstructed":false,"confidence_score":1.0,"payload":{"provider":"bitflyer_ws_board","exchange":"bitflyer","transport":"websocket","channel":"lightning_board_BTC_JPY","received_ts":"2026-03-14T20:24:57.077051Z","subscription_id":null,"message_id":null,"source_sequence":null,"raw_message_meta":{"raw_channel":"lightning_board_BTC_JPY","subscription_channel":"lightning_board_BTC_JPY","recv_timeout_sec":10,"ssl_verify":false,"socket_url":"wss://ws.lightstream.bitflyer.com/json-rpc"},"source_payload":{"mid_price":11314009.0,"bids":[{"price":11309643.0,"size":0.014964}],"asks":[{"price":11328291.0,"size":0.0},{"price":11328379.0,"size":0.001}]}}}
{"schema_version":"collector.vnext.raw","schema_contract":null,"schema_contract_version":null,"payload_contract_version":null,"record_type":"market.orderbook.snapshot","record_id":"collector_main-market-orderbook-snapshot-000000000089","collector_id":"collector_main","collector_role":"production","host_name":"MAIN-PC","session_id":"collector_main-sess-20260314T202422Z-8fdf264f","stream_session_id":"collector_main-stream-bitflyer-board_ws-20260314T202455Z-7c8f3ac8","exchange":"bitflyer","market":"spot","symbol":"BTC_JPY","instrument_id":"bitflyer.spot.BTC_JPY","channel":"board_ws","transport":"websocket","source_event_id":null,"source_sequence":null,"sequence_id":89,"exchange_ts":null,"collector_ts":"2026-03-14T20:24:57Z","ingest_ts":"2026-03-14T20:24:57Z","event_ts":"2026-03-14T20:24:57Z","quality_flags":[],"is_partial":false,"is_reconstructed":false,"confidence_score":1.0,"payload":{"provider":"bitflyer_ws_board_snapshot","exchange":"bitflyer","transport":"websocket","channel":"lightning_board_snapshot_BTC_JPY","received_ts":"2026-03-14T20:24:57.158368Z","subscription_id":null,"message_id":null,"source_sequence":null,"raw_message_meta":{"raw_channel":"lightning_board_snapshot_BTC_JPY","subscription_channel":"lightning_board_snapshot_BTC_JPY","recv_timeout_sec":10,"ssl_verify":false,"socket_url":"wss://ws.lightstream.bitflyer.com/json-rpc"},"source_payload":{"mid_price":11314009.0,"bids":[{"price":11309643.0,"size":0.014964},{"price":11309641.0,"size":0.04549174},{"price":11309640.0,"size":0.014844},{"price":11309636.0,"size":0.014808},{"price":11309634.0,"size":0.02},{"price":11309048.0,"size":0.015372},{"price":11308136.0,"size":0.5},{"price":11307440.0,"size":0.0801},{"price":11307133.0,"size":0.5},{"price":11306838.0,"size":0.2},{"price":11305384.0,"size":0.01},{"price":11304585.0,"size":0.01},{"price":11303745.0,"size":0.0560304},{"price":11302769.0,"size":0.053},{"price":11301012.0,"size":2.97141947},{"price":11300898.0,"size":0.001},{"price":11298963.0,"size":0.30996699},{"price":11298534.0,"size":1.50015},{"price":11298401.0,"size":0.98312977},{"price":11291711.0,"size":0.002},{"price":11291323.0,"size":0.31183619},{"price":11289652.0,"size":0.6},{"price":11288661.0,"size":0.002},{"price":11288560.0,"size":0.2886},{"price":11287184.0,"size":0.002},{"price":11286090.0,"size":0.18915459},{"price":11285798.0,"size":0.3026},{"price":11285266.0,"size":0.002},{"price":11285264.0,"size":0.29858071},{"price":11285263.0,"size":1.484},{"price":11283036.0,"size":0.2577},{"price":11281871.0,"size":0.002},{"price":11280274.0,"size":0.2682},{"price":11280205.0,"size":0.001},{"price":11279282.0,"size":0.0015},{"price":11278476.0,"size":0.002},{"price":11277748.0,"size":0.0966561},{"price":11277602.0,"size":0.005},{"price":11275102.0,"size":0.01},{"price":11275081.0,"size":0.002},{"price":11275000.0,"size":0.001},{"price":11274588.0,"size":0.0047},{"price":11271686.0,"size":0.002},{"price":11271000.0,"size":0.003},{"price":11270000.0,"size":0.106},{"price":11268871.0,"size":0.281},{"price":11268411.0,"size":0.01},{"price":11268291.0,"size":0.002},{"price":11266829.0,"size":1.966},{"price":11266666.0,"size":0.04},{"price":11265000.0,"size":0.02},{"price":11263000.0,"size":0.006},{"price":11262564.0,"size":0.0015},{"price":11260000.0,"size":0.3565},{"price":11257537.0,"size":0.001},{"price":11257000.0,"size":0.001},{"price":11255200.0,"size":0.001},{"price":11255115.0,"size":0.00377},{"price":11253628.0,"size":2.036},{"price":11253000.0,"size":0.03189},{"price":11251000.0,"size":0.0131},{"price":11250250.0,"size":0.00105},{"price":11250200.0,"size":0.001},{"price":11250100.0,"size":0.015},{"price":11250005.0,"size":0.001},{"price":11250001.0,"size":0.00104},{"price":11250000.0,"size":0.76834},{"price":11246544.0,"size":0.0015},{"price":11246203.0,"size":0.001},{"price":11245141.0,"size":0.0031},{"price":11245000.0,"size":0.05},{"price":11244444.0,"size":0.04},{"price":11244243.0,"size":0.01},{"price":11240200.0,"size":0.001},{"price":11240000.0,"size":0.007304},{"price":11236190.0,"size":0.01},{"price":11235200.0,"size":0.001},{"price":11234869.0,"size":0.001},{"price":11232000.0,"size":0.089},{"price":11231243.0,"size":0.01},{"price":11231000.0,"size":0.105},{"price":11230200.0,"size":0.001},{"price":11230000.0,"size":0.0308},{"price":11228423.0,"size":1.951},{"price":11224500.0,"size":0.06},{"price":11224355.0,"size":0.0015},{"price":11223968.0,"size":0.001},{"price":11223535.0,"size":0.001},{"price":11223344.0,"size":0.01},{"price":11223000.0,"size":0.1},{"price":11222222.0,"size":0.092525},{"price":11221459.0,"size":0.1393},{"price":11221120.0,"size":0.011},{"price":11220756.0,"size":1.79},{"price":11220200.0,"size":0.001},{"price":11220001.0,"size":0.004457},{"price":11220000.0,"size":0.321},{"price":11219517.0,"size":0.01},{"price":11219000.0,"size":0.1},{"price":11215200.0,"size":0.001},{"price":11215000.0,"size":0.02},{"price":11212358.0,"size":1.2},{"price":11212201.0,"size":0.001},{"price":11211800.0,"size":0.001},{"price":11211111.0,"size":0.06},{"price":11210200.0,"size":0.001},{"price":11210000.0,"size":0.10622},{"price":11208032.0,"size":0.01},{"price":11207755.0,"size":0.0015},{"price":11206000.0,"size":0.09015},{"price":11205200.0,"size":0.001},{"price":11204578.0,"size":0.002},{"price":11203931.0,"size":1.0},{"price":11201000.0,"size":0.01},{"price":11200867.0,"size":0.001},{"price":11200800.0,"size":0.05},{"price":11200425.0,"size":0.1},{"price":11200200.0,"size":0.001},{"price":11200198.0,"size":0.003},{"price":11200150.0,"size":0.002},{"price":11200002.0,"size":0.001},{"price":11200001.0,"size":0.01104},{"price":11200000.0,"size":1.35988728},{"price":11198508.0,"size":0.05},{"price":11198243.0,"size":0.01},{"price":11197134.0,"size":2.993},{"price":11197000.0,"size":0.0085},{"price":11195692.0,"size":0.0015},{"price":11194090.0,"size":0.03},{"price":11190770.0,"size":0.0309},{"price":11190000.0,"size":0.0010016},{"price":11189555.0,"size":0.5},{"price":11189533.0,"size":0.001},{"price":11188629.0,"size":0.01},{"price":11188382.0,"size":0.001},{"price":11185000.0,"size":0.0085},{"price":11180043.0,"size":0.972},{"price":11180000.0,"size":0.23215},{"price":11178973.0,"size":0.0015},{"price":11178199.0,"size":0.001},{"price":11170000.0,"size":0.001},{"price":11169662.0,"size":0.01},{"price":11169593.0,"size":0.001},{"price":11169243.0,"size":0.01},{"price":11166865.0,"size":0.001},{"price":11164029.0,"size":0.001},{"price":11160854.0,"size":0.1},{"price":11160000.0,"size":0.02376},{"price":11156269.0,"size":0.01},{"price":11155531.0,"size":0.001},{"price":11155377.0,"size":0.00636009},{"price":11153999.0,"size":0.00101},{"price":11151000.0,"size":0.001},{"price":11150250.0,"size":0.00175},{"price":11150005.0,"size":0.001},{"price":11150001.0,"size":0.00104},{"price":11150000.0,"size":0.6398956},{"price":11148000.0,"size":0.08963},{"price":11144197.0,"size":0.001},{"price":11144000.0,"size":0.0897},{"price":11140000.0,"size":0.2},{"price":11136243.0,"size":0.01},{"price":11136155.0,"size":0.02},{"price":11135869.0,"size":0.1},{"price":11130000.0,"size":0.116},{"price":11129979.0,"size":0.0053908},{"price":11126388.0,"size":0.02},{"price":11124900.0,"size":0.00133},{"price":11121090.0,"size":0.1},{"price":11120000.0,"size":0.0033},{"price":11118078.0,"size":0.01},{"price":11111800.0,"size":0.001},{"price":11111111.0,"size":0.2919257},{"price":11111000.0,"size":0.003},{"price":11110594.0,"size":0.001},{"price":11110000.0,"size":0.056937},{"price":11109662.0,"size":0.01},{"price":11108008.0,"size":0.01},{"price":11106000.0,"size":0.2},{"price":11105000.0,"size":0.02},{"price":11101297.0,"size":0.001},{"price":11100005.0,"size":0.001},{"price":11100001.0,"size":0.01104},{"price":11100000.0,"size":1.7472049},{"price":11099141.0,"size":0.01},{"price":11096243.0,"size":0.01},{"price":11094090.0,"size":0.01},{"price":11088888.0,"size":0.001},{"price":11085245.0,"size":0.001},{"price":11080200.0,"size":0.001},{"price":11080000.0,"size":0.0223},{"price":11075100.0,"size":0.003},{"price":11071558.0,"size":1.0},{"price":11070200.0,"size":0.001},{"price":11070000.0,"size":0.0902},{"price":11065200.0,"size":0.001},{"price":11064370.0,"size":0.00497091},{"price":11060200.0,"size":0.001},{"price":11060000.0,"size":0.145},{"price":11059689.0,"size":0.009},{"price":11056428.0,"size":0.002},{"price":11055500.0,"size":0.02},{"price":11055200.0,"size":0.001},{"price":11055100.0,"size":0.003},{"price":11050200.0,"size":0.001},{"price":11050005.0,"size":0.001},{"price":11050002.0,"size":0.001},{"price":11050001.0,"size":0.00104},{"price":11050000.0,"size":0.43176147},{"price":11046420.0,"size":0.2},{"price":11044243.0,"size":0.01},{"price":11041380.0,"size":0.01},{"price":11040200.0,"size":0.001},{"price":11040000.0,"size":0.00777181},{"price":11035865.0,"size":0.1},{"price":11035200.0,"size":0.001},{"price":11035000.0,"size":0.0013},{"price":11030200.0,"size":0.001},{"price":11030000.0,"size":0.025},{"price":11025500.0,"size":0.009531},{"price":11025200.0,"size":0.001},{"price":11025000.0,"size":0.71497},{"price":11020772.0,"size":0.014},{"price":11020200.0,"size":0.002},{"price":11020000.0,"size":0.005},{"price":11015200.0,"size":0.001},{"price":11012000.0,"size":0.1},{"price":11011800.0,"size":0.001},{"price":11010200.0,"size":0.001},{"price":11010000.0,"size":0.347},{"price":11007277.0,"size":0.01},{"price":11006000.0,"size":0.2},{"price":11005200.0,"size":0.001},{"price":11004890.0,"size":0.001535},{"price":11003000.0,"size":0.0155},{"price":11001000.0,"size":0.013},{"price":11000500.0,"size":0.05117658},{"price":11000200.0,"size":0.001},{"price":11000002.0,"size":0.004},{"price":11000001.0,"size":0.02604},{"price":11000000.0,"size":4.55923365},{"price":10999999.0,"size":0.003},{"price":10999000.0,"size":0.001},{"price":10996855.0,"size":0.0011},{"price":10995200.0,"size":0.001},{"price":10994499.0,"size":0.00169176},{"price":10990200.0,"size":0.001},{"price":10990000.0,"size":0.10219},{"price":10989001.0,"size":0.00197},{"price":10988999.0,"size":0.001},{"price":10988324.0,"size":0.002},{"price":10987654.0,"size":0.001},{"price":10985200.0,"size":0.001},{"price":10985150.0,"size":0.01},{"price":10980500.0,"size":0.005},{"price":10980200.0,"size":0.001},{"price":10980002.0,"size":0.4},{"price":10980000.0,"size":0.028},{"price":10975200.0,"size":0.001},{"price":10975000.0,"size":0.1},{"price":10971261.0,"size":0.001},{"price":10971243.0,"size":0.01},{"price":10970375.0,"size":1.9},{"price":10970200.0,"size":0.001},{"price":10970000.0,"size":0.09304},{"price":10966600.0,"size":0.001003},{"price":10965200.0,"size":0.001},{"price":10960200.0,"size":0.001},{"price":10960000.0,"size":0.0083},{"price":10956673.0,"size":0.01},{"price":10955200.0,"size":0.001},{"price":10954950.0,"size":0.001},{"price":10950500.0,"size":0.005},{"price":10950001.0,"size":0.00204},{"price":10950000.0,"size":0.5485028},{"price":10949550.0,"size":0.01870657},{"price":10949172.0,"size":0.1},{"price":10948000.0,"size":0.1},{"price":10945243.0,"size":0.01},{"price":10940402.0,"size":0.001},{"price":10940200.0,"size":0.001},{"price":10940000.0,"size":0.331},{"price":10938243.0,"size":0.01},{"price":10936200.0,"size":0.00137},{"price":10935200.0,"size":0.001},{"price":10930200.0,"size":0.002},{"price":10930000.0,"size":0.0193},{"price":10925200.0,"size":0.002},{"price":10924451.0,"size":0.0012},{"price":10920509.0,"size":0.01},{"price":10920200.0,"size":0.002},{"price":10920000.0,"size":0.52},{"price":10915200.0,"size":0.001},{"price":10914000.0,"size":0.005},{"price":10911800.0,"size":0.001},{"price":10910500.0,"size":0.005},{"price":10910200.0,"size":0.003},{"price":10910000.0,"size":0.005},{"price":10908243.0,"size":0.01},{"price":10906308.0,"size":0.013}],"asks":[{"price":11318376.0,"size":0.03470197},{"price":11318377.0,"size":0.0709},{"price":11318876.0,"size":0.02},{"price":11318962.0,"size":0.005},{"price":11319187.0,"size":0.00908554},{"price":11319647.0,"size":0.2962},{"price":11319834.0,"size":0.7},{"price":11320000.0,"size":0.02},{"price":11320015.0,"size":0.015444},{"price":11320457.0,"size":0.02},{"price":11320458.0,"size":0.014844},{"price":11321872.0,"size":0.0554256},{"price":11322000.0,"size":0.005},{"price":11322201.0,"size":0.0529},{"price":11322245.0,"size":0.01},{"price":11322409.0,"size":0.2893},{"price":11323570.0,"size":0.33025099},{"price":11323571.0,"size":0.57572293},{"price":11323572.0,"size":0.015},{"price":11324247.0,"size":0.0039988},{"price":11324837.0,"size":0.01},{"price":11325171.0,"size":0.2951},{"price":11326901.0,"size":0.4199},{"price":11327933.0,"size":0.2824},{"price":11328050.0,"size":0.002},{"price":11328379.0,"size":0.001},{"price":11329436.0,"size":0.0015},{"price":11331059.0,"size":0.001},{"price":11334615.0,"size":1.189881},{"price":11334748.0,"size":1.189881},{"price":11338261.0,"size":0.30062519},{"price":11340000.0,"size":0.13586406},{"price":11340646.0,"size":0.34844633},{"price":11340647.0,"size":0.001},{"price":11342955.0,"size":0.28501097},{"price":11342956.0,"size":1.60199848},{"price":11342957.0,"size":0.01},{"price":11346154.0,"size":0.0015},{"price":11346821.0,"size":1.489},{"price":11348000.0,"size":0.1999},{"price":11348521.0,"size":1.928},{"price":11349700.0,"size":0.001},{"price":11350000.0,"size":0.022},{"price":11353877.0,"size":0.001},{"price":11354939.0,"size":0.01},{"price":11355555.0,"size":0.001},{"price":11359242.0,"size":0.0011},{"price":11359700.0,"size":0.001},{"price":11362692.0,"size":0.0015},{"price":11365211.0,"size":0.001},{"price":11369700.0,"size":0.001},{"price":11370000.0,"size":0.1},{"price":11372478.0,"size":1.943},{"price":11376000.0,"size":0.02},{"price":11376545.0,"size":0.001},{"price":11377000.0,"size":0.2287},{"price":11377269.0,"size":0.002},{"price":11379471.0,"size":2.018},{"price":11379700.0,"size":0.001},{"price":11379865.0,"size":0.03},{"price":11380000.0,"size":0.0223},{"price":11380324.0,"size":0.002},{"price":11381766.0,"size":0.4},{"price":11382386.0,"size":0.0015},{"price":11385000.0,"size":0.2548},{"price":11385403.0,"size":0.002},{"price":11385664.0,"size":0.002},{"price":11386197.0,"size":0.002},{"price":11387072.0,"size":0.01},{"price":11387354.0,"size":0.002},{"price":11387879.0,"size":0.001},{"price":11388885.0,"size":0.03},{"price":11389700.0,"size":0.001},{"price":11390000.0,"size":0.2488},{"price":11390050.0,"size":0.001},{"price":11392387.0,"size":1.0},{"price":11394939.0,"size":0.01},{"price":11395000.0,"size":0.06},{"price":11395775.0,"size":0.01},{"price":11396555.0,"size":0.03},{"price":11398444.0,"size":0.001995},{"price":11399213.0,"size":0.001},{"price":11399673.0,"size":0.0015},{"price":11399700.0,"size":0.001},{"price":11400000.0,"size":0.5225},{"price":11405000.0,"size":0.0275},{"price":11406336.0,"size":1.0},{"price":11408700.0,"size":0.001},{"price":11409415.0,"size":0.055},{"price":11410000.0,"size":0.03},{"price":11410547.0,"size":0.001},{"price":11410853.0,"size":0.002},{"price":11412000.0,"size":0.0878},{"price":11415000.0,"size":0.002},{"price":11415141.0,"size":0.0041},{"price":11417481.0,"size":0.0015},{"price":11418700.0,"size":0.001},{"price":11420000.0,"size":0.401},{"price":11421268.0,"size":0.05},{"price":11421881.0,"size":0.001},{"price":11423339.0,"size":2.0},{"price":11424296.0,"size":0.002},{"price":11424941.0,"size":0.972},{"price":11425000.0,"size":0.049},{"price":11426426.0,"size":0.002},{"price":11428121.0,"size":0.002},{"price":11428700.0,"size":0.001},{"price":11429302.0,"size":0.01},{"price":11432718.0,"size":0.002},{"price":11433211.0,"size":0.03},{"price":11433215.0,"size":0.001},{"price":11433333.0,"size":0.001},{"price":11437315.0,"size":0.002},{"price":11438525.0,"size":0.0011},{"price":11438700.0,"size":0.001},{"price":11439557.0,"size":0.001},{"price":11440000.0,"size":0.1038},{"price":11441911.0,"size":0.002},{"price":11443629.0,"size":0.002},{"price":11444549.0,"size":0.001},{"price":11446508.0,"size":0.001},{"price":11447000.0,"size":0.01},{"price":11447071.0,"size":0.002},{"price":11448000.0,"size":0.0875},{"price":11448700.0,"size":0.001},{"price":11450000.0,"size":0.258},{"price":11451105.0,"size":0.002},{"price":11453321.0,"size":0.03},{"price":11455702.0,"size":0.002},{"price":11455883.0,"size":0.001},{"price":11458700.0,"size":0.001},{"price":11458988.0,"size":0.01},{"price":11460000.0,"size":0.01702},{"price":11460299.0,"size":0.002},{"price":11464896.0,"size":0.002},{"price":11467217.0,"size":0.001},{"price":11468700.0,"size":0.001},{"price":11470000.0,"size":0.01},{"price":11471000.0,"size":0.01},{"price":11475000.0,"size":0.0028},{"price":11478431.0,"size":0.002},{"price":11478551.0,"size":0.001},{"price":11478700.0,"size":0.001},{"price":11480000.0,"size":0.12491},{"price":11485000.0,"size":0.01},{"price":11486555.0,"size":0.03},{"price":11487685.0,"size":0.01},{"price":11488000.0,"size":0.102},{"price":11488700.0,"size":0.001},{"price":11489885.0,"size":0.001},{"price":11490841.0,"size":0.002},{"price":11495450.0,"size":0.002},{"price":11495850.0,"size":0.001},{"price":11498700.0,"size":0.001},{"price":11498917.0,"size":0.002},{"price":11499000.0,"size":0.01},{"price":11500000.0,"size":0.69859519},{"price":11501219.0,"size":0.001},{"price":11502377.0,"size":0.002},{"price":11502800.0,"size":0.00132},{"price":11503108.0,"size":0.0198},{"price":11505000.0,"size":0.0028},{"price":11505001.0,"size":0.002},{"price":11505836.0,"size":0.003},{"price":11508431.0,"size":0.047},{"price":11508700.0,"size":0.001},{"price":11508888.0,"size":0.02},{"price":11510000.0,"size":0.0976},{"price":11512553.0,"size":0.001},{"price":11513633.0,"size":0.08},{"price":11514332.0,"size":0.02},{"price":11518700.0,"size":0.001},{"price":11518992.0,"size":0.002},{"price":11519855.0,"size":0.01},{"price":11520000.0,"size":0.001},{"price":11522423.0,"size":0.97},{"price":11523211.0,"size":0.01},{"price":11523887.0,"size":0.001},{"price":11524999.0,"size":0.001},{"price":11528700.0,"size":0.001},{"price":11529852.0,"size":0.01},{"price":11530000.0,"size":0.261},{"price":11533985.0,"size":0.002},{"price":11534084.0,"size":0.001},{"price":11535321.0,"size":0.01},{"price":11538666.0,"size":0.002},{"price":11538700.0,"size":0.001},{"price":11540000.0,"size":0.0048},{"price":11540357.0,"size":0.002},{"price":11541011.0,"size":0.005},{"price":11541109.0,"size":0.01},{"price":11544663.0,"size":0.002},{"price":11545262.0,"size":0.002},{"price":11546541.0,"size":0.01},{"price":11548144.0,"size":0.002},{"price":11548700.0,"size":0.001},{"price":11550000.0,"size":0.014},{"price":11551109.0,"size":0.01},{"price":11551625.0,"size":0.002},{"price":11552111.0,"size":0.01},{"price":11553687.0,"size":0.1},{"price":11555106.0,"size":0.002},{"price":11555115.0,"size":0.001},{"price":11556000.0,"size":0.1},{"price":11558587.0,"size":0.002},{"price":11558700.0,"size":0.001},{"price":11559855.0,"size":0.01},{"price":11560831.0,"size":0.0198},{"price":11561109.0,"size":0.01},{"price":11562000.0,"size":0.087},{"price":11562068.0,"size":0.002},{"price":11565548.0,"size":0.002},{"price":11566139.0,"size":0.0228},{"price":11566551.0,"size":0.01},{"price":11568700.0,"size":0.001},{"price":11569029.0,"size":0.002},{"price":11570196.0,"size":0.002},{"price":11571109.0,"size":0.01},{"price":11572510.0,"size":0.002},{"price":11573211.0,"size":0.01},{"price":11574840.0,"size":0.002},{"price":11575991.0,"size":0.001},{"price":11578700.0,"size":0.001},{"price":11579484.0,"size":0.002},{"price":11579851.0,"size":0.01},{"price":11580000.0,"size":0.7735},{"price":11581109.0,"size":0.01},{"price":11584128.0,"size":0.002},{"price":11585000.0,"size":0.002},{"price":11586532.0,"size":0.01},{"price":11587498.0,"size":0.0198},{"price":11588700.0,"size":0.001},{"price":11589612.0,"size":0.012},{"price":11590000.0,"size":0.1},{"price":11590749.0,"size":0.002},{"price":11591109.0,"size":0.01},{"price":11593211.0,"size":0.01},{"price":11596753.0,"size":0.002},{"price":11598555.0,"size":0.01},{"price":11598700.0,"size":0.001},{"price":11599999.0,"size":0.001},{"price":11600000.0,"size":3.6141},{"price":11601109.0,"size":0.02},{"price":11606655.0,"size":0.01},{"price":11610000.0,"size":0.302},{"price":11611109.0,"size":0.01},{"price":11613321.0,"size":0.01},{"price":11620000.0,"size":1.35441682},{"price":11621011.0,"size":0.01},{"price":11621109.0,"size":0.01},{"price":11623096.0,"size":0.008},{"price":11629000.0,"size":0.1},{"price":11630000.0,"size":0.201},{"price":11631059.0,"size":0.01},{"price":11631479.0,"size":0.01},{"price":11631773.0,"size":0.00386871},{"price":11635950.0,"size":0.001},{"price":11638259.0,"size":0.001},{"price":11639700.0,"size":0.001},{"price":11640000.0,"size":1.0},{"price":11640820.0,"size":0.01},{"price":11645040.0,"size":1.7},{"price":11645295.0,"size":0.05},{"price":11647158.0,"size":0.05},{"price":11649900.0,"size":0.02906},{"price":11649999.0,"size":0.001},{"price":11650000.0,"size":0.593},{"price":11651059.0,"size":0.01},{"price":11653658.0,"size":0.008},{"price":11654321.0,"size":0.001},{"price":11659700.0,"size":0.001},{"price":11661479.0,"size":0.01},{"price":11666000.0,"size":0.001},{"price":11666666.0,"size":0.013},{"price":11669700.0,"size":0.001},{"price":11671059.0,"size":0.01},{"price":11672562.0,"size":0.0198},{"price":11679224.0,"size":0.012},{"price":11680000.0,"size":0.004},{"price":11685000.0,"size":0.003},{"price":11688000.0,"size":0.001},{"price":11689732.0,"size":0.01},{"price":11690330.0,"size":0.0198},{"price":11691059.0,"size":0.01},{"price":11692558.0,"size":0.01},{"price":11698800.0,"size":0.00131},{"price":11699000.0,"size":0.001},{"price":11699631.0,"size":0.001},{"price":11699998.0,"size":0.01},{"price":11699999.0,"size":0.001},{"price":11700000.0,"size":1.03762841},{"price":11701059.0,"size":0.01},{"price":11720000.0,"size":0.1},{"price":11721059.0,"size":0.01},{"price":11725000.0,"size":0.005},{"price":11726791.0,"size":0.01},{"price":11730000.0,"size":0.9382},{"price":11740000.0,"size":0.101},{"price":11741059.0,"size":0.01},{"price":11748937.0,"size":0.001}]}}}
{"schema_version":"collector.vnext.raw","schema_contract":null,"schema_contract_version":null,"payload_contract_version":null,"record_type":"market.orderbook.diff","record_id":"collector_main-market-orderbook-diff-000000000061","collector_id":"collector_main","collector_role":"production","host_name":"MAIN-PC","session_id":"collector_main-sess-20260314T202512Z-5e0ec04a","stream_session_id":"collector_main-stream-bitflyer-board_ws-20260314T203007Z-9ed26c91","exchange":"bitflyer","market":"spot","symbol":"BTC_JPY","instrument_id":"bitflyer.spot.BTC_JPY","channel":"board_ws","transport":"websocket","source_event_id":null,"source_sequence":null,"sequence_id":61,"exchange_ts":null,"collector_ts":"2026-03-14T20:30:07Z","ingest_ts":"2026-03-14T20:30:07Z","event_ts":"2026-03-14T20:30:07Z","quality_flags":[],"is_partial":false,"is_reconstructed":false,"confidence_score":1.0,"payload":{"provider":"bitflyer_ws_board","exchange":"bitflyer","transport":"websocket","channel":"lightning_board_BTC_JPY","received_ts":"2026-03-14T20:30:07.282126Z","subscription_id":null,"message_id":null,"source_sequence":null,"raw_message_meta":{"raw_channel":"lightning_board_BTC_JPY","subscription_channel":"lightning_board_BTC_JPY","recv_timeout_sec":10,"ssl_verify":false,"socket_url":"wss://ws.lightstream.bitflyer.com/json-rpc"},"source_payload":{"mid_price":11313931.0,"bids":[{"price":11307498.0,"size":0.0},{"price":11309974.0,"size":0.0},{"price":11306932.0,"size":0.0},{"price":11311635.0,"size":0.0}],"asks":[{"price":11317185.0,"size":0.0},{"price":11317032.0,"size":0.0},{"price":11316786.0,"size":0.0},{"price":11316788.0,"size":0.03381192}]}}}
{"schema_version":"collector.vnext.raw","schema_contract":null,"schema_contract_version":null,"payload_contract_version":null,"record_type":"market.orderbook.diff","record_id":"collector_main-market-orderbook-diff-000000000065","collector_id":"collector_main","collector_role":"production","host_name":"MAIN-PC","session_id":"collector_main-sess-20260314T202512Z-5e0ec04a","stream_session_id":"collector_main-stream-bitflyer-board_ws-20260314T203007Z-9ed26c91","exchange":"bitflyer","market":"spot","symbol":"BTC_JPY","instrument_id":"bitflyer.spot.BTC_JPY","channel":"board_ws","transport":"websocket","source_event_id":null,"source_sequence":null,"sequence_id":65,"exchange_ts":null,"collector_ts":"2026-03-14T20:30:07Z","ingest_ts":"2026-03-14T20:30:07Z","event_ts":"2026-03-14T20:30:07Z","quality_flags":[],"is_partial":false,"is_reconstructed":false,"confidence_score":1.0,"payload":{"provider":"bitflyer_ws_board","exchange":"bitflyer","transport":"websocket","channel":"lightning_board_BTC_JPY","received_ts":"2026-03-14T20:30:07.391679Z","subscription_id":null,"message_id":null,"source_sequence":null,"raw_message_meta":{"raw_channel":"lightning_board_BTC_JPY","subscription_channel":"lightning_board_BTC_JPY","recv_timeout_sec":10,"ssl_verify":false,"socket_url":"wss://ws.lightstream.bitflyer.com/json-rpc"},"source_payload":{"mid_price":11314134.0,"bids":[{"price":11283390.0,"size":0.002},{"price":11309671.0,"size":0.0},{"price":11311074.0,"size":0.0}],"asks":[{"price":11316788.0,"size":0.0},{"price":11325482.0,"size":0.2631}]}}}
{"schema_version":"collector.vnext.raw","schema_contract":null,"schema_contract_version":null,"payload_contract_version":null,"record_type":"market.orderbook.diff","record_id":"collector_main-market-orderbook-diff-000000000067","collector_id":"collector_main","collector_role":"production","host_name":"MAIN-PC","session_id":"collector_main-sess-20260314T202512Z-5e0ec04a","stream_session_id":"collector_main-stream-bitflyer-board_ws-20260314T203007Z-9ed26c91","exchange":"bitflyer","market":"spot","symbol":"BTC_JPY","instrument_id":"bitflyer.spot.BTC_JPY","channel":"board_ws","transport":"websocket","source_event_id":null,"source_sequence":null,"sequence_id":67,"exchange_ts":null,"collector_ts":"2026-03-14T20:30:07Z","ingest_ts":"2026-03-14T20:30:07Z","event_ts":"2026-03-14T20:30:07Z","quality_flags":[],"is_partial":false,"is_reconstructed":false,"confidence_score":1.0,"payload":{"provider":"bitflyer_ws_board","exchange":"bitflyer","transport":"websocket","channel":"lightning_board_BTC_JPY","received_ts":"2026-03-14T20:30:07.501012Z","subscription_id":null,"message_id":null,"source_sequence":null,"raw_message_meta":{"raw_channel":"lightning_board_BTC_JPY","subscription_channel":"lightning_board_BTC_JPY","recv_timeout_sec":10,"ssl_verify":false,"socket_url":"wss://ws.lightstream.bitflyer.com/json-rpc"},"source_payload":{"mid_price":11313929.0,"bids":[{"price":11311636.0,"size":0.0},{"price":11308724.0,"size":0.0},{"price":11310585.0,"size":0.014412}],"asks":[{"price":11316785.0,"size":0.0},{"price":11317161.0,"size":0.0176687},{"price":11317196.0,"size":0.0},{"price":11316786.0,"size":0.0862}]}}}
{"schema_version":"collector.vnext.raw","schema_contract":null,"schema_contract_version":null,"payload_contract_version":null,"record_type":"market.orderbook.diff","record_id":"collector_main-market-orderbook-diff-000000000069","collector_id":"collector_main","collector_role":"production","host_name":"MAIN-PC","session_id":"collector_main-sess-20260314T202512Z-5e0ec04a","stream_session_id":"collector_main-stream-bitflyer-board_ws-20260314T203007Z-9ed26c91","exchange":"bitflyer","market":"spot","symbol":"BTC_JPY","instrument_id":"bitflyer.spot.BTC_JPY","channel":"board_ws","transport":"websocket","source_event_id":null,"source_sequence":null,"sequence_id":69,"exchange_ts":null,"collector_ts":"2026-03-14T20:30:07Z","ingest_ts":"2026-03-14T20:30:07Z","event_ts":"2026-03-14T20:30:07Z","quality_flags":[],"is_partial":false,"is_reconstructed":false,"confidence_score":1.0,"payload":{"provider":"bitflyer_ws_board","exchange":"bitflyer","transport":"websocket","channel":"lightning_board_BTC_JPY","received_ts":"2026-03-14T20:30:07.622269Z","subscription_id":null,"message_id":null,"source_sequence":null,"raw_message_meta":{"raw_channel":"lightning_board_BTC_JPY","subscription_channel":"lightning_board_BTC_JPY","recv_timeout_sec":10,"ssl_verify":false,"socket_url":"wss://ws.lightstream.bitflyer.com/json-rpc"},"source_payload":{"mid_price":11313930.0,"bids":[{"price":11308775.0,"size":0.005},{"price":11311074.0,"size":0.05242693},{"price":11302784.0,"size":0.0},{"price":11307325.0,"size":0.0}],"asks":[{"price":11317195.0,"size":0.0323904},{"price":11332137.0,"size":0.0}]}}}
{"schema_version":"collector.vnext.raw","schema_contract":null,"schema_contract_version":null,"payload_contract_version":null,"record_type":"market.orderbook.snapshot","record_id":"collector_main-market-orderbook-snapshot-000000000071","collector_id":"collector_main","collector_role":"production","host_name":"MAIN-PC","session_id":"collector_main-sess-20260314T202512Z-5e0ec04a","stream_session_id":"collector_main-stream-bitflyer-board_ws-20260314T203007Z-9ed26c91","exchange":"bitflyer","market":"spot","symbol":"BTC_JPY","instrument_id":"bitflyer.spot.BTC_JPY","channel":"board_ws","transport":"websocket","source_event_id":null,"source_sequence":null,"sequence_id":71,"exchange_ts":null,"collector_ts":"2026-03-14T20:30:07Z","ingest_ts":"2026-03-14T20:30:07Z","event_ts":"2026-03-14T20:30:07Z","quality_flags":[],"is_partial":false,"is_reconstructed":false,"confidence_score":1.0,"payload":{"provider":"bitflyer_ws_board_snapshot","exchange":"bitflyer","transport":"websocket","channel":"lightning_board_snapshot_BTC_JPY","received_ts":"2026-03-14T20:30:07.693447Z","subscription_id":null,"message_id":null,"source_sequence":null,"raw_message_meta":{"raw_channel":"lightning_board_snapshot_BTC_JPY","subscription_channel":"lightning_board_snapshot_BTC_JPY","recv_timeout_sec":10,"ssl_verify":false,"socket_url":"wss://ws.lightstream.bitflyer.com/json-rpc"},"source_payload":{"mid_price":11313929.0,"bids":[{"price":11311074.0,"size":0.05242693},{"price":11311073.0,"size":0.005},{"price":11310585.0,"size":0.014412},{"price":11309735.0,"size":0.015276},{"price":11309634.0,"size":0.02},{"price":11309277.0,"size":0.0083579},{"price":11309242.0,"size":0.015168},{"price":11308775.0,"size":0.005},{"price":11308725.0,"size":0.02},{"price":11308365.0,"size":0.02},{"price":11308364.0,"size":0.0099986},{"price":11308024.0,"size":0.02},{"price":11308023.0,"size":0.5},{"price":11307805.0,"size":0.014688},{"price":11307440.0,"size":0.0801},{"price":11307046.0,"size":0.5},{"price":11306067.0,"size":0.053},{"price":11305384.0,"size":0.01},{"price":11304585.0,"size":0.01},{"price":11303619.0,"size":2.97274495},{"price":11303343.0,"size":0.054432},{"price":11302835.0,"size":0.0013039},{"price":11300844.0,"size":0.048},{"price":11300649.0,"size":0.0099986},{"price":11298581.0,"size":0.15},{"price":11290403.0,"size":0.3122},{"price":11289652.0,"size":0.6},{"price":11288328.0,"size":0.002},{"price":11287916.0,"size":0.002},{"price":11287641.0,"size":0.2854},{"price":11286090.0,"size":0.18915459},{"price":11285264.0,"size":0.29858071},{"price":11284933.0,"size":0.002},{"price":11284879.0,"size":0.3075},{"price":11283390.0,"size":0.002},{"price":11282117.0,"size":0.3055},{"price":11281538.0,"size":0.002},{"price":11280205.0,"size":0.001},{"price":11279607.0,"size":0.6},{"price":11279282.0,"size":0.0015},{"price":11278143.0,"size":0.002},{"price":11277748.0,"size":0.0966561},{"price":11277602.0,"size":0.005},{"price":11275102.0,"size":0.01},{"price":11275000.0,"size":0.001},{"price":11274748.0,"size":0.002},{"price":11274588.0,"size":0.0047},{"price":11271353.0,"size":0.002},{"price":11271000.0,"size":0.003},{"price":11270000.0,"size":0.106},{"price":11268871.0,"size":0.281},{"price":11268411.0,"size":0.01},{"price":11267958.0,"size":0.002},{"price":11266666.0,"size":0.04},{"price":11265000.0,"size":0.02},{"price":11264563.0,"size":0.002},{"price":11263807.0,"size":1.484},{"price":11263000.0,"size":0.006},{"price":11262564.0,"size":0.0015},{"price":11261168.0,"size":0.002},{"price":11260000.0,"size":0.3565},{"price":11257985.0,"size":1.966},{"price":11257773.0,"size":0.002},{"price":11257537.0,"size":0.001},{"price":11257000.0,"size":0.001},{"price":11255200.0,"size":0.001},{"price":11255115.0,"size":0.00377},{"price":11253000.0,"size":0.03189},{"price":11251000.0,"size":0.0131},{"price":11250250.0,"size":0.00105},{"price":11250200.0,"size":0.001},{"price":11250100.0,"size":0.015},{"price":11250005.0,"size":0.001},{"price":11250001.0,"size":0.00104},{"price":11250000.0,"size":1.66134},{"price":11248998.0,"size":2.036},{"price":11246544.0,"size":0.0015},{"price":11246203.0,"size":0.001},{"price":11245141.0,"size":0.0031},{"price":11245000.0,"size":0.05},{"price":11244444.0,"size":0.04},{"price":11244243.0,"size":0.01},{"price":11240200.0,"size":0.001},{"price":11240000.0,"size":0.007304},{"price":11236190.0,"size":0.01},{"price":11235200.0,"size":0.001},{"price":11234869.0,"size":0.001},{"price":11232000.0,"size":0.089},{"price":11231243.0,"size":0.01},{"price":11231000.0,"size":0.105},{"price":11230200.0,"size":0.001},{"price":11230000.0,"size":0.0308},{"price":11228423.0,"size":1.951},{"price":11224500.0,"size":0.06},{"price":11224355.0,"size":0.0015},{"price":11223968.0,"size":0.001},{"price":11223535.0,"size":0.001},{"price":11223344.0,"size":0.01},{"price":11223000.0,"size":0.1},{"price":11222222.0,"size":0.092525},{"price":11221459.0,"size":0.1393},{"price":11221120.0,"size":0.011},{"price":11220200.0,"size":0.001},{"price":11220001.0,"size":0.004457},{"price":11220000.0,"size":0.321},{"price":11219517.0,"size":0.01},{"price":11219000.0,"size":0.1},{"price":11215200.0,"size":0.001},{"price":11215000.0,"size":0.02},{"price":11212358.0,"size":1.2},{"price":11212201.0,"size":0.001},{"price":11211800.0,"size":0.001},{"price":11211111.0,"size":0.06},{"price":11210200.0,"size":0.001},{"price":11210000.0,"size":0.10622},{"price":11208032.0,"size":0.01},{"price":11207755.0,"size":0.0015},{"price":11206000.0,"size":0.09015},{"price":11205200.0,"size":0.001},{"price":11204578.0,"size":0.002},{"price":11203931.0,"size":1.0},{"price":11201000.0,"size":0.01},{"price":11200867.0,"size":0.001},{"price":11200800.0,"size":0.05},{"price":11200425.0,"size":0.1},{"price":11200200.0,"size":0.001},{"price":11200198.0,"size":0.003},{"price":11200150.0,"size":0.002},{"price":11200002.0,"size":0.001},{"price":11200001.0,"size":0.01104},{"price":11200000.0,"size":1.35988728},{"price":11198508.0,"size":0.05},{"price":11198243.0,"size":0.01},{"price":11197134.0,"size":2.993},{"price":11197000.0,"size":0.0085},{"price":11195692.0,"size":0.0015},{"price":11194090.0,"size":0.03},{"price":11190770.0,"size":0.0309},{"price":11190000.0,"size":0.0010016},{"price":11189555.0,"size":0.5},{"price":11189533.0,"size":0.001},{"price":11188629.0,"size":0.01},{"price":11188382.0,"size":0.001},{"price":11185000.0,"size":0.0085},{"price":11180043.0,"size":0.972},{"price":11180000.0,"size":0.23215},{"price":11178973.0,"size":0.0015},{"price":11178199.0,"size":0.001},{"price":11170000.0,"size":0.001},{"price":11169662.0,"size":0.01},{"price":11169593.0,"size":0.001},{"price":11169243.0,"size":0.01},{"price":11166865.0,"size":0.001},{"price":11164029.0,"size":0.001},{"price":11160854.0,"size":0.1},{"price":11160000.0,"size":0.02376},{"price":11156269.0,"size":0.01},{"price":11155531.0,"size":0.001},{"price":11155377.0,"size":0.00636009},{"price":11153999.0,"size":0.00101},{"price":11151000.0,"size":0.001},{"price":11150250.0,"size":0.00175},{"price":11150005.0,"size":0.001},{"price":11150001.0,"size":0.00104},{"price":11150000.0,"size":0.6398956},{"price":11148000.0,"size":0.08963},{"price":11144197.0,"size":0.001},{"price":11144000.0,"size":0.0897},{"price":11140000.0,"size":0.2},{"price":11136243.0,"size":0.01},{"price":11136155.0,"size":0.02},{"price":11135869.0,"size":0.1},{"price":11130000.0,"size":0.116},{"price":11129979.0,"size":0.0053908},{"price":11126388.0,"size":0.02},{"price":11124900.0,"size":0.00133},{"price":11121090.0,"size":0.1},{"price":11120000.0,"size":0.0033},{"price":11118078.0,"size":0.01},{"price":11111800.0,"size":0.001},{"price":11111111.0,"size":0.2919257},{"price":11111000.0,"size":0.003},{"price":11110594.0,"size":0.001},{"price":11110000.0,"size":0.056937},{"price":11109662.0,"size":0.01},{"price":11108008.0,"size":0.01},{"price":11106000.0,"size":0.2},{"price":11105000.0,"size":0.02},{"price":11101297.0,"size":0.001},{"price":11100005.0,"size":0.001},{"price":11100001.0,"size":0.01104},{"price":11100000.0,"size":1.7472049},{"price":11099141.0,"size":0.01},{"price":11096243.0,"size":0.01},{"price":11094090.0,"size":0.01},{"price":11088888.0,"size":0.001},{"price":11085245.0,"size":0.001},{"price":11080200.0,"size":0.001},{"price":11080000.0,"size":0.0223},{"price":11075100.0,"size":0.003},{"price":11071558.0,"size":1.0},{"price":11070200.0,"size":0.001},{"price":11070000.0,"size":0.0902},{"price":11065200.0,"size":0.001},{"price":11064370.0,"size":0.00497091},{"price":11060200.0,"size":0.001},{"price":11060000.0,"size":0.145},{"price":11059689.0,"size":0.009},{"price":11056428.0,"size":0.002},{"price":11055500.0,"size":0.02},{"price":11055200.0,"size":0.001},{"price":11055100.0,"size":0.003},{"price":11050200.0,"size":0.001},{"price":11050005.0,"size":0.001},{"price":11050002.0,"size":0.001},{"price":11050001.0,"size":0.00104},{"price":11050000.0,"size":0.43176147},{"price":11046420.0,"size":0.2},{"price":11044243.0,"size":0.01},{"price":11041380.0,"size":0.01},{"price":11040200.0,"size":0.001},{"price":11040000.0,"size":0.00777181},{"price":11035865.0,"size":0.1},{"price":11035200.0,"size":0.001},{"price":11035000.0,"size":0.0013},{"price":11030200.0,"size":0.001},{"price":11030000.0,"size":0.025},{"price":11025500.0,"size":0.009531},{"price":11025200.0,"size":0.001},{"price":11025000.0,"size":0.71497},{"price":11020772.0,"size":0.014},{"price":11020200.0,"size":0.002},{"price":11020000.0,"size":0.005},{"price":11015200.0,"size":0.001},{"price":11012000.0,"size":0.1},{"price":11011800.0,"size":0.001},{"price":11010200.0,"size":0.001},{"price":11010000.0,"size":0.347},{"price":11007277.0,"size":0.01},{"price":11006000.0,"size":0.2},{"price":11005200.0,"size":0.001},{"price":11004890.0,"size":0.001535},{"price":11003000.0,"size":0.0155},{"price":11001000.0,"size":0.013},{"price":11000500.0,"size":0.05117658},{"price":11000200.0,"size":0.001},{"price":11000002.0,"size":0.004},{"price":11000001.0,"size":0.02604},{"price":11000000.0,"size":4.55923365},{"price":10999999.0,"size":0.003},{"price":10999000.0,"size":0.001},{"price":10996855.0,"size":0.0011},{"price":10995200.0,"size":0.001},{"price":10994499.0,"size":0.00169176},{"price":10990200.0,"size":0.001},{"price":10990000.0,"size":0.10219},{"price":10989001.0,"size":0.00197},{"price":10988999.0,"size":0.001},{"price":10988324.0,"size":0.002},{"price":10987654.0,"size":0.001},{"price":10985200.0,"size":0.001},{"price":10985150.0,"size":0.01},{"price":10980500.0,"size":0.005},{"price":10980200.0,"size":0.001},{"price":10980002.0,"size":0.4},{"price":10980000.0,"size":0.028},{"price":10975200.0,"size":0.001},{"price":10975000.0,"size":0.1},{"price":10971261.0,"size":0.001},{"price":10971243.0,"size":0.01},{"price":10970375.0,"size":1.9},{"price":10970200.0,"size":0.001},{"price":10970000.0,"size":0.09304},{"price":10966600.0,"size":0.001003},{"price":10965200.0,"size":0.001},{"price":10960200.0,"size":0.001},{"price":10960000.0,"size":0.0083},{"price":10956673.0,"size":0.01},{"price":10955200.0,"size":0.001},{"price":10954950.0,"size":0.001},{"price":10950500.0,"size":0.005},{"price":10950001.0,"size":0.00204},{"price":10950000.0,"size":0.5485028},{"price":10949550.0,"size":0.01870657},{"price":10949172.0,"size":0.1},{"price":10948000.0,"size":0.1},{"price":10945243.0,"size":0.01},{"price":10940402.0,"size":0.001},{"price":10940200.0,"size":0.001},{"price":10940000.0,"size":0.331},{"price":10938243.0,"size":0.01},{"price":10936200.0,"size":0.00137},{"price":10935200.0,"size":0.001},{"price":10930200.0,"size":0.002},{"price":10930000.0,"size":0.0193},{"price":10925200.0,"size":0.002},{"price":10924451.0,"size":0.0012},{"price":10920509.0,"size":0.01},{"price":10920200.0,"size":0.002},{"price":10920000.0,"size":0.52}],"asks":[{"price":11316785.0,"size":0.03452268},{"price":11316786.0,"size":0.0862},{"price":11317161.0,"size":0.0176687},{"price":11318668.0,"size":0.02},{"price":11318876.0,"size":0.02},{"price":11319518.0,"size":0.02},{"price":11319579.0,"size":0.02},{"price":11319958.0,"size":0.3103},{"price":11320000.0,"size":0.02},{"price":11320163.0,"size":0.015348},{"price":11320458.0,"size":0.014844},{"price":11321760.0,"size":0.052056},{"price":11322000.0,"size":0.005},{"price":11322245.0,"size":0.01},{"price":11322720.0,"size":0.3039},{"price":11323191.0,"size":0.57568243},{"price":11323572.0,"size":0.015},{"price":11324837.0,"size":0.01},{"price":11325482.0,"size":0.2631},{"price":11325976.0,"size":0.0529},{"price":11326901.0,"size":0.4199},{"price":11328050.0,"size":0.002},{"price":11328091.0,"size":0.0099982},{"price":11328244.0,"size":0.3111},{"price":11329436.0,"size":0.0015},{"price":11331059.0,"size":0.001},{"price":11332138.0,"size":0.0071267},{"price":11340000.0,"size":0.13586406},{"price":11340647.0,"size":0.001},{"price":11342956.0,"size":1.60199848},{"price":11342957.0,"size":0.01},{"price":11346154.0,"size":0.0015},{"price":11348000.0,"size":0.1999},{"price":11349700.0,"size":0.001},{"price":11350000.0,"size":0.022},{"price":11353807.0,"size":0.001},{"price":11353877.0,"size":0.001},{"price":11354939.0,"size":0.01},{"price":11355555.0,"size":0.001},{"price":11359242.0,"size":0.0011},{"price":11359700.0,"size":0.001},{"price":11362692.0,"size":0.0015},{"price":11365210.0,"size":0.61109747},{"price":11365211.0,"size":0.31285479},{"price":11368857.0,"size":0.47834347},{"price":11368858.0,"size":1.489},{"price":11369700.0,"size":0.001},{"price":11370000.0,"size":0.1},{"price":11370766.0,"size":1.928},{"price":11376000.0,"size":0.02},{"price":11376545.0,"size":0.001},{"price":11377000.0,"size":0.2287},{"price":11377269.0,"size":0.002},{"price":11379471.0,"size":2.018},{"price":11379700.0,"size":0.001},{"price":11379865.0,"size":0.03},{"price":11380000.0,"size":0.0223},{"price":11380324.0,"size":0.002},{"price":11381766.0,"size":0.4},{"price":11382386.0,"size":0.0015},{"price":11385000.0,"size":0.2548},{"price":11385403.0,"size":0.002},{"price":11385664.0,"size":0.002},{"price":11386197.0,"size":0.002},{"price":11387072.0,"size":0.01},{"price":11387354.0,"size":0.002},{"price":11387879.0,"size":0.001},{"price":11388885.0,"size":0.03},{"price":11389700.0,"size":0.001},{"price":11390000.0,"size":0.2488},{"price":11390050.0,"size":0.001},{"price":11392387.0,"size":1.0},{"price":11394939.0,"size":0.01},{"price":11395000.0,"size":0.06},{"price":11395775.0,"size":0.01},{"price":11396555.0,"size":0.03},{"price":11398444.0,"size":0.001995},{"price":11398783.0,"size":1.943},{"price":11399213.0,"size":0.001},{"price":11399673.0,"size":0.0015},{"price":11399700.0,"size":0.001},{"price":11400000.0,"size":0.5225},{"price":11405000.0,"size":0.0275},{"price":11406336.0,"size":1.0},{"price":11408700.0,"size":0.001},{"price":11409415.0,"size":0.055},{"price":11410000.0,"size":0.03},{"price":11410547.0,"size":0.001},{"price":11410853.0,"size":0.002},{"price":11412000.0,"size":0.0878},{"price":11415000.0,"size":0.002},{"price":11415141.0,"size":0.0041},{"price":11417481.0,"size":0.0015},{"price":11418700.0,"size":0.001},{"price":11420000.0,"size":0.401},{"price":11421268.0,"size":0.05},{"price":11421881.0,"size":0.001},{"price":11423339.0,"size":2.0},{"price":11424296.0,"size":0.002},{"price":11424941.0,"size":0.972},{"price":11425000.0,"size":0.049},{"price":11426426.0,"size":0.002},{"price":11428121.0,"size":0.002},{"price":11428700.0,"size":0.001},{"price":11429302.0,"size":0.01},{"price":11432718.0,"size":0.002},{"price":11433211.0,"size":0.03},{"price":11433215.0,"size":0.001},{"price":11433333.0,"size":0.001},{"price":11437315.0,"size":0.002},{"price":11438525.0,"size":0.0011},{"price":11438700.0,"size":0.001},{"price":11439557.0,"size":0.001},{"price":11440000.0,"size":0.1038},{"price":11441911.0,"size":0.002},{"price":11443629.0,"size":0.002},{"price":11444549.0,"size":0.001},{"price":11446508.0,"size":0.001},{"price":11447000.0,"size":0.01},{"price":11447071.0,"size":0.002},{"price":11448000.0,"size":0.0875},{"price":11448700.0,"size":0.001},{"price":11450000.0,"size":0.258},{"price":11451105.0,"size":0.002},{"price":11453321.0,"size":0.03},{"price":11455702.0,"size":0.002},{"price":11455883.0,"size":0.001},{"price":11458700.0,"size":0.001},{"price":11458988.0,"size":0.01},{"price":11460000.0,"size":0.01702},{"price":11460299.0,"size":0.002},{"price":11464896.0,"size":0.002},{"price":11467217.0,"size":0.001},{"price":11468700.0,"size":0.001},{"price":11470000.0,"size":0.01},{"price":11471000.0,"size":0.01},{"price":11475000.0,"size":0.0028},{"price":11478431.0,"size":0.002},{"price":11478551.0,"size":0.001},{"price":11478700.0,"size":0.001},{"price":11480000.0,"size":0.12491},{"price":11485000.0,"size":0.01},{"price":11486555.0,"size":0.03},{"price":11487685.0,"size":0.01},{"price":11488000.0,"size":0.102},{"price":11488700.0,"size":0.001},{"price":11489885.0,"size":0.001},{"price":11490841.0,"size":0.002},{"price":11495450.0,"size":0.002},{"price":11495850.0,"size":0.001},{"price":11498700.0,"size":0.001},{"price":11498917.0,"size":0.002},{"price":11499000.0,"size":0.01},{"price":11500000.0,"size":0.69859519},{"price":11501219.0,"size":0.001},{"price":11502377.0,"size":0.002},{"price":11502800.0,"size":0.00132},{"price":11503108.0,"size":0.0198},{"price":11505000.0,"size":0.0028},{"price":11505001.0,"size":0.002},{"price":11505836.0,"size":0.003},{"price":11508431.0,"size":0.047},{"price":11508700.0,"size":0.001},{"price":11508888.0,"size":0.02},{"price":11510000.0,"size":0.0976},{"price":11512553.0,"size":0.001},{"price":11513633.0,"size":0.08},{"price":11514332.0,"size":0.02},{"price":11518700.0,"size":0.001},{"price":11518992.0,"size":0.002},{"price":11519855.0,"size":0.01},{"price":11520000.0,"size":0.001},{"price":11522423.0,"size":0.97},{"price":11523211.0,"size":0.01},{"price":11523887.0,"size":0.001},{"price":11524999.0,"size":0.001},{"price":11528700.0,"size":0.001},{"price":11529852.0,"size":0.01},{"price":11530000.0,"size":0.261},{"price":11533985.0,"size":0.002},{"price":11534084.0,"size":0.001},{"price":11535321.0,"size":0.01},{"price":11538666.0,"size":0.002},{"price":11538700.0,"size":0.001},{"price":11540000.0,"size":0.0048},{"price":11540357.0,"size":0.002},{"price":11541011.0,"size":0.005},{"price":11541109.0,"size":0.01},{"price":11544663.0,"size":0.002},{"price":11545262.0,"size":0.002},{"price":11546541.0,"size":0.01},{"price":11548144.0,"size":0.002},{"price":11548700.0,"size":0.001},{"price":11550000.0,"size":0.014},{"price":11551109.0,"size":0.01},{"price":11551625.0,"size":0.002},{"price":11552111.0,"size":0.01},{"price":11553687.0,"size":0.1},{"price":11555106.0,"size":0.002},{"price":11555115.0,"size":0.001},{"price":11556000.0,"size":0.1},{"price":11558587.0,"size":0.002},{"price":11558700.0,"size":0.001},{"price":11559855.0,"size":0.01},{"price":11560831.0,"size":0.0198},{"price":11561109.0,"size":0.01},{"price":11562000.0,"size":0.087},{"price":11562068.0,"size":0.002},{"price":11565548.0,"size":0.002},{"price":11566139.0,"size":0.0228},{"price":11566551.0,"size":0.01},{"price":11568700.0,"size":0.001},{"price":11569029.0,"size":0.002},{"price":11570196.0,"size":0.002},{"price":11571109.0,"size":0.01},{"price":11572510.0,"size":0.002},{"price":11573211.0,"size":0.01},{"price":11574840.0,"size":0.002},{"price":11575991.0,"size":0.001},{"price":11578700.0,"size":0.001},{"price":11579484.0,"size":0.002},{"price":11579851.0,"size":0.01},{"price":11580000.0,"size":0.7735},{"price":11581109.0,"size":0.01},{"price":11584128.0,"size":0.002},{"price":11585000.0,"size":0.002},{"price":11586532.0,"size":0.01},{"price":11587498.0,"size":0.0198},{"price":11588700.0,"size":0.001},{"price":11589612.0,"size":0.012},{"price":11590000.0,"size":0.1},{"price":11590749.0,"size":0.002},{"price":11591109.0,"size":0.01},{"price":11593211.0,"size":0.01},{"price":11596753.0,"size":0.002},{"price":11598555.0,"size":0.01},{"price":11598700.0,"size":0.001},{"price":11599999.0,"size":0.001},{"price":11600000.0,"size":3.6141},{"price":11601109.0,"size":0.02},{"price":11606655.0,"size":0.01},{"price":11610000.0,"size":0.302},{"price":11611109.0,"size":0.01},{"price":11613321.0,"size":0.01},{"price":11620000.0,"size":1.35441682},{"price":11621011.0,"size":0.01},{"price":11621109.0,"size":0.01},{"price":11623096.0,"size":0.008},{"price":11629000.0,"size":0.1},{"price":11630000.0,"size":0.201},{"price":11631059.0,"size":0.01},{"price":11631479.0,"size":0.01},{"price":11631773.0,"size":0.00386871},{"price":11635950.0,"size":0.001},{"price":11638259.0,"size":0.001},{"price":11639700.0,"size":0.001},{"price":11640000.0,"size":1.0},{"price":11640820.0,"size":0.01},{"price":11645040.0,"size":1.7},{"price":11645295.0,"size":0.05},{"price":11647158.0,"size":0.05},{"price":11649900.0,"size":0.02906},{"price":11649999.0,"size":0.001},{"price":11650000.0,"size":0.593},{"price":11651059.0,"size":0.01},{"price":11653658.0,"size":0.008},{"price":11654321.0,"size":0.001},{"price":11659700.0,"size":0.001},{"price":11661479.0,"size":0.01},{"price":11666000.0,"size":0.001},{"price":11666666.0,"size":0.013},{"price":11669700.0,"size":0.001},{"price":11671059.0,"size":0.01},{"price":11672562.0,"size":0.0198},{"price":11679224.0,"size":0.012},{"price":11680000.0,"size":0.004},{"price":11685000.0,"size":0.003},{"price":11688000.0,"size":0.001},{"price":11689732.0,"size":0.01},{"price":11690330.0,"size":0.0198},{"price":11691059.0,"size":0.01},{"price":11692558.0,"size":0.01},{"price":11698800.0,"size":0.00131},{"price":11699000.0,"size":0.001},{"price":11699631.0,"size":0.001},{"price":11699998.0,"size":0.01},{"price":11699999.0,"size":0.001},{"price":11700000.0,"size":1.03762841},{"price":11701059.0,"size":0.01},{"price":11720000.0,"size":0.1},{"price":11721059.0,"size":0.01},{"price":11725000.0,"size":0.005},{"price":11726791.0,"size":0.01},{"price":11730000.0,"size":0.9382},{"price":11740000.0,"size":0.101},{"price":11741059.0,"size":0.01},{"price":11748937.0,"size":0.001},{"price":11749999.0,"size":0.001},{"price":11750000.0,"size":0.90537866},{"price":11750050.0,"size":0.2}]}}}
{"schema_version":"collector.vnext.raw","schema_contract":null,"schema_contract_version":null,"payload_contract_version":null,"record_type":"market.orderbook.diff","record_id":"collector_main-market-orderbook-diff-000000000061","collector_id":"collector_main","collector_role":"production","host_name":"MAIN-PC","session_id":"collector_main-sess-20260314T203022Z-d6ce6cf3","stream_session_id":"collector_main-stream-bitflyer-board_ws-20260314T203122Z-1da3472e","exchange":"bitflyer","market":"spot","symbol":"BTC_JPY","instrument_id":"bitflyer.spot.BTC_JPY","channel":"board_ws","transport":"websocket","source_event_id":null,"source_sequence":null,"sequence_id":61,"exchange_ts":null,"collector_ts":"2026-03-14T20:31:22Z","ingest_ts":"2026-03-14T20:31:22Z","event_ts":"2026-03-14T20:31:22Z","quality_flags":[],"is_partial":false,"is_reconstructed":false,"confidence_score":1.0,"payload":{"provider":"bitflyer_ws_board","exchange":"bitflyer","transport":"websocket","channel":"lightning_board_BTC_JPY","received_ts":"2026-03-14T20:31:22.292112Z","subscription_id":null,"message_id":null,"source_sequence":null,"raw_message_meta":{"raw_channel":"lightning_board_BTC_JPY","subscription_channel":"lightning_board_BTC_JPY","recv_timeout_sec":10,"ssl_verify":false,"socket_url":"wss://ws.lightstream.bitflyer.com/json-rpc"},"source_payload":{"mid_price":11313234.0,"bids":[{"price":11309893.0,"size":0.0}],"asks":[{"price":11316022.0,"size":0.0}]}}}
{"schema_version":"collector.vnext.raw","schema_contract":null,"schema_contract_version":null,"payload_contract_version":null,"record_type":"market.orderbook.diff","record_id":"collector_main-market-orderbook-diff-000000000065","collector_id":"collector_main","collector_role":"production","host_name":"MAIN-PC","session_id":"collector_main-sess-20260314T203022Z-d6ce6cf3","stream_session_id":"collector_main-stream-bitflyer-board_ws-20260314T203122Z-1da3472e","exchange":"bitflyer","market":"spot","symbol":"BTC_JPY","instrument_id":"bitflyer.spot.BTC_JPY","channel":"board_ws","transport":"websocket","source_event_id":null,"source_sequence":null,"sequence_id":65,"exchange_ts":null,"collector_ts":"2026-03-14T20:31:22Z","ingest_ts":"2026-03-14T20:31:22Z","event_ts":"2026-03-14T20:31:22Z","quality_flags":[],"is_partial":false,"is_reconstructed":false,"confidence_score":1.0,"payload":{"provider":"bitflyer_ws_board","exchange":"bitflyer","transport":"websocket","channel":"lightning_board_BTC_JPY","received_ts":"2026-03-14T20:31:22.390976Z","subscription_id":null,"message_id":null,"source_sequence":null,"raw_message_meta":{"raw_channel":"lightning_board_BTC_JPY","subscription_channel":"lightning_board_BTC_JPY","recv_timeout_sec":10,"ssl_verify":false,"socket_url":"wss://ws.lightstream.bitflyer.com/json-rpc"},"source_payload":{"mid_price":11313181.0,"bids":[],"asks":[{"price":11316023.0,"size":0.00997228},{"price":11315809.0,"size":0.03403537},{"price":11315704.0,"size":0.0347},{"price":11315810.0,"size":0.203}]}}}
{"schema_version":"collector.vnext.raw","schema_contract":null,"schema_contract_version":null,"payload_contract_version":null,"record_type":"market.orderbook.diff","record_id":"collector_main-market-orderbook-diff-000000000067","collector_id":"collector_main","collector_role":"production","host_name":"MAIN-PC","session_id":"collector_main-sess-20260314T203022Z-d6ce6cf3","stream_session_id":"collector_main-stream-bitflyer-board_ws-20260314T203122Z-1da3472e","exchange":"bitflyer","market":"spot","symbol":"BTC_JPY","instrument_id":"bitflyer.spot.BTC_JPY","channel":"board_ws","transport":"websocket","source_event_id":null,"source_sequence":null,"sequence_id":67,"exchange_ts":null,"collector_ts":"2026-03-14T20:31:22Z","ingest_ts":"2026-03-14T20:31:22Z","event_ts":"2026-03-14T20:31:22Z","quality_flags":[],"is_partial":false,"is_reconstructed":false,"confidence_score":1.0,"payload":{"provider":"bitflyer_ws_board","exchange":"bitflyer","transport":"websocket","channel":"lightning_board_BTC_JPY","received_ts":"2026-03-14T20:31:22.609536Z","subscription_id":null,"message_id":null,"source_sequence":null,"raw_message_meta":{"raw_channel":"lightning_board_BTC_JPY","subscription_channel":"lightning_board_BTC_JPY","recv_timeout_sec":10,"ssl_verify":false,"socket_url":"wss://ws.lightstream.bitflyer.com/json-rpc"},"source_payload":{"mid_price":11313181.0,"bids":[],"asks":[{"price":11332024.0,"size":0.0},{"price":11315809.0,"size":0.0}]}}}
{"schema_version":"collector.vnext.raw","schema_contract":null,"schema_contract_version":null,"payload_contract_version":null,"record_type":"market.orderbook.diff","record_id":"collector_main-market-orderbook-diff-000000000069","collector_id":"collector_main","collector_role":"production","host_name":"MAIN-PC","session_id":"collector_main-sess-20260314T203022Z-d6ce6cf3","stream_session_id":"collector_main-stream-bitflyer-board_ws-20260314T203122Z-1da3472e","exchange":"bitflyer","market":"spot","symbol":"BTC_JPY","instrument_id":"bitflyer.spot.BTC_JPY","channel":"board_ws","transport":"websocket","source_event_id":null,"source_sequence":null,"sequence_id":69,"exchange_ts":null,"collector_ts":"2026-03-14T20:31:22Z","ingest_ts":"2026-03-14T20:31:22Z","event_ts":"2026-03-14T20:31:22Z","quality_flags":[],"is_partial":false,"is_reconstructed":false,"confidence_score":1.0,"payload":{"provider":"bitflyer_ws_board","exchange":"bitflyer","transport":"websocket","channel":"lightning_board_BTC_JPY","received_ts":"2026-03-14T20:31:22.735790Z","subscription_id":null,"message_id":null,"source_sequence":null,"raw_message_meta":{"raw_channel":"lightning_board_BTC_JPY","subscription_channel":"lightning_board_BTC_JPY","recv_timeout_sec":10,"ssl_verify":false,"socket_url":"wss://ws.lightstream.bitflyer.com/json-rpc"},"source_payload":{"mid_price":11313180.0,"bids":[],"asks":[{"price":11315703.0,"size":0.03515295},{"price":11332138.0,"size":0.0096922},{"price":11315810.0,"size":0.1255},{"price":11315704.0,"size":0.1268}]}}}
{"schema_version":"collector.vnext.raw","schema_contract":null,"schema_contract_version":null,"payload_contract_version":null,"record_type":"market.orderbook.snapshot","record_id":"collector_main-market-orderbook-snapshot-000000000071","collector_id":"collector_main","collector_role":"production","host_name":"MAIN-PC","session_id":"collector_main-sess-20260314T203022Z-d6ce6cf3","stream_session_id":"collector_main-stream-bitflyer-board_ws-20260314T203122Z-1da3472e","exchange":"bitflyer","market":"spot","symbol":"BTC_JPY","instrument_id":"bitflyer.spot.BTC_JPY","channel":"board_ws","transport":"websocket","source_event_id":null,"source_sequence":null,"sequence_id":71,"exchange_ts":null,"collector_ts":"2026-03-14T20:31:22Z","ingest_ts":"2026-03-14T20:31:22Z","event_ts":"2026-03-14T20:31:22Z","quality_flags":[],"is_partial":false,"is_reconstructed":false,"confidence_score":1.0,"payload":{"provider":"bitflyer_ws_board_snapshot","exchange":"bitflyer","transport":"websocket","channel":"lightning_board_snapshot_BTC_JPY","received_ts":"2026-03-14T20:31:22.802315Z","subscription_id":null,"message_id":null,"source_sequence":null,"raw_message_meta":{"raw_channel":"lightning_board_snapshot_BTC_JPY","subscription_channel":"lightning_board_snapshot_BTC_JPY","recv_timeout_sec":10,"ssl_verify":false,"socket_url":"wss://ws.lightstream.bitflyer.com/json-rpc"},"source_payload":{"mid_price":11313180.0,"bids":[{"price":11310658.0,"size":0.0099986},{"price":11310154.0,"size":0.04521264},{"price":11310153.0,"size":0.1275},{"price":11309858.0,"size":0.1275},{"price":11309736.0,"size":0.02},{"price":11309735.0,"size":0.015276},{"price":11309634.0,"size":0.02},{"price":11309242.0,"size":0.015168},{"price":11309010.0,"size":0.2},{"price":11308023.0,"size":0.5},{"price":11307805.0,"size":0.014688},{"price":11307440.0,"size":0.0801},{"price":11307141.0,"size":0.05},{"price":11307046.0,"size":0.5},{"price":11306023.0,"size":0.05},{"price":11305391.0,"size":0.053},{"price":11305384.0,"size":0.01},{"price":11304585.0,"size":0.01},{"price":11303663.0,"size":2.97712911},{"price":11303343.0,"size":0.054432},{"price":11303070.0,"size":0.0015213},{"price":11301266.0,"size":0.0099986},{"price":11301203.0,"size":0.078},{"price":11298581.0,"size":0.15},{"price":11296888.0,"size":0.98322348},{"price":11296886.0,"size":1.50015},{"price":11292672.0,"size":1.484},{"price":11289652.0,"size":0.6},{"price":11287992.0,"size":0.2982},{"price":11286090.0,"size":0.18915459},{"price":11285230.0,"size":0.308},{"price":11282468.0,"size":0.2858},{"price":11280205.0,"size":0.001},{"price":11279706.0,"size":0.2629},{"price":11279607.0,"size":0.6},{"price":11279282.0,"size":0.0015},{"price":11277748.0,"size":0.0966561},{"price":11277620.0,"size":1.966},{"price":11277602.0,"size":0.005},{"price":11275102.0,"size":0.01},{"price":11275000.0,"size":0.001},{"price":11274588.0,"size":0.0047},{"price":11271000.0,"size":0.003},{"price":11270000.0,"size":0.106},{"price":11268871.0,"size":0.281},{"price":11268411.0,"size":0.01},{"price":11266666.0,"size":0.04},{"price":11265000.0,"size":0.02},{"price":11263000.0,"size":0.006},{"price":11262564.0,"size":0.0015},{"price":11260000.0,"size":0.3565},{"price":11257537.0,"size":0.001},{"price":11257000.0,"size":0.001},{"price":11255200.0,"size":0.001},{"price":11255115.0,"size":0.00377},{"price":11253000.0,"size":0.03189},{"price":11251000.0,"size":0.0131},{"price":11250250.0,"size":0.00105},{"price":11250200.0,"size":0.001},{"price":11250100.0,"size":0.015},{"price":11250005.0,"size":0.001},{"price":11250001.0,"size":0.00104},{"price":11250000.0,"size":1.66134},{"price":11248998.0,"size":2.036},{"price":11246544.0,"size":0.0015},{"price":11246203.0,"size":0.001},{"price":11245141.0,"size":0.0031},{"price":11245000.0,"size":0.05},{"price":11244444.0,"size":0.04},{"price":11244243.0,"size":0.01},{"price":11240200.0,"size":0.001},{"price":11240000.0,"size":0.007304},{"price":11236190.0,"size":0.01},{"price":11235200.0,"size":0.001},{"price":11234869.0,"size":0.001},{"price":11232000.0,"size":0.089},{"price":11231243.0,"size":0.01},{"price":11231000.0,"size":0.105},{"price":11230200.0,"size":0.001},{"price":11230000.0,"size":0.0308},{"price":11228423.0,"size":1.951},{"price":11224500.0,"size":0.06},{"price":11224355.0,"size":0.0015},{"price":11223968.0,"size":0.001},{"price":11223535.0,"size":0.001},{"price":11223344.0,"size":0.01},{"price":11223000.0,"size":0.1},{"price":11222222.0,"size":0.092525},{"price":11221459.0,"size":0.1393},{"price":11221120.0,"size":0.011},{"price":11220200.0,"size":0.001},{"price":11220001.0,"size":0.004457},{"price":11220000.0,"size":0.321},{"price":11219517.0,"size":0.01},{"price":11219000.0,"size":0.1},{"price":11215200.0,"size":0.001},{"price":11215000.0,"size":0.02},{"price":11212358.0,"size":1.2},{"price":11212201.0,"size":0.001},{"price":11211800.0,"size":0.001},{"price":11211111.0,"size":0.06},{"price":11210200.0,"size":0.001},{"price":11210000.0,"size":0.10622},{"price":11208032.0,"size":0.01},{"price":11207755.0,"size":0.0015},{"price":11206000.0,"size":0.09015},{"price":11205200.0,"size":0.001},{"price":11204578.0,"size":0.002},{"price":11203931.0,"size":1.0},{"price":11201000.0,"size":0.01},{"price":11200867.0,"size":0.001},{"price":11200800.0,"size":0.05},{"price":11200425.0,"size":0.1},{"price":11200200.0,"size":0.001},{"price":11200198.0,"size":0.003},{"price":11200150.0,"size":0.002},{"price":11200002.0,"size":0.001},{"price":11200001.0,"size":0.01104},{"price":11200000.0,"size":1.35988728},{"price":11198508.0,"size":0.05},{"price":11198243.0,"size":0.01},{"price":11197134.0,"size":2.993},{"price":11197000.0,"size":0.0085},{"price":11195692.0,"size":0.0015},{"price":11194090.0,"size":0.03},{"price":11190770.0,"size":0.0309},{"price":11190000.0,"size":0.0010016},{"price":11189555.0,"size":0.5},{"price":11189533.0,"size":0.001},{"price":11188629.0,"size":0.01},{"price":11188382.0,"size":0.001},{"price":11185000.0,"size":0.0085},{"price":11180043.0,"size":0.972},{"price":11180000.0,"size":0.23215},{"price":11178973.0,"size":0.0015},{"price":11178199.0,"size":0.001},{"price":11170000.0,"size":0.001},{"price":11169662.0,"size":0.01},{"price":11169593.0,"size":0.001},{"price":11169243.0,"size":0.01},{"price":11166865.0,"size":0.001},{"price":11164029.0,"size":0.001},{"price":11160854.0,"size":0.1},{"price":11160000.0,"size":0.02376},{"price":11156269.0,"size":0.01},{"price":11155531.0,"size":0.001},{"price":11155377.0,"size":0.00636009},{"price":11153999.0,"size":0.00101},{"price":11151000.0,"size":0.001},{"price":11150250.0,"size":0.00175},{"price":11150005.0,"size":0.001},{"price":11150001.0,"size":0.00104},{"price":11150000.0,"size":0.6398956},{"price":11148000.0,"size":0.08963},{"price":11144197.0,"size":0.001},{"price":11144000.0,"size":0.0897},{"price":11140000.0,"size":0.2},{"price":11136243.0,"size":0.01},{"price":11136155.0,"size":0.02},{"price":11135869.0,"size":0.1},{"price":11130000.0,"size":0.116},{"price":11129979.0,"size":0.0053908},{"price":11126388.0,"size":0.02},{"price":11124900.0,"size":0.00133},{"price":11121090.0,"size":0.1},{"price":11120000.0,"size":0.0033},{"price":11118078.0,"size":0.01},{"price":11111800.0,"size":0.001},{"price":11111111.0,"size":0.2919257},{"price":11111000.0,"size":0.003},{"price":11110594.0,"size":0.001},{"price":11110000.0,"size":0.056937},{"price":11109662.0,"size":0.01},{"price":11108008.0,"size":0.01},{"price":11106000.0,"size":0.2},{"price":11105000.0,"size":0.02},{"price":11101297.0,"size":0.001},{"price":11100005.0,"size":0.001},{"price":11100001.0,"size":0.01104},{"price":11100000.0,"size":1.7472049},{"price":11099141.0,"size":0.01},{"price":11096243.0,"size":0.01},{"price":11094090.0,"size":0.01},{"price":11088888.0,"size":0.001},{"price":11085245.0,"size":0.001},{"price":11080200.0,"size":0.001},{"price":11080000.0,"size":0.0223},{"price":11075100.0,"size":0.003},{"price":11071558.0,"size":1.0},{"price":11070200.0,"size":0.001},{"price":11070000.0,"size":0.0902},{"price":11065200.0,"size":0.001},{"price":11064370.0,"size":0.00497091},{"price":11060200.0,"size":0.001},{"price":11060000.0,"size":0.145},{"price":11059689.0,"size":0.009},{"price":11056428.0,"size":0.002},{"price":11055500.0,"size":0.02},{"price":11055200.0,"size":0.001},{"price":11055100.0,"size":0.003},{"price":11050200.0,"size":0.001},{"price":11050005.0,"size":0.001},{"price":11050002.0,"size":0.001},{"price":11050001.0,"size":0.00104},{"price":11050000.0,"size":0.43176147},{"price":11046420.0,"size":0.2},{"price":11044243.0,"size":0.01},{"price":11041380.0,"size":0.01},{"price":11040200.0,"size":0.001},{"price":11040000.0,"size":0.00777181},{"price":11035865.0,"size":0.1},{"price":11035200.0,"size":0.001},{"price":11035000.0,"size":0.0013},{"price":11030200.0,"size":0.001},{"price":11030000.0,"size":0.025},{"price":11025500.0,"size":0.009531},{"price":11025200.0,"size":0.001},{"price":11025000.0,"size":0.71497},{"price":11020772.0,"size":0.014},{"price":11020200.0,"size":0.002},{"price":11020000.0,"size":0.005},{"price":11015200.0,"size":0.001},{"price":11012000.0,"size":0.1},{"price":11011800.0,"size":0.001},{"price":11010200.0,"size":0.001},{"price":11010000.0,"size":0.347},{"price":11007277.0,"size":0.01},{"price":11006000.0,"size":0.2},{"price":11005200.0,"size":0.001},{"price":11004890.0,"size":0.001535},{"price":11003000.0,"size":0.0155},{"price":11001000.0,"size":0.013},{"price":11000500.0,"size":0.05117658},{"price":11000200.0,"size":0.001},{"price":11000002.0,"size":0.004},{"price":11000001.0,"size":0.02604},{"price":11000000.0,"size":4.55923365},{"price":10999999.0,"size":0.003},{"price":10999000.0,"size":0.001},{"price":10996855.0,"size":0.0011},{"price":10995200.0,"size":0.001},{"price":10994499.0,"size":0.00169176},{"price":10990200.0,"size":0.001},{"price":10990000.0,"size":0.10219},{"price":10989001.0,"size":0.00197},{"price":10988999.0,"size":0.001},{"price":10988324.0,"size":0.002},{"price":10987654.0,"size":0.001},{"price":10985200.0,"size":0.001},{"price":10985150.0,"size":0.01},{"price":10980500.0,"size":0.005},{"price":10980200.0,"size":0.001},{"price":10980002.0,"size":0.4},{"price":10980000.0,"size":0.028},{"price":10975200.0,"size":0.001},{"price":10975000.0,"size":0.1},{"price":10971261.0,"size":0.001},{"price":10971243.0,"size":0.01},{"price":10970375.0,"size":1.9},{"price":10970200.0,"size":0.001},{"price":10970000.0,"size":0.09304},{"price":10966600.0,"size":0.001003},{"price":10965200.0,"size":0.001},{"price":10960200.0,"size":0.001},{"price":10960000.0,"size":0.0083},{"price":10956673.0,"size":0.01},{"price":10955200.0,"size":0.001},{"price":10954950.0,"size":0.001},{"price":10950500.0,"size":0.005},{"price":10950001.0,"size":0.00204},{"price":10950000.0,"size":0.5485028},{"price":10949550.0,"size":0.01870657},{"price":10949172.0,"size":0.1},{"price":10948000.0,"size":0.1},{"price":10945243.0,"size":0.01},{"price":10940402.0,"size":0.001},{"price":10940200.0,"size":0.001},{"price":10940000.0,"size":0.331},{"price":10938243.0,"size":0.01},{"price":10936200.0,"size":0.00137},{"price":10935200.0,"size":0.001},{"price":10930200.0,"size":0.002},{"price":10930000.0,"size":0.0193},{"price":10925200.0,"size":0.002},{"price":10924451.0,"size":0.0012},{"price":10920509.0,"size":0.01},{"price":10920200.0,"size":0.002},{"price":10920000.0,"size":0.52},{"price":10915200.0,"size":0.001},{"price":10914000.0,"size":0.005},{"price":10911800.0,"size":0.001},{"price":10910500.0,"size":0.005},{"price":10910200.0,"size":0.003},{"price":10910000.0,"size":0.005},{"price":10908243.0,"size":0.01},{"price":10906308.0,"size":0.013},{"price":10905200.0,"size":0.001},{"price":10903000.0,"size":0.027},{"price":10900200.0,"size":0.002},{"price":10900001.0,"size":0.00204}],"asks":[{"price":11315703.0,"size":0.03515295},{"price":11315704.0,"size":0.1268},{"price":11315810.0,"size":0.1255},{"price":11316023.0,"size":0.00997228},{"price":11316564.0,"size":0.02},{"price":11316565.0,"size":0.005},{"price":11317634.0,"size":0.017668},{"price":11317669.0,"size":0.2986},{"price":11317823.0,"size":0.02},{"price":11318668.0,"size":0.02},{"price":11318876.0,"size":0.02},{"price":11319518.0,"size":0.02},{"price":11319579.0,"size":0.02},{"price":11320000.0,"size":0.02},{"price":11320163.0,"size":0.015348},{"price":11320431.0,"size":0.2586},{"price":11320458.0,"size":0.014844},{"price":11321760.0,"size":0.052056},{"price":11322000.0,"size":0.005},{"price":11322245.0,"size":0.01},{"price":11323193.0,"size":0.2604},{"price":11323252.0,"size":0.57571998},{"price":11323572.0,"size":0.015},{"price":11324837.0,"size":0.01},{"price":11325955.0,"size":0.2592},{"price":11325976.0,"size":0.0529},{"price":11326901.0,"size":0.4199},{"price":11327978.0,"size":0.0095204},{"price":11328050.0,"size":0.002},{"price":11329436.0,"size":0.0015},{"price":11331059.0,"size":0.001},{"price":11331584.0,"size":1.189881},{"price":11331586.0,"size":1.189881},{"price":11332138.0,"size":0.0096922},{"price":11340000.0,"size":0.13586406},{"price":11340197.0,"size":1.489},{"price":11340647.0,"size":0.001},{"price":11342956.0,"size":1.60199848},{"price":11342957.0,"size":0.01},{"price":11346154.0,"size":0.0015},{"price":11348000.0,"size":0.1999},{"price":11349700.0,"size":0.001},{"price":11350000.0,"size":0.022},{"price":11350514.0,"size":1.928},{"price":11353807.0,"size":0.001},{"price":11353877.0,"size":0.001},{"price":11354939.0,"size":0.01},{"price":11355555.0,"size":0.001},{"price":11359242.0,"size":0.0011},{"price":11359700.0,"size":0.001},{"price":11362692.0,"size":0.0015},{"price":11365210.0,"size":0.61109747},{"price":11365211.0,"size":0.31285479},{"price":11368857.0,"size":0.47834347},{"price":11369700.0,"size":0.001},{"price":11370000.0,"size":0.1},{"price":11376000.0,"size":0.02},{"price":11376545.0,"size":0.001},{"price":11377000.0,"size":0.2287},{"price":11377269.0,"size":0.002},{"price":11379471.0,"size":2.018},{"price":11379700.0,"size":0.001},{"price":11379865.0,"size":0.03},{"price":11380000.0,"size":0.0223},{"price":11380324.0,"size":0.002},{"price":11381766.0,"size":0.4},{"price":11382386.0,"size":0.0015},{"price":11385000.0,"size":0.2548},{"price":11385403.0,"size":0.002},{"price":11385664.0,"size":0.002},{"price":11386197.0,"size":0.002},{"price":11387072.0,"size":0.01},{"price":11387354.0,"size":0.002},{"price":11387879.0,"size":0.001},{"price":11388885.0,"size":0.03},{"price":11389700.0,"size":0.001},{"price":11390000.0,"size":0.2488},{"price":11390050.0,"size":0.001},{"price":11392387.0,"size":1.0},{"price":11394939.0,"size":0.01},{"price":11395000.0,"size":0.06},{"price":11395775.0,"size":0.01},{"price":11396555.0,"size":0.03},{"price":11398444.0,"size":0.001995},{"price":11398783.0,"size":1.943},{"price":11399213.0,"size":0.001},{"price":11399673.0,"size":0.0015},{"price":11399700.0,"size":0.001},{"price":11400000.0,"size":0.5225},{"price":11405000.0,"size":0.0275},{"price":11406336.0,"size":1.0},{"price":11408700.0,"size":0.001},{"price":11409415.0,"size":0.055},{"price":11410000.0,"size":0.03},{"price":11410547.0,"size":0.001},{"price":11412000.0,"size":0.0878},{"price":11415000.0,"size":0.002},{"price":11415141.0,"size":0.0041},{"price":11417481.0,"size":0.0015},{"price":11418700.0,"size":0.001},{"price":11420000.0,"size":0.401},{"price":11421268.0,"size":0.05},{"price":11421881.0,"size":0.001},{"price":11423339.0,"size":2.0},{"price":11424296.0,"size":0.002},{"price":11424941.0,"size":0.972},{"price":11425000.0,"size":0.049},{"price":11426426.0,"size":0.002},{"price":11428700.0,"size":0.001},{"price":11429302.0,"size":0.01},{"price":11433211.0,"size":0.03},{"price":11433215.0,"size":0.001},{"price":11433333.0,"size":0.001},{"price":11438525.0,"size":0.0011},{"price":11438700.0,"size":0.001},{"price":11439557.0,"size":0.001},{"price":11440000.0,"size":0.1038},{"price":11443629.0,"size":0.002},{"price":11444549.0,"size":0.001},{"price":11447000.0,"size":0.01},{"price":11447071.0,"size":0.002},{"price":11448000.0,"size":0.0875},{"price":11448700.0,"size":0.001},{"price":11450000.0,"size":0.258},{"price":11453321.0,"size":0.03},{"price":11455883.0,"size":0.001},{"price":11458700.0,"size":0.001},{"price":11458988.0,"size":0.01},{"price":11460000.0,"size":0.01702},{"price":11467217.0,"size":0.001},{"price":11468700.0,"size":0.001},{"price":11470000.0,"size":0.01},{"price":11471000.0,"size":0.01},{"price":11475000.0,"size":0.0028},{"price":11478431.0,"size":0.002},{"price":11478551.0,"size":0.001},{"price":11478700.0,"size":0.001},{"price":11480000.0,"size":0.12491},{"price":11485000.0,"size":0.01},{"price":11486555.0,"size":0.03},{"price":11487685.0,"size":0.01},{"price":11488000.0,"size":0.102},{"price":11488700.0,"size":0.001},{"price":11489885.0,"size":0.001},{"price":11495850.0,"size":0.001},{"price":11498700.0,"size":0.001},{"price":11498917.0,"size":0.002},{"price":11499000.0,"size":0.01},{"price":11500000.0,"size":0.69859519},{"price":11501219.0,"size":0.001},{"price":11502377.0,"size":0.002},{"price":11502800.0,"size":0.00132},{"price":11503108.0,"size":0.0198},{"price":11505000.0,"size":0.0028},{"price":11505001.0,"size":0.002},{"price":11505836.0,"size":0.003},{"price":11508431.0,"size":0.047},{"price":11508700.0,"size":0.001},{"price":11508888.0,"size":0.02},{"price":11510000.0,"size":0.0976},{"price":11512553.0,"size":0.001},{"price":11513633.0,"size":0.08},{"price":11514332.0,"size":0.02},{"price":11518700.0,"size":0.001},{"price":11519855.0,"size":0.01},{"price":11520000.0,"size":0.001},{"price":11522423.0,"size":0.97},{"price":11523211.0,"size":0.01},{"price":11523887.0,"size":0.001},{"price":11524999.0,"size":0.001},{"price":11528700.0,"size":0.001},{"price":11529852.0,"size":0.01},{"price":11530000.0,"size":0.261},{"price":11533985.0,"size":0.002},{"price":11534084.0,"size":0.001},{"price":11535321.0,"size":0.01},{"price":11538666.0,"size":0.002},{"price":11538700.0,"size":0.001},{"price":11540000.0,"size":0.0048},{"price":11541011.0,"size":0.005},{"price":11541109.0,"size":0.01},{"price":11544663.0,"size":0.002},{"price":11546541.0,"size":0.01},{"price":11548144.0,"size":0.002},{"price":11548700.0,"size":0.001},{"price":11550000.0,"size":0.014},{"price":11551109.0,"size":0.01},{"price":11551625.0,"size":0.002},{"price":11552111.0,"size":0.01},{"price":11553687.0,"size":0.1},{"price":11555106.0,"size":0.002},{"price":11555115.0,"size":0.001},{"price":11556000.0,"size":0.1},{"price":11558587.0,"size":0.002},{"price":11558700.0,"size":0.001},{"price":11559855.0,"size":0.01},{"price":11560831.0,"size":0.0198},{"price":11561109.0,"size":0.01},{"price":11562000.0,"size":0.087},{"price":11562068.0,"size":0.002},{"price":11565548.0,"size":0.002},{"price":11566139.0,"size":0.0228},{"price":11566551.0,"size":0.01},{"price":11568700.0,"size":0.001},{"price":11569029.0,"size":0.002},{"price":11571109.0,"size":0.01},{"price":11572510.0,"size":0.002},{"price":11573211.0,"size":0.01},{"price":11575991.0,"size":0.001},{"price":11578700.0,"size":0.001},{"price":11579851.0,"size":0.01},{"price":11580000.0,"size":0.7735},{"price":11581109.0,"size":0.01},{"price":11585000.0,"size":0.002},{"price":11586532.0,"size":0.01},{"price":11587498.0,"size":0.0198},{"price":11588700.0,"size":0.001},{"price":11589612.0,"size":0.012},{"price":11590000.0,"size":0.1},{"price":11590749.0,"size":0.002},{"price":11591109.0,"size":0.01},{"price":11593211.0,"size":0.01},{"price":11598555.0,"size":0.01},{"price":11598700.0,"size":0.001},{"price":11599999.0,"size":0.001},{"price":11600000.0,"size":3.6141},{"price":11601109.0,"size":0.02},{"price":11606655.0,"size":0.01},{"price":11610000.0,"size":0.302},{"price":11611109.0,"size":0.01},{"price":11613321.0,"size":0.01},{"price":11620000.0,"size":1.35441682},{"price":11621011.0,"size":0.01},{"price":11621109.0,"size":0.01},{"price":11623096.0,"size":0.008},{"price":11629000.0,"size":0.1},{"price":11630000.0,"size":0.201},{"price":11631059.0,"size":0.01},{"price":11631479.0,"size":0.01},{"price":11631773.0,"size":0.00386871},{"price":11635950.0,"size":0.001},{"price":11638259.0,"size":0.001},{"price":11639700.0,"size":0.001},{"price":11640000.0,"size":1.0},{"price":11640820.0,"size":0.01},{"price":11645040.0,"size":1.7},{"price":11645295.0,"size":0.05},{"price":11647158.0,"size":0.05},{"price":11649900.0,"size":0.02906},{"price":11649999.0,"size":0.001},{"price":11650000.0,"size":0.593},{"price":11651059.0,"size":0.01},{"price":11653658.0,"size":0.008},{"price":11654321.0,"size":0.001},{"price":11659700.0,"size":0.001},{"price":11661479.0,"size":0.01},{"price":11666000.0,"size":0.001},{"price":11666666.0,"size":0.013},{"price":11669700.0,"size":0.001},{"price":11671059.0,"size":0.01},{"price":11672562.0,"size":0.0198},{"price":11679224.0,"size":0.012},{"price":11680000.0,"size":0.004},{"price":11685000.0,"size":0.003},{"price":11688000.0,"size":0.001},{"price":11689732.0,"size":0.01},{"price":11690330.0,"size":0.0198},{"price":11691059.0,"size":0.01},{"price":11692558.0,"size":0.01},{"price":11698800.0,"size":0.00131},{"price":11699000.0,"size":0.001},{"price":11699631.0,"size":0.001},{"price":11699998.0,"size":0.01},{"price":11699999.0,"size":0.001},{"price":11700000.0,"size":1.03762841},{"price":11701059.0,"size":0.01},{"price":11720000.0,"size":0.1},{"price":11721059.0,"size":0.01},{"price":11725000.0,"size":0.005},{"price":11726791.0,"size":0.01},{"price":11730000.0,"size":0.9382},{"price":11740000.0,"size":0.101},{"price":11741059.0,"size":0.01},{"price":11748937.0,"size":0.001},{"price":11749999.0,"size":0.001},{"price":11750000.0,"size":0.90537866},{"price":11750050.0,"size":0.2},{"price":11751151.0,"size":0.01},{"price":11755000.0,"size":0.001},{"price":11757860.0,"size":1.82},{"price":11759999.0,"size":0.001},{"price":11760000.0,"size":0.001},{"price":11761059.0,"size":0.02},{"price":11765432.0,"size":0.001},{"price":11768000.0,"size":0.01},{"price":11768836.0,"size":0.012},{"price":11770000.0,"size":0.25464896},{"price":11771059.0,"size":0.01755555},{"price":11772000.0,"size":0.002},{"price":11775000.0,"size":0.11593}]}}}
{"schema_version":"collector.vnext.raw","schema_contract":null,"schema_contract_version":null,"payload_contract_version":null,"record_type":"market.orderbook.diff","record_id":"collector_main-market-orderbook-diff-000000000061","collector_id":"collector_main","collector_role":"production","host_name":"MAIN-PC","session_id":"collector_main-sess-20260314T203137Z-e804aa95","stream_session_id":"collector_main-stream-bitflyer-board_ws-20260314T203157Z-61ca9e02","exchange":"bitflyer","market":"spot","symbol":"BTC_JPY","instrument_id":"bitflyer.spot.BTC_JPY","channel":"board_ws","transport":"websocket","source_event_id":null,"source_sequence":null,"sequence_id":61,"exchange_ts":null,"collector_ts":"2026-03-14T20:31:58Z","ingest_ts":"2026-03-14T20:31:58Z","event_ts":"2026-03-14T20:31:58Z","quality_flags":[],"is_partial":false,"is_reconstructed":false,"confidence_score":1.0,"payload":{"provider":"bitflyer_ws_board","exchange":"bitflyer","transport":"websocket","channel":"lightning_board_BTC_JPY","received_ts":"2026-03-14T20:31:58.095205Z","subscription_id":null,"message_id":null,"source_sequence":null,"raw_message_meta":{"raw_channel":"lightning_board_BTC_JPY","subscription_channel":"lightning_board_BTC_JPY","recv_timeout_sec":10,"ssl_verify":false,"socket_url":"wss://ws.lightstream.bitflyer.com/json-rpc"},"source_payload":{"mid_price":11313431.0,"bids":[],"asks":[{"price":11332023.0,"size":0.0},{"price":11331936.0,"size":0.0092403}]}}}
{"schema_version":"collector.vnext.raw","schema_contract":null,"schema_contract_version":null,"payload_contract_version":null,"record_type":"market.orderbook.diff","record_id":"collector_main-market-orderbook-diff-000000000065","collector_id":"collector_main","collector_role":"production","host_name":"MAIN-PC","session_id":"collector_main-sess-20260314T203137Z-e804aa95","stream_session_id":"collector_main-stream-bitflyer-board_ws-20260314T203157Z-61ca9e02","exchange":"bitflyer","market":"spot","symbol":"BTC_JPY","instrument_id":"bitflyer.spot.BTC_JPY","channel":"board_ws","transport":"websocket","source_event_id":null,"source_sequence":null,"sequence_id":65,"exchange_ts":null,"collector_ts":"2026-03-14T20:31:58Z","ingest_ts":"2026-03-14T20:31:58Z","event_ts":"2026-03-14T20:31:58Z","quality_flags":[],"is_partial":false,"is_reconstructed":false,"confidence_score":1.0,"payload":{"provider":"bitflyer_ws_board","exchange":"bitflyer","transport":"websocket","channel":"lightning_board_BTC_JPY","received_ts":"2026-03-14T20:31:58.440295Z","subscription_id":null,"message_id":null,"source_sequence":null,"raw_message_meta":{"raw_channel":"lightning_board_BTC_JPY","subscription_channel":"lightning_board_BTC_JPY","recv_timeout_sec":10,"ssl_verify":false,"socket_url":"wss://ws.lightstream.bitflyer.com/json-rpc"},"source_payload":{"mid_price":11313431.0,"bids":[{"price":11256864.0,"size":0.002}],"asks":[]}}}
{"schema_version":"collector.vnext.raw","schema_contract":null,"schema_contract_version":null,"payload_contract_version":null,"record_type":"market.orderbook.diff","record_id":"collector_main-market-orderbook-diff-000000000067","collector_id":"collector_main","collector_role":"production","host_name":"MAIN-PC","session_id":"collector_main-sess-20260314T203137Z-e804aa95","stream_session_id":"collector_main-stream-bitflyer-board_ws-20260314T203157Z-61ca9e02","exchange":"bitflyer","market":"spot","symbol":"BTC_JPY","instrument_id":"bitflyer.spot.BTC_JPY","channel":"board_ws","transport":"websocket","source_event_id":null,"source_sequence":null,"sequence_id":67,"exchange_ts":null,"collector_ts":"2026-03-14T20:31:58Z","ingest_ts":"2026-03-14T20:31:58Z","event_ts":"2026-03-14T20:31:58Z","quality_flags":[],"is_partial":false,"is_reconstructed":false,"confidence_score":1.0,"payload":{"provider":"bitflyer_ws_board","exchange":"bitflyer","transport":"websocket","channel":"lightning_board_BTC_JPY","received_ts":"2026-03-14T20:31:58.641254Z","subscription_id":null,"message_id":null,"source_sequence":null,"raw_message_meta":{"raw_channel":"lightning_board_BTC_JPY","subscription_channel":"lightning_board_BTC_JPY","recv_timeout_sec":10,"ssl_verify":false,"socket_url":"wss://ws.lightstream.bitflyer.com/json-rpc"},"source_payload":{"mid_price":11313431.0,"bids":[],"asks":[{"price":11331936.0,"size":0.0},{"price":11332023.0,"size":0.0096916}]}}}
{"schema_version":"collector.vnext.raw","schema_contract":null,"schema_contract_version":null,"payload_contract_version":null,"record_type":"market.orderbook.diff","record_id":"collector_main-market-orderbook-diff-000000000069","collector_id":"collector_main","collector_role":"production","host_name":"MAIN-PC","session_id":"collector_main-sess-20260314T203137Z-e804aa95","stream_session_id":"collector_main-stream-bitflyer-board_ws-20260314T203157Z-61ca9e02","exchange":"bitflyer","market":"spot","symbol":"BTC_JPY","instrument_id":"bitflyer.spot.BTC_JPY","channel":"board_ws","transport":"websocket","source_event_id":null,"source_sequence":null,"sequence_id":69,"exchange_ts":null,"collector_ts":"2026-03-14T20:31:59Z","ingest_ts":"2026-03-14T20:31:59Z","event_ts":"2026-03-14T20:31:59Z","quality_flags":[],"is_partial":false,"is_reconstructed":false,"confidence_score":1.0,"payload":{"provider":"bitflyer_ws_board","exchange":"bitflyer","transport":"websocket","channel":"lightning_board_BTC_JPY","received_ts":"2026-03-14T20:31:59.184776Z","subscription_id":null,"message_id":null,"source_sequence":null,"raw_message_meta":{"raw_channel":"lightning_board_BTC_JPY","subscription_channel":"lightning_board_BTC_JPY","recv_timeout_sec":10,"ssl_verify":false,"socket_url":"wss://ws.lightstream.bitflyer.com/json-rpc"},"source_payload":{"mid_price":11313431.0,"bids":[],"asks":[{"price":11332023.0,"size":0.0},{"price":11331936.0,"size":0.0092404}]}}}
{"schema_version":"collector.vnext.raw","schema_contract":null,"schema_contract_version":null,"payload_contract_version":null,"record_type":"market.orderbook.diff","record_id":"collector_main-market-orderbook-diff-000000000071","collector_id":"collector_main","collector_role":"production","host_name":"MAIN-PC","session_id":"collector_main-sess-20260314T203137Z-e804aa95","stream_session_id":"collector_main-stream-bitflyer-board_ws-20260314T203157Z-61ca9e02","exchange":"bitflyer","market":"spot","symbol":"BTC_JPY","instrument_id":"bitflyer.spot.BTC_JPY","channel":"board_ws","transport":"websocket","source_event_id":null,"source_sequence":null,"sequence_id":71,"exchange_ts":null,"collector_ts":"2026-03-14T20:31:59Z","ingest_ts":"2026-03-14T20:31:59Z","event_ts":"2026-03-14T20:31:59Z","quality_flags":[],"is_partial":false,"is_reconstructed":false,"confidence_score":1.0,"payload":{"provider":"bitflyer_ws_board","exchange":"bitflyer","transport":"websocket","channel":"lightning_board_BTC_JPY","received_ts":"2026-03-14T20:31:59.408200Z","subscription_id":null,"message_id":null,"source_sequence":null,"raw_message_meta":{"raw_channel":"lightning_board_BTC_JPY","subscription_channel":"lightning_board_BTC_JPY","recv_timeout_sec":10,"ssl_verify":false,"socket_url":"wss://ws.lightstream.bitflyer.com/json-rpc"},"source_payload":{"mid_price":11313431.0,"bids":[],"asks":[{"price":11327977.0,"size":0.0}]}}}
{"schema_version":"collector.vnext.raw","schema_contract":null,"schema_contract_version":null,"payload_contract_version":null,"record_type":"market.orderbook.diff","record_id":"collector_main-market-orderbook-diff-000000000073","collector_id":"collector_main","collector_role":"production","host_name":"MAIN-PC","session_id":"collector_main-sess-20260314T203137Z-e804aa95","stream_session_id":"collector_main-stream-bitflyer-board_ws-20260314T203157Z-61ca9e02","exchange":"bitflyer","market":"spot","symbol":"BTC_JPY","instrument_id":"bitflyer.spot.BTC_JPY","channel":"board_ws","transport":"websocket","source_event_id":null,"source_sequence":null,"sequence_id":73,"exchange_ts":null,"collector_ts":"2026-03-14T20:31:59Z","ingest_ts":"2026-03-14T20:31:59Z","event_ts":"2026-03-14T20:31:59Z","quality_flags":[],"is_partial":false,"is_reconstructed":false,"confidence_score":1.0,"payload":{"provider":"bitflyer_ws_board","exchange":"bitflyer","transport":"websocket","channel":"lightning_board_BTC_JPY","received_ts":"2026-03-14T20:31:59.555588Z","subscription_id":null,"message_id":null,"source_sequence":null,"raw_message_meta":{"raw_channel":"lightning_board_BTC_JPY","subscription_channel":"lightning_board_BTC_JPY","recv_timeout_sec":10,"ssl_verify":false,"socket_url":"wss://ws.lightstream.bitflyer.com/json-rpc"},"source_payload":{"mid_price":11313431.0,"bids":[],"asks":[{"price":11327890.0,"size":0.0092404}]}}}
{"schema_version":"collector.vnext.raw","schema_contract":null,"schema_contract_version":null,"payload_contract_version":null,"record_type":"market.orderbook.diff","record_id":"collector_main-market-orderbook-diff-000000000075","collector_id":"collector_main","collector_role":"production","host_name":"MAIN-PC","session_id":"collector_main-sess-20260314T203137Z-e804aa95","stream_session_id":"collector_main-stream-bitflyer-board_ws-20260314T203157Z-61ca9e02","exchange":"bitflyer","market":"spot","symbol":"BTC_JPY","instrument_id":"bitflyer.spot.BTC_JPY","channel":"board_ws","transport":"websocket","source_event_id":null,"source_sequence":null,"sequence_id":75,"exchange_ts":null,"collector_ts":"2026-03-14T20:31:59Z","ingest_ts":"2026-03-14T20:31:59Z","event_ts":"2026-03-14T20:31:59Z","quality_flags":[],"is_partial":false,"is_reconstructed":false,"confidence_score":1.0,"payload":{"provider":"bitflyer_ws_board","exchange":"bitflyer","transport":"websocket","channel":"lightning_board_BTC_JPY","received_ts":"2026-03-14T20:31:59.669107Z","subscription_id":null,"message_id":null,"source_sequence":null,"raw_message_meta":{"raw_channel":"lightning_board_BTC_JPY","subscription_channel":"lightning_board_BTC_JPY","recv_timeout_sec":10,"ssl_verify":false,"socket_url":"wss://ws.lightstream.bitflyer.com/json-rpc"},"source_payload":{"mid_price":11313431.0,"bids":[{"price":11252338.0,"size":0.002}],"asks":[]}}}
{"schema_version":"collector.vnext.raw","schema_contract":null,"schema_contract_version":null,"payload_contract_version":null,"record_type":"market.orderbook.diff","record_id":"collector_main-market-orderbook-diff-000000000077","collector_id":"collector_main","collector_role":"production","host_name":"MAIN-PC","session_id":"collector_main-sess-20260314T203137Z-e804aa95","stream_session_id":"collector_main-stream-bitflyer-board_ws-20260314T203157Z-61ca9e02","exchange":"bitflyer","market":"spot","symbol":"BTC_JPY","instrument_id":"bitflyer.spot.BTC_JPY","channel":"board_ws","transport":"websocket","source_event_id":null,"source_sequence":null,"sequence_id":77,"exchange_ts":null,"collector_ts":"2026-03-14T20:31:59Z","ingest_ts":"2026-03-14T20:31:59Z","event_ts":"2026-03-14T20:31:59Z","quality_flags":[],"is_partial":false,"is_reconstructed":false,"confidence_score":1.0,"payload":{"provider":"bitflyer_ws_board","exchange":"bitflyer","transport":"websocket","channel":"lightning_board_BTC_JPY","received_ts":"2026-03-14T20:31:59.891061Z","subscription_id":null,"message_id":null,"source_sequence":null,"raw_message_meta":{"raw_channel":"lightning_board_BTC_JPY","subscription_channel":"lightning_board_BTC_JPY","recv_timeout_sec":10,"ssl_verify":false,"socket_url":"wss://ws.lightstream.bitflyer.com/json-rpc"},"source_payload":{"mid_price":11313431.0,"bids":[{"price":11310242.0,"size":0.0}],"asks":[{"price":11327890.0,"size":0.0}]}}}
{"schema_version":"collector.vnext.raw","schema_contract":null,"schema_contract_version":null,"payload_contract_version":null,"record_type":"market.orderbook.diff","record_id":"collector_main-market-orderbook-diff-000000000079","collector_id":"collector_main","collector_role":"production","host_name":"MAIN-PC","session_id":"collector_main-sess-20260314T203137Z-e804aa95","stream_session_id":"collector_main-stream-bitflyer-board_ws-20260314T203157Z-61ca9e02","exchange":"bitflyer","market":"spot","symbol":"BTC_JPY","instrument_id":"bitflyer.spot.BTC_JPY","channel":"board_ws","transport":"websocket","source_event_id":null,"source_sequence":null,"sequence_id":79,"exchange_ts":null,"collector_ts":"2026-03-14T20:32:00Z","ingest_ts":"2026-03-14T20:32:00Z","event_ts":"2026-03-14T20:32:00Z","quality_flags":[],"is_partial":false,"is_reconstructed":false,"confidence_score":1.0,"payload":{"provider":"bitflyer_ws_board","exchange":"bitflyer","transport":"websocket","channel":"lightning_board_BTC_JPY","received_ts":"2026-03-14T20:32:00.001015Z","subscription_id":null,"message_id":null,"source_sequence":null,"raw_message_meta":{"raw_channel":"lightning_board_BTC_JPY","subscription_channel":"lightning_board_BTC_JPY","recv_timeout_sec":10,"ssl_verify":false,"socket_url":"wss://ws.lightstream.bitflyer.com/json-rpc"},"source_payload":{"mid_price":11313431.0,"bids":[{"price":11309598.0,"size":0.005}],"asks":[]}}}
{"schema_version":"collector.vnext.raw","schema_contract":null,"schema_contract_version":null,"payload_contract_version":null,"record_type":"market.orderbook.diff","record_id":"collector_main-market-orderbook-diff-000000000081","collector_id":"collector_main","collector_role":"production","host_name":"MAIN-PC","session_id":"collector_main-sess-20260314T203137Z-e804aa95","stream_session_id":"collector_main-stream-bitflyer-board_ws-20260314T203157Z-61ca9e02","exchange":"bitflyer","market":"spot","symbol":"BTC_JPY","instrument_id":"bitflyer.spot.BTC_JPY","channel":"board_ws","transport":"websocket","source_event_id":null,"source_sequence":null,"sequence_id":81,"exchange_ts":null,"collector_ts":"2026-03-14T20:32:00Z","ingest_ts":"2026-03-14T20:32:00Z","event_ts":"2026-03-14T20:32:00Z","quality_flags":[],"is_partial":false,"is_reconstructed":false,"confidence_score":1.0,"payload":{"provider":"bitflyer_ws_board","exchange":"bitflyer","transport":"websocket","channel":"lightning_board_BTC_JPY","received_ts":"2026-03-14T20:32:00.109792Z","subscription_id":null,"message_id":null,"source_sequence":null,"raw_message_meta":{"raw_channel":"lightning_board_BTC_JPY","subscription_channel":"lightning_board_BTC_JPY","recv_timeout_sec":10,"ssl_verify":false,"socket_url":"wss://ws.lightstream.bitflyer.com/json-rpc"},"source_payload":{"mid_price":11313431.0,"bids":[{"price":11304302.0,"size":0.0},{"price":11310243.0,"size":0.0}],"asks":[{"price":11327889.0,"size":0.2},{"price":11331936.0,"size":0.0}]}}}
{"schema_version":"collector.vnext.raw","schema_contract":null,"schema_contract_version":null,"payload_contract_version":null,"record_type":"market.orderbook.diff","record_id":"collector_main-market-orderbook-diff-000000000083","collector_id":"collector_main","collector_role":"production","host_name":"MAIN-PC","session_id":"collector_main-sess-20260314T203137Z-e804aa95","stream_session_id":"collector_main-stream-bitflyer-board_ws-20260314T203157Z-61ca9e02","exchange":"bitflyer","market":"spot","symbol":"BTC_JPY","instrument_id":"bitflyer.spot.BTC_JPY","channel":"board_ws","transport":"websocket","source_event_id":null,"source_sequence":null,"sequence_id":83,"exchange_ts":null,"collector_ts":"2026-03-14T20:32:00Z","ingest_ts":"2026-03-14T20:32:00Z","event_ts":"2026-03-14T20:32:00Z","quality_flags":[],"is_partial":false,"is_reconstructed":false,"confidence_score":1.0,"payload":{"provider":"bitflyer_ws_board","exchange":"bitflyer","transport":"websocket","channel":"lightning_board_BTC_JPY","received_ts":"2026-03-14T20:32:00.212659Z","subscription_id":null,"message_id":null,"source_sequence":null,"raw_message_meta":{"raw_channel":"lightning_board_BTC_JPY","subscription_channel":"lightning_board_BTC_JPY","recv_timeout_sec":10,"ssl_verify":false,"socket_url":"wss://ws.lightstream.bitflyer.com/json-rpc"},"source_payload":{"mid_price":11313431.0,"bids":[{"price":11309737.0,"size":0.04594475},{"price":11303658.0,"size":0.0028253}],"asks":[{"price":11331821.0,"size":0.0091216}]}}}
{"schema_version":"collector.vnext.raw","schema_contract":null,"schema_contract_version":null,"payload_contract_version":null,"record_type":"market.orderbook.diff","record_id":"collector_main-market-orderbook-diff-000000000085","collector_id":"collector_main","collector_role":"production","host_name":"MAIN-PC","session_id":"collector_main-sess-20260314T203137Z-e804aa95","stream_session_id":"collector_main-stream-bitflyer-board_ws-20260314T203157Z-61ca9e02","exchange":"bitflyer","market":"spot","symbol":"BTC_JPY","instrument_id":"bitflyer.spot.BTC_JPY","channel":"board_ws","transport":"websocket","source_event_id":null,"source_sequence":null,"sequence_id":85,"exchange_ts":null,"collector_ts":"2026-03-14T20:32:00Z","ingest_ts":"2026-03-14T20:32:00Z","event_ts":"2026-03-14T20:32:00Z","quality_flags":[],"is_partial":false,"is_reconstructed":false,"confidence_score":1.0,"payload":{"provider":"bitflyer_ws_board","exchange":"bitflyer","transport":"websocket","channel":"lightning_board_BTC_JPY","received_ts":"2026-03-14T20:32:00.314902Z","subscription_id":null,"message_id":null,"source_sequence":null,"raw_message_meta":{"raw_channel":"lightning_board_BTC_JPY","subscription_channel":"lightning_board_BTC_JPY","recv_timeout_sec":10,"ssl_verify":false,"socket_url":"wss://ws.lightstream.bitflyer.com/json-rpc"},"source_payload":{"mid_price":11313431.0,"bids":[],"asks":[{"price":11316564.0,"size":0.0}]}}}
{"schema_version":"collector.vnext.raw","schema_contract":null,"schema_contract_version":null,"payload_contract_version":null,"record_type":"market.orderbook.diff","record_id":"collector_main-market-orderbook-diff-000000000087","collector_id":"collector_main","collector_role":"production","host_name":"MAIN-PC","session_id":"collector_main-sess-20260314T203137Z-e804aa95","stream_session_id":"collector_main-stream-bitflyer-board_ws-20260314T203157Z-61ca9e02","exchange":"bitflyer","market":"spot","symbol":"BTC_JPY","instrument_id":"bitflyer.spot.BTC_JPY","channel":"board_ws","transport":"websocket","source_event_id":null,"source_sequence":null,"sequence_id":87,"exchange_ts":null,"collector_ts":"2026-03-14T20:32:00Z","ingest_ts":"2026-03-14T20:32:00Z","event_ts":"2026-03-14T20:32:00Z","quality_flags":[],"is_partial":false,"is_reconstructed":false,"confidence_score":1.0,"payload":{"provider":"bitflyer_ws_board","exchange":"bitflyer","transport":"websocket","channel":"lightning_board_BTC_JPY","received_ts":"2026-03-14T20:32:00.435062Z","subscription_id":null,"message_id":null,"source_sequence":null,"raw_message_meta":{"raw_channel":"lightning_board_BTC_JPY","subscription_channel":"lightning_board_BTC_JPY","recv_timeout_sec":10,"ssl_verify":false,"socket_url":"wss://ws.lightstream.bitflyer.com/json-rpc"},"source_payload":{"mid_price":11313431.0,"bids":[],"asks":[{"price":11327889.0,"size":0.0},{"price":11327775.0,"size":0.0112005}]}}}
{"schema_version":"collector.vnext.raw","schema_contract":null,"schema_contract_version":null,"payload_contract_version":null,"record_type":"market.orderbook.diff","record_id":"collector_main-market-orderbook-diff-000000000089","collector_id":"collector_main","collector_role":"production","host_name":"MAIN-PC","session_id":"collector_main-sess-20260314T203137Z-e804aa95","stream_session_id":"collector_main-stream-bitflyer-board_ws-20260314T203157Z-61ca9e02","exchange":"bitflyer","market":"spot","symbol":"BTC_JPY","instrument_id":"bitflyer.spot.BTC_JPY","channel":"board_ws","transport":"websocket","source_event_id":null,"source_sequence":null,"sequence_id":89,"exchange_ts":null,"collector_ts":"2026-03-14T20:32:00Z","ingest_ts":"2026-03-14T20:32:00Z","event_ts":"2026-03-14T20:32:00Z","quality_flags":[],"is_partial":false,"is_reconstructed":false,"confidence_score":1.0,"payload":{"provider":"bitflyer_ws_board","exchange":"bitflyer","transport":"websocket","channel":"lightning_board_BTC_JPY","received_ts":"2026-03-14T20:32:00.563426Z","subscription_id":null,"message_id":null,"source_sequence":null,"raw_message_meta":{"raw_channel":"lightning_board_BTC_JPY","subscription_channel":"lightning_board_BTC_JPY","recv_timeout_sec":10,"ssl_verify":false,"socket_url":"wss://ws.lightstream.bitflyer.com/json-rpc"},"source_payload":{"mid_price":11313431.0,"bids":[],"asks":[{"price":11331821.0,"size":0.0},{"price":11331935.0,"size":0.0094069}]}}}
{"schema_version":"collector.vnext.raw","schema_contract":null,"schema_contract_version":null,"payload_contract_version":null,"record_type":"market.orderbook.diff","record_id":"collector_main-market-orderbook-diff-000000000091","collector_id":"collector_main","collector_role":"production","host_name":"MAIN-PC","session_id":"collector_main-sess-20260314T203137Z-e804aa95","stream_session_id":"collector_main-stream-bitflyer-board_ws-20260314T203157Z-61ca9e02","exchange":"bitflyer","market":"spot","symbol":"BTC_JPY","instrument_id":"bitflyer.spot.BTC_JPY","channel":"board_ws","transport":"websocket","source_event_id":null,"source_sequence":null,"sequence_id":91,"exchange_ts":null,"collector_ts":"2026-03-14T20:32:00Z","ingest_ts":"2026-03-14T20:32:00Z","event_ts":"2026-03-14T20:32:00Z","quality_flags":[],"is_partial":false,"is_reconstructed":false,"confidence_score":1.0,"payload":{"provider":"bitflyer_ws_board","exchange":"bitflyer","transport":"websocket","channel":"lightning_board_BTC_JPY","received_ts":"2026-03-14T20:32:00.953930Z","subscription_id":null,"message_id":null,"source_sequence":null,"raw_message_meta":{"raw_channel":"lightning_board_BTC_JPY","subscription_channel":"lightning_board_BTC_JPY","recv_timeout_sec":10,"ssl_verify":false,"socket_url":"wss://ws.lightstream.bitflyer.com/json-rpc"},"source_payload":{"mid_price":11313431.0,"bids":[{"price":11247812.0,"size":0.002}],"asks":[{"price":11327775.0,"size":0.0}]}}}
{"schema_version":"collector.vnext.raw","schema_contract":null,"schema_contract_version":null,"payload_contract_version":null,"record_type":"market.orderbook.diff","record_id":"collector_main-market-orderbook-diff-000000000093","collector_id":"collector_main","collector_role":"production","host_name":"MAIN-PC","session_id":"collector_main-sess-20260314T203137Z-e804aa95","stream_session_id":"collector_main-stream-bitflyer-board_ws-20260314T203157Z-61ca9e02","exchange":"bitflyer","market":"spot","symbol":"BTC_JPY","instrument_id":"bitflyer.spot.BTC_JPY","channel":"board_ws","transport":"websocket","source_event_id":null,"source_sequence":null,"sequence_id":93,"exchange_ts":null,"collector_ts":"2026-03-14T20:32:01Z","ingest_ts":"2026-03-14T20:32:01Z","event_ts":"2026-03-14T20:32:01Z","quality_flags":[],"is_partial":false,"is_reconstructed":false,"confidence_score":1.0,"payload":{"provider":"bitflyer_ws_board","exchange":"bitflyer","transport":"websocket","channel":"lightning_board_BTC_JPY","received_ts":"2026-03-14T20:32:01.048646Z","subscription_id":null,"message_id":null,"source_sequence":null,"raw_message_meta":{"raw_channel":"lightning_board_BTC_JPY","subscription_channel":"lightning_board_BTC_JPY","recv_timeout_sec":10,"ssl_verify":false,"socket_url":"wss://ws.lightstream.bitflyer.com/json-rpc"},"source_payload":{"mid_price":11313431.0,"bids":[],"asks":[{"price":11327889.0,"size":0.2}]}}}
{"schema_version":"collector.vnext.raw","schema_contract":null,"schema_contract_version":null,"payload_contract_version":null,"record_type":"market.orderbook.diff","record_id":"collector_main-market-orderbook-diff-000000000095","collector_id":"collector_main","collector_role":"production","host_name":"MAIN-PC","session_id":"collector_main-sess-20260314T203137Z-e804aa95","stream_session_id":"collector_main-stream-bitflyer-board_ws-20260314T203157Z-61ca9e02","exchange":"bitflyer","market":"spot","symbol":"BTC_JPY","instrument_id":"bitflyer.spot.BTC_JPY","channel":"board_ws","transport":"websocket","source_event_id":null,"source_sequence":null,"sequence_id":95,"exchange_ts":null,"collector_ts":"2026-03-14T20:32:01Z","ingest_ts":"2026-03-14T20:32:01Z","event_ts":"2026-03-14T20:32:01Z","quality_flags":[],"is_partial":false,"is_reconstructed":false,"confidence_score":1.0,"payload":{"provider":"bitflyer_ws_board","exchange":"bitflyer","transport":"websocket","channel":"lightning_board_BTC_JPY","received_ts":"2026-03-14T20:32:01.595415Z","subscription_id":null,"message_id":null,"source_sequence":null,"raw_message_meta":{"raw_channel":"lightning_board_BTC_JPY","subscription_channel":"lightning_board_BTC_JPY","recv_timeout_sec":10,"ssl_verify":false,"socket_url":"wss://ws.lightstream.bitflyer.com/json-rpc"},"source_payload":{"mid_price":11313431.0,"bids":[],"asks":[{"price":11331935.0,"size":0.0}]}}}
{"schema_version":"collector.vnext.raw","schema_contract":null,"schema_contract_version":null,"payload_contract_version":null,"record_type":"market.orderbook.diff","record_id":"collector_main-market-orderbook-diff-000000000097","collector_id":"collector_main","collector_role":"production","host_name":"MAIN-PC","session_id":"collector_main-sess-20260314T203137Z-e804aa95","stream_session_id":"collector_main-stream-bitflyer-board_ws-20260314T203157Z-61ca9e02","exchange":"bitflyer","market":"spot","symbol":"BTC_JPY","instrument_id":"bitflyer.spot.BTC_JPY","channel":"board_ws","transport":"websocket","source_event_id":null,"source_sequence":null,"sequence_id":97,"exchange_ts":null,"collector_ts":"2026-03-14T20:32:01Z","ingest_ts":"2026-03-14T20:32:01Z","event_ts":"2026-03-14T20:32:01Z","quality_flags":[],"is_partial":false,"is_reconstructed":false,"confidence_score":1.0,"payload":{"provider":"bitflyer_ws_board","exchange":"bitflyer","transport":"websocket","channel":"lightning_board_BTC_JPY","received_ts":"2026-03-14T20:32:01.726799Z","subscription_id":null,"message_id":null,"source_sequence":null,"raw_message_meta":{"raw_channel":"lightning_board_BTC_JPY","subscription_channel":"lightning_board_BTC_JPY","recv_timeout_sec":10,"ssl_verify":false,"socket_url":"wss://ws.lightstream.bitflyer.com/json-rpc"},"source_payload":{"mid_price":11313431.0,"bids":[],"asks":[{"price":11331821.0,"size":0.0091218}]}}}
{"schema_version":"collector.vnext.raw","schema_contract":null,"schema_contract_version":null,"payload_contract_version":null,"record_type":"market.orderbook.diff","record_id":"collector_main-market-orderbook-diff-000000000099","collector_id":"collector_main","collector_role":"production","host_name":"MAIN-PC","session_id":"collector_main-sess-20260314T203137Z-e804aa95","stream_session_id":"collector_main-stream-bitflyer-board_ws-20260314T203157Z-61ca9e02","exchange":"bitflyer","market":"spot","symbol":"BTC_JPY","instrument_id":"bitflyer.spot.BTC_JPY","channel":"board_ws","transport":"websocket","source_event_id":null,"source_sequence":null,"sequence_id":99,"exchange_ts":null,"collector_ts":"2026-03-14T20:32:01Z","ingest_ts":"2026-03-14T20:32:01Z","event_ts":"2026-03-14T20:32:01Z","quality_flags":[],"is_partial":false,"is_reconstructed":false,"confidence_score":1.0,"payload":{"provider":"bitflyer_ws_board","exchange":"bitflyer","transport":"websocket","channel":"lightning_board_BTC_JPY","received_ts":"2026-03-14T20:32:01.860043Z","subscription_id":null,"message_id":null,"source_sequence":null,"raw_message_meta":{"raw_channel":"lightning_board_BTC_JPY","subscription_channel":"lightning_board_BTC_JPY","recv_timeout_sec":10,"ssl_verify":false,"socket_url":"wss://ws.lightstream.bitflyer.com/json-rpc"},"source_payload":{"mid_price":11313431.0,"bids":[],"asks":[{"price":11327889.0,"size":0.0}]}}}
{"schema_version":"collector.vnext.raw","schema_contract":null,"schema_contract_version":null,"payload_contract_version":null,"record_type":"market.orderbook.diff","record_id":"collector_main-market-orderbook-diff-000000000101","collector_id":"collector_main","collector_role":"production","host_name":"MAIN-PC","session_id":"collector_main-sess-20260314T203137Z-e804aa95","stream_session_id":"collector_main-stream-bitflyer-board_ws-20260314T203157Z-61ca9e02","exchange":"bitflyer","market":"spot","symbol":"BTC_JPY","instrument_id":"bitflyer.spot.BTC_JPY","channel":"board_ws","transport":"websocket","source_event_id":null,"source_sequence":null,"sequence_id":101,"exchange_ts":null,"collector_ts":"2026-03-14T20:32:02Z","ingest_ts":"2026-03-14T20:32:02Z","event_ts":"2026-03-14T20:32:02Z","quality_flags":[],"is_partial":false,"is_reconstructed":false,"confidence_score":1.0,"payload":{"provider":"bitflyer_ws_board","exchange":"bitflyer","transport":"websocket","channel":"lightning_board_BTC_JPY","received_ts":"2026-03-14T20:32:02.026141Z","subscription_id":null,"message_id":null,"source_sequence":null,"raw_message_meta":{"raw_channel":"lightning_board_BTC_JPY","subscription_channel":"lightning_board_BTC_JPY","recv_timeout_sec":10,"ssl_verify":false,"socket_url":"wss://ws.lightstream.bitflyer.com/json-rpc"},"source_payload":{"mid_price":11313431.0,"bids":[],"asks":[{"price":11327775.0,"size":0.01},{"price":11331821.0,"size":0.0}]}}}
{"schema_version":"collector.vnext.raw","schema_contract":null,"schema_contract_version":null,"payload_contract_version":null,"record_type":"market.orderbook.diff","record_id":"collector_main-market-orderbook-diff-000000000103","collector_id":"collector_main","collector_role":"production","host_name":"MAIN-PC","session_id":"collector_main-sess-20260314T203137Z-e804aa95","stream_session_id":"collector_main-stream-bitflyer-board_ws-20260314T203157Z-61ca9e02","exchange":"bitflyer","market":"spot","symbol":"BTC_JPY","instrument_id":"bitflyer.spot.BTC_JPY","channel":"board_ws","transport":"websocket","source_event_id":null,"source_sequence":null,"sequence_id":103,"exchange_ts":null,"collector_ts":"2026-03-14T20:32:02Z","ingest_ts":"2026-03-14T20:32:02Z","event_ts":"2026-03-14T20:32:02Z","quality_flags":[],"is_partial":false,"is_reconstructed":false,"confidence_score":1.0,"payload":{"provider":"bitflyer_ws_board","exchange":"bitflyer","transport":"websocket","channel":"lightning_board_BTC_JPY","received_ts":"2026-03-14T20:32:02.129964Z","subscription_id":null,"message_id":null,"source_sequence":null,"raw_message_meta":{"raw_channel":"lightning_board_BTC_JPY","subscription_channel":"lightning_board_BTC_JPY","recv_timeout_sec":10,"ssl_verify":false,"socket_url":"wss://ws.lightstream.bitflyer.com/json-rpc"},"source_payload":{"mid_price":11313431.0,"bids":[],"asks":[{"price":11331935.0,"size":0.0094069}]}}}
{"schema_version":"collector.vnext.raw","schema_contract":null,"schema_contract_version":null,"payload_contract_version":null,"record_type":"market.orderbook.diff","record_id":"collector_main-market-orderbook-diff-000000000105","collector_id":"collector_main","collector_role":"production","host_name":"MAIN-PC","session_id":"collector_main-sess-20260314T203137Z-e804aa95","stream_session_id":"collector_main-stream-bitflyer-board_ws-20260314T203157Z-61ca9e02","exchange":"bitflyer","market":"spot","symbol":"BTC_JPY","instrument_id":"bitflyer.spot.BTC_JPY","channel":"board_ws","transport":"websocket","source_event_id":null,"source_sequence":null,"sequence_id":105,"exchange_ts":null,"collector_ts":"2026-03-14T20:32:02Z","ingest_ts":"2026-03-14T20:32:02Z","event_ts":"2026-03-14T20:32:02Z","quality_flags":[],"is_partial":false,"is_reconstructed":false,"confidence_score":1.0,"payload":{"provider":"bitflyer_ws_board","exchange":"bitflyer","transport":"websocket","channel":"lightning_board_BTC_JPY","received_ts":"2026-03-14T20:32:02.382642Z","subscription_id":null,"message_id":null,"source_sequence":null,"raw_message_meta":{"raw_channel":"lightning_board_BTC_JPY","subscription_channel":"lightning_board_BTC_JPY","recv_timeout_sec":10,"ssl_verify":false,"socket_url":"wss://ws.lightstream.bitflyer.com/json-rpc"},"source_payload":{"mid_price":11313431.0,"bids":[{"price":11309598.0,"size":0.0}],"asks":[{"price":11327775.0,"size":0.0}]}}}
{"schema_version":"collector.vnext.raw","schema_contract":null,"schema_contract_version":null,"payload_contract_version":null,"record_type":"market.orderbook.diff","record_id":"collector_main-market-orderbook-diff-000000000107","collector_id":"collector_main","collector_role":"production","host_name":"MAIN-PC","session_id":"collector_main-sess-20260314T203137Z-e804aa95","stream_session_id":"collector_main-stream-bitflyer-board_ws-20260314T203157Z-61ca9e02","exchange":"bitflyer","market":"spot","symbol":"BTC_JPY","instrument_id":"bitflyer.spot.BTC_JPY","channel":"board_ws","transport":"websocket","source_event_id":null,"source_sequence":null,"sequence_id":107,"exchange_ts":null,"collector_ts":"2026-03-14T20:32:02Z","ingest_ts":"2026-03-14T20:32:02Z","event_ts":"2026-03-14T20:32:02Z","quality_flags":[],"is_partial":false,"is_reconstructed":false,"confidence_score":1.0,"payload":{"provider":"bitflyer_ws_board","exchange":"bitflyer","transport":"websocket","channel":"lightning_board_BTC_JPY","received_ts":"2026-03-14T20:32:02.486969Z","subscription_id":null,"message_id":null,"source_sequence":null,"raw_message_meta":{"raw_channel":"lightning_board_BTC_JPY","subscription_channel":"lightning_board_BTC_JPY","recv_timeout_sec":10,"ssl_verify":false,"socket_url":"wss://ws.lightstream.bitflyer.com/json-rpc"},"source_payload":{"mid_price":11313431.0,"bids":[{"price":11309641.0,"size":0.005}],"asks":[{"price":11327889.0,"size":0.2}]}}}
{"schema_version":"collector.vnext.raw","schema_contract":null,"schema_contract_version":null,"payload_contract_version":null,"record_type":"market.orderbook.diff","record_id":"collector_main-market-orderbook-diff-000000000109","collector_id":"collector_main","collector_role":"production","host_name":"MAIN-PC","session_id":"collector_main-sess-20260314T203137Z-e804aa95","stream_session_id":"collector_main-stream-bitflyer-board_ws-20260314T203157Z-61ca9e02","exchange":"bitflyer","market":"spot","symbol":"BTC_JPY","instrument_id":"bitflyer.spot.BTC_JPY","channel":"board_ws","transport":"websocket","source_event_id":null,"source_sequence":null,"sequence_id":109,"exchange_ts":null,"collector_ts":"2026-03-14T20:32:02Z","ingest_ts":"2026-03-14T20:32:02Z","event_ts":"2026-03-14T20:32:02Z","quality_flags":[],"is_partial":false,"is_reconstructed":false,"confidence_score":1.0,"payload":{"provider":"bitflyer_ws_board","exchange":"bitflyer","transport":"websocket","channel":"lightning_board_BTC_JPY","received_ts":"2026-03-14T20:32:02.594926Z","subscription_id":null,"message_id":null,"source_sequence":null,"raw_message_meta":{"raw_channel":"lightning_board_BTC_JPY","subscription_channel":"lightning_board_BTC_JPY","recv_timeout_sec":10,"ssl_verify":false,"socket_url":"wss://ws.lightstream.bitflyer.com/json-rpc"},"source_payload":{"mid_price":11313431.0,"bids":[{"price":11303658.0,"size":0.0},{"price":11303701.0,"size":0.0030426}],"asks":[{"price":11331935.0,"size":0.0},{"price":11331821.0,"size":0.005}]}}}
