{"schema_version":"collector.vnext.raw","schema_contract":null,"schema_contract_version":null,"payload_contract_version":null,"record_type":"market.orderbook.snapshot","record_id":"collector_main-market-orderbook-snapshot-000000000113","collector_id":"collector_main","collector_role":"production","host_name":"MAIN-PC","session_id":"collector_main-sess-20260314T200940Z-3f6b5158","stream_session_id":"collector_main-stream-bitflyer-board_ws-20260314T201056Z-e40b261b","exchange":"bitflyer","market":"spot","symbol":"BTC_JPY","instrument_id":"bitflyer.spot.BTC_JPY","channel":"board_ws","transport":"websocket","source_event_id":null,"source_sequence":null,"sequence_id":113,"exchange_ts":null,"collector_ts":"2026-03-14T20:11:00Z","ingest_ts":"2026-03-14T20:11:00Z","event_ts":"2026-03-14T20:11:00Z","quality_flags":[],"is_partial":false,"is_reconstructed":false,"confidence_score":1.0,"payload":{"provider":"bitflyer_ws_board_snapshot","exchange":"bitflyer","transport":"websocket","channel":"lightning_board_snapshot_BTC_JPY","received_ts":"2026-03-14T20:11:00.845572Z","subscription_id":null,"message_id":null,"source_sequence":null,"raw_message_meta":{"raw_channel":"lightning_board_snapshot_BTC_JPY","subscription_channel":"lightning_board_snapshot_BTC_JPY","recv_timeout_sec":10,"ssl_verify":false,"socket_url":"wss://ws.lightstream.bitflyer.com/json-rpc"},"source_payload":{"mid_price":11306011.0,"bids":[{"price":11303773.0,"size":0.04590183},{"price":11303772.0,"size":0.00999866},{"price":11302336.0,"size":0.015132},{"price":11301963.0,"size":0.0176942},{"price":11301928.0,"size":0.015108},{"price":11301489.0,"size":0.1275},{"price":11300923.0,"size":0.1275},{"price":11300857.0,"size":0.02},{"price":11300856.0,"size":0.014976},{"price":11300798.0,"size":0.015336},{"price":11300226.0,"size":0.005},{"price":11300093.0,"size":0.02},{"price":11298963.0,"size":0.02},{"price":11298579.0,"size":0.05},{"price":11298513.0,"size":0.05},{"price":11298070.0,"size":0.5},{"price":11297887.0,"size":0.0531},{"price":11297439.0,"size":0.5},{"price":11296625.0,"size":0.052056},{"price":11295883.0,"size":2.97412229},{"price":11295882.0,"size":0.6},{"price":11294484.0,"size":0.00999859},{"price":11294287.0,"size":0.001},{"price":11293270.0,"size":0.0801},{"price":11292244.0,"size":0.048},{"price":11289443.0,"size":0.04},{"price":11288470.0,"size":0.132},{"price":11287378.0,"size":1.50015},{"price":11286651.0,"size":0.98403398},{"price":11283324.0,"size":0.2665},{"price":11280562.0,"size":0.3089},{"price":11280205.0,"size":0.001},{"price":11279282.0,"size":0.0015},{"price":11277800.0,"size":0.2689},{"price":11277748.0,"size":0.0966561},{"price":11277602.0,"size":0.005},{"price":11275360.0,"size":1.484},{"price":11275103.0,"size":0.17894886},{"price":11275102.0,"size":0.01},{"price":11275038.0,"size":0.2726},{"price":11275000.0,"size":0.001},{"price":11274588.0,"size":0.0047},{"price":11271711.0,"size":0.6},{"price":11271000.0,"size":0.003},{"price":11270000.0,"size":0.106},{"price":11268871.0,"size":0.281},{"price":11268411.0,"size":0.01},{"price":11266666.0,"size":0.04},{"price":11265000.0,"size":0.02},{"price":11263999.0,"size":1.966},{"price":11263000.0,"size":0.006},{"price":11262564.0,"size":0.0015},{"price":11260000.0,"size":0.3565},{"price":11257537.0,"size":0.001},{"price":11257000.0,"size":0.001},{"price":11255200.0,"size":0.001},{"price":11255115.0,"size":0.00377},{"price":11253000.0,"size":0.03189},{"price":11251000.0,"size":0.0131},{"price":11250250.0,"size":0.00105},{"price":11250200.0,"size":0.001},{"price":11250100.0,"size":0.015},{"price":11250005.0,"size":0.001},{"price":11250001.0,"size":0.00104},{"price":11250000.0,"size":0.76834},{"price":11246544.0,"size":0.0015},{"price":11246203.0,"size":0.001},{"price":11245141.0,"size":0.0031},{"price":11245000.0,"size":0.05},{"price":11244444.0,"size":0.04},{"price":11244243.0,"size":0.01},{"price":11240200.0,"size":0.001},{"price":11240000.0,"size":0.007304},{"price":11236190.0,"size":0.01},{"price":11235200.0,"size":0.001},{"price":11234869.0,"size":0.001},{"price":11233345.0,"size":2.036},{"price":11232000.0,"size":0.089},{"price":11231243.0,"size":0.01},{"price":11231000.0,"size":0.105},{"price":11230200.0,"size":0.001},{"price":11230000.0,"size":0.0308},{"price":11228423.0,"size":1.951},{"price":11224500.0,"size":0.06},{"price":11224355.0,"size":0.0015},{"price":11223968.0,"size":0.001},{"price":11223535.0,"size":0.001},{"price":11223344.0,"size":0.01},{"price":11223000.0,"size":0.1},{"price":11222222.0,"size":0.092525},{"price":11221459.0,"size":0.1393},{"price":11221120.0,"size":0.011},{"price":11220200.0,"size":0.001},{"price":11220001.0,"size":0.004457},{"price":11220000.0,"size":0.321},{"price":11219517.0,"size":0.01},{"price":11219000.0,"size":0.1},{"price":11215200.0,"size":0.001},{"price":11215000.0,"size":0.02},{"price":11212358.0,"size":1.2},{"price":11212201.0,"size":0.001},{"price":11211800.0,"size":0.001},{"price":11211111.0,"size":0.06},{"price":11210200.0,"size":0.001},{"price":11210000.0,"size":0.10622},{"price":11208032.0,"size":0.01},{"price":11207755.0,"size":0.0015},{"price":11206000.0,"size":0.09015},{"price":11205200.0,"size":0.001},{"price":11204578.0,"size":0.002},{"price":11203931.0,"size":1.0},{"price":11201000.0,"size":0.01},{"price":11200867.0,"size":0.001},{"price":11200800.0,"size":0.05},{"price":11200425.0,"size":0.1},{"price":11200200.0,"size":0.001},{"price":11200198.0,"size":0.003},{"price":11200150.0,"size":0.002},{"price":11200002.0,"size":0.001},{"price":11200001.0,"size":0.01104},{"price":11200000.0,"size":1.35988728},{"price":11198508.0,"size":0.05},{"price":11198243.0,"size":0.01},{"price":11197134.0,"size":2.0},{"price":11197000.0,"size":0.0085},{"price":11195692.0,"size":0.0015},{"price":11194090.0,"size":0.03},{"price":11190770.0,"size":0.0309},{"price":11190000.0,"size":0.0010016},{"price":11189555.0,"size":0.5},{"price":11189533.0,"size":0.001},{"price":11188629.0,"size":0.01},{"price":11188382.0,"size":0.001},{"price":11185000.0,"size":0.0085},{"price":11180043.0,"size":0.972},{"price":11180000.0,"size":0.23215},{"price":11178973.0,"size":0.0015},{"price":11178199.0,"size":0.001},{"price":11170000.0,"size":0.001},{"price":11169662.0,"size":0.01},{"price":11169593.0,"size":0.001},{"price":11169243.0,"size":0.01},{"price":11166865.0,"size":0.001},{"price":11164029.0,"size":0.001},{"price":11160854.0,"size":0.1},{"price":11160000.0,"size":0.02376},{"price":11156269.0,"size":0.01},{"price":11155531.0,"size":0.001},{"price":11155377.0,"size":0.00636009},{"price":11153999.0,"size":0.00101},{"price":11150250.0,"size":0.00175},{"price":11150005.0,"size":0.001},{"price":11150001.0,"size":0.00104},{"price":11150000.0,"size":0.6398956},{"price":11148000.0,"size":0.08963},{"price":11144197.0,"size":0.001},{"price":11144000.0,"size":0.0897},{"price":11140000.0,"size":0.2},{"price":11136243.0,"size":0.01},{"price":11136155.0,"size":0.02},{"price":11135869.0,"size":0.1},{"price":11130000.0,"size":0.116},{"price":11129979.0,"size":0.0053908},{"price":11126388.0,"size":0.02},{"price":11124900.0,"size":0.00133},{"price":11121090.0,"size":0.1},{"price":11120000.0,"size":0.0033},{"price":11118078.0,"size":0.01},{"price":11111800.0,"size":0.001},{"price":11111111.0,"size":0.2919257},{"price":11111000.0,"size":0.003},{"price":11110594.0,"size":0.001},{"price":11110000.0,"size":0.056937},{"price":11109662.0,"size":0.01},{"price":11108008.0,"size":0.01},{"price":11106000.0,"size":0.2},{"price":11105000.0,"size":0.02},{"price":11101297.0,"size":0.001},{"price":11100005.0,"size":0.001},{"price":11100001.0,"size":0.01104},{"price":11100000.0,"size":2.7475049},{"price":11099141.0,"size":0.01},{"price":11096243.0,"size":0.01},{"price":11094090.0,"size":0.01},{"price":11088888.0,"size":0.001},{"price":11085245.0,"size":0.001},{"price":11080200.0,"size":0.001},{"price":11080000.0,"size":0.0223},{"price":11075100.0,"size":0.003},{"price":11071558.0,"size":1.0},{"price":11070200.0,"size":0.001},{"price":11070000.0,"size":0.0902},{"price":11065200.0,"size":0.001},{"price":11064370.0,"size":0.00497091},{"price":11060200.0,"size":0.001},{"price":11060000.0,"size":0.145},{"price":11059689.0,"size":0.009},{"price":11056428.0,"size":0.002},{"price":11055500.0,"size":0.02},{"price":11055200.0,"size":0.001},{"price":11055100.0,"size":0.003},{"price":11050200.0,"size":0.001},{"price":11050005.0,"size":0.001},{"price":11050002.0,"size":0.001},{"price":11050001.0,"size":0.00104},{"price":11050000.0,"size":0.43176147},{"price":11046420.0,"size":0.2},{"price":11044243.0,"size":0.01},{"price":11041380.0,"size":0.01},{"price":11040200.0,"size":0.001},{"price":11040000.0,"size":0.00777181},{"price":11035865.0,"size":0.1},{"price":11035200.0,"size":0.001},{"price":11035000.0,"size":0.0013},{"price":11030200.0,"size":0.001},{"price":11030000.0,"size":0.025},{"price":11025500.0,"size":0.009531},{"price":11025200.0,"size":0.001},{"price":11025000.0,"size":0.71497},{"price":11020772.0,"size":0.014},{"price":11020200.0,"size":0.002},{"price":11020000.0,"size":0.005},{"price":11015200.0,"size":0.001},{"price":11012000.0,"size":0.1},{"price":11011800.0,"size":0.001},{"price":11010200.0,"size":0.001},{"price":11010000.0,"size":0.347},{"price":11007277.0,"size":0.01},{"price":11006000.0,"size":0.2},{"price":11005200.0,"size":0.001},{"price":11004890.0,"size":0.001535},{"price":11003000.0,"size":0.0155},{"price":11001000.0,"size":0.013},{"price":11000500.0,"size":0.05117658},{"price":11000200.0,"size":0.001},{"price":11000002.0,"size":0.004},{"price":11000001.0,"size":0.02604},{"price":11000000.0,"size":5.47323365},{"price":10999999.0,"size":0.003},{"price":10999000.0,"size":0.001},{"price":10996855.0,"size":0.0011},{"price":10995200.0,"size":0.001},{"price":10994499.0,"size":0.00169176},{"price":10990200.0,"size":0.001},{"price":10990000.0,"size":0.10219},{"price":10989001.0,"size":0.00197},{"price":10988999.0,"size":0.001},{"price":10988324.0,"size":0.002},{"price":10987654.0,"size":0.001},{"price":10985200.0,"size":0.001},{"price":10985150.0,"size":0.01},{"price":10980500.0,"size":0.005},{"price":10980200.0,"size":0.001},{"price":10980002.0,"size":0.4},{"price":10980000.0,"size":0.028},{"price":10975200.0,"size":0.001},{"price":10975000.0,"size":0.1},{"price":10971261.0,"size":0.001},{"price":10971243.0,"size":0.01},{"price":10970375.0,"size":1.9},{"price":10970200.0,"size":0.001},{"price":10970000.0,"size":0.09304},{"price":10966600.0,"size":0.001003},{"price":10965200.0,"size":0.001},{"price":10960200.0,"size":0.001},{"price":10960000.0,"size":0.0083},{"price":10956673.0,"size":0.01},{"price":10955200.0,"size":0.001},{"price":10954950.0,"size":0.001},{"price":10950500.0,"size":0.005},{"price":10950001.0,"size":0.00204},{"price":10950000.0,"size":0.5485028},{"price":10949550.0,"size":0.01870657},{"price":10949172.0,"size":0.1},{"price":10948000.0,"size":0.1},{"price":10945243.0,"size":0.01},{"price":10940402.0,"size":0.001},{"price":10940200.0,"size":0.001},{"price":10940000.0,"size":0.331},{"price":10938243.0,"size":0.01},{"price":10936200.0,"size":0.00137},{"price":10935200.0,"size":0.001},{"price":10930200.0,"size":0.002},{"price":10930000.0,"size":0.0193},{"price":10925200.0,"size":0.002},{"price":10924451.0,"size":0.0012},{"price":10920509.0,"size":0.01},{"price":10920200.0,"size":0.002},{"price":10920000.0,"size":0.52},{"price":10915200.0,"size":0.001},{"price":10914000.0,"size":0.005},{"price":10911800.0,"size":0.001},{"price":10910500.0,"size":0.005},{"price":10910200.0,"size":0.003},{"price":10910000.0,"size":0.005},{"price":10908243.0,"size":0.01},{"price":10906308.0,"size":0.013},{"price":10905200.0,"size":0.001},{"price":10903000.0,"size":0.027},{"price":10900200.0,"size":0.002}],"asks":[{"price":11308250.0,"size":0.09308185},{"price":11308865.0,"size":0.02},{"price":11308866.0,"size":0.005},{"price":11308930.0,"size":0.02},{"price":11309329.0,"size":0.02},{"price":11309968.0,"size":0.02},{"price":11309969.0,"size":0.1251},{"price":11310444.0,"size":0.02},{"price":11311005.0,"size":0.02},{"price":11311006.0,"size":0.2778},{"price":11311681.0,"size":0.015492},{"price":11312048.0,"size":0.01506},{"price":11312719.0,"size":0.02},{"price":11312720.0,"size":0.4199},{"price":11313584.0,"size":0.052056},{"price":11313658.0,"size":0.01},{"price":11313768.0,"size":0.258},{"price":11313957.0,"size":0.014772},{"price":11315344.0,"size":0.57612881},{"price":11316530.0,"size":0.2806},{"price":11318050.0,"size":0.002},{"price":11318640.0,"size":0.01},{"price":11318849.0,"size":0.053},{"price":11319292.0,"size":0.3099},{"price":11320000.0,"size":0.02},{"price":11320996.0,"size":0.0930818},{"price":11322000.0,"size":0.005},{"price":11323556.0,"size":1.189881},{"price":11323581.0,"size":1.189881},{"price":11325036.0,"size":0.0111226},{"price":11328050.0,"size":0.002},{"price":11329436.0,"size":0.0015},{"price":11331059.0,"size":0.001},{"price":11334237.0,"size":1.489},{"price":11335742.0,"size":1.928},{"price":11340000.0,"size":0.13586406},{"price":11340647.0,"size":0.001},{"price":11342956.0,"size":1.60199848},{"price":11342957.0,"size":0.01},{"price":11346154.0,"size":0.0015},{"price":11348000.0,"size":0.1999},{"price":11349700.0,"size":0.001},{"price":11350000.0,"size":0.022},{"price":11353877.0,"size":0.001},{"price":11354939.0,"size":0.01},{"price":11355555.0,"size":0.001},{"price":11358323.0,"size":2.018},{"price":11359242.0,"size":0.0011},{"price":11359700.0,"size":0.001},{"price":11362692.0,"size":0.0015},{"price":11365211.0,"size":0.001},{"price":11369700.0,"size":0.001},{"price":11370000.0,"size":0.1},{"price":11372478.0,"size":1.943},{"price":11376000.0,"size":0.02},{"price":11376545.0,"size":0.001},{"price":11377000.0,"size":0.2287},{"price":11377269.0,"size":0.002},{"price":11379700.0,"size":0.001},{"price":11379865.0,"size":0.03},{"price":11380000.0,"size":0.0223},{"price":11380324.0,"size":0.002},{"price":11381766.0,"size":0.4},{"price":11382386.0,"size":0.0015},{"price":11385000.0,"size":0.2548},{"price":11385403.0,"size":0.002},{"price":11385664.0,"size":0.002},{"price":11387072.0,"size":0.01},{"price":11387354.0,"size":0.002},{"price":11387879.0,"size":0.001},{"price":11388885.0,"size":0.03},{"price":11389700.0,"size":0.001},{"price":11390000.0,"size":0.2488},{"price":11390050.0,"size":0.001},{"price":11392387.0,"size":1.0},{"price":11394939.0,"size":0.01},{"price":11395000.0,"size":0.06},{"price":11395775.0,"size":0.01},{"price":11396555.0,"size":0.03},{"price":11398444.0,"size":0.001995},{"price":11399213.0,"size":0.001},{"price":11399673.0,"size":0.0015},{"price":11399700.0,"size":0.001},{"price":11400000.0,"size":0.5525},{"price":11405000.0,"size":0.0275},{"price":11406336.0,"size":1.0},{"price":11408700.0,"size":0.001},{"price":11409415.0,"size":0.055},{"price":11410000.0,"size":0.03},{"price":11410547.0,"size":0.001},{"price":11410853.0,"size":0.002},{"price":11412000.0,"size":0.0878},{"price":11415000.0,"size":0.002},{"price":11415141.0,"size":0.0041},{"price":11417481.0,"size":0.0015},{"price":11418700.0,"size":0.001},{"price":11420000.0,"size":0.401},{"price":11421268.0,"size":0.05},{"price":11421881.0,"size":0.001},{"price":11423339.0,"size":2.0},{"price":11424296.0,"size":0.002},{"price":11424941.0,"size":0.972},{"price":11425000.0,"size":0.049},{"price":11426426.0,"size":0.002},{"price":11428121.0,"size":0.002},{"price":11428700.0,"size":0.001},{"price":11429302.0,"size":0.01},{"price":11432718.0,"size":0.002},{"price":11433211.0,"size":0.03},{"price":11433215.0,"size":0.001},{"price":11433333.0,"size":0.001},{"price":11437315.0,"size":0.002},{"price":11438525.0,"size":0.0011},{"price":11438700.0,"size":0.001},{"price":11439557.0,"size":0.001},{"price":11440000.0,"size":0.1038},{"price":11441911.0,"size":0.002},{"price":11443629.0,"size":0.002},{"price":11444549.0,"size":0.001},{"price":11446508.0,"size":0.001},{"price":11447000.0,"size":0.01},{"price":11447071.0,"size":0.002},{"price":11448000.0,"size":0.0875},{"price":11448700.0,"size":0.001},{"price":11450000.0,"size":0.258},{"price":11451105.0,"size":0.002},{"price":11453321.0,"size":0.03},{"price":11455702.0,"size":0.002},{"price":11455883.0,"size":0.001},{"price":11458700.0,"size":0.001},{"price":11458988.0,"size":0.01},{"price":11460000.0,"size":0.01702},{"price":11460299.0,"size":0.002},{"price":11464896.0,"size":0.002},{"price":11467217.0,"size":0.001},{"price":11468700.0,"size":0.001},{"price":11470000.0,"size":0.01},{"price":11471000.0,"size":0.01},{"price":11475000.0,"size":0.0028},{"price":11478431.0,"size":0.002},{"price":11478551.0,"size":0.001},{"price":11478700.0,"size":0.001},{"price":11480000.0,"size":0.12491},{"price":11485000.0,"size":0.01},{"price":11486555.0,"size":0.03},{"price":11487685.0,"size":0.01},{"price":11488000.0,"size":0.102},{"price":11488700.0,"size":0.001},{"price":11489885.0,"size":0.001},{"price":11490841.0,"size":0.002},{"price":11495450.0,"size":0.002},{"price":11495850.0,"size":0.001},{"price":11498700.0,"size":0.001},{"price":11498917.0,"size":0.002},{"price":11499000.0,"size":0.01},{"price":11500000.0,"size":0.46859519},{"price":11501219.0,"size":0.001},{"price":11502377.0,"size":0.002},{"price":11502800.0,"size":0.00132},{"price":11503108.0,"size":0.0198},{"price":11505000.0,"size":0.0028},{"price":11505001.0,"size":0.002},{"price":11505836.0,"size":0.003},{"price":11508431.0,"size":0.047},{"price":11508700.0,"size":0.001},{"price":11508888.0,"size":0.02},{"price":11510000.0,"size":0.0976},{"price":11512553.0,"size":0.001},{"price":11513633.0,"size":0.08},{"price":11514332.0,"size":0.02},{"price":11518700.0,"size":0.001},{"price":11518992.0,"size":0.002},{"price":11519855.0,"size":0.01},{"price":11520000.0,"size":0.001},{"price":11522423.0,"size":0.97},{"price":11523211.0,"size":0.01},{"price":11523887.0,"size":0.001},{"price":11524999.0,"size":0.001},{"price":11528700.0,"size":0.001},{"price":11529852.0,"size":0.01},{"price":11530000.0,"size":0.261},{"price":11533985.0,"size":0.002},{"price":11534084.0,"size":0.001},{"price":11535321.0,"size":0.01},{"price":11538666.0,"size":0.002},{"price":11538700.0,"size":0.001},{"price":11540000.0,"size":0.0048},{"price":11540357.0,"size":0.002},{"price":11541011.0,"size":0.005},{"price":11541109.0,"size":0.01},{"price":11544663.0,"size":0.002},{"price":11546541.0,"size":0.01},{"price":11548144.0,"size":0.002},{"price":11548700.0,"size":0.001},{"price":11550000.0,"size":0.014},{"price":11551109.0,"size":0.01},{"price":11552111.0,"size":0.01},{"price":11553687.0,"size":0.1},{"price":11555115.0,"size":0.001},{"price":11556000.0,"size":0.1},{"price":11558700.0,"size":0.001},{"price":11559855.0,"size":0.01},{"price":11560831.0,"size":0.0198},{"price":11561109.0,"size":0.01},{"price":11562000.0,"size":0.087},{"price":11566139.0,"size":0.0228},{"price":11566551.0,"size":0.01},{"price":11568700.0,"size":0.001},{"price":11571109.0,"size":0.01},{"price":11573211.0,"size":0.01},{"price":11578700.0,"size":0.001},{"price":11579851.0,"size":0.01},{"price":11580000.0,"size":0.7735},{"price":11581109.0,"size":0.01},{"price":11585000.0,"size":0.002},{"price":11586532.0,"size":0.01},{"price":11587498.0,"size":0.0198},{"price":11588700.0,"size":0.001},{"price":11589612.0,"size":0.012},{"price":11590000.0,"size":0.1},{"price":11590749.0,"size":0.002},{"price":11591109.0,"size":0.01},{"price":11593211.0,"size":0.01},{"price":11598555.0,"size":0.01},{"price":11598700.0,"size":0.001},{"price":11599999.0,"size":0.001},{"price":11600000.0,"size":3.6141},{"price":11601109.0,"size":0.02},{"price":11606655.0,"size":0.01},{"price":11610000.0,"size":0.302},{"price":11611109.0,"size":0.01},{"price":11613321.0,"size":0.01},{"price":11620000.0,"size":1.35441682},{"price":11621011.0,"size":0.01},{"price":11621109.0,"size":0.01},{"price":11623096.0,"size":0.008},{"price":11629000.0,"size":0.1},{"price":11630000.0,"size":0.201},{"price":11631059.0,"size":0.01},{"price":11631479.0,"size":0.01},{"price":11631773.0,"size":0.00386871},{"price":11635950.0,"size":0.001},{"price":11638259.0,"size":0.001},{"price":11639700.0,"size":0.001},{"price":11640000.0,"size":1.0},{"price":11640820.0,"size":0.01},{"price":11641651.0,"size":2.0},{"price":11645295.0,"size":0.05},{"price":11647158.0,"size":0.05},{"price":11649900.0,"size":0.02906},{"price":11649999.0,"size":0.001},{"price":11650000.0,"size":0.593},{"price":11651059.0,"size":0.01},{"price":11653658.0,"size":0.008},{"price":11654321.0,"size":0.001},{"price":11659700.0,"size":0.001},{"price":11661479.0,"size":0.01},{"price":11666000.0,"size":0.001},{"price":11666666.0,"size":0.013},{"price":11669700.0,"size":0.001},{"price":11671059.0,"size":0.01},{"price":11672562.0,"size":0.0198},{"price":11679224.0,"size":0.012},{"price":11680000.0,"size":0.004},{"price":11685000.0,"size":0.003},{"price":11688000.0,"size":0.001},{"price":11689732.0,"size":0.01},{"price":11690330.0,"size":0.0198},{"price":11691059.0,"size":0.01},{"price":11692558.0,"size":0.01},{"price":11698800.0,"size":0.00131},{"price":11699000.0,"size":0.001},{"price":11699631.0,"size":0.001},{"price":11699998.0,"size":0.01},{"price":11699999.0,"size":0.001},{"price":11700000.0,"size":1.03762841},{"price":11701059.0,"size":0.01},{"price":11720000.0,"size":0.1},{"price":11721059.0,"size":0.01},{"price":11725000.0,"size":0.005},{"price":11726791.0,"size":0.01},{"price":11730000.0,"size":0.9382},{"price":11740000.0,"size":0.101},{"price":11741059.0,"size":0.01},{"price":11745417.0,"size":2.0},{"price":11748937.0,"size":0.001},{"price":11749999.0,"size":0.001},{"price":11750000.0,"size":0.90537866},{"price":11750050.0,"size":0.2},{"price":11751151.0,"size":0.01},{"price":11755000.0,"size":0.001},{"price":11759999.0,"size":0.001},{"price":11760000.0,"size":0.001},{"price":11761059.0,"size":0.02},{"price":11765432.0,"size":0.001},{"price":11768000.0,"size":0.01},{"price":11768836.0,"size":0.012},{"price":11770000.0,"size":0.25464896},{"price":11771059.0,"size":0.01755555},{"price":11772000.0,"size":0.002}]}}}
{"schema_version":"collector.vnext.raw","schema_contract":null,"schema_contract_version":null,"payload_contract_version":null,"record_type":"market.orderbook.diff","record_id":"collector_main-market-orderbook-diff-000000000061","collector_id":"collector_main","collector_role":"production","host_name":"MAIN-PC","session_id":"collector_main-sess-20260314T201115Z-12e412ee","stream_session_id":"collector_main-stream-bitflyer-board_ws-20260314T201116Z-eb471dba","exchange":"bitflyer","market":"spot","symbol":"BTC_JPY","instrument_id":"bitflyer.spot.BTC_JPY","channel":"board_ws","transport":"websocket","source_event_id":null,"source_sequence":null,"sequence_id":61,"exchange_ts":null,"collector_ts":"2026-03-14T20:11:17Z","ingest_ts":"2026-03-14T20:11:17Z","event_ts":"2026-03-14T20:11:17Z","quality_flags":[],"is_partial":false,"is_reconstructed":false,"confidence_score":1.0,"payload":{"provider":"bitflyer_ws_board","exchange":"bitflyer","transport":"websocket","channel":"lightning_board_BTC_JPY","received_ts":"2026-03-14T20:11:17.126740Z","subscription_id":null,"message_id":null,"source_sequence":null,"raw_message_meta":{"raw_channel":"lightning_board_BTC_JPY","subscription_channel":"lightning_board_BTC_JPY","recv_timeout_sec":10,"ssl_verify":false,"socket_url":"wss://ws.lightstream.bitflyer.com/json-rpc"},"source_payload":{"mid_price":11304866.0,"bids":[{"price":11294489.0,"size":0.0013033},{"price":11302177.0,"size":0.0}],"asks":[]}}}
{"schema_version":"collector.vnext.raw","schema_contract":null,"schema_contract_version":null,"payload_contract_version":null,"record_type":"market.orderbook.diff","record_id":"collector_main-market-orderbook-diff-000000000065","collector_id":"collector_main","collector_role":"production","host_name":"MAIN-PC","session_id":"collector_main-sess-20260314T201115Z-12e412ee","stream_session_id":"collector_main-stream-bitflyer-board_ws-20260314T201116Z-eb471dba","exchange":"bitflyer","market":"spot","symbol":"BTC_JPY","instrument_id":"bitflyer.spot.BTC_JPY","channel":"board_ws","transport":"websocket","source_event_id":null,"source_sequence":null,"sequence_id":65,"exchange_ts":null,"collector_ts":"2026-03-14T20:11:17Z","ingest_ts":"2026-03-14T20:11:17Z","event_ts":"2026-03-14T20:11:17Z","quality_flags":[],"is_partial":false,"is_reconstructed":false,"confidence_score":1.0,"payload":{"provider":"bitflyer_ws_board","exchange":"bitflyer","transport":"websocket","channel":"lightning_board_BTC_JPY","received_ts":"2026-03-14T20:11:17.250705Z","subscription_id":null,"message_id":null,"source_sequence":null,"raw_message_meta":{"raw_channel":"lightning_board_BTC_JPY","subscription_channel":"lightning_board_BTC_JPY","recv_timeout_sec":10,"ssl_verify":false,"socket_url":"wss://ws.lightstream.bitflyer.com/json-rpc"},"source_payload":{"mid_price":11304943.0,"bids":[{"price":11301990.0,"size":0.0},{"price":11301047.0,"size":0.0},{"price":11302178.0,"size":0.06223979}],"asks":[{"price":11308864.0,"size":0.04636061}]}}}
{"schema_version":"collector.vnext.raw","schema_contract":null,"schema_contract_version":null,"payload_contract_version":null,"record_type":"market.orderbook.diff","record_id":"collector_main-market-orderbook-diff-000000000067","collector_id":"collector_main","collector_role":"production","host_name":"MAIN-PC","session_id":"collector_main-sess-20260314T201115Z-12e412ee","stream_session_id":"collector_main-stream-bitflyer-board_ws-20260314T201116Z-eb471dba","exchange":"bitflyer","market":"spot","symbol":"BTC_JPY","instrument_id":"bitflyer.spot.BTC_JPY","channel":"board_ws","transport":"websocket","source_event_id":null,"source_sequence":null,"sequence_id":67,"exchange_ts":null,"collector_ts":"2026-03-14T20:11:17Z","ingest_ts":"2026-03-14T20:11:17Z","event_ts":"2026-03-14T20:11:17Z","quality_flags":[],"is_partial":false,"is_reconstructed":false,"confidence_score":1.0,"payload":{"provider":"bitflyer_ws_board","exchange":"bitflyer","transport":"websocket","channel":"lightning_board_BTC_JPY","received_ts":"2026-03-14T20:11:17.382462Z","subscription_id":null,"message_id":null,"source_sequence":null,"raw_message_meta":{"raw_channel":"lightning_board_BTC_JPY","subscription_channel":"lightning_board_BTC_JPY","recv_timeout_sec":10,"ssl_verify":false,"socket_url":"wss://ws.lightstream.bitflyer.com/json-rpc"},"source_payload":{"mid_price":11304874.0,"bids":[{"price":11302025.0,"size":0.0},{"price":11302040.0,"size":0.1275},{"price":11302178.0,"size":0.0},{"price":11300379.0,"size":0.0}],"asks":[]}}}
{"schema_version":"collector.vnext.raw","schema_contract":null,"schema_contract_version":null,"payload_contract_version":null,"record_type":"market.orderbook.diff","record_id":"collector_main-market-orderbook-diff-000000000069","collector_id":"collector_main","collector_role":"production","host_name":"MAIN-PC","session_id":"collector_main-sess-20260314T201115Z-12e412ee","stream_session_id":"collector_main-stream-bitflyer-board_ws-20260314T201116Z-eb471dba","exchange":"bitflyer","market":"spot","symbol":"BTC_JPY","instrument_id":"bitflyer.spot.BTC_JPY","channel":"board_ws","transport":"websocket","source_event_id":null,"source_sequence":null,"sequence_id":69,"exchange_ts":null,"collector_ts":"2026-03-14T20:11:17Z","ingest_ts":"2026-03-14T20:11:17Z","event_ts":"2026-03-14T20:11:17Z","quality_flags":[],"is_partial":false,"is_reconstructed":false,"confidence_score":1.0,"payload":{"provider":"bitflyer_ws_board","exchange":"bitflyer","transport":"websocket","channel":"lightning_board_BTC_JPY","received_ts":"2026-03-14T20:11:17.492667Z","subscription_id":null,"message_id":null,"source_sequence":null,"raw_message_meta":{"raw_channel":"lightning_board_BTC_JPY","subscription_channel":"lightning_board_BTC_JPY","recv_timeout_sec":10,"ssl_verify":false,"socket_url":"wss://ws.lightstream.bitflyer.com/json-rpc"},"source_payload":{"mid_price":11304867.0,"bids":[{"price":11300429.0,"size":0.005},{"price":11302026.0,"size":0.06267778},{"price":11302040.0,"size":0.0},{"price":11302682.0,"size":0.0}],"asks":[]}}}
{"schema_version":"collector.vnext.raw","schema_contract":null,"schema_contract_version":null,"payload_contract_version":null,"record_type":"market.orderbook.diff","record_id":"collector_main-market-orderbook-diff-000000000071","collector_id":"collector_main","collector_role":"production","host_name":"MAIN-PC","session_id":"collector_main-sess-20260314T201115Z-12e412ee","stream_session_id":"collector_main-stream-bitflyer-board_ws-20260314T201116Z-eb471dba","exchange":"bitflyer","market":"spot","symbol":"BTC_JPY","instrument_id":"bitflyer.spot.BTC_JPY","channel":"board_ws","transport":"websocket","source_event_id":null,"source_sequence":null,"sequence_id":71,"exchange_ts":null,"collector_ts":"2026-03-14T20:11:17Z","ingest_ts":"2026-03-14T20:11:17Z","event_ts":"2026-03-14T20:11:17Z","quality_flags":[],"is_partial":false,"is_reconstructed":false,"confidence_score":1.0,"payload":{"provider":"bitflyer_ws_board","exchange":"bitflyer","transport":"websocket","channel":"lightning_board_BTC_JPY","received_ts":"2026-03-14T20:11:17.598688Z","subscription_id":null,"message_id":null,"source_sequence":null,"raw_message_meta":{"raw_channel":"lightning_board_BTC_JPY","subscription_channel":"lightning_board_BTC_JPY","recv_timeout_sec":10,"ssl_verify":false,"socket_url":"wss://ws.lightstream.bitflyer.com/json-rpc"},"source_payload":{"mid_price":11304669.0,"bids":[{"price":11302026.0,"size":0.0}],"asks":[]}}}
{"schema_version":"collector.vnext.raw","schema_contract":null,"schema_contract_version":null,"payload_contract_version":null,"record_type":"market.orderbook.diff","record_id":"collector_main-market-orderbook-diff-000000000073","collector_id":"collector_main","collector_role":"production","host_name":"MAIN-PC","session_id":"collector_main-sess-20260314T201115Z-12e412ee","stream_session_id":"collector_main-stream-bitflyer-board_ws-20260314T201116Z-eb471dba","exchange":"bitflyer","market":"spot","symbol":"BTC_JPY","instrument_id":"bitflyer.spot.BTC_JPY","channel":"board_ws","transport":"websocket","source_event_id":null,"source_sequence":null,"sequence_id":73,"exchange_ts":null,"collector_ts":"2026-03-14T20:11:17Z","ingest_ts":"2026-03-14T20:11:17Z","event_ts":"2026-03-14T20:11:17Z","quality_flags":[],"is_partial":false,"is_reconstructed":false,"confidence_score":1.0,"payload":{"provider":"bitflyer_ws_board","exchange":"bitflyer","transport":"websocket","channel":"lightning_board_BTC_JPY","received_ts":"2026-03-14T20:11:17.688780Z","subscription_id":null,"message_id":null,"source_sequence":null,"raw_message_meta":{"raw_channel":"lightning_board_BTC_JPY","subscription_channel":"lightning_board_BTC_JPY","recv_timeout_sec":10,"ssl_verify":false,"socket_url":"wss://ws.lightstream.bitflyer.com/json-rpc"},"source_payload":{"mid_price":11304669.0,"bids":[{"price":11302179.0,"size":0.0},{"price":11302041.0,"size":0.0},{"price":11280030.0,"size":0.002},{"price":11297887.0,"size":0.0}],"asks":[]}}}
{"schema_version":"collector.vnext.raw","schema_contract":null,"schema_contract_version":null,"payload_contract_version":null,"record_type":"market.orderbook.diff","record_id":"collector_main-market-orderbook-diff-000000000075","collector_id":"collector_main","collector_role":"production","host_name":"MAIN-PC","session_id":"collector_main-sess-20260314T201115Z-12e412ee","stream_session_id":"collector_main-stream-bitflyer-board_ws-20260314T201116Z-eb471dba","exchange":"bitflyer","market":"spot","symbol":"BTC_JPY","instrument_id":"bitflyer.spot.BTC_JPY","channel":"board_ws","transport":"websocket","source_event_id":null,"source_sequence":null,"sequence_id":75,"exchange_ts":null,"collector_ts":"2026-03-14T20:11:17Z","ingest_ts":"2026-03-14T20:11:17Z","event_ts":"2026-03-14T20:11:17Z","quality_flags":[],"is_partial":false,"is_reconstructed":false,"confidence_score":1.0,"payload":{"provider":"bitflyer_ws_board","exchange":"bitflyer","transport":"websocket","channel":"lightning_board_BTC_JPY","received_ts":"2026-03-14T20:11:17.821591Z","subscription_id":null,"message_id":null,"source_sequence":null,"raw_message_meta":{"raw_channel":"lightning_board_BTC_JPY","subscription_channel":"lightning_board_BTC_JPY","recv_timeout_sec":10,"ssl_verify":false,"socket_url":"wss://ws.lightstream.bitflyer.com/json-rpc"},"source_payload":{"mid_price":11304874.0,"bids":[{"price":11301665.0,"size":0.0176947},{"price":11302040.0,"size":0.1275},{"price":11301631.0,"size":0.06753737},{"price":11301630.0,"size":0.0},{"price":11301842.0,"size":0.1275}],"asks":[]}}}
{"schema_version":"collector.vnext.raw","schema_contract":null,"schema_contract_version":null,"payload_contract_version":null,"record_type":"market.orderbook.diff","record_id":"collector_main-market-orderbook-diff-000000000077","collector_id":"collector_main","collector_role":"production","host_name":"MAIN-PC","session_id":"collector_main-sess-20260314T201115Z-12e412ee","stream_session_id":"collector_main-stream-bitflyer-board_ws-20260314T201116Z-eb471dba","exchange":"bitflyer","market":"spot","symbol":"BTC_JPY","instrument_id":"bitflyer.spot.BTC_JPY","channel":"board_ws","transport":"websocket","source_event_id":null,"source_sequence":null,"sequence_id":77,"exchange_ts":null,"collector_ts":"2026-03-14T20:11:17Z","ingest_ts":"2026-03-14T20:11:17Z","event_ts":"2026-03-14T20:11:17Z","quality_flags":[],"is_partial":false,"is_reconstructed":false,"confidence_score":1.0,"payload":{"provider":"bitflyer_ws_board","exchange":"bitflyer","transport":"websocket","channel":"lightning_board_BTC_JPY","received_ts":"2026-03-14T20:11:17.925721Z","subscription_id":null,"message_id":null,"source_sequence":null,"raw_message_meta":{"raw_channel":"lightning_board_BTC_JPY","subscription_channel":"lightning_board_BTC_JPY","recv_timeout_sec":10,"ssl_verify":false,"socket_url":"wss://ws.lightstream.bitflyer.com/json-rpc"},"source_payload":{"mid_price":11304874.0,"bids":[{"price":11297290.0,"size":0.0531}],"asks":[]}}}
{"schema_version":"collector.vnext.raw","schema_contract":null,"schema_contract_version":null,"payload_contract_version":null,"record_type":"market.orderbook.diff","record_id":"collector_main-market-orderbook-diff-000000000079","collector_id":"collector_main","collector_role":"production","host_name":"MAIN-PC","session_id":"collector_main-sess-20260314T201115Z-12e412ee","stream_session_id":"collector_main-stream-bitflyer-board_ws-20260314T201116Z-eb471dba","exchange":"bitflyer","market":"spot","symbol":"BTC_JPY","instrument_id":"bitflyer.spot.BTC_JPY","channel":"board_ws","transport":"websocket","source_event_id":null,"source_sequence":null,"sequence_id":79,"exchange_ts":null,"collector_ts":"2026-03-14T20:11:18Z","ingest_ts":"2026-03-14T20:11:18Z","event_ts":"2026-03-14T20:11:18Z","quality_flags":[],"is_partial":false,"is_reconstructed":false,"confidence_score":1.0,"payload":{"provider":"bitflyer_ws_board","exchange":"bitflyer","transport":"websocket","channel":"lightning_board_BTC_JPY","received_ts":"2026-03-14T20:11:18.032125Z","subscription_id":null,"message_id":null,"source_sequence":null,"raw_message_meta":{"raw_channel":"lightning_board_BTC_JPY","subscription_channel":"lightning_board_BTC_JPY","recv_timeout_sec":10,"ssl_verify":false,"socket_url":"wss://ws.lightstream.bitflyer.com/json-rpc"},"source_payload":{"mid_price":11304874.0,"bids":[{"price":11250065.0,"size":0.002},{"price":11299290.0,"size":0.01},{"price":11301631.0,"size":0.0},{"price":11301648.0,"size":0.015552},{"price":11302041.0,"size":0.06090462}],"asks":[{"price":13886000.0,"size":0.0},{"price":13877500.0,"size":0.0}]}}}
{"schema_version":"collector.vnext.raw","schema_contract":null,"schema_contract_version":null,"payload_contract_version":null,"record_type":"market.orderbook.diff","record_id":"collector_main-market-orderbook-diff-000000000081","collector_id":"collector_main","collector_role":"production","host_name":"MAIN-PC","session_id":"collector_main-sess-20260314T201115Z-12e412ee","stream_session_id":"collector_main-stream-bitflyer-board_ws-20260314T201116Z-eb471dba","exchange":"bitflyer","market":"spot","symbol":"BTC_JPY","instrument_id":"bitflyer.spot.BTC_JPY","channel":"board_ws","transport":"websocket","source_event_id":null,"source_sequence":null,"sequence_id":81,"exchange_ts":null,"collector_ts":"2026-03-14T20:11:18Z","ingest_ts":"2026-03-14T20:11:18Z","event_ts":"2026-03-14T20:11:18Z","quality_flags":[],"is_partial":false,"is_reconstructed":false,"confidence_score":1.0,"payload":{"provider":"bitflyer_ws_board","exchange":"bitflyer","transport":"websocket","channel":"lightning_board_BTC_JPY","received_ts":"2026-03-14T20:11:18.127466Z","subscription_id":null,"message_id":null,"source_sequence":null,"raw_message_meta":{"raw_channel":"lightning_board_BTC_JPY","subscription_channel":"lightning_board_BTC_JPY","recv_timeout_sec":10,"ssl_verify":false,"socket_url":"wss://ws.lightstream.bitflyer.com/json-rpc"},"source_payload":{"mid_price":11304874.0,"bids":[{"price":11302041.0,"size":0.06590462}],"asks":[]}}}
{"schema_version":"collector.vnext.raw","schema_contract":null,"schema_contract_version":null,"payload_contract_version":null,"record_type":"market.orderbook.diff","record_id":"collector_main-market-orderbook-diff-000000000083","collector_id":"collector_main","collector_role":"production","host_name":"MAIN-PC","session_id":"collector_main-sess-20260314T201115Z-12e412ee","stream_session_id":"collector_main-stream-bitflyer-board_ws-20260314T201116Z-eb471dba","exchange":"bitflyer","market":"spot","symbol":"BTC_JPY","instrument_id":"bitflyer.spot.BTC_JPY","channel":"board_ws","transport":"websocket","source_event_id":null,"source_sequence":null,"sequence_id":83,"exchange_ts":null,"collector_ts":"2026-03-14T20:11:18Z","ingest_ts":"2026-03-14T20:11:18Z","event_ts":"2026-03-14T20:11:18Z","quality_flags":[],"is_partial":false,"is_reconstructed":false,"confidence_score":1.0,"payload":{"provider":"bitflyer_ws_board","exchange":"bitflyer","transport":"websocket","channel":"lightning_board_BTC_JPY","received_ts":"2026-03-14T20:11:18.438463Z","subscription_id":null,"message_id":null,"source_sequence":null,"raw_message_meta":{"raw_channel":"lightning_board_BTC_JPY","subscription_channel":"lightning_board_BTC_JPY","recv_timeout_sec":10,"ssl_verify":false,"socket_url":"wss://ws.lightstream.bitflyer.com/json-rpc"},"source_payload":{"mid_price":11304874.0,"bids":[],"asks":[{"price":13869000.0,"size":0.0}]}}}
{"schema_version":"collector.vnext.raw","schema_contract":null,"schema_contract_version":null,"payload_contract_version":null,"record_type":"market.orderbook.diff","record_id":"collector_main-market-orderbook-diff-000000000085","collector_id":"collector_main","collector_role":"production","host_name":"MAIN-PC","session_id":"collector_main-sess-20260314T201115Z-12e412ee","stream_session_id":"collector_main-stream-bitflyer-board_ws-20260314T201116Z-eb471dba","exchange":"bitflyer","market":"spot","symbol":"BTC_JPY","instrument_id":"bitflyer.spot.BTC_JPY","channel":"board_ws","transport":"websocket","source_event_id":null,"source_sequence":null,"sequence_id":85,"exchange_ts":null,"collector_ts":"2026-03-14T20:11:18Z","ingest_ts":"2026-03-14T20:11:18Z","event_ts":"2026-03-14T20:11:18Z","quality_flags":[],"is_partial":false,"is_reconstructed":false,"confidence_score":1.0,"payload":{"provider":"bitflyer_ws_board","exchange":"bitflyer","transport":"websocket","channel":"lightning_board_BTC_JPY","received_ts":"2026-03-14T20:11:18.672762Z","subscription_id":null,"message_id":null,"source_sequence":null,"raw_message_meta":{"raw_channel":"lightning_board_BTC_JPY","subscription_channel":"lightning_board_BTC_JPY","recv_timeout_sec":10,"ssl_verify":false,"socket_url":"wss://ws.lightstream.bitflyer.com/json-rpc"},"source_payload":{"mid_price":11304874.0,"bids":[{"price":11301665.0,"size":0.0}],"asks":[]}}}
{"schema_version":"collector.vnext.raw","schema_contract":null,"schema_contract_version":null,"payload_contract_version":null,"record_type":"market.orderbook.diff","record_id":"collector_main-market-orderbook-diff-000000000087","collector_id":"collector_main","collector_role":"production","host_name":"MAIN-PC","session_id":"collector_main-sess-20260314T201115Z-12e412ee","stream_session_id":"collector_main-stream-bitflyer-board_ws-20260314T201116Z-eb471dba","exchange":"bitflyer","market":"spot","symbol":"BTC_JPY","instrument_id":"bitflyer.spot.BTC_JPY","channel":"board_ws","transport":"websocket","source_event_id":null,"source_sequence":null,"sequence_id":87,"exchange_ts":null,"collector_ts":"2026-03-14T20:11:18Z","ingest_ts":"2026-03-14T20:11:18Z","event_ts":"2026-03-14T20:11:18Z","quality_flags":[],"is_partial":false,"is_reconstructed":false,"confidence_score":1.0,"payload":{"provider":"bitflyer_ws_board","exchange":"bitflyer","transport":"websocket","channel":"lightning_board_BTC_JPY","received_ts":"2026-03-14T20:11:18.766740Z","subscription_id":null,"message_id":null,"source_sequence":null,"raw_message_meta":{"raw_channel":"lightning_board_BTC_JPY","subscription_channel":"lightning_board_BTC_JPY","recv_timeout_sec":10,"ssl_verify":false,"socket_url":"wss://ws.lightstream.bitflyer.com/json-rpc"},"source_payload":{"mid_price":11304874.0,"bids":[],"asks":[{"price":11308250.0,"size":0.0}]}}}
{"schema_version":"collector.vnext.raw","schema_contract":null,"schema_contract_version":null,"payload_contract_version":null,"record_type":"market.orderbook.diff","record_id":"collector_main-market-orderbook-diff-000000000089","collector_id":"collector_main","collector_role":"production","host_name":"MAIN-PC","session_id":"collector_main-sess-20260314T201115Z-12e412ee","stream_session_id":"collector_main-stream-bitflyer-board_ws-20260314T201116Z-eb471dba","exchange":"bitflyer","market":"spot","symbol":"BTC_JPY","instrument_id":"bitflyer.spot.BTC_JPY","channel":"board_ws","transport":"websocket","source_event_id":null,"source_sequence":null,"sequence_id":89,"exchange_ts":null,"collector_ts":"2026-03-14T20:11:18Z","ingest_ts":"2026-03-14T20:11:18Z","event_ts":"2026-03-14T20:11:18Z","quality_flags":[],"is_partial":false,"is_reconstructed":false,"confidence_score":1.0,"payload":{"provider":"bitflyer_ws_board","exchange":"bitflyer","transport":"websocket","channel":"lightning_board_BTC_JPY","received_ts":"2026-03-14T20:11:18.915185Z","subscription_id":null,"message_id":null,"source_sequence":null,"raw_message_meta":{"raw_channel":"lightning_board_BTC_JPY","subscription_channel":"lightning_board_BTC_JPY","recv_timeout_sec":10,"ssl_verify":false,"socket_url":"wss://ws.lightstream.bitflyer.com/json-rpc"},"source_payload":{"mid_price":11305205.0,"bids":[{"price":11302702.0,"size":0.00999866}],"asks":[]}}}
{"schema_version":"collector.vnext.raw","schema_contract":null,"schema_contract_version":null,"payload_contract_version":null,"record_type":"market.orderbook.diff","record_id":"collector_main-market-orderbook-diff-000000000091","collector_id":"collector_main","collector_role":"production","host_name":"MAIN-PC","session_id":"collector_main-sess-20260314T201115Z-12e412ee","stream_session_id":"collector_main-stream-bitflyer-board_ws-20260314T201116Z-eb471dba","exchange":"bitflyer","market":"spot","symbol":"BTC_JPY","instrument_id":"bitflyer.spot.BTC_JPY","channel":"board_ws","transport":"websocket","source_event_id":null,"source_sequence":null,"sequence_id":91,"exchange_ts":null,"collector_ts":"2026-03-14T20:11:19Z","ingest_ts":"2026-03-14T20:11:19Z","event_ts":"2026-03-14T20:11:19Z","quality_flags":[],"is_partial":false,"is_reconstructed":false,"confidence_score":1.0,"payload":{"provider":"bitflyer_ws_board","exchange":"bitflyer","transport":"websocket","channel":"lightning_board_BTC_JPY","received_ts":"2026-03-14T20:11:19.032698Z","subscription_id":null,"message_id":null,"source_sequence":null,"raw_message_meta":{"raw_channel":"lightning_board_BTC_JPY","subscription_channel":"lightning_board_BTC_JPY","recv_timeout_sec":10,"ssl_verify":false,"socket_url":"wss://ws.lightstream.bitflyer.com/json-rpc"},"source_payload":{"mid_price":11305205.0,"bids":[{"price":11302041.0,"size":0.005}],"asks":[]}}}
{"schema_version":"collector.vnext.raw","schema_contract":null,"schema_contract_version":null,"payload_contract_version":null,"record_type":"market.orderbook.diff","record_id":"collector_main-market-orderbook-diff-000000000093","collector_id":"collector_main","collector_role":"production","host_name":"MAIN-PC","session_id":"collector_main-sess-20260314T201115Z-12e412ee","stream_session_id":"collector_main-stream-bitflyer-board_ws-20260314T201116Z-eb471dba","exchange":"bitflyer","market":"spot","symbol":"BTC_JPY","instrument_id":"bitflyer.spot.BTC_JPY","channel":"board_ws","transport":"websocket","source_event_id":null,"source_sequence":null,"sequence_id":93,"exchange_ts":null,"collector_ts":"2026-03-14T20:11:19Z","ingest_ts":"2026-03-14T20:11:19Z","event_ts":"2026-03-14T20:11:19Z","quality_flags":[],"is_partial":false,"is_reconstructed":false,"confidence_score":1.0,"payload":{"provider":"bitflyer_ws_board","exchange":"bitflyer","transport":"websocket","channel":"lightning_board_BTC_JPY","received_ts":"2026-03-14T20:11:19.173166Z","subscription_id":null,"message_id":null,"source_sequence":null,"raw_message_meta":{"raw_channel":"lightning_board_BTC_JPY","subscription_channel":"lightning_board_BTC_JPY","recv_timeout_sec":10,"ssl_verify":false,"socket_url":"wss://ws.lightstream.bitflyer.com/json-rpc"},"source_payload":{"mid_price":11305205.0,"bids":[{"price":11302075.0,"size":0.017694}],"asks":[]}}}
{"schema_version":"collector.vnext.raw","schema_contract":null,"schema_contract_version":null,"payload_contract_version":null,"record_type":"market.orderbook.diff","record_id":"collector_main-market-orderbook-diff-000000000095","collector_id":"collector_main","collector_role":"production","host_name":"MAIN-PC","session_id":"collector_main-sess-20260314T201115Z-12e412ee","stream_session_id":"collector_main-stream-bitflyer-board_ws-20260314T201116Z-eb471dba","exchange":"bitflyer","market":"spot","symbol":"BTC_JPY","instrument_id":"bitflyer.spot.BTC_JPY","channel":"board_ws","transport":"websocket","source_event_id":null,"source_sequence":null,"sequence_id":95,"exchange_ts":null,"collector_ts":"2026-03-14T20:11:19Z","ingest_ts":"2026-03-14T20:11:19Z","event_ts":"2026-03-14T20:11:19Z","quality_flags":[],"is_partial":false,"is_reconstructed":false,"confidence_score":1.0,"payload":{"provider":"bitflyer_ws_board","exchange":"bitflyer","transport":"websocket","channel":"lightning_board_BTC_JPY","received_ts":"2026-03-14T20:11:19.282329Z","subscription_id":null,"message_id":null,"source_sequence":null,"raw_message_meta":{"raw_channel":"lightning_board_BTC_JPY","subscription_channel":"lightning_board_BTC_JPY","recv_timeout_sec":10,"ssl_verify":false,"socket_url":"wss://ws.lightstream.bitflyer.com/json-rpc"},"source_payload":{"mid_price":11305205.0,"bids":[{"price":11245542.0,"size":0.002},{"price":11302703.0,"size":0.05487565}],"asks":[]}}}
{"schema_version":"collector.vnext.raw","schema_contract":null,"schema_contract_version":null,"payload_contract_version":null,"record_type":"market.orderbook.diff","record_id":"collector_main-market-orderbook-diff-000000000097","collector_id":"collector_main","collector_role":"production","host_name":"MAIN-PC","session_id":"collector_main-sess-20260314T201115Z-12e412ee","stream_session_id":"collector_main-stream-bitflyer-board_ws-20260314T201116Z-eb471dba","exchange":"bitflyer","market":"spot","symbol":"BTC_JPY","instrument_id":"bitflyer.spot.BTC_JPY","channel":"board_ws","transport":"websocket","source_event_id":null,"source_sequence":null,"sequence_id":97,"exchange_ts":null,"collector_ts":"2026-03-14T20:11:19Z","ingest_ts":"2026-03-14T20:11:19Z","event_ts":"2026-03-14T20:11:19Z","quality_flags":[],"is_partial":false,"is_reconstructed":false,"confidence_score":1.0,"payload":{"provider":"bitflyer_ws_board","exchange":"bitflyer","transport":"websocket","channel":"lightning_board_BTC_JPY","received_ts":"2026-03-14T20:11:19.811279Z","subscription_id":null,"message_id":null,"source_sequence":null,"raw_message_meta":{"raw_channel":"lightning_board_BTC_JPY","subscription_channel":"lightning_board_BTC_JPY","recv_timeout_sec":10,"ssl_verify":false,"socket_url":"wss://ws.lightstream.bitflyer.com/json-rpc"},"source_payload":{"mid_price":11305205.0,"bids":[{"price":11276638.0,"size":0.002}],"asks":[]}}}
{"schema_version":"collector.vnext.raw","schema_contract":null,"schema_contract_version":null,"payload_contract_version":null,"record_type":"market.orderbook.diff","record_id":"collector_main-market-orderbook-diff-000000000099","collector_id":"collector_main","collector_role":"production","host_name":"MAIN-PC","session_id":"collector_main-sess-20260314T201115Z-12e412ee","stream_session_id":"collector_main-stream-bitflyer-board_ws-20260314T201116Z-eb471dba","exchange":"bitflyer","market":"spot","symbol":"BTC_JPY","instrument_id":"bitflyer.spot.BTC_JPY","channel":"board_ws","transport":"websocket","source_event_id":null,"source_sequence":null,"sequence_id":99,"exchange_ts":null,"collector_ts":"2026-03-14T20:11:20Z","ingest_ts":"2026-03-14T20:11:20Z","event_ts":"2026-03-14T20:11:20Z","quality_flags":[],"is_partial":false,"is_reconstructed":false,"confidence_score":1.0,"payload":{"provider":"bitflyer_ws_board","exchange":"bitflyer","transport":"websocket","channel":"lightning_board_BTC_JPY","received_ts":"2026-03-14T20:11:20.377317Z","subscription_id":null,"message_id":null,"source_sequence":null,"raw_message_meta":{"raw_channel":"lightning_board_BTC_JPY","subscription_channel":"lightning_board_BTC_JPY","recv_timeout_sec":10,"ssl_verify":false,"socket_url":"wss://ws.lightstream.bitflyer.com/json-rpc"},"source_payload":{"mid_price":11305205.0,"bids":[{"price":11241019.0,"size":0.002}],"asks":[]}}}
{"schema_version":"collector.vnext.raw","schema_contract":null,"schema_contract_version":null,"payload_contract_version":null,"record_type":"market.orderbook.snapshot","record_id":"collector_main-market-orderbook-snapshot-000000000101","collector_id":"collector_main","collector_role":"production","host_name":"MAIN-PC","session_id":"collector_main-sess-20260314T201115Z-12e412ee","stream_session_id":"collector_main-stream-bitflyer-board_ws-20260314T201116Z-eb471dba","exchange":"bitflyer","market":"spot","symbol":"BTC_JPY","instrument_id":"bitflyer.spot.BTC_JPY","channel":"board_ws","transport":"websocket","source_event_id":null,"source_sequence":null,"sequence_id":101,"exchange_ts":null,"collector_ts":"2026-03-14T20:11:20Z","ingest_ts":"2026-03-14T20:11:20Z","event_ts":"2026-03-14T20:11:20Z","quality_flags":[],"is_partial":false,"is_reconstructed":false,"confidence_score":1.0,"payload":{"provider":"bitflyer_ws_board_snapshot","exchange":"bitflyer","transport":"websocket","channel":"lightning_board_snapshot_BTC_JPY","received_ts":"2026-03-14T20:11:20.906449Z","subscription_id":null,"message_id":null,"source_sequence":null,"raw_message_meta":{"raw_channel":"lightning_board_snapshot_BTC_JPY","subscription_channel":"lightning_board_snapshot_BTC_JPY","recv_timeout_sec":10,"ssl_verify":false,"socket_url":"wss://ws.lightstream.bitflyer.com/json-rpc"},"source_payload":{"mid_price":11305205.0,"bids":[{"price":11302703.0,"size":0.05487565},{"price":11302702.0,"size":0.00999866},{"price":11302075.0,"size":0.017694},{"price":11302041.0,"size":0.005},{"price":11302040.0,"size":0.1275},{"price":11301842.0,"size":0.1275},{"price":11301648.0,"size":0.015552},{"price":11300857.0,"size":0.02},{"price":11300856.0,"size":0.014976},{"price":11300798.0,"size":0.015336},{"price":11300429.0,"size":0.005},{"price":11300093.0,"size":0.02},{"price":11299290.0,"size":0.01},{"price":11298963.0,"size":0.02},{"price":11298579.0,"size":0.05},{"price":11298513.0,"size":0.05},{"price":11298070.0,"size":0.5},{"price":11297439.0,"size":0.5},{"price":11297290.0,"size":0.0531},{"price":11296625.0,"size":0.052056},{"price":11295884.0,"size":2.97444819},{"price":11295882.0,"size":0.6},{"price":11294489.0,"size":0.0013033},{"price":11294484.0,"size":0.00999859},{"price":11293270.0,"size":0.0801},{"price":11292244.0,"size":0.048},{"price":11289443.0,"size":0.04},{"price":11288470.0,"size":0.132},{"price":11287378.0,"size":1.50015},{"price":11286651.0,"size":0.98403398},{"price":11283324.0,"size":0.2665},{"price":11281726.0,"size":0.002},{"price":11280562.0,"size":0.3089},{"price":11280205.0,"size":0.001},{"price":11280030.0,"size":0.002},{"price":11279282.0,"size":0.0015},{"price":11277800.0,"size":0.2689},{"price":11277748.0,"size":0.0966561},{"price":11277602.0,"size":0.005},{"price":11277203.0,"size":0.002},{"price":11276638.0,"size":0.002},{"price":11275360.0,"size":1.484},{"price":11275103.0,"size":0.17894886},{"price":11275102.0,"size":0.01},{"price":11275038.0,"size":0.2726},{"price":11275000.0,"size":0.001},{"price":11274588.0,"size":0.0047},{"price":11272680.0,"size":0.002},{"price":11271711.0,"size":0.6},{"price":11271000.0,"size":0.003},{"price":11270000.0,"size":0.106},{"price":11268871.0,"size":0.281},{"price":11268411.0,"size":0.01},{"price":11268157.0,"size":0.002},{"price":11266666.0,"size":0.04},{"price":11265000.0,"size":0.02},{"price":11263999.0,"size":1.966},{"price":11263634.0,"size":0.002},{"price":11263000.0,"size":0.006},{"price":11262564.0,"size":0.0015},{"price":11260000.0,"size":0.3565},{"price":11259111.0,"size":0.002},{"price":11257537.0,"size":0.001},{"price":11257000.0,"size":0.001},{"price":11255200.0,"size":0.001},{"price":11255115.0,"size":0.00377},{"price":11254588.0,"size":0.002},{"price":11253000.0,"size":0.03189},{"price":11251000.0,"size":0.0131},{"price":11250250.0,"size":0.00105},{"price":11250200.0,"size":0.001},{"price":11250100.0,"size":0.015},{"price":11250065.0,"size":0.002},{"price":11250005.0,"size":0.001},{"price":11250001.0,"size":0.00104},{"price":11250000.0,"size":0.76834},{"price":11246544.0,"size":0.0015},{"price":11246203.0,"size":0.001},{"price":11245542.0,"size":0.002},{"price":11245141.0,"size":0.0031},{"price":11245000.0,"size":0.05},{"price":11244444.0,"size":0.04},{"price":11244243.0,"size":0.01},{"price":11241019.0,"size":0.002},{"price":11240200.0,"size":0.001},{"price":11240000.0,"size":0.007304},{"price":11236190.0,"size":0.01},{"price":11235200.0,"size":0.001},{"price":11234869.0,"size":0.001},{"price":11233345.0,"size":2.036},{"price":11232000.0,"size":0.089},{"price":11231243.0,"size":0.01},{"price":11231000.0,"size":0.105},{"price":11230200.0,"size":0.001},{"price":11230000.0,"size":0.0308},{"price":11228423.0,"size":1.951},{"price":11224500.0,"size":0.06},{"price":11224355.0,"size":0.0015},{"price":11223968.0,"size":0.001},{"price":11223535.0,"size":0.001},{"price":11223344.0,"size":0.01},{"price":11223000.0,"size":0.1},{"price":11222222.0,"size":0.092525},{"price":11221459.0,"size":0.1393},{"price":11221120.0,"size":0.011},{"price":11220200.0,"size":0.001},{"price":11220001.0,"size":0.004457},{"price":11220000.0,"size":0.321},{"price":11219517.0,"size":0.01},{"price":11219000.0,"size":0.1},{"price":11215200.0,"size":0.001},{"price":11215000.0,"size":0.02},{"price":11212358.0,"size":1.2},{"price":11212201.0,"size":0.001},{"price":11211800.0,"size":0.001},{"price":11211111.0,"size":0.06},{"price":11210200.0,"size":0.001},{"price":11210000.0,"size":0.10622},{"price":11208032.0,"size":0.01},{"price":11207755.0,"size":0.0015},{"price":11206000.0,"size":0.09015},{"price":11205200.0,"size":0.001},{"price":11204578.0,"size":0.002},{"price":11203931.0,"size":1.0},{"price":11201000.0,"size":0.01},{"price":11200867.0,"size":0.001},{"price":11200800.0,"size":0.05},{"price":11200425.0,"size":0.1},{"price":11200200.0,"size":0.001},{"price":11200198.0,"size":0.003},{"price":11200150.0,"size":0.002},{"price":11200002.0,"size":0.001},{"price":11200001.0,"size":0.01104},{"price":11200000.0,"size":1.35988728},{"price":11198508.0,"size":0.05},{"price":11198243.0,"size":0.01},{"price":11197134.0,"size":2.0},{"price":11197000.0,"size":0.0085},{"price":11195692.0,"size":0.0015},{"price":11194090.0,"size":0.03},{"price":11190770.0,"size":0.0309},{"price":11190000.0,"size":0.0010016},{"price":11189555.0,"size":0.5},{"price":11189533.0,"size":0.001},{"price":11188629.0,"size":0.01},{"price":11188382.0,"size":0.001},{"price":11185000.0,"size":0.0085},{"price":11180043.0,"size":0.972},{"price":11180000.0,"size":0.23215},{"price":11178973.0,"size":0.0015},{"price":11178199.0,"size":0.001},{"price":11170000.0,"size":0.001},{"price":11169662.0,"size":0.01},{"price":11169593.0,"size":0.001},{"price":11169243.0,"size":0.01},{"price":11166865.0,"size":0.001},{"price":11164029.0,"size":0.001},{"price":11160854.0,"size":0.1},{"price":11160000.0,"size":0.02376},{"price":11156269.0,"size":0.01},{"price":11155531.0,"size":0.001},{"price":11155377.0,"size":0.00636009},{"price":11153999.0,"size":0.00101},{"price":11150250.0,"size":0.00175},{"price":11150005.0,"size":0.001},{"price":11150001.0,"size":0.00104},{"price":11150000.0,"size":0.6398956},{"price":11148000.0,"size":0.08963},{"price":11144197.0,"size":0.001},{"price":11144000.0,"size":0.0897},{"price":11140000.0,"size":0.2},{"price":11136243.0,"size":0.01},{"price":11136155.0,"size":0.02},{"price":11135869.0,"size":0.1},{"price":11130000.0,"size":0.116},{"price":11129979.0,"size":0.0053908},{"price":11126388.0,"size":0.02},{"price":11124900.0,"size":0.00133},{"price":11121090.0,"size":0.1},{"price":11120000.0,"size":0.0033},{"price":11118078.0,"size":0.01},{"price":11111800.0,"size":0.001},{"price":11111111.0,"size":0.2919257},{"price":11111000.0,"size":0.003},{"price":11110594.0,"size":0.001},{"price":11110000.0,"size":0.056937},{"price":11109662.0,"size":0.01},{"price":11108008.0,"size":0.01},{"price":11106000.0,"size":0.2},{"price":11105000.0,"size":0.02},{"price":11101297.0,"size":0.001},{"price":11100005.0,"size":0.001},{"price":11100001.0,"size":0.01104},{"price":11100000.0,"size":2.7475049},{"price":11099141.0,"size":0.01},{"price":11096243.0,"size":0.01},{"price":11094090.0,"size":0.01},{"price":11088888.0,"size":0.001},{"price":11085245.0,"size":0.001},{"price":11080200.0,"size":0.001},{"price":11080000.0,"size":0.0223},{"price":11075100.0,"size":0.003},{"price":11071558.0,"size":1.0},{"price":11070200.0,"size":0.001},{"price":11070000.0,"size":0.0902},{"price":11065200.0,"size":0.001},{"price":11064370.0,"size":0.00497091},{"price":11060200.0,"size":0.001},{"price":11060000.0,"size":0.145},{"price":11059689.0,"size":0.009},{"price":11056428.0,"size":0.002},{"price":11055500.0,"size":0.02},{"price":11055200.0,"size":0.001},{"price":11055100.0,"size":0.003},{"price":11050200.0,"size":0.001},{"price":11050005.0,"size":0.001},{"price":11050002.0,"size":0.001},{"price":11050001.0,"size":0.00104},{"price":11050000.0,"size":0.43176147},{"price":11046420.0,"size":0.2},{"price":11044243.0,"size":0.01},{"price":11041380.0,"size":0.01},{"price":11040200.0,"size":0.001},{"price":11040000.0,"size":0.00777181},{"price":11035865.0,"size":0.1},{"price":11035200.0,"size":0.001},{"price":11035000.0,"size":0.0013},{"price":11030200.0,"size":0.001},{"price":11030000.0,"size":0.025},{"price":11025500.0,"size":0.009531},{"price":11025200.0,"size":0.001},{"price":11025000.0,"size":0.71497},{"price":11020772.0,"size":0.014},{"price":11020200.0,"size":0.002},{"price":11020000.0,"size":0.005},{"price":11015200.0,"size":0.001},{"price":11012000.0,"size":0.1},{"price":11011800.0,"size":0.001},{"price":11010200.0,"size":0.001},{"price":11010000.0,"size":0.347},{"price":11007277.0,"size":0.01},{"price":11006000.0,"size":0.2},{"price":11005200.0,"size":0.001},{"price":11004890.0,"size":0.001535},{"price":11003000.0,"size":0.0155},{"price":11001000.0,"size":0.013},{"price":11000500.0,"size":0.05117658},{"price":11000200.0,"size":0.001},{"price":11000002.0,"size":0.004},{"price":11000001.0,"size":0.02604},{"price":11000000.0,"size":5.47323365},{"price":10999999.0,"size":0.003},{"price":10999000.0,"size":0.001},{"price":10996855.0,"size":0.0011},{"price":10995200.0,"size":0.001},{"price":10994499.0,"size":0.00169176},{"price":10990200.0,"size":0.001},{"price":10990000.0,"size":0.10219},{"price":10989001.0,"size":0.00197},{"price":10988999.0,"size":0.001},{"price":10988324.0,"size":0.002},{"price":10987654.0,"size":0.001},{"price":10985200.0,"size":0.001},{"price":10985150.0,"size":0.01},{"price":10980500.0,"size":0.005},{"price":10980200.0,"size":0.001},{"price":10980002.0,"size":0.4},{"price":10980000.0,"size":0.028},{"price":10975200.0,"size":0.001},{"price":10975000.0,"size":0.1},{"price":10971261.0,"size":0.001},{"price":10971243.0,"size":0.01},{"price":10970375.0,"size":1.9},{"price":10970200.0,"size":0.001},{"price":10970000.0,"size":0.09304},{"price":10966600.0,"size":0.001003},{"price":10965200.0,"size":0.001},{"price":10960200.0,"size":0.001},{"price":10960000.0,"size":0.0083},{"price":10956673.0,"size":0.01},{"price":10955200.0,"size":0.001},{"price":10954950.0,"size":0.001},{"price":10950500.0,"size":0.005},{"price":10950001.0,"size":0.00204},{"price":10950000.0,"size":0.5485028},{"price":10949550.0,"size":0.01870657},{"price":10949172.0,"size":0.1},{"price":10948000.0,"size":0.1},{"price":10945243.0,"size":0.01},{"price":10940402.0,"size":0.001},{"price":10940200.0,"size":0.001},{"price":10940000.0,"size":0.331},{"price":10938243.0,"size":0.01},{"price":10936200.0,"size":0.00137},{"price":10935200.0,"size":0.001},{"price":10930200.0,"size":0.002},{"price":10930000.0,"size":0.0193},{"price":10925200.0,"size":0.002},{"price":10924451.0,"size":0.0012},{"price":10920509.0,"size":0.01}],"asks":[{"price":11307708.0,"size":0.1793},{"price":11308864.0,"size":0.04636061},{"price":11308865.0,"size":0.02},{"price":11308866.0,"size":0.005},{"price":11308930.0,"size":0.02},{"price":11309329.0,"size":0.02},{"price":11310444.0,"size":0.02},{"price":11311005.0,"size":0.02},{"price":11311006.0,"size":0.2778},{"price":11311681.0,"size":0.015492},{"price":11312048.0,"size":0.01506},{"price":11312719.0,"size":0.02},{"price":11312720.0,"size":0.4199},{"price":11313584.0,"size":0.052056},{"price":11313658.0,"size":0.01},{"price":11313768.0,"size":0.258},{"price":11313957.0,"size":0.014772},{"price":11315343.0,"size":0.57612746},{"price":11316530.0,"size":0.2806},{"price":11318050.0,"size":0.002},{"price":11318640.0,"size":0.01},{"price":11318849.0,"size":0.053},{"price":11319292.0,"size":0.3099},{"price":11320000.0,"size":0.02},{"price":11320994.0,"size":0.15},{"price":11322000.0,"size":0.005},{"price":11323556.0,"size":1.189881},{"price":11323581.0,"size":1.189881},{"price":11325034.0,"size":0.0128337},{"price":11328050.0,"size":0.002},{"price":11329436.0,"size":0.0015},{"price":11331059.0,"size":0.001},{"price":11334237.0,"size":1.489},{"price":11335742.0,"size":1.928},{"price":11340000.0,"size":0.13586406},{"price":11340647.0,"size":0.001},{"price":11342956.0,"size":1.60199848},{"price":11342957.0,"size":0.01},{"price":11346154.0,"size":0.0015},{"price":11348000.0,"size":0.1999},{"price":11349700.0,"size":0.001},{"price":11350000.0,"size":0.022},{"price":11353877.0,"size":0.001},{"price":11354939.0,"size":0.01},{"price":11355555.0,"size":0.001},{"price":11358323.0,"size":2.018},{"price":11359242.0,"size":0.0011},{"price":11359700.0,"size":0.001},{"price":11362692.0,"size":0.0015},{"price":11365211.0,"size":0.001},{"price":11369700.0,"size":0.001},{"price":11370000.0,"size":0.1},{"price":11372478.0,"size":1.943},{"price":11376000.0,"size":0.02},{"price":11376545.0,"size":0.001},{"price":11377000.0,"size":0.2287},{"price":11377269.0,"size":0.002},{"price":11379700.0,"size":0.001},{"price":11379865.0,"size":0.03},{"price":11380000.0,"size":0.0223},{"price":11380324.0,"size":0.002},{"price":11381766.0,"size":0.4},{"price":11382386.0,"size":0.0015},{"price":11385000.0,"size":0.2548},{"price":11385403.0,"size":0.002},{"price":11385664.0,"size":0.002},{"price":11387072.0,"size":0.01},{"price":11387354.0,"size":0.002},{"price":11387879.0,"size":0.001},{"price":11388885.0,"size":0.03},{"price":11389700.0,"size":0.001},{"price":11390000.0,"size":0.2488},{"price":11390050.0,"size":0.001},{"price":11392387.0,"size":1.0},{"price":11394939.0,"size":0.01},{"price":11395000.0,"size":0.06},{"price":11395775.0,"size":0.01},{"price":11396555.0,"size":0.03},{"price":11398444.0,"size":0.001995},{"price":11399213.0,"size":0.001},{"price":11399673.0,"size":0.0015},{"price":11399700.0,"size":0.001},{"price":11400000.0,"size":0.5525},{"price":11405000.0,"size":0.0275},{"price":11406336.0,"size":1.0},{"price":11408700.0,"size":0.001},{"price":11409415.0,"size":0.055},{"price":11410000.0,"size":0.03},{"price":11410547.0,"size":0.001},{"price":11410853.0,"size":0.002},{"price":11412000.0,"size":0.0878},{"price":11415000.0,"size":0.002},{"price":11415141.0,"size":0.0041},{"price":11417481.0,"size":0.0015},{"price":11418700.0,"size":0.001},{"price":11420000.0,"size":0.401},{"price":11421268.0,"size":0.05},{"price":11421881.0,"size":0.001},{"price":11423339.0,"size":2.0},{"price":11424296.0,"size":0.002},{"price":11424941.0,"size":0.972},{"price":11425000.0,"size":0.049},{"price":11426426.0,"size":0.002},{"price":11428121.0,"size":0.002},{"price":11428700.0,"size":0.001},{"price":11429302.0,"size":0.01},{"price":11432718.0,"size":0.002},{"price":11433211.0,"size":0.03},{"price":11433215.0,"size":0.001},{"price":11433333.0,"size":0.001},{"price":11437315.0,"size":0.002},{"price":11438525.0,"size":0.0011},{"price":11438700.0,"size":0.001},{"price":11439557.0,"size":0.001},{"price":11440000.0,"size":0.1038},{"price":11441911.0,"size":0.002},{"price":11443629.0,"size":0.002},{"price":11444549.0,"size":0.001},{"price":11446508.0,"size":0.001},{"price":11447000.0,"size":0.01},{"price":11447071.0,"size":0.002},{"price":11448000.0,"size":0.0875},{"price":11448700.0,"size":0.001},{"price":11450000.0,"size":0.258},{"price":11451105.0,"size":0.002},{"price":11453321.0,"size":0.03},{"price":11455702.0,"size":0.002},{"price":11455883.0,"size":0.001},{"price":11458700.0,"size":0.001},{"price":11458988.0,"size":0.01},{"price":11460000.0,"size":0.01702},{"price":11460299.0,"size":0.002},{"price":11464896.0,"size":0.002},{"price":11467217.0,"size":0.001},{"price":11468700.0,"size":0.001},{"price":11470000.0,"size":0.01},{"price":11471000.0,"size":0.01},{"price":11475000.0,"size":0.0028},{"price":11478431.0,"size":0.002},{"price":11478551.0,"size":0.001},{"price":11478700.0,"size":0.001},{"price":11480000.0,"size":0.12491},{"price":11485000.0,"size":0.01},{"price":11486555.0,"size":0.03},{"price":11487685.0,"size":0.01},{"price":11488000.0,"size":0.102},{"price":11488700.0,"size":0.001},{"price":11489885.0,"size":0.001},{"price":11490841.0,"size":0.002},{"price":11495450.0,"size":0.002},{"price":11495850.0,"size":0.001},{"price":11498700.0,"size":0.001},{"price":11498917.0,"size":0.002},{"price":11499000.0,"size":0.01},{"price":11500000.0,"size":0.46859519},{"price":11501219.0,"size":0.001},{"price":11502377.0,"size":0.002},{"price":11502800.0,"size":0.00132},{"price":11503108.0,"size":0.0198},{"price":11505000.0,"size":0.0028},{"price":11505001.0,"size":0.002},{"price":11505836.0,"size":0.003},{"price":11508431.0,"size":0.047},{"price":11508700.0,"size":0.001},{"price":11508888.0,"size":0.02},{"price":11510000.0,"size":0.0976},{"price":11512553.0,"size":0.001},{"price":11513633.0,"size":0.08},{"price":11514332.0,"size":0.02},{"price":11518700.0,"size":0.001},{"price":11518992.0,"size":0.002},{"price":11519855.0,"size":0.01},{"price":11520000.0,"size":0.001},{"price":11522423.0,"size":0.97},{"price":11523211.0,"size":0.01},{"price":11523887.0,"size":0.001},{"price":11524999.0,"size":0.001},{"price":11528700.0,"size":0.001},{"price":11529852.0,"size":0.01},{"price":11530000.0,"size":0.261},{"price":11533985.0,"size":0.002},{"price":11534084.0,"size":0.001},{"price":11535321.0,"size":0.01},{"price":11538666.0,"size":0.002},{"price":11538700.0,"size":0.001},{"price":11540000.0,"size":0.0048},{"price":11540357.0,"size":0.002},{"price":11541011.0,"size":0.005},{"price":11541109.0,"size":0.01},{"price":11544663.0,"size":0.002},{"price":11545262.0,"size":0.002},{"price":11546541.0,"size":0.01},{"price":11548144.0,"size":0.002},{"price":11548700.0,"size":0.001},{"price":11550000.0,"size":0.014},{"price":11551109.0,"size":0.01},{"price":11551625.0,"size":0.002},{"price":11552111.0,"size":0.01},{"price":11553687.0,"size":0.1},{"price":11555106.0,"size":0.002},{"price":11555115.0,"size":0.001},{"price":11556000.0,"size":0.1},{"price":11558587.0,"size":0.002},{"price":11558700.0,"size":0.001},{"price":11559855.0,"size":0.01},{"price":11560831.0,"size":0.0198},{"price":11561109.0,"size":0.01},{"price":11562000.0,"size":0.087},{"price":11562068.0,"size":0.002},{"price":11565548.0,"size":0.002},{"price":11566139.0,"size":0.0228},{"price":11566551.0,"size":0.01},{"price":11568700.0,"size":0.001},{"price":11569029.0,"size":0.002},{"price":11570196.0,"size":0.002},{"price":11571109.0,"size":0.01},{"price":11572510.0,"size":0.002},{"price":11573211.0,"size":0.01},{"price":11574840.0,"size":0.002},{"price":11575991.0,"size":0.001},{"price":11578700.0,"size":0.001},{"price":11579484.0,"size":0.002},{"price":11579851.0,"size":0.01},{"price":11580000.0,"size":0.7735},{"price":11581109.0,"size":0.01},{"price":11584128.0,"size":0.002},{"price":11585000.0,"size":0.002},{"price":11586532.0,"size":0.01},{"price":11587498.0,"size":0.0198},{"price":11588700.0,"size":0.001},{"price":11589612.0,"size":0.012},{"price":11590000.0,"size":0.1},{"price":11590749.0,"size":0.002},{"price":11591109.0,"size":0.01},{"price":11593211.0,"size":0.01},{"price":11596753.0,"size":0.002},{"price":11598555.0,"size":0.01},{"price":11598700.0,"size":0.001},{"price":11599999.0,"size":0.001},{"price":11600000.0,"size":3.6141},{"price":11601109.0,"size":0.02},{"price":11606655.0,"size":0.01},{"price":11610000.0,"size":0.302},{"price":11611109.0,"size":0.01},{"price":11613321.0,"size":0.01},{"price":11620000.0,"size":1.35441682},{"price":11621011.0,"size":0.01},{"price":11621109.0,"size":0.01},{"price":11623096.0,"size":0.008},{"price":11629000.0,"size":0.1},{"price":11630000.0,"size":0.201},{"price":11631059.0,"size":0.01},{"price":11631479.0,"size":0.01},{"price":11631773.0,"size":0.00386871},{"price":11635950.0,"size":0.001},{"price":11638259.0,"size":0.001},{"price":11639700.0,"size":0.001},{"price":11640000.0,"size":1.0},{"price":11640820.0,"size":0.01},{"price":11641651.0,"size":2.0},{"price":11645295.0,"size":0.05},{"price":11647158.0,"size":0.05},{"price":11649900.0,"size":0.02906},{"price":11649999.0,"size":0.001},{"price":11650000.0,"size":0.593},{"price":11651059.0,"size":0.01},{"price":11653658.0,"size":0.008},{"price":11654321.0,"size":0.001},{"price":11659700.0,"size":0.001},{"price":11661479.0,"size":0.01},{"price":11666000.0,"size":0.001},{"price":11666666.0,"size":0.013},{"price":11669700.0,"size":0.001},{"price":11671059.0,"size":0.01},{"price":11672562.0,"size":0.0198},{"price":11679224.0,"size":0.012},{"price":11680000.0,"size":0.004},{"price":11685000.0,"size":0.003},{"price":11688000.0,"size":0.001},{"price":11689732.0,"size":0.01},{"price":11690330.0,"size":0.0198},{"price":11691059.0,"size":0.01},{"price":11692558.0,"size":0.01},{"price":11698800.0,"size":0.00131},{"price":11699000.0,"size":0.001},{"price":11699631.0,"size":0.001},{"price":11699998.0,"size":0.01},{"price":11699999.0,"size":0.001},{"price":11700000.0,"size":1.03762841},{"price":11701059.0,"size":0.01},{"price":11720000.0,"size":0.1},{"price":11721059.0,"size":0.01},{"price":11725000.0,"size":0.005},{"price":11726791.0,"size":0.01},{"price":11730000.0,"size":0.9382},{"price":11740000.0,"size":0.101},{"price":11741059.0,"size":0.01},{"price":11745417.0,"size":2.0},{"price":11748937.0,"size":0.001},{"price":11749999.0,"size":0.001}]}}}
{"schema_version":"collector.vnext.raw","schema_contract":null,"schema_contract_version":null,"payload_contract_version":null,"record_type":"market.orderbook.snapshot","record_id":"collector_main-market-orderbook-snapshot-000000000061","collector_id":"collector_main","collector_role":"production","host_name":"MAIN-PC","session_id":"collector_main-sess-20260314T201135Z-e7f01376","stream_session_id":"collector_main-stream-bitflyer-board_ws-20260314T201145Z-dce12e93","exchange":"bitflyer","market":"spot","symbol":"BTC_JPY","instrument_id":"bitflyer.spot.BTC_JPY","channel":"board_ws","transport":"websocket","source_event_id":null,"source_sequence":null,"sequence_id":61,"exchange_ts":null,"collector_ts":"2026-03-14T20:11:45Z","ingest_ts":"2026-03-14T20:11:45Z","event_ts":"2026-03-14T20:11:45Z","quality_flags":[],"is_partial":false,"is_reconstructed":false,"confidence_score":1.0,"payload":{"provider":"bitflyer_ws_board_snapshot","exchange":"bitflyer","transport":"websocket","channel":"lightning_board_snapshot_BTC_JPY","received_ts":"2026-03-14T20:11:45.929310Z","subscription_id":null,"message_id":null,"source_sequence":null,"raw_message_meta":{"raw_channel":"lightning_board_snapshot_BTC_JPY","subscription_channel":"lightning_board_snapshot_BTC_JPY","recv_timeout_sec":10,"ssl_verify":false,"socket_url":"wss://ws.lightstream.bitflyer.com/json-rpc"},"source_payload":{"mid_price":11304979.0,"bids":[{"price":11302627.0,"size":0.07665499},{"price":11302626.0,"size":0.1275},{"price":11302443.0,"size":0.1275},{"price":11302078.0,"size":0.005},{"price":11301991.0,"size":0.00999866},{"price":11301649.0,"size":0.02},{"price":11301648.0,"size":0.015552},{"price":11300857.0,"size":0.02},{"price":11300856.0,"size":0.014976},{"price":11300799.0,"size":0.02},{"price":11300798.0,"size":0.015336},{"price":11300681.0,"size":0.02},{"price":11300680.0,"size":0.2},{"price":11299290.0,"size":0.01},{"price":11298579.0,"size":0.05},{"price":11298513.0,"size":0.05},{"price":11298070.0,"size":0.5},{"price":11297439.0,"size":0.5},{"price":11297290.0,"size":0.0531},{"price":11296625.0,"size":0.052056},{"price":11296054.0,"size":2.97428671},{"price":11295882.0,"size":0.6},{"price":11294740.0,"size":0.003041},{"price":11293270.0,"size":0.0801},{"price":11293110.0,"size":0.00999859},{"price":11292244.0,"size":0.048},{"price":11289443.0,"size":0.04},{"price":11288470.0,"size":0.132},{"price":11287378.0,"size":1.50015},{"price":11286651.0,"size":0.98403398},{"price":11283324.0,"size":0.2665},{"price":11281726.0,"size":0.002},{"price":11280562.0,"size":0.3089},{"price":11280205.0,"size":0.001},{"price":11280030.0,"size":0.002},{"price":11279282.0,"size":0.0015},{"price":11277800.0,"size":0.2689},{"price":11277748.0,"size":0.0966561},{"price":11277602.0,"size":0.005},{"price":11277203.0,"size":0.002},{"price":11276638.0,"size":0.002},{"price":11275360.0,"size":1.484},{"price":11275103.0,"size":0.17894886},{"price":11275102.0,"size":0.01},{"price":11275038.0,"size":0.2726},{"price":11275000.0,"size":0.001},{"price":11274588.0,"size":0.0047},{"price":11273246.0,"size":0.002},{"price":11272680.0,"size":0.002},{"price":11271711.0,"size":0.6},{"price":11271000.0,"size":0.003},{"price":11270000.0,"size":0.106},{"price":11269854.0,"size":0.002},{"price":11268871.0,"size":0.281},{"price":11268411.0,"size":0.01},{"price":11268157.0,"size":0.002},{"price":11266666.0,"size":0.04},{"price":11266462.0,"size":0.002},{"price":11265000.0,"size":0.02},{"price":11263999.0,"size":1.966},{"price":11263634.0,"size":0.002},{"price":11263070.0,"size":0.002},{"price":11263000.0,"size":0.006},{"price":11262564.0,"size":0.0015},{"price":11260000.0,"size":0.3565},{"price":11259678.0,"size":0.002},{"price":11259111.0,"size":0.002},{"price":11257537.0,"size":0.001},{"price":11257000.0,"size":0.001},{"price":11256286.0,"size":0.002},{"price":11255200.0,"size":0.001},{"price":11255115.0,"size":0.00377},{"price":11254588.0,"size":0.002},{"price":11253000.0,"size":0.03189},{"price":11252894.0,"size":0.002},{"price":11251000.0,"size":0.0131},{"price":11250250.0,"size":0.00105},{"price":11250200.0,"size":0.001},{"price":11250100.0,"size":0.015},{"price":11250065.0,"size":0.002},{"price":11250005.0,"size":0.001},{"price":11250001.0,"size":0.00104},{"price":11250000.0,"size":0.76834},{"price":11249502.0,"size":0.002},{"price":11248205.0,"size":1.79},{"price":11246544.0,"size":0.0015},{"price":11246203.0,"size":0.001},{"price":11245542.0,"size":0.002},{"price":11245141.0,"size":0.0031},{"price":11245000.0,"size":0.05},{"price":11244444.0,"size":0.04},{"price":11244243.0,"size":0.01},{"price":11241019.0,"size":0.002},{"price":11240200.0,"size":0.001},{"price":11240000.0,"size":0.007304},{"price":11236190.0,"size":0.01},{"price":11235200.0,"size":0.001},{"price":11234869.0,"size":0.001},{"price":11233345.0,"size":2.036},{"price":11232000.0,"size":0.089},{"price":11231243.0,"size":0.01},{"price":11231000.0,"size":0.105},{"price":11230200.0,"size":0.001},{"price":11230000.0,"size":0.0308},{"price":11228423.0,"size":1.951},{"price":11224500.0,"size":0.06},{"price":11224355.0,"size":0.0015},{"price":11223968.0,"size":0.001},{"price":11223535.0,"size":0.001},{"price":11223344.0,"size":0.01},{"price":11223000.0,"size":0.1},{"price":11222222.0,"size":0.092525},{"price":11221459.0,"size":0.1393},{"price":11221120.0,"size":0.011},{"price":11220200.0,"size":0.001},{"price":11220001.0,"size":0.004457},{"price":11220000.0,"size":0.321},{"price":11219517.0,"size":0.01},{"price":11219000.0,"size":0.1},{"price":11215200.0,"size":0.001},{"price":11215000.0,"size":0.02},{"price":11212358.0,"size":1.2},{"price":11212201.0,"size":0.001},{"price":11211800.0,"size":0.001},{"price":11211111.0,"size":0.06},{"price":11210200.0,"size":0.001},{"price":11210000.0,"size":0.10622},{"price":11208032.0,"size":0.01},{"price":11207755.0,"size":0.0015},{"price":11206000.0,"size":0.09015},{"price":11205200.0,"size":0.001},{"price":11204578.0,"size":0.002},{"price":11203931.0,"size":1.0},{"price":11201000.0,"size":0.01},{"price":11200867.0,"size":0.001},{"price":11200800.0,"size":0.05},{"price":11200425.0,"size":0.1},{"price":11200200.0,"size":0.001},{"price":11200198.0,"size":0.003},{"price":11200150.0,"size":0.002},{"price":11200002.0,"size":0.001},{"price":11200001.0,"size":0.01104},{"price":11200000.0,"size":1.35988728},{"price":11198508.0,"size":0.05},{"price":11198243.0,"size":0.01},{"price":11197134.0,"size":2.0},{"price":11197000.0,"size":0.0085},{"price":11195692.0,"size":0.0015},{"price":11194090.0,"size":0.03},{"price":11190770.0,"size":0.0309},{"price":11190000.0,"size":0.0010016},{"price":11189555.0,"size":0.5},{"price":11189533.0,"size":0.001},{"price":11188629.0,"size":0.01},{"price":11188382.0,"size":0.001},{"price":11185000.0,"size":0.0085},{"price":11180043.0,"size":0.972},{"price":11180000.0,"size":0.23215},{"price":11178973.0,"size":0.0015},{"price":11178199.0,"size":0.001},{"price":11170000.0,"size":0.001},{"price":11169662.0,"size":0.01},{"price":11169593.0,"size":0.001},{"price":11169243.0,"size":0.01},{"price":11166865.0,"size":0.001},{"price":11164029.0,"size":0.001},{"price":11160854.0,"size":0.1},{"price":11160000.0,"size":0.02376},{"price":11156269.0,"size":0.01},{"price":11155531.0,"size":0.001},{"price":11155377.0,"size":0.00636009},{"price":11153999.0,"size":0.00101},{"price":11150250.0,"size":0.00175},{"price":11150005.0,"size":0.001},{"price":11150001.0,"size":0.00104},{"price":11150000.0,"size":0.6398956},{"price":11148000.0,"size":0.08963},{"price":11144197.0,"size":0.001},{"price":11144000.0,"size":0.0897},{"price":11140000.0,"size":0.2},{"price":11136243.0,"size":0.01},{"price":11136155.0,"size":0.02},{"price":11135869.0,"size":0.1},{"price":11130000.0,"size":0.116},{"price":11129979.0,"size":0.0053908},{"price":11126388.0,"size":0.02},{"price":11124900.0,"size":0.00133},{"price":11121090.0,"size":0.1},{"price":11120000.0,"size":0.0033},{"price":11118078.0,"size":0.01},{"price":11111800.0,"size":0.001},{"price":11111111.0,"size":0.2919257},{"price":11111000.0,"size":0.003},{"price":11110594.0,"size":0.001},{"price":11110000.0,"size":0.056937},{"price":11109662.0,"size":0.01},{"price":11108008.0,"size":0.01},{"price":11106000.0,"size":0.2},{"price":11105000.0,"size":0.02},{"price":11101297.0,"size":0.001},{"price":11100005.0,"size":0.001},{"price":11100001.0,"size":0.01104},{"price":11100000.0,"size":2.7475049},{"price":11099141.0,"size":0.01},{"price":11096243.0,"size":0.01},{"price":11094090.0,"size":0.01},{"price":11088888.0,"size":0.001},{"price":11085245.0,"size":0.001},{"price":11080200.0,"size":0.001},{"price":11080000.0,"size":0.0223},{"price":11075100.0,"size":0.003},{"price":11071558.0,"size":1.0},{"price":11070200.0,"size":0.001},{"price":11070000.0,"size":0.0902},{"price":11065200.0,"size":0.001},{"price":11064370.0,"size":0.00497091},{"price":11060200.0,"size":0.001},{"price":11060000.0,"size":0.145},{"price":11059689.0,"size":0.009},{"price":11056428.0,"size":0.002},{"price":11055500.0,"size":0.02},{"price":11055200.0,"size":0.001},{"price":11055100.0,"size":0.003},{"price":11050200.0,"size":0.001},{"price":11050005.0,"size":0.001},{"price":11050002.0,"size":0.001},{"price":11050001.0,"size":0.00104},{"price":11050000.0,"size":0.43176147},{"price":11046420.0,"size":0.2},{"price":11044243.0,"size":0.01},{"price":11041380.0,"size":0.01},{"price":11040200.0,"size":0.001},{"price":11040000.0,"size":0.00777181},{"price":11035865.0,"size":0.1},{"price":11035200.0,"size":0.001},{"price":11035000.0,"size":0.0013},{"price":11030200.0,"size":0.001},{"price":11030000.0,"size":0.025},{"price":11025500.0,"size":0.009531},{"price":11025200.0,"size":0.001},{"price":11025000.0,"size":0.71497},{"price":11020772.0,"size":0.014},{"price":11020200.0,"size":0.002},{"price":11020000.0,"size":0.005},{"price":11015200.0,"size":0.001},{"price":11012000.0,"size":0.1},{"price":11011800.0,"size":0.001},{"price":11010200.0,"size":0.001},{"price":11010000.0,"size":0.347},{"price":11007277.0,"size":0.01},{"price":11006000.0,"size":0.2},{"price":11005200.0,"size":0.001},{"price":11004890.0,"size":0.001535},{"price":11003000.0,"size":0.0155},{"price":11001000.0,"size":0.013},{"price":11000500.0,"size":0.05117658},{"price":11000200.0,"size":0.001},{"price":11000002.0,"size":0.004},{"price":11000001.0,"size":0.02604},{"price":11000000.0,"size":5.47323365},{"price":10999999.0,"size":0.003},{"price":10999000.0,"size":0.001},{"price":10996855.0,"size":0.0011},{"price":10995200.0,"size":0.001},{"price":10994499.0,"size":0.00169176},{"price":10990200.0,"size":0.001},{"price":10990000.0,"size":0.10219},{"price":10989001.0,"size":0.00197},{"price":10988999.0,"size":0.001},{"price":10988324.0,"size":0.002},{"price":10987654.0,"size":0.001},{"price":10985200.0,"size":0.001},{"price":10985150.0,"size":0.01},{"price":10980500.0,"size":0.005},{"price":10980200.0,"size":0.001},{"price":10980002.0,"size":0.4},{"price":10980000.0,"size":0.028},{"price":10975200.0,"size":0.001},{"price":10975000.0,"size":0.1},{"price":10971261.0,"size":0.001},{"price":10971243.0,"size":0.01},{"price":10970375.0,"size":1.9},{"price":10970200.0,"size":0.001},{"price":10970000.0,"size":0.09304},{"price":10966600.0,"size":0.001003},{"price":10965200.0,"size":0.001},{"price":10960200.0,"size":0.001},{"price":10960000.0,"size":0.0083},{"price":10956673.0,"size":0.01},{"price":10955200.0,"size":0.001},{"price":10954950.0,"size":0.001},{"price":10950500.0,"size":0.005},{"price":10950001.0,"size":0.00204},{"price":10950000.0,"size":0.5485028},{"price":10949550.0,"size":0.01870657},{"price":10949172.0,"size":0.1},{"price":10948000.0,"size":0.1},{"price":10945243.0,"size":0.01},{"price":10940402.0,"size":0.001},{"price":10940200.0,"size":0.001}],"asks":[{"price":11307331.0,"size":0.06751272},{"price":11308197.0,"size":0.04500085},{"price":11308198.0,"size":0.01000118},{"price":11308930.0,"size":0.02},{"price":11309329.0,"size":0.02},{"price":11310157.0,"size":0.1275},{"price":11310444.0,"size":0.02},{"price":11311005.0,"size":0.02},{"price":11311006.0,"size":0.2778},{"price":11311681.0,"size":0.015492},{"price":11312048.0,"size":0.01506},{"price":11312719.0,"size":0.02},{"price":11312720.0,"size":0.4199},{"price":11313584.0,"size":0.052056},{"price":11313658.0,"size":0.01},{"price":11313768.0,"size":0.258},{"price":11313957.0,"size":0.014772},{"price":11315342.0,"size":0.57612737},{"price":11316530.0,"size":0.2806},{"price":11318050.0,"size":0.002},{"price":11318640.0,"size":0.01},{"price":11318965.0,"size":0.053},{"price":11319292.0,"size":0.3099},{"price":11320000.0,"size":0.02},{"price":11320875.0,"size":0.0686},{"price":11322000.0,"size":0.005},{"price":11323556.0,"size":1.189881},{"price":11323581.0,"size":1.189881},{"price":11324915.0,"size":0.0139742},{"price":11328050.0,"size":0.002},{"price":11329436.0,"size":0.0015},{"price":11331059.0,"size":0.001},{"price":11334237.0,"size":1.489},{"price":11340000.0,"size":0.13586406},{"price":11340647.0,"size":0.001},{"price":11342956.0,"size":1.60199848},{"price":11342957.0,"size":0.01},{"price":11343043.0,"size":1.928},{"price":11346154.0,"size":0.0015},{"price":11348000.0,"size":0.1999},{"price":11349700.0,"size":0.001},{"price":11350000.0,"size":0.022},{"price":11353877.0,"size":0.001},{"price":11354939.0,"size":0.01},{"price":11355555.0,"size":0.001},{"price":11358323.0,"size":2.018},{"price":11359242.0,"size":0.0011},{"price":11359700.0,"size":0.001},{"price":11362692.0,"size":0.0015},{"price":11365211.0,"size":0.001},{"price":11369700.0,"size":0.001},{"price":11370000.0,"size":0.1},{"price":11372478.0,"size":1.943},{"price":11376000.0,"size":0.02},{"price":11376545.0,"size":0.001},{"price":11377000.0,"size":0.2287},{"price":11377269.0,"size":0.002},{"price":11379700.0,"size":0.001},{"price":11379865.0,"size":0.03},{"price":11380000.0,"size":0.0223},{"price":11380324.0,"size":0.002},{"price":11381766.0,"size":0.4},{"price":11382386.0,"size":0.0015},{"price":11385000.0,"size":0.2548},{"price":11385403.0,"size":0.002},{"price":11385664.0,"size":0.002},{"price":11387072.0,"size":0.01},{"price":11387354.0,"size":0.002},{"price":11387879.0,"size":0.001},{"price":11388885.0,"size":0.03},{"price":11389700.0,"size":0.001},{"price":11390000.0,"size":0.2488},{"price":11390050.0,"size":0.001},{"price":11392387.0,"size":1.0},{"price":11394939.0,"size":0.01},{"price":11395000.0,"size":0.06},{"price":11395775.0,"size":0.01},{"price":11396555.0,"size":0.03},{"price":11398444.0,"size":0.001995},{"price":11399213.0,"size":0.001},{"price":11399673.0,"size":0.0015},{"price":11399700.0,"size":0.001},{"price":11400000.0,"size":0.5525},{"price":11405000.0,"size":0.0275},{"price":11406336.0,"size":1.0},{"price":11408700.0,"size":0.001},{"price":11409415.0,"size":0.055},{"price":11410000.0,"size":0.03},{"price":11410547.0,"size":0.001},{"price":11410853.0,"size":0.002},{"price":11412000.0,"size":0.0878},{"price":11415000.0,"size":0.002},{"price":11415141.0,"size":0.0041},{"price":11417481.0,"size":0.0015},{"price":11418700.0,"size":0.001},{"price":11420000.0,"size":0.401},{"price":11421268.0,"size":0.05},{"price":11421881.0,"size":0.001},{"price":11423339.0,"size":2.0},{"price":11424296.0,"size":0.002},{"price":11424941.0,"size":0.972},{"price":11425000.0,"size":0.049},{"price":11426426.0,"size":0.002},{"price":11428121.0,"size":0.002},{"price":11428700.0,"size":0.001},{"price":11429302.0,"size":0.01},{"price":11432718.0,"size":0.002},{"price":11433211.0,"size":0.03},{"price":11433215.0,"size":0.001},{"price":11433333.0,"size":0.001},{"price":11437315.0,"size":0.002},{"price":11438525.0,"size":0.0011},{"price":11438700.0,"size":0.001},{"price":11439557.0,"size":0.001},{"price":11440000.0,"size":0.1038},{"price":11441911.0,"size":0.002},{"price":11443629.0,"size":0.002},{"price":11444549.0,"size":0.001},{"price":11446508.0,"size":0.001},{"price":11447000.0,"size":0.01},{"price":11447071.0,"size":0.002},{"price":11448000.0,"size":0.0875},{"price":11448700.0,"size":0.001},{"price":11450000.0,"size":0.258},{"price":11451105.0,"size":0.002},{"price":11453321.0,"size":0.03},{"price":11455702.0,"size":0.002},{"price":11455883.0,"size":0.001},{"price":11458700.0,"size":0.001},{"price":11458988.0,"size":0.01},{"price":11460000.0,"size":0.01702},{"price":11460299.0,"size":0.002},{"price":11464896.0,"size":0.002},{"price":11467217.0,"size":0.001},{"price":11468700.0,"size":0.001},{"price":11470000.0,"size":0.01},{"price":11471000.0,"size":0.01},{"price":11475000.0,"size":0.0028},{"price":11478431.0,"size":0.002},{"price":11478551.0,"size":0.001},{"price":11478700.0,"size":0.001},{"price":11480000.0,"size":0.12491},{"price":11485000.0,"size":0.01},{"price":11486555.0,"size":0.03},{"price":11487685.0,"size":0.01},{"price":11488000.0,"size":0.102},{"price":11488700.0,"size":0.001},{"price":11489885.0,"size":0.001},{"price":11490841.0,"size":0.002},{"price":11495450.0,"size":0.002},{"price":11495850.0,"size":0.001},{"price":11498700.0,"size":0.001},{"price":11498917.0,"size":0.002},{"price":11499000.0,"size":0.01},{"price":11500000.0,"size":0.46859519},{"price":11501219.0,"size":0.001},{"price":11502377.0,"size":0.002},{"price":11502800.0,"size":0.00132},{"price":11503108.0,"size":0.0198},{"price":11505000.0,"size":0.0028},{"price":11505001.0,"size":0.002},{"price":11505836.0,"size":0.003},{"price":11508431.0,"size":0.047},{"price":11508700.0,"size":0.001},{"price":11508888.0,"size":0.02},{"price":11510000.0,"size":0.0976},{"price":11512553.0,"size":0.001},{"price":11513633.0,"size":0.08},{"price":11514332.0,"size":0.02},{"price":11518700.0,"size":0.001},{"price":11518992.0,"size":0.002},{"price":11519855.0,"size":0.01},{"price":11520000.0,"size":0.001},{"price":11522423.0,"size":0.97},{"price":11523211.0,"size":0.01},{"price":11523887.0,"size":0.001},{"price":11524999.0,"size":0.001},{"price":11528700.0,"size":0.001},{"price":11529852.0,"size":0.01},{"price":11530000.0,"size":0.261},{"price":11533985.0,"size":0.002},{"price":11534084.0,"size":0.001},{"price":11535321.0,"size":0.01},{"price":11538666.0,"size":0.002},{"price":11538700.0,"size":0.001},{"price":11540000.0,"size":0.0048},{"price":11540357.0,"size":0.002},{"price":11541011.0,"size":0.005},{"price":11541109.0,"size":0.01},{"price":11544663.0,"size":0.002},{"price":11545262.0,"size":0.002},{"price":11546541.0,"size":0.01},{"price":11548144.0,"size":0.002},{"price":11548700.0,"size":0.001},{"price":11550000.0,"size":0.014},{"price":11551109.0,"size":0.01},{"price":11551625.0,"size":0.002},{"price":11552111.0,"size":0.01},{"price":11553687.0,"size":0.1},{"price":11555106.0,"size":0.002},{"price":11555115.0,"size":0.001},{"price":11556000.0,"size":0.1},{"price":11558587.0,"size":0.002},{"price":11558700.0,"size":0.001},{"price":11559855.0,"size":0.01},{"price":11560831.0,"size":0.0198},{"price":11561109.0,"size":0.01},{"price":11562000.0,"size":0.087},{"price":11562068.0,"size":0.002},{"price":11565548.0,"size":0.002},{"price":11566139.0,"size":0.0228},{"price":11566551.0,"size":0.01},{"price":11568700.0,"size":0.001},{"price":11569029.0,"size":0.002},{"price":11570196.0,"size":0.002},{"price":11571109.0,"size":0.01},{"price":11572510.0,"size":0.002},{"price":11573211.0,"size":0.01},{"price":11574840.0,"size":0.002},{"price":11575991.0,"size":0.001},{"price":11578700.0,"size":0.001},{"price":11579484.0,"size":0.002},{"price":11579851.0,"size":0.01},{"price":11580000.0,"size":0.7735},{"price":11581109.0,"size":0.01},{"price":11584128.0,"size":0.002},{"price":11585000.0,"size":0.002},{"price":11586532.0,"size":0.01},{"price":11587498.0,"size":0.0198},{"price":11588700.0,"size":0.001},{"price":11589612.0,"size":0.012},{"price":11590000.0,"size":0.1},{"price":11590749.0,"size":0.002},{"price":11591109.0,"size":0.01},{"price":11593211.0,"size":0.01},{"price":11596753.0,"size":0.002},{"price":11598555.0,"size":0.01},{"price":11598700.0,"size":0.001},{"price":11599999.0,"size":0.001},{"price":11600000.0,"size":3.6141},{"price":11601109.0,"size":0.02},{"price":11606655.0,"size":0.01},{"price":11610000.0,"size":0.302},{"price":11611109.0,"size":0.01},{"price":11613321.0,"size":0.01},{"price":11620000.0,"size":1.35441682},{"price":11621011.0,"size":0.01},{"price":11621109.0,"size":0.01},{"price":11623096.0,"size":0.008},{"price":11629000.0,"size":0.1},{"price":11630000.0,"size":0.201},{"price":11631059.0,"size":0.01},{"price":11631479.0,"size":0.01},{"price":11631773.0,"size":0.00386871},{"price":11635950.0,"size":0.001},{"price":11638259.0,"size":0.001},{"price":11639700.0,"size":0.001},{"price":11640000.0,"size":1.0},{"price":11640820.0,"size":0.01},{"price":11641651.0,"size":2.0},{"price":11645295.0,"size":0.05},{"price":11647158.0,"size":0.05},{"price":11649900.0,"size":0.02906},{"price":11649999.0,"size":0.001},{"price":11650000.0,"size":0.593},{"price":11651059.0,"size":0.01},{"price":11653658.0,"size":0.008},{"price":11654321.0,"size":0.001},{"price":11659700.0,"size":0.001},{"price":11661479.0,"size":0.01},{"price":11666000.0,"size":0.001},{"price":11666666.0,"size":0.013},{"price":11669700.0,"size":0.001},{"price":11671059.0,"size":0.01},{"price":11672562.0,"size":0.0198},{"price":11679224.0,"size":0.012},{"price":11680000.0,"size":0.004},{"price":11685000.0,"size":0.003},{"price":11688000.0,"size":0.001},{"price":11689732.0,"size":0.01},{"price":11690330.0,"size":0.0198},{"price":11691059.0,"size":0.01},{"price":11692558.0,"size":0.01},{"price":11698800.0,"size":0.00131},{"price":11699000.0,"size":0.001},{"price":11699631.0,"size":0.001},{"price":11699998.0,"size":0.01},{"price":11699999.0,"size":0.001},{"price":11700000.0,"size":1.03762841},{"price":11701059.0,"size":0.01},{"price":11720000.0,"size":0.1},{"price":11721059.0,"size":0.01},{"price":11725000.0,"size":0.005},{"price":11726791.0,"size":0.01},{"price":11730000.0,"size":0.9382},{"price":11740000.0,"size":0.101},{"price":11741059.0,"size":0.01},{"price":11748937.0,"size":0.001},{"price":11749999.0,"size":0.001},{"price":11750000.0,"size":0.90537866}]}}}
{"schema_version":"collector.vnext.raw","schema_contract":null,"schema_contract_version":null,"payload_contract_version":null,"record_type":"market.orderbook.diff","record_id":"collector_main-market-orderbook-diff-000000000064","collector_id":"collector_main","collector_role":"production","host_name":"MAIN-PC","session_id":"collector_main-sess-20260314T201135Z-e7f01376","stream_session_id":"collector_main-stream-bitflyer-board_ws-20260314T201145Z-dce12e93","exchange":"bitflyer","market":"spot","symbol":"BTC_JPY","instrument_id":"bitflyer.spot.BTC_JPY","channel":"board_ws","transport":"websocket","source_event_id":null,"source_sequence":null,"sequence_id":64,"exchange_ts":null,"collector_ts":"2026-03-14T20:11:45Z","ingest_ts":"2026-03-14T20:11:45Z","event_ts":"2026-03-14T20:11:45Z","quality_flags":[],"is_partial":false,"is_reconstructed":false,"confidence_score":1.0,"payload":{"provider":"bitflyer_ws_board","exchange":"bitflyer","transport":"websocket","channel":"lightning_board_BTC_JPY","received_ts":"2026-03-14T20:11:45.984467Z","subscription_id":null,"message_id":null,"source_sequence":null,"raw_message_meta":{"raw_channel":"lightning_board_BTC_JPY","subscription_channel":"lightning_board_BTC_JPY","recv_timeout_sec":10,"ssl_verify":false,"socket_url":"wss://ws.lightstream.bitflyer.com/json-rpc"},"source_payload":{"mid_price":11304996.0,"bids":[{"price":11302661.0,"size":0.0176931}],"asks":[{"price":11324915.0,"size":0.0}]}}}
{"schema_version":"collector.vnext.raw","schema_contract":null,"schema_contract_version":null,"payload_contract_version":null,"record_type":"market.orderbook.diff","record_id":"collector_main-market-orderbook-diff-000000000061","collector_id":"collector_main","collector_role":"production","host_name":"MAIN-PC","session_id":"collector_main-sess-20260314T201201Z-06ad1229","stream_session_id":"collector_main-stream-bitflyer-board_ws-20260314T201334Z-de089732","exchange":"bitflyer","market":"spot","symbol":"BTC_JPY","instrument_id":"bitflyer.spot.BTC_JPY","channel":"board_ws","transport":"websocket","source_event_id":null,"source_sequence":null,"sequence_id":61,"exchange_ts":null,"collector_ts":"2026-03-14T20:13:34Z","ingest_ts":"2026-03-14T20:13:34Z","event_ts":"2026-03-14T20:13:34Z","quality_flags":[],"is_partial":false,"is_reconstructed":false,"confidence_score":1.0,"payload":{"provider":"bitflyer_ws_board","exchange":"bitflyer","transport":"websocket","channel":"lightning_board_BTC_JPY","received_ts":"2026-03-14T20:13:34.447266Z","subscription_id":null,"message_id":null,"source_sequence":null,"raw_message_meta":{"raw_channel":"lightning_board_BTC_JPY","subscription_channel":"lightning_board_BTC_JPY","recv_timeout_sec":10,"ssl_verify":false,"socket_url":"wss://ws.lightstream.bitflyer.com/json-rpc"},"source_payload":{"mid_price":11303387.0,"bids":[{"price":11300920.0,"size":0.04138619},{"price":11300877.0,"size":0.0},{"price":11300919.0,"size":0.0}],"asks":[{"price":11305484.0,"size":0.0578}]}}}
{"schema_version":"collector.vnext.raw","schema_contract":null,"schema_contract_version":null,"payload_contract_version":null,"record_type":"market.orderbook.diff","record_id":"collector_main-market-orderbook-diff-000000000065","collector_id":"collector_main","collector_role":"production","host_name":"MAIN-PC","session_id":"collector_main-sess-20260314T201201Z-06ad1229","stream_session_id":"collector_main-stream-bitflyer-board_ws-20260314T201334Z-de089732","exchange":"bitflyer","market":"spot","symbol":"BTC_JPY","instrument_id":"bitflyer.spot.BTC_JPY","channel":"board_ws","transport":"websocket","source_event_id":null,"source_sequence":null,"sequence_id":65,"exchange_ts":null,"collector_ts":"2026-03-14T20:13:34Z","ingest_ts":"2026-03-14T20:13:34Z","event_ts":"2026-03-14T20:13:34Z","quality_flags":[],"is_partial":false,"is_reconstructed":false,"confidence_score":1.0,"payload":{"provider":"bitflyer_ws_board","exchange":"bitflyer","transport":"websocket","channel":"lightning_board_BTC_JPY","received_ts":"2026-03-14T20:13:34.656900Z","subscription_id":null,"message_id":null,"source_sequence":null,"raw_message_meta":{"raw_channel":"lightning_board_BTC_JPY","subscription_channel":"lightning_board_BTC_JPY","recv_timeout_sec":10,"ssl_verify":false,"socket_url":"wss://ws.lightstream.bitflyer.com/json-rpc"},"source_payload":{"mid_price":11303387.0,"bids":[{"price":11300920.0,"size":0.0}],"asks":[]}}}
{"schema_version":"collector.vnext.raw","schema_contract":null,"schema_contract_version":null,"payload_contract_version":null,"record_type":"market.orderbook.diff","record_id":"collector_main-market-orderbook-diff-000000000067","collector_id":"collector_main","collector_role":"production","host_name":"MAIN-PC","session_id":"collector_main-sess-20260314T201201Z-06ad1229","stream_session_id":"collector_main-stream-bitflyer-board_ws-20260314T201334Z-de089732","exchange":"bitflyer","market":"spot","symbol":"BTC_JPY","instrument_id":"bitflyer.spot.BTC_JPY","channel":"board_ws","transport":"websocket","source_event_id":null,"source_sequence":null,"sequence_id":67,"exchange_ts":null,"collector_ts":"2026-03-14T20:13:34Z","ingest_ts":"2026-03-14T20:13:34Z","event_ts":"2026-03-14T20:13:34Z","quality_flags":[],"is_partial":false,"is_reconstructed":false,"confidence_score":1.0,"payload":{"provider":"bitflyer_ws_board","exchange":"bitflyer","transport":"websocket","channel":"lightning_board_BTC_JPY","received_ts":"2026-03-14T20:13:34.766053Z","subscription_id":null,"message_id":null,"source_sequence":null,"raw_message_meta":{"raw_channel":"lightning_board_BTC_JPY","subscription_channel":"lightning_board_BTC_JPY","recv_timeout_sec":10,"ssl_verify":false,"socket_url":"wss://ws.lightstream.bitflyer.com/json-rpc"},"source_payload":{"mid_price":11303387.0,"bids":[{"price":11299981.0,"size":0.05295124},{"price":11298580.0,"size":0.02}],"asks":[]}}}
{"schema_version":"collector.vnext.raw","schema_contract":null,"schema_contract_version":null,"payload_contract_version":null,"record_type":"market.orderbook.diff","record_id":"collector_main-market-orderbook-diff-000000000069","collector_id":"collector_main","collector_role":"production","host_name":"MAIN-PC","session_id":"collector_main-sess-20260314T201201Z-06ad1229","stream_session_id":"collector_main-stream-bitflyer-board_ws-20260314T201334Z-de089732","exchange":"bitflyer","market":"spot","symbol":"BTC_JPY","instrument_id":"bitflyer.spot.BTC_JPY","channel":"board_ws","transport":"websocket","source_event_id":null,"source_sequence":null,"sequence_id":69,"exchange_ts":null,"collector_ts":"2026-03-14T20:13:34Z","ingest_ts":"2026-03-14T20:13:34Z","event_ts":"2026-03-14T20:13:34Z","quality_flags":[],"is_partial":false,"is_reconstructed":false,"confidence_score":1.0,"payload":{"provider":"bitflyer_ws_board","exchange":"bitflyer","transport":"websocket","channel":"lightning_board_BTC_JPY","received_ts":"2026-03-14T20:13:34.865941Z","subscription_id":null,"message_id":null,"source_sequence":null,"raw_message_meta":{"raw_channel":"lightning_board_BTC_JPY","subscription_channel":"lightning_board_BTC_JPY","recv_timeout_sec":10,"ssl_verify":false,"socket_url":"wss://ws.lightstream.bitflyer.com/json-rpc"},"source_payload":{"mid_price":11303387.0,"bids":[{"price":11298851.0,"size":0.02},{"price":11300093.0,"size":0.02}],"asks":[]}}}
{"schema_version":"collector.vnext.raw","schema_contract":null,"schema_contract_version":null,"payload_contract_version":null,"record_type":"market.orderbook.diff","record_id":"collector_main-market-orderbook-diff-000000000071","collector_id":"collector_main","collector_role":"production","host_name":"MAIN-PC","session_id":"collector_main-sess-20260314T201201Z-06ad1229","stream_session_id":"collector_main-stream-bitflyer-board_ws-20260314T201334Z-de089732","exchange":"bitflyer","market":"spot","symbol":"BTC_JPY","instrument_id":"bitflyer.spot.BTC_JPY","channel":"board_ws","transport":"websocket","source_event_id":null,"source_sequence":null,"sequence_id":71,"exchange_ts":null,"collector_ts":"2026-03-14T20:13:35Z","ingest_ts":"2026-03-14T20:13:35Z","event_ts":"2026-03-14T20:13:35Z","quality_flags":[],"is_partial":false,"is_reconstructed":false,"confidence_score":1.0,"payload":{"provider":"bitflyer_ws_board","exchange":"bitflyer","transport":"websocket","channel":"lightning_board_BTC_JPY","received_ts":"2026-03-14T20:13:35.048957Z","subscription_id":null,"message_id":null,"source_sequence":null,"raw_message_meta":{"raw_channel":"lightning_board_BTC_JPY","subscription_channel":"lightning_board_BTC_JPY","recv_timeout_sec":10,"ssl_verify":false,"socket_url":"wss://ws.lightstream.bitflyer.com/json-rpc"},"source_payload":{"mid_price":11303387.0,"bids":[{"price":11299981.0,"size":0.0},{"price":11300954.0,"size":0.0},{"price":11294843.0,"size":0.0}],"asks":[{"price":11319180.0,"size":0.0}]}}}
{"schema_version":"collector.vnext.raw","schema_contract":null,"schema_contract_version":null,"payload_contract_version":null,"record_type":"market.orderbook.diff","record_id":"collector_main-market-orderbook-diff-000000000073","collector_id":"collector_main","collector_role":"production","host_name":"MAIN-PC","session_id":"collector_main-sess-20260314T201201Z-06ad1229","stream_session_id":"collector_main-stream-bitflyer-board_ws-20260314T201334Z-de089732","exchange":"bitflyer","market":"spot","symbol":"BTC_JPY","instrument_id":"bitflyer.spot.BTC_JPY","channel":"board_ws","transport":"websocket","source_event_id":null,"source_sequence":null,"sequence_id":73,"exchange_ts":null,"collector_ts":"2026-03-14T20:13:35Z","ingest_ts":"2026-03-14T20:13:35Z","event_ts":"2026-03-14T20:13:35Z","quality_flags":[],"is_partial":false,"is_reconstructed":false,"confidence_score":1.0,"payload":{"provider":"bitflyer_ws_board","exchange":"bitflyer","transport":"websocket","channel":"lightning_board_BTC_JPY","received_ts":"2026-03-14T20:13:35.156719Z","subscription_id":null,"message_id":null,"source_sequence":null,"raw_message_meta":{"raw_channel":"lightning_board_BTC_JPY","subscription_channel":"lightning_board_BTC_JPY","recv_timeout_sec":10,"ssl_verify":false,"socket_url":"wss://ws.lightstream.bitflyer.com/json-rpc"},"source_payload":{"mid_price":11303387.0,"bids":[{"price":11300094.0,"size":0.05085292}],"asks":[]}}}
{"schema_version":"collector.vnext.raw","schema_contract":null,"schema_contract_version":null,"payload_contract_version":null,"record_type":"market.orderbook.diff","record_id":"collector_main-market-orderbook-diff-000000000075","collector_id":"collector_main","collector_role":"production","host_name":"MAIN-PC","session_id":"collector_main-sess-20260314T201201Z-06ad1229","stream_session_id":"collector_main-stream-bitflyer-board_ws-20260314T201334Z-de089732","exchange":"bitflyer","market":"spot","symbol":"BTC_JPY","instrument_id":"bitflyer.spot.BTC_JPY","channel":"board_ws","transport":"websocket","source_event_id":null,"source_sequence":null,"sequence_id":75,"exchange_ts":null,"collector_ts":"2026-03-14T20:13:35Z","ingest_ts":"2026-03-14T20:13:35Z","event_ts":"2026-03-14T20:13:35Z","quality_flags":[],"is_partial":false,"is_reconstructed":false,"confidence_score":1.0,"payload":{"provider":"bitflyer_ws_board","exchange":"bitflyer","transport":"websocket","channel":"lightning_board_BTC_JPY","received_ts":"2026-03-14T20:13:35.266638Z","subscription_id":null,"message_id":null,"source_sequence":null,"raw_message_meta":{"raw_channel":"lightning_board_BTC_JPY","subscription_channel":"lightning_board_BTC_JPY","recv_timeout_sec":10,"ssl_verify":false,"socket_url":"wss://ws.lightstream.bitflyer.com/json-rpc"},"source_payload":{"mid_price":11303387.0,"bids":[{"price":11275106.0,"size":0.002}],"asks":[]}}}
{"schema_version":"collector.vnext.raw","schema_contract":null,"schema_contract_version":null,"payload_contract_version":null,"record_type":"market.orderbook.diff","record_id":"collector_main-market-orderbook-diff-000000000077","collector_id":"collector_main","collector_role":"production","host_name":"MAIN-PC","session_id":"collector_main-sess-20260314T201201Z-06ad1229","stream_session_id":"collector_main-stream-bitflyer-board_ws-20260314T201334Z-de089732","exchange":"bitflyer","market":"spot","symbol":"BTC_JPY","instrument_id":"bitflyer.spot.BTC_JPY","channel":"board_ws","transport":"websocket","source_event_id":null,"source_sequence":null,"sequence_id":77,"exchange_ts":null,"collector_ts":"2026-03-14T20:13:35Z","ingest_ts":"2026-03-14T20:13:35Z","event_ts":"2026-03-14T20:13:35Z","quality_flags":[],"is_partial":false,"is_reconstructed":false,"confidence_score":1.0,"payload":{"provider":"bitflyer_ws_board","exchange":"bitflyer","transport":"websocket","channel":"lightning_board_BTC_JPY","received_ts":"2026-03-14T20:13:35.378256Z","subscription_id":null,"message_id":null,"source_sequence":null,"raw_message_meta":{"raw_channel":"lightning_board_BTC_JPY","subscription_channel":"lightning_board_BTC_JPY","recv_timeout_sec":10,"ssl_verify":false,"socket_url":"wss://ws.lightstream.bitflyer.com/json-rpc"},"source_payload":{"mid_price":11303387.0,"bids":[],"asks":[{"price":11314642.0,"size":0.0528}]}}}
{"schema_version":"collector.vnext.raw","schema_contract":null,"schema_contract_version":null,"payload_contract_version":null,"record_type":"market.orderbook.diff","record_id":"collector_main-market-orderbook-diff-000000000079","collector_id":"collector_main","collector_role":"production","host_name":"MAIN-PC","session_id":"collector_main-sess-20260314T201201Z-06ad1229","stream_session_id":"collector_main-stream-bitflyer-board_ws-20260314T201334Z-de089732","exchange":"bitflyer","market":"spot","symbol":"BTC_JPY","instrument_id":"bitflyer.spot.BTC_JPY","channel":"board_ws","transport":"websocket","source_event_id":null,"source_sequence":null,"sequence_id":79,"exchange_ts":null,"collector_ts":"2026-03-14T20:13:35Z","ingest_ts":"2026-03-14T20:13:35Z","event_ts":"2026-03-14T20:13:35Z","quality_flags":[],"is_partial":false,"is_reconstructed":false,"confidence_score":1.0,"payload":{"provider":"bitflyer_ws_board","exchange":"bitflyer","transport":"websocket","channel":"lightning_board_BTC_JPY","received_ts":"2026-03-14T20:13:35.489876Z","subscription_id":null,"message_id":null,"source_sequence":null,"raw_message_meta":{"raw_channel":"lightning_board_BTC_JPY","subscription_channel":"lightning_board_BTC_JPY","recv_timeout_sec":10,"ssl_verify":false,"socket_url":"wss://ws.lightstream.bitflyer.com/json-rpc"},"source_payload":{"mid_price":11303387.0,"bids":[{"price":11300095.0,"size":0.02},{"price":11299169.0,"size":0.0176986}],"asks":[]}}}
{"schema_version":"collector.vnext.raw","schema_contract":null,"schema_contract_version":null,"payload_contract_version":null,"record_type":"market.orderbook.diff","record_id":"collector_main-market-orderbook-diff-000000000081","collector_id":"collector_main","collector_role":"production","host_name":"MAIN-PC","session_id":"collector_main-sess-20260314T201201Z-06ad1229","stream_session_id":"collector_main-stream-bitflyer-board_ws-20260314T201334Z-de089732","exchange":"bitflyer","market":"spot","symbol":"BTC_JPY","instrument_id":"bitflyer.spot.BTC_JPY","channel":"board_ws","transport":"websocket","source_event_id":null,"source_sequence":null,"sequence_id":81,"exchange_ts":null,"collector_ts":"2026-03-14T20:13:35Z","ingest_ts":"2026-03-14T20:13:35Z","event_ts":"2026-03-14T20:13:35Z","quality_flags":[],"is_partial":false,"is_reconstructed":false,"confidence_score":1.0,"payload":{"provider":"bitflyer_ws_board","exchange":"bitflyer","transport":"websocket","channel":"lightning_board_BTC_JPY","received_ts":"2026-03-14T20:13:35.580192Z","subscription_id":null,"message_id":null,"source_sequence":null,"raw_message_meta":{"raw_channel":"lightning_board_BTC_JPY","subscription_channel":"lightning_board_BTC_JPY","recv_timeout_sec":10,"ssl_verify":false,"socket_url":"wss://ws.lightstream.bitflyer.com/json-rpc"},"source_payload":{"mid_price":11303387.0,"bids":[{"price":11294764.0,"size":0.0531},{"price":11300561.0,"size":0.1275},{"price":11300094.0,"size":0.0}],"asks":[{"price":11307909.0,"size":0.1275}]}}}
{"schema_version":"collector.vnext.raw","schema_contract":null,"schema_contract_version":null,"payload_contract_version":null,"record_type":"market.orderbook.diff","record_id":"collector_main-market-orderbook-diff-000000000083","collector_id":"collector_main","collector_role":"production","host_name":"MAIN-PC","session_id":"collector_main-sess-20260314T201201Z-06ad1229","stream_session_id":"collector_main-stream-bitflyer-board_ws-20260314T201334Z-de089732","exchange":"bitflyer","market":"spot","symbol":"BTC_JPY","instrument_id":"bitflyer.spot.BTC_JPY","channel":"board_ws","transport":"websocket","source_event_id":null,"source_sequence":null,"sequence_id":83,"exchange_ts":null,"collector_ts":"2026-03-14T20:13:35Z","ingest_ts":"2026-03-14T20:13:35Z","event_ts":"2026-03-14T20:13:35Z","quality_flags":[],"is_partial":false,"is_reconstructed":false,"confidence_score":1.0,"payload":{"provider":"bitflyer_ws_board","exchange":"bitflyer","transport":"websocket","channel":"lightning_board_BTC_JPY","received_ts":"2026-03-14T20:13:35.720429Z","subscription_id":null,"message_id":null,"source_sequence":null,"raw_message_meta":{"raw_channel":"lightning_board_BTC_JPY","subscription_channel":"lightning_board_BTC_JPY","recv_timeout_sec":10,"ssl_verify":false,"socket_url":"wss://ws.lightstream.bitflyer.com/json-rpc"},"source_payload":{"mid_price":11303387.0,"bids":[{"price":11275103.0,"size":0.0},{"price":11300096.0,"size":0.05180797}],"asks":[]}}}
{"schema_version":"collector.vnext.raw","schema_contract":null,"schema_contract_version":null,"payload_contract_version":null,"record_type":"market.orderbook.diff","record_id":"collector_main-market-orderbook-diff-000000000085","collector_id":"collector_main","collector_role":"production","host_name":"MAIN-PC","session_id":"collector_main-sess-20260314T201201Z-06ad1229","stream_session_id":"collector_main-stream-bitflyer-board_ws-20260314T201334Z-de089732","exchange":"bitflyer","market":"spot","symbol":"BTC_JPY","instrument_id":"bitflyer.spot.BTC_JPY","channel":"board_ws","transport":"websocket","source_event_id":null,"source_sequence":null,"sequence_id":85,"exchange_ts":null,"collector_ts":"2026-03-14T20:13:35Z","ingest_ts":"2026-03-14T20:13:35Z","event_ts":"2026-03-14T20:13:35Z","quality_flags":[],"is_partial":false,"is_reconstructed":false,"confidence_score":1.0,"payload":{"provider":"bitflyer_ws_board","exchange":"bitflyer","transport":"websocket","channel":"lightning_board_BTC_JPY","received_ts":"2026-03-14T20:13:35.829200Z","subscription_id":null,"message_id":null,"source_sequence":null,"raw_message_meta":{"raw_channel":"lightning_board_BTC_JPY","subscription_channel":"lightning_board_BTC_JPY","recv_timeout_sec":10,"ssl_verify":false,"socket_url":"wss://ws.lightstream.bitflyer.com/json-rpc"},"source_payload":{"mid_price":11303387.0,"bids":[{"price":11299170.0,"size":0.02},{"price":11300096.0,"size":0.0},{"price":11300561.0,"size":0.0},{"price":11300095.0,"size":0.0},{"price":11300562.0,"size":0.046709},{"price":11301126.0,"size":0.1275}],"asks":[]}}}
{"schema_version":"collector.vnext.raw","schema_contract":null,"schema_contract_version":null,"payload_contract_version":null,"record_type":"market.orderbook.diff","record_id":"collector_main-market-orderbook-diff-000000000087","collector_id":"collector_main","collector_role":"production","host_name":"MAIN-PC","session_id":"collector_main-sess-20260314T201201Z-06ad1229","stream_session_id":"collector_main-stream-bitflyer-board_ws-20260314T201334Z-de089732","exchange":"bitflyer","market":"spot","symbol":"BTC_JPY","instrument_id":"bitflyer.spot.BTC_JPY","channel":"board_ws","transport":"websocket","source_event_id":null,"source_sequence":null,"sequence_id":87,"exchange_ts":null,"collector_ts":"2026-03-14T20:13:35Z","ingest_ts":"2026-03-14T20:13:35Z","event_ts":"2026-03-14T20:13:35Z","quality_flags":[],"is_partial":false,"is_reconstructed":false,"confidence_score":1.0,"payload":{"provider":"bitflyer_ws_board","exchange":"bitflyer","transport":"websocket","channel":"lightning_board_BTC_JPY","received_ts":"2026-03-14T20:13:35.983196Z","subscription_id":null,"message_id":null,"source_sequence":null,"raw_message_meta":{"raw_channel":"lightning_board_BTC_JPY","subscription_channel":"lightning_board_BTC_JPY","recv_timeout_sec":10,"ssl_verify":false,"socket_url":"wss://ws.lightstream.bitflyer.com/json-rpc"},"source_payload":{"mid_price":11303387.0,"bids":[{"price":11301126.0,"size":0.0}],"asks":[]}}}
{"schema_version":"collector.vnext.raw","schema_contract":null,"schema_contract_version":null,"payload_contract_version":null,"record_type":"market.orderbook.snapshot","record_id":"collector_main-market-orderbook-snapshot-000000000089","collector_id":"collector_main","collector_role":"production","host_name":"MAIN-PC","session_id":"collector_main-sess-20260314T201201Z-06ad1229","stream_session_id":"collector_main-stream-bitflyer-board_ws-20260314T201334Z-de089732","exchange":"bitflyer","market":"spot","symbol":"BTC_JPY","instrument_id":"bitflyer.spot.BTC_JPY","channel":"board_ws","transport":"websocket","source_event_id":null,"source_sequence":null,"sequence_id":89,"exchange_ts":null,"collector_ts":"2026-03-14T20:13:36Z","ingest_ts":"2026-03-14T20:13:36Z","event_ts":"2026-03-14T20:13:36Z","quality_flags":[],"is_partial":false,"is_reconstructed":false,"confidence_score":1.0,"payload":{"provider":"bitflyer_ws_board_snapshot","exchange":"bitflyer","transport":"websocket","channel":"lightning_board_snapshot_BTC_JPY","received_ts":"2026-03-14T20:13:36.077051Z","subscription_id":null,"message_id":null,"source_sequence":null,"raw_message_meta":{"raw_channel":"lightning_board_snapshot_BTC_JPY","subscription_channel":"lightning_board_snapshot_BTC_JPY","recv_timeout_sec":10,"ssl_verify":false,"socket_url":"wss://ws.lightstream.bitflyer.com/json-rpc"},"source_payload":{"mid_price":11303387.0,"bids":[{"price":11301291.0,"size":0.005},{"price":11300562.0,"size":0.046709},{"price":11300093.0,"size":0.02},{"price":11299980.0,"size":0.00999866},{"price":11299170.0,"size":0.02},{"price":11299169.0,"size":0.0176986},{"price":11299134.0,"size":0.02},{"price":11299133.0,"size":0.015024},{"price":11298963.0,"size":0.02},{"price":11298853.0,"size":0.02},{"price":11298851.0,"size":0.02},{"price":11298850.0,"size":0.014976},{"price":11298580.0,"size":0.02},{"price":11298579.0,"size":0.05},{"price":11298531.0,"size":0.014712},{"price":11298513.0,"size":0.05},{"price":11298242.0,"size":0.014772},{"price":11297568.0,"size":0.01},{"price":11297439.0,"size":0.5},{"price":11295351.0,"size":0.005},{"price":11294764.0,"size":0.0531},{"price":11293682.0,"size":0.053352},{"price":11293357.0,"size":0.5},{"price":11293270.0,"size":0.0801},{"price":11293055.0,"size":2.97488679},{"price":11292244.0,"size":0.048},{"price":11291636.0,"size":0.132},{"price":11291140.0,"size":0.00999859},{"price":11289443.0,"size":0.04},{"price":11287378.0,"size":1.50015},{"price":11286651.0,"size":0.98403398},{"price":11280562.0,"size":0.3089},{"price":11280205.0,"size":0.001},{"price":11280195.0,"size":0.002},{"price":11279434.0,"size":0.6},{"price":11279282.0,"size":0.0015},{"price":11278498.0,"size":0.002},{"price":11277800.0,"size":0.2689},{"price":11277748.0,"size":0.0966561},{"price":11277602.0,"size":0.005},{"price":11275673.0,"size":0.002},{"price":11275360.0,"size":1.484},{"price":11275106.0,"size":0.002},{"price":11275102.0,"size":0.01},{"price":11275038.0,"size":0.2726},{"price":11275000.0,"size":0.001},{"price":11274588.0,"size":0.0047},{"price":11272276.0,"size":0.2915},{"price":11271151.0,"size":0.002},{"price":11271000.0,"size":0.003},{"price":11270000.0,"size":0.106},{"price":11268871.0,"size":0.281},{"price":11268411.0,"size":0.01},{"price":11266666.0,"size":0.04},{"price":11266629.0,"size":0.002},{"price":11265879.0,"size":0.6},{"price":11265000.0,"size":0.02},{"price":11263999.0,"size":1.966},{"price":11263000.0,"size":0.006},{"price":11262564.0,"size":0.0015},{"price":11262107.0,"size":0.002},{"price":11260000.0,"size":0.3565},{"price":11257585.0,"size":0.002},{"price":11257537.0,"size":0.001},{"price":11257000.0,"size":0.001},{"price":11255200.0,"size":0.001},{"price":11255115.0,"size":0.00377},{"price":11253628.0,"size":2.036},{"price":11253063.0,"size":0.002},{"price":11253000.0,"size":0.03189},{"price":11251000.0,"size":0.0131},{"price":11250250.0,"size":0.00105},{"price":11250200.0,"size":0.001},{"price":11250100.0,"size":0.015},{"price":11250005.0,"size":0.001},{"price":11250001.0,"size":0.00104},{"price":11250000.0,"size":0.76834},{"price":11248541.0,"size":0.002},{"price":11246544.0,"size":0.0015},{"price":11246203.0,"size":0.001},{"price":11245141.0,"size":0.0031},{"price":11245000.0,"size":0.05},{"price":11244444.0,"size":0.04},{"price":11244243.0,"size":0.01},{"price":11244019.0,"size":0.002},{"price":11240200.0,"size":0.001},{"price":11240000.0,"size":0.007304},{"price":11239497.0,"size":0.002},{"price":11236190.0,"size":0.01},{"price":11235200.0,"size":0.001},{"price":11234869.0,"size":0.001},{"price":11232000.0,"size":0.089},{"price":11231243.0,"size":0.01},{"price":11231000.0,"size":0.105},{"price":11230200.0,"size":0.001},{"price":11230000.0,"size":0.0308},{"price":11228423.0,"size":1.951},{"price":11224500.0,"size":0.06},{"price":11224355.0,"size":0.0015},{"price":11223968.0,"size":0.001},{"price":11223535.0,"size":0.001},{"price":11223344.0,"size":0.01},{"price":11223000.0,"size":0.1},{"price":11222222.0,"size":0.092525},{"price":11221459.0,"size":0.1393},{"price":11221120.0,"size":0.011},{"price":11220200.0,"size":0.001},{"price":11220001.0,"size":0.004457},{"price":11220000.0,"size":0.321},{"price":11219517.0,"size":0.01},{"price":11219000.0,"size":0.1},{"price":11215200.0,"size":0.001},{"price":11215000.0,"size":0.02},{"price":11212713.0,"size":1.79},{"price":11212358.0,"size":1.2},{"price":11212201.0,"size":0.001},{"price":11211800.0,"size":0.001},{"price":11211111.0,"size":0.06},{"price":11210200.0,"size":0.001},{"price":11210000.0,"size":0.10622},{"price":11208032.0,"size":0.01},{"price":11207755.0,"size":0.0015},{"price":11206000.0,"size":0.09015},{"price":11205200.0,"size":0.001},{"price":11204578.0,"size":0.002},{"price":11203931.0,"size":1.0},{"price":11201000.0,"size":0.01},{"price":11200867.0,"size":0.001},{"price":11200800.0,"size":0.05},{"price":11200425.0,"size":0.1},{"price":11200200.0,"size":0.001},{"price":11200198.0,"size":0.003},{"price":11200150.0,"size":0.002},{"price":11200002.0,"size":0.001},{"price":11200001.0,"size":0.01104},{"price":11200000.0,"size":1.35988728},{"price":11198508.0,"size":0.05},{"price":11198243.0,"size":0.01},{"price":11197134.0,"size":2.0},{"price":11197000.0,"size":0.0085},{"price":11195692.0,"size":0.0015},{"price":11194090.0,"size":0.03},{"price":11190770.0,"size":0.0309},{"price":11190000.0,"size":0.0010016},{"price":11189555.0,"size":0.5},{"price":11189533.0,"size":0.001},{"price":11188629.0,"size":0.01},{"price":11188382.0,"size":0.001},{"price":11185000.0,"size":0.0085},{"price":11180043.0,"size":0.972},{"price":11180000.0,"size":0.23215},{"price":11178973.0,"size":0.0015},{"price":11178199.0,"size":0.001},{"price":11170000.0,"size":0.001},{"price":11169662.0,"size":0.01},{"price":11169593.0,"size":0.001},{"price":11169243.0,"size":0.01},{"price":11166865.0,"size":0.001},{"price":11164029.0,"size":0.001},{"price":11160854.0,"size":0.1},{"price":11160000.0,"size":0.02376},{"price":11156269.0,"size":0.01},{"price":11155531.0,"size":0.001},{"price":11155377.0,"size":0.00636009},{"price":11153999.0,"size":0.00101},{"price":11150250.0,"size":0.00175},{"price":11150005.0,"size":0.001},{"price":11150001.0,"size":0.00104},{"price":11150000.0,"size":0.6398956},{"price":11148000.0,"size":0.08963},{"price":11144197.0,"size":0.001},{"price":11144000.0,"size":0.0897},{"price":11140000.0,"size":0.2},{"price":11136243.0,"size":0.01},{"price":11136155.0,"size":0.02},{"price":11135869.0,"size":0.1},{"price":11130000.0,"size":0.116},{"price":11129979.0,"size":0.0053908},{"price":11126388.0,"size":0.02},{"price":11124900.0,"size":0.00133},{"price":11121090.0,"size":0.1},{"price":11120000.0,"size":0.0033},{"price":11118078.0,"size":0.01},{"price":11111800.0,"size":0.001},{"price":11111111.0,"size":0.2919257},{"price":11111000.0,"size":0.003},{"price":11110594.0,"size":0.001},{"price":11110000.0,"size":0.056937},{"price":11109662.0,"size":0.01},{"price":11108008.0,"size":0.01},{"price":11106000.0,"size":0.2},{"price":11105000.0,"size":0.02},{"price":11101297.0,"size":0.001},{"price":11100005.0,"size":0.001},{"price":11100001.0,"size":0.01104},{"price":11100000.0,"size":2.7475049},{"price":11099141.0,"size":0.01},{"price":11096243.0,"size":0.01},{"price":11094090.0,"size":0.01},{"price":11088888.0,"size":0.001},{"price":11085245.0,"size":0.001},{"price":11080200.0,"size":0.001},{"price":11080000.0,"size":0.0223},{"price":11075100.0,"size":0.003},{"price":11071558.0,"size":1.0},{"price":11070200.0,"size":0.001},{"price":11070000.0,"size":0.0902},{"price":11065200.0,"size":0.001},{"price":11064370.0,"size":0.00497091},{"price":11060200.0,"size":0.001},{"price":11060000.0,"size":0.145},{"price":11059689.0,"size":0.009},{"price":11056428.0,"size":0.002},{"price":11055500.0,"size":0.02},{"price":11055200.0,"size":0.001},{"price":11055100.0,"size":0.003},{"price":11050200.0,"size":0.001},{"price":11050005.0,"size":0.001},{"price":11050002.0,"size":0.001},{"price":11050001.0,"size":0.00104},{"price":11050000.0,"size":0.43176147},{"price":11046420.0,"size":0.2},{"price":11044243.0,"size":0.01},{"price":11041380.0,"size":0.01},{"price":11040200.0,"size":0.001},{"price":11040000.0,"size":0.00777181},{"price":11035865.0,"size":0.1},{"price":11035200.0,"size":0.001},{"price":11035000.0,"size":0.0013},{"price":11030200.0,"size":0.001},{"price":11030000.0,"size":0.025},{"price":11025500.0,"size":0.009531},{"price":11025200.0,"size":0.001},{"price":11025000.0,"size":0.71497},{"price":11020772.0,"size":0.014},{"price":11020200.0,"size":0.002},{"price":11020000.0,"size":0.005},{"price":11015200.0,"size":0.001},{"price":11012000.0,"size":0.1},{"price":11011800.0,"size":0.001},{"price":11010200.0,"size":0.001},{"price":11010000.0,"size":0.347},{"price":11007277.0,"size":0.01},{"price":11006000.0,"size":0.2},{"price":11005200.0,"size":0.001},{"price":11004890.0,"size":0.001535},{"price":11003000.0,"size":0.0155},{"price":11001000.0,"size":0.013},{"price":11000500.0,"size":0.05117658},{"price":11000200.0,"size":0.001},{"price":11000002.0,"size":0.004},{"price":11000001.0,"size":0.02604},{"price":11000000.0,"size":5.47323365},{"price":10999999.0,"size":0.003},{"price":10999000.0,"size":0.001},{"price":10996855.0,"size":0.0011},{"price":10995200.0,"size":0.001},{"price":10994499.0,"size":0.00169176},{"price":10990200.0,"size":0.001},{"price":10990000.0,"size":0.10219},{"price":10989001.0,"size":0.00197},{"price":10988999.0,"size":0.001},{"price":10988324.0,"size":0.002},{"price":10987654.0,"size":0.001},{"price":10985200.0,"size":0.001},{"price":10985150.0,"size":0.01},{"price":10980500.0,"size":0.005},{"price":10980200.0,"size":0.001},{"price":10980002.0,"size":0.4},{"price":10980000.0,"size":0.028},{"price":10975200.0,"size":0.001},{"price":10975000.0,"size":0.1},{"price":10971261.0,"size":0.001},{"price":10971243.0,"size":0.01},{"price":10970375.0,"size":1.9},{"price":10970200.0,"size":0.001},{"price":10970000.0,"size":0.09304},{"price":10966600.0,"size":0.001003},{"price":10965200.0,"size":0.001},{"price":10960200.0,"size":0.001},{"price":10960000.0,"size":0.0083},{"price":10956673.0,"size":0.01},{"price":10955200.0,"size":0.001},{"price":10954950.0,"size":0.001},{"price":10950500.0,"size":0.005},{"price":10950001.0,"size":0.00204},{"price":10950000.0,"size":0.5485028},{"price":10949550.0,"size":0.01870657},{"price":10949172.0,"size":0.1},{"price":10948000.0,"size":0.1},{"price":10945243.0,"size":0.01},{"price":10940402.0,"size":0.001},{"price":10940200.0,"size":0.001},{"price":10940000.0,"size":0.331},{"price":10938243.0,"size":0.01},{"price":10936200.0,"size":0.00137},{"price":10935200.0,"size":0.001},{"price":10930200.0,"size":0.002},{"price":10930000.0,"size":0.0193},{"price":10925200.0,"size":0.002}],"asks":[{"price":11305483.0,"size":0.0464319},{"price":11305484.0,"size":0.0578},{"price":11306219.0,"size":0.02},{"price":11306220.0,"size":0.01000118},{"price":11307909.0,"size":0.1275},{"price":11308243.0,"size":0.02},{"price":11308244.0,"size":0.2917},{"price":11308930.0,"size":0.02},{"price":11309329.0,"size":0.02},{"price":11310444.0,"size":0.02},{"price":11310637.0,"size":0.053352},{"price":11311005.0,"size":0.02},{"price":11311006.0,"size":0.2778},{"price":11311681.0,"size":0.015492},{"price":11312048.0,"size":0.01506},{"price":11312719.0,"size":0.57627887},{"price":11312720.0,"size":0.4199},{"price":11313658.0,"size":0.01},{"price":11313768.0,"size":0.258},{"price":11313957.0,"size":0.014772},{"price":11314642.0,"size":0.0528},{"price":11316530.0,"size":0.2806},{"price":11318050.0,"size":0.002},{"price":11318640.0,"size":0.01},{"price":11319156.0,"size":0.15},{"price":11320000.0,"size":0.02},{"price":11322000.0,"size":0.005},{"price":11323196.0,"size":0.014259},{"price":11323556.0,"size":1.189881},{"price":11323581.0,"size":1.189881},{"price":11328050.0,"size":0.002},{"price":11329436.0,"size":0.0015},{"price":11331059.0,"size":0.001},{"price":11334237.0,"size":1.489},{"price":11340000.0,"size":0.13586406},{"price":11340647.0,"size":0.001},{"price":11342956.0,"size":1.60199848},{"price":11342957.0,"size":0.01},{"price":11343043.0,"size":1.928},{"price":11346154.0,"size":0.0015},{"price":11348000.0,"size":0.1999},{"price":11349700.0,"size":0.001},{"price":11350000.0,"size":0.022},{"price":11353877.0,"size":0.001},{"price":11354939.0,"size":0.01},{"price":11355555.0,"size":0.001},{"price":11358323.0,"size":2.018},{"price":11359242.0,"size":0.0011},{"price":11359700.0,"size":0.001},{"price":11362692.0,"size":0.0015},{"price":11365211.0,"size":0.001},{"price":11369700.0,"size":0.001},{"price":11370000.0,"size":0.1},{"price":11372478.0,"size":1.943},{"price":11376000.0,"size":0.02},{"price":11376545.0,"size":0.001},{"price":11377000.0,"size":0.2287},{"price":11377269.0,"size":0.002},{"price":11379700.0,"size":0.001},{"price":11379865.0,"size":0.03},{"price":11380000.0,"size":0.0223},{"price":11380324.0,"size":0.002},{"price":11381766.0,"size":0.4},{"price":11382386.0,"size":0.0015},{"price":11385000.0,"size":0.2548},{"price":11385403.0,"size":0.002},{"price":11385664.0,"size":0.002},{"price":11387072.0,"size":0.01},{"price":11387354.0,"size":0.002},{"price":11387879.0,"size":0.001},{"price":11388885.0,"size":0.03},{"price":11389700.0,"size":0.001},{"price":11390000.0,"size":0.2488},{"price":11390050.0,"size":0.001},{"price":11392387.0,"size":1.0},{"price":11394939.0,"size":0.01},{"price":11395000.0,"size":0.06},{"price":11395775.0,"size":0.01},{"price":11396555.0,"size":0.03},{"price":11398444.0,"size":0.001995},{"price":11399213.0,"size":0.001},{"price":11399673.0,"size":0.0015},{"price":11399700.0,"size":0.001},{"price":11400000.0,"size":0.5525},{"price":11405000.0,"size":0.0275},{"price":11406336.0,"size":1.0},{"price":11408700.0,"size":0.001},{"price":11409415.0,"size":0.055},{"price":11410000.0,"size":0.03},{"price":11410547.0,"size":0.001},{"price":11410853.0,"size":0.002},{"price":11412000.0,"size":0.0878},{"price":11415000.0,"size":0.002},{"price":11415141.0,"size":0.0041},{"price":11417481.0,"size":0.0015},{"price":11418700.0,"size":0.001},{"price":11420000.0,"size":0.401},{"price":11421268.0,"size":0.05},{"price":11421881.0,"size":0.001},{"price":11423339.0,"size":2.0},{"price":11424296.0,"size":0.002},{"price":11424941.0,"size":0.972},{"price":11425000.0,"size":0.049},{"price":11426426.0,"size":0.002},{"price":11428121.0,"size":0.002},{"price":11428700.0,"size":0.001},{"price":11429302.0,"size":0.01},{"price":11432718.0,"size":0.002},{"price":11433211.0,"size":0.03},{"price":11433215.0,"size":0.001},{"price":11433333.0,"size":0.001},{"price":11437315.0,"size":0.002},{"price":11438525.0,"size":0.0011},{"price":11438700.0,"size":0.001},{"price":11439557.0,"size":0.001},{"price":11440000.0,"size":0.1038},{"price":11441911.0,"size":0.002},{"price":11443629.0,"size":0.002},{"price":11444549.0,"size":0.001},{"price":11446508.0,"size":0.001},{"price":11447000.0,"size":0.01},{"price":11447071.0,"size":0.002},{"price":11448000.0,"size":0.0875},{"price":11448700.0,"size":0.001},{"price":11450000.0,"size":0.258},{"price":11451105.0,"size":0.002},{"price":11453321.0,"size":0.03},{"price":11455702.0,"size":0.002},{"price":11455883.0,"size":0.001},{"price":11458700.0,"size":0.001},{"price":11458988.0,"size":0.01},{"price":11460000.0,"size":0.01702},{"price":11460299.0,"size":0.002},{"price":11464896.0,"size":0.002},{"price":11467217.0,"size":0.001},{"price":11468700.0,"size":0.001},{"price":11470000.0,"size":0.01},{"price":11471000.0,"size":0.01},{"price":11475000.0,"size":0.0028},{"price":11478431.0,"size":0.002},{"price":11478551.0,"size":0.001},{"price":11478700.0,"size":0.001},{"price":11480000.0,"size":0.12491},{"price":11485000.0,"size":0.01},{"price":11486555.0,"size":0.03},{"price":11487685.0,"size":0.01},{"price":11488000.0,"size":0.102},{"price":11488700.0,"size":0.001},{"price":11489885.0,"size":0.001},{"price":11490841.0,"size":0.002},{"price":11495450.0,"size":0.002},{"price":11495850.0,"size":0.001},{"price":11498700.0,"size":0.001},{"price":11498917.0,"size":0.002},{"price":11499000.0,"size":0.01},{"price":11500000.0,"size":0.46859519},{"price":11501219.0,"size":0.001},{"price":11502377.0,"size":0.002},{"price":11502800.0,"size":0.00132},{"price":11503108.0,"size":0.0198},{"price":11505000.0,"size":0.0028},{"price":11505001.0,"size":0.002},{"price":11505836.0,"size":0.003},{"price":11508431.0,"size":0.047},{"price":11508700.0,"size":0.001},{"price":11508888.0,"size":0.02},{"price":11510000.0,"size":0.0976},{"price":11512553.0,"size":0.001},{"price":11513633.0,"size":0.08},{"price":11514332.0,"size":0.02},{"price":11518700.0,"size":0.001},{"price":11518992.0,"size":0.002},{"price":11519855.0,"size":0.01},{"price":11520000.0,"size":0.001},{"price":11522423.0,"size":0.97},{"price":11523211.0,"size":0.01},{"price":11523887.0,"size":0.001},{"price":11524999.0,"size":0.001},{"price":11528700.0,"size":0.001},{"price":11529852.0,"size":0.01},{"price":11530000.0,"size":0.261},{"price":11533985.0,"size":0.002},{"price":11534084.0,"size":0.001},{"price":11535321.0,"size":0.01},{"price":11538666.0,"size":0.002},{"price":11538700.0,"size":0.001},{"price":11540000.0,"size":0.0048},{"price":11540357.0,"size":0.002},{"price":11541011.0,"size":0.005},{"price":11541109.0,"size":0.01},{"price":11544663.0,"size":0.002},{"price":11545262.0,"size":0.002},{"price":11546541.0,"size":0.01},{"price":11548144.0,"size":0.002},{"price":11548700.0,"size":0.001},{"price":11550000.0,"size":0.014},{"price":11551109.0,"size":0.01},{"price":11551625.0,"size":0.002},{"price":11552111.0,"size":0.01},{"price":11553687.0,"size":0.1},{"price":11555106.0,"size":0.002},{"price":11555115.0,"size":0.001},{"price":11556000.0,"size":0.1},{"price":11558587.0,"size":0.002},{"price":11558700.0,"size":0.001},{"price":11559855.0,"size":0.01},{"price":11560831.0,"size":0.0198},{"price":11561109.0,"size":0.01},{"price":11562000.0,"size":0.087},{"price":11562068.0,"size":0.002},{"price":11565548.0,"size":0.002},{"price":11566139.0,"size":0.0228},{"price":11566551.0,"size":0.01},{"price":11568700.0,"size":0.001},{"price":11569029.0,"size":0.002},{"price":11570196.0,"size":0.002},{"price":11571109.0,"size":0.01},{"price":11572510.0,"size":0.002},{"price":11573211.0,"size":0.01},{"price":11574840.0,"size":0.002},{"price":11575991.0,"size":0.001},{"price":11578700.0,"size":0.001},{"price":11579484.0,"size":0.002},{"price":11579851.0,"size":0.01},{"price":11580000.0,"size":0.7735},{"price":11581109.0,"size":0.01},{"price":11584128.0,"size":0.002},{"price":11585000.0,"size":0.002},{"price":11586532.0,"size":0.01},{"price":11587498.0,"size":0.0198},{"price":11588700.0,"size":0.001},{"price":11589612.0,"size":0.012},{"price":11590000.0,"size":0.1},{"price":11590749.0,"size":0.002},{"price":11591109.0,"size":0.01},{"price":11593211.0,"size":0.01},{"price":11596753.0,"size":0.002},{"price":11598555.0,"size":0.01},{"price":11598700.0,"size":0.001},{"price":11599999.0,"size":0.001},{"price":11600000.0,"size":3.6141},{"price":11601109.0,"size":0.02},{"price":11606655.0,"size":0.01},{"price":11610000.0,"size":0.302},{"price":11611109.0,"size":0.01},{"price":11613321.0,"size":0.01},{"price":11620000.0,"size":1.35441682},{"price":11621011.0,"size":0.01},{"price":11621109.0,"size":0.01},{"price":11623096.0,"size":0.008},{"price":11629000.0,"size":0.1},{"price":11630000.0,"size":0.201},{"price":11631059.0,"size":0.01},{"price":11631479.0,"size":0.01},{"price":11631773.0,"size":0.00386871},{"price":11635950.0,"size":0.001},{"price":11638259.0,"size":0.001},{"price":11639700.0,"size":0.001},{"price":11640000.0,"size":1.0},{"price":11640820.0,"size":0.01},{"price":11641651.0,"size":2.0},{"price":11645295.0,"size":0.05},{"price":11647158.0,"size":0.05},{"price":11649900.0,"size":0.02906},{"price":11649999.0,"size":0.001},{"price":11650000.0,"size":0.593},{"price":11651059.0,"size":0.01},{"price":11653658.0,"size":0.008},{"price":11654321.0,"size":0.001},{"price":11659700.0,"size":0.001},{"price":11661479.0,"size":0.01},{"price":11666000.0,"size":0.001},{"price":11666666.0,"size":0.013},{"price":11669700.0,"size":0.001},{"price":11671059.0,"size":0.01},{"price":11672562.0,"size":0.0198},{"price":11679224.0,"size":0.012},{"price":11680000.0,"size":0.004},{"price":11685000.0,"size":0.003},{"price":11688000.0,"size":0.001},{"price":11689732.0,"size":0.01},{"price":11690330.0,"size":0.0198},{"price":11691059.0,"size":0.01},{"price":11692558.0,"size":0.01},{"price":11698800.0,"size":0.00131},{"price":11699000.0,"size":0.001},{"price":11699631.0,"size":0.001},{"price":11699998.0,"size":0.01},{"price":11699999.0,"size":0.001},{"price":11700000.0,"size":1.03762841},{"price":11701059.0,"size":0.01},{"price":11720000.0,"size":0.1},{"price":11721059.0,"size":0.01},{"price":11725000.0,"size":0.005},{"price":11726791.0,"size":0.01},{"price":11730000.0,"size":0.9382},{"price":11740000.0,"size":0.101},{"price":11741059.0,"size":0.01},{"price":11748937.0,"size":0.001},{"price":11749999.0,"size":0.001}]}}}
{"schema_version":"collector.vnext.raw","schema_contract":null,"schema_contract_version":null,"payload_contract_version":null,"record_type":"market.orderbook.diff","record_id":"collector_main-market-orderbook-diff-000000000061","collector_id":"collector_main","collector_role":"production","host_name":"MAIN-PC","session_id":"collector_main-sess-20260314T201351Z-eb54378f","stream_session_id":"collector_main-stream-bitflyer-board_ws-20260314T201419Z-afd1971d","exchange":"bitflyer","market":"spot","symbol":"BTC_JPY","instrument_id":"bitflyer.spot.BTC_JPY","channel":"board_ws","transport":"websocket","source_event_id":null,"source_sequence":null,"sequence_id":61,"exchange_ts":null,"collector_ts":"2026-03-14T20:14:19Z","ingest_ts":"2026-03-14T20:14:19Z","event_ts":"2026-03-14T20:14:19Z","quality_flags":[],"is_partial":false,"is_reconstructed":false,"confidence_score":1.0,"payload":{"provider":"bitflyer_ws_board","exchange":"bitflyer","transport":"websocket","channel":"lightning_board_BTC_JPY","received_ts":"2026-03-14T20:14:19.360991Z","subscription_id":null,"message_id":null,"source_sequence":null,"raw_message_meta":{"raw_channel":"lightning_board_BTC_JPY","subscription_channel":"lightning_board_BTC_JPY","recv_timeout_sec":10,"ssl_verify":false,"socket_url":"wss://ws.lightstream.bitflyer.com/json-rpc"},"source_payload":{"mid_price":11303676.0,"bids":[{"price":11301833.0,"size":0.0},{"price":11301576.0,"size":0.0}],"asks":[{"price":11319150.0,"size":0.0},{"price":11307909.0,"size":0.0}]}}}
{"schema_version":"collector.vnext.raw","schema_contract":null,"schema_contract_version":null,"payload_contract_version":null,"record_type":"market.orderbook.diff","record_id":"collector_main-market-orderbook-diff-000000000065","collector_id":"collector_main","collector_role":"production","host_name":"MAIN-PC","session_id":"collector_main-sess-20260314T201351Z-eb54378f","stream_session_id":"collector_main-stream-bitflyer-board_ws-20260314T201419Z-afd1971d","exchange":"bitflyer","market":"spot","symbol":"BTC_JPY","instrument_id":"bitflyer.spot.BTC_JPY","channel":"board_ws","transport":"websocket","source_event_id":null,"source_sequence":null,"sequence_id":65,"exchange_ts":null,"collector_ts":"2026-03-14T20:14:19Z","ingest_ts":"2026-03-14T20:14:19Z","event_ts":"2026-03-14T20:14:19Z","quality_flags":[],"is_partial":false,"is_reconstructed":false,"confidence_score":1.0,"payload":{"provider":"bitflyer_ws_board","exchange":"bitflyer","transport":"websocket","channel":"lightning_board_BTC_JPY","received_ts":"2026-03-14T20:14:19.475515Z","subscription_id":null,"message_id":null,"source_sequence":null,"raw_message_meta":{"raw_channel":"lightning_board_BTC_JPY","subscription_channel":"lightning_board_BTC_JPY","recv_timeout_sec":10,"ssl_verify":false,"socket_url":"wss://ws.lightstream.bitflyer.com/json-rpc"},"source_payload":{"mid_price":11303676.0,"bids":[],"asks":[{"price":11319151.0,"size":0.2},{"price":11323189.0,"size":0.0}]}}}
{"schema_version":"collector.vnext.raw","schema_contract":null,"schema_contract_version":null,"payload_contract_version":null,"record_type":"market.orderbook.diff","record_id":"collector_main-market-orderbook-diff-000000000067","collector_id":"collector_main","collector_role":"production","host_name":"MAIN-PC","session_id":"collector_main-sess-20260314T201351Z-eb54378f","stream_session_id":"collector_main-stream-bitflyer-board_ws-20260314T201419Z-afd1971d","exchange":"bitflyer","market":"spot","symbol":"BTC_JPY","instrument_id":"bitflyer.spot.BTC_JPY","channel":"board_ws","transport":"websocket","source_event_id":null,"source_sequence":null,"sequence_id":67,"exchange_ts":null,"collector_ts":"2026-03-14T20:14:19Z","ingest_ts":"2026-03-14T20:14:19Z","event_ts":"2026-03-14T20:14:19Z","quality_flags":[],"is_partial":false,"is_reconstructed":false,"confidence_score":1.0,"payload":{"provider":"bitflyer_ws_board","exchange":"bitflyer","transport":"websocket","channel":"lightning_board_BTC_JPY","received_ts":"2026-03-14T20:14:19.588989Z","subscription_id":null,"message_id":null,"source_sequence":null,"raw_message_meta":{"raw_channel":"lightning_board_BTC_JPY","subscription_channel":"lightning_board_BTC_JPY","recv_timeout_sec":10,"ssl_verify":false,"socket_url":"wss://ws.lightstream.bitflyer.com/json-rpc"},"source_payload":{"mid_price":11303676.0,"bids":[{"price":11301868.0,"size":0.0}],"asks":[{"price":11323190.0,"size":0.0142595},{"price":11307908.0,"size":0.0}]}}}
{"schema_version":"collector.vnext.raw","schema_contract":null,"schema_contract_version":null,"payload_contract_version":null,"record_type":"market.orderbook.diff","record_id":"collector_main-market-orderbook-diff-000000000069","collector_id":"collector_main","collector_role":"production","host_name":"MAIN-PC","session_id":"collector_main-sess-20260314T201351Z-eb54378f","stream_session_id":"collector_main-stream-bitflyer-board_ws-20260314T201419Z-afd1971d","exchange":"bitflyer","market":"spot","symbol":"BTC_JPY","instrument_id":"bitflyer.spot.BTC_JPY","channel":"board_ws","transport":"websocket","source_event_id":null,"source_sequence":null,"sequence_id":69,"exchange_ts":null,"collector_ts":"2026-03-14T20:14:19Z","ingest_ts":"2026-03-14T20:14:19Z","event_ts":"2026-03-14T20:14:19Z","quality_flags":[],"is_partial":false,"is_reconstructed":false,"confidence_score":1.0,"payload":{"provider":"bitflyer_ws_board","exchange":"bitflyer","transport":"websocket","channel":"lightning_board_BTC_JPY","received_ts":"2026-03-14T20:14:19.751820Z","subscription_id":null,"message_id":null,"source_sequence":null,"raw_message_meta":{"raw_channel":"lightning_board_BTC_JPY","subscription_channel":"lightning_board_BTC_JPY","recv_timeout_sec":10,"ssl_verify":false,"socket_url":"wss://ws.lightstream.bitflyer.com/json-rpc"},"source_payload":{"mid_price":11303659.0,"bids":[{"price":11301869.0,"size":0.0}],"asks":[{"price":11455702.0,"size":0.002}]}}}
{"schema_version":"collector.vnext.raw","schema_contract":null,"schema_contract_version":null,"payload_contract_version":null,"record_type":"market.orderbook.diff","record_id":"collector_main-market-orderbook-diff-000000000071","collector_id":"collector_main","collector_role":"production","host_name":"MAIN-PC","session_id":"collector_main-sess-20260314T201351Z-eb54378f","stream_session_id":"collector_main-stream-bitflyer-board_ws-20260314T201419Z-afd1971d","exchange":"bitflyer","market":"spot","symbol":"BTC_JPY","instrument_id":"bitflyer.spot.BTC_JPY","channel":"board_ws","transport":"websocket","source_event_id":null,"source_sequence":null,"sequence_id":71,"exchange_ts":null,"collector_ts":"2026-03-14T20:14:19Z","ingest_ts":"2026-03-14T20:14:19Z","event_ts":"2026-03-14T20:14:19Z","quality_flags":[],"is_partial":false,"is_reconstructed":false,"confidence_score":1.0,"payload":{"provider":"bitflyer_ws_board","exchange":"bitflyer","transport":"websocket","channel":"lightning_board_BTC_JPY","received_ts":"2026-03-14T20:14:19.875678Z","subscription_id":null,"message_id":null,"source_sequence":null,"raw_message_meta":{"raw_channel":"lightning_board_BTC_JPY","subscription_channel":"lightning_board_BTC_JPY","recv_timeout_sec":10,"ssl_verify":false,"socket_url":"wss://ws.lightstream.bitflyer.com/json-rpc"},"source_payload":{"mid_price":11303659.0,"bids":[{"price":11301835.0,"size":0.05226449}],"asks":[]}}}
{"schema_version":"collector.vnext.raw","schema_contract":null,"schema_contract_version":null,"payload_contract_version":null,"record_type":"market.orderbook.diff","record_id":"collector_main-market-orderbook-diff-000000000073","collector_id":"collector_main","collector_role":"production","host_name":"MAIN-PC","session_id":"collector_main-sess-20260314T201351Z-eb54378f","stream_session_id":"collector_main-stream-bitflyer-board_ws-20260314T201419Z-afd1971d","exchange":"bitflyer","market":"spot","symbol":"BTC_JPY","instrument_id":"bitflyer.spot.BTC_JPY","channel":"board_ws","transport":"websocket","source_event_id":null,"source_sequence":null,"sequence_id":73,"exchange_ts":null,"collector_ts":"2026-03-14T20:14:19Z","ingest_ts":"2026-03-14T20:14:19Z","event_ts":"2026-03-14T20:14:19Z","quality_flags":[],"is_partial":false,"is_reconstructed":false,"confidence_score":1.0,"payload":{"provider":"bitflyer_ws_board","exchange":"bitflyer","transport":"websocket","channel":"lightning_board_BTC_JPY","received_ts":"2026-03-14T20:14:19.985409Z","subscription_id":null,"message_id":null,"source_sequence":null,"raw_message_meta":{"raw_channel":"lightning_board_BTC_JPY","subscription_channel":"lightning_board_BTC_JPY","recv_timeout_sec":10,"ssl_verify":false,"socket_url":"wss://ws.lightstream.bitflyer.com/json-rpc"},"source_payload":{"mid_price":11303659.0,"bids":[{"price":11300539.0,"size":0.0176965}],"asks":[]}}}
{"schema_version":"collector.vnext.raw","schema_contract":null,"schema_contract_version":null,"payload_contract_version":null,"record_type":"market.orderbook.diff","record_id":"collector_main-market-orderbook-diff-000000000075","collector_id":"collector_main","collector_role":"production","host_name":"MAIN-PC","session_id":"collector_main-sess-20260314T201351Z-eb54378f","stream_session_id":"collector_main-stream-bitflyer-board_ws-20260314T201419Z-afd1971d","exchange":"bitflyer","market":"spot","symbol":"BTC_JPY","instrument_id":"bitflyer.spot.BTC_JPY","channel":"board_ws","transport":"websocket","source_event_id":null,"source_sequence":null,"sequence_id":75,"exchange_ts":null,"collector_ts":"2026-03-14T20:14:20Z","ingest_ts":"2026-03-14T20:14:20Z","event_ts":"2026-03-14T20:14:20Z","quality_flags":[],"is_partial":false,"is_reconstructed":false,"confidence_score":1.0,"payload":{"provider":"bitflyer_ws_board","exchange":"bitflyer","transport":"websocket","channel":"lightning_board_BTC_JPY","received_ts":"2026-03-14T20:14:20.094711Z","subscription_id":null,"message_id":null,"source_sequence":null,"raw_message_meta":{"raw_channel":"lightning_board_BTC_JPY","subscription_channel":"lightning_board_BTC_JPY","recv_timeout_sec":10,"ssl_verify":false,"socket_url":"wss://ws.lightstream.bitflyer.com/json-rpc"},"source_payload":{"mid_price":11303659.0,"bids":[{"price":11291747.0,"size":0.0}],"asks":[]}}}
{"schema_version":"collector.vnext.raw","schema_contract":null,"schema_contract_version":null,"payload_contract_version":null,"record_type":"market.orderbook.diff","record_id":"collector_main-market-orderbook-diff-000000000077","collector_id":"collector_main","collector_role":"production","host_name":"MAIN-PC","session_id":"collector_main-sess-20260314T201351Z-eb54378f","stream_session_id":"collector_main-stream-bitflyer-board_ws-20260314T201419Z-afd1971d","exchange":"bitflyer","market":"spot","symbol":"BTC_JPY","instrument_id":"bitflyer.spot.BTC_JPY","channel":"board_ws","transport":"websocket","source_event_id":null,"source_sequence":null,"sequence_id":77,"exchange_ts":null,"collector_ts":"2026-03-14T20:14:20Z","ingest_ts":"2026-03-14T20:14:20Z","event_ts":"2026-03-14T20:14:20Z","quality_flags":[],"is_partial":false,"is_reconstructed":false,"confidence_score":1.0,"payload":{"provider":"bitflyer_ws_board","exchange":"bitflyer","transport":"websocket","channel":"lightning_board_BTC_JPY","received_ts":"2026-03-14T20:14:20.360436Z","subscription_id":null,"message_id":null,"source_sequence":null,"raw_message_meta":{"raw_channel":"lightning_board_BTC_JPY","subscription_channel":"lightning_board_BTC_JPY","recv_timeout_sec":10,"ssl_verify":false,"socket_url":"wss://ws.lightstream.bitflyer.com/json-rpc"},"source_payload":{"mid_price":11303659.0,"bids":[{"price":11292331.0,"size":0.00999859}],"asks":[]}}}
{"schema_version":"collector.vnext.raw","schema_contract":null,"schema_contract_version":null,"payload_contract_version":null,"record_type":"market.orderbook.diff","record_id":"collector_main-market-orderbook-diff-000000000079","collector_id":"collector_main","collector_role":"production","host_name":"MAIN-PC","session_id":"collector_main-sess-20260314T201351Z-eb54378f","stream_session_id":"collector_main-stream-bitflyer-board_ws-20260314T201419Z-afd1971d","exchange":"bitflyer","market":"spot","symbol":"BTC_JPY","instrument_id":"bitflyer.spot.BTC_JPY","channel":"board_ws","transport":"websocket","source_event_id":null,"source_sequence":null,"sequence_id":79,"exchange_ts":null,"collector_ts":"2026-03-14T20:14:20Z","ingest_ts":"2026-03-14T20:14:20Z","event_ts":"2026-03-14T20:14:20Z","quality_flags":[],"is_partial":false,"is_reconstructed":false,"confidence_score":1.0,"payload":{"provider":"bitflyer_ws_board","exchange":"bitflyer","transport":"websocket","channel":"lightning_board_BTC_JPY","received_ts":"2026-03-14T20:14:20.594830Z","subscription_id":null,"message_id":null,"source_sequence":null,"raw_message_meta":{"raw_channel":"lightning_board_BTC_JPY","subscription_channel":"lightning_board_BTC_JPY","recv_timeout_sec":10,"ssl_verify":false,"socket_url":"wss://ws.lightstream.bitflyer.com/json-rpc"},"source_payload":{"mid_price":11303723.0,"bids":[{"price":11301963.0,"size":0.1275}],"asks":[{"price":11308181.0,"size":0.1275}]}}}
{"schema_version":"collector.vnext.raw","schema_contract":null,"schema_contract_version":null,"payload_contract_version":null,"record_type":"market.orderbook.diff","record_id":"collector_main-market-orderbook-diff-000000000081","collector_id":"collector_main","collector_role":"production","host_name":"MAIN-PC","session_id":"collector_main-sess-20260314T201351Z-eb54378f","stream_session_id":"collector_main-stream-bitflyer-board_ws-20260314T201419Z-afd1971d","exchange":"bitflyer","market":"spot","symbol":"BTC_JPY","instrument_id":"bitflyer.spot.BTC_JPY","channel":"board_ws","transport":"websocket","source_event_id":null,"source_sequence":null,"sequence_id":81,"exchange_ts":null,"collector_ts":"2026-03-14T20:14:20Z","ingest_ts":"2026-03-14T20:14:20Z","event_ts":"2026-03-14T20:14:20Z","quality_flags":[],"is_partial":false,"is_reconstructed":false,"confidence_score":1.0,"payload":{"provider":"bitflyer_ws_board","exchange":"bitflyer","transport":"websocket","channel":"lightning_board_BTC_JPY","received_ts":"2026-03-14T20:14:20.687930Z","subscription_id":null,"message_id":null,"source_sequence":null,"raw_message_meta":{"raw_channel":"lightning_board_BTC_JPY","subscription_channel":"lightning_board_BTC_JPY","recv_timeout_sec":10,"ssl_verify":false,"socket_url":"wss://ws.lightstream.bitflyer.com/json-rpc"},"source_payload":{"mid_price":11303723.0,"bids":[{"price":11301835.0,"size":0.0},{"price":11300539.0,"size":0.0}],"asks":[]}}}
{"schema_version":"collector.vnext.raw","schema_contract":null,"schema_contract_version":null,"payload_contract_version":null,"record_type":"market.orderbook.diff","record_id":"collector_main-market-orderbook-diff-000000000083","collector_id":"collector_main","collector_role":"production","host_name":"MAIN-PC","session_id":"collector_main-sess-20260314T201351Z-eb54378f","stream_session_id":"collector_main-stream-bitflyer-board_ws-20260314T201419Z-afd1971d","exchange":"bitflyer","market":"spot","symbol":"BTC_JPY","instrument_id":"bitflyer.spot.BTC_JPY","channel":"board_ws","transport":"websocket","source_event_id":null,"source_sequence":null,"sequence_id":83,"exchange_ts":null,"collector_ts":"2026-03-14T20:14:20Z","ingest_ts":"2026-03-14T20:14:20Z","event_ts":"2026-03-14T20:14:20Z","quality_flags":[],"is_partial":false,"is_reconstructed":false,"confidence_score":1.0,"payload":{"provider":"bitflyer_ws_board","exchange":"bitflyer","transport":"websocket","channel":"lightning_board_BTC_JPY","received_ts":"2026-03-14T20:14:20.869792Z","subscription_id":null,"message_id":null,"source_sequence":null,"raw_message_meta":{"raw_channel":"lightning_board_BTC_JPY","subscription_channel":"lightning_board_BTC_JPY","recv_timeout_sec":10,"ssl_verify":false,"socket_url":"wss://ws.lightstream.bitflyer.com/json-rpc"},"source_payload":{"mid_price":11303755.0,"bids":[{"price":11301964.0,"size":0.05228517},{"price":11302027.0,"size":0.1275}],"asks":[{"price":11319151.0,"size":0.0}]}}}
{"schema_version":"collector.vnext.raw","schema_contract":null,"schema_contract_version":null,"payload_contract_version":null,"record_type":"market.orderbook.diff","record_id":"collector_main-market-orderbook-diff-000000000085","collector_id":"collector_main","collector_role":"production","host_name":"MAIN-PC","session_id":"collector_main-sess-20260314T201351Z-eb54378f","stream_session_id":"collector_main-stream-bitflyer-board_ws-20260314T201419Z-afd1971d","exchange":"bitflyer","market":"spot","symbol":"BTC_JPY","instrument_id":"bitflyer.spot.BTC_JPY","channel":"board_ws","transport":"websocket","source_event_id":null,"source_sequence":null,"sequence_id":85,"exchange_ts":null,"collector_ts":"2026-03-14T20:14:20Z","ingest_ts":"2026-03-14T20:14:20Z","event_ts":"2026-03-14T20:14:20Z","quality_flags":[],"is_partial":false,"is_reconstructed":false,"confidence_score":1.0,"payload":{"provider":"bitflyer_ws_board","exchange":"bitflyer","transport":"websocket","channel":"lightning_board_BTC_JPY","received_ts":"2026-03-14T20:14:20.999578Z","subscription_id":null,"message_id":null,"source_sequence":null,"raw_message_meta":{"raw_channel":"lightning_board_BTC_JPY","subscription_channel":"lightning_board_BTC_JPY","recv_timeout_sec":10,"ssl_verify":false,"socket_url":"wss://ws.lightstream.bitflyer.com/json-rpc"},"source_payload":{"mid_price":11303755.0,"bids":[],"asks":[{"price":11319150.0,"size":0.0565876},{"price":11460299.0,"size":0.002},{"price":11323190.0,"size":0.0}]}}}
{"schema_version":"collector.vnext.raw","schema_contract":null,"schema_contract_version":null,"payload_contract_version":null,"record_type":"market.orderbook.diff","record_id":"collector_main-market-orderbook-diff-000000000087","collector_id":"collector_main","collector_role":"production","host_name":"MAIN-PC","session_id":"collector_main-sess-20260314T201351Z-eb54378f","stream_session_id":"collector_main-stream-bitflyer-board_ws-20260314T201419Z-afd1971d","exchange":"bitflyer","market":"spot","symbol":"BTC_JPY","instrument_id":"bitflyer.spot.BTC_JPY","channel":"board_ws","transport":"websocket","source_event_id":null,"source_sequence":null,"sequence_id":87,"exchange_ts":null,"collector_ts":"2026-03-14T20:14:21Z","ingest_ts":"2026-03-14T20:14:21Z","event_ts":"2026-03-14T20:14:21Z","quality_flags":[],"is_partial":false,"is_reconstructed":false,"confidence_score":1.0,"payload":{"provider":"bitflyer_ws_board","exchange":"bitflyer","transport":"websocket","channel":"lightning_board_BTC_JPY","received_ts":"2026-03-14T20:14:21.115849Z","subscription_id":null,"message_id":null,"source_sequence":null,"raw_message_meta":{"raw_channel":"lightning_board_BTC_JPY","subscription_channel":"lightning_board_BTC_JPY","recv_timeout_sec":10,"ssl_verify":false,"socket_url":"wss://ws.lightstream.bitflyer.com/json-rpc"},"source_payload":{"mid_price":11303756.0,"bids":[{"price":11301964.0,"size":0.0},{"price":11302028.0,"size":0.04963906}],"asks":[{"price":11323189.0,"size":0.0142595}]}}}
{"schema_version":"collector.vnext.raw","schema_contract":null,"schema_contract_version":null,"payload_contract_version":null,"record_type":"market.orderbook.snapshot","record_id":"collector_main-market-orderbook-snapshot-000000000089","collector_id":"collector_main","collector_role":"production","host_name":"MAIN-PC","session_id":"collector_main-sess-20260314T201351Z-eb54378f","stream_session_id":"collector_main-stream-bitflyer-board_ws-20260314T201419Z-afd1971d","exchange":"bitflyer","market":"spot","symbol":"BTC_JPY","instrument_id":"bitflyer.spot.BTC_JPY","channel":"board_ws","transport":"websocket","source_event_id":null,"source_sequence":null,"sequence_id":89,"exchange_ts":null,"collector_ts":"2026-03-14T20:14:21Z","ingest_ts":"2026-03-14T20:14:21Z","event_ts":"2026-03-14T20:14:21Z","quality_flags":[],"is_partial":false,"is_reconstructed":false,"confidence_score":1.0,"payload":{"provider":"bitflyer_ws_board_snapshot","exchange":"bitflyer","transport":"websocket","channel":"lightning_board_snapshot_BTC_JPY","received_ts":"2026-03-14T20:14:21.141595Z","subscription_id":null,"message_id":null,"source_sequence":null,"raw_message_meta":{"raw_channel":"lightning_board_snapshot_BTC_JPY","subscription_channel":"lightning_board_snapshot_BTC_JPY","recv_timeout_sec":10,"ssl_verify":false,"socket_url":"wss://ws.lightstream.bitflyer.com/json-rpc"},"source_payload":{"mid_price":11303756.0,"bids":[{"price":11302028.0,"size":0.04963906},{"price":11302027.0,"size":0.1275},{"price":11301999.0,"size":0.0176942},{"price":11301963.0,"size":0.1275},{"price":11301834.0,"size":0.005},{"price":11301015.0,"size":0.00999866},{"price":11300504.0,"size":0.2},{"price":11300004.0,"size":0.015264},{"price":11299661.0,"size":0.01512},{"price":11299134.0,"size":0.02},{"price":11299133.0,"size":0.015024},{"price":11297568.0,"size":0.01},{"price":11297439.0,"size":0.5},{"price":11295763.0,"size":0.05},{"price":11295198.0,"size":0.05},{"price":11294564.0,"size":0.0032582},{"price":11293683.0,"size":2.9748021},{"price":11293682.0,"size":0.053352},{"price":11293357.0,"size":0.5},{"price":11293270.0,"size":0.0801},{"price":11292331.0,"size":0.00999859},{"price":11292244.0,"size":0.048},{"price":11291636.0,"size":0.132},{"price":11290529.0,"size":0.0531},{"price":11289443.0,"size":0.04},{"price":11287378.0,"size":1.50015},{"price":11286651.0,"size":0.98403398},{"price":11280562.0,"size":0.3089},{"price":11280205.0,"size":0.001},{"price":11279434.0,"size":0.6},{"price":11279282.0,"size":0.0015},{"price":11278498.0,"size":0.002},{"price":11277800.0,"size":0.2689},{"price":11277748.0,"size":0.0966561},{"price":11277602.0,"size":0.005},{"price":11275360.0,"size":1.484},{"price":11275106.0,"size":0.002},{"price":11275102.0,"size":0.01},{"price":11275038.0,"size":0.2726},{"price":11275000.0,"size":0.001},{"price":11274589.0,"size":0.16876195},{"price":11274588.0,"size":0.0047},{"price":11272276.0,"size":0.2915},{"price":11271714.0,"size":0.002},{"price":11271000.0,"size":0.003},{"price":11270000.0,"size":0.106},{"price":11268871.0,"size":0.281},{"price":11268411.0,"size":0.01},{"price":11268322.0,"size":0.002},{"price":11266666.0,"size":0.04},{"price":11265879.0,"size":0.6},{"price":11265000.0,"size":0.02},{"price":11264930.0,"size":0.002},{"price":11263999.0,"size":1.966},{"price":11263000.0,"size":0.006},{"price":11262564.0,"size":0.0015},{"price":11261538.0,"size":0.002},{"price":11260000.0,"size":0.3565},{"price":11258146.0,"size":0.002},{"price":11257537.0,"size":0.001},{"price":11257000.0,"size":0.001},{"price":11255200.0,"size":0.001},{"price":11255115.0,"size":0.00377},{"price":11254754.0,"size":0.002},{"price":11253628.0,"size":2.036},{"price":11253000.0,"size":0.03189},{"price":11251362.0,"size":0.002},{"price":11251000.0,"size":0.0131},{"price":11250250.0,"size":0.00105},{"price":11250200.0,"size":0.001},{"price":11250100.0,"size":0.015},{"price":11250005.0,"size":0.001},{"price":11250001.0,"size":0.00104},{"price":11250000.0,"size":0.76834},{"price":11247970.0,"size":0.002},{"price":11246544.0,"size":0.0015},{"price":11246203.0,"size":0.001},{"price":11245141.0,"size":0.0031},{"price":11245000.0,"size":0.05},{"price":11244444.0,"size":0.04},{"price":11244243.0,"size":0.01},{"price":11240200.0,"size":0.001},{"price":11240000.0,"size":0.007304},{"price":11236190.0,"size":0.01},{"price":11235200.0,"size":0.001},{"price":11234869.0,"size":0.001},{"price":11232000.0,"size":0.089},{"price":11231243.0,"size":0.01},{"price":11231000.0,"size":0.105},{"price":11230200.0,"size":0.001},{"price":11230000.0,"size":0.0308},{"price":11228423.0,"size":1.951},{"price":11224500.0,"size":0.06},{"price":11224355.0,"size":0.0015},{"price":11223968.0,"size":0.001},{"price":11223535.0,"size":0.001},{"price":11223344.0,"size":0.01},{"price":11223000.0,"size":0.1},{"price":11222222.0,"size":0.092525},{"price":11221459.0,"size":0.1393},{"price":11221120.0,"size":0.011},{"price":11220200.0,"size":0.001},{"price":11220001.0,"size":0.004457},{"price":11220000.0,"size":0.321},{"price":11219517.0,"size":0.01},{"price":11219000.0,"size":0.1},{"price":11215200.0,"size":0.001},{"price":11215000.0,"size":0.02},{"price":11212713.0,"size":1.79},{"price":11212358.0,"size":1.2},{"price":11212201.0,"size":0.001},{"price":11211800.0,"size":0.001},{"price":11211111.0,"size":0.06},{"price":11210200.0,"size":0.001},{"price":11210000.0,"size":0.10622},{"price":11208032.0,"size":0.01},{"price":11207755.0,"size":0.0015},{"price":11206000.0,"size":0.09015},{"price":11205200.0,"size":0.001},{"price":11204578.0,"size":0.002},{"price":11203931.0,"size":1.0},{"price":11201000.0,"size":0.01},{"price":11200867.0,"size":0.001},{"price":11200800.0,"size":0.05},{"price":11200425.0,"size":0.1},{"price":11200200.0,"size":0.001},{"price":11200198.0,"size":0.003},{"price":11200150.0,"size":0.002},{"price":11200002.0,"size":0.001},{"price":11200001.0,"size":0.01104},{"price":11200000.0,"size":1.35988728},{"price":11198508.0,"size":0.05},{"price":11198243.0,"size":0.01},{"price":11197134.0,"size":2.0},{"price":11197000.0,"size":0.0085},{"price":11195692.0,"size":0.0015},{"price":11194090.0,"size":0.03},{"price":11190770.0,"size":0.0309},{"price":11190000.0,"size":0.0010016},{"price":11189555.0,"size":0.5},{"price":11189533.0,"size":0.001},{"price":11188629.0,"size":0.01},{"price":11188382.0,"size":0.001},{"price":11185000.0,"size":0.0085},{"price":11180043.0,"size":0.972},{"price":11180000.0,"size":0.23215},{"price":11178973.0,"size":0.0015},{"price":11178199.0,"size":0.001},{"price":11170000.0,"size":0.001},{"price":11169662.0,"size":0.01},{"price":11169593.0,"size":0.001},{"price":11169243.0,"size":0.01},{"price":11166865.0,"size":0.001},{"price":11164029.0,"size":0.001},{"price":11160854.0,"size":0.1},{"price":11160000.0,"size":0.02376},{"price":11156269.0,"size":0.01},{"price":11155531.0,"size":0.001},{"price":11155377.0,"size":0.00636009},{"price":11153999.0,"size":0.00101},{"price":11150250.0,"size":0.00175},{"price":11150005.0,"size":0.001},{"price":11150001.0,"size":0.00104},{"price":11150000.0,"size":0.6398956},{"price":11148000.0,"size":0.08963},{"price":11144197.0,"size":0.001},{"price":11144000.0,"size":0.0897},{"price":11140000.0,"size":0.2},{"price":11136243.0,"size":0.01},{"price":11136155.0,"size":0.02},{"price":11135869.0,"size":0.1},{"price":11130000.0,"size":0.116},{"price":11129979.0,"size":0.0053908},{"price":11126388.0,"size":0.02},{"price":11124900.0,"size":0.00133},{"price":11121090.0,"size":0.1},{"price":11120000.0,"size":0.0033},{"price":11118078.0,"size":0.01},{"price":11111800.0,"size":0.001},{"price":11111111.0,"size":0.2919257},{"price":11111000.0,"size":0.003},{"price":11110594.0,"size":0.001},{"price":11110000.0,"size":0.056937},{"price":11109662.0,"size":0.01},{"price":11108008.0,"size":0.01},{"price":11106000.0,"size":0.2},{"price":11105000.0,"size":0.02},{"price":11101297.0,"size":0.001},{"price":11100005.0,"size":0.001},{"price":11100001.0,"size":0.01104},{"price":11100000.0,"size":2.7475049},{"price":11099141.0,"size":0.01},{"price":11096243.0,"size":0.01},{"price":11094090.0,"size":0.01},{"price":11088888.0,"size":0.001},{"price":11085245.0,"size":0.001},{"price":11080200.0,"size":0.001},{"price":11080000.0,"size":0.0223},{"price":11075100.0,"size":0.003},{"price":11071558.0,"size":1.0},{"price":11070200.0,"size":0.001},{"price":11070000.0,"size":0.0902},{"price":11065200.0,"size":0.001},{"price":11064370.0,"size":0.00497091},{"price":11060200.0,"size":0.001},{"price":11060000.0,"size":0.145},{"price":11059689.0,"size":0.009},{"price":11056428.0,"size":0.002},{"price":11055500.0,"size":0.02},{"price":11055200.0,"size":0.001},{"price":11055100.0,"size":0.003},{"price":11050200.0,"size":0.001},{"price":11050005.0,"size":0.001},{"price":11050002.0,"size":0.001},{"price":11050001.0,"size":0.00104},{"price":11050000.0,"size":0.43176147},{"price":11046420.0,"size":0.2},{"price":11044243.0,"size":0.01},{"price":11041380.0,"size":0.01},{"price":11040200.0,"size":0.001},{"price":11040000.0,"size":0.00777181},{"price":11035865.0,"size":0.1},{"price":11035200.0,"size":0.001},{"price":11035000.0,"size":0.0013},{"price":11030200.0,"size":0.001},{"price":11030000.0,"size":0.025},{"price":11025500.0,"size":0.009531},{"price":11025200.0,"size":0.001},{"price":11025000.0,"size":0.71497},{"price":11020772.0,"size":0.014},{"price":11020200.0,"size":0.002},{"price":11020000.0,"size":0.005},{"price":11015200.0,"size":0.001},{"price":11012000.0,"size":0.1},{"price":11011800.0,"size":0.001},{"price":11010200.0,"size":0.001},{"price":11010000.0,"size":0.347},{"price":11007277.0,"size":0.01},{"price":11006000.0,"size":0.2},{"price":11005200.0,"size":0.001},{"price":11004890.0,"size":0.001535},{"price":11003000.0,"size":0.0155},{"price":11001000.0,"size":0.013},{"price":11000500.0,"size":0.05117658},{"price":11000200.0,"size":0.001},{"price":11000002.0,"size":0.004},{"price":11000001.0,"size":0.02604},{"price":11000000.0,"size":5.47323365},{"price":10999999.0,"size":0.003},{"price":10999000.0,"size":0.001},{"price":10996855.0,"size":0.0011},{"price":10995200.0,"size":0.001},{"price":10994499.0,"size":0.00169176},{"price":10990200.0,"size":0.001},{"price":10990000.0,"size":0.10219},{"price":10989001.0,"size":0.00197},{"price":10988999.0,"size":0.001},{"price":10988324.0,"size":0.002},{"price":10987654.0,"size":0.001},{"price":10985200.0,"size":0.001},{"price":10985150.0,"size":0.01},{"price":10980500.0,"size":0.005},{"price":10980200.0,"size":0.001},{"price":10980002.0,"size":0.4},{"price":10980000.0,"size":0.028},{"price":10975200.0,"size":0.001},{"price":10975000.0,"size":0.1},{"price":10971261.0,"size":0.001},{"price":10971243.0,"size":0.01},{"price":10970375.0,"size":1.9},{"price":10970200.0,"size":0.001},{"price":10970000.0,"size":0.09304},{"price":10966600.0,"size":0.001003},{"price":10965200.0,"size":0.001},{"price":10960200.0,"size":0.001},{"price":10960000.0,"size":0.0083},{"price":10956673.0,"size":0.01},{"price":10955200.0,"size":0.001},{"price":10954950.0,"size":0.001},{"price":10950500.0,"size":0.005},{"price":10950001.0,"size":0.00204},{"price":10950000.0,"size":0.5485028},{"price":10949550.0,"size":0.01870657},{"price":10949172.0,"size":0.1},{"price":10948000.0,"size":0.1},{"price":10945243.0,"size":0.01},{"price":10940402.0,"size":0.001},{"price":10940200.0,"size":0.001},{"price":10940000.0,"size":0.331},{"price":10938243.0,"size":0.01},{"price":10936200.0,"size":0.00137},{"price":10935200.0,"size":0.001},{"price":10930200.0,"size":0.002},{"price":10930000.0,"size":0.0193},{"price":10925200.0,"size":0.002},{"price":10924451.0,"size":0.0012},{"price":10920509.0,"size":0.01},{"price":10920200.0,"size":0.002},{"price":10920000.0,"size":0.52},{"price":10915200.0,"size":0.001}],"asks":[{"price":11305484.0,"size":0.05658763},{"price":11307388.0,"size":0.04672708},{"price":11307389.0,"size":0.02},{"price":11307390.0,"size":0.01000118},{"price":11308181.0,"size":0.1275},{"price":11308243.0,"size":0.02},{"price":11308244.0,"size":0.2917},{"price":11308930.0,"size":0.02},{"price":11309329.0,"size":0.02},{"price":11310444.0,"size":0.02},{"price":11310637.0,"size":0.053352},{"price":11311005.0,"size":0.02},{"price":11311006.0,"size":0.2778},{"price":11311681.0,"size":0.015492},{"price":11312048.0,"size":0.01506},{"price":11312720.0,"size":0.4199},{"price":11313655.0,"size":0.57620824},{"price":11313658.0,"size":0.01},{"price":11313768.0,"size":0.258},{"price":11313957.0,"size":0.014772},{"price":11316530.0,"size":0.2806},{"price":11316606.0,"size":0.053},{"price":11318050.0,"size":0.002},{"price":11318640.0,"size":0.01},{"price":11319150.0,"size":0.0565876},{"price":11320000.0,"size":0.02},{"price":11322000.0,"size":0.005},{"price":11323189.0,"size":0.0142595},{"price":11323556.0,"size":1.189881},{"price":11323581.0,"size":1.189881},{"price":11328050.0,"size":0.002},{"price":11329436.0,"size":0.0015},{"price":11331059.0,"size":0.001},{"price":11334237.0,"size":1.489},{"price":11340000.0,"size":0.13586406},{"price":11340647.0,"size":0.001},{"price":11342956.0,"size":1.60199848},{"price":11342957.0,"size":0.01},{"price":11343043.0,"size":1.928},{"price":11346154.0,"size":0.0015},{"price":11348000.0,"size":0.1999},{"price":11349700.0,"size":0.001},{"price":11350000.0,"size":0.022},{"price":11353877.0,"size":0.001},{"price":11354939.0,"size":0.01},{"price":11355555.0,"size":0.001},{"price":11358323.0,"size":2.018},{"price":11359242.0,"size":0.0011},{"price":11359700.0,"size":0.001},{"price":11362692.0,"size":0.0015},{"price":11365211.0,"size":0.001},{"price":11369700.0,"size":0.001},{"price":11370000.0,"size":0.1},{"price":11372478.0,"size":1.943},{"price":11376000.0,"size":0.02},{"price":11376545.0,"size":0.001},{"price":11377000.0,"size":0.2287},{"price":11377269.0,"size":0.002},{"price":11379700.0,"size":0.001},{"price":11379865.0,"size":0.03},{"price":11380000.0,"size":0.0223},{"price":11380324.0,"size":0.002},{"price":11381766.0,"size":0.4},{"price":11382386.0,"size":0.0015},{"price":11385000.0,"size":0.2548},{"price":11385403.0,"size":0.002},{"price":11385664.0,"size":0.002},{"price":11387072.0,"size":0.01},{"price":11387354.0,"size":0.002},{"price":11387879.0,"size":0.001},{"price":11388885.0,"size":0.03},{"price":11389700.0,"size":0.001},{"price":11390000.0,"size":0.2488},{"price":11390050.0,"size":0.001},{"price":11392387.0,"size":1.0},{"price":11394939.0,"size":0.01},{"price":11395000.0,"size":0.06},{"price":11395775.0,"size":0.01},{"price":11396555.0,"size":0.03},{"price":11398444.0,"size":0.001995},{"price":11399213.0,"size":0.001},{"price":11399673.0,"size":0.0015},{"price":11399700.0,"size":0.001},{"price":11400000.0,"size":0.5525},{"price":11405000.0,"size":0.0275},{"price":11406336.0,"size":1.0},{"price":11408700.0,"size":0.001},{"price":11409415.0,"size":0.055},{"price":11410000.0,"size":0.03},{"price":11410547.0,"size":0.001},{"price":11410853.0,"size":0.002},{"price":11412000.0,"size":0.0878},{"price":11415000.0,"size":0.002},{"price":11415141.0,"size":0.0041},{"price":11417481.0,"size":0.0015},{"price":11418700.0,"size":0.001},{"price":11420000.0,"size":0.401},{"price":11421268.0,"size":0.05},{"price":11421881.0,"size":0.001},{"price":11423339.0,"size":2.0},{"price":11424296.0,"size":0.002},{"price":11424941.0,"size":0.972},{"price":11425000.0,"size":0.049},{"price":11426426.0,"size":0.002},{"price":11428121.0,"size":0.002},{"price":11428700.0,"size":0.001},{"price":11429302.0,"size":0.01},{"price":11432718.0,"size":0.002},{"price":11433211.0,"size":0.03},{"price":11433215.0,"size":0.001},{"price":11433333.0,"size":0.001},{"price":11437315.0,"size":0.002},{"price":11438525.0,"size":0.0011},{"price":11438700.0,"size":0.001},{"price":11439557.0,"size":0.001},{"price":11440000.0,"size":0.1038},{"price":11441911.0,"size":0.002},{"price":11443629.0,"size":0.002},{"price":11444549.0,"size":0.001},{"price":11446508.0,"size":0.001},{"price":11447000.0,"size":0.01},{"price":11447071.0,"size":0.002},{"price":11448000.0,"size":0.0875},{"price":11448700.0,"size":0.001},{"price":11450000.0,"size":0.258},{"price":11451105.0,"size":0.002},{"price":11453321.0,"size":0.03},{"price":11455702.0,"size":0.002},{"price":11455883.0,"size":0.001},{"price":11458700.0,"size":0.001},{"price":11458988.0,"size":0.01},{"price":11460000.0,"size":0.01702},{"price":11460299.0,"size":0.002},{"price":11467217.0,"size":0.001},{"price":11468700.0,"size":0.001},{"price":11470000.0,"size":0.01},{"price":11471000.0,"size":0.01},{"price":11475000.0,"size":0.0028},{"price":11478431.0,"size":0.002},{"price":11478551.0,"size":0.001},{"price":11478700.0,"size":0.001},{"price":11480000.0,"size":0.12491},{"price":11485000.0,"size":0.01},{"price":11486555.0,"size":0.03},{"price":11487685.0,"size":0.01},{"price":11488000.0,"size":0.102},{"price":11488700.0,"size":0.001},{"price":11489885.0,"size":0.001},{"price":11495850.0,"size":0.001},{"price":11498700.0,"size":0.001},{"price":11498917.0,"size":0.002},{"price":11499000.0,"size":0.01},{"price":11500000.0,"size":0.46859519},{"price":11501219.0,"size":0.001},{"price":11502377.0,"size":0.002},{"price":11502800.0,"size":0.00132},{"price":11503108.0,"size":0.0198},{"price":11505000.0,"size":0.0028},{"price":11505001.0,"size":0.002},{"price":11505836.0,"size":0.003},{"price":11508431.0,"size":0.047},{"price":11508700.0,"size":0.001},{"price":11508888.0,"size":0.02},{"price":11510000.0,"size":0.0976},{"price":11512553.0,"size":0.001},{"price":11513633.0,"size":0.08},{"price":11514332.0,"size":0.02},{"price":11518700.0,"size":0.001},{"price":11519855.0,"size":0.01},{"price":11520000.0,"size":0.001},{"price":11522423.0,"size":0.97},{"price":11523211.0,"size":0.01},{"price":11523887.0,"size":0.001},{"price":11524999.0,"size":0.001},{"price":11528700.0,"size":0.001},{"price":11529852.0,"size":0.01},{"price":11530000.0,"size":0.261},{"price":11533985.0,"size":0.002},{"price":11534084.0,"size":0.001},{"price":11535321.0,"size":0.01},{"price":11538666.0,"size":0.002},{"price":11538700.0,"size":0.001},{"price":11540000.0,"size":0.0048},{"price":11541011.0,"size":0.005},{"price":11541109.0,"size":0.01},{"price":11544663.0,"size":0.002},{"price":11546541.0,"size":0.01},{"price":11548144.0,"size":0.002},{"price":11548700.0,"size":0.001},{"price":11550000.0,"size":0.014},{"price":11551109.0,"size":0.01},{"price":11551625.0,"size":0.002},{"price":11552111.0,"size":0.01},{"price":11553687.0,"size":0.1},{"price":11555106.0,"size":0.002},{"price":11555115.0,"size":0.001},{"price":11556000.0,"size":0.1},{"price":11558587.0,"size":0.002},{"price":11558700.0,"size":0.001},{"price":11559855.0,"size":0.01},{"price":11560831.0,"size":0.0198},{"price":11561109.0,"size":0.01},{"price":11562000.0,"size":0.087},{"price":11562068.0,"size":0.002},{"price":11565548.0,"size":0.002},{"price":11566139.0,"size":0.0228},{"price":11566551.0,"size":0.01},{"price":11568700.0,"size":0.001},{"price":11569029.0,"size":0.002},{"price":11571109.0,"size":0.01},{"price":11572510.0,"size":0.002},{"price":11573211.0,"size":0.01},{"price":11575991.0,"size":0.001},{"price":11578700.0,"size":0.001},{"price":11579851.0,"size":0.01},{"price":11580000.0,"size":0.7735},{"price":11581109.0,"size":0.01},{"price":11585000.0,"size":0.002},{"price":11586532.0,"size":0.01},{"price":11587498.0,"size":0.0198},{"price":11588700.0,"size":0.001},{"price":11589612.0,"size":0.012},{"price":11590000.0,"size":0.1},{"price":11590749.0,"size":0.002},{"price":11591109.0,"size":0.01},{"price":11593211.0,"size":0.01},{"price":11598555.0,"size":0.01},{"price":11598700.0,"size":0.001},{"price":11599999.0,"size":0.001},{"price":11600000.0,"size":3.6141},{"price":11601109.0,"size":0.02},{"price":11606655.0,"size":0.01},{"price":11610000.0,"size":0.302},{"price":11611109.0,"size":0.01},{"price":11613321.0,"size":0.01},{"price":11620000.0,"size":1.35441682},{"price":11621011.0,"size":0.01},{"price":11621109.0,"size":0.01},{"price":11623096.0,"size":0.008},{"price":11629000.0,"size":0.1},{"price":11630000.0,"size":0.201},{"price":11631059.0,"size":0.01},{"price":11631479.0,"size":0.01},{"price":11631773.0,"size":0.00386871},{"price":11635950.0,"size":0.001},{"price":11638259.0,"size":0.001},{"price":11639700.0,"size":0.001},{"price":11640000.0,"size":1.0},{"price":11640820.0,"size":0.01},{"price":11641651.0,"size":2.0},{"price":11645295.0,"size":0.05},{"price":11647158.0,"size":0.05},{"price":11649900.0,"size":0.02906},{"price":11649999.0,"size":0.001},{"price":11650000.0,"size":0.593},{"price":11651059.0,"size":0.01},{"price":11653658.0,"size":0.008},{"price":11654321.0,"size":0.001},{"price":11659700.0,"size":0.001},{"price":11661479.0,"size":0.01},{"price":11666000.0,"size":0.001},{"price":11666666.0,"size":0.013},{"price":11669700.0,"size":0.001},{"price":11671059.0,"size":0.01},{"price":11672562.0,"size":0.0198},{"price":11679224.0,"size":0.012},{"price":11680000.0,"size":0.004},{"price":11685000.0,"size":0.003},{"price":11688000.0,"size":0.001},{"price":11689732.0,"size":0.01},{"price":11690330.0,"size":0.0198},{"price":11691059.0,"size":0.01},{"price":11692558.0,"size":0.01},{"price":11698800.0,"size":0.00131},{"price":11699000.0,"size":0.001},{"price":11699631.0,"size":0.001},{"price":11699998.0,"size":0.01},{"price":11699999.0,"size":0.001},{"price":11700000.0,"size":1.03762841},{"price":11701059.0,"size":0.01},{"price":11720000.0,"size":0.1},{"price":11721059.0,"size":0.01},{"price":11725000.0,"size":0.005},{"price":11726791.0,"size":0.01},{"price":11730000.0,"size":0.9382},{"price":11740000.0,"size":0.101},{"price":11741059.0,"size":0.01},{"price":11748937.0,"size":0.001},{"price":11749999.0,"size":0.001},{"price":11750000.0,"size":0.90537866},{"price":11750050.0,"size":0.2},{"price":11751151.0,"size":0.01},{"price":11755000.0,"size":0.001},{"price":11757860.0,"size":1.82},{"price":11759999.0,"size":0.001},{"price":11760000.0,"size":0.001},{"price":11761059.0,"size":0.02},{"price":11765432.0,"size":0.001},{"price":11768000.0,"size":0.01},{"price":11768836.0,"size":0.012}]}}}
{"schema_version":"collector.vnext.raw","schema_contract":null,"schema_contract_version":null,"payload_contract_version":null,"record_type":"market.orderbook.diff","record_id":"collector_main-market-orderbook-diff-000000000061","collector_id":"collector_main","collector_role":"production","host_name":"MAIN-PC","session_id":"collector_main-sess-20260314T201436Z-61c8c9bf","stream_session_id":"collector_main-stream-bitflyer-board_ws-20260314T201622Z-ef233542","exchange":"bitflyer","market":"spot","symbol":"BTC_JPY","instrument_id":"bitflyer.spot.BTC_JPY","channel":"board_ws","transport":"websocket","source_event_id":null,"source_sequence":null,"sequence_id":61,"exchange_ts":null,"collector_ts":"2026-03-14T20:16:22Z","ingest_ts":"2026-03-14T20:16:22Z","event_ts":"2026-03-14T20:16:22Z","quality_flags":[],"is_partial":false,"is_reconstructed":false,"confidence_score":1.0,"payload":{"provider":"bitflyer_ws_board","exchange":"bitflyer","transport":"websocket","channel":"lightning_board_BTC_JPY","received_ts":"2026-03-14T20:16:22.799239Z","subscription_id":null,"message_id":null,"source_sequence":null,"raw_message_meta":{"raw_channel":"lightning_board_BTC_JPY","subscription_channel":"lightning_board_BTC_JPY","recv_timeout_sec":10,"ssl_verify":false,"socket_url":"wss://ws.lightstream.bitflyer.com/json-rpc"},"source_payload":{"mid_price":11307016.0,"bids":[{"price":11304190.0,"size":0.0}],"asks":[{"price":11309295.0,"size":0.0677}]}}}
{"schema_version":"collector.vnext.raw","schema_contract":null,"schema_contract_version":null,"payload_contract_version":null,"record_type":"market.orderbook.diff","record_id":"collector_main-market-orderbook-diff-000000000065","collector_id":"collector_main","collector_role":"production","host_name":"MAIN-PC","session_id":"collector_main-sess-20260314T201436Z-61c8c9bf","stream_session_id":"collector_main-stream-bitflyer-board_ws-20260314T201622Z-ef233542","exchange":"bitflyer","market":"spot","symbol":"BTC_JPY","instrument_id":"bitflyer.spot.BTC_JPY","channel":"board_ws","transport":"websocket","source_event_id":null,"source_sequence":null,"sequence_id":65,"exchange_ts":null,"collector_ts":"2026-03-14T20:16:22Z","ingest_ts":"2026-03-14T20:16:22Z","event_ts":"2026-03-14T20:16:22Z","quality_flags":[],"is_partial":false,"is_reconstructed":false,"confidence_score":1.0,"payload":{"provider":"bitflyer_ws_board","exchange":"bitflyer","transport":"websocket","channel":"lightning_board_BTC_JPY","received_ts":"2026-03-14T20:16:22.923449Z","subscription_id":null,"message_id":null,"source_sequence":null,"raw_message_meta":{"raw_channel":"lightning_board_BTC_JPY","subscription_channel":"lightning_board_BTC_JPY","recv_timeout_sec":10,"ssl_verify":false,"socket_url":"wss://ws.lightstream.bitflyer.com/json-rpc"},"source_payload":{"mid_price":11307016.0,"bids":[{"price":11304191.0,"size":0.0}],"asks":[]}}}
{"schema_version":"collector.vnext.raw","schema_contract":null,"schema_contract_version":null,"payload_contract_version":null,"record_type":"market.orderbook.diff","record_id":"collector_main-market-orderbook-diff-000000000067","collector_id":"collector_main","collector_role":"production","host_name":"MAIN-PC","session_id":"collector_main-sess-20260314T201436Z-61c8c9bf","stream_session_id":"collector_main-stream-bitflyer-board_ws-20260314T201622Z-ef233542","exchange":"bitflyer","market":"spot","symbol":"BTC_JPY","instrument_id":"bitflyer.spot.BTC_JPY","channel":"board_ws","transport":"websocket","source_event_id":null,"source_sequence":null,"sequence_id":67,"exchange_ts":null,"collector_ts":"2026-03-14T20:16:23Z","ingest_ts":"2026-03-14T20:16:23Z","event_ts":"2026-03-14T20:16:23Z","quality_flags":[],"is_partial":false,"is_reconstructed":false,"confidence_score":1.0,"payload":{"provider":"bitflyer_ws_board","exchange":"bitflyer","transport":"websocket","channel":"lightning_board_BTC_JPY","received_ts":"2026-03-14T20:16:23.076585Z","subscription_id":null,"message_id":null,"source_sequence":null,"raw_message_meta":{"raw_channel":"lightning_board_BTC_JPY","subscription_channel":"lightning_board_BTC_JPY","recv_timeout_sec":10,"ssl_verify":false,"socket_url":"wss://ws.lightstream.bitflyer.com/json-rpc"},"source_payload":{"mid_price":11307016.0,"bids":[{"price":11303678.0,"size":0.05007648}],"asks":[]}}}
{"schema_version":"collector.vnext.raw","schema_contract":null,"schema_contract_version":null,"payload_contract_version":null,"record_type":"market.orderbook.diff","record_id":"collector_main-market-orderbook-diff-000000000069","collector_id":"collector_main","collector_role":"production","host_name":"MAIN-PC","session_id":"collector_main-sess-20260314T201436Z-61c8c9bf","stream_session_id":"collector_main-stream-bitflyer-board_ws-20260314T201622Z-ef233542","exchange":"bitflyer","market":"spot","symbol":"BTC_JPY","instrument_id":"bitflyer.spot.BTC_JPY","channel":"board_ws","transport":"websocket","source_event_id":null,"source_sequence":null,"sequence_id":69,"exchange_ts":null,"collector_ts":"2026-03-14T20:16:23Z","ingest_ts":"2026-03-14T20:16:23Z","event_ts":"2026-03-14T20:16:23Z","quality_flags":[],"is_partial":false,"is_reconstructed":false,"confidence_score":1.0,"payload":{"provider":"bitflyer_ws_board","exchange":"bitflyer","transport":"websocket","channel":"lightning_board_BTC_JPY","received_ts":"2026-03-14T20:16:23.254657Z","subscription_id":null,"message_id":null,"source_sequence":null,"raw_message_meta":{"raw_channel":"lightning_board_BTC_JPY","subscription_channel":"lightning_board_BTC_JPY","recv_timeout_sec":10,"ssl_verify":false,"socket_url":"wss://ws.lightstream.bitflyer.com/json-rpc"},"source_payload":{"mid_price":11307016.0,"bids":[{"price":11269288.0,"size":0.002},{"price":10171000.0,"size":0.0},{"price":11293830.0,"size":0.0}],"asks":[{"price":11311871.0,"size":0.0}]}}}
{"schema_version":"collector.vnext.raw","schema_contract":null,"schema_contract_version":null,"payload_contract_version":null,"record_type":"market.orderbook.diff","record_id":"collector_main-market-orderbook-diff-000000000071","collector_id":"collector_main","collector_role":"production","host_name":"MAIN-PC","session_id":"collector_main-sess-20260314T201436Z-61c8c9bf","stream_session_id":"collector_main-stream-bitflyer-board_ws-20260314T201622Z-ef233542","exchange":"bitflyer","market":"spot","symbol":"BTC_JPY","instrument_id":"bitflyer.spot.BTC_JPY","channel":"board_ws","transport":"websocket","source_event_id":null,"source_sequence":null,"sequence_id":71,"exchange_ts":null,"collector_ts":"2026-03-14T20:16:23Z","ingest_ts":"2026-03-14T20:16:23Z","event_ts":"2026-03-14T20:16:23Z","quality_flags":[],"is_partial":false,"is_reconstructed":false,"confidence_score":1.0,"payload":{"provider":"bitflyer_ws_board","exchange":"bitflyer","transport":"websocket","channel":"lightning_board_BTC_JPY","received_ts":"2026-03-14T20:16:23.500530Z","subscription_id":null,"message_id":null,"source_sequence":null,"raw_message_meta":{"raw_channel":"lightning_board_BTC_JPY","subscription_channel":"lightning_board_BTC_JPY","recv_timeout_sec":10,"ssl_verify":false,"socket_url":"wss://ws.lightstream.bitflyer.com/json-rpc"},"source_payload":{"mid_price":11307016.0,"bids":[{"price":11294795.0,"size":0.0099986}],"asks":[{"price":11311208.0,"size":0.0099999}]}}}
{"schema_version":"collector.vnext.raw","schema_contract":null,"schema_contract_version":null,"payload_contract_version":null,"record_type":"market.orderbook.diff","record_id":"collector_main-market-orderbook-diff-000000000073","collector_id":"collector_main","collector_role":"production","host_name":"MAIN-PC","session_id":"collector_main-sess-20260314T201436Z-61c8c9bf","stream_session_id":"collector_main-stream-bitflyer-board_ws-20260314T201622Z-ef233542","exchange":"bitflyer","market":"spot","symbol":"BTC_JPY","instrument_id":"bitflyer.spot.BTC_JPY","channel":"board_ws","transport":"websocket","source_event_id":null,"source_sequence":null,"sequence_id":73,"exchange_ts":null,"collector_ts":"2026-03-14T20:16:23Z","ingest_ts":"2026-03-14T20:16:23Z","event_ts":"2026-03-14T20:16:23Z","quality_flags":[],"is_partial":false,"is_reconstructed":false,"confidence_score":1.0,"payload":{"provider":"bitflyer_ws_board","exchange":"bitflyer","transport":"websocket","channel":"lightning_board_BTC_JPY","received_ts":"2026-03-14T20:16:23.625790Z","subscription_id":null,"message_id":null,"source_sequence":null,"raw_message_meta":{"raw_channel":"lightning_board_BTC_JPY","subscription_channel":"lightning_board_BTC_JPY","recv_timeout_sec":10,"ssl_verify":false,"socket_url":"wss://ws.lightstream.bitflyer.com/json-rpc"},"source_payload":{"mid_price":11307016.0,"bids":[{"price":11303677.0,"size":0.0}],"asks":[]}}}
{"schema_version":"collector.vnext.raw","schema_contract":null,"schema_contract_version":null,"payload_contract_version":null,"record_type":"market.orderbook.diff","record_id":"collector_main-market-orderbook-diff-000000000075","collector_id":"collector_main","collector_role":"production","host_name":"MAIN-PC","session_id":"collector_main-sess-20260314T201436Z-61c8c9bf","stream_session_id":"collector_main-stream-bitflyer-board_ws-20260314T201622Z-ef233542","exchange":"bitflyer","market":"spot","symbol":"BTC_JPY","instrument_id":"bitflyer.spot.BTC_JPY","channel":"board_ws","transport":"websocket","source_event_id":null,"source_sequence":null,"sequence_id":75,"exchange_ts":null,"collector_ts":"2026-03-14T20:16:23Z","ingest_ts":"2026-03-14T20:16:23Z","event_ts":"2026-03-14T20:16:23Z","quality_flags":[],"is_partial":false,"is_reconstructed":false,"confidence_score":1.0,"payload":{"provider":"bitflyer_ws_board","exchange":"bitflyer","transport":"websocket","channel":"lightning_board_BTC_JPY","received_ts":"2026-03-14T20:16:23.750790Z","subscription_id":null,"message_id":null,"source_sequence":null,"raw_message_meta":{"raw_channel":"lightning_board_BTC_JPY","subscription_channel":"lightning_board_BTC_JPY","recv_timeout_sec":10,"ssl_verify":false,"socket_url":"wss://ws.lightstream.bitflyer.com/json-rpc"},"source_payload":{"mid_price":11307016.0,"bids":[{"price":11303678.0,"size":0.0}],"asks":[]}}}
{"schema_version":"collector.vnext.raw","schema_contract":null,"schema_contract_version":null,"payload_contract_version":null,"record_type":"market.orderbook.diff","record_id":"collector_main-market-orderbook-diff-000000000077","collector_id":"collector_main","collector_role":"production","host_name":"MAIN-PC","session_id":"collector_main-sess-20260314T201436Z-61c8c9bf","stream_session_id":"collector_main-stream-bitflyer-board_ws-20260314T201622Z-ef233542","exchange":"bitflyer","market":"spot","symbol":"BTC_JPY","instrument_id":"bitflyer.spot.BTC_JPY","channel":"board_ws","transport":"websocket","source_event_id":null,"source_sequence":null,"sequence_id":77,"exchange_ts":null,"collector_ts":"2026-03-14T20:16:23Z","ingest_ts":"2026-03-14T20:16:23Z","event_ts":"2026-03-14T20:16:23Z","quality_flags":[],"is_partial":false,"is_reconstructed":false,"confidence_score":1.0,"payload":{"provider":"bitflyer_ws_board","exchange":"bitflyer","transport":"websocket","channel":"lightning_board_BTC_JPY","received_ts":"2026-03-14T20:16:23.877060Z","subscription_id":null,"message_id":null,"source_sequence":null,"raw_message_meta":{"raw_channel":"lightning_board_BTC_JPY","subscription_channel":"lightning_board_BTC_JPY","recv_timeout_sec":10,"ssl_verify":false,"socket_url":"wss://ws.lightstream.bitflyer.com/json-rpc"},"source_payload":{"mid_price":11307016.0,"bids":[{"price":11303085.0,"size":0.0561731}],"asks":[]}}}
{"schema_version":"collector.vnext.raw","schema_contract":null,"schema_contract_version":null,"payload_contract_version":null,"record_type":"market.orderbook.diff","record_id":"collector_main-market-orderbook-diff-000000000079","collector_id":"collector_main","collector_role":"production","host_name":"MAIN-PC","session_id":"collector_main-sess-20260314T201436Z-61c8c9bf","stream_session_id":"collector_main-stream-bitflyer-board_ws-20260314T201622Z-ef233542","exchange":"bitflyer","market":"spot","symbol":"BTC_JPY","instrument_id":"bitflyer.spot.BTC_JPY","channel":"board_ws","transport":"websocket","source_event_id":null,"source_sequence":null,"sequence_id":79,"exchange_ts":null,"collector_ts":"2026-03-14T20:16:24Z","ingest_ts":"2026-03-14T20:16:24Z","event_ts":"2026-03-14T20:16:24Z","quality_flags":[],"is_partial":false,"is_reconstructed":false,"confidence_score":1.0,"payload":{"provider":"bitflyer_ws_board","exchange":"bitflyer","transport":"websocket","channel":"lightning_board_BTC_JPY","received_ts":"2026-03-14T20:16:23.985799Z","subscription_id":null,"message_id":null,"source_sequence":null,"raw_message_meta":{"raw_channel":"lightning_board_BTC_JPY","subscription_channel":"lightning_board_BTC_JPY","recv_timeout_sec":10,"ssl_verify":false,"socket_url":"wss://ws.lightstream.bitflyer.com/json-rpc"},"source_payload":{"mid_price":11307008.0,"bids":[{"price":11302493.0,"size":0.1275}],"asks":[{"price":11309278.0,"size":0.1275}]}}}
{"schema_version":"collector.vnext.raw","schema_contract":null,"schema_contract_version":null,"payload_contract_version":null,"record_type":"market.orderbook.diff","record_id":"collector_main-market-orderbook-diff-000000000081","collector_id":"collector_main","collector_role":"production","host_name":"MAIN-PC","session_id":"collector_main-sess-20260314T201436Z-61c8c9bf","stream_session_id":"collector_main-stream-bitflyer-board_ws-20260314T201622Z-ef233542","exchange":"bitflyer","market":"spot","symbol":"BTC_JPY","instrument_id":"bitflyer.spot.BTC_JPY","channel":"board_ws","transport":"websocket","source_event_id":null,"source_sequence":null,"sequence_id":81,"exchange_ts":null,"collector_ts":"2026-03-14T20:16:24Z","ingest_ts":"2026-03-14T20:16:24Z","event_ts":"2026-03-14T20:16:24Z","quality_flags":[],"is_partial":false,"is_reconstructed":false,"confidence_score":1.0,"payload":{"provider":"bitflyer_ws_board","exchange":"bitflyer","transport":"websocket","channel":"lightning_board_BTC_JPY","received_ts":"2026-03-14T20:16:24.157091Z","subscription_id":null,"message_id":null,"source_sequence":null,"raw_message_meta":{"raw_channel":"lightning_board_BTC_JPY","subscription_channel":"lightning_board_BTC_JPY","recv_timeout_sec":10,"ssl_verify":false,"socket_url":"wss://ws.lightstream.bitflyer.com/json-rpc"},"source_payload":{"mid_price":11307008.0,"bids":[{"price":11303624.0,"size":0.1275},{"price":11302322.0,"size":0.0176937}],"asks":[{"price":11309294.0,"size":0.0}]}}}
{"schema_version":"collector.vnext.raw","schema_contract":null,"schema_contract_version":null,"payload_contract_version":null,"record_type":"market.orderbook.diff","record_id":"collector_main-market-orderbook-diff-000000000083","collector_id":"collector_main","collector_role":"production","host_name":"MAIN-PC","session_id":"collector_main-sess-20260314T201436Z-61c8c9bf","stream_session_id":"collector_main-stream-bitflyer-board_ws-20260314T201622Z-ef233542","exchange":"bitflyer","market":"spot","symbol":"BTC_JPY","instrument_id":"bitflyer.spot.BTC_JPY","channel":"board_ws","transport":"websocket","source_event_id":null,"source_sequence":null,"sequence_id":83,"exchange_ts":null,"collector_ts":"2026-03-14T20:16:24Z","ingest_ts":"2026-03-14T20:16:24Z","event_ts":"2026-03-14T20:16:24Z","quality_flags":[],"is_partial":false,"is_reconstructed":false,"confidence_score":1.0,"payload":{"provider":"bitflyer_ws_board","exchange":"bitflyer","transport":"websocket","channel":"lightning_board_BTC_JPY","received_ts":"2026-03-14T20:16:24.266216Z","subscription_id":null,"message_id":null,"source_sequence":null,"raw_message_meta":{"raw_channel":"lightning_board_BTC_JPY","subscription_channel":"lightning_board_BTC_JPY","recv_timeout_sec":10,"ssl_verify":false,"socket_url":"wss://ws.lightstream.bitflyer.com/json-rpc"},"source_payload":{"mid_price":11307008.0,"bids":[],"asks":[{"price":11309277.0,"size":0.04353519},{"price":11309295.0,"size":0.0}]}}}
{"schema_version":"collector.vnext.raw","schema_contract":null,"schema_contract_version":null,"payload_contract_version":null,"record_type":"market.orderbook.diff","record_id":"collector_main-market-orderbook-diff-000000000085","collector_id":"collector_main","collector_role":"production","host_name":"MAIN-PC","session_id":"collector_main-sess-20260314T201436Z-61c8c9bf","stream_session_id":"collector_main-stream-bitflyer-board_ws-20260314T201622Z-ef233542","exchange":"bitflyer","market":"spot","symbol":"BTC_JPY","instrument_id":"bitflyer.spot.BTC_JPY","channel":"board_ws","transport":"websocket","source_event_id":null,"source_sequence":null,"sequence_id":85,"exchange_ts":null,"collector_ts":"2026-03-14T20:16:24Z","ingest_ts":"2026-03-14T20:16:24Z","event_ts":"2026-03-14T20:16:24Z","quality_flags":[],"is_partial":false,"is_reconstructed":false,"confidence_score":1.0,"payload":{"provider":"bitflyer_ws_board","exchange":"bitflyer","transport":"websocket","channel":"lightning_board_BTC_JPY","received_ts":"2026-03-14T20:16:24.375049Z","subscription_id":null,"message_id":null,"source_sequence":null,"raw_message_meta":{"raw_channel":"lightning_board_BTC_JPY","subscription_channel":"lightning_board_BTC_JPY","recv_timeout_sec":10,"ssl_verify":false,"socket_url":"wss://ws.lightstream.bitflyer.com/json-rpc"},"source_payload":{"mid_price":11307008.0,"bids":[{"price":11302493.0,"size":0.0},{"price":11303085.0,"size":0.0}],"asks":[{"price":11309278.0,"size":0.1898}]}}}
{"schema_version":"collector.vnext.raw","schema_contract":null,"schema_contract_version":null,"payload_contract_version":null,"record_type":"market.orderbook.diff","record_id":"collector_main-market-orderbook-diff-000000000087","collector_id":"collector_main","collector_role":"production","host_name":"MAIN-PC","session_id":"collector_main-sess-20260314T201436Z-61c8c9bf","stream_session_id":"collector_main-stream-bitflyer-board_ws-20260314T201622Z-ef233542","exchange":"bitflyer","market":"spot","symbol":"BTC_JPY","instrument_id":"bitflyer.spot.BTC_JPY","channel":"board_ws","transport":"websocket","source_event_id":null,"source_sequence":null,"sequence_id":87,"exchange_ts":null,"collector_ts":"2026-03-14T20:16:24Z","ingest_ts":"2026-03-14T20:16:24Z","event_ts":"2026-03-14T20:16:24Z","quality_flags":[],"is_partial":false,"is_reconstructed":false,"confidence_score":1.0,"payload":{"provider":"bitflyer_ws_board","exchange":"bitflyer","transport":"websocket","channel":"lightning_board_BTC_JPY","received_ts":"2026-03-14T20:16:24.484650Z","subscription_id":null,"message_id":null,"source_sequence":null,"raw_message_meta":{"raw_channel":"lightning_board_BTC_JPY","subscription_channel":"lightning_board_BTC_JPY","recv_timeout_sec":10,"ssl_verify":false,"socket_url":"wss://ws.lightstream.bitflyer.com/json-rpc"},"source_payload":{"mid_price":11307008.0,"bids":[{"price":11303625.0,"size":0.04699848},{"price":11264765.0,"size":0.002}],"asks":[]}}}
{"schema_version":"collector.vnext.raw","schema_contract":null,"schema_contract_version":null,"payload_contract_version":null,"record_type":"market.orderbook.diff","record_id":"collector_main-market-orderbook-diff-000000000089","collector_id":"collector_main","collector_role":"production","host_name":"MAIN-PC","session_id":"collector_main-sess-20260314T201436Z-61c8c9bf","stream_session_id":"collector_main-stream-bitflyer-board_ws-20260314T201622Z-ef233542","exchange":"bitflyer","market":"spot","symbol":"BTC_JPY","instrument_id":"bitflyer.spot.BTC_JPY","channel":"board_ws","transport":"websocket","source_event_id":null,"source_sequence":null,"sequence_id":89,"exchange_ts":null,"collector_ts":"2026-03-14T20:16:24Z","ingest_ts":"2026-03-14T20:16:24Z","event_ts":"2026-03-14T20:16:24Z","quality_flags":[],"is_partial":false,"is_reconstructed":false,"confidence_score":1.0,"payload":{"provider":"bitflyer_ws_board","exchange":"bitflyer","transport":"websocket","channel":"lightning_board_BTC_JPY","received_ts":"2026-03-14T20:16:24.600066Z","subscription_id":null,"message_id":null,"source_sequence":null,"raw_message_meta":{"raw_channel":"lightning_board_BTC_JPY","subscription_channel":"lightning_board_BTC_JPY","recv_timeout_sec":10,"ssl_verify":false,"socket_url":"wss://ws.lightstream.bitflyer.com/json-rpc"},"source_payload":{"mid_price":11307008.0,"bids":[{"price":11304181.0,"size":0.1275}],"asks":[]}}}
{"schema_version":"collector.vnext.raw","schema_contract":null,"schema_contract_version":null,"payload_contract_version":null,"record_type":"market.orderbook.diff","record_id":"collector_main-market-orderbook-diff-000000000091","collector_id":"collector_main","collector_role":"production","host_name":"MAIN-PC","session_id":"collector_main-sess-20260314T201436Z-61c8c9bf","stream_session_id":"collector_main-stream-bitflyer-board_ws-20260314T201622Z-ef233542","exchange":"bitflyer","market":"spot","symbol":"BTC_JPY","instrument_id":"bitflyer.spot.BTC_JPY","channel":"board_ws","transport":"websocket","source_event_id":null,"source_sequence":null,"sequence_id":91,"exchange_ts":null,"collector_ts":"2026-03-14T20:16:24Z","ingest_ts":"2026-03-14T20:16:24Z","event_ts":"2026-03-14T20:16:24Z","quality_flags":[],"is_partial":false,"is_reconstructed":false,"confidence_score":1.0,"payload":{"provider":"bitflyer_ws_board","exchange":"bitflyer","transport":"websocket","channel":"lightning_board_BTC_JPY","received_ts":"2026-03-14T20:16:24.810643Z","subscription_id":null,"message_id":null,"source_sequence":null,"raw_message_meta":{"raw_channel":"lightning_board_BTC_JPY","subscription_channel":"lightning_board_BTC_JPY","recv_timeout_sec":10,"ssl_verify":false,"socket_url":"wss://ws.lightstream.bitflyer.com/json-rpc"},"source_payload":{"mid_price":11307008.0,"bids":[{"price":11304181.0,"size":0.0},{"price":11303624.0,"size":0.0},{"price":11303625.0,"size":0.0}],"asks":[]}}}
