{"schema_version":"collector.vnext.raw","schema_contract":null,"schema_contract_version":null,"payload_contract_version":null,"record_type":"market.orderbook.snapshot","record_id":"collector_main-market-orderbook-snapshot-000000000111","collector_id":"collector_main","collector_role":"production","host_name":"MAIN-PC","session_id":"collector_main-sess-20260314T203137Z-e804aa95","stream_session_id":"collector_main-stream-bitflyer-board_ws-20260314T203157Z-61ca9e02","exchange":"bitflyer","market":"spot","symbol":"BTC_JPY","instrument_id":"bitflyer.spot.BTC_JPY","channel":"board_ws","transport":"websocket","source_event_id":null,"source_sequence":null,"sequence_id":111,"exchange_ts":null,"collector_ts":"2026-03-14T20:32:02Z","ingest_ts":"2026-03-14T20:32:02Z","event_ts":"2026-03-14T20:32:02Z","quality_flags":[],"is_partial":false,"is_reconstructed":false,"confidence_score":1.0,"payload":{"provider":"bitflyer_ws_board_snapshot","exchange":"bitflyer","transport":"websocket","channel":"lightning_board_snapshot_BTC_JPY","received_ts":"2026-03-14T20:32:02.844384Z","subscription_id":null,"message_id":null,"source_sequence":null,"raw_message_meta":{"raw_channel":"lightning_board_snapshot_BTC_JPY","subscription_channel":"lightning_board_snapshot_BTC_JPY","recv_timeout_sec":10,"ssl_verify":false,"socket_url":"wss://ws.lightstream.bitflyer.com/json-rpc"},"source_payload":{"mid_price":11313431.0,"bids":[{"price":11311159.0,"size":0.0083535},{"price":11311150.0,"size":0.1275},{"price":11311124.0,"size":0.1275},{"price":11310658.0,"size":0.0099986},{"price":11309737.0,"size":0.04594475},{"price":11309736.0,"size":0.02},{"price":11309735.0,"size":0.015276},{"price":11309641.0,"size":0.005},{"price":11309634.0,"size":0.02},{"price":11309242.0,"size":0.015168},{"price":11308023.0,"size":0.5},{"price":11307805.0,"size":0.014688},{"price":11307440.0,"size":0.0801},{"price":11307141.0,"size":0.05},{"price":11307046.0,"size":0.5},{"price":11306023.0,"size":0.05},{"price":11305391.0,"size":0.053},{"price":11305384.0,"size":0.01},{"price":11304585.0,"size":0.01},{"price":11303712.0,"size":2.97729922},{"price":11303701.0,"size":0.0030426},{"price":11303343.0,"size":0.054432},{"price":11301266.0,"size":0.0099986},{"price":11301203.0,"size":0.078},{"price":11298581.0,"size":0.15},{"price":11296888.0,"size":0.98322348},{"price":11296886.0,"size":1.50015},{"price":11292672.0,"size":1.484},{"price":11289652.0,"size":0.6},{"price":11288546.0,"size":0.002},{"price":11287992.0,"size":0.2982},{"price":11287710.0,"size":0.002},{"price":11286090.0,"size":0.18915459},{"price":11285230.0,"size":0.308},{"price":11284316.0,"size":0.002},{"price":11284020.0,"size":0.002},{"price":11282468.0,"size":0.2858},{"price":11280922.0,"size":0.002},{"price":11280205.0,"size":0.001},{"price":11279706.0,"size":0.2629},{"price":11279607.0,"size":0.6},{"price":11279494.0,"size":0.002},{"price":11279282.0,"size":0.0015},{"price":11277748.0,"size":0.0966561},{"price":11277620.0,"size":1.966},{"price":11277602.0,"size":0.005},{"price":11277528.0,"size":0.002},{"price":11275102.0,"size":0.01},{"price":11275000.0,"size":0.001},{"price":11274968.0,"size":0.002},{"price":11274588.0,"size":0.0047},{"price":11274134.0,"size":0.002},{"price":11271000.0,"size":0.003},{"price":11270740.0,"size":0.002},{"price":11270442.0,"size":0.002},{"price":11270000.0,"size":0.106},{"price":11268871.0,"size":0.281},{"price":11268411.0,"size":0.01},{"price":11267346.0,"size":0.002},{"price":11266666.0,"size":0.04},{"price":11265916.0,"size":0.002},{"price":11265000.0,"size":0.02},{"price":11263952.0,"size":0.002},{"price":11263843.0,"size":1.79},{"price":11263000.0,"size":0.006},{"price":11262564.0,"size":0.0015},{"price":11261390.0,"size":0.002},{"price":11260558.0,"size":0.002},{"price":11260000.0,"size":0.3565},{"price":11257537.0,"size":0.001},{"price":11257164.0,"size":0.002},{"price":11257000.0,"size":0.001},{"price":11256864.0,"size":0.002},{"price":11255200.0,"size":0.001},{"price":11255115.0,"size":0.00377},{"price":11253000.0,"size":0.03189},{"price":11252338.0,"size":0.002},{"price":11251000.0,"size":0.0131},{"price":11250250.0,"size":0.00105},{"price":11250200.0,"size":0.001},{"price":11250100.0,"size":0.015},{"price":11250005.0,"size":0.001},{"price":11250001.0,"size":0.00104},{"price":11250000.0,"size":1.66134},{"price":11248998.0,"size":2.036},{"price":11247812.0,"size":0.002},{"price":11246544.0,"size":0.0015},{"price":11246203.0,"size":0.001},{"price":11245141.0,"size":0.0031},{"price":11245000.0,"size":0.05},{"price":11244444.0,"size":0.04},{"price":11244243.0,"size":0.01},{"price":11240200.0,"size":0.001},{"price":11240000.0,"size":0.007304},{"price":11236190.0,"size":0.01},{"price":11235200.0,"size":0.001},{"price":11234869.0,"size":0.001},{"price":11232000.0,"size":0.089},{"price":11231243.0,"size":0.01},{"price":11231000.0,"size":0.105},{"price":11230200.0,"size":0.001},{"price":11230000.0,"size":0.0308},{"price":11228423.0,"size":1.951},{"price":11224500.0,"size":0.06},{"price":11224355.0,"size":0.0015},{"price":11223968.0,"size":0.001},{"price":11223535.0,"size":0.001},{"price":11223344.0,"size":0.01},{"price":11223000.0,"size":0.1},{"price":11222222.0,"size":0.092525},{"price":11221459.0,"size":0.1393},{"price":11221120.0,"size":0.011},{"price":11220200.0,"size":0.001},{"price":11220001.0,"size":0.004457},{"price":11220000.0,"size":0.321},{"price":11219517.0,"size":0.01},{"price":11219000.0,"size":0.1},{"price":11215200.0,"size":0.001},{"price":11215000.0,"size":0.02},{"price":11212358.0,"size":1.2},{"price":11212201.0,"size":0.001},{"price":11211800.0,"size":0.001},{"price":11211111.0,"size":0.06},{"price":11210200.0,"size":0.001},{"price":11210000.0,"size":0.10622},{"price":11208032.0,"size":0.01},{"price":11207755.0,"size":0.0015},{"price":11206000.0,"size":0.09015},{"price":11205200.0,"size":0.001},{"price":11204578.0,"size":0.002},{"price":11203931.0,"size":1.0},{"price":11201000.0,"size":0.01},{"price":11200867.0,"size":0.001},{"price":11200800.0,"size":0.05},{"price":11200425.0,"size":0.1},{"price":11200200.0,"size":0.001},{"price":11200198.0,"size":0.003},{"price":11200150.0,"size":0.002},{"price":11200002.0,"size":0.001},{"price":11200001.0,"size":0.01104},{"price":11200000.0,"size":1.35988728},{"price":11198508.0,"size":0.05},{"price":11198243.0,"size":0.01},{"price":11197134.0,"size":2.993},{"price":11197000.0,"size":0.0085},{"price":11195692.0,"size":0.0015},{"price":11194090.0,"size":0.03},{"price":11190770.0,"size":0.0309},{"price":11190000.0,"size":0.0010016},{"price":11189555.0,"size":0.5},{"price":11189533.0,"size":0.001},{"price":11188629.0,"size":0.01},{"price":11188382.0,"size":0.001},{"price":11185000.0,"size":0.0085},{"price":11180043.0,"size":0.972},{"price":11180000.0,"size":0.23215},{"price":11178973.0,"size":0.0015},{"price":11178199.0,"size":0.001},{"price":11170000.0,"size":0.001},{"price":11169662.0,"size":0.01},{"price":11169593.0,"size":0.001},{"price":11169243.0,"size":0.01},{"price":11166865.0,"size":0.001},{"price":11164029.0,"size":0.001},{"price":11160854.0,"size":0.1},{"price":11160000.0,"size":0.02376},{"price":11156269.0,"size":0.01},{"price":11155531.0,"size":0.001},{"price":11155377.0,"size":0.00636009},{"price":11153999.0,"size":0.00101},{"price":11151000.0,"size":0.001},{"price":11150250.0,"size":0.00175},{"price":11150005.0,"size":0.001},{"price":11150001.0,"size":0.00104},{"price":11150000.0,"size":0.6398956},{"price":11148000.0,"size":0.08963},{"price":11144197.0,"size":0.001},{"price":11144000.0,"size":0.0897},{"price":11140000.0,"size":0.2},{"price":11136243.0,"size":0.01},{"price":11136155.0,"size":0.02},{"price":11135869.0,"size":0.1},{"price":11130000.0,"size":0.116},{"price":11129979.0,"size":0.0053908},{"price":11126388.0,"size":0.02},{"price":11124900.0,"size":0.00133},{"price":11121090.0,"size":0.1},{"price":11120000.0,"size":0.0033},{"price":11118078.0,"size":0.01},{"price":11111800.0,"size":0.001},{"price":11111111.0,"size":0.2919257},{"price":11111000.0,"size":0.003},{"price":11110594.0,"size":0.001},{"price":11110000.0,"size":0.056937},{"price":11109662.0,"size":0.01},{"price":11108008.0,"size":0.01},{"price":11106000.0,"size":0.2},{"price":11105000.0,"size":0.02},{"price":11101297.0,"size":0.001},{"price":11100005.0,"size":0.001},{"price":11100001.0,"size":0.01104},{"price":11100000.0,"size":1.7472049},{"price":11099141.0,"size":0.01},{"price":11096243.0,"size":0.01},{"price":11094090.0,"size":0.01},{"price":11088888.0,"size":0.001},{"price":11085245.0,"size":0.001},{"price":11080200.0,"size":0.001},{"price":11080000.0,"size":0.0223},{"price":11075100.0,"size":0.003},{"price":11071558.0,"size":1.0},{"price":11070200.0,"size":0.001},{"price":11070000.0,"size":0.0902},{"price":11065200.0,"size":0.001},{"price":11064370.0,"size":0.00497091},{"price":11060200.0,"size":0.001},{"price":11060000.0,"size":0.145},{"price":11059689.0,"size":0.009},{"price":11056428.0,"size":0.002},{"price":11055500.0,"size":0.02},{"price":11055200.0,"size":0.001},{"price":11055100.0,"size":0.003},{"price":11050200.0,"size":0.001},{"price":11050005.0,"size":0.001},{"price":11050002.0,"size":0.001},{"price":11050001.0,"size":0.00104},{"price":11050000.0,"size":0.43176147},{"price":11046420.0,"size":0.2},{"price":11044243.0,"size":0.01},{"price":11041380.0,"size":0.01},{"price":11040200.0,"size":0.001},{"price":11040000.0,"size":0.00777181},{"price":11035865.0,"size":0.1},{"price":11035200.0,"size":0.001},{"price":11035000.0,"size":0.0013},{"price":11030200.0,"size":0.001},{"price":11030000.0,"size":0.025},{"price":11025500.0,"size":0.009531},{"price":11025200.0,"size":0.001},{"price":11025000.0,"size":0.71497},{"price":11020772.0,"size":0.014},{"price":11020200.0,"size":0.002},{"price":11020000.0,"size":0.005},{"price":11015200.0,"size":0.001},{"price":11012000.0,"size":0.1},{"price":11011800.0,"size":0.001},{"price":11010200.0,"size":0.001},{"price":11010000.0,"size":0.347},{"price":11007277.0,"size":0.01},{"price":11006000.0,"size":0.2},{"price":11005200.0,"size":0.001},{"price":11004890.0,"size":0.001535},{"price":11003000.0,"size":0.0155},{"price":11001000.0,"size":0.013},{"price":11000500.0,"size":0.05117658},{"price":11000200.0,"size":0.001},{"price":11000002.0,"size":0.004},{"price":11000001.0,"size":0.02604},{"price":11000000.0,"size":4.55923365},{"price":10999999.0,"size":0.003},{"price":10999000.0,"size":0.001},{"price":10996855.0,"size":0.0011},{"price":10995200.0,"size":0.001},{"price":10994499.0,"size":0.00169176},{"price":10990200.0,"size":0.001},{"price":10990000.0,"size":0.10219},{"price":10989001.0,"size":0.00197},{"price":10988999.0,"size":0.001},{"price":10988324.0,"size":0.002},{"price":10987654.0,"size":0.001},{"price":10985200.0,"size":0.001},{"price":10985150.0,"size":0.01},{"price":10980500.0,"size":0.005},{"price":10980200.0,"size":0.001},{"price":10980002.0,"size":0.4},{"price":10980000.0,"size":0.028},{"price":10975200.0,"size":0.001},{"price":10975000.0,"size":0.1},{"price":10971261.0,"size":0.001},{"price":10971243.0,"size":0.01},{"price":10970375.0,"size":1.9},{"price":10970200.0,"size":0.001},{"price":10970000.0,"size":0.09304},{"price":10966600.0,"size":0.001003},{"price":10965200.0,"size":0.001},{"price":10960200.0,"size":0.001},{"price":10960000.0,"size":0.0083},{"price":10956673.0,"size":0.01},{"price":10955200.0,"size":0.001},{"price":10954950.0,"size":0.001},{"price":10950500.0,"size":0.005},{"price":10950001.0,"size":0.00204},{"price":10950000.0,"size":0.5485028},{"price":10949550.0,"size":0.01870657},{"price":10949172.0,"size":0.1},{"price":10948000.0,"size":0.1},{"price":10945243.0,"size":0.01},{"price":10940402.0,"size":0.001},{"price":10940200.0,"size":0.001},{"price":10940000.0,"size":0.331}],"asks":[{"price":11315703.0,"size":0.02997095},{"price":11315704.0,"size":0.1268},{"price":11315810.0,"size":0.1255},{"price":11316023.0,"size":0.00997228},{"price":11316565.0,"size":0.005},{"price":11317668.0,"size":0.02},{"price":11317669.0,"size":0.2986},{"price":11317823.0,"size":0.02},{"price":11318668.0,"size":0.02},{"price":11318876.0,"size":0.02},{"price":11319518.0,"size":0.02},{"price":11319579.0,"size":0.02},{"price":11320000.0,"size":0.02},{"price":11320163.0,"size":0.015348},{"price":11320431.0,"size":0.2586},{"price":11320458.0,"size":0.014844},{"price":11321760.0,"size":0.052056},{"price":11322000.0,"size":0.005},{"price":11322245.0,"size":0.01},{"price":11323193.0,"size":0.2604},{"price":11323383.0,"size":0.57571972},{"price":11323572.0,"size":0.015},{"price":11324837.0,"size":0.01},{"price":11325955.0,"size":0.2592},{"price":11325976.0,"size":0.0529},{"price":11326901.0,"size":0.4199},{"price":11327889.0,"size":0.2},{"price":11328050.0,"size":0.002},{"price":11329436.0,"size":0.0015},{"price":11331059.0,"size":0.001},{"price":11331584.0,"size":1.189881},{"price":11331586.0,"size":1.189881},{"price":11331821.0,"size":0.005},{"price":11340000.0,"size":0.13586406},{"price":11340197.0,"size":1.489},{"price":11340647.0,"size":0.001},{"price":11342956.0,"size":1.60199848},{"price":11342957.0,"size":0.01},{"price":11346154.0,"size":0.0015},{"price":11348000.0,"size":0.1999},{"price":11349700.0,"size":0.001},{"price":11350000.0,"size":0.022},{"price":11350514.0,"size":1.928},{"price":11353807.0,"size":0.001},{"price":11353877.0,"size":0.001},{"price":11354939.0,"size":0.01},{"price":11355555.0,"size":0.001},{"price":11359242.0,"size":0.0011},{"price":11359700.0,"size":0.001},{"price":11362692.0,"size":0.0015},{"price":11365211.0,"size":0.001},{"price":11369700.0,"size":0.001},{"price":11370000.0,"size":0.1},{"price":11376000.0,"size":0.02},{"price":11376545.0,"size":0.001},{"price":11377000.0,"size":0.2287},{"price":11377269.0,"size":0.002},{"price":11379471.0,"size":2.018},{"price":11379700.0,"size":0.001},{"price":11379865.0,"size":0.03},{"price":11380000.0,"size":0.0223},{"price":11380324.0,"size":0.002},{"price":11381766.0,"size":0.4},{"price":11382386.0,"size":0.0015},{"price":11385000.0,"size":0.2548},{"price":11385403.0,"size":0.002},{"price":11385664.0,"size":0.002},{"price":11386197.0,"size":0.002},{"price":11387072.0,"size":0.01},{"price":11387354.0,"size":0.002},{"price":11387879.0,"size":0.001},{"price":11388885.0,"size":0.03},{"price":11389700.0,"size":0.001},{"price":11390000.0,"size":0.2488},{"price":11390050.0,"size":0.001},{"price":11392387.0,"size":1.0},{"price":11392758.0,"size":0.002},{"price":11394939.0,"size":0.01},{"price":11395000.0,"size":0.06},{"price":11395775.0,"size":0.01},{"price":11396555.0,"size":0.03},{"price":11398444.0,"size":0.001995},{"price":11398783.0,"size":1.943},{"price":11399213.0,"size":0.001},{"price":11399673.0,"size":0.0015},{"price":11399700.0,"size":0.001},{"price":11400000.0,"size":0.5225},{"price":11405000.0,"size":0.0275},{"price":11406336.0,"size":1.0},{"price":11408700.0,"size":0.001},{"price":11409415.0,"size":0.055},{"price":11410000.0,"size":0.03},{"price":11410547.0,"size":0.001},{"price":11410853.0,"size":0.002},{"price":11412000.0,"size":0.0878},{"price":11415000.0,"size":0.002},{"price":11415141.0,"size":0.0041},{"price":11417481.0,"size":0.0015},{"price":11418700.0,"size":0.001},{"price":11420000.0,"size":0.401},{"price":11421268.0,"size":0.05},{"price":11421881.0,"size":0.001},{"price":11423339.0,"size":2.0},{"price":11424296.0,"size":0.002},{"price":11424941.0,"size":0.972},{"price":11425000.0,"size":0.049},{"price":11426426.0,"size":0.002},{"price":11428121.0,"size":0.002},{"price":11428700.0,"size":0.001},{"price":11429302.0,"size":0.01},{"price":11432718.0,"size":0.002},{"price":11433211.0,"size":0.03},{"price":11433215.0,"size":0.001},{"price":11433333.0,"size":0.001},{"price":11437315.0,"size":0.002},{"price":11438525.0,"size":0.0011},{"price":11438700.0,"size":0.001},{"price":11439557.0,"size":0.001},{"price":11440000.0,"size":0.1038},{"price":11441911.0,"size":0.002},{"price":11443629.0,"size":0.002},{"price":11444549.0,"size":0.001},{"price":11446508.0,"size":0.001},{"price":11447000.0,"size":0.01},{"price":11447071.0,"size":0.002},{"price":11448000.0,"size":0.0875},{"price":11448700.0,"size":0.001},{"price":11450000.0,"size":0.258},{"price":11451105.0,"size":0.002},{"price":11453321.0,"size":0.03},{"price":11455702.0,"size":0.002},{"price":11455883.0,"size":0.001},{"price":11458700.0,"size":0.001},{"price":11458988.0,"size":0.01},{"price":11460000.0,"size":0.01702},{"price":11460299.0,"size":0.002},{"price":11464896.0,"size":0.002},{"price":11467217.0,"size":0.001},{"price":11468700.0,"size":0.001},{"price":11470000.0,"size":0.01},{"price":11471000.0,"size":0.01},{"price":11475000.0,"size":0.0028},{"price":11478431.0,"size":0.002},{"price":11478551.0,"size":0.001},{"price":11478700.0,"size":0.001},{"price":11480000.0,"size":0.12491},{"price":11485000.0,"size":0.01},{"price":11486555.0,"size":0.03},{"price":11487685.0,"size":0.01},{"price":11488000.0,"size":0.102},{"price":11488700.0,"size":0.001},{"price":11489885.0,"size":0.001},{"price":11490841.0,"size":0.002},{"price":11495450.0,"size":0.002},{"price":11495850.0,"size":0.001},{"price":11498700.0,"size":0.001},{"price":11498917.0,"size":0.002},{"price":11499000.0,"size":0.01},{"price":11500000.0,"size":0.69859519},{"price":11501219.0,"size":0.001},{"price":11502377.0,"size":0.002},{"price":11502800.0,"size":0.00132},{"price":11503108.0,"size":0.0198},{"price":11505000.0,"size":0.0028},{"price":11505001.0,"size":0.002},{"price":11505836.0,"size":0.003},{"price":11508431.0,"size":0.047},{"price":11508700.0,"size":0.001},{"price":11508888.0,"size":0.02},{"price":11510000.0,"size":0.0976},{"price":11512553.0,"size":0.001},{"price":11513633.0,"size":0.08},{"price":11514332.0,"size":0.02},{"price":11518700.0,"size":0.001},{"price":11518992.0,"size":0.002},{"price":11519855.0,"size":0.01},{"price":11520000.0,"size":0.001},{"price":11522423.0,"size":0.97},{"price":11523211.0,"size":0.01},{"price":11523887.0,"size":0.001},{"price":11524999.0,"size":0.001},{"price":11528700.0,"size":0.001},{"price":11529852.0,"size":0.01},{"price":11530000.0,"size":0.261},{"price":11533985.0,"size":0.002},{"price":11534084.0,"size":0.001},{"price":11535321.0,"size":0.01},{"price":11538666.0,"size":0.002},{"price":11538700.0,"size":0.001},{"price":11540000.0,"size":0.0048},{"price":11540357.0,"size":0.002},{"price":11541011.0,"size":0.005},{"price":11541109.0,"size":0.01},{"price":11544663.0,"size":0.002},{"price":11545262.0,"size":0.002},{"price":11546541.0,"size":0.01},{"price":11548144.0,"size":0.002},{"price":11548700.0,"size":0.001},{"price":11550000.0,"size":0.014},{"price":11551109.0,"size":0.01},{"price":11551625.0,"size":0.002},{"price":11552111.0,"size":0.01},{"price":11553687.0,"size":0.1},{"price":11555106.0,"size":0.002},{"price":11555115.0,"size":0.001},{"price":11556000.0,"size":0.1},{"price":11558587.0,"size":0.002},{"price":11558700.0,"size":0.001},{"price":11559855.0,"size":0.01},{"price":11560831.0,"size":0.0198},{"price":11561109.0,"size":0.01},{"price":11562000.0,"size":0.087},{"price":11562068.0,"size":0.002},{"price":11565548.0,"size":0.002},{"price":11566139.0,"size":0.0228},{"price":11566551.0,"size":0.01},{"price":11568700.0,"size":0.001},{"price":11569029.0,"size":0.002},{"price":11570196.0,"size":0.002},{"price":11571109.0,"size":0.01},{"price":11572510.0,"size":0.002},{"price":11573211.0,"size":0.01},{"price":11574840.0,"size":0.002},{"price":11575991.0,"size":0.001},{"price":11578700.0,"size":0.001},{"price":11579484.0,"size":0.002},{"price":11579851.0,"size":0.01},{"price":11580000.0,"size":0.7735},{"price":11581109.0,"size":0.01},{"price":11584128.0,"size":0.002},{"price":11585000.0,"size":0.002},{"price":11586532.0,"size":0.01},{"price":11587498.0,"size":0.0198},{"price":11588700.0,"size":0.001},{"price":11589612.0,"size":0.012},{"price":11590000.0,"size":0.1},{"price":11590749.0,"size":0.002},{"price":11591109.0,"size":0.01},{"price":11593211.0,"size":0.01},{"price":11596753.0,"size":0.002},{"price":11598555.0,"size":0.01},{"price":11598700.0,"size":0.001},{"price":11599999.0,"size":0.001},{"price":11600000.0,"size":3.6141},{"price":11601109.0,"size":0.02},{"price":11606655.0,"size":0.01},{"price":11610000.0,"size":0.302},{"price":11611109.0,"size":0.01},{"price":11613321.0,"size":0.01},{"price":11620000.0,"size":1.35441682},{"price":11621011.0,"size":0.01},{"price":11621109.0,"size":0.01},{"price":11623096.0,"size":0.008},{"price":11629000.0,"size":0.1},{"price":11630000.0,"size":0.201},{"price":11631059.0,"size":0.01},{"price":11631479.0,"size":0.01},{"price":11631773.0,"size":0.00386871},{"price":11635950.0,"size":0.001},{"price":11638259.0,"size":0.001},{"price":11639700.0,"size":0.001},{"price":11640000.0,"size":1.0},{"price":11640820.0,"size":0.01},{"price":11645040.0,"size":1.7},{"price":11645295.0,"size":0.05},{"price":11647158.0,"size":0.05},{"price":11649900.0,"size":0.02906},{"price":11649999.0,"size":0.001},{"price":11650000.0,"size":0.593},{"price":11651059.0,"size":0.01},{"price":11653658.0,"size":0.008},{"price":11654321.0,"size":0.001},{"price":11659700.0,"size":0.001},{"price":11661479.0,"size":0.01},{"price":11666000.0,"size":0.001},{"price":11666666.0,"size":0.013},{"price":11669700.0,"size":0.001},{"price":11671059.0,"size":0.01},{"price":11672562.0,"size":0.0198},{"price":11679224.0,"size":0.012},{"price":11680000.0,"size":0.004},{"price":11685000.0,"size":0.003},{"price":11688000.0,"size":0.001},{"price":11689732.0,"size":0.01},{"price":11690330.0,"size":0.0198},{"price":11691059.0,"size":0.01},{"price":11692558.0,"size":0.01},{"price":11698800.0,"size":0.00131},{"price":11699000.0,"size":0.001},{"price":11699631.0,"size":0.001},{"price":11699998.0,"size":0.01},{"price":11699999.0,"size":0.001},{"price":11700000.0,"size":1.03762841},{"price":11701059.0,"size":0.01},{"price":11720000.0,"size":0.1},{"price":11721059.0,"size":0.01},{"price":11725000.0,"size":0.005},{"price":11726791.0,"size":0.01},{"price":11730000.0,"size":0.9382},{"price":11740000.0,"size":0.101}]}}}
{"schema_version":"collector.vnext.raw","schema_contract":null,"schema_contract_version":null,"payload_contract_version":null,"record_type":"market.orderbook.diff","record_id":"collector_main-market-orderbook-diff-000000000061","collector_id":"collector_main","collector_role":"production","host_name":"MAIN-PC","session_id":"collector_main-sess-20260314T203217Z-564a9aa3","stream_session_id":"collector_main-stream-bitflyer-board_ws-20260314T203220Z-265dacdd","exchange":"bitflyer","market":"spot","symbol":"BTC_JPY","instrument_id":"bitflyer.spot.BTC_JPY","channel":"board_ws","transport":"websocket","source_event_id":null,"source_sequence":null,"sequence_id":61,"exchange_ts":null,"collector_ts":"2026-03-14T20:32:20Z","ingest_ts":"2026-03-14T20:32:20Z","event_ts":"2026-03-14T20:32:20Z","quality_flags":[],"is_partial":false,"is_reconstructed":false,"confidence_score":1.0,"payload":{"provider":"bitflyer_ws_board","exchange":"bitflyer","transport":"websocket","channel":"lightning_board_BTC_JPY","received_ts":"2026-03-14T20:32:20.204357Z","subscription_id":null,"message_id":null,"source_sequence":null,"raw_message_meta":{"raw_channel":"lightning_board_BTC_JPY","subscription_channel":"lightning_board_BTC_JPY","recv_timeout_sec":10,"ssl_verify":false,"socket_url":"wss://ws.lightstream.bitflyer.com/json-rpc"},"source_payload":{"mid_price":11313432.0,"bids":[{"price":11311124.0,"size":0.0},{"price":11311150.0,"size":0.0}],"asks":[]}}}
{"schema_version":"collector.vnext.raw","schema_contract":null,"schema_contract_version":null,"payload_contract_version":null,"record_type":"market.orderbook.diff","record_id":"collector_main-market-orderbook-diff-000000000065","collector_id":"collector_main","collector_role":"production","host_name":"MAIN-PC","session_id":"collector_main-sess-20260314T203217Z-564a9aa3","stream_session_id":"collector_main-stream-bitflyer-board_ws-20260314T203220Z-265dacdd","exchange":"bitflyer","market":"spot","symbol":"BTC_JPY","instrument_id":"bitflyer.spot.BTC_JPY","channel":"board_ws","transport":"websocket","source_event_id":null,"source_sequence":null,"sequence_id":65,"exchange_ts":null,"collector_ts":"2026-03-14T20:32:20Z","ingest_ts":"2026-03-14T20:32:20Z","event_ts":"2026-03-14T20:32:20Z","quality_flags":[],"is_partial":false,"is_reconstructed":false,"confidence_score":1.0,"payload":{"provider":"bitflyer_ws_board","exchange":"bitflyer","transport":"websocket","channel":"lightning_board_BTC_JPY","received_ts":"2026-03-14T20:32:20.329679Z","subscription_id":null,"message_id":null,"source_sequence":null,"raw_message_meta":{"raw_channel":"lightning_board_BTC_JPY","subscription_channel":"lightning_board_BTC_JPY","recv_timeout_sec":10,"ssl_verify":false,"socket_url":"wss://ws.lightstream.bitflyer.com/json-rpc"},"source_payload":{"mid_price":11313432.0,"bids":[{"price":11311159.0,"size":0.0}],"asks":[]}}}
{"schema_version":"collector.vnext.raw","schema_contract":null,"schema_contract_version":null,"payload_contract_version":null,"record_type":"market.orderbook.diff","record_id":"collector_main-market-orderbook-diff-000000000067","collector_id":"collector_main","collector_role":"production","host_name":"MAIN-PC","session_id":"collector_main-sess-20260314T203217Z-564a9aa3","stream_session_id":"collector_main-stream-bitflyer-board_ws-20260314T203220Z-265dacdd","exchange":"bitflyer","market":"spot","symbol":"BTC_JPY","instrument_id":"bitflyer.spot.BTC_JPY","channel":"board_ws","transport":"websocket","source_event_id":null,"source_sequence":null,"sequence_id":67,"exchange_ts":null,"collector_ts":"2026-03-14T20:32:20Z","ingest_ts":"2026-03-14T20:32:20Z","event_ts":"2026-03-14T20:32:20Z","quality_flags":[],"is_partial":false,"is_reconstructed":false,"confidence_score":1.0,"payload":{"provider":"bitflyer_ws_board","exchange":"bitflyer","transport":"websocket","channel":"lightning_board_BTC_JPY","received_ts":"2026-03-14T20:32:20.438910Z","subscription_id":null,"message_id":null,"source_sequence":null,"raw_message_meta":{"raw_channel":"lightning_board_BTC_JPY","subscription_channel":"lightning_board_BTC_JPY","recv_timeout_sec":10,"ssl_verify":false,"socket_url":"wss://ws.lightstream.bitflyer.com/json-rpc"},"source_payload":{"mid_price":11313432.0,"bids":[{"price":11311151.0,"size":0.0},{"price":11311160.0,"size":0.0}],"asks":[]}}}
{"schema_version":"collector.vnext.raw","schema_contract":null,"schema_contract_version":null,"payload_contract_version":null,"record_type":"market.orderbook.diff","record_id":"collector_main-market-orderbook-diff-000000000069","collector_id":"collector_main","collector_role":"production","host_name":"MAIN-PC","session_id":"collector_main-sess-20260314T203217Z-564a9aa3","stream_session_id":"collector_main-stream-bitflyer-board_ws-20260314T203220Z-265dacdd","exchange":"bitflyer","market":"spot","symbol":"BTC_JPY","instrument_id":"bitflyer.spot.BTC_JPY","channel":"board_ws","transport":"websocket","source_event_id":null,"source_sequence":null,"sequence_id":69,"exchange_ts":null,"collector_ts":"2026-03-14T20:32:20Z","ingest_ts":"2026-03-14T20:32:20Z","event_ts":"2026-03-14T20:32:20Z","quality_flags":[],"is_partial":false,"is_reconstructed":false,"confidence_score":1.0,"payload":{"provider":"bitflyer_ws_board","exchange":"bitflyer","transport":"websocket","channel":"lightning_board_BTC_JPY","received_ts":"2026-03-14T20:32:20.578908Z","subscription_id":null,"message_id":null,"source_sequence":null,"raw_message_meta":{"raw_channel":"lightning_board_BTC_JPY","subscription_channel":"lightning_board_BTC_JPY","recv_timeout_sec":10,"ssl_verify":false,"socket_url":"wss://ws.lightstream.bitflyer.com/json-rpc"},"source_payload":{"mid_price":11312834.0,"bids":[{"price":11311161.0,"size":0.0},{"price":11309965.0,"size":0.05304749}],"asks":[]}}}
{"schema_version":"collector.vnext.raw","schema_contract":null,"schema_contract_version":null,"payload_contract_version":null,"record_type":"market.orderbook.diff","record_id":"collector_main-market-orderbook-diff-000000000071","collector_id":"collector_main","collector_role":"production","host_name":"MAIN-PC","session_id":"collector_main-sess-20260314T203217Z-564a9aa3","stream_session_id":"collector_main-stream-bitflyer-board_ws-20260314T203220Z-265dacdd","exchange":"bitflyer","market":"spot","symbol":"BTC_JPY","instrument_id":"bitflyer.spot.BTC_JPY","channel":"board_ws","transport":"websocket","source_event_id":null,"source_sequence":null,"sequence_id":71,"exchange_ts":null,"collector_ts":"2026-03-14T20:32:20Z","ingest_ts":"2026-03-14T20:32:20Z","event_ts":"2026-03-14T20:32:20Z","quality_flags":[],"is_partial":false,"is_reconstructed":false,"confidence_score":1.0,"payload":{"provider":"bitflyer_ws_board","exchange":"bitflyer","transport":"websocket","channel":"lightning_board_BTC_JPY","received_ts":"2026-03-14T20:32:20.719731Z","subscription_id":null,"message_id":null,"source_sequence":null,"raw_message_meta":{"raw_channel":"lightning_board_BTC_JPY","subscription_channel":"lightning_board_BTC_JPY","recv_timeout_sec":10,"ssl_verify":false,"socket_url":"wss://ws.lightstream.bitflyer.com/json-rpc"},"source_payload":{"mid_price":11312834.0,"bids":[],"asks":[{"price":11320216.0,"size":0.0}]}}}
{"schema_version":"collector.vnext.raw","schema_contract":null,"schema_contract_version":null,"payload_contract_version":null,"record_type":"market.orderbook.diff","record_id":"collector_main-market-orderbook-diff-000000000073","collector_id":"collector_main","collector_role":"production","host_name":"MAIN-PC","session_id":"collector_main-sess-20260314T203217Z-564a9aa3","stream_session_id":"collector_main-stream-bitflyer-board_ws-20260314T203220Z-265dacdd","exchange":"bitflyer","market":"spot","symbol":"BTC_JPY","instrument_id":"bitflyer.spot.BTC_JPY","channel":"board_ws","transport":"websocket","source_event_id":null,"source_sequence":null,"sequence_id":73,"exchange_ts":null,"collector_ts":"2026-03-14T20:32:20Z","ingest_ts":"2026-03-14T20:32:20Z","event_ts":"2026-03-14T20:32:20Z","quality_flags":[],"is_partial":false,"is_reconstructed":false,"confidence_score":1.0,"payload":{"provider":"bitflyer_ws_board","exchange":"bitflyer","transport":"websocket","channel":"lightning_board_BTC_JPY","received_ts":"2026-03-14T20:32:20.829290Z","subscription_id":null,"message_id":null,"source_sequence":null,"raw_message_meta":{"raw_channel":"lightning_board_BTC_JPY","subscription_channel":"lightning_board_BTC_JPY","recv_timeout_sec":10,"ssl_verify":false,"socket_url":"wss://ws.lightstream.bitflyer.com/json-rpc"},"source_payload":{"mid_price":11312834.0,"bids":[{"price":11309669.0,"size":0.008357},{"price":11309966.0,"size":0.02}],"asks":[]}}}
{"schema_version":"collector.vnext.raw","schema_contract":null,"schema_contract_version":null,"payload_contract_version":null,"record_type":"market.orderbook.diff","record_id":"collector_main-market-orderbook-diff-000000000075","collector_id":"collector_main","collector_role":"production","host_name":"MAIN-PC","session_id":"collector_main-sess-20260314T203217Z-564a9aa3","stream_session_id":"collector_main-stream-bitflyer-board_ws-20260314T203220Z-265dacdd","exchange":"bitflyer","market":"spot","symbol":"BTC_JPY","instrument_id":"bitflyer.spot.BTC_JPY","channel":"board_ws","transport":"websocket","source_event_id":null,"source_sequence":null,"sequence_id":75,"exchange_ts":null,"collector_ts":"2026-03-14T20:32:20Z","ingest_ts":"2026-03-14T20:32:20Z","event_ts":"2026-03-14T20:32:20Z","quality_flags":[],"is_partial":false,"is_reconstructed":false,"confidence_score":1.0,"payload":{"provider":"bitflyer_ws_board","exchange":"bitflyer","transport":"websocket","channel":"lightning_board_BTC_JPY","received_ts":"2026-03-14T20:32:20.954039Z","subscription_id":null,"message_id":null,"source_sequence":null,"raw_message_meta":{"raw_channel":"lightning_board_BTC_JPY","subscription_channel":"lightning_board_BTC_JPY","recv_timeout_sec":10,"ssl_verify":false,"socket_url":"wss://ws.lightstream.bitflyer.com/json-rpc"},"source_payload":{"mid_price":11312834.0,"bids":[{"price":11308162.0,"size":0.02},{"price":10134884.0,"size":0.00392}],"asks":[{"price":12044668.0,"size":0.00599}]}}}
{"schema_version":"collector.vnext.raw","schema_contract":null,"schema_contract_version":null,"payload_contract_version":null,"record_type":"market.orderbook.diff","record_id":"collector_main-market-orderbook-diff-000000000077","collector_id":"collector_main","collector_role":"production","host_name":"MAIN-PC","session_id":"collector_main-sess-20260314T203217Z-564a9aa3","stream_session_id":"collector_main-stream-bitflyer-board_ws-20260314T203220Z-265dacdd","exchange":"bitflyer","market":"spot","symbol":"BTC_JPY","instrument_id":"bitflyer.spot.BTC_JPY","channel":"board_ws","transport":"websocket","source_event_id":null,"source_sequence":null,"sequence_id":77,"exchange_ts":null,"collector_ts":"2026-03-14T20:32:21Z","ingest_ts":"2026-03-14T20:32:21Z","event_ts":"2026-03-14T20:32:21Z","quality_flags":[],"is_partial":false,"is_reconstructed":false,"confidence_score":1.0,"payload":{"provider":"bitflyer_ws_board","exchange":"bitflyer","transport":"websocket","channel":"lightning_board_BTC_JPY","received_ts":"2026-03-14T20:32:21.047446Z","subscription_id":null,"message_id":null,"source_sequence":null,"raw_message_meta":{"raw_channel":"lightning_board_BTC_JPY","subscription_channel":"lightning_board_BTC_JPY","recv_timeout_sec":10,"ssl_verify":false,"socket_url":"wss://ws.lightstream.bitflyer.com/json-rpc"},"source_payload":{"mid_price":11312834.0,"bids":[{"price":11308024.0,"size":0.02},{"price":11309965.0,"size":0.0}],"asks":[{"price":11316466.0,"size":0.0}]}}}
{"schema_version":"collector.vnext.raw","schema_contract":null,"schema_contract_version":null,"payload_contract_version":null,"record_type":"market.orderbook.diff","record_id":"collector_main-market-orderbook-diff-000000000079","collector_id":"collector_main","collector_role":"production","host_name":"MAIN-PC","session_id":"collector_main-sess-20260314T203217Z-564a9aa3","stream_session_id":"collector_main-stream-bitflyer-board_ws-20260314T203220Z-265dacdd","exchange":"bitflyer","market":"spot","symbol":"BTC_JPY","instrument_id":"bitflyer.spot.BTC_JPY","channel":"board_ws","transport":"websocket","source_event_id":null,"source_sequence":null,"sequence_id":79,"exchange_ts":null,"collector_ts":"2026-03-14T20:32:21Z","ingest_ts":"2026-03-14T20:32:21Z","event_ts":"2026-03-14T20:32:21Z","quality_flags":[],"is_partial":false,"is_reconstructed":false,"confidence_score":1.0,"payload":{"provider":"bitflyer_ws_board","exchange":"bitflyer","transport":"websocket","channel":"lightning_board_BTC_JPY","received_ts":"2026-03-14T20:32:21.157829Z","subscription_id":null,"message_id":null,"source_sequence":null,"raw_message_meta":{"raw_channel":"lightning_board_BTC_JPY","subscription_channel":"lightning_board_BTC_JPY","recv_timeout_sec":10,"ssl_verify":false,"socket_url":"wss://ws.lightstream.bitflyer.com/json-rpc"},"source_payload":{"mid_price":11313388.0,"bids":[{"price":11309967.0,"size":0.0549592},{"price":11309516.0,"size":0.02},{"price":11308024.0,"size":0.0},{"price":11311073.0,"size":0.02}],"asks":[]}}}
{"schema_version":"collector.vnext.raw","schema_contract":null,"schema_contract_version":null,"payload_contract_version":null,"record_type":"market.orderbook.diff","record_id":"collector_main-market-orderbook-diff-000000000081","collector_id":"collector_main","collector_role":"production","host_name":"MAIN-PC","session_id":"collector_main-sess-20260314T203217Z-564a9aa3","stream_session_id":"collector_main-stream-bitflyer-board_ws-20260314T203220Z-265dacdd","exchange":"bitflyer","market":"spot","symbol":"BTC_JPY","instrument_id":"bitflyer.spot.BTC_JPY","channel":"board_ws","transport":"websocket","source_event_id":null,"source_sequence":null,"sequence_id":81,"exchange_ts":null,"collector_ts":"2026-03-14T20:32:21Z","ingest_ts":"2026-03-14T20:32:21Z","event_ts":"2026-03-14T20:32:21Z","quality_flags":[],"is_partial":false,"is_reconstructed":false,"confidence_score":1.0,"payload":{"provider":"bitflyer_ws_board","exchange":"bitflyer","transport":"websocket","channel":"lightning_board_BTC_JPY","received_ts":"2026-03-14T20:32:21.268136Z","subscription_id":null,"message_id":null,"source_sequence":null,"raw_message_meta":{"raw_channel":"lightning_board_BTC_JPY","subscription_channel":"lightning_board_BTC_JPY","recv_timeout_sec":10,"ssl_verify":false,"socket_url":"wss://ws.lightstream.bitflyer.com/json-rpc"},"source_payload":{"mid_price":11313300.0,"bids":[{"price":11308162.0,"size":0.0},{"price":11309670.0,"size":0.02},{"price":11309966.0,"size":0.0},{"price":11311124.0,"size":0.1275}],"asks":[{"price":11315476.0,"size":0.00997228},{"price":11317348.0,"size":0.1275}]}}}
{"schema_version":"collector.vnext.raw","schema_contract":null,"schema_contract_version":null,"payload_contract_version":null,"record_type":"market.orderbook.diff","record_id":"collector_main-market-orderbook-diff-000000000083","collector_id":"collector_main","collector_role":"production","host_name":"MAIN-PC","session_id":"collector_main-sess-20260314T203217Z-564a9aa3","stream_session_id":"collector_main-stream-bitflyer-board_ws-20260314T203220Z-265dacdd","exchange":"bitflyer","market":"spot","symbol":"BTC_JPY","instrument_id":"bitflyer.spot.BTC_JPY","channel":"board_ws","transport":"websocket","source_event_id":null,"source_sequence":null,"sequence_id":83,"exchange_ts":null,"collector_ts":"2026-03-14T20:32:21Z","ingest_ts":"2026-03-14T20:32:21Z","event_ts":"2026-03-14T20:32:21Z","quality_flags":[],"is_partial":false,"is_reconstructed":false,"confidence_score":1.0,"payload":{"provider":"bitflyer_ws_board","exchange":"bitflyer","transport":"websocket","channel":"lightning_board_BTC_JPY","received_ts":"2026-03-14T20:32:21.375534Z","subscription_id":null,"message_id":null,"source_sequence":null,"raw_message_meta":{"raw_channel":"lightning_board_BTC_JPY","subscription_channel":"lightning_board_BTC_JPY","recv_timeout_sec":10,"ssl_verify":false,"socket_url":"wss://ws.lightstream.bitflyer.com/json-rpc"},"source_payload":{"mid_price":11313300.0,"bids":[{"price":11309967.0,"size":0.0},{"price":11311074.0,"size":0.04759529},{"price":11311125.0,"size":0.1275}],"asks":[]}}}
{"schema_version":"collector.vnext.raw","schema_contract":null,"schema_contract_version":null,"payload_contract_version":null,"record_type":"market.orderbook.diff","record_id":"collector_main-market-orderbook-diff-000000000085","collector_id":"collector_main","collector_role":"production","host_name":"MAIN-PC","session_id":"collector_main-sess-20260314T203217Z-564a9aa3","stream_session_id":"collector_main-stream-bitflyer-board_ws-20260314T203220Z-265dacdd","exchange":"bitflyer","market":"spot","symbol":"BTC_JPY","instrument_id":"bitflyer.spot.BTC_JPY","channel":"board_ws","transport":"websocket","source_event_id":null,"source_sequence":null,"sequence_id":85,"exchange_ts":null,"collector_ts":"2026-03-14T20:32:21Z","ingest_ts":"2026-03-14T20:32:21Z","event_ts":"2026-03-14T20:32:21Z","quality_flags":[],"is_partial":false,"is_reconstructed":false,"confidence_score":1.0,"payload":{"provider":"bitflyer_ws_board","exchange":"bitflyer","transport":"websocket","channel":"lightning_board_BTC_JPY","received_ts":"2026-03-14T20:32:21.525681Z","subscription_id":null,"message_id":null,"source_sequence":null,"raw_message_meta":{"raw_channel":"lightning_board_BTC_JPY","subscription_channel":"lightning_board_BTC_JPY","recv_timeout_sec":10,"ssl_verify":false,"socket_url":"wss://ws.lightstream.bitflyer.com/json-rpc"},"source_payload":{"mid_price":11313300.0,"bids":[{"price":11311074.0,"size":0.0},{"price":11311125.0,"size":0.17124774}],"asks":[{"price":11315703.0,"size":0.0},{"price":11317357.0,"size":0.0},{"price":11315475.0,"size":0.01137767},{"price":11317260.0,"size":0.0327},{"price":11315704.0,"size":0.0}]}}}
{"schema_version":"collector.vnext.raw","schema_contract":null,"schema_contract_version":null,"payload_contract_version":null,"record_type":"market.orderbook.diff","record_id":"collector_main-market-orderbook-diff-000000000087","collector_id":"collector_main","collector_role":"production","host_name":"MAIN-PC","session_id":"collector_main-sess-20260314T203217Z-564a9aa3","stream_session_id":"collector_main-stream-bitflyer-board_ws-20260314T203220Z-265dacdd","exchange":"bitflyer","market":"spot","symbol":"BTC_JPY","instrument_id":"bitflyer.spot.BTC_JPY","channel":"board_ws","transport":"websocket","source_event_id":null,"source_sequence":null,"sequence_id":87,"exchange_ts":null,"collector_ts":"2026-03-14T20:32:21Z","ingest_ts":"2026-03-14T20:32:21Z","event_ts":"2026-03-14T20:32:21Z","quality_flags":[],"is_partial":false,"is_reconstructed":false,"confidence_score":1.0,"payload":{"provider":"bitflyer_ws_board","exchange":"bitflyer","transport":"websocket","channel":"lightning_board_BTC_JPY","received_ts":"2026-03-14T20:32:21.631116Z","subscription_id":null,"message_id":null,"source_sequence":null,"raw_message_meta":{"raw_channel":"lightning_board_BTC_JPY","subscription_channel":"lightning_board_BTC_JPY","recv_timeout_sec":10,"ssl_verify":false,"socket_url":"wss://ws.lightstream.bitflyer.com/json-rpc"},"source_payload":{"mid_price":11313300.0,"bids":[{"price":11309669.0,"size":0.0}],"asks":[{"price":11315476.0,"size":0.08217228}]}}}
{"schema_version":"collector.vnext.raw","schema_contract":null,"schema_contract_version":null,"payload_contract_version":null,"record_type":"market.orderbook.diff","record_id":"collector_main-market-orderbook-diff-000000000089","collector_id":"collector_main","collector_role":"production","host_name":"MAIN-PC","session_id":"collector_main-sess-20260314T203217Z-564a9aa3","stream_session_id":"collector_main-stream-bitflyer-board_ws-20260314T203220Z-265dacdd","exchange":"bitflyer","market":"spot","symbol":"BTC_JPY","instrument_id":"bitflyer.spot.BTC_JPY","channel":"board_ws","transport":"websocket","source_event_id":null,"source_sequence":null,"sequence_id":89,"exchange_ts":null,"collector_ts":"2026-03-14T20:32:21Z","ingest_ts":"2026-03-14T20:32:21Z","event_ts":"2026-03-14T20:32:21Z","quality_flags":[],"is_partial":false,"is_reconstructed":false,"confidence_score":1.0,"payload":{"provider":"bitflyer_ws_board","exchange":"bitflyer","transport":"websocket","channel":"lightning_board_BTC_JPY","received_ts":"2026-03-14T20:32:21.768173Z","subscription_id":null,"message_id":null,"source_sequence":null,"raw_message_meta":{"raw_channel":"lightning_board_BTC_JPY","subscription_channel":"lightning_board_BTC_JPY","recv_timeout_sec":10,"ssl_verify":false,"socket_url":"wss://ws.lightstream.bitflyer.com/json-rpc"},"source_payload":{"mid_price":11313300.0,"bids":[{"price":11309670.0,"size":0.0}],"asks":[]}}}
