{"schema_version":"collector.vnext.raw","schema_contract":null,"schema_contract_version":null,"payload_contract_version":null,"record_type":"market.orderbook.snapshot","record_id":"collector_main-market-orderbook-snapshot-000000000099","collector_id":"collector_main","collector_role":"production","host_name":"MAIN-PC","session_id":"collector_main-sess-20260314T200620Z-29b5dd1a","stream_session_id":"collector_main-stream-bitflyer-board_ws-20260314T200742Z-39ba71d1","exchange":"bitflyer","market":"spot","symbol":"BTC_JPY","instrument_id":"bitflyer.spot.BTC_JPY","channel":"board_ws","transport":"websocket","source_event_id":null,"source_sequence":null,"sequence_id":99,"exchange_ts":null,"collector_ts":"2026-03-14T20:07:45Z","ingest_ts":"2026-03-14T20:07:45Z","event_ts":"2026-03-14T20:07:45Z","quality_flags":[],"is_partial":false,"is_reconstructed":false,"confidence_score":1.0,"payload":{"provider":"bitflyer_ws_board_snapshot","exchange":"bitflyer","transport":"websocket","channel":"lightning_board_snapshot_BTC_JPY","received_ts":"2026-03-14T20:07:45.545139Z","subscription_id":null,"message_id":null,"source_sequence":null,"raw_message_meta":{"raw_channel":"lightning_board_snapshot_BTC_JPY","subscription_channel":"lightning_board_snapshot_BTC_JPY","recv_timeout_sec":10,"ssl_verify":false,"socket_url":"wss://ws.lightstream.bitflyer.com/json-rpc"},"source_payload":{"mid_price":11304467.0,"bids":[{"price":11301682.0,"size":0.05846985},{"price":11301681.0,"size":0.1275},{"price":11301422.0,"size":0.1275},{"price":11300902.0,"size":0.00999859},{"price":11300884.0,"size":0.014736},{"price":11300480.0,"size":0.015396},{"price":11300159.0,"size":0.015348},{"price":11299842.0,"size":0.014904},{"price":11298420.0,"size":0.05},{"price":11298105.0,"size":0.005},{"price":11297887.0,"size":0.0531},{"price":11297439.0,"size":0.5},{"price":11296579.0,"size":0.0546048},{"price":11294182.0,"size":0.01},{"price":11293572.0,"size":2.9745938},{"price":11293571.0,"size":0.5},{"price":11293270.0,"size":0.0801},{"price":11292166.0,"size":0.0019547},{"price":11291329.0,"size":0.00999859},{"price":11289447.0,"size":0.35602834},{"price":11289443.0,"size":0.04},{"price":11288418.0,"size":0.042},{"price":11287378.0,"size":1.50015},{"price":11286651.0,"size":0.98403398},{"price":11286157.0,"size":0.144},{"price":11280205.0,"size":0.001},{"price":11279788.0,"size":0.3091},{"price":11279282.0,"size":0.0015},{"price":11277748.0,"size":0.0966561},{"price":11277602.0,"size":0.005},{"price":11277083.0,"size":0.6},{"price":11277026.0,"size":0.2566},{"price":11276220.0,"size":0.002},{"price":11275360.0,"size":1.484},{"price":11275103.0,"size":0.17894886},{"price":11275102.0,"size":0.01},{"price":11275000.0,"size":0.001},{"price":11274588.0,"size":0.0047},{"price":11274264.0,"size":0.3084},{"price":11273619.0,"size":0.002},{"price":11271699.0,"size":0.002},{"price":11271502.0,"size":0.2661},{"price":11271000.0,"size":0.003},{"price":11270229.0,"size":0.002},{"price":11270000.0,"size":0.106},{"price":11268871.0,"size":0.281},{"price":11268411.0,"size":0.01},{"price":11267178.0,"size":0.002},{"price":11266839.0,"size":0.002},{"price":11266666.0,"size":0.04},{"price":11265000.0,"size":0.02},{"price":11263999.0,"size":1.966},{"price":11263449.0,"size":0.002},{"price":11263000.0,"size":0.006},{"price":11262564.0,"size":0.0015},{"price":11260059.0,"size":0.002},{"price":11260000.0,"size":0.3565},{"price":11257537.0,"size":0.001},{"price":11257000.0,"size":0.001},{"price":11256669.0,"size":0.002},{"price":11255200.0,"size":0.001},{"price":11255115.0,"size":0.00377},{"price":11253279.0,"size":0.002},{"price":11253000.0,"size":0.03189},{"price":11251000.0,"size":0.0131},{"price":11250250.0,"size":0.00105},{"price":11250200.0,"size":0.001},{"price":11250100.0,"size":0.015},{"price":11250005.0,"size":0.001},{"price":11250001.0,"size":0.00104},{"price":11250000.0,"size":0.76834},{"price":11249889.0,"size":0.002},{"price":11246544.0,"size":0.0015},{"price":11246499.0,"size":0.002},{"price":11246203.0,"size":0.001},{"price":11245141.0,"size":0.0031},{"price":11245000.0,"size":0.05},{"price":11244444.0,"size":0.04},{"price":11244243.0,"size":0.01},{"price":11243109.0,"size":0.002},{"price":11240200.0,"size":0.001},{"price":11240000.0,"size":0.007304},{"price":11236190.0,"size":0.01},{"price":11235200.0,"size":0.001},{"price":11234869.0,"size":0.001},{"price":11233345.0,"size":2.036},{"price":11232000.0,"size":0.089},{"price":11231243.0,"size":0.01},{"price":11231000.0,"size":0.105},{"price":11230200.0,"size":0.001},{"price":11230000.0,"size":0.0308},{"price":11228423.0,"size":1.951},{"price":11224500.0,"size":0.06},{"price":11224355.0,"size":0.0015},{"price":11223968.0,"size":0.001},{"price":11223535.0,"size":0.001},{"price":11223344.0,"size":0.01},{"price":11223000.0,"size":0.1},{"price":11222222.0,"size":0.092525},{"price":11221459.0,"size":0.1393},{"price":11221120.0,"size":0.011},{"price":11220200.0,"size":0.001},{"price":11220001.0,"size":0.004457},{"price":11220000.0,"size":0.321},{"price":11219595.0,"size":1.79},{"price":11219517.0,"size":0.01},{"price":11219000.0,"size":0.1},{"price":11215200.0,"size":0.001},{"price":11215000.0,"size":0.02},{"price":11212358.0,"size":1.2},{"price":11212201.0,"size":0.001},{"price":11211800.0,"size":0.001},{"price":11211111.0,"size":0.06},{"price":11210200.0,"size":0.001},{"price":11210000.0,"size":0.10622},{"price":11208032.0,"size":0.01},{"price":11207755.0,"size":0.0015},{"price":11206000.0,"size":0.09015},{"price":11205200.0,"size":0.001},{"price":11204578.0,"size":0.002},{"price":11203931.0,"size":1.0},{"price":11201000.0,"size":0.01},{"price":11200867.0,"size":0.001},{"price":11200800.0,"size":0.05},{"price":11200425.0,"size":0.1},{"price":11200200.0,"size":0.001},{"price":11200198.0,"size":0.003},{"price":11200150.0,"size":0.002},{"price":11200002.0,"size":0.001},{"price":11200001.0,"size":0.01104},{"price":11200000.0,"size":1.35988728},{"price":11198508.0,"size":0.05},{"price":11198243.0,"size":0.01},{"price":11197134.0,"size":2.0},{"price":11197000.0,"size":0.0085},{"price":11195692.0,"size":0.0015},{"price":11194090.0,"size":0.03},{"price":11190770.0,"size":0.0309},{"price":11190000.0,"size":0.0010016},{"price":11189555.0,"size":0.5},{"price":11189533.0,"size":0.001},{"price":11188629.0,"size":0.01},{"price":11188382.0,"size":0.001},{"price":11185000.0,"size":0.0085},{"price":11180043.0,"size":0.972},{"price":11180000.0,"size":0.23215},{"price":11178973.0,"size":0.0015},{"price":11178199.0,"size":0.001},{"price":11170000.0,"size":0.001},{"price":11169662.0,"size":0.01},{"price":11169593.0,"size":0.001},{"price":11169243.0,"size":0.01},{"price":11166865.0,"size":0.001},{"price":11164029.0,"size":0.001},{"price":11160854.0,"size":0.1},{"price":11160000.0,"size":0.02376},{"price":11156269.0,"size":0.01},{"price":11155531.0,"size":0.001},{"price":11155377.0,"size":0.00636009},{"price":11153999.0,"size":0.00101},{"price":11150250.0,"size":0.00175},{"price":11150005.0,"size":0.001},{"price":11150001.0,"size":0.00104},{"price":11150000.0,"size":0.6398956},{"price":11148000.0,"size":0.08963},{"price":11144197.0,"size":0.001},{"price":11144000.0,"size":0.0897},{"price":11140000.0,"size":0.2},{"price":11136243.0,"size":0.01},{"price":11135869.0,"size":0.1},{"price":11130000.0,"size":0.116},{"price":11129979.0,"size":0.0053908},{"price":11126388.0,"size":0.02},{"price":11124900.0,"size":0.00133},{"price":11121090.0,"size":0.1},{"price":11120000.0,"size":0.0033},{"price":11118078.0,"size":0.01},{"price":11111800.0,"size":0.001},{"price":11111111.0,"size":0.2919257},{"price":11111000.0,"size":0.003},{"price":11110594.0,"size":0.001},{"price":11110000.0,"size":0.056937},{"price":11109662.0,"size":0.01},{"price":11108008.0,"size":0.01},{"price":11106000.0,"size":0.2},{"price":11105000.0,"size":0.02},{"price":11101297.0,"size":0.001},{"price":11100005.0,"size":0.001},{"price":11100001.0,"size":0.01104},{"price":11100000.0,"size":2.7475049},{"price":11099141.0,"size":0.01},{"price":11096243.0,"size":0.01},{"price":11094090.0,"size":0.01},{"price":11088888.0,"size":0.001},{"price":11085245.0,"size":0.001},{"price":11080200.0,"size":0.001},{"price":11080000.0,"size":0.0223},{"price":11075100.0,"size":0.003},{"price":11071558.0,"size":1.0},{"price":11070200.0,"size":0.001},{"price":11070000.0,"size":0.0902},{"price":11065200.0,"size":0.001},{"price":11064370.0,"size":0.00497091},{"price":11060200.0,"size":0.001},{"price":11060000.0,"size":0.145},{"price":11059689.0,"size":0.009},{"price":11056428.0,"size":0.002},{"price":11055500.0,"size":0.02},{"price":11055200.0,"size":0.001},{"price":11055100.0,"size":0.003},{"price":11050200.0,"size":0.001},{"price":11050005.0,"size":0.001},{"price":11050002.0,"size":0.001},{"price":11050001.0,"size":0.00104},{"price":11050000.0,"size":0.43176147},{"price":11046420.0,"size":0.2},{"price":11044243.0,"size":0.01},{"price":11041380.0,"size":0.01},{"price":11040200.0,"size":0.001},{"price":11040000.0,"size":0.00777181},{"price":11035865.0,"size":0.1},{"price":11035200.0,"size":0.001},{"price":11035000.0,"size":0.0013},{"price":11030200.0,"size":0.001},{"price":11030000.0,"size":0.025},{"price":11025500.0,"size":0.009531},{"price":11025200.0,"size":0.001},{"price":11025000.0,"size":0.71497},{"price":11020772.0,"size":0.014},{"price":11020200.0,"size":0.002},{"price":11020000.0,"size":0.005},{"price":11015200.0,"size":0.001},{"price":11012000.0,"size":0.1},{"price":11011800.0,"size":0.001},{"price":11010200.0,"size":0.001},{"price":11010000.0,"size":0.347},{"price":11007277.0,"size":0.01},{"price":11006000.0,"size":0.2},{"price":11005200.0,"size":0.001},{"price":11004890.0,"size":0.001535},{"price":11003000.0,"size":0.0155},{"price":11001000.0,"size":0.013},{"price":11000500.0,"size":0.05117658},{"price":11000200.0,"size":0.001},{"price":11000002.0,"size":0.004},{"price":11000001.0,"size":0.02604},{"price":11000000.0,"size":5.47323365},{"price":10999999.0,"size":0.003},{"price":10999000.0,"size":0.001},{"price":10996855.0,"size":0.0011},{"price":10995200.0,"size":0.001},{"price":10994499.0,"size":0.00169176},{"price":10990200.0,"size":0.001},{"price":10990000.0,"size":0.10219},{"price":10989001.0,"size":0.00197},{"price":10988999.0,"size":0.001},{"price":10988324.0,"size":0.002},{"price":10987654.0,"size":0.001},{"price":10985200.0,"size":0.001},{"price":10985150.0,"size":0.01},{"price":10980500.0,"size":0.005},{"price":10980200.0,"size":0.001},{"price":10980002.0,"size":0.4},{"price":10980000.0,"size":0.028},{"price":10975200.0,"size":0.001},{"price":10975000.0,"size":0.1},{"price":10971261.0,"size":0.001},{"price":10971243.0,"size":0.01},{"price":10970375.0,"size":1.9},{"price":10970200.0,"size":0.001},{"price":10970000.0,"size":0.09304},{"price":10966600.0,"size":0.001003},{"price":10965200.0,"size":0.001},{"price":10960200.0,"size":0.001},{"price":10960000.0,"size":0.0083},{"price":10956673.0,"size":0.01},{"price":10955200.0,"size":0.001},{"price":10954950.0,"size":0.001},{"price":10950500.0,"size":0.005},{"price":10950001.0,"size":0.00204},{"price":10950000.0,"size":0.5485028},{"price":10949550.0,"size":0.01870657},{"price":10949172.0,"size":0.1},{"price":10948000.0,"size":0.1},{"price":10945243.0,"size":0.01},{"price":10940402.0,"size":0.001},{"price":10940200.0,"size":0.001},{"price":10940000.0,"size":0.331},{"price":10938243.0,"size":0.01},{"price":10936200.0,"size":0.00137},{"price":10935200.0,"size":0.001},{"price":10930200.0,"size":0.002},{"price":10930000.0,"size":0.0193},{"price":10925200.0,"size":0.002},{"price":10924451.0,"size":0.0012},{"price":10920509.0,"size":0.01},{"price":10920200.0,"size":0.002},{"price":10920000.0,"size":0.52},{"price":10915200.0,"size":0.001},{"price":10914000.0,"size":0.005}],"asks":[{"price":11307253.0,"size":0.07220538},{"price":11308289.0,"size":0.015372},{"price":11308930.0,"size":0.02},{"price":11309442.0,"size":0.00999365},{"price":11310316.0,"size":0.1251},{"price":11311053.0,"size":0.3089},{"price":11311117.0,"size":0.014736},{"price":11312720.0,"size":0.4199},{"price":11312851.0,"size":0.01},{"price":11313538.0,"size":0.0546048},{"price":11313815.0,"size":0.2756},{"price":11316577.0,"size":0.2935},{"price":11317167.0,"size":0.053},{"price":11317394.0,"size":0.57627111},{"price":11318050.0,"size":0.002},{"price":11318644.0,"size":0.0772},{"price":11319339.0,"size":0.2603},{"price":11320000.0,"size":0.02},{"price":11322000.0,"size":0.005},{"price":11322682.0,"size":0.0074164},{"price":11323555.0,"size":0.57939033},{"price":11323556.0,"size":1.189881},{"price":11323581.0,"size":1.189881},{"price":11328050.0,"size":0.002},{"price":11329436.0,"size":0.0015},{"price":11331059.0,"size":0.001},{"price":11334236.0,"size":0.33650097},{"price":11334237.0,"size":1.489},{"price":11335742.0,"size":1.928},{"price":11340000.0,"size":0.13586406},{"price":11340647.0,"size":0.001},{"price":11342956.0,"size":1.60199848},{"price":11342957.0,"size":0.01},{"price":11346154.0,"size":0.0015},{"price":11348000.0,"size":0.1999},{"price":11349700.0,"size":0.001},{"price":11350000.0,"size":0.022},{"price":11353877.0,"size":0.001},{"price":11354939.0,"size":0.01},{"price":11355555.0,"size":0.001},{"price":11358323.0,"size":2.018},{"price":11359242.0,"size":0.0011},{"price":11359700.0,"size":0.001},{"price":11362692.0,"size":0.0015},{"price":11365211.0,"size":0.001},{"price":11369700.0,"size":0.001},{"price":11370000.0,"size":0.1},{"price":11372478.0,"size":1.943},{"price":11376000.0,"size":0.02},{"price":11376545.0,"size":0.001},{"price":11377000.0,"size":0.2287},{"price":11377269.0,"size":0.002},{"price":11379700.0,"size":0.001},{"price":11379865.0,"size":0.03},{"price":11380000.0,"size":0.0223},{"price":11380324.0,"size":0.002},{"price":11381766.0,"size":0.4},{"price":11382386.0,"size":0.0015},{"price":11385000.0,"size":0.2548},{"price":11385403.0,"size":0.002},{"price":11385664.0,"size":0.002},{"price":11387072.0,"size":0.01},{"price":11387354.0,"size":0.002},{"price":11387879.0,"size":0.001},{"price":11388885.0,"size":0.03},{"price":11389700.0,"size":0.001},{"price":11390000.0,"size":0.2488},{"price":11390050.0,"size":0.001},{"price":11392387.0,"size":1.0},{"price":11394939.0,"size":0.01},{"price":11395000.0,"size":0.06},{"price":11395775.0,"size":0.01},{"price":11396555.0,"size":0.03},{"price":11398444.0,"size":0.001995},{"price":11399213.0,"size":0.001},{"price":11399673.0,"size":0.0015},{"price":11399700.0,"size":0.001},{"price":11400000.0,"size":0.5525},{"price":11405000.0,"size":0.0275},{"price":11406336.0,"size":1.0},{"price":11408700.0,"size":0.001},{"price":11409415.0,"size":0.055},{"price":11410000.0,"size":0.03},{"price":11410547.0,"size":0.001},{"price":11410853.0,"size":0.002},{"price":11412000.0,"size":0.0878},{"price":11415000.0,"size":0.002},{"price":11415141.0,"size":0.0041},{"price":11417481.0,"size":0.0015},{"price":11418700.0,"size":0.001},{"price":11420000.0,"size":0.401},{"price":11421268.0,"size":0.05},{"price":11421881.0,"size":0.001},{"price":11423339.0,"size":2.0},{"price":11424296.0,"size":0.002},{"price":11424941.0,"size":0.972},{"price":11425000.0,"size":0.049},{"price":11426426.0,"size":0.002},{"price":11428121.0,"size":0.002},{"price":11428700.0,"size":0.001},{"price":11429302.0,"size":0.01},{"price":11432718.0,"size":0.002},{"price":11433211.0,"size":0.03},{"price":11433215.0,"size":0.001},{"price":11433333.0,"size":0.001},{"price":11437315.0,"size":0.002},{"price":11438525.0,"size":0.0011},{"price":11438700.0,"size":0.001},{"price":11439557.0,"size":0.001},{"price":11440000.0,"size":0.1038},{"price":11441911.0,"size":0.002},{"price":11443629.0,"size":0.002},{"price":11444549.0,"size":0.001},{"price":11446508.0,"size":0.001},{"price":11447000.0,"size":0.01},{"price":11447071.0,"size":0.002},{"price":11448000.0,"size":0.0875},{"price":11448700.0,"size":0.001},{"price":11450000.0,"size":0.263},{"price":11451105.0,"size":0.002},{"price":11453321.0,"size":0.03},{"price":11455702.0,"size":0.002},{"price":11455883.0,"size":0.001},{"price":11458700.0,"size":0.001},{"price":11458988.0,"size":0.01},{"price":11460000.0,"size":0.01702},{"price":11460299.0,"size":0.002},{"price":11464896.0,"size":0.002},{"price":11467217.0,"size":0.001},{"price":11468700.0,"size":0.001},{"price":11470000.0,"size":0.01},{"price":11471000.0,"size":0.01},{"price":11475000.0,"size":0.0028},{"price":11478431.0,"size":0.002},{"price":11478551.0,"size":0.001},{"price":11478700.0,"size":0.001},{"price":11480000.0,"size":0.12491},{"price":11485000.0,"size":0.01},{"price":11486555.0,"size":0.03},{"price":11487685.0,"size":0.01},{"price":11488000.0,"size":0.102},{"price":11488700.0,"size":0.001},{"price":11489885.0,"size":0.001},{"price":11490841.0,"size":0.002},{"price":11495450.0,"size":0.002},{"price":11495850.0,"size":0.001},{"price":11498700.0,"size":0.001},{"price":11498917.0,"size":0.002},{"price":11499000.0,"size":0.01},{"price":11500000.0,"size":0.46859519},{"price":11501219.0,"size":0.001},{"price":11502377.0,"size":0.002},{"price":11502800.0,"size":0.00132},{"price":11503108.0,"size":0.0198},{"price":11505000.0,"size":0.0028},{"price":11505001.0,"size":0.002},{"price":11505836.0,"size":0.003},{"price":11508431.0,"size":0.047},{"price":11508700.0,"size":0.001},{"price":11508888.0,"size":0.02},{"price":11510000.0,"size":0.0976},{"price":11512553.0,"size":0.001},{"price":11513633.0,"size":0.08},{"price":11514332.0,"size":0.02},{"price":11518700.0,"size":0.001},{"price":11518992.0,"size":0.002},{"price":11519855.0,"size":0.01},{"price":11520000.0,"size":0.001},{"price":11522423.0,"size":0.97},{"price":11523211.0,"size":0.01},{"price":11523887.0,"size":0.001},{"price":11524999.0,"size":0.001},{"price":11528700.0,"size":0.001},{"price":11529852.0,"size":0.01},{"price":11530000.0,"size":0.261},{"price":11533985.0,"size":0.002},{"price":11534084.0,"size":0.001},{"price":11535321.0,"size":0.01},{"price":11538666.0,"size":0.002},{"price":11538700.0,"size":0.001},{"price":11540000.0,"size":0.0048},{"price":11540357.0,"size":0.002},{"price":11541011.0,"size":0.005},{"price":11541109.0,"size":0.01},{"price":11544663.0,"size":0.002},{"price":11545262.0,"size":0.002},{"price":11546541.0,"size":0.01},{"price":11548144.0,"size":0.002},{"price":11548700.0,"size":0.001},{"price":11550000.0,"size":0.014},{"price":11551109.0,"size":0.01},{"price":11551625.0,"size":0.002},{"price":11552111.0,"size":0.01},{"price":11553687.0,"size":0.1},{"price":11555106.0,"size":0.002},{"price":11555115.0,"size":0.001},{"price":11556000.0,"size":0.1},{"price":11558587.0,"size":0.002},{"price":11558700.0,"size":0.001},{"price":11559855.0,"size":0.01},{"price":11560831.0,"size":0.0198},{"price":11561109.0,"size":0.01},{"price":11562000.0,"size":0.087},{"price":11562068.0,"size":0.002},{"price":11565548.0,"size":0.002},{"price":11566139.0,"size":0.0228},{"price":11566551.0,"size":0.01},{"price":11568700.0,"size":0.001},{"price":11569029.0,"size":0.002},{"price":11570196.0,"size":0.002},{"price":11571109.0,"size":0.01},{"price":11572510.0,"size":0.002},{"price":11573211.0,"size":0.01},{"price":11574840.0,"size":0.002},{"price":11575991.0,"size":0.001},{"price":11578700.0,"size":0.001},{"price":11579484.0,"size":0.002},{"price":11579851.0,"size":0.01},{"price":11580000.0,"size":0.7735},{"price":11581109.0,"size":0.01},{"price":11584128.0,"size":0.002},{"price":11585000.0,"size":0.002},{"price":11586532.0,"size":0.01},{"price":11587498.0,"size":0.0198},{"price":11588700.0,"size":0.001},{"price":11589612.0,"size":0.012},{"price":11590000.0,"size":0.1},{"price":11590749.0,"size":0.002},{"price":11591109.0,"size":0.01},{"price":11593211.0,"size":0.01},{"price":11596753.0,"size":0.002},{"price":11598555.0,"size":0.01},{"price":11598700.0,"size":0.001},{"price":11599999.0,"size":0.001},{"price":11600000.0,"size":3.6141},{"price":11601109.0,"size":0.02},{"price":11606655.0,"size":0.01},{"price":11610000.0,"size":0.302},{"price":11611109.0,"size":0.01},{"price":11613321.0,"size":0.01},{"price":11620000.0,"size":1.35441682},{"price":11621011.0,"size":0.01},{"price":11621109.0,"size":0.01},{"price":11623096.0,"size":0.008},{"price":11629000.0,"size":0.1},{"price":11630000.0,"size":0.201},{"price":11630012.0,"size":0.05},{"price":11631059.0,"size":0.01},{"price":11631479.0,"size":0.01},{"price":11631773.0,"size":0.00386871},{"price":11635950.0,"size":0.001},{"price":11638259.0,"size":0.001},{"price":11639700.0,"size":0.001},{"price":11640000.0,"size":1.0},{"price":11640820.0,"size":0.01},{"price":11641651.0,"size":2.0},{"price":11645295.0,"size":0.05},{"price":11647158.0,"size":0.05},{"price":11649900.0,"size":0.02906},{"price":11649999.0,"size":0.001},{"price":11650000.0,"size":0.593},{"price":11651059.0,"size":0.01},{"price":11653658.0,"size":0.008},{"price":11654321.0,"size":0.001},{"price":11659700.0,"size":0.001},{"price":11661479.0,"size":0.01},{"price":11666000.0,"size":0.001},{"price":11666666.0,"size":0.013},{"price":11669700.0,"size":0.001},{"price":11671059.0,"size":0.01},{"price":11672562.0,"size":0.0198},{"price":11679224.0,"size":0.012},{"price":11680000.0,"size":0.004},{"price":11685000.0,"size":0.003},{"price":11688000.0,"size":0.001},{"price":11689732.0,"size":0.01},{"price":11690330.0,"size":0.0198},{"price":11691059.0,"size":0.01},{"price":11692558.0,"size":0.01},{"price":11698800.0,"size":0.00131},{"price":11699000.0,"size":0.001},{"price":11699631.0,"size":0.001},{"price":11699998.0,"size":0.01},{"price":11699999.0,"size":0.001},{"price":11700000.0,"size":1.03762841},{"price":11701059.0,"size":0.01},{"price":11720000.0,"size":0.1},{"price":11721059.0,"size":0.01},{"price":11725000.0,"size":0.005},{"price":11726791.0,"size":0.01},{"price":11730000.0,"size":0.9382},{"price":11740000.0,"size":0.101},{"price":11741059.0,"size":0.01},{"price":11745417.0,"size":2.0},{"price":11748937.0,"size":0.001},{"price":11749999.0,"size":0.001},{"price":11750000.0,"size":0.90537866},{"price":11750050.0,"size":0.2},{"price":11751151.0,"size":0.01},{"price":11755000.0,"size":0.001}]}}}
{"schema_version":"collector.vnext.raw","schema_contract":null,"schema_contract_version":null,"payload_contract_version":null,"record_type":"market.orderbook.diff","record_id":"collector_main-market-orderbook-diff-000000000061","collector_id":"collector_main","collector_role":"production","host_name":"MAIN-PC","session_id":"collector_main-sess-20260314T200800Z-e6cfd48d","stream_session_id":"collector_main-stream-bitflyer-board_ws-20260314T200816Z-602aefa2","exchange":"bitflyer","market":"spot","symbol":"BTC_JPY","instrument_id":"bitflyer.spot.BTC_JPY","channel":"board_ws","transport":"websocket","source_event_id":null,"source_sequence":null,"sequence_id":61,"exchange_ts":null,"collector_ts":"2026-03-14T20:08:16Z","ingest_ts":"2026-03-14T20:08:16Z","event_ts":"2026-03-14T20:08:16Z","quality_flags":[],"is_partial":false,"is_reconstructed":false,"confidence_score":1.0,"payload":{"provider":"bitflyer_ws_board","exchange":"bitflyer","transport":"websocket","channel":"lightning_board_BTC_JPY","received_ts":"2026-03-14T20:08:16.224362Z","subscription_id":null,"message_id":null,"source_sequence":null,"raw_message_meta":{"raw_channel":"lightning_board_BTC_JPY","subscription_channel":"lightning_board_BTC_JPY","recv_timeout_sec":10,"ssl_verify":false,"socket_url":"wss://ws.lightstream.bitflyer.com/json-rpc"},"source_payload":{"mid_price":11306071.0,"bids":[{"price":11298690.0,"size":0.0},{"price":11301681.0,"size":0.0}],"asks":[]}}}
{"schema_version":"collector.vnext.raw","schema_contract":null,"schema_contract_version":null,"payload_contract_version":null,"record_type":"market.orderbook.diff","record_id":"collector_main-market-orderbook-diff-000000000065","collector_id":"collector_main","collector_role":"production","host_name":"MAIN-PC","session_id":"collector_main-sess-20260314T200800Z-e6cfd48d","stream_session_id":"collector_main-stream-bitflyer-board_ws-20260314T200816Z-602aefa2","exchange":"bitflyer","market":"spot","symbol":"BTC_JPY","instrument_id":"bitflyer.spot.BTC_JPY","channel":"board_ws","transport":"websocket","source_event_id":null,"source_sequence":null,"sequence_id":65,"exchange_ts":null,"collector_ts":"2026-03-14T20:08:16Z","ingest_ts":"2026-03-14T20:08:16Z","event_ts":"2026-03-14T20:08:16Z","quality_flags":[],"is_partial":false,"is_reconstructed":false,"confidence_score":1.0,"payload":{"provider":"bitflyer_ws_board","exchange":"bitflyer","transport":"websocket","channel":"lightning_board_BTC_JPY","received_ts":"2026-03-14T20:08:16.344632Z","subscription_id":null,"message_id":null,"source_sequence":null,"raw_message_meta":{"raw_channel":"lightning_board_BTC_JPY","subscription_channel":"lightning_board_BTC_JPY","recv_timeout_sec":10,"ssl_verify":false,"socket_url":"wss://ws.lightstream.bitflyer.com/json-rpc"},"source_payload":{"mid_price":11305745.0,"bids":[{"price":11294183.0,"size":0.0},{"price":11303134.0,"size":0.0},{"price":11303786.0,"size":0.0}],"asks":[{"price":11318115.0,"size":0.0}]}}}
{"schema_version":"collector.vnext.raw","schema_contract":null,"schema_contract_version":null,"payload_contract_version":null,"record_type":"market.orderbook.diff","record_id":"collector_main-market-orderbook-diff-000000000067","collector_id":"collector_main","collector_role":"production","host_name":"MAIN-PC","session_id":"collector_main-sess-20260314T200800Z-e6cfd48d","stream_session_id":"collector_main-stream-bitflyer-board_ws-20260314T200816Z-602aefa2","exchange":"bitflyer","market":"spot","symbol":"BTC_JPY","instrument_id":"bitflyer.spot.BTC_JPY","channel":"board_ws","transport":"websocket","source_event_id":null,"source_sequence":null,"sequence_id":67,"exchange_ts":null,"collector_ts":"2026-03-14T20:08:16Z","ingest_ts":"2026-03-14T20:08:16Z","event_ts":"2026-03-14T20:08:16Z","quality_flags":[],"is_partial":false,"is_reconstructed":false,"confidence_score":1.0,"payload":{"provider":"bitflyer_ws_board","exchange":"bitflyer","transport":"websocket","channel":"lightning_board_BTC_JPY","received_ts":"2026-03-14T20:08:16.453416Z","subscription_id":null,"message_id":null,"source_sequence":null,"raw_message_meta":{"raw_channel":"lightning_board_BTC_JPY","subscription_channel":"lightning_board_BTC_JPY","recv_timeout_sec":10,"ssl_verify":false,"socket_url":"wss://ws.lightstream.bitflyer.com/json-rpc"},"source_payload":{"mid_price":11306072.0,"bids":[{"price":11303787.0,"size":0.04426245},{"price":11301716.0,"size":0.0},{"price":11298691.0,"size":0.02},{"price":11296187.0,"size":0.0}],"asks":[{"price":11309602.0,"size":0.014868},{"price":11318410.0,"size":0.57619101}]}}}
{"schema_version":"collector.vnext.raw","schema_contract":null,"schema_contract_version":null,"payload_contract_version":null,"record_type":"market.orderbook.diff","record_id":"collector_main-market-orderbook-diff-000000000069","collector_id":"collector_main","collector_role":"production","host_name":"MAIN-PC","session_id":"collector_main-sess-20260314T200800Z-e6cfd48d","stream_session_id":"collector_main-stream-bitflyer-board_ws-20260314T200816Z-602aefa2","exchange":"bitflyer","market":"spot","symbol":"BTC_JPY","instrument_id":"bitflyer.spot.BTC_JPY","channel":"board_ws","transport":"websocket","source_event_id":null,"source_sequence":null,"sequence_id":69,"exchange_ts":null,"collector_ts":"2026-03-14T20:08:16Z","ingest_ts":"2026-03-14T20:08:16Z","event_ts":"2026-03-14T20:08:16Z","quality_flags":[],"is_partial":false,"is_reconstructed":false,"confidence_score":1.0,"payload":{"provider":"bitflyer_ws_board","exchange":"bitflyer","transport":"websocket","channel":"lightning_board_BTC_JPY","received_ts":"2026-03-14T20:08:16.578574Z","subscription_id":null,"message_id":null,"source_sequence":null,"raw_message_meta":{"raw_channel":"lightning_board_BTC_JPY","subscription_channel":"lightning_board_BTC_JPY","recv_timeout_sec":10,"ssl_verify":false,"socket_url":"wss://ws.lightstream.bitflyer.com/json-rpc"},"source_payload":{"mid_price":11307332.0,"bids":[{"price":11306308.0,"size":0.00999866},{"price":11298605.0,"size":0.02},{"price":11290731.0,"size":0.06},{"price":11303787.0,"size":0.0},{"price":11289447.0,"size":0.0},{"price":11293572.0,"size":2.97425747}],"asks":[{"price":11310316.0,"size":0.0}]}}}
{"schema_version":"collector.vnext.raw","schema_contract":null,"schema_contract_version":null,"payload_contract_version":null,"record_type":"market.orderbook.diff","record_id":"collector_main-market-orderbook-diff-000000000071","collector_id":"collector_main","collector_role":"production","host_name":"MAIN-PC","session_id":"collector_main-sess-20260314T200800Z-e6cfd48d","stream_session_id":"collector_main-stream-bitflyer-board_ws-20260314T200816Z-602aefa2","exchange":"bitflyer","market":"spot","symbol":"BTC_JPY","instrument_id":"bitflyer.spot.BTC_JPY","channel":"board_ws","transport":"websocket","source_event_id":null,"source_sequence":null,"sequence_id":71,"exchange_ts":null,"collector_ts":"2026-03-14T20:08:16Z","ingest_ts":"2026-03-14T20:08:16Z","event_ts":"2026-03-14T20:08:16Z","quality_flags":[],"is_partial":false,"is_reconstructed":false,"confidence_score":1.0,"payload":{"provider":"bitflyer_ws_board","exchange":"bitflyer","transport":"websocket","channel":"lightning_board_BTC_JPY","received_ts":"2026-03-14T20:08:16.704340Z","subscription_id":null,"message_id":null,"source_sequence":null,"raw_message_meta":{"raw_channel":"lightning_board_BTC_JPY","subscription_channel":"lightning_board_BTC_JPY","recv_timeout_sec":10,"ssl_verify":false,"socket_url":"wss://ws.lightstream.bitflyer.com/json-rpc"},"source_payload":{"mid_price":11307332.0,"bids":[{"price":11297888.0,"size":0.02},{"price":11303134.0,"size":0.0},{"price":11298691.0,"size":0.0},{"price":11298037.0,"size":0.02},{"price":11302496.0,"size":0.014952}],"asks":[]}}}
{"schema_version":"collector.vnext.raw","schema_contract":null,"schema_contract_version":null,"payload_contract_version":null,"record_type":"market.orderbook.diff","record_id":"collector_main-market-orderbook-diff-000000000073","collector_id":"collector_main","collector_role":"production","host_name":"MAIN-PC","session_id":"collector_main-sess-20260314T200800Z-e6cfd48d","stream_session_id":"collector_main-stream-bitflyer-board_ws-20260314T200816Z-602aefa2","exchange":"bitflyer","market":"spot","symbol":"BTC_JPY","instrument_id":"bitflyer.spot.BTC_JPY","channel":"board_ws","transport":"websocket","source_event_id":null,"source_sequence":null,"sequence_id":73,"exchange_ts":null,"collector_ts":"2026-03-14T20:08:16Z","ingest_ts":"2026-03-14T20:08:16Z","event_ts":"2026-03-14T20:08:16Z","quality_flags":[],"is_partial":false,"is_reconstructed":false,"confidence_score":1.0,"payload":{"provider":"bitflyer_ws_board","exchange":"bitflyer","transport":"websocket","channel":"lightning_board_BTC_JPY","received_ts":"2026-03-14T20:08:16.831818Z","subscription_id":null,"message_id":null,"source_sequence":null,"raw_message_meta":{"raw_channel":"lightning_board_BTC_JPY","subscription_channel":"lightning_board_BTC_JPY","recv_timeout_sec":10,"ssl_verify":false,"socket_url":"wss://ws.lightstream.bitflyer.com/json-rpc"},"source_payload":{"mid_price":11307332.0,"bids":[{"price":11303788.0,"size":0.0},{"price":11294507.0,"size":0.00999859},{"price":11303134.0,"size":0.04811664}],"asks":[{"price":11309602.0,"size":0.0},{"price":11318410.0,"size":0.0}]}}}
{"schema_version":"collector.vnext.raw","schema_contract":null,"schema_contract_version":null,"payload_contract_version":null,"record_type":"market.orderbook.diff","record_id":"collector_main-market-orderbook-diff-000000000075","collector_id":"collector_main","collector_role":"production","host_name":"MAIN-PC","session_id":"collector_main-sess-20260314T200800Z-e6cfd48d","stream_session_id":"collector_main-stream-bitflyer-board_ws-20260314T200816Z-602aefa2","exchange":"bitflyer","market":"spot","symbol":"BTC_JPY","instrument_id":"bitflyer.spot.BTC_JPY","channel":"board_ws","transport":"websocket","source_event_id":null,"source_sequence":null,"sequence_id":75,"exchange_ts":null,"collector_ts":"2026-03-14T20:08:16Z","ingest_ts":"2026-03-14T20:08:16Z","event_ts":"2026-03-14T20:08:16Z","quality_flags":[],"is_partial":false,"is_reconstructed":false,"confidence_score":1.0,"payload":{"provider":"bitflyer_ws_board","exchange":"bitflyer","transport":"websocket","channel":"lightning_board_BTC_JPY","received_ts":"2026-03-14T20:08:16.957441Z","subscription_id":null,"message_id":null,"source_sequence":null,"raw_message_meta":{"raw_channel":"lightning_board_BTC_JPY","subscription_channel":"lightning_board_BTC_JPY","recv_timeout_sec":10,"ssl_verify":false,"socket_url":"wss://ws.lightstream.bitflyer.com/json-rpc"},"source_payload":{"mid_price":11307332.0,"bids":[{"price":11298726.0,"size":0.0176993},{"price":11303657.0,"size":0.014964},{"price":11298580.0,"size":0.02},{"price":11301517.0,"size":0.01}],"asks":[{"price":11310315.0,"size":0.0},{"price":11318426.0,"size":0.57619101}]}}}
{"schema_version":"collector.vnext.raw","schema_contract":null,"schema_contract_version":null,"payload_contract_version":null,"record_type":"market.orderbook.diff","record_id":"collector_main-market-orderbook-diff-000000000077","collector_id":"collector_main","collector_role":"production","host_name":"MAIN-PC","session_id":"collector_main-sess-20260314T200800Z-e6cfd48d","stream_session_id":"collector_main-stream-bitflyer-board_ws-20260314T200816Z-602aefa2","exchange":"bitflyer","market":"spot","symbol":"BTC_JPY","instrument_id":"bitflyer.spot.BTC_JPY","channel":"board_ws","transport":"websocket","source_event_id":null,"source_sequence":null,"sequence_id":77,"exchange_ts":null,"collector_ts":"2026-03-14T20:08:17Z","ingest_ts":"2026-03-14T20:08:17Z","event_ts":"2026-03-14T20:08:17Z","quality_flags":[],"is_partial":false,"is_reconstructed":false,"confidence_score":1.0,"payload":{"provider":"bitflyer_ws_board","exchange":"bitflyer","transport":"websocket","channel":"lightning_board_BTC_JPY","received_ts":"2026-03-14T20:08:17.195630Z","subscription_id":null,"message_id":null,"source_sequence":null,"raw_message_meta":{"raw_channel":"lightning_board_BTC_JPY","subscription_channel":"lightning_board_BTC_JPY","recv_timeout_sec":10,"ssl_verify":false,"socket_url":"wss://ws.lightstream.bitflyer.com/json-rpc"},"source_payload":{"mid_price":11307332.0,"bids":[{"price":11297888.0,"size":0.0},{"price":11303134.0,"size":0.0}],"asks":[]}}}
{"schema_version":"collector.vnext.raw","schema_contract":null,"schema_contract_version":null,"payload_contract_version":null,"record_type":"market.orderbook.diff","record_id":"collector_main-market-orderbook-diff-000000000079","collector_id":"collector_main","collector_role":"production","host_name":"MAIN-PC","session_id":"collector_main-sess-20260314T200800Z-e6cfd48d","stream_session_id":"collector_main-stream-bitflyer-board_ws-20260314T200816Z-602aefa2","exchange":"bitflyer","market":"spot","symbol":"BTC_JPY","instrument_id":"bitflyer.spot.BTC_JPY","channel":"board_ws","transport":"websocket","source_event_id":null,"source_sequence":null,"sequence_id":79,"exchange_ts":null,"collector_ts":"2026-03-14T20:08:17Z","ingest_ts":"2026-03-14T20:08:17Z","event_ts":"2026-03-14T20:08:17Z","quality_flags":[],"is_partial":false,"is_reconstructed":false,"confidence_score":1.0,"payload":{"provider":"bitflyer_ws_board","exchange":"bitflyer","transport":"websocket","channel":"lightning_board_BTC_JPY","received_ts":"2026-03-14T20:08:17.296967Z","subscription_id":null,"message_id":null,"source_sequence":null,"raw_message_meta":{"raw_channel":"lightning_board_BTC_JPY","subscription_channel":"lightning_board_BTC_JPY","recv_timeout_sec":10,"ssl_verify":false,"socket_url":"wss://ws.lightstream.bitflyer.com/json-rpc"},"source_payload":{"mid_price":11307332.0,"bids":[{"price":11303658.0,"size":0.04257465}],"asks":[]}}}
{"schema_version":"collector.vnext.raw","schema_contract":null,"schema_contract_version":null,"payload_contract_version":null,"record_type":"market.orderbook.diff","record_id":"collector_main-market-orderbook-diff-000000000081","collector_id":"collector_main","collector_role":"production","host_name":"MAIN-PC","session_id":"collector_main-sess-20260314T200800Z-e6cfd48d","stream_session_id":"collector_main-stream-bitflyer-board_ws-20260314T200816Z-602aefa2","exchange":"bitflyer","market":"spot","symbol":"BTC_JPY","instrument_id":"bitflyer.spot.BTC_JPY","channel":"board_ws","transport":"websocket","source_event_id":null,"source_sequence":null,"sequence_id":81,"exchange_ts":null,"collector_ts":"2026-03-14T20:08:17Z","ingest_ts":"2026-03-14T20:08:17Z","event_ts":"2026-03-14T20:08:17Z","quality_flags":[],"is_partial":false,"is_reconstructed":false,"confidence_score":1.0,"payload":{"provider":"bitflyer_ws_board","exchange":"bitflyer","transport":"websocket","channel":"lightning_board_BTC_JPY","received_ts":"2026-03-14T20:08:17.469484Z","subscription_id":null,"message_id":null,"source_sequence":null,"raw_message_meta":{"raw_channel":"lightning_board_BTC_JPY","subscription_channel":"lightning_board_BTC_JPY","recv_timeout_sec":10,"ssl_verify":false,"socket_url":"wss://ws.lightstream.bitflyer.com/json-rpc"},"source_payload":{"mid_price":11307332.0,"bids":[{"price":11298852.0,"size":0.1275}],"asks":[{"price":11310160.0,"size":0.1251}]}}}
{"schema_version":"collector.vnext.raw","schema_contract":null,"schema_contract_version":null,"payload_contract_version":null,"record_type":"market.orderbook.diff","record_id":"collector_main-market-orderbook-diff-000000000083","collector_id":"collector_main","collector_role":"production","host_name":"MAIN-PC","session_id":"collector_main-sess-20260314T200800Z-e6cfd48d","stream_session_id":"collector_main-stream-bitflyer-board_ws-20260314T200816Z-602aefa2","exchange":"bitflyer","market":"spot","symbol":"BTC_JPY","instrument_id":"bitflyer.spot.BTC_JPY","channel":"board_ws","transport":"websocket","source_event_id":null,"source_sequence":null,"sequence_id":83,"exchange_ts":null,"collector_ts":"2026-03-14T20:08:17Z","ingest_ts":"2026-03-14T20:08:17Z","event_ts":"2026-03-14T20:08:17Z","quality_flags":[],"is_partial":false,"is_reconstructed":false,"confidence_score":1.0,"payload":{"provider":"bitflyer_ws_board","exchange":"bitflyer","transport":"websocket","channel":"lightning_board_BTC_JPY","received_ts":"2026-03-14T20:08:17.590539Z","subscription_id":null,"message_id":null,"source_sequence":null,"raw_message_meta":{"raw_channel":"lightning_board_BTC_JPY","subscription_channel":"lightning_board_BTC_JPY","recv_timeout_sec":10,"ssl_verify":false,"socket_url":"wss://ws.lightstream.bitflyer.com/json-rpc"},"source_payload":{"mid_price":11307332.0,"bids":[{"price":11290731.0,"size":0.0},{"price":11298726.0,"size":0.0}],"asks":[]}}}
{"schema_version":"collector.vnext.raw","schema_contract":null,"schema_contract_version":null,"payload_contract_version":null,"record_type":"market.orderbook.diff","record_id":"collector_main-market-orderbook-diff-000000000085","collector_id":"collector_main","collector_role":"production","host_name":"MAIN-PC","session_id":"collector_main-sess-20260314T200800Z-e6cfd48d","stream_session_id":"collector_main-stream-bitflyer-board_ws-20260314T200816Z-602aefa2","exchange":"bitflyer","market":"spot","symbol":"BTC_JPY","instrument_id":"bitflyer.spot.BTC_JPY","channel":"board_ws","transport":"websocket","source_event_id":null,"source_sequence":null,"sequence_id":85,"exchange_ts":null,"collector_ts":"2026-03-14T20:08:17Z","ingest_ts":"2026-03-14T20:08:17Z","event_ts":"2026-03-14T20:08:17Z","quality_flags":[],"is_partial":false,"is_reconstructed":false,"confidence_score":1.0,"payload":{"provider":"bitflyer_ws_board","exchange":"bitflyer","transport":"websocket","channel":"lightning_board_BTC_JPY","received_ts":"2026-03-14T20:08:17.688993Z","subscription_id":null,"message_id":null,"source_sequence":null,"raw_message_meta":{"raw_channel":"lightning_board_BTC_JPY","subscription_channel":"lightning_board_BTC_JPY","recv_timeout_sec":10,"ssl_verify":false,"socket_url":"wss://ws.lightstream.bitflyer.com/json-rpc"},"source_payload":{"mid_price":11307332.0,"bids":[],"asks":[{"price":11323555.0,"size":0.0}]}}}
{"schema_version":"collector.vnext.raw","schema_contract":null,"schema_contract_version":null,"payload_contract_version":null,"record_type":"market.orderbook.diff","record_id":"collector_main-market-orderbook-diff-000000000087","collector_id":"collector_main","collector_role":"production","host_name":"MAIN-PC","session_id":"collector_main-sess-20260314T200800Z-e6cfd48d","stream_session_id":"collector_main-stream-bitflyer-board_ws-20260314T200816Z-602aefa2","exchange":"bitflyer","market":"spot","symbol":"BTC_JPY","instrument_id":"bitflyer.spot.BTC_JPY","channel":"board_ws","transport":"websocket","source_event_id":null,"source_sequence":null,"sequence_id":87,"exchange_ts":null,"collector_ts":"2026-03-14T20:08:17Z","ingest_ts":"2026-03-14T20:08:17Z","event_ts":"2026-03-14T20:08:17Z","quality_flags":[],"is_partial":false,"is_reconstructed":false,"confidence_score":1.0,"payload":{"provider":"bitflyer_ws_board","exchange":"bitflyer","transport":"websocket","channel":"lightning_board_BTC_JPY","received_ts":"2026-03-14T20:08:17.797678Z","subscription_id":null,"message_id":null,"source_sequence":null,"raw_message_meta":{"raw_channel":"lightning_board_BTC_JPY","subscription_channel":"lightning_board_BTC_JPY","recv_timeout_sec":10,"ssl_verify":false,"socket_url":"wss://ws.lightstream.bitflyer.com/json-rpc"},"source_payload":{"mid_price":11307332.0,"bids":[{"price":11298037.0,"size":0.0},{"price":11299417.0,"size":0.1275}],"asks":[]}}}
{"schema_version":"collector.vnext.raw","schema_contract":null,"schema_contract_version":null,"payload_contract_version":null,"record_type":"market.orderbook.diff","record_id":"collector_main-market-orderbook-diff-000000000089","collector_id":"collector_main","collector_role":"production","host_name":"MAIN-PC","session_id":"collector_main-sess-20260314T200800Z-e6cfd48d","stream_session_id":"collector_main-stream-bitflyer-board_ws-20260314T200816Z-602aefa2","exchange":"bitflyer","market":"spot","symbol":"BTC_JPY","instrument_id":"bitflyer.spot.BTC_JPY","channel":"board_ws","transport":"websocket","source_event_id":null,"source_sequence":null,"sequence_id":89,"exchange_ts":null,"collector_ts":"2026-03-14T20:08:18Z","ingest_ts":"2026-03-14T20:08:18Z","event_ts":"2026-03-14T20:08:18Z","quality_flags":[],"is_partial":false,"is_reconstructed":false,"confidence_score":1.0,"payload":{"provider":"bitflyer_ws_board","exchange":"bitflyer","transport":"websocket","channel":"lightning_board_BTC_JPY","received_ts":"2026-03-14T20:08:18.004389Z","subscription_id":null,"message_id":null,"source_sequence":null,"raw_message_meta":{"raw_channel":"lightning_board_BTC_JPY","subscription_channel":"lightning_board_BTC_JPY","recv_timeout_sec":10,"ssl_verify":false,"socket_url":"wss://ws.lightstream.bitflyer.com/json-rpc"},"source_payload":{"mid_price":11307332.0,"bids":[{"price":11298852.0,"size":0.0}],"asks":[]}}}
{"schema_version":"collector.vnext.raw","schema_contract":null,"schema_contract_version":null,"payload_contract_version":null,"record_type":"market.orderbook.diff","record_id":"collector_main-market-orderbook-diff-000000000091","collector_id":"collector_main","collector_role":"production","host_name":"MAIN-PC","session_id":"collector_main-sess-20260314T200800Z-e6cfd48d","stream_session_id":"collector_main-stream-bitflyer-board_ws-20260314T200816Z-602aefa2","exchange":"bitflyer","market":"spot","symbol":"BTC_JPY","instrument_id":"bitflyer.spot.BTC_JPY","channel":"board_ws","transport":"websocket","source_event_id":null,"source_sequence":null,"sequence_id":91,"exchange_ts":null,"collector_ts":"2026-03-14T20:08:18Z","ingest_ts":"2026-03-14T20:08:18Z","event_ts":"2026-03-14T20:08:18Z","quality_flags":[],"is_partial":false,"is_reconstructed":false,"confidence_score":1.0,"payload":{"provider":"bitflyer_ws_board","exchange":"bitflyer","transport":"websocket","channel":"lightning_board_BTC_JPY","received_ts":"2026-03-14T20:08:18.320393Z","subscription_id":null,"message_id":null,"source_sequence":null,"raw_message_meta":{"raw_channel":"lightning_board_BTC_JPY","subscription_channel":"lightning_board_BTC_JPY","recv_timeout_sec":10,"ssl_verify":false,"socket_url":"wss://ws.lightstream.bitflyer.com/json-rpc"},"source_payload":{"mid_price":11307332.0,"bids":[{"price":11299452.0,"size":0.0176982},{"price":11299982.0,"size":0.1275}],"asks":[]}}}
{"schema_version":"collector.vnext.raw","schema_contract":null,"schema_contract_version":null,"payload_contract_version":null,"record_type":"market.orderbook.diff","record_id":"collector_main-market-orderbook-diff-000000000093","collector_id":"collector_main","collector_role":"production","host_name":"MAIN-PC","session_id":"collector_main-sess-20260314T200800Z-e6cfd48d","stream_session_id":"collector_main-stream-bitflyer-board_ws-20260314T200816Z-602aefa2","exchange":"bitflyer","market":"spot","symbol":"BTC_JPY","instrument_id":"bitflyer.spot.BTC_JPY","channel":"board_ws","transport":"websocket","source_event_id":null,"source_sequence":null,"sequence_id":93,"exchange_ts":null,"collector_ts":"2026-03-14T20:08:18Z","ingest_ts":"2026-03-14T20:08:18Z","event_ts":"2026-03-14T20:08:18Z","quality_flags":[],"is_partial":false,"is_reconstructed":false,"confidence_score":1.0,"payload":{"provider":"bitflyer_ws_board","exchange":"bitflyer","transport":"websocket","channel":"lightning_board_BTC_JPY","received_ts":"2026-03-14T20:08:18.470058Z","subscription_id":null,"message_id":null,"source_sequence":null,"raw_message_meta":{"raw_channel":"lightning_board_BTC_JPY","subscription_channel":"lightning_board_BTC_JPY","recv_timeout_sec":10,"ssl_verify":false,"socket_url":"wss://ws.lightstream.bitflyer.com/json-rpc"},"source_payload":{"mid_price":11307332.0,"bids":[{"price":11299417.0,"size":0.0}],"asks":[]}}}
{"schema_version":"collector.vnext.raw","schema_contract":null,"schema_contract_version":null,"payload_contract_version":null,"record_type":"market.orderbook.diff","record_id":"collector_main-market-orderbook-diff-000000000095","collector_id":"collector_main","collector_role":"production","host_name":"MAIN-PC","session_id":"collector_main-sess-20260314T200800Z-e6cfd48d","stream_session_id":"collector_main-stream-bitflyer-board_ws-20260314T200816Z-602aefa2","exchange":"bitflyer","market":"spot","symbol":"BTC_JPY","instrument_id":"bitflyer.spot.BTC_JPY","channel":"board_ws","transport":"websocket","source_event_id":null,"source_sequence":null,"sequence_id":95,"exchange_ts":null,"collector_ts":"2026-03-14T20:08:18Z","ingest_ts":"2026-03-14T20:08:18Z","event_ts":"2026-03-14T20:08:18Z","quality_flags":[],"is_partial":false,"is_reconstructed":false,"confidence_score":1.0,"payload":{"provider":"bitflyer_ws_board","exchange":"bitflyer","transport":"websocket","channel":"lightning_board_BTC_JPY","received_ts":"2026-03-14T20:08:18.768302Z","subscription_id":null,"message_id":null,"source_sequence":null,"raw_message_meta":{"raw_channel":"lightning_board_BTC_JPY","subscription_channel":"lightning_board_BTC_JPY","recv_timeout_sec":10,"ssl_verify":false,"socket_url":"wss://ws.lightstream.bitflyer.com/json-rpc"},"source_payload":{"mid_price":11307332.0,"bids":[{"price":11300548.0,"size":0.1275}],"asks":[]}}}
{"schema_version":"collector.vnext.raw","schema_contract":null,"schema_contract_version":null,"payload_contract_version":null,"record_type":"market.orderbook.diff","record_id":"collector_main-market-orderbook-diff-000000000097","collector_id":"collector_main","collector_role":"production","host_name":"MAIN-PC","session_id":"collector_main-sess-20260314T200800Z-e6cfd48d","stream_session_id":"collector_main-stream-bitflyer-board_ws-20260314T200816Z-602aefa2","exchange":"bitflyer","market":"spot","symbol":"BTC_JPY","instrument_id":"bitflyer.spot.BTC_JPY","channel":"board_ws","transport":"websocket","source_event_id":null,"source_sequence":null,"sequence_id":97,"exchange_ts":null,"collector_ts":"2026-03-14T20:08:19Z","ingest_ts":"2026-03-14T20:08:19Z","event_ts":"2026-03-14T20:08:19Z","quality_flags":[],"is_partial":false,"is_reconstructed":false,"confidence_score":1.0,"payload":{"provider":"bitflyer_ws_board","exchange":"bitflyer","transport":"websocket","channel":"lightning_board_BTC_JPY","received_ts":"2026-03-14T20:08:19.026993Z","subscription_id":null,"message_id":null,"source_sequence":null,"raw_message_meta":{"raw_channel":"lightning_board_BTC_JPY","subscription_channel":"lightning_board_BTC_JPY","recv_timeout_sec":10,"ssl_verify":false,"socket_url":"wss://ws.lightstream.bitflyer.com/json-rpc"},"source_payload":{"mid_price":11307332.0,"bids":[{"price":11299452.0,"size":0.0},{"price":11299982.0,"size":0.0},{"price":11273619.0,"size":0.0},{"price":11270229.0,"size":0.0},{"price":11266839.0,"size":0.0},{"price":11263449.0,"size":0.0},{"price":11260059.0,"size":0.0},{"price":11256669.0,"size":0.0},{"price":11253279.0,"size":0.0},{"price":11249889.0,"size":0.0},{"price":11246499.0,"size":0.0},{"price":11243109.0,"size":0.0}],"asks":[{"price":11424296.0,"size":0.0},{"price":11426426.0,"size":0.0},{"price":11443629.0,"size":0.0},{"price":11447071.0,"size":0.0},{"price":11478431.0,"size":0.0}]}}}
{"schema_version":"collector.vnext.raw","schema_contract":null,"schema_contract_version":null,"payload_contract_version":null,"record_type":"market.orderbook.diff","record_id":"collector_main-market-orderbook-diff-000000000099","collector_id":"collector_main","collector_role":"production","host_name":"MAIN-PC","session_id":"collector_main-sess-20260314T200800Z-e6cfd48d","stream_session_id":"collector_main-stream-bitflyer-board_ws-20260314T200816Z-602aefa2","exchange":"bitflyer","market":"spot","symbol":"BTC_JPY","instrument_id":"bitflyer.spot.BTC_JPY","channel":"board_ws","transport":"websocket","source_event_id":null,"source_sequence":null,"sequence_id":99,"exchange_ts":null,"collector_ts":"2026-03-14T20:08:19Z","ingest_ts":"2026-03-14T20:08:19Z","event_ts":"2026-03-14T20:08:19Z","quality_flags":[],"is_partial":false,"is_reconstructed":false,"confidence_score":1.0,"payload":{"provider":"bitflyer_ws_board","exchange":"bitflyer","transport":"websocket","channel":"lightning_board_BTC_JPY","received_ts":"2026-03-14T20:08:19.121776Z","subscription_id":null,"message_id":null,"source_sequence":null,"raw_message_meta":{"raw_channel":"lightning_board_BTC_JPY","subscription_channel":"lightning_board_BTC_JPY","recv_timeout_sec":10,"ssl_verify":false,"socket_url":"wss://ws.lightstream.bitflyer.com/json-rpc"},"source_payload":{"mid_price":11307332.0,"bids":[{"price":11287379.0,"size":0.29298039}],"asks":[{"price":11498917.0,"size":0.0},{"price":11502377.0,"size":0.0},{"price":11505836.0,"size":0.001},{"price":11533985.0,"size":0.0},{"price":11538666.0,"size":0.0},{"price":11544663.0,"size":0.0},{"price":11548144.0,"size":0.0},{"price":11551625.0,"size":0.0},{"price":11555106.0,"size":0.0},{"price":11558587.0,"size":0.0},{"price":11562068.0,"size":0.0},{"price":11565548.0,"size":0.0},{"price":11569029.0,"size":0.0},{"price":11572510.0,"size":0.0},{"price":11575991.0,"size":0.0}]}}}
{"schema_version":"collector.vnext.raw","schema_contract":null,"schema_contract_version":null,"payload_contract_version":null,"record_type":"market.orderbook.diff","record_id":"collector_main-market-orderbook-diff-000000000101","collector_id":"collector_main","collector_role":"production","host_name":"MAIN-PC","session_id":"collector_main-sess-20260314T200800Z-e6cfd48d","stream_session_id":"collector_main-stream-bitflyer-board_ws-20260314T200816Z-602aefa2","exchange":"bitflyer","market":"spot","symbol":"BTC_JPY","instrument_id":"bitflyer.spot.BTC_JPY","channel":"board_ws","transport":"websocket","source_event_id":null,"source_sequence":null,"sequence_id":101,"exchange_ts":null,"collector_ts":"2026-03-14T20:08:19Z","ingest_ts":"2026-03-14T20:08:19Z","event_ts":"2026-03-14T20:08:19Z","quality_flags":[],"is_partial":false,"is_reconstructed":false,"confidence_score":1.0,"payload":{"provider":"bitflyer_ws_board","exchange":"bitflyer","transport":"websocket","channel":"lightning_board_BTC_JPY","received_ts":"2026-03-14T20:08:19.246903Z","subscription_id":null,"message_id":null,"source_sequence":null,"raw_message_meta":{"raw_channel":"lightning_board_BTC_JPY","subscription_channel":"lightning_board_BTC_JPY","recv_timeout_sec":10,"ssl_verify":false,"socket_url":"wss://ws.lightstream.bitflyer.com/json-rpc"},"source_payload":{"mid_price":11307332.0,"bids":[{"price":11300548.0,"size":0.0},{"price":11298852.0,"size":0.1275}],"asks":[]}}}
{"schema_version":"collector.vnext.raw","schema_contract":null,"schema_contract_version":null,"payload_contract_version":null,"record_type":"market.orderbook.diff","record_id":"collector_main-market-orderbook-diff-000000000103","collector_id":"collector_main","collector_role":"production","host_name":"MAIN-PC","session_id":"collector_main-sess-20260314T200800Z-e6cfd48d","stream_session_id":"collector_main-stream-bitflyer-board_ws-20260314T200816Z-602aefa2","exchange":"bitflyer","market":"spot","symbol":"BTC_JPY","instrument_id":"bitflyer.spot.BTC_JPY","channel":"board_ws","transport":"websocket","source_event_id":null,"source_sequence":null,"sequence_id":103,"exchange_ts":null,"collector_ts":"2026-03-14T20:08:19Z","ingest_ts":"2026-03-14T20:08:19Z","event_ts":"2026-03-14T20:08:19Z","quality_flags":[],"is_partial":false,"is_reconstructed":false,"confidence_score":1.0,"payload":{"provider":"bitflyer_ws_board","exchange":"bitflyer","transport":"websocket","channel":"lightning_board_BTC_JPY","received_ts":"2026-03-14T20:08:19.368341Z","subscription_id":null,"message_id":null,"source_sequence":null,"raw_message_meta":{"raw_channel":"lightning_board_BTC_JPY","subscription_channel":"lightning_board_BTC_JPY","recv_timeout_sec":10,"ssl_verify":false,"socket_url":"wss://ws.lightstream.bitflyer.com/json-rpc"},"source_payload":{"mid_price":11307332.0,"bids":[{"price":11300583.0,"size":0.0176964}],"asks":[{"price":11312986.0,"size":0.01}]}}}
{"schema_version":"collector.vnext.raw","schema_contract":null,"schema_contract_version":null,"payload_contract_version":null,"record_type":"market.orderbook.diff","record_id":"collector_main-market-orderbook-diff-000000000105","collector_id":"collector_main","collector_role":"production","host_name":"MAIN-PC","session_id":"collector_main-sess-20260314T200800Z-e6cfd48d","stream_session_id":"collector_main-stream-bitflyer-board_ws-20260314T200816Z-602aefa2","exchange":"bitflyer","market":"spot","symbol":"BTC_JPY","instrument_id":"bitflyer.spot.BTC_JPY","channel":"board_ws","transport":"websocket","source_event_id":null,"source_sequence":null,"sequence_id":105,"exchange_ts":null,"collector_ts":"2026-03-14T20:08:19Z","ingest_ts":"2026-03-14T20:08:19Z","event_ts":"2026-03-14T20:08:19Z","quality_flags":[],"is_partial":false,"is_reconstructed":false,"confidence_score":1.0,"payload":{"provider":"bitflyer_ws_board","exchange":"bitflyer","transport":"websocket","channel":"lightning_board_BTC_JPY","received_ts":"2026-03-14T20:08:19.509421Z","subscription_id":null,"message_id":null,"source_sequence":null,"raw_message_meta":{"raw_channel":"lightning_board_BTC_JPY","subscription_channel":"lightning_board_BTC_JPY","recv_timeout_sec":10,"ssl_verify":false,"socket_url":"wss://ws.lightstream.bitflyer.com/json-rpc"},"source_payload":{"mid_price":11307332.0,"bids":[{"price":11299417.0,"size":0.1275},{"price":11294507.0,"size":0.0}],"asks":[]}}}
{"schema_version":"collector.vnext.raw","schema_contract":null,"schema_contract_version":null,"payload_contract_version":null,"record_type":"market.orderbook.diff","record_id":"collector_main-market-orderbook-diff-000000000107","collector_id":"collector_main","collector_role":"production","host_name":"MAIN-PC","session_id":"collector_main-sess-20260314T200800Z-e6cfd48d","stream_session_id":"collector_main-stream-bitflyer-board_ws-20260314T200816Z-602aefa2","exchange":"bitflyer","market":"spot","symbol":"BTC_JPY","instrument_id":"bitflyer.spot.BTC_JPY","channel":"board_ws","transport":"websocket","source_event_id":null,"source_sequence":null,"sequence_id":107,"exchange_ts":null,"collector_ts":"2026-03-14T20:08:19Z","ingest_ts":"2026-03-14T20:08:19Z","event_ts":"2026-03-14T20:08:19Z","quality_flags":[],"is_partial":false,"is_reconstructed":false,"confidence_score":1.0,"payload":{"provider":"bitflyer_ws_board","exchange":"bitflyer","transport":"websocket","channel":"lightning_board_BTC_JPY","received_ts":"2026-03-14T20:08:19.646701Z","subscription_id":null,"message_id":null,"source_sequence":null,"raw_message_meta":{"raw_channel":"lightning_board_BTC_JPY","subscription_channel":"lightning_board_BTC_JPY","recv_timeout_sec":10,"ssl_verify":false,"socket_url":"wss://ws.lightstream.bitflyer.com/json-rpc"},"source_payload":{"mid_price":11307332.0,"bids":[{"price":11288470.0,"size":0.132}],"asks":[{"price":11318640.0,"size":0.01}]}}}
{"schema_version":"collector.vnext.raw","schema_contract":null,"schema_contract_version":null,"payload_contract_version":null,"record_type":"market.orderbook.diff","record_id":"collector_main-market-orderbook-diff-000000000109","collector_id":"collector_main","collector_role":"production","host_name":"MAIN-PC","session_id":"collector_main-sess-20260314T200800Z-e6cfd48d","stream_session_id":"collector_main-stream-bitflyer-board_ws-20260314T200816Z-602aefa2","exchange":"bitflyer","market":"spot","symbol":"BTC_JPY","instrument_id":"bitflyer.spot.BTC_JPY","channel":"board_ws","transport":"websocket","source_event_id":null,"source_sequence":null,"sequence_id":109,"exchange_ts":null,"collector_ts":"2026-03-14T20:08:19Z","ingest_ts":"2026-03-14T20:08:19Z","event_ts":"2026-03-14T20:08:19Z","quality_flags":[],"is_partial":false,"is_reconstructed":false,"confidence_score":1.0,"payload":{"provider":"bitflyer_ws_board","exchange":"bitflyer","transport":"websocket","channel":"lightning_board_BTC_JPY","received_ts":"2026-03-14T20:08:19.866411Z","subscription_id":null,"message_id":null,"source_sequence":null,"raw_message_meta":{"raw_channel":"lightning_board_BTC_JPY","subscription_channel":"lightning_board_BTC_JPY","recv_timeout_sec":10,"ssl_verify":false,"socket_url":"wss://ws.lightstream.bitflyer.com/json-rpc"},"source_payload":{"mid_price":11307332.0,"bids":[{"price":11296155.0,"size":0.00999859}],"asks":[]}}}
{"schema_version":"collector.vnext.raw","schema_contract":null,"schema_contract_version":null,"payload_contract_version":null,"record_type":"market.orderbook.diff","record_id":"collector_main-market-orderbook-diff-000000000111","collector_id":"collector_main","collector_role":"production","host_name":"MAIN-PC","session_id":"collector_main-sess-20260314T200800Z-e6cfd48d","stream_session_id":"collector_main-stream-bitflyer-board_ws-20260314T200816Z-602aefa2","exchange":"bitflyer","market":"spot","symbol":"BTC_JPY","instrument_id":"bitflyer.spot.BTC_JPY","channel":"board_ws","transport":"websocket","source_event_id":null,"source_sequence":null,"sequence_id":111,"exchange_ts":null,"collector_ts":"2026-03-14T20:08:19Z","ingest_ts":"2026-03-14T20:08:19Z","event_ts":"2026-03-14T20:08:19Z","quality_flags":[],"is_partial":false,"is_reconstructed":false,"confidence_score":1.0,"payload":{"provider":"bitflyer_ws_board","exchange":"bitflyer","transport":"websocket","channel":"lightning_board_BTC_JPY","received_ts":"2026-03-14T20:08:19.972239Z","subscription_id":null,"message_id":null,"source_sequence":null,"raw_message_meta":{"raw_channel":"lightning_board_BTC_JPY","subscription_channel":"lightning_board_BTC_JPY","recv_timeout_sec":10,"ssl_verify":false,"socket_url":"wss://ws.lightstream.bitflyer.com/json-rpc"},"source_payload":{"mid_price":11307332.0,"bids":[{"price":11299982.0,"size":0.1275}],"asks":[]}}}
{"schema_version":"collector.vnext.raw","schema_contract":null,"schema_contract_version":null,"payload_contract_version":null,"record_type":"market.orderbook.diff","record_id":"collector_main-market-orderbook-diff-000000000113","collector_id":"collector_main","collector_role":"production","host_name":"MAIN-PC","session_id":"collector_main-sess-20260314T200800Z-e6cfd48d","stream_session_id":"collector_main-stream-bitflyer-board_ws-20260314T200816Z-602aefa2","exchange":"bitflyer","market":"spot","symbol":"BTC_JPY","instrument_id":"bitflyer.spot.BTC_JPY","channel":"board_ws","transport":"websocket","source_event_id":null,"source_sequence":null,"sequence_id":113,"exchange_ts":null,"collector_ts":"2026-03-14T20:08:20Z","ingest_ts":"2026-03-14T20:08:20Z","event_ts":"2026-03-14T20:08:20Z","quality_flags":[],"is_partial":false,"is_reconstructed":false,"confidence_score":1.0,"payload":{"provider":"bitflyer_ws_board","exchange":"bitflyer","transport":"websocket","channel":"lightning_board_BTC_JPY","received_ts":"2026-03-14T20:08:20.139118Z","subscription_id":null,"message_id":null,"source_sequence":null,"raw_message_meta":{"raw_channel":"lightning_board_BTC_JPY","subscription_channel":"lightning_board_BTC_JPY","recv_timeout_sec":10,"ssl_verify":false,"socket_url":"wss://ws.lightstream.bitflyer.com/json-rpc"},"source_payload":{"mid_price":11307332.0,"bids":[{"price":11300583.0,"size":0.0},{"price":11299417.0,"size":0.0},{"price":11298580.0,"size":0.0}],"asks":[]}}}
{"schema_version":"collector.vnext.raw","schema_contract":null,"schema_contract_version":null,"payload_contract_version":null,"record_type":"market.orderbook.snapshot","record_id":"collector_main-market-orderbook-snapshot-000000000115","collector_id":"collector_main","collector_role":"production","host_name":"MAIN-PC","session_id":"collector_main-sess-20260314T200800Z-e6cfd48d","stream_session_id":"collector_main-stream-bitflyer-board_ws-20260314T200816Z-602aefa2","exchange":"bitflyer","market":"spot","symbol":"BTC_JPY","instrument_id":"bitflyer.spot.BTC_JPY","channel":"board_ws","transport":"websocket","source_event_id":null,"source_sequence":null,"sequence_id":115,"exchange_ts":null,"collector_ts":"2026-03-14T20:08:20Z","ingest_ts":"2026-03-14T20:08:20Z","event_ts":"2026-03-14T20:08:20Z","quality_flags":[],"is_partial":false,"is_reconstructed":false,"confidence_score":1.0,"payload":{"provider":"bitflyer_ws_board_snapshot","exchange":"bitflyer","transport":"websocket","channel":"lightning_board_snapshot_BTC_JPY","received_ts":"2026-03-14T20:08:20.601415Z","subscription_id":null,"message_id":null,"source_sequence":null,"raw_message_meta":{"raw_channel":"lightning_board_snapshot_BTC_JPY","subscription_channel":"lightning_board_snapshot_BTC_JPY","recv_timeout_sec":10,"ssl_verify":false,"socket_url":"wss://ws.lightstream.bitflyer.com/json-rpc"},"source_payload":{"mid_price":11307332.0,"bids":[{"price":11306308.0,"size":0.00999866},{"price":11303658.0,"size":0.04257465},{"price":11303657.0,"size":0.014964},{"price":11303133.0,"size":0.005},{"price":11302496.0,"size":0.014952},{"price":11302172.0,"size":0.01494},{"price":11301853.0,"size":0.015216},{"price":11301517.0,"size":0.01},{"price":11300548.0,"size":0.1275},{"price":11299982.0,"size":0.1275},{"price":11298605.0,"size":0.02},{"price":11298604.0,"size":0.2},{"price":11298579.0,"size":0.05},{"price":11298513.0,"size":0.05},{"price":11297887.0,"size":0.0531},{"price":11297439.0,"size":0.5},{"price":11296579.0,"size":0.0546048},{"price":11296155.0,"size":0.00999859},{"price":11293572.0,"size":2.97425747},{"price":11293571.0,"size":0.5},{"price":11293270.0,"size":0.0801},{"price":11292664.0,"size":0.001},{"price":11289443.0,"size":0.04},{"price":11288470.0,"size":0.132},{"price":11287379.0,"size":0.29298039},{"price":11287378.0,"size":1.50015},{"price":11286651.0,"size":0.98403398},{"price":11282795.0,"size":0.2658},{"price":11280205.0,"size":0.001},{"price":11280033.0,"size":0.2616},{"price":11279282.0,"size":0.0015},{"price":11277748.0,"size":0.0966561},{"price":11277602.0,"size":0.005},{"price":11277271.0,"size":0.2642},{"price":11277083.0,"size":0.6},{"price":11276220.0,"size":0.002},{"price":11275360.0,"size":1.484},{"price":11275103.0,"size":0.17894886},{"price":11275102.0,"size":0.01},{"price":11275000.0,"size":0.001},{"price":11274588.0,"size":0.0047},{"price":11274509.0,"size":0.2679},{"price":11271699.0,"size":0.002},{"price":11271000.0,"size":0.003},{"price":11270000.0,"size":0.106},{"price":11268871.0,"size":0.281},{"price":11268411.0,"size":0.01},{"price":11267178.0,"size":0.002},{"price":11266666.0,"size":0.04},{"price":11265000.0,"size":0.02},{"price":11263999.0,"size":1.966},{"price":11263000.0,"size":0.006},{"price":11262657.0,"size":0.002},{"price":11262564.0,"size":0.0015},{"price":11260000.0,"size":0.3565},{"price":11258136.0,"size":0.002},{"price":11257537.0,"size":0.001},{"price":11257000.0,"size":0.001},{"price":11255200.0,"size":0.001},{"price":11255115.0,"size":0.00377},{"price":11253615.0,"size":0.002},{"price":11253000.0,"size":0.03189},{"price":11251000.0,"size":0.0131},{"price":11250250.0,"size":0.00105},{"price":11250200.0,"size":0.001},{"price":11250100.0,"size":0.015},{"price":11250005.0,"size":0.001},{"price":11250001.0,"size":0.00104},{"price":11250000.0,"size":0.76834},{"price":11249094.0,"size":0.002},{"price":11246544.0,"size":0.0015},{"price":11246203.0,"size":0.001},{"price":11245141.0,"size":0.0031},{"price":11245000.0,"size":0.05},{"price":11244573.0,"size":0.002},{"price":11244444.0,"size":0.04},{"price":11244243.0,"size":0.01},{"price":11240200.0,"size":0.001},{"price":11240052.0,"size":0.002},{"price":11240000.0,"size":0.007304},{"price":11236190.0,"size":0.01},{"price":11235531.0,"size":0.002},{"price":11235200.0,"size":0.001},{"price":11234869.0,"size":0.001},{"price":11233345.0,"size":2.036},{"price":11232000.0,"size":0.089},{"price":11231243.0,"size":0.01},{"price":11231000.0,"size":0.105},{"price":11230200.0,"size":0.001},{"price":11230000.0,"size":0.0308},{"price":11228423.0,"size":1.951},{"price":11224500.0,"size":0.06},{"price":11224355.0,"size":0.0015},{"price":11223968.0,"size":0.001},{"price":11223535.0,"size":0.001},{"price":11223344.0,"size":0.01},{"price":11223000.0,"size":0.1},{"price":11222222.0,"size":0.092525},{"price":11221459.0,"size":0.1393},{"price":11221120.0,"size":0.011},{"price":11220200.0,"size":0.001},{"price":11220001.0,"size":0.004457},{"price":11220000.0,"size":0.321},{"price":11219595.0,"size":1.79},{"price":11219517.0,"size":0.01},{"price":11219000.0,"size":0.1},{"price":11215200.0,"size":0.001},{"price":11215000.0,"size":0.02},{"price":11212358.0,"size":1.2},{"price":11212201.0,"size":0.001},{"price":11211800.0,"size":0.001},{"price":11211111.0,"size":0.06},{"price":11210200.0,"size":0.001},{"price":11210000.0,"size":0.10622},{"price":11208032.0,"size":0.01},{"price":11207755.0,"size":0.0015},{"price":11206000.0,"size":0.09015},{"price":11205200.0,"size":0.001},{"price":11204578.0,"size":0.002},{"price":11203931.0,"size":1.0},{"price":11201000.0,"size":0.01},{"price":11200867.0,"size":0.001},{"price":11200800.0,"size":0.05},{"price":11200425.0,"size":0.1},{"price":11200200.0,"size":0.001},{"price":11200198.0,"size":0.003},{"price":11200150.0,"size":0.002},{"price":11200002.0,"size":0.001},{"price":11200001.0,"size":0.01104},{"price":11200000.0,"size":1.35988728},{"price":11198508.0,"size":0.05},{"price":11198243.0,"size":0.01},{"price":11197134.0,"size":2.0},{"price":11197000.0,"size":0.0085},{"price":11195692.0,"size":0.0015},{"price":11194090.0,"size":0.03},{"price":11190770.0,"size":0.0309},{"price":11190000.0,"size":0.0010016},{"price":11189555.0,"size":0.5},{"price":11189533.0,"size":0.001},{"price":11188629.0,"size":0.01},{"price":11188382.0,"size":0.001},{"price":11185000.0,"size":0.0085},{"price":11180043.0,"size":0.972},{"price":11180000.0,"size":0.23215},{"price":11178973.0,"size":0.0015},{"price":11178199.0,"size":0.001},{"price":11170000.0,"size":0.001},{"price":11169662.0,"size":0.01},{"price":11169593.0,"size":0.001},{"price":11169243.0,"size":0.01},{"price":11166865.0,"size":0.001},{"price":11164029.0,"size":0.001},{"price":11160854.0,"size":0.1},{"price":11160000.0,"size":0.02376},{"price":11156269.0,"size":0.01},{"price":11155531.0,"size":0.001},{"price":11155377.0,"size":0.00636009},{"price":11153999.0,"size":0.00101},{"price":11150250.0,"size":0.00175},{"price":11150005.0,"size":0.001},{"price":11150001.0,"size":0.00104},{"price":11150000.0,"size":0.6398956},{"price":11148000.0,"size":0.08963},{"price":11144197.0,"size":0.001},{"price":11144000.0,"size":0.0897},{"price":11140000.0,"size":0.2},{"price":11136243.0,"size":0.01},{"price":11135869.0,"size":0.1},{"price":11130000.0,"size":0.116},{"price":11129979.0,"size":0.0053908},{"price":11126388.0,"size":0.02},{"price":11124900.0,"size":0.00133},{"price":11121090.0,"size":0.1},{"price":11120000.0,"size":0.0033},{"price":11118078.0,"size":0.01},{"price":11111800.0,"size":0.001},{"price":11111111.0,"size":0.2919257},{"price":11111000.0,"size":0.003},{"price":11110594.0,"size":0.001},{"price":11110000.0,"size":0.056937},{"price":11109662.0,"size":0.01},{"price":11108008.0,"size":0.01},{"price":11106000.0,"size":0.2},{"price":11105000.0,"size":0.02},{"price":11101297.0,"size":0.001},{"price":11100005.0,"size":0.001},{"price":11100001.0,"size":0.01104},{"price":11100000.0,"size":2.7475049},{"price":11099141.0,"size":0.01},{"price":11096243.0,"size":0.01},{"price":11094090.0,"size":0.01},{"price":11088888.0,"size":0.001},{"price":11085245.0,"size":0.001},{"price":11080200.0,"size":0.001},{"price":11080000.0,"size":0.0223},{"price":11075100.0,"size":0.003},{"price":11071558.0,"size":1.0},{"price":11070200.0,"size":0.001},{"price":11070000.0,"size":0.0902},{"price":11065200.0,"size":0.001},{"price":11064370.0,"size":0.00497091},{"price":11060200.0,"size":0.001},{"price":11060000.0,"size":0.145},{"price":11059689.0,"size":0.009},{"price":11056428.0,"size":0.002},{"price":11055500.0,"size":0.02},{"price":11055200.0,"size":0.001},{"price":11055100.0,"size":0.003},{"price":11050200.0,"size":0.001},{"price":11050005.0,"size":0.001},{"price":11050002.0,"size":0.001},{"price":11050001.0,"size":0.00104},{"price":11050000.0,"size":0.43176147},{"price":11046420.0,"size":0.2},{"price":11044243.0,"size":0.01},{"price":11041380.0,"size":0.01},{"price":11040200.0,"size":0.001},{"price":11040000.0,"size":0.00777181},{"price":11035865.0,"size":0.1},{"price":11035200.0,"size":0.001},{"price":11035000.0,"size":0.0013},{"price":11030200.0,"size":0.001},{"price":11030000.0,"size":0.025},{"price":11025500.0,"size":0.009531},{"price":11025200.0,"size":0.001},{"price":11025000.0,"size":0.71497},{"price":11020772.0,"size":0.014},{"price":11020200.0,"size":0.002},{"price":11020000.0,"size":0.005},{"price":11015200.0,"size":0.001},{"price":11012000.0,"size":0.1},{"price":11011800.0,"size":0.001},{"price":11010200.0,"size":0.001},{"price":11010000.0,"size":0.347},{"price":11007277.0,"size":0.01},{"price":11006000.0,"size":0.2},{"price":11005200.0,"size":0.001},{"price":11004890.0,"size":0.001535},{"price":11003000.0,"size":0.0155},{"price":11001000.0,"size":0.013},{"price":11000500.0,"size":0.05117658},{"price":11000200.0,"size":0.001},{"price":11000002.0,"size":0.004},{"price":11000001.0,"size":0.02604},{"price":11000000.0,"size":5.47323365},{"price":10999999.0,"size":0.003},{"price":10999000.0,"size":0.001},{"price":10996855.0,"size":0.0011},{"price":10995200.0,"size":0.001},{"price":10994499.0,"size":0.00169176},{"price":10990200.0,"size":0.001},{"price":10990000.0,"size":0.10219},{"price":10989001.0,"size":0.00197},{"price":10988999.0,"size":0.001},{"price":10988324.0,"size":0.002},{"price":10987654.0,"size":0.001},{"price":10985200.0,"size":0.001},{"price":10985150.0,"size":0.01},{"price":10980500.0,"size":0.005},{"price":10980200.0,"size":0.001},{"price":10980002.0,"size":0.4},{"price":10980000.0,"size":0.028},{"price":10975200.0,"size":0.001},{"price":10975000.0,"size":0.1},{"price":10971261.0,"size":0.001},{"price":10971243.0,"size":0.01},{"price":10970375.0,"size":1.9},{"price":10970200.0,"size":0.001},{"price":10970000.0,"size":0.09304},{"price":10966600.0,"size":0.001003},{"price":10965200.0,"size":0.001},{"price":10960200.0,"size":0.001},{"price":10960000.0,"size":0.0083},{"price":10956673.0,"size":0.01},{"price":10955200.0,"size":0.001},{"price":10954950.0,"size":0.001},{"price":10950500.0,"size":0.005},{"price":10950001.0,"size":0.00204},{"price":10950000.0,"size":0.5485028},{"price":10949550.0,"size":0.01870657},{"price":10949172.0,"size":0.1},{"price":10948000.0,"size":0.1},{"price":10945243.0,"size":0.01},{"price":10940402.0,"size":0.001},{"price":10940200.0,"size":0.001},{"price":10940000.0,"size":0.331},{"price":10938243.0,"size":0.01},{"price":10936200.0,"size":0.00137},{"price":10935200.0,"size":0.001},{"price":10930200.0,"size":0.002},{"price":10930000.0,"size":0.0193},{"price":10925200.0,"size":0.002},{"price":10924451.0,"size":0.0012},{"price":10920509.0,"size":0.01},{"price":10920200.0,"size":0.002},{"price":10920000.0,"size":0.52},{"price":10915200.0,"size":0.001},{"price":10914000.0,"size":0.005},{"price":10911800.0,"size":0.001}],"asks":[{"price":11308357.0,"size":0.0776},{"price":11308930.0,"size":0.02},{"price":11309329.0,"size":0.02},{"price":11310160.0,"size":0.1251},{"price":11310713.0,"size":0.00999365},{"price":11311117.0,"size":0.014736},{"price":11311119.0,"size":0.3027},{"price":11312720.0,"size":0.4199},{"price":11312986.0,"size":0.01},{"price":11313538.0,"size":0.0546048},{"price":11313881.0,"size":0.2842},{"price":11313957.0,"size":0.014772},{"price":11316643.0,"size":0.2737},{"price":11317167.0,"size":0.053},{"price":11318050.0,"size":0.002},{"price":11318426.0,"size":0.57619101},{"price":11318640.0,"size":0.01},{"price":11319405.0,"size":0.2718},{"price":11320000.0,"size":0.02},{"price":11320586.0,"size":0.0776},{"price":11322000.0,"size":0.005},{"price":11323556.0,"size":1.189881},{"price":11323581.0,"size":1.189881},{"price":11324625.0,"size":0.0096974},{"price":11328050.0,"size":0.002},{"price":11329436.0,"size":0.0015},{"price":11331059.0,"size":0.001},{"price":11334236.0,"size":0.33650097},{"price":11334237.0,"size":1.489},{"price":11335742.0,"size":1.928},{"price":11340000.0,"size":0.13586406},{"price":11340647.0,"size":0.001},{"price":11342956.0,"size":1.60199848},{"price":11342957.0,"size":0.01},{"price":11346154.0,"size":0.0015},{"price":11348000.0,"size":0.1999},{"price":11349700.0,"size":0.001},{"price":11350000.0,"size":0.022},{"price":11353877.0,"size":0.001},{"price":11354939.0,"size":0.01},{"price":11355555.0,"size":0.001},{"price":11358323.0,"size":2.018},{"price":11359242.0,"size":0.0011},{"price":11359700.0,"size":0.001},{"price":11362692.0,"size":0.0015},{"price":11365211.0,"size":0.001},{"price":11369700.0,"size":0.001},{"price":11370000.0,"size":0.1},{"price":11372478.0,"size":1.943},{"price":11376000.0,"size":0.02},{"price":11376545.0,"size":0.001},{"price":11377000.0,"size":0.2287},{"price":11377269.0,"size":0.002},{"price":11379700.0,"size":0.001},{"price":11379865.0,"size":0.03},{"price":11380000.0,"size":0.0223},{"price":11380324.0,"size":0.002},{"price":11381766.0,"size":0.4},{"price":11382386.0,"size":0.0015},{"price":11385000.0,"size":0.2548},{"price":11385403.0,"size":0.002},{"price":11385664.0,"size":0.002},{"price":11387072.0,"size":0.01},{"price":11387354.0,"size":0.002},{"price":11387879.0,"size":0.001},{"price":11388885.0,"size":0.03},{"price":11389700.0,"size":0.001},{"price":11390000.0,"size":0.2488},{"price":11390050.0,"size":0.001},{"price":11392387.0,"size":1.0},{"price":11394939.0,"size":0.01},{"price":11395000.0,"size":0.06},{"price":11395775.0,"size":0.01},{"price":11396555.0,"size":0.03},{"price":11398444.0,"size":0.001995},{"price":11399213.0,"size":0.001},{"price":11399673.0,"size":0.0015},{"price":11399700.0,"size":0.001},{"price":11400000.0,"size":0.5525},{"price":11405000.0,"size":0.0275},{"price":11406336.0,"size":1.0},{"price":11408700.0,"size":0.001},{"price":11409415.0,"size":0.055},{"price":11410000.0,"size":0.03},{"price":11410547.0,"size":0.001},{"price":11410853.0,"size":0.002},{"price":11412000.0,"size":0.0878},{"price":11415000.0,"size":0.002},{"price":11415141.0,"size":0.0041},{"price":11417481.0,"size":0.0015},{"price":11418700.0,"size":0.001},{"price":11420000.0,"size":0.401},{"price":11421268.0,"size":0.05},{"price":11421881.0,"size":0.001},{"price":11423339.0,"size":2.0},{"price":11424941.0,"size":0.972},{"price":11425000.0,"size":0.049},{"price":11428121.0,"size":0.002},{"price":11428700.0,"size":0.001},{"price":11429302.0,"size":0.01},{"price":11432718.0,"size":0.002},{"price":11433211.0,"size":0.03},{"price":11433215.0,"size":0.001},{"price":11433333.0,"size":0.001},{"price":11437315.0,"size":0.002},{"price":11438525.0,"size":0.0011},{"price":11438700.0,"size":0.001},{"price":11439557.0,"size":0.001},{"price":11440000.0,"size":0.1038},{"price":11441911.0,"size":0.002},{"price":11444549.0,"size":0.001},{"price":11446508.0,"size":0.001},{"price":11447000.0,"size":0.01},{"price":11448000.0,"size":0.0875},{"price":11448700.0,"size":0.001},{"price":11450000.0,"size":0.258},{"price":11451105.0,"size":0.002},{"price":11453321.0,"size":0.03},{"price":11455702.0,"size":0.002},{"price":11455883.0,"size":0.001},{"price":11458700.0,"size":0.001},{"price":11458988.0,"size":0.01},{"price":11460000.0,"size":0.01702},{"price":11460299.0,"size":0.002},{"price":11464896.0,"size":0.002},{"price":11467217.0,"size":0.001},{"price":11468700.0,"size":0.001},{"price":11470000.0,"size":0.01},{"price":11471000.0,"size":0.01},{"price":11475000.0,"size":0.0028},{"price":11478551.0,"size":0.001},{"price":11478700.0,"size":0.001},{"price":11480000.0,"size":0.12491},{"price":11485000.0,"size":0.01},{"price":11486555.0,"size":0.03},{"price":11487685.0,"size":0.01},{"price":11488000.0,"size":0.102},{"price":11488700.0,"size":0.001},{"price":11489885.0,"size":0.001},{"price":11490841.0,"size":0.002},{"price":11495450.0,"size":0.002},{"price":11495850.0,"size":0.001},{"price":11498700.0,"size":0.001},{"price":11499000.0,"size":0.01},{"price":11500000.0,"size":0.46859519},{"price":11501219.0,"size":0.001},{"price":11502800.0,"size":0.00132},{"price":11503108.0,"size":0.0198},{"price":11505000.0,"size":0.0028},{"price":11505001.0,"size":0.002},{"price":11505836.0,"size":0.001},{"price":11508431.0,"size":0.047},{"price":11508700.0,"size":0.001},{"price":11508888.0,"size":0.02},{"price":11510000.0,"size":0.0976},{"price":11512553.0,"size":0.001},{"price":11513633.0,"size":0.08},{"price":11514332.0,"size":0.02},{"price":11518700.0,"size":0.001},{"price":11518992.0,"size":0.002},{"price":11519855.0,"size":0.01},{"price":11520000.0,"size":0.001},{"price":11522423.0,"size":0.97},{"price":11523211.0,"size":0.01},{"price":11523887.0,"size":0.001},{"price":11524999.0,"size":0.001},{"price":11528700.0,"size":0.001},{"price":11529852.0,"size":0.01},{"price":11530000.0,"size":0.261},{"price":11534084.0,"size":0.001},{"price":11535321.0,"size":0.01},{"price":11538700.0,"size":0.001},{"price":11540000.0,"size":0.0048},{"price":11540357.0,"size":0.002},{"price":11541011.0,"size":0.005},{"price":11541109.0,"size":0.01},{"price":11545262.0,"size":0.002},{"price":11546541.0,"size":0.01},{"price":11548700.0,"size":0.001},{"price":11550000.0,"size":0.014},{"price":11551109.0,"size":0.01},{"price":11552111.0,"size":0.01},{"price":11553687.0,"size":0.1},{"price":11555115.0,"size":0.001},{"price":11556000.0,"size":0.1},{"price":11558700.0,"size":0.001},{"price":11559855.0,"size":0.01},{"price":11560831.0,"size":0.0198},{"price":11561109.0,"size":0.01},{"price":11562000.0,"size":0.087},{"price":11566139.0,"size":0.0228},{"price":11566551.0,"size":0.01},{"price":11568700.0,"size":0.001},{"price":11570196.0,"size":0.002},{"price":11571109.0,"size":0.01},{"price":11573211.0,"size":0.01},{"price":11574840.0,"size":0.002},{"price":11578700.0,"size":0.001},{"price":11579484.0,"size":0.002},{"price":11579851.0,"size":0.01},{"price":11580000.0,"size":0.7735},{"price":11581109.0,"size":0.01},{"price":11584128.0,"size":0.002},{"price":11585000.0,"size":0.002},{"price":11586532.0,"size":0.01},{"price":11587498.0,"size":0.0198},{"price":11588700.0,"size":0.001},{"price":11589612.0,"size":0.012},{"price":11590000.0,"size":0.1},{"price":11590749.0,"size":0.002},{"price":11591109.0,"size":0.01},{"price":11593211.0,"size":0.01},{"price":11596753.0,"size":0.002},{"price":11598555.0,"size":0.01},{"price":11598700.0,"size":0.001},{"price":11599999.0,"size":0.001},{"price":11600000.0,"size":3.6141},{"price":11601109.0,"size":0.02},{"price":11606655.0,"size":0.01},{"price":11610000.0,"size":0.302},{"price":11611109.0,"size":0.01},{"price":11613321.0,"size":0.01},{"price":11620000.0,"size":1.35441682},{"price":11621011.0,"size":0.01},{"price":11621109.0,"size":0.01},{"price":11623096.0,"size":0.008},{"price":11629000.0,"size":0.1},{"price":11630000.0,"size":0.201},{"price":11630012.0,"size":0.05},{"price":11631059.0,"size":0.01},{"price":11631479.0,"size":0.01},{"price":11631773.0,"size":0.00386871},{"price":11635950.0,"size":0.001},{"price":11638259.0,"size":0.001},{"price":11639700.0,"size":0.001},{"price":11640000.0,"size":1.0},{"price":11640820.0,"size":0.01},{"price":11641651.0,"size":2.0},{"price":11645295.0,"size":0.05},{"price":11647158.0,"size":0.05},{"price":11649900.0,"size":0.02906},{"price":11649999.0,"size":0.001},{"price":11650000.0,"size":0.593},{"price":11651059.0,"size":0.01},{"price":11653658.0,"size":0.008},{"price":11654321.0,"size":0.001},{"price":11659700.0,"size":0.001},{"price":11661479.0,"size":0.01},{"price":11666000.0,"size":0.001},{"price":11666666.0,"size":0.013},{"price":11669700.0,"size":0.001},{"price":11671059.0,"size":0.01},{"price":11672562.0,"size":0.0198},{"price":11679224.0,"size":0.012},{"price":11680000.0,"size":0.004},{"price":11685000.0,"size":0.003},{"price":11688000.0,"size":0.001},{"price":11689732.0,"size":0.01},{"price":11690330.0,"size":0.0198},{"price":11691059.0,"size":0.01},{"price":11692558.0,"size":0.01},{"price":11698800.0,"size":0.00131},{"price":11699000.0,"size":0.001},{"price":11699631.0,"size":0.001},{"price":11699998.0,"size":0.01},{"price":11699999.0,"size":0.001},{"price":11700000.0,"size":1.03762841},{"price":11701059.0,"size":0.01},{"price":11720000.0,"size":0.1},{"price":11721059.0,"size":0.01},{"price":11725000.0,"size":0.005},{"price":11726791.0,"size":0.01},{"price":11730000.0,"size":0.9382},{"price":11740000.0,"size":0.101},{"price":11741059.0,"size":0.01},{"price":11745417.0,"size":2.0},{"price":11748937.0,"size":0.001},{"price":11749999.0,"size":0.001},{"price":11750000.0,"size":0.90537866},{"price":11750050.0,"size":0.2},{"price":11751151.0,"size":0.01},{"price":11755000.0,"size":0.001},{"price":11759999.0,"size":0.001},{"price":11760000.0,"size":0.001},{"price":11761059.0,"size":0.02},{"price":11765432.0,"size":0.001},{"price":11768000.0,"size":0.01},{"price":11768836.0,"size":0.012},{"price":11770000.0,"size":0.25464896},{"price":11771059.0,"size":0.01755555},{"price":11772000.0,"size":0.002},{"price":11775000.0,"size":0.11593},{"price":11775222.0,"size":0.001657},{"price":11775577.0,"size":0.00013523},{"price":11775800.0,"size":0.001},{"price":11775900.0,"size":0.2},{"price":11775989.0,"size":0.005},{"price":11777000.0,"size":0.5956},{"price":11777777.0,"size":0.0067},{"price":11778541.0,"size":0.001}]}}}
{"schema_version":"collector.vnext.raw","schema_contract":null,"schema_contract_version":null,"payload_contract_version":null,"record_type":"market.orderbook.diff","record_id":"collector_main-market-orderbook-diff-000000000061","collector_id":"collector_main","collector_role":"production","host_name":"MAIN-PC","session_id":"collector_main-sess-20260314T200835Z-09908d0d","stream_session_id":"collector_main-stream-bitflyer-board_ws-20260314T200921Z-c3dda1fe","exchange":"bitflyer","market":"spot","symbol":"BTC_JPY","instrument_id":"bitflyer.spot.BTC_JPY","channel":"board_ws","transport":"websocket","source_event_id":null,"source_sequence":null,"sequence_id":61,"exchange_ts":null,"collector_ts":"2026-03-14T20:09:21Z","ingest_ts":"2026-03-14T20:09:21Z","event_ts":"2026-03-14T20:09:21Z","quality_flags":[],"is_partial":false,"is_reconstructed":false,"confidence_score":1.0,"payload":{"provider":"bitflyer_ws_board","exchange":"bitflyer","transport":"websocket","channel":"lightning_board_BTC_JPY","received_ts":"2026-03-14T20:09:21.453467Z","subscription_id":null,"message_id":null,"source_sequence":null,"raw_message_meta":{"raw_channel":"lightning_board_BTC_JPY","subscription_channel":"lightning_board_BTC_JPY","recv_timeout_sec":10,"ssl_verify":false,"socket_url":"wss://ws.lightstream.bitflyer.com/json-rpc"},"source_payload":{"mid_price":11307298.0,"bids":[{"price":11300229.0,"size":0.0},{"price":11300657.0,"size":0.0},{"price":11296160.0,"size":0.0},{"price":11304330.0,"size":0.0}],"asks":[{"price":11310268.0,"size":0.0},{"price":11319484.0,"size":0.0}]}}}
{"schema_version":"collector.vnext.raw","schema_contract":null,"schema_contract_version":null,"payload_contract_version":null,"record_type":"market.orderbook.diff","record_id":"collector_main-market-orderbook-diff-000000000065","collector_id":"collector_main","collector_role":"production","host_name":"MAIN-PC","session_id":"collector_main-sess-20260314T200835Z-09908d0d","stream_session_id":"collector_main-stream-bitflyer-board_ws-20260314T200921Z-c3dda1fe","exchange":"bitflyer","market":"spot","symbol":"BTC_JPY","instrument_id":"bitflyer.spot.BTC_JPY","channel":"board_ws","transport":"websocket","source_event_id":null,"source_sequence":null,"sequence_id":65,"exchange_ts":null,"collector_ts":"2026-03-14T20:09:21Z","ingest_ts":"2026-03-14T20:09:21Z","event_ts":"2026-03-14T20:09:21Z","quality_flags":[],"is_partial":false,"is_reconstructed":false,"confidence_score":1.0,"payload":{"provider":"bitflyer_ws_board","exchange":"bitflyer","transport":"websocket","channel":"lightning_board_BTC_JPY","received_ts":"2026-03-14T20:09:21.580114Z","subscription_id":null,"message_id":null,"source_sequence":null,"raw_message_meta":{"raw_channel":"lightning_board_BTC_JPY","subscription_channel":"lightning_board_BTC_JPY","recv_timeout_sec":10,"ssl_verify":false,"socket_url":"wss://ws.lightstream.bitflyer.com/json-rpc"},"source_payload":{"mid_price":11307298.0,"bids":[{"price":11296158.0,"size":0.0}],"asks":[{"price":11318848.0,"size":0.30637708},{"price":11320479.0,"size":0.57609457}]}}}
{"schema_version":"collector.vnext.raw","schema_contract":null,"schema_contract_version":null,"payload_contract_version":null,"record_type":"market.orderbook.diff","record_id":"collector_main-market-orderbook-diff-000000000067","collector_id":"collector_main","collector_role":"production","host_name":"MAIN-PC","session_id":"collector_main-sess-20260314T200835Z-09908d0d","stream_session_id":"collector_main-stream-bitflyer-board_ws-20260314T200921Z-c3dda1fe","exchange":"bitflyer","market":"spot","symbol":"BTC_JPY","instrument_id":"bitflyer.spot.BTC_JPY","channel":"board_ws","transport":"websocket","source_event_id":null,"source_sequence":null,"sequence_id":67,"exchange_ts":null,"collector_ts":"2026-03-14T20:09:21Z","ingest_ts":"2026-03-14T20:09:21Z","event_ts":"2026-03-14T20:09:21Z","quality_flags":[],"is_partial":false,"is_reconstructed":false,"confidence_score":1.0,"payload":{"provider":"bitflyer_ws_board","exchange":"bitflyer","transport":"websocket","channel":"lightning_board_BTC_JPY","received_ts":"2026-03-14T20:09:21.687743Z","subscription_id":null,"message_id":null,"source_sequence":null,"raw_message_meta":{"raw_channel":"lightning_board_BTC_JPY","subscription_channel":"lightning_board_BTC_JPY","recv_timeout_sec":10,"ssl_verify":false,"socket_url":"wss://ws.lightstream.bitflyer.com/json-rpc"},"source_payload":{"mid_price":11307058.0,"bids":[{"price":11296161.0,"size":2.97384901},{"price":11304331.0,"size":0.0},{"price":11300692.0,"size":0.0}],"asks":[]}}}
{"schema_version":"collector.vnext.raw","schema_contract":null,"schema_contract_version":null,"payload_contract_version":null,"record_type":"market.orderbook.diff","record_id":"collector_main-market-orderbook-diff-000000000069","collector_id":"collector_main","collector_role":"production","host_name":"MAIN-PC","session_id":"collector_main-sess-20260314T200835Z-09908d0d","stream_session_id":"collector_main-stream-bitflyer-board_ws-20260314T200921Z-c3dda1fe","exchange":"bitflyer","market":"spot","symbol":"BTC_JPY","instrument_id":"bitflyer.spot.BTC_JPY","channel":"board_ws","transport":"websocket","source_event_id":null,"source_sequence":null,"sequence_id":69,"exchange_ts":null,"collector_ts":"2026-03-14T20:09:21Z","ingest_ts":"2026-03-14T20:09:21Z","event_ts":"2026-03-14T20:09:21Z","quality_flags":[],"is_partial":false,"is_reconstructed":false,"confidence_score":1.0,"payload":{"provider":"bitflyer_ws_board","exchange":"bitflyer","transport":"websocket","channel":"lightning_board_BTC_JPY","received_ts":"2026-03-14T20:09:21.808764Z","subscription_id":null,"message_id":null,"source_sequence":null,"raw_message_meta":{"raw_channel":"lightning_board_BTC_JPY","subscription_channel":"lightning_board_BTC_JPY","recv_timeout_sec":10,"ssl_verify":false,"socket_url":"wss://ws.lightstream.bitflyer.com/json-rpc"},"source_payload":{"mid_price":11307639.0,"bids":[{"price":11303852.0,"size":0.0},{"price":11305012.0,"size":0.00999866},{"price":11304332.0,"size":0.04183187}],"asks":[{"price":11310267.0,"size":0.005}]}}}
{"schema_version":"collector.vnext.raw","schema_contract":null,"schema_contract_version":null,"payload_contract_version":null,"record_type":"market.orderbook.diff","record_id":"collector_main-market-orderbook-diff-000000000071","collector_id":"collector_main","collector_role":"production","host_name":"MAIN-PC","session_id":"collector_main-sess-20260314T200835Z-09908d0d","stream_session_id":"collector_main-stream-bitflyer-board_ws-20260314T200921Z-c3dda1fe","exchange":"bitflyer","market":"spot","symbol":"BTC_JPY","instrument_id":"bitflyer.spot.BTC_JPY","channel":"board_ws","transport":"websocket","source_event_id":null,"source_sequence":null,"sequence_id":71,"exchange_ts":null,"collector_ts":"2026-03-14T20:09:21Z","ingest_ts":"2026-03-14T20:09:21Z","event_ts":"2026-03-14T20:09:21Z","quality_flags":[],"is_partial":false,"is_reconstructed":false,"confidence_score":1.0,"payload":{"provider":"bitflyer_ws_board","exchange":"bitflyer","transport":"websocket","channel":"lightning_board_BTC_JPY","received_ts":"2026-03-14T20:09:21.906783Z","subscription_id":null,"message_id":null,"source_sequence":null,"raw_message_meta":{"raw_channel":"lightning_board_BTC_JPY","subscription_channel":"lightning_board_BTC_JPY","recv_timeout_sec":10,"ssl_verify":false,"socket_url":"wss://ws.lightstream.bitflyer.com/json-rpc"},"source_payload":{"mid_price":11307639.0,"bids":[{"price":11294412.0,"size":0.00999859},{"price":11304332.0,"size":0.0},{"price":11303851.0,"size":0.0},{"price":11303212.0,"size":0.0},{"price":11302773.0,"size":0.0},{"price":11291744.0,"size":0.048},{"price":11300798.0,"size":0.015336},{"price":11297972.0,"size":0.015}],"asks":[{"price":11579484.0,"size":0.002}]}}}
{"schema_version":"collector.vnext.raw","schema_contract":null,"schema_contract_version":null,"payload_contract_version":null,"record_type":"market.orderbook.diff","record_id":"collector_main-market-orderbook-diff-000000000073","collector_id":"collector_main","collector_role":"production","host_name":"MAIN-PC","session_id":"collector_main-sess-20260314T200835Z-09908d0d","stream_session_id":"collector_main-stream-bitflyer-board_ws-20260314T200921Z-c3dda1fe","exchange":"bitflyer","market":"spot","symbol":"BTC_JPY","instrument_id":"bitflyer.spot.BTC_JPY","channel":"board_ws","transport":"websocket","source_event_id":null,"source_sequence":null,"sequence_id":73,"exchange_ts":null,"collector_ts":"2026-03-14T20:09:22Z","ingest_ts":"2026-03-14T20:09:22Z","event_ts":"2026-03-14T20:09:22Z","quality_flags":[],"is_partial":false,"is_reconstructed":false,"confidence_score":1.0,"payload":{"provider":"bitflyer_ws_board","exchange":"bitflyer","transport":"websocket","channel":"lightning_board_BTC_JPY","received_ts":"2026-03-14T20:09:22.015639Z","subscription_id":null,"message_id":null,"source_sequence":null,"raw_message_meta":{"raw_channel":"lightning_board_BTC_JPY","subscription_channel":"lightning_board_BTC_JPY","recv_timeout_sec":10,"ssl_verify":false,"socket_url":"wss://ws.lightstream.bitflyer.com/json-rpc"},"source_payload":{"mid_price":11307639.0,"bids":[{"price":11303852.0,"size":0.0},{"price":11252386.0,"size":0.002},{"price":11303994.0,"size":0.015348},{"price":11304333.0,"size":0.04568171}],"asks":[]}}}
{"schema_version":"collector.vnext.raw","schema_contract":null,"schema_contract_version":null,"payload_contract_version":null,"record_type":"market.orderbook.diff","record_id":"collector_main-market-orderbook-diff-000000000075","collector_id":"collector_main","collector_role":"production","host_name":"MAIN-PC","session_id":"collector_main-sess-20260314T200835Z-09908d0d","stream_session_id":"collector_main-stream-bitflyer-board_ws-20260314T200921Z-c3dda1fe","exchange":"bitflyer","market":"spot","symbol":"BTC_JPY","instrument_id":"bitflyer.spot.BTC_JPY","channel":"board_ws","transport":"websocket","source_event_id":null,"source_sequence":null,"sequence_id":75,"exchange_ts":null,"collector_ts":"2026-03-14T20:09:22Z","ingest_ts":"2026-03-14T20:09:22Z","event_ts":"2026-03-14T20:09:22Z","quality_flags":[],"is_partial":false,"is_reconstructed":false,"confidence_score":1.0,"payload":{"provider":"bitflyer_ws_board","exchange":"bitflyer","transport":"websocket","channel":"lightning_board_BTC_JPY","received_ts":"2026-03-14T20:09:22.142520Z","subscription_id":null,"message_id":null,"source_sequence":null,"raw_message_meta":{"raw_channel":"lightning_board_BTC_JPY","subscription_channel":"lightning_board_BTC_JPY","recv_timeout_sec":10,"ssl_verify":false,"socket_url":"wss://ws.lightstream.bitflyer.com/json-rpc"},"source_payload":{"mid_price":11307639.0,"bids":[{"price":11304333.0,"size":0.0},{"price":11299727.0,"size":0.0176977},{"price":11300799.0,"size":0.07264048}],"asks":[]}}}
{"schema_version":"collector.vnext.raw","schema_contract":null,"schema_contract_version":null,"payload_contract_version":null,"record_type":"market.orderbook.diff","record_id":"collector_main-market-orderbook-diff-000000000077","collector_id":"collector_main","collector_role":"production","host_name":"MAIN-PC","session_id":"collector_main-sess-20260314T200835Z-09908d0d","stream_session_id":"collector_main-stream-bitflyer-board_ws-20260314T200921Z-c3dda1fe","exchange":"bitflyer","market":"spot","symbol":"BTC_JPY","instrument_id":"bitflyer.spot.BTC_JPY","channel":"board_ws","transport":"websocket","source_event_id":null,"source_sequence":null,"sequence_id":77,"exchange_ts":null,"collector_ts":"2026-03-14T20:09:22Z","ingest_ts":"2026-03-14T20:09:22Z","event_ts":"2026-03-14T20:09:22Z","quality_flags":[],"is_partial":false,"is_reconstructed":false,"confidence_score":1.0,"payload":{"provider":"bitflyer_ws_board","exchange":"bitflyer","transport":"websocket","channel":"lightning_board_BTC_JPY","received_ts":"2026-03-14T20:09:22.236177Z","subscription_id":null,"message_id":null,"source_sequence":null,"raw_message_meta":{"raw_channel":"lightning_board_BTC_JPY","subscription_channel":"lightning_board_BTC_JPY","recv_timeout_sec":10,"ssl_verify":false,"socket_url":"wss://ws.lightstream.bitflyer.com/json-rpc"},"source_payload":{"mid_price":11307639.0,"bids":[{"price":11300799.0,"size":0.0}],"asks":[]}}}
{"schema_version":"collector.vnext.raw","schema_contract":null,"schema_contract_version":null,"payload_contract_version":null,"record_type":"market.orderbook.diff","record_id":"collector_main-market-orderbook-diff-000000000079","collector_id":"collector_main","collector_role":"production","host_name":"MAIN-PC","session_id":"collector_main-sess-20260314T200835Z-09908d0d","stream_session_id":"collector_main-stream-bitflyer-board_ws-20260314T200921Z-c3dda1fe","exchange":"bitflyer","market":"spot","symbol":"BTC_JPY","instrument_id":"bitflyer.spot.BTC_JPY","channel":"board_ws","transport":"websocket","source_event_id":null,"source_sequence":null,"sequence_id":79,"exchange_ts":null,"collector_ts":"2026-03-14T20:09:22Z","ingest_ts":"2026-03-14T20:09:22Z","event_ts":"2026-03-14T20:09:22Z","quality_flags":[],"is_partial":false,"is_reconstructed":false,"confidence_score":1.0,"payload":{"provider":"bitflyer_ws_board","exchange":"bitflyer","transport":"websocket","channel":"lightning_board_BTC_JPY","received_ts":"2026-03-14T20:09:22.359893Z","subscription_id":null,"message_id":null,"source_sequence":null,"raw_message_meta":{"raw_channel":"lightning_board_BTC_JPY","subscription_channel":"lightning_board_BTC_JPY","recv_timeout_sec":10,"ssl_verify":false,"socket_url":"wss://ws.lightstream.bitflyer.com/json-rpc"},"source_payload":{"mid_price":11307639.0,"bids":[{"price":11303995.0,"size":0.04568694}],"asks":[]}}}
{"schema_version":"collector.vnext.raw","schema_contract":null,"schema_contract_version":null,"payload_contract_version":null,"record_type":"market.orderbook.diff","record_id":"collector_main-market-orderbook-diff-000000000081","collector_id":"collector_main","collector_role":"production","host_name":"MAIN-PC","session_id":"collector_main-sess-20260314T200835Z-09908d0d","stream_session_id":"collector_main-stream-bitflyer-board_ws-20260314T200921Z-c3dda1fe","exchange":"bitflyer","market":"spot","symbol":"BTC_JPY","instrument_id":"bitflyer.spot.BTC_JPY","channel":"board_ws","transport":"websocket","source_event_id":null,"source_sequence":null,"sequence_id":81,"exchange_ts":null,"collector_ts":"2026-03-14T20:09:22Z","ingest_ts":"2026-03-14T20:09:22Z","event_ts":"2026-03-14T20:09:22Z","quality_flags":[],"is_partial":false,"is_reconstructed":false,"confidence_score":1.0,"payload":{"provider":"bitflyer_ws_board","exchange":"bitflyer","transport":"websocket","channel":"lightning_board_BTC_JPY","received_ts":"2026-03-14T20:09:22.594315Z","subscription_id":null,"message_id":null,"source_sequence":null,"raw_message_meta":{"raw_channel":"lightning_board_BTC_JPY","subscription_channel":"lightning_board_BTC_JPY","recv_timeout_sec":10,"ssl_verify":false,"socket_url":"wss://ws.lightstream.bitflyer.com/json-rpc"},"source_payload":{"mid_price":11307456.0,"bids":[{"price":11300854.0,"size":0.1275},{"price":11300289.0,"size":0.1275}],"asks":[{"price":11309901.0,"size":0.1251},{"price":11319404.0,"size":0.0}]}}}
{"schema_version":"collector.vnext.raw","schema_contract":null,"schema_contract_version":null,"payload_contract_version":null,"record_type":"market.orderbook.diff","record_id":"collector_main-market-orderbook-diff-000000000083","collector_id":"collector_main","collector_role":"production","host_name":"MAIN-PC","session_id":"collector_main-sess-20260314T200835Z-09908d0d","stream_session_id":"collector_main-stream-bitflyer-board_ws-20260314T200921Z-c3dda1fe","exchange":"bitflyer","market":"spot","symbol":"BTC_JPY","instrument_id":"bitflyer.spot.BTC_JPY","channel":"board_ws","transport":"websocket","source_event_id":null,"source_sequence":null,"sequence_id":83,"exchange_ts":null,"collector_ts":"2026-03-14T20:09:22Z","ingest_ts":"2026-03-14T20:09:22Z","event_ts":"2026-03-14T20:09:22Z","quality_flags":[],"is_partial":false,"is_reconstructed":false,"confidence_score":1.0,"payload":{"provider":"bitflyer_ws_board","exchange":"bitflyer","transport":"websocket","channel":"lightning_board_BTC_JPY","received_ts":"2026-03-14T20:09:22.830130Z","subscription_id":null,"message_id":null,"source_sequence":null,"raw_message_meta":{"raw_channel":"lightning_board_BTC_JPY","subscription_channel":"lightning_board_BTC_JPY","recv_timeout_sec":10,"ssl_verify":false,"socket_url":"wss://ws.lightstream.bitflyer.com/json-rpc"},"source_payload":{"mid_price":11307456.0,"bids":[{"price":11300289.0,"size":0.0},{"price":11291744.0,"size":0.0}],"asks":[{"price":11320479.0,"size":0.0},{"price":11325160.0,"size":0.0},{"price":11321159.0,"size":0.57609457}]}}}
{"schema_version":"collector.vnext.raw","schema_contract":null,"schema_contract_version":null,"payload_contract_version":null,"record_type":"market.orderbook.diff","record_id":"collector_main-market-orderbook-diff-000000000085","collector_id":"collector_main","collector_role":"production","host_name":"MAIN-PC","session_id":"collector_main-sess-20260314T200835Z-09908d0d","stream_session_id":"collector_main-stream-bitflyer-board_ws-20260314T200921Z-c3dda1fe","exchange":"bitflyer","market":"spot","symbol":"BTC_JPY","instrument_id":"bitflyer.spot.BTC_JPY","channel":"board_ws","transport":"websocket","source_event_id":null,"source_sequence":null,"sequence_id":85,"exchange_ts":null,"collector_ts":"2026-03-14T20:09:22Z","ingest_ts":"2026-03-14T20:09:22Z","event_ts":"2026-03-14T20:09:22Z","quality_flags":[],"is_partial":false,"is_reconstructed":false,"confidence_score":1.0,"payload":{"provider":"bitflyer_ws_board","exchange":"bitflyer","transport":"websocket","channel":"lightning_board_BTC_JPY","received_ts":"2026-03-14T20:09:22.922344Z","subscription_id":null,"message_id":null,"source_sequence":null,"raw_message_meta":{"raw_channel":"lightning_board_BTC_JPY","subscription_channel":"lightning_board_BTC_JPY","recv_timeout_sec":10,"ssl_verify":false,"socket_url":"wss://ws.lightstream.bitflyer.com/json-rpc"},"source_payload":{"mid_price":11307456.0,"bids":[{"price":11293678.0,"size":0.0}],"asks":[]}}}
{"schema_version":"collector.vnext.raw","schema_contract":null,"schema_contract_version":null,"payload_contract_version":null,"record_type":"market.orderbook.diff","record_id":"collector_main-market-orderbook-diff-000000000087","collector_id":"collector_main","collector_role":"production","host_name":"MAIN-PC","session_id":"collector_main-sess-20260314T200835Z-09908d0d","stream_session_id":"collector_main-stream-bitflyer-board_ws-20260314T200921Z-c3dda1fe","exchange":"bitflyer","market":"spot","symbol":"BTC_JPY","instrument_id":"bitflyer.spot.BTC_JPY","channel":"board_ws","transport":"websocket","source_event_id":null,"source_sequence":null,"sequence_id":87,"exchange_ts":null,"collector_ts":"2026-03-14T20:09:23Z","ingest_ts":"2026-03-14T20:09:23Z","event_ts":"2026-03-14T20:09:23Z","quality_flags":[],"is_partial":false,"is_reconstructed":false,"confidence_score":1.0,"payload":{"provider":"bitflyer_ws_board","exchange":"bitflyer","transport":"websocket","channel":"lightning_board_BTC_JPY","received_ts":"2026-03-14T20:09:23.037147Z","subscription_id":null,"message_id":null,"source_sequence":null,"raw_message_meta":{"raw_channel":"lightning_board_BTC_JPY","subscription_channel":"lightning_board_BTC_JPY","recv_timeout_sec":10,"ssl_verify":false,"socket_url":"wss://ws.lightstream.bitflyer.com/json-rpc"},"source_payload":{"mid_price":11307456.0,"bids":[{"price":11299727.0,"size":0.0},{"price":10125787.0,"size":0.0}],"asks":[{"price":11325160.0,"size":0.0059893},{"price":12036506.0,"size":0.0}]}}}
{"schema_version":"collector.vnext.raw","schema_contract":null,"schema_contract_version":null,"payload_contract_version":null,"record_type":"market.orderbook.diff","record_id":"collector_main-market-orderbook-diff-000000000089","collector_id":"collector_main","collector_role":"production","host_name":"MAIN-PC","session_id":"collector_main-sess-20260314T200835Z-09908d0d","stream_session_id":"collector_main-stream-bitflyer-board_ws-20260314T200921Z-c3dda1fe","exchange":"bitflyer","market":"spot","symbol":"BTC_JPY","instrument_id":"bitflyer.spot.BTC_JPY","channel":"board_ws","transport":"websocket","source_event_id":null,"source_sequence":null,"sequence_id":89,"exchange_ts":null,"collector_ts":"2026-03-14T20:09:23Z","ingest_ts":"2026-03-14T20:09:23Z","event_ts":"2026-03-14T20:09:23Z","quality_flags":[],"is_partial":false,"is_reconstructed":false,"confidence_score":1.0,"payload":{"provider":"bitflyer_ws_board","exchange":"bitflyer","transport":"websocket","channel":"lightning_board_BTC_JPY","received_ts":"2026-03-14T20:09:23.174496Z","subscription_id":null,"message_id":null,"source_sequence":null,"raw_message_meta":{"raw_channel":"lightning_board_BTC_JPY","subscription_channel":"lightning_board_BTC_JPY","recv_timeout_sec":10,"ssl_verify":false,"socket_url":"wss://ws.lightstream.bitflyer.com/json-rpc"},"source_payload":{"mid_price":11307456.0,"bids":[{"price":11301237.0,"size":0.1275}],"asks":[{"price":11584128.0,"size":0.002}]}}}
{"schema_version":"collector.vnext.raw","schema_contract":null,"schema_contract_version":null,"payload_contract_version":null,"record_type":"market.orderbook.diff","record_id":"collector_main-market-orderbook-diff-000000000091","collector_id":"collector_main","collector_role":"production","host_name":"MAIN-PC","session_id":"collector_main-sess-20260314T200835Z-09908d0d","stream_session_id":"collector_main-stream-bitflyer-board_ws-20260314T200921Z-c3dda1fe","exchange":"bitflyer","market":"spot","symbol":"BTC_JPY","instrument_id":"bitflyer.spot.BTC_JPY","channel":"board_ws","transport":"websocket","source_event_id":null,"source_sequence":null,"sequence_id":91,"exchange_ts":null,"collector_ts":"2026-03-14T20:09:23Z","ingest_ts":"2026-03-14T20:09:23Z","event_ts":"2026-03-14T20:09:23Z","quality_flags":[],"is_partial":false,"is_reconstructed":false,"confidence_score":1.0,"payload":{"provider":"bitflyer_ws_board","exchange":"bitflyer","transport":"websocket","channel":"lightning_board_BTC_JPY","received_ts":"2026-03-14T20:09:23.385941Z","subscription_id":null,"message_id":null,"source_sequence":null,"raw_message_meta":{"raw_channel":"lightning_board_BTC_JPY","subscription_channel":"lightning_board_BTC_JPY","recv_timeout_sec":10,"ssl_verify":false,"socket_url":"wss://ws.lightstream.bitflyer.com/json-rpc"},"source_payload":{"mid_price":11307456.0,"bids":[{"price":11301237.0,"size":0.0},{"price":11301272.0,"size":0.0176953}],"asks":[{"price":11321120.0,"size":0.0}]}}}
{"schema_version":"collector.vnext.raw","schema_contract":null,"schema_contract_version":null,"payload_contract_version":null,"record_type":"market.orderbook.diff","record_id":"collector_main-market-orderbook-diff-000000000093","collector_id":"collector_main","collector_role":"production","host_name":"MAIN-PC","session_id":"collector_main-sess-20260314T200835Z-09908d0d","stream_session_id":"collector_main-stream-bitflyer-board_ws-20260314T200921Z-c3dda1fe","exchange":"bitflyer","market":"spot","symbol":"BTC_JPY","instrument_id":"bitflyer.spot.BTC_JPY","channel":"board_ws","transport":"websocket","source_event_id":null,"source_sequence":null,"sequence_id":93,"exchange_ts":null,"collector_ts":"2026-03-14T20:09:23Z","ingest_ts":"2026-03-14T20:09:23Z","event_ts":"2026-03-14T20:09:23Z","quality_flags":[],"is_partial":false,"is_reconstructed":false,"confidence_score":1.0,"payload":{"provider":"bitflyer_ws_board","exchange":"bitflyer","transport":"websocket","channel":"lightning_board_BTC_JPY","received_ts":"2026-03-14T20:09:23.520220Z","subscription_id":null,"message_id":null,"source_sequence":null,"raw_message_meta":{"raw_channel":"lightning_board_BTC_JPY","subscription_channel":"lightning_board_BTC_JPY","recv_timeout_sec":10,"ssl_verify":false,"socket_url":"wss://ws.lightstream.bitflyer.com/json-rpc"},"source_payload":{"mid_price":11307456.0,"bids":[{"price":11293678.0,"size":0.001},{"price":11299617.0,"size":0.0},{"price":11301237.0,"size":0.1275}],"asks":[]}}}
{"schema_version":"collector.vnext.raw","schema_contract":null,"schema_contract_version":null,"payload_contract_version":null,"record_type":"market.orderbook.diff","record_id":"collector_main-market-orderbook-diff-000000000095","collector_id":"collector_main","collector_role":"production","host_name":"MAIN-PC","session_id":"collector_main-sess-20260314T200835Z-09908d0d","stream_session_id":"collector_main-stream-bitflyer-board_ws-20260314T200921Z-c3dda1fe","exchange":"bitflyer","market":"spot","symbol":"BTC_JPY","instrument_id":"bitflyer.spot.BTC_JPY","channel":"board_ws","transport":"websocket","source_event_id":null,"source_sequence":null,"sequence_id":95,"exchange_ts":null,"collector_ts":"2026-03-14T20:09:23Z","ingest_ts":"2026-03-14T20:09:23Z","event_ts":"2026-03-14T20:09:23Z","quality_flags":[],"is_partial":false,"is_reconstructed":false,"confidence_score":1.0,"payload":{"provider":"bitflyer_ws_board","exchange":"bitflyer","transport":"websocket","channel":"lightning_board_BTC_JPY","received_ts":"2026-03-14T20:09:23.625598Z","subscription_id":null,"message_id":null,"source_sequence":null,"raw_message_meta":{"raw_channel":"lightning_board_BTC_JPY","subscription_channel":"lightning_board_BTC_JPY","recv_timeout_sec":10,"ssl_verify":false,"socket_url":"wss://ws.lightstream.bitflyer.com/json-rpc"},"source_payload":{"mid_price":11307456.0,"bids":[],"asks":[{"price":11323555.0,"size":0.3429732}]}}}
{"schema_version":"collector.vnext.raw","schema_contract":null,"schema_contract_version":null,"payload_contract_version":null,"record_type":"market.orderbook.diff","record_id":"collector_main-market-orderbook-diff-000000000097","collector_id":"collector_main","collector_role":"production","host_name":"MAIN-PC","session_id":"collector_main-sess-20260314T200835Z-09908d0d","stream_session_id":"collector_main-stream-bitflyer-board_ws-20260314T200921Z-c3dda1fe","exchange":"bitflyer","market":"spot","symbol":"BTC_JPY","instrument_id":"bitflyer.spot.BTC_JPY","channel":"board_ws","transport":"websocket","source_event_id":null,"source_sequence":null,"sequence_id":97,"exchange_ts":null,"collector_ts":"2026-03-14T20:09:23Z","ingest_ts":"2026-03-14T20:09:23Z","event_ts":"2026-03-14T20:09:23Z","quality_flags":[],"is_partial":false,"is_reconstructed":false,"confidence_score":1.0,"payload":{"provider":"bitflyer_ws_board","exchange":"bitflyer","transport":"websocket","channel":"lightning_board_BTC_JPY","received_ts":"2026-03-14T20:09:23.719368Z","subscription_id":null,"message_id":null,"source_sequence":null,"raw_message_meta":{"raw_channel":"lightning_board_BTC_JPY","subscription_channel":"lightning_board_BTC_JPY","recv_timeout_sec":10,"ssl_verify":false,"socket_url":"wss://ws.lightstream.bitflyer.com/json-rpc"},"source_payload":{"mid_price":11307456.0,"bids":[{"price":11271711.0,"size":0.6},{"price":11300854.0,"size":0.0},{"price":11301237.0,"size":0.0}],"asks":[]}}}
{"schema_version":"collector.vnext.raw","schema_contract":null,"schema_contract_version":null,"payload_contract_version":null,"record_type":"market.orderbook.diff","record_id":"collector_main-market-orderbook-diff-000000000099","collector_id":"collector_main","collector_role":"production","host_name":"MAIN-PC","session_id":"collector_main-sess-20260314T200835Z-09908d0d","stream_session_id":"collector_main-stream-bitflyer-board_ws-20260314T200921Z-c3dda1fe","exchange":"bitflyer","market":"spot","symbol":"BTC_JPY","instrument_id":"bitflyer.spot.BTC_JPY","channel":"board_ws","transport":"websocket","source_event_id":null,"source_sequence":null,"sequence_id":99,"exchange_ts":null,"collector_ts":"2026-03-14T20:09:23Z","ingest_ts":"2026-03-14T20:09:23Z","event_ts":"2026-03-14T20:09:23Z","quality_flags":[],"is_partial":false,"is_reconstructed":false,"confidence_score":1.0,"payload":{"provider":"bitflyer_ws_board","exchange":"bitflyer","transport":"websocket","channel":"lightning_board_BTC_JPY","received_ts":"2026-03-14T20:09:23.837687Z","subscription_id":null,"message_id":null,"source_sequence":null,"raw_message_meta":{"raw_channel":"lightning_board_BTC_JPY","subscription_channel":"lightning_board_BTC_JPY","recv_timeout_sec":10,"ssl_verify":false,"socket_url":"wss://ws.lightstream.bitflyer.com/json-rpc"},"source_payload":{"mid_price":11307456.0,"bids":[{"price":11299693.0,"size":0.02},{"price":11300093.0,"size":0.02}],"asks":[]}}}
{"schema_version":"collector.vnext.raw","schema_contract":null,"schema_contract_version":null,"payload_contract_version":null,"record_type":"market.orderbook.diff","record_id":"collector_main-market-orderbook-diff-000000000101","collector_id":"collector_main","collector_role":"production","host_name":"MAIN-PC","session_id":"collector_main-sess-20260314T200835Z-09908d0d","stream_session_id":"collector_main-stream-bitflyer-board_ws-20260314T200921Z-c3dda1fe","exchange":"bitflyer","market":"spot","symbol":"BTC_JPY","instrument_id":"bitflyer.spot.BTC_JPY","channel":"board_ws","transport":"websocket","source_event_id":null,"source_sequence":null,"sequence_id":101,"exchange_ts":null,"collector_ts":"2026-03-14T20:09:23Z","ingest_ts":"2026-03-14T20:09:23Z","event_ts":"2026-03-14T20:09:23Z","quality_flags":[],"is_partial":false,"is_reconstructed":false,"confidence_score":1.0,"payload":{"provider":"bitflyer_ws_board","exchange":"bitflyer","transport":"websocket","channel":"lightning_board_BTC_JPY","received_ts":"2026-03-14T20:09:23.964981Z","subscription_id":null,"message_id":null,"source_sequence":null,"raw_message_meta":{"raw_channel":"lightning_board_BTC_JPY","subscription_channel":"lightning_board_BTC_JPY","recv_timeout_sec":10,"ssl_verify":false,"socket_url":"wss://ws.lightstream.bitflyer.com/json-rpc"},"source_payload":{"mid_price":11307456.0,"bids":[{"price":11301273.0,"size":0.02}],"asks":[]}}}
{"schema_version":"collector.vnext.raw","schema_contract":null,"schema_contract_version":null,"payload_contract_version":null,"record_type":"market.orderbook.diff","record_id":"collector_main-market-orderbook-diff-000000000103","collector_id":"collector_main","collector_role":"production","host_name":"MAIN-PC","session_id":"collector_main-sess-20260314T200835Z-09908d0d","stream_session_id":"collector_main-stream-bitflyer-board_ws-20260314T200921Z-c3dda1fe","exchange":"bitflyer","market":"spot","symbol":"BTC_JPY","instrument_id":"bitflyer.spot.BTC_JPY","channel":"board_ws","transport":"websocket","source_event_id":null,"source_sequence":null,"sequence_id":103,"exchange_ts":null,"collector_ts":"2026-03-14T20:09:24Z","ingest_ts":"2026-03-14T20:09:24Z","event_ts":"2026-03-14T20:09:24Z","quality_flags":[],"is_partial":false,"is_reconstructed":false,"confidence_score":1.0,"payload":{"provider":"bitflyer_ws_board","exchange":"bitflyer","transport":"websocket","channel":"lightning_board_BTC_JPY","received_ts":"2026-03-14T20:09:24.063397Z","subscription_id":null,"message_id":null,"source_sequence":null,"raw_message_meta":{"raw_channel":"lightning_board_BTC_JPY","subscription_channel":"lightning_board_BTC_JPY","recv_timeout_sec":10,"ssl_verify":false,"socket_url":"wss://ws.lightstream.bitflyer.com/json-rpc"},"source_payload":{"mid_price":11307456.0,"bids":[{"price":11300106.0,"size":0.1275},{"price":11298963.0,"size":0.02},{"price":11248994.0,"size":0.002}],"asks":[]}}}
{"schema_version":"collector.vnext.raw","schema_contract":null,"schema_contract_version":null,"payload_contract_version":null,"record_type":"market.orderbook.diff","record_id":"collector_main-market-orderbook-diff-000000000105","collector_id":"collector_main","collector_role":"production","host_name":"MAIN-PC","session_id":"collector_main-sess-20260314T200835Z-09908d0d","stream_session_id":"collector_main-stream-bitflyer-board_ws-20260314T200921Z-c3dda1fe","exchange":"bitflyer","market":"spot","symbol":"BTC_JPY","instrument_id":"bitflyer.spot.BTC_JPY","channel":"board_ws","transport":"websocket","source_event_id":null,"source_sequence":null,"sequence_id":105,"exchange_ts":null,"collector_ts":"2026-03-14T20:09:24Z","ingest_ts":"2026-03-14T20:09:24Z","event_ts":"2026-03-14T20:09:24Z","quality_flags":[],"is_partial":false,"is_reconstructed":false,"confidence_score":1.0,"payload":{"provider":"bitflyer_ws_board","exchange":"bitflyer","transport":"websocket","channel":"lightning_board_BTC_JPY","received_ts":"2026-03-14T20:09:24.173522Z","subscription_id":null,"message_id":null,"source_sequence":null,"raw_message_meta":{"raw_channel":"lightning_board_BTC_JPY","subscription_channel":"lightning_board_BTC_JPY","recv_timeout_sec":10,"ssl_verify":false,"socket_url":"wss://ws.lightstream.bitflyer.com/json-rpc"},"source_payload":{"mid_price":11307456.0,"bids":[{"price":11298853.0,"size":0.02},{"price":11301272.0,"size":0.0}],"asks":[]}}}
{"schema_version":"collector.vnext.raw","schema_contract":null,"schema_contract_version":null,"payload_contract_version":null,"record_type":"market.orderbook.diff","record_id":"collector_main-market-orderbook-diff-000000000107","collector_id":"collector_main","collector_role":"production","host_name":"MAIN-PC","session_id":"collector_main-sess-20260314T200835Z-09908d0d","stream_session_id":"collector_main-stream-bitflyer-board_ws-20260314T200921Z-c3dda1fe","exchange":"bitflyer","market":"spot","symbol":"BTC_JPY","instrument_id":"bitflyer.spot.BTC_JPY","channel":"board_ws","transport":"websocket","source_event_id":null,"source_sequence":null,"sequence_id":107,"exchange_ts":null,"collector_ts":"2026-03-14T20:09:24Z","ingest_ts":"2026-03-14T20:09:24Z","event_ts":"2026-03-14T20:09:24Z","quality_flags":[],"is_partial":false,"is_reconstructed":false,"confidence_score":1.0,"payload":{"provider":"bitflyer_ws_board","exchange":"bitflyer","transport":"websocket","channel":"lightning_board_BTC_JPY","received_ts":"2026-03-14T20:09:24.282285Z","subscription_id":null,"message_id":null,"source_sequence":null,"raw_message_meta":{"raw_channel":"lightning_board_BTC_JPY","subscription_channel":"lightning_board_BTC_JPY","recv_timeout_sec":10,"ssl_verify":false,"socket_url":"wss://ws.lightstream.bitflyer.com/json-rpc"},"source_payload":{"mid_price":11307456.0,"bids":[{"price":11301802.0,"size":0.1275}],"asks":[{"price":11596753.0,"size":0.002}]}}}
{"schema_version":"collector.vnext.raw","schema_contract":null,"schema_contract_version":null,"payload_contract_version":null,"record_type":"market.orderbook.diff","record_id":"collector_main-market-orderbook-diff-000000000109","collector_id":"collector_main","collector_role":"production","host_name":"MAIN-PC","session_id":"collector_main-sess-20260314T200835Z-09908d0d","stream_session_id":"collector_main-stream-bitflyer-board_ws-20260314T200921Z-c3dda1fe","exchange":"bitflyer","market":"spot","symbol":"BTC_JPY","instrument_id":"bitflyer.spot.BTC_JPY","channel":"board_ws","transport":"websocket","source_event_id":null,"source_sequence":null,"sequence_id":109,"exchange_ts":null,"collector_ts":"2026-03-14T20:09:24Z","ingest_ts":"2026-03-14T20:09:24Z","event_ts":"2026-03-14T20:09:24Z","quality_flags":[],"is_partial":false,"is_reconstructed":false,"confidence_score":1.0,"payload":{"provider":"bitflyer_ws_board","exchange":"bitflyer","transport":"websocket","channel":"lightning_board_BTC_JPY","received_ts":"2026-03-14T20:09:24.386161Z","subscription_id":null,"message_id":null,"source_sequence":null,"raw_message_meta":{"raw_channel":"lightning_board_BTC_JPY","subscription_channel":"lightning_board_BTC_JPY","recv_timeout_sec":10,"ssl_verify":false,"socket_url":"wss://ws.lightstream.bitflyer.com/json-rpc"},"source_payload":{"mid_price":11307456.0,"bids":[{"price":11301273.0,"size":0.0},{"price":11299617.0,"size":0.2}],"asks":[{"price":11321120.0,"size":0.2}]}}}
{"schema_version":"collector.vnext.raw","schema_contract":null,"schema_contract_version":null,"payload_contract_version":null,"record_type":"market.orderbook.diff","record_id":"collector_main-market-orderbook-diff-000000000111","collector_id":"collector_main","collector_role":"production","host_name":"MAIN-PC","session_id":"collector_main-sess-20260314T200835Z-09908d0d","stream_session_id":"collector_main-stream-bitflyer-board_ws-20260314T200921Z-c3dda1fe","exchange":"bitflyer","market":"spot","symbol":"BTC_JPY","instrument_id":"bitflyer.spot.BTC_JPY","channel":"board_ws","transport":"websocket","source_event_id":null,"source_sequence":null,"sequence_id":111,"exchange_ts":null,"collector_ts":"2026-03-14T20:09:24Z","ingest_ts":"2026-03-14T20:09:24Z","event_ts":"2026-03-14T20:09:24Z","quality_flags":[],"is_partial":false,"is_reconstructed":false,"confidence_score":1.0,"payload":{"provider":"bitflyer_ws_board","exchange":"bitflyer","transport":"websocket","channel":"lightning_board_BTC_JPY","received_ts":"2026-03-14T20:09:24.490087Z","subscription_id":null,"message_id":null,"source_sequence":null,"raw_message_meta":{"raw_channel":"lightning_board_BTC_JPY","subscription_channel":"lightning_board_BTC_JPY","recv_timeout_sec":10,"ssl_verify":false,"socket_url":"wss://ws.lightstream.bitflyer.com/json-rpc"},"source_payload":{"mid_price":11307456.0,"bids":[{"price":11301802.0,"size":0.0},{"price":11300106.0,"size":0.0}],"asks":[]}}}
{"schema_version":"collector.vnext.raw","schema_contract":null,"schema_contract_version":null,"payload_contract_version":null,"record_type":"market.orderbook.diff","record_id":"collector_main-market-orderbook-diff-000000000113","collector_id":"collector_main","collector_role":"production","host_name":"MAIN-PC","session_id":"collector_main-sess-20260314T200835Z-09908d0d","stream_session_id":"collector_main-stream-bitflyer-board_ws-20260314T200921Z-c3dda1fe","exchange":"bitflyer","market":"spot","symbol":"BTC_JPY","instrument_id":"bitflyer.spot.BTC_JPY","channel":"board_ws","transport":"websocket","source_event_id":null,"source_sequence":null,"sequence_id":113,"exchange_ts":null,"collector_ts":"2026-03-14T20:09:24Z","ingest_ts":"2026-03-14T20:09:24Z","event_ts":"2026-03-14T20:09:24Z","quality_flags":[],"is_partial":false,"is_reconstructed":false,"confidence_score":1.0,"payload":{"provider":"bitflyer_ws_board","exchange":"bitflyer","transport":"websocket","channel":"lightning_board_BTC_JPY","received_ts":"2026-03-14T20:09:24.719812Z","subscription_id":null,"message_id":null,"source_sequence":null,"raw_message_meta":{"raw_channel":"lightning_board_BTC_JPY","subscription_channel":"lightning_board_BTC_JPY","recv_timeout_sec":10,"ssl_verify":false,"socket_url":"wss://ws.lightstream.bitflyer.com/json-rpc"},"source_payload":{"mid_price":11307456.0,"bids":[{"price":11301837.0,"size":0.0176944},{"price":11300106.0,"size":0.1275}],"asks":[]}}}
{"schema_version":"collector.vnext.raw","schema_contract":null,"schema_contract_version":null,"payload_contract_version":null,"record_type":"market.orderbook.diff","record_id":"collector_main-market-orderbook-diff-000000000115","collector_id":"collector_main","collector_role":"production","host_name":"MAIN-PC","session_id":"collector_main-sess-20260314T200835Z-09908d0d","stream_session_id":"collector_main-stream-bitflyer-board_ws-20260314T200921Z-c3dda1fe","exchange":"bitflyer","market":"spot","symbol":"BTC_JPY","instrument_id":"bitflyer.spot.BTC_JPY","channel":"board_ws","transport":"websocket","source_event_id":null,"source_sequence":null,"sequence_id":115,"exchange_ts":null,"collector_ts":"2026-03-14T20:09:25Z","ingest_ts":"2026-03-14T20:09:25Z","event_ts":"2026-03-14T20:09:25Z","quality_flags":[],"is_partial":false,"is_reconstructed":false,"confidence_score":1.0,"payload":{"provider":"bitflyer_ws_board","exchange":"bitflyer","transport":"websocket","channel":"lightning_board_BTC_JPY","received_ts":"2026-03-14T20:09:25.031543Z","subscription_id":null,"message_id":null,"source_sequence":null,"raw_message_meta":{"raw_channel":"lightning_board_BTC_JPY","subscription_channel":"lightning_board_BTC_JPY","recv_timeout_sec":10,"ssl_verify":false,"socket_url":"wss://ws.lightstream.bitflyer.com/json-rpc"},"source_payload":{"mid_price":11307456.0,"bids":[{"price":11301237.0,"size":0.1275}],"asks":[]}}}
{"schema_version":"collector.vnext.raw","schema_contract":null,"schema_contract_version":null,"payload_contract_version":null,"record_type":"market.orderbook.diff","record_id":"collector_main-market-orderbook-diff-000000000117","collector_id":"collector_main","collector_role":"production","host_name":"MAIN-PC","session_id":"collector_main-sess-20260314T200835Z-09908d0d","stream_session_id":"collector_main-stream-bitflyer-board_ws-20260314T200921Z-c3dda1fe","exchange":"bitflyer","market":"spot","symbol":"BTC_JPY","instrument_id":"bitflyer.spot.BTC_JPY","channel":"board_ws","transport":"websocket","source_event_id":null,"source_sequence":null,"sequence_id":117,"exchange_ts":null,"collector_ts":"2026-03-14T20:09:25Z","ingest_ts":"2026-03-14T20:09:25Z","event_ts":"2026-03-14T20:09:25Z","quality_flags":[],"is_partial":false,"is_reconstructed":false,"confidence_score":1.0,"payload":{"provider":"bitflyer_ws_board","exchange":"bitflyer","transport":"websocket","channel":"lightning_board_BTC_JPY","received_ts":"2026-03-14T20:09:25.176175Z","subscription_id":null,"message_id":null,"source_sequence":null,"raw_message_meta":{"raw_channel":"lightning_board_BTC_JPY","subscription_channel":"lightning_board_BTC_JPY","recv_timeout_sec":10,"ssl_verify":false,"socket_url":"wss://ws.lightstream.bitflyer.com/json-rpc"},"source_payload":{"mid_price":11307456.0,"bids":[{"price":11301237.0,"size":0.0},{"price":11300106.0,"size":0.0}],"asks":[]}}}
{"schema_version":"collector.vnext.raw","schema_contract":null,"schema_contract_version":null,"payload_contract_version":null,"record_type":"market.orderbook.diff","record_id":"collector_main-market-orderbook-diff-000000000119","collector_id":"collector_main","collector_role":"production","host_name":"MAIN-PC","session_id":"collector_main-sess-20260314T200835Z-09908d0d","stream_session_id":"collector_main-stream-bitflyer-board_ws-20260314T200921Z-c3dda1fe","exchange":"bitflyer","market":"spot","symbol":"BTC_JPY","instrument_id":"bitflyer.spot.BTC_JPY","channel":"board_ws","transport":"websocket","source_event_id":null,"source_sequence":null,"sequence_id":119,"exchange_ts":null,"collector_ts":"2026-03-14T20:09:25Z","ingest_ts":"2026-03-14T20:09:25Z","event_ts":"2026-03-14T20:09:25Z","quality_flags":[],"is_partial":false,"is_reconstructed":false,"confidence_score":1.0,"payload":{"provider":"bitflyer_ws_board","exchange":"bitflyer","transport":"websocket","channel":"lightning_board_BTC_JPY","received_ts":"2026-03-14T20:09:25.313195Z","subscription_id":null,"message_id":null,"source_sequence":null,"raw_message_meta":{"raw_channel":"lightning_board_BTC_JPY","subscription_channel":"lightning_board_BTC_JPY","recv_timeout_sec":10,"ssl_verify":false,"socket_url":"wss://ws.lightstream.bitflyer.com/json-rpc"},"source_payload":{"mid_price":11307456.0,"bids":[{"price":11301837.0,"size":0.0}],"asks":[]}}}
{"schema_version":"collector.vnext.raw","schema_contract":null,"schema_contract_version":null,"payload_contract_version":null,"record_type":"market.orderbook.diff","record_id":"collector_main-market-orderbook-diff-000000000121","collector_id":"collector_main","collector_role":"production","host_name":"MAIN-PC","session_id":"collector_main-sess-20260314T200835Z-09908d0d","stream_session_id":"collector_main-stream-bitflyer-board_ws-20260314T200921Z-c3dda1fe","exchange":"bitflyer","market":"spot","symbol":"BTC_JPY","instrument_id":"bitflyer.spot.BTC_JPY","channel":"board_ws","transport":"websocket","source_event_id":null,"source_sequence":null,"sequence_id":121,"exchange_ts":null,"collector_ts":"2026-03-14T20:09:25Z","ingest_ts":"2026-03-14T20:09:25Z","event_ts":"2026-03-14T20:09:25Z","quality_flags":[],"is_partial":false,"is_reconstructed":false,"confidence_score":1.0,"payload":{"provider":"bitflyer_ws_board","exchange":"bitflyer","transport":"websocket","channel":"lightning_board_BTC_JPY","received_ts":"2026-03-14T20:09:25.439995Z","subscription_id":null,"message_id":null,"source_sequence":null,"raw_message_meta":{"raw_channel":"lightning_board_BTC_JPY","subscription_channel":"lightning_board_BTC_JPY","recv_timeout_sec":10,"ssl_verify":false,"socket_url":"wss://ws.lightstream.bitflyer.com/json-rpc"},"source_payload":{"mid_price":11307456.0,"bids":[{"price":11300106.0,"size":0.1275}],"asks":[]}}}
{"schema_version":"collector.vnext.raw","schema_contract":null,"schema_contract_version":null,"payload_contract_version":null,"record_type":"market.orderbook.snapshot","record_id":"collector_main-market-orderbook-snapshot-000000000123","collector_id":"collector_main","collector_role":"production","host_name":"MAIN-PC","session_id":"collector_main-sess-20260314T200835Z-09908d0d","stream_session_id":"collector_main-stream-bitflyer-board_ws-20260314T200921Z-c3dda1fe","exchange":"bitflyer","market":"spot","symbol":"BTC_JPY","instrument_id":"bitflyer.spot.BTC_JPY","channel":"board_ws","transport":"websocket","source_event_id":null,"source_sequence":null,"sequence_id":123,"exchange_ts":null,"collector_ts":"2026-03-14T20:09:25Z","ingest_ts":"2026-03-14T20:09:25Z","event_ts":"2026-03-14T20:09:25Z","quality_flags":[],"is_partial":false,"is_reconstructed":false,"confidence_score":1.0,"payload":{"provider":"bitflyer_ws_board_snapshot","exchange":"bitflyer","transport":"websocket","channel":"lightning_board_snapshot_BTC_JPY","received_ts":"2026-03-14T20:09:25.695029Z","subscription_id":null,"message_id":null,"source_sequence":null,"raw_message_meta":{"raw_channel":"lightning_board_snapshot_BTC_JPY","subscription_channel":"lightning_board_snapshot_BTC_JPY","recv_timeout_sec":10,"ssl_verify":false,"socket_url":"wss://ws.lightstream.bitflyer.com/json-rpc"},"source_payload":{"mid_price":11307456.0,"bids":[{"price":11305012.0,"size":0.00999866},{"price":11303995.0,"size":0.04568694},{"price":11303994.0,"size":0.015348},{"price":11300798.0,"size":0.015336},{"price":11300796.0,"size":0.01},{"price":11300672.0,"size":0.1275},{"price":11300106.0,"size":0.1275},{"price":11300093.0,"size":0.02},{"price":11299693.0,"size":0.02},{"price":11299692.0,"size":0.0537408},{"price":11299617.0,"size":0.2},{"price":11298963.0,"size":0.02},{"price":11298853.0,"size":0.02},{"price":11298579.0,"size":0.05},{"price":11298513.0,"size":0.05},{"price":11298070.0,"size":0.5},{"price":11297972.0,"size":0.015},{"price":11297887.0,"size":0.0531},{"price":11297439.0,"size":0.5},{"price":11296161.0,"size":2.97384901},{"price":11294412.0,"size":0.00999859},{"price":11293678.0,"size":0.001},{"price":11293270.0,"size":0.0801},{"price":11289443.0,"size":0.04},{"price":11288470.0,"size":0.132},{"price":11287379.0,"size":0.29298039},{"price":11287378.0,"size":1.50015},{"price":11286651.0,"size":0.98403398},{"price":11283122.0,"size":0.002},{"price":11280205.0,"size":0.001},{"price":11279522.0,"size":0.002},{"price":11279282.0,"size":0.0015},{"price":11277748.0,"size":0.0966561},{"price":11277602.0,"size":0.005},{"price":11276130.0,"size":0.002},{"price":11275360.0,"size":1.484},{"price":11275103.0,"size":0.17894886},{"price":11275102.0,"size":0.01},{"price":11275000.0,"size":0.001},{"price":11274588.0,"size":0.0047},{"price":11272738.0,"size":0.002},{"price":11271711.0,"size":0.6},{"price":11271000.0,"size":0.003},{"price":11270000.0,"size":0.106},{"price":11269946.0,"size":0.6},{"price":11269346.0,"size":0.002},{"price":11268871.0,"size":0.281},{"price":11268411.0,"size":0.01},{"price":11266666.0,"size":0.04},{"price":11265954.0,"size":0.002},{"price":11265000.0,"size":0.02},{"price":11263999.0,"size":1.966},{"price":11263000.0,"size":0.006},{"price":11262564.0,"size":0.0015},{"price":11262562.0,"size":0.002},{"price":11260000.0,"size":0.3565},{"price":11259170.0,"size":0.002},{"price":11257537.0,"size":0.001},{"price":11257000.0,"size":0.001},{"price":11255778.0,"size":0.002},{"price":11255200.0,"size":0.001},{"price":11255115.0,"size":0.00377},{"price":11253000.0,"size":0.03189},{"price":11252386.0,"size":0.002},{"price":11251000.0,"size":0.0131},{"price":11250250.0,"size":0.00105},{"price":11250200.0,"size":0.001},{"price":11250100.0,"size":0.015},{"price":11250005.0,"size":0.001},{"price":11250001.0,"size":0.00104},{"price":11250000.0,"size":0.76834},{"price":11248994.0,"size":0.002},{"price":11246544.0,"size":0.0015},{"price":11246203.0,"size":0.001},{"price":11245141.0,"size":0.0031},{"price":11245000.0,"size":0.05},{"price":11244444.0,"size":0.04},{"price":11244243.0,"size":0.01},{"price":11240200.0,"size":0.001},{"price":11240000.0,"size":0.007304},{"price":11236190.0,"size":0.01},{"price":11235200.0,"size":0.001},{"price":11234869.0,"size":0.001},{"price":11233345.0,"size":2.036},{"price":11232000.0,"size":0.089},{"price":11231243.0,"size":0.01},{"price":11231000.0,"size":0.105},{"price":11230200.0,"size":0.001},{"price":11230000.0,"size":0.0308},{"price":11228423.0,"size":1.951},{"price":11224500.0,"size":0.06},{"price":11224355.0,"size":0.0015},{"price":11223968.0,"size":0.001},{"price":11223535.0,"size":0.001},{"price":11223344.0,"size":0.01},{"price":11223000.0,"size":0.1},{"price":11222222.0,"size":0.092525},{"price":11221459.0,"size":0.1393},{"price":11221120.0,"size":0.011},{"price":11220200.0,"size":0.001},{"price":11220001.0,"size":0.004457},{"price":11220000.0,"size":0.321},{"price":11219595.0,"size":1.79},{"price":11219517.0,"size":0.01},{"price":11219000.0,"size":0.1},{"price":11215200.0,"size":0.001},{"price":11215000.0,"size":0.02},{"price":11212358.0,"size":1.2},{"price":11212201.0,"size":0.001},{"price":11211800.0,"size":0.001},{"price":11211111.0,"size":0.06},{"price":11210200.0,"size":0.001},{"price":11210000.0,"size":0.10622},{"price":11208032.0,"size":0.01},{"price":11207755.0,"size":0.0015},{"price":11206000.0,"size":0.09015},{"price":11205200.0,"size":0.001},{"price":11204578.0,"size":0.002},{"price":11203931.0,"size":1.0},{"price":11201000.0,"size":0.01},{"price":11200867.0,"size":0.001},{"price":11200800.0,"size":0.05},{"price":11200425.0,"size":0.1},{"price":11200200.0,"size":0.001},{"price":11200198.0,"size":0.003},{"price":11200150.0,"size":0.002},{"price":11200002.0,"size":0.001},{"price":11200001.0,"size":0.01104},{"price":11200000.0,"size":1.35988728},{"price":11198508.0,"size":0.05},{"price":11198243.0,"size":0.01},{"price":11197134.0,"size":2.0},{"price":11197000.0,"size":0.0085},{"price":11195692.0,"size":0.0015},{"price":11194090.0,"size":0.03},{"price":11190770.0,"size":0.0309},{"price":11190000.0,"size":0.0010016},{"price":11189555.0,"size":0.5},{"price":11189533.0,"size":0.001},{"price":11188629.0,"size":0.01},{"price":11188382.0,"size":0.001},{"price":11185000.0,"size":0.0085},{"price":11180043.0,"size":0.972},{"price":11180000.0,"size":0.23215},{"price":11178973.0,"size":0.0015},{"price":11178199.0,"size":0.001},{"price":11170000.0,"size":0.001},{"price":11169662.0,"size":0.01},{"price":11169593.0,"size":0.001},{"price":11169243.0,"size":0.01},{"price":11166865.0,"size":0.001},{"price":11164029.0,"size":0.001},{"price":11160854.0,"size":0.1},{"price":11160000.0,"size":0.02376},{"price":11156269.0,"size":0.01},{"price":11155531.0,"size":0.001},{"price":11155377.0,"size":0.00636009},{"price":11153999.0,"size":0.00101},{"price":11150250.0,"size":0.00175},{"price":11150005.0,"size":0.001},{"price":11150001.0,"size":0.00104},{"price":11150000.0,"size":0.6398956},{"price":11148000.0,"size":0.08963},{"price":11144197.0,"size":0.001},{"price":11144000.0,"size":0.0897},{"price":11140000.0,"size":0.2},{"price":11136243.0,"size":0.01},{"price":11135869.0,"size":0.1},{"price":11130000.0,"size":0.116},{"price":11129979.0,"size":0.0053908},{"price":11126388.0,"size":0.02},{"price":11124900.0,"size":0.00133},{"price":11121090.0,"size":0.1},{"price":11120000.0,"size":0.0033},{"price":11118078.0,"size":0.01},{"price":11111800.0,"size":0.001},{"price":11111111.0,"size":0.2919257},{"price":11111000.0,"size":0.003},{"price":11110594.0,"size":0.001},{"price":11110000.0,"size":0.056937},{"price":11109662.0,"size":0.01},{"price":11108008.0,"size":0.01},{"price":11106000.0,"size":0.2},{"price":11105000.0,"size":0.02},{"price":11101297.0,"size":0.001},{"price":11100005.0,"size":0.001},{"price":11100001.0,"size":0.01104},{"price":11100000.0,"size":2.7475049},{"price":11099141.0,"size":0.01},{"price":11096243.0,"size":0.01},{"price":11094090.0,"size":0.01},{"price":11088888.0,"size":0.001},{"price":11085245.0,"size":0.001},{"price":11080200.0,"size":0.001},{"price":11080000.0,"size":0.0223},{"price":11075100.0,"size":0.003},{"price":11071558.0,"size":1.0},{"price":11070200.0,"size":0.001},{"price":11070000.0,"size":0.0902},{"price":11065200.0,"size":0.001},{"price":11064370.0,"size":0.00497091},{"price":11060200.0,"size":0.001},{"price":11060000.0,"size":0.145},{"price":11059689.0,"size":0.009},{"price":11056428.0,"size":0.002},{"price":11055500.0,"size":0.02},{"price":11055200.0,"size":0.001},{"price":11055100.0,"size":0.003},{"price":11050200.0,"size":0.001},{"price":11050005.0,"size":0.001},{"price":11050002.0,"size":0.001},{"price":11050001.0,"size":0.00104},{"price":11050000.0,"size":0.43176147},{"price":11046420.0,"size":0.2},{"price":11044243.0,"size":0.01},{"price":11041380.0,"size":0.01},{"price":11040200.0,"size":0.001},{"price":11040000.0,"size":0.00777181},{"price":11035865.0,"size":0.1},{"price":11035200.0,"size":0.001},{"price":11035000.0,"size":0.0013},{"price":11030200.0,"size":0.001},{"price":11030000.0,"size":0.025},{"price":11025500.0,"size":0.009531},{"price":11025200.0,"size":0.001},{"price":11025000.0,"size":0.71497},{"price":11020772.0,"size":0.014},{"price":11020200.0,"size":0.002},{"price":11020000.0,"size":0.005},{"price":11015200.0,"size":0.001},{"price":11012000.0,"size":0.1},{"price":11011800.0,"size":0.001},{"price":11010200.0,"size":0.001},{"price":11010000.0,"size":0.347},{"price":11007277.0,"size":0.01},{"price":11006000.0,"size":0.2},{"price":11005200.0,"size":0.001},{"price":11004890.0,"size":0.001535},{"price":11003000.0,"size":0.0155},{"price":11001000.0,"size":0.013},{"price":11000500.0,"size":0.05117658},{"price":11000200.0,"size":0.001},{"price":11000002.0,"size":0.004},{"price":11000001.0,"size":0.02604},{"price":11000000.0,"size":5.47323365},{"price":10999999.0,"size":0.003},{"price":10999000.0,"size":0.001},{"price":10996855.0,"size":0.0011},{"price":10995200.0,"size":0.001},{"price":10994499.0,"size":0.00169176},{"price":10990200.0,"size":0.001},{"price":10990000.0,"size":0.10219},{"price":10989001.0,"size":0.00197},{"price":10988999.0,"size":0.001},{"price":10988324.0,"size":0.002},{"price":10987654.0,"size":0.001},{"price":10985200.0,"size":0.001},{"price":10985150.0,"size":0.01},{"price":10980500.0,"size":0.005},{"price":10980200.0,"size":0.001},{"price":10980002.0,"size":0.4},{"price":10980000.0,"size":0.028},{"price":10975200.0,"size":0.001},{"price":10975000.0,"size":0.1},{"price":10971261.0,"size":0.001},{"price":10971243.0,"size":0.01},{"price":10970375.0,"size":1.9},{"price":10970200.0,"size":0.001},{"price":10970000.0,"size":0.09304},{"price":10966600.0,"size":0.001003},{"price":10965200.0,"size":0.001},{"price":10960200.0,"size":0.001},{"price":10960000.0,"size":0.0083},{"price":10956673.0,"size":0.01},{"price":10955200.0,"size":0.001},{"price":10954950.0,"size":0.001},{"price":10950500.0,"size":0.005},{"price":10950001.0,"size":0.00204},{"price":10950000.0,"size":0.5485028},{"price":10949550.0,"size":0.01870657},{"price":10949172.0,"size":0.1},{"price":10948000.0,"size":0.1},{"price":10945243.0,"size":0.01},{"price":10940402.0,"size":0.001},{"price":10940200.0,"size":0.001},{"price":10940000.0,"size":0.331},{"price":10938243.0,"size":0.01},{"price":10936200.0,"size":0.00137},{"price":10935200.0,"size":0.001},{"price":10930200.0,"size":0.002},{"price":10930000.0,"size":0.0193},{"price":10925200.0,"size":0.002},{"price":10924451.0,"size":0.0012},{"price":10920509.0,"size":0.01},{"price":10920200.0,"size":0.002},{"price":10920000.0,"size":0.52},{"price":10915200.0,"size":0.001},{"price":10914000.0,"size":0.005},{"price":10911800.0,"size":0.001},{"price":10910500.0,"size":0.005}],"asks":[{"price":11309901.0,"size":0.1251},{"price":11310266.0,"size":0.02},{"price":11310267.0,"size":0.005},{"price":11311293.0,"size":0.02},{"price":11311294.0,"size":0.00999365},{"price":11311681.0,"size":0.015492},{"price":11312048.0,"size":0.01506},{"price":11312719.0,"size":0.02},{"price":11312720.0,"size":0.4199},{"price":11313658.0,"size":0.01},{"price":11313957.0,"size":0.014772},{"price":11316655.0,"size":0.0537408},{"price":11318050.0,"size":0.002},{"price":11318640.0,"size":0.01},{"price":11318848.0,"size":0.30637708},{"price":11318849.0,"size":0.053},{"price":11320000.0,"size":0.02},{"price":11321120.0,"size":0.2},{"price":11321159.0,"size":0.57609457},{"price":11322000.0,"size":0.005},{"price":11323555.0,"size":0.3429732},{"price":11323556.0,"size":1.189881},{"price":11323581.0,"size":1.189881},{"price":11325160.0,"size":0.0059893},{"price":11328050.0,"size":0.002},{"price":11329436.0,"size":0.0015},{"price":11331059.0,"size":0.001},{"price":11334236.0,"size":0.33650097},{"price":11334237.0,"size":1.489},{"price":11335742.0,"size":1.928},{"price":11340000.0,"size":0.13586406},{"price":11340647.0,"size":0.001},{"price":11342956.0,"size":1.60199848},{"price":11342957.0,"size":0.01},{"price":11346154.0,"size":0.0015},{"price":11348000.0,"size":0.1999},{"price":11349700.0,"size":0.001},{"price":11350000.0,"size":0.022},{"price":11353877.0,"size":0.001},{"price":11354939.0,"size":0.01},{"price":11355555.0,"size":0.001},{"price":11358323.0,"size":2.018},{"price":11359242.0,"size":0.0011},{"price":11359700.0,"size":0.001},{"price":11362692.0,"size":0.0015},{"price":11365211.0,"size":0.001},{"price":11369700.0,"size":0.001},{"price":11370000.0,"size":0.1},{"price":11372478.0,"size":1.943},{"price":11376000.0,"size":0.02},{"price":11376545.0,"size":0.001},{"price":11377000.0,"size":0.2287},{"price":11377269.0,"size":0.002},{"price":11379700.0,"size":0.001},{"price":11379865.0,"size":0.03},{"price":11380000.0,"size":0.0223},{"price":11380324.0,"size":0.002},{"price":11381766.0,"size":0.4},{"price":11382386.0,"size":0.0015},{"price":11385000.0,"size":0.2548},{"price":11385403.0,"size":0.002},{"price":11385664.0,"size":0.002},{"price":11387072.0,"size":0.01},{"price":11387354.0,"size":0.002},{"price":11387879.0,"size":0.001},{"price":11388885.0,"size":0.03},{"price":11389700.0,"size":0.001},{"price":11390000.0,"size":0.2488},{"price":11390050.0,"size":0.001},{"price":11392387.0,"size":1.0},{"price":11394939.0,"size":0.01},{"price":11395000.0,"size":0.06},{"price":11395775.0,"size":0.01},{"price":11396555.0,"size":0.03},{"price":11398444.0,"size":0.001995},{"price":11399213.0,"size":0.001},{"price":11399673.0,"size":0.0015},{"price":11399700.0,"size":0.001},{"price":11400000.0,"size":0.5525},{"price":11405000.0,"size":0.0275},{"price":11406336.0,"size":1.0},{"price":11408700.0,"size":0.001},{"price":11409415.0,"size":0.055},{"price":11410000.0,"size":0.03},{"price":11410547.0,"size":0.001},{"price":11410853.0,"size":0.002},{"price":11412000.0,"size":0.0878},{"price":11415000.0,"size":0.002},{"price":11415141.0,"size":0.0041},{"price":11417481.0,"size":0.0015},{"price":11418700.0,"size":0.001},{"price":11420000.0,"size":0.401},{"price":11421268.0,"size":0.05},{"price":11421881.0,"size":0.001},{"price":11423339.0,"size":2.0},{"price":11424296.0,"size":0.002},{"price":11424941.0,"size":0.972},{"price":11425000.0,"size":0.049},{"price":11426426.0,"size":0.002},{"price":11428121.0,"size":0.002},{"price":11428700.0,"size":0.001},{"price":11429302.0,"size":0.01},{"price":11432718.0,"size":0.002},{"price":11433211.0,"size":0.03},{"price":11433215.0,"size":0.001},{"price":11433333.0,"size":0.001},{"price":11437315.0,"size":0.002},{"price":11438525.0,"size":0.0011},{"price":11438700.0,"size":0.001},{"price":11439557.0,"size":0.001},{"price":11440000.0,"size":0.1038},{"price":11441911.0,"size":0.002},{"price":11443629.0,"size":0.002},{"price":11444549.0,"size":0.001},{"price":11446508.0,"size":0.001},{"price":11447000.0,"size":0.01},{"price":11447071.0,"size":0.002},{"price":11448000.0,"size":0.0875},{"price":11448700.0,"size":0.001},{"price":11450000.0,"size":0.258},{"price":11451105.0,"size":0.002},{"price":11453321.0,"size":0.03},{"price":11455702.0,"size":0.002},{"price":11455883.0,"size":0.001},{"price":11458700.0,"size":0.001},{"price":11458988.0,"size":0.01},{"price":11460000.0,"size":0.01702},{"price":11460299.0,"size":0.002},{"price":11464896.0,"size":0.002},{"price":11467217.0,"size":0.001},{"price":11468700.0,"size":0.001},{"price":11470000.0,"size":0.01},{"price":11471000.0,"size":0.01},{"price":11475000.0,"size":0.0028},{"price":11478431.0,"size":0.002},{"price":11478551.0,"size":0.001},{"price":11478700.0,"size":0.001},{"price":11480000.0,"size":0.12491},{"price":11485000.0,"size":0.01},{"price":11486555.0,"size":0.03},{"price":11487685.0,"size":0.01},{"price":11488000.0,"size":0.102},{"price":11488700.0,"size":0.001},{"price":11489885.0,"size":0.001},{"price":11490841.0,"size":0.002},{"price":11495450.0,"size":0.002},{"price":11495850.0,"size":0.001},{"price":11498700.0,"size":0.001},{"price":11498917.0,"size":0.002},{"price":11499000.0,"size":0.01},{"price":11500000.0,"size":0.46859519},{"price":11501219.0,"size":0.001},{"price":11502377.0,"size":0.002},{"price":11502800.0,"size":0.00132},{"price":11503108.0,"size":0.0198},{"price":11505000.0,"size":0.0028},{"price":11505001.0,"size":0.002},{"price":11505836.0,"size":0.003},{"price":11508431.0,"size":0.047},{"price":11508700.0,"size":0.001},{"price":11508888.0,"size":0.02},{"price":11510000.0,"size":0.0976},{"price":11512553.0,"size":0.001},{"price":11513633.0,"size":0.08},{"price":11514332.0,"size":0.02},{"price":11518700.0,"size":0.001},{"price":11518992.0,"size":0.002},{"price":11519855.0,"size":0.01},{"price":11520000.0,"size":0.001},{"price":11522423.0,"size":0.97},{"price":11523211.0,"size":0.01},{"price":11523887.0,"size":0.001},{"price":11524999.0,"size":0.001},{"price":11528700.0,"size":0.001},{"price":11529852.0,"size":0.01},{"price":11530000.0,"size":0.261},{"price":11533985.0,"size":0.002},{"price":11534084.0,"size":0.001},{"price":11535321.0,"size":0.01},{"price":11538666.0,"size":0.002},{"price":11538700.0,"size":0.001},{"price":11540000.0,"size":0.0048},{"price":11540357.0,"size":0.002},{"price":11541011.0,"size":0.005},{"price":11541109.0,"size":0.01},{"price":11544663.0,"size":0.002},{"price":11545262.0,"size":0.002},{"price":11546541.0,"size":0.01},{"price":11548144.0,"size":0.002},{"price":11548700.0,"size":0.001},{"price":11550000.0,"size":0.014},{"price":11551109.0,"size":0.01},{"price":11551625.0,"size":0.002},{"price":11552111.0,"size":0.01},{"price":11553687.0,"size":0.1},{"price":11555106.0,"size":0.002},{"price":11555115.0,"size":0.001},{"price":11556000.0,"size":0.1},{"price":11558587.0,"size":0.002},{"price":11558700.0,"size":0.001},{"price":11559855.0,"size":0.01},{"price":11560831.0,"size":0.0198},{"price":11561109.0,"size":0.01},{"price":11562000.0,"size":0.087},{"price":11562068.0,"size":0.002},{"price":11565548.0,"size":0.002},{"price":11566139.0,"size":0.0228},{"price":11566551.0,"size":0.01},{"price":11568700.0,"size":0.001},{"price":11569029.0,"size":0.002},{"price":11570196.0,"size":0.002},{"price":11571109.0,"size":0.01},{"price":11572510.0,"size":0.002},{"price":11573211.0,"size":0.01},{"price":11574840.0,"size":0.002},{"price":11575991.0,"size":0.001},{"price":11578700.0,"size":0.001},{"price":11579484.0,"size":0.002},{"price":11579851.0,"size":0.01},{"price":11580000.0,"size":0.7735},{"price":11581109.0,"size":0.01},{"price":11584128.0,"size":0.002},{"price":11585000.0,"size":0.002},{"price":11586532.0,"size":0.01},{"price":11587498.0,"size":0.0198},{"price":11588700.0,"size":0.001},{"price":11589612.0,"size":0.012},{"price":11590000.0,"size":0.1},{"price":11590749.0,"size":0.002},{"price":11591109.0,"size":0.01},{"price":11593211.0,"size":0.01},{"price":11596753.0,"size":0.002},{"price":11598555.0,"size":0.01},{"price":11598700.0,"size":0.001},{"price":11599999.0,"size":0.001},{"price":11600000.0,"size":3.6141},{"price":11601109.0,"size":0.02},{"price":11606655.0,"size":0.01},{"price":11610000.0,"size":0.302},{"price":11611109.0,"size":0.01},{"price":11613321.0,"size":0.01},{"price":11620000.0,"size":1.35441682},{"price":11621011.0,"size":0.01},{"price":11621109.0,"size":0.01},{"price":11623096.0,"size":0.008},{"price":11629000.0,"size":0.1},{"price":11630000.0,"size":0.201},{"price":11631059.0,"size":0.01},{"price":11631479.0,"size":0.01},{"price":11631773.0,"size":0.00386871},{"price":11635950.0,"size":0.001},{"price":11638259.0,"size":0.001},{"price":11639700.0,"size":0.001},{"price":11640000.0,"size":1.0},{"price":11640820.0,"size":0.01},{"price":11641651.0,"size":2.0},{"price":11645295.0,"size":0.05},{"price":11647158.0,"size":0.05},{"price":11649900.0,"size":0.02906},{"price":11649999.0,"size":0.001},{"price":11650000.0,"size":0.593},{"price":11651059.0,"size":0.01},{"price":11653658.0,"size":0.008},{"price":11654321.0,"size":0.001},{"price":11659700.0,"size":0.001},{"price":11661479.0,"size":0.01},{"price":11666000.0,"size":0.001},{"price":11666666.0,"size":0.013},{"price":11669700.0,"size":0.001},{"price":11671059.0,"size":0.01},{"price":11672562.0,"size":0.0198},{"price":11679224.0,"size":0.012},{"price":11680000.0,"size":0.004},{"price":11685000.0,"size":0.003},{"price":11688000.0,"size":0.001},{"price":11689732.0,"size":0.01},{"price":11690330.0,"size":0.0198},{"price":11691059.0,"size":0.01},{"price":11692558.0,"size":0.01},{"price":11698800.0,"size":0.00131},{"price":11699000.0,"size":0.001},{"price":11699631.0,"size":0.001},{"price":11699998.0,"size":0.01},{"price":11699999.0,"size":0.001},{"price":11700000.0,"size":1.03762841},{"price":11701059.0,"size":0.01},{"price":11720000.0,"size":0.1},{"price":11721059.0,"size":0.01},{"price":11725000.0,"size":0.005},{"price":11726791.0,"size":0.01},{"price":11730000.0,"size":0.9382},{"price":11740000.0,"size":0.101},{"price":11741059.0,"size":0.01},{"price":11745417.0,"size":2.0},{"price":11748937.0,"size":0.001},{"price":11749999.0,"size":0.001},{"price":11750000.0,"size":0.90537866},{"price":11750050.0,"size":0.2},{"price":11751151.0,"size":0.01},{"price":11755000.0,"size":0.001}]}}}
{"schema_version":"collector.vnext.raw","schema_contract":null,"schema_contract_version":null,"payload_contract_version":null,"record_type":"market.orderbook.diff","record_id":"collector_main-market-orderbook-diff-000000000061","collector_id":"collector_main","collector_role":"production","host_name":"MAIN-PC","session_id":"collector_main-sess-20260314T200940Z-3f6b5158","stream_session_id":"collector_main-stream-bitflyer-board_ws-20260314T201056Z-e40b261b","exchange":"bitflyer","market":"spot","symbol":"BTC_JPY","instrument_id":"bitflyer.spot.BTC_JPY","channel":"board_ws","transport":"websocket","source_event_id":null,"source_sequence":null,"sequence_id":61,"exchange_ts":null,"collector_ts":"2026-03-14T20:10:56Z","ingest_ts":"2026-03-14T20:10:56Z","event_ts":"2026-03-14T20:10:56Z","quality_flags":[],"is_partial":false,"is_reconstructed":false,"confidence_score":1.0,"payload":{"provider":"bitflyer_ws_board","exchange":"bitflyer","transport":"websocket","channel":"lightning_board_BTC_JPY","received_ts":"2026-03-14T20:10:56.763429Z","subscription_id":null,"message_id":null,"source_sequence":null,"raw_message_meta":{"raw_channel":"lightning_board_BTC_JPY","subscription_channel":"lightning_board_BTC_JPY","recv_timeout_sec":10,"ssl_verify":false,"socket_url":"wss://ws.lightstream.bitflyer.com/json-rpc"},"source_payload":{"mid_price":11306309.0,"bids":[{"price":11301107.0,"size":0.0},{"price":11301673.0,"size":0.0}],"asks":[{"price":11490841.0,"size":0.002},{"price":11310267.0,"size":0.0}]}}}
{"schema_version":"collector.vnext.raw","schema_contract":null,"schema_contract_version":null,"payload_contract_version":null,"record_type":"market.orderbook.diff","record_id":"collector_main-market-orderbook-diff-000000000065","collector_id":"collector_main","collector_role":"production","host_name":"MAIN-PC","session_id":"collector_main-sess-20260314T200940Z-3f6b5158","stream_session_id":"collector_main-stream-bitflyer-board_ws-20260314T201056Z-e40b261b","exchange":"bitflyer","market":"spot","symbol":"BTC_JPY","instrument_id":"bitflyer.spot.BTC_JPY","channel":"board_ws","transport":"websocket","source_event_id":null,"source_sequence":null,"sequence_id":65,"exchange_ts":null,"collector_ts":"2026-03-14T20:10:56Z","ingest_ts":"2026-03-14T20:10:56Z","event_ts":"2026-03-14T20:10:56Z","quality_flags":[],"is_partial":false,"is_reconstructed":false,"confidence_score":1.0,"payload":{"provider":"bitflyer_ws_board","exchange":"bitflyer","transport":"websocket","channel":"lightning_board_BTC_JPY","received_ts":"2026-03-14T20:10:56.877151Z","subscription_id":null,"message_id":null,"source_sequence":null,"raw_message_meta":{"raw_channel":"lightning_board_BTC_JPY","subscription_channel":"lightning_board_BTC_JPY","recv_timeout_sec":10,"ssl_verify":false,"socket_url":"wss://ws.lightstream.bitflyer.com/json-rpc"},"source_payload":{"mid_price":11305447.0,"bids":[{"price":11304368.0,"size":0.0},{"price":11302645.0,"size":0.05831321}],"asks":[{"price":11320996.0,"size":0.0},{"price":11320997.0,"size":0.2}]}}}
{"schema_version":"collector.vnext.raw","schema_contract":null,"schema_contract_version":null,"payload_contract_version":null,"record_type":"market.orderbook.diff","record_id":"collector_main-market-orderbook-diff-000000000067","collector_id":"collector_main","collector_role":"production","host_name":"MAIN-PC","session_id":"collector_main-sess-20260314T200940Z-3f6b5158","stream_session_id":"collector_main-stream-bitflyer-board_ws-20260314T201056Z-e40b261b","exchange":"bitflyer","market":"spot","symbol":"BTC_JPY","instrument_id":"bitflyer.spot.BTC_JPY","channel":"board_ws","transport":"websocket","source_event_id":null,"source_sequence":null,"sequence_id":67,"exchange_ts":null,"collector_ts":"2026-03-14T20:10:57Z","ingest_ts":"2026-03-14T20:10:57Z","event_ts":"2026-03-14T20:10:57Z","quality_flags":[],"is_partial":false,"is_reconstructed":false,"confidence_score":1.0,"payload":{"provider":"bitflyer_ws_board","exchange":"bitflyer","transport":"websocket","channel":"lightning_board_BTC_JPY","received_ts":"2026-03-14T20:10:57.017611Z","subscription_id":null,"message_id":null,"source_sequence":null,"raw_message_meta":{"raw_channel":"lightning_board_BTC_JPY","subscription_channel":"lightning_board_BTC_JPY","recv_timeout_sec":10,"ssl_verify":false,"socket_url":"wss://ws.lightstream.bitflyer.com/json-rpc"},"source_payload":{"mid_price":11306011.0,"bids":[{"price":11303772.0,"size":0.00999866},{"price":11302645.0,"size":0.0},{"price":11301708.0,"size":0.0},{"price":11304369.0,"size":0.0},{"price":11302644.0,"size":0.0},{"price":11302322.0,"size":0.0}],"asks":[{"price":11325036.0,"size":0.0},{"price":11325037.0,"size":0.0111226}]}}}
{"schema_version":"collector.vnext.raw","schema_contract":null,"schema_contract_version":null,"payload_contract_version":null,"record_type":"market.orderbook.diff","record_id":"collector_main-market-orderbook-diff-000000000069","collector_id":"collector_main","collector_role":"production","host_name":"MAIN-PC","session_id":"collector_main-sess-20260314T200940Z-3f6b5158","stream_session_id":"collector_main-stream-bitflyer-board_ws-20260314T201056Z-e40b261b","exchange":"bitflyer","market":"spot","symbol":"BTC_JPY","instrument_id":"bitflyer.spot.BTC_JPY","channel":"board_ws","transport":"websocket","source_event_id":null,"source_sequence":null,"sequence_id":69,"exchange_ts":null,"collector_ts":"2026-03-14T20:10:57Z","ingest_ts":"2026-03-14T20:10:57Z","event_ts":"2026-03-14T20:10:57Z","quality_flags":[],"is_partial":false,"is_reconstructed":false,"confidence_score":1.0,"payload":{"provider":"bitflyer_ws_board","exchange":"bitflyer","transport":"websocket","channel":"lightning_board_BTC_JPY","received_ts":"2026-03-14T20:10:57.127662Z","subscription_id":null,"message_id":null,"source_sequence":null,"raw_message_meta":{"raw_channel":"lightning_board_BTC_JPY","subscription_channel":"lightning_board_BTC_JPY","recv_timeout_sec":10,"ssl_verify":false,"socket_url":"wss://ws.lightstream.bitflyer.com/json-rpc"},"source_payload":{"mid_price":11306011.0,"bids":[{"price":11302646.0,"size":0.0569246}],"asks":[]}}}
{"schema_version":"collector.vnext.raw","schema_contract":null,"schema_contract_version":null,"payload_contract_version":null,"record_type":"market.orderbook.diff","record_id":"collector_main-market-orderbook-diff-000000000071","collector_id":"collector_main","collector_role":"production","host_name":"MAIN-PC","session_id":"collector_main-sess-20260314T200940Z-3f6b5158","stream_session_id":"collector_main-stream-bitflyer-board_ws-20260314T201056Z-e40b261b","exchange":"bitflyer","market":"spot","symbol":"BTC_JPY","instrument_id":"bitflyer.spot.BTC_JPY","channel":"board_ws","transport":"websocket","source_event_id":null,"source_sequence":null,"sequence_id":71,"exchange_ts":null,"collector_ts":"2026-03-14T20:10:57Z","ingest_ts":"2026-03-14T20:10:57Z","event_ts":"2026-03-14T20:10:57Z","quality_flags":[],"is_partial":false,"is_reconstructed":false,"confidence_score":1.0,"payload":{"provider":"bitflyer_ws_board","exchange":"bitflyer","transport":"websocket","channel":"lightning_board_BTC_JPY","received_ts":"2026-03-14T20:10:57.239817Z","subscription_id":null,"message_id":null,"source_sequence":null,"raw_message_meta":{"raw_channel":"lightning_board_BTC_JPY","subscription_channel":"lightning_board_BTC_JPY","recv_timeout_sec":10,"ssl_verify":false,"socket_url":"wss://ws.lightstream.bitflyer.com/json-rpc"},"source_payload":{"mid_price":11306011.0,"bids":[{"price":11301928.0,"size":0.015108},{"price":11302646.0,"size":0.0},{"price":11302336.0,"size":0.015132},{"price":11303773.0,"size":0.04590183}],"asks":[]}}}
{"schema_version":"collector.vnext.raw","schema_contract":null,"schema_contract_version":null,"payload_contract_version":null,"record_type":"market.orderbook.diff","record_id":"collector_main-market-orderbook-diff-000000000073","collector_id":"collector_main","collector_role":"production","host_name":"MAIN-PC","session_id":"collector_main-sess-20260314T200940Z-3f6b5158","stream_session_id":"collector_main-stream-bitflyer-board_ws-20260314T201056Z-e40b261b","exchange":"bitflyer","market":"spot","symbol":"BTC_JPY","instrument_id":"bitflyer.spot.BTC_JPY","channel":"board_ws","transport":"websocket","source_event_id":null,"source_sequence":null,"sequence_id":73,"exchange_ts":null,"collector_ts":"2026-03-14T20:10:57Z","ingest_ts":"2026-03-14T20:10:57Z","event_ts":"2026-03-14T20:10:57Z","quality_flags":[],"is_partial":false,"is_reconstructed":false,"confidence_score":1.0,"payload":{"provider":"bitflyer_ws_board","exchange":"bitflyer","transport":"websocket","channel":"lightning_board_BTC_JPY","received_ts":"2026-03-14T20:10:57.344692Z","subscription_id":null,"message_id":null,"source_sequence":null,"raw_message_meta":{"raw_channel":"lightning_board_BTC_JPY","subscription_channel":"lightning_board_BTC_JPY","recv_timeout_sec":10,"ssl_verify":false,"socket_url":"wss://ws.lightstream.bitflyer.com/json-rpc"},"source_payload":{"mid_price":11306011.0,"bids":[{"price":11300172.0,"size":0.0},{"price":11300892.0,"size":0.0176959},{"price":11300226.0,"size":0.005}],"asks":[]}}}
{"schema_version":"collector.vnext.raw","schema_contract":null,"schema_contract_version":null,"payload_contract_version":null,"record_type":"market.orderbook.diff","record_id":"collector_main-market-orderbook-diff-000000000075","collector_id":"collector_main","collector_role":"production","host_name":"MAIN-PC","session_id":"collector_main-sess-20260314T200940Z-3f6b5158","stream_session_id":"collector_main-stream-bitflyer-board_ws-20260314T201056Z-e40b261b","exchange":"bitflyer","market":"spot","symbol":"BTC_JPY","instrument_id":"bitflyer.spot.BTC_JPY","channel":"board_ws","transport":"websocket","source_event_id":null,"source_sequence":null,"sequence_id":75,"exchange_ts":null,"collector_ts":"2026-03-14T20:10:57Z","ingest_ts":"2026-03-14T20:10:57Z","event_ts":"2026-03-14T20:10:57Z","quality_flags":[],"is_partial":false,"is_reconstructed":false,"confidence_score":1.0,"payload":{"provider":"bitflyer_ws_board","exchange":"bitflyer","transport":"websocket","channel":"lightning_board_BTC_JPY","received_ts":"2026-03-14T20:10:57.461480Z","subscription_id":null,"message_id":null,"source_sequence":null,"raw_message_meta":{"raw_channel":"lightning_board_BTC_JPY","subscription_channel":"lightning_board_BTC_JPY","recv_timeout_sec":10,"ssl_verify":false,"socket_url":"wss://ws.lightstream.bitflyer.com/json-rpc"},"source_payload":{"mid_price":11306011.0,"bids":[{"price":11294233.0,"size":0.0},{"price":11294287.0,"size":0.001}],"asks":[]}}}
{"schema_version":"collector.vnext.raw","schema_contract":null,"schema_contract_version":null,"payload_contract_version":null,"record_type":"market.orderbook.diff","record_id":"collector_main-market-orderbook-diff-000000000077","collector_id":"collector_main","collector_role":"production","host_name":"MAIN-PC","session_id":"collector_main-sess-20260314T200940Z-3f6b5158","stream_session_id":"collector_main-stream-bitflyer-board_ws-20260314T201056Z-e40b261b","exchange":"bitflyer","market":"spot","symbol":"BTC_JPY","instrument_id":"bitflyer.spot.BTC_JPY","channel":"board_ws","transport":"websocket","source_event_id":null,"source_sequence":null,"sequence_id":77,"exchange_ts":null,"collector_ts":"2026-03-14T20:10:57Z","ingest_ts":"2026-03-14T20:10:57Z","event_ts":"2026-03-14T20:10:57Z","quality_flags":[],"is_partial":false,"is_reconstructed":false,"confidence_score":1.0,"payload":{"provider":"bitflyer_ws_board","exchange":"bitflyer","transport":"websocket","channel":"lightning_board_BTC_JPY","received_ts":"2026-03-14T20:10:57.565500Z","subscription_id":null,"message_id":null,"source_sequence":null,"raw_message_meta":{"raw_channel":"lightning_board_BTC_JPY","subscription_channel":"lightning_board_BTC_JPY","recv_timeout_sec":10,"ssl_verify":false,"socket_url":"wss://ws.lightstream.bitflyer.com/json-rpc"},"source_payload":{"mid_price":11306011.0,"bids":[],"asks":[{"price":11308930.0,"size":0.02},{"price":11309329.0,"size":0.02}]}}}
{"schema_version":"collector.vnext.raw","schema_contract":null,"schema_contract_version":null,"payload_contract_version":null,"record_type":"market.orderbook.diff","record_id":"collector_main-market-orderbook-diff-000000000079","collector_id":"collector_main","collector_role":"production","host_name":"MAIN-PC","session_id":"collector_main-sess-20260314T200940Z-3f6b5158","stream_session_id":"collector_main-stream-bitflyer-board_ws-20260314T201056Z-e40b261b","exchange":"bitflyer","market":"spot","symbol":"BTC_JPY","instrument_id":"bitflyer.spot.BTC_JPY","channel":"board_ws","transport":"websocket","source_event_id":null,"source_sequence":null,"sequence_id":79,"exchange_ts":null,"collector_ts":"2026-03-14T20:10:57Z","ingest_ts":"2026-03-14T20:10:57Z","event_ts":"2026-03-14T20:10:57Z","quality_flags":[],"is_partial":false,"is_reconstructed":false,"confidence_score":1.0,"payload":{"provider":"bitflyer_ws_board","exchange":"bitflyer","transport":"websocket","channel":"lightning_board_BTC_JPY","received_ts":"2026-03-14T20:10:57.699718Z","subscription_id":null,"message_id":null,"source_sequence":null,"raw_message_meta":{"raw_channel":"lightning_board_BTC_JPY","subscription_channel":"lightning_board_BTC_JPY","recv_timeout_sec":10,"ssl_verify":false,"socket_url":"wss://ws.lightstream.bitflyer.com/json-rpc"},"source_payload":{"mid_price":11306011.0,"bids":[],"asks":[{"price":11308865.0,"size":0.02}]}}}
{"schema_version":"collector.vnext.raw","schema_contract":null,"schema_contract_version":null,"payload_contract_version":null,"record_type":"market.orderbook.diff","record_id":"collector_main-market-orderbook-diff-000000000081","collector_id":"collector_main","collector_role":"production","host_name":"MAIN-PC","session_id":"collector_main-sess-20260314T200940Z-3f6b5158","stream_session_id":"collector_main-stream-bitflyer-board_ws-20260314T201056Z-e40b261b","exchange":"bitflyer","market":"spot","symbol":"BTC_JPY","instrument_id":"bitflyer.spot.BTC_JPY","channel":"board_ws","transport":"websocket","source_event_id":null,"source_sequence":null,"sequence_id":81,"exchange_ts":null,"collector_ts":"2026-03-14T20:10:57Z","ingest_ts":"2026-03-14T20:10:57Z","event_ts":"2026-03-14T20:10:57Z","quality_flags":[],"is_partial":false,"is_reconstructed":false,"confidence_score":1.0,"payload":{"provider":"bitflyer_ws_board","exchange":"bitflyer","transport":"websocket","channel":"lightning_board_BTC_JPY","received_ts":"2026-03-14T20:10:57.813880Z","subscription_id":null,"message_id":null,"source_sequence":null,"raw_message_meta":{"raw_channel":"lightning_board_BTC_JPY","subscription_channel":"lightning_board_BTC_JPY","recv_timeout_sec":10,"ssl_verify":false,"socket_url":"wss://ws.lightstream.bitflyer.com/json-rpc"},"source_payload":{"mid_price":11306011.0,"bids":[],"asks":[{"price":11544663.0,"size":0.002}]}}}
{"schema_version":"collector.vnext.raw","schema_contract":null,"schema_contract_version":null,"payload_contract_version":null,"record_type":"market.orderbook.diff","record_id":"collector_main-market-orderbook-diff-000000000083","collector_id":"collector_main","collector_role":"production","host_name":"MAIN-PC","session_id":"collector_main-sess-20260314T200940Z-3f6b5158","stream_session_id":"collector_main-stream-bitflyer-board_ws-20260314T201056Z-e40b261b","exchange":"bitflyer","market":"spot","symbol":"BTC_JPY","instrument_id":"bitflyer.spot.BTC_JPY","channel":"board_ws","transport":"websocket","source_event_id":null,"source_sequence":null,"sequence_id":83,"exchange_ts":null,"collector_ts":"2026-03-14T20:10:57Z","ingest_ts":"2026-03-14T20:10:57Z","event_ts":"2026-03-14T20:10:57Z","quality_flags":[],"is_partial":false,"is_reconstructed":false,"confidence_score":1.0,"payload":{"provider":"bitflyer_ws_board","exchange":"bitflyer","transport":"websocket","channel":"lightning_board_BTC_JPY","received_ts":"2026-03-14T20:10:57.938269Z","subscription_id":null,"message_id":null,"source_sequence":null,"raw_message_meta":{"raw_channel":"lightning_board_BTC_JPY","subscription_channel":"lightning_board_BTC_JPY","recv_timeout_sec":10,"ssl_verify":false,"socket_url":"wss://ws.lightstream.bitflyer.com/json-rpc"},"source_payload":{"mid_price":11306011.0,"bids":[{"price":11300923.0,"size":0.1275}],"asks":[{"price":11495450.0,"size":0.002}]}}}
{"schema_version":"collector.vnext.raw","schema_contract":null,"schema_contract_version":null,"payload_contract_version":null,"record_type":"market.orderbook.diff","record_id":"collector_main-market-orderbook-diff-000000000085","collector_id":"collector_main","collector_role":"production","host_name":"MAIN-PC","session_id":"collector_main-sess-20260314T200940Z-3f6b5158","stream_session_id":"collector_main-stream-bitflyer-board_ws-20260314T201056Z-e40b261b","exchange":"bitflyer","market":"spot","symbol":"BTC_JPY","instrument_id":"bitflyer.spot.BTC_JPY","channel":"board_ws","transport":"websocket","source_event_id":null,"source_sequence":null,"sequence_id":85,"exchange_ts":null,"collector_ts":"2026-03-14T20:10:58Z","ingest_ts":"2026-03-14T20:10:58Z","event_ts":"2026-03-14T20:10:58Z","quality_flags":[],"is_partial":false,"is_reconstructed":false,"confidence_score":1.0,"payload":{"provider":"bitflyer_ws_board","exchange":"bitflyer","transport":"websocket","channel":"lightning_board_BTC_JPY","received_ts":"2026-03-14T20:10:58.063543Z","subscription_id":null,"message_id":null,"source_sequence":null,"raw_message_meta":{"raw_channel":"lightning_board_BTC_JPY","subscription_channel":"lightning_board_BTC_JPY","recv_timeout_sec":10,"ssl_verify":false,"socket_url":"wss://ws.lightstream.bitflyer.com/json-rpc"},"source_payload":{"mid_price":11306011.0,"bids":[{"price":11300923.0,"size":0.0},{"price":11300892.0,"size":0.0}],"asks":[{"price":11309969.0,"size":0.1251}]}}}
{"schema_version":"collector.vnext.raw","schema_contract":null,"schema_contract_version":null,"payload_contract_version":null,"record_type":"market.orderbook.diff","record_id":"collector_main-market-orderbook-diff-000000000087","collector_id":"collector_main","collector_role":"production","host_name":"MAIN-PC","session_id":"collector_main-sess-20260314T200940Z-3f6b5158","stream_session_id":"collector_main-stream-bitflyer-board_ws-20260314T201056Z-e40b261b","exchange":"bitflyer","market":"spot","symbol":"BTC_JPY","instrument_id":"bitflyer.spot.BTC_JPY","channel":"board_ws","transport":"websocket","source_event_id":null,"source_sequence":null,"sequence_id":87,"exchange_ts":null,"collector_ts":"2026-03-14T20:10:58Z","ingest_ts":"2026-03-14T20:10:58Z","event_ts":"2026-03-14T20:10:58Z","quality_flags":[],"is_partial":false,"is_reconstructed":false,"confidence_score":1.0,"payload":{"provider":"bitflyer_ws_board","exchange":"bitflyer","transport":"websocket","channel":"lightning_board_BTC_JPY","received_ts":"2026-03-14T20:10:58.281609Z","subscription_id":null,"message_id":null,"source_sequence":null,"raw_message_meta":{"raw_channel":"lightning_board_BTC_JPY","subscription_channel":"lightning_board_BTC_JPY","recv_timeout_sec":10,"ssl_verify":false,"socket_url":"wss://ws.lightstream.bitflyer.com/json-rpc"},"source_payload":{"mid_price":11306011.0,"bids":[{"price":11301489.0,"size":0.1275}],"asks":[]}}}
{"schema_version":"collector.vnext.raw","schema_contract":null,"schema_contract_version":null,"payload_contract_version":null,"record_type":"market.orderbook.diff","record_id":"collector_main-market-orderbook-diff-000000000089","collector_id":"collector_main","collector_role":"production","host_name":"MAIN-PC","session_id":"collector_main-sess-20260314T200940Z-3f6b5158","stream_session_id":"collector_main-stream-bitflyer-board_ws-20260314T201056Z-e40b261b","exchange":"bitflyer","market":"spot","symbol":"BTC_JPY","instrument_id":"bitflyer.spot.BTC_JPY","channel":"board_ws","transport":"websocket","source_event_id":null,"source_sequence":null,"sequence_id":89,"exchange_ts":null,"collector_ts":"2026-03-14T20:10:58Z","ingest_ts":"2026-03-14T20:10:58Z","event_ts":"2026-03-14T20:10:58Z","quality_flags":[],"is_partial":false,"is_reconstructed":false,"confidence_score":1.0,"payload":{"provider":"bitflyer_ws_board","exchange":"bitflyer","transport":"websocket","channel":"lightning_board_BTC_JPY","received_ts":"2026-03-14T20:10:58.392074Z","subscription_id":null,"message_id":null,"source_sequence":null,"raw_message_meta":{"raw_channel":"lightning_board_BTC_JPY","subscription_channel":"lightning_board_BTC_JPY","recv_timeout_sec":10,"ssl_verify":false,"socket_url":"wss://ws.lightstream.bitflyer.com/json-rpc"},"source_payload":{"mid_price":11306011.0,"bids":[{"price":11300923.0,"size":0.1275}],"asks":[{"price":11309968.0,"size":0.02},{"price":11320997.0,"size":0.0},{"price":11320996.0,"size":0.0930818}]}}}
{"schema_version":"collector.vnext.raw","schema_contract":null,"schema_contract_version":null,"payload_contract_version":null,"record_type":"market.orderbook.diff","record_id":"collector_main-market-orderbook-diff-000000000091","collector_id":"collector_main","collector_role":"production","host_name":"MAIN-PC","session_id":"collector_main-sess-20260314T200940Z-3f6b5158","stream_session_id":"collector_main-stream-bitflyer-board_ws-20260314T201056Z-e40b261b","exchange":"bitflyer","market":"spot","symbol":"BTC_JPY","instrument_id":"bitflyer.spot.BTC_JPY","channel":"board_ws","transport":"websocket","source_event_id":null,"source_sequence":null,"sequence_id":91,"exchange_ts":null,"collector_ts":"2026-03-14T20:10:58Z","ingest_ts":"2026-03-14T20:10:58Z","event_ts":"2026-03-14T20:10:58Z","quality_flags":[],"is_partial":false,"is_reconstructed":false,"confidence_score":1.0,"payload":{"provider":"bitflyer_ws_board","exchange":"bitflyer","transport":"websocket","channel":"lightning_board_BTC_JPY","received_ts":"2026-03-14T20:10:58.500402Z","subscription_id":null,"message_id":null,"source_sequence":null,"raw_message_meta":{"raw_channel":"lightning_board_BTC_JPY","subscription_channel":"lightning_board_BTC_JPY","recv_timeout_sec":10,"ssl_verify":false,"socket_url":"wss://ws.lightstream.bitflyer.com/json-rpc"},"source_payload":{"mid_price":11306011.0,"bids":[{"price":11301489.0,"size":0.0},{"price":11300854.0,"size":0.0}],"asks":[{"price":11325037.0,"size":0.0},{"price":11325036.0,"size":0.0111226}]}}}
{"schema_version":"collector.vnext.raw","schema_contract":null,"schema_contract_version":null,"payload_contract_version":null,"record_type":"market.orderbook.diff","record_id":"collector_main-market-orderbook-diff-000000000093","collector_id":"collector_main","collector_role":"production","host_name":"MAIN-PC","session_id":"collector_main-sess-20260314T200940Z-3f6b5158","stream_session_id":"collector_main-stream-bitflyer-board_ws-20260314T201056Z-e40b261b","exchange":"bitflyer","market":"spot","symbol":"BTC_JPY","instrument_id":"bitflyer.spot.BTC_JPY","channel":"board_ws","transport":"websocket","source_event_id":null,"source_sequence":null,"sequence_id":93,"exchange_ts":null,"collector_ts":"2026-03-14T20:10:58Z","ingest_ts":"2026-03-14T20:10:58Z","event_ts":"2026-03-14T20:10:58Z","quality_flags":[],"is_partial":false,"is_reconstructed":false,"confidence_score":1.0,"payload":{"provider":"bitflyer_ws_board","exchange":"bitflyer","transport":"websocket","channel":"lightning_board_BTC_JPY","received_ts":"2026-03-14T20:10:58.625553Z","subscription_id":null,"message_id":null,"source_sequence":null,"raw_message_meta":{"raw_channel":"lightning_board_BTC_JPY","subscription_channel":"lightning_board_BTC_JPY","recv_timeout_sec":10,"ssl_verify":false,"socket_url":"wss://ws.lightstream.bitflyer.com/json-rpc"},"source_payload":{"mid_price":11306011.0,"bids":[{"price":11300923.0,"size":0.0},{"price":11302054.0,"size":0.1275},{"price":11301963.0,"size":0.0176942}],"asks":[{"price":11309969.0,"size":0.0}]}}}
{"schema_version":"collector.vnext.raw","schema_contract":null,"schema_contract_version":null,"payload_contract_version":null,"record_type":"market.orderbook.diff","record_id":"collector_main-market-orderbook-diff-000000000095","collector_id":"collector_main","collector_role":"production","host_name":"MAIN-PC","session_id":"collector_main-sess-20260314T200940Z-3f6b5158","stream_session_id":"collector_main-stream-bitflyer-board_ws-20260314T201056Z-e40b261b","exchange":"bitflyer","market":"spot","symbol":"BTC_JPY","instrument_id":"bitflyer.spot.BTC_JPY","channel":"board_ws","transport":"websocket","source_event_id":null,"source_sequence":null,"sequence_id":95,"exchange_ts":null,"collector_ts":"2026-03-14T20:10:58Z","ingest_ts":"2026-03-14T20:10:58Z","event_ts":"2026-03-14T20:10:58Z","quality_flags":[],"is_partial":false,"is_reconstructed":false,"confidence_score":1.0,"payload":{"provider":"bitflyer_ws_board","exchange":"bitflyer","transport":"websocket","channel":"lightning_board_BTC_JPY","received_ts":"2026-03-14T20:10:58.745623Z","subscription_id":null,"message_id":null,"source_sequence":null,"raw_message_meta":{"raw_channel":"lightning_board_BTC_JPY","subscription_channel":"lightning_board_BTC_JPY","recv_timeout_sec":10,"ssl_verify":false,"socket_url":"wss://ws.lightstream.bitflyer.com/json-rpc"},"source_payload":{"mid_price":11306011.0,"bids":[{"price":11300855.0,"size":0.0},{"price":11302054.0,"size":0.0}],"asks":[]}}}
{"schema_version":"collector.vnext.raw","schema_contract":null,"schema_contract_version":null,"payload_contract_version":null,"record_type":"market.orderbook.diff","record_id":"collector_main-market-orderbook-diff-000000000097","collector_id":"collector_main","collector_role":"production","host_name":"MAIN-PC","session_id":"collector_main-sess-20260314T200940Z-3f6b5158","stream_session_id":"collector_main-stream-bitflyer-board_ws-20260314T201056Z-e40b261b","exchange":"bitflyer","market":"spot","symbol":"BTC_JPY","instrument_id":"bitflyer.spot.BTC_JPY","channel":"board_ws","transport":"websocket","source_event_id":null,"source_sequence":null,"sequence_id":97,"exchange_ts":null,"collector_ts":"2026-03-14T20:10:58Z","ingest_ts":"2026-03-14T20:10:58Z","event_ts":"2026-03-14T20:10:58Z","quality_flags":[],"is_partial":false,"is_reconstructed":false,"confidence_score":1.0,"payload":{"provider":"bitflyer_ws_board","exchange":"bitflyer","transport":"websocket","channel":"lightning_board_BTC_JPY","received_ts":"2026-03-14T20:10:58.891508Z","subscription_id":null,"message_id":null,"source_sequence":null,"raw_message_meta":{"raw_channel":"lightning_board_BTC_JPY","subscription_channel":"lightning_board_BTC_JPY","recv_timeout_sec":10,"ssl_verify":false,"socket_url":"wss://ws.lightstream.bitflyer.com/json-rpc"},"source_payload":{"mid_price":11306011.0,"bids":[{"price":11302619.0,"size":0.1275}],"asks":[{"price":11309968.0,"size":0.0}]}}}
{"schema_version":"collector.vnext.raw","schema_contract":null,"schema_contract_version":null,"payload_contract_version":null,"record_type":"market.orderbook.diff","record_id":"collector_main-market-orderbook-diff-000000000099","collector_id":"collector_main","collector_role":"production","host_name":"MAIN-PC","session_id":"collector_main-sess-20260314T200940Z-3f6b5158","stream_session_id":"collector_main-stream-bitflyer-board_ws-20260314T201056Z-e40b261b","exchange":"bitflyer","market":"spot","symbol":"BTC_JPY","instrument_id":"bitflyer.spot.BTC_JPY","channel":"board_ws","transport":"websocket","source_event_id":null,"source_sequence":null,"sequence_id":99,"exchange_ts":null,"collector_ts":"2026-03-14T20:10:59Z","ingest_ts":"2026-03-14T20:10:59Z","event_ts":"2026-03-14T20:10:59Z","quality_flags":[],"is_partial":false,"is_reconstructed":false,"confidence_score":1.0,"payload":{"provider":"bitflyer_ws_board","exchange":"bitflyer","transport":"websocket","channel":"lightning_board_BTC_JPY","received_ts":"2026-03-14T20:10:59.016048Z","subscription_id":null,"message_id":null,"source_sequence":null,"raw_message_meta":{"raw_channel":"lightning_board_BTC_JPY","subscription_channel":"lightning_board_BTC_JPY","recv_timeout_sec":10,"ssl_verify":false,"socket_url":"wss://ws.lightstream.bitflyer.com/json-rpc"},"source_payload":{"mid_price":11306011.0,"bids":[{"price":11300923.0,"size":0.1275},{"price":11302619.0,"size":0.0}],"asks":[{"price":11309969.0,"size":0.1251}]}}}
{"schema_version":"collector.vnext.raw","schema_contract":null,"schema_contract_version":null,"payload_contract_version":null,"record_type":"market.orderbook.diff","record_id":"collector_main-market-orderbook-diff-000000000101","collector_id":"collector_main","collector_role":"production","host_name":"MAIN-PC","session_id":"collector_main-sess-20260314T200940Z-3f6b5158","stream_session_id":"collector_main-stream-bitflyer-board_ws-20260314T201056Z-e40b261b","exchange":"bitflyer","market":"spot","symbol":"BTC_JPY","instrument_id":"bitflyer.spot.BTC_JPY","channel":"board_ws","transport":"websocket","source_event_id":null,"source_sequence":null,"sequence_id":101,"exchange_ts":null,"collector_ts":"2026-03-14T20:10:59Z","ingest_ts":"2026-03-14T20:10:59Z","event_ts":"2026-03-14T20:10:59Z","quality_flags":[],"is_partial":false,"is_reconstructed":false,"confidence_score":1.0,"payload":{"provider":"bitflyer_ws_board","exchange":"bitflyer","transport":"websocket","channel":"lightning_board_BTC_JPY","received_ts":"2026-03-14T20:10:59.141000Z","subscription_id":null,"message_id":null,"source_sequence":null,"raw_message_meta":{"raw_channel":"lightning_board_BTC_JPY","subscription_channel":"lightning_board_BTC_JPY","recv_timeout_sec":10,"ssl_verify":false,"socket_url":"wss://ws.lightstream.bitflyer.com/json-rpc"},"source_payload":{"mid_price":11306011.0,"bids":[],"asks":[{"price":11518992.0,"size":0.002}]}}}
{"schema_version":"collector.vnext.raw","schema_contract":null,"schema_contract_version":null,"payload_contract_version":null,"record_type":"market.orderbook.diff","record_id":"collector_main-market-orderbook-diff-000000000103","collector_id":"collector_main","collector_role":"production","host_name":"MAIN-PC","session_id":"collector_main-sess-20260314T200940Z-3f6b5158","stream_session_id":"collector_main-stream-bitflyer-board_ws-20260314T201056Z-e40b261b","exchange":"bitflyer","market":"spot","symbol":"BTC_JPY","instrument_id":"bitflyer.spot.BTC_JPY","channel":"board_ws","transport":"websocket","source_event_id":null,"source_sequence":null,"sequence_id":103,"exchange_ts":null,"collector_ts":"2026-03-14T20:10:59Z","ingest_ts":"2026-03-14T20:10:59Z","event_ts":"2026-03-14T20:10:59Z","quality_flags":[],"is_partial":false,"is_reconstructed":false,"confidence_score":1.0,"payload":{"provider":"bitflyer_ws_board","exchange":"bitflyer","transport":"websocket","channel":"lightning_board_BTC_JPY","received_ts":"2026-03-14T20:10:59.266736Z","subscription_id":null,"message_id":null,"source_sequence":null,"raw_message_meta":{"raw_channel":"lightning_board_BTC_JPY","subscription_channel":"lightning_board_BTC_JPY","recv_timeout_sec":10,"ssl_verify":false,"socket_url":"wss://ws.lightstream.bitflyer.com/json-rpc"},"source_payload":{"mid_price":11306011.0,"bids":[{"price":11301489.0,"size":0.1275}],"asks":[{"price":11309968.0,"size":0.02}]}}}
{"schema_version":"collector.vnext.raw","schema_contract":null,"schema_contract_version":null,"payload_contract_version":null,"record_type":"market.orderbook.diff","record_id":"collector_main-market-orderbook-diff-000000000105","collector_id":"collector_main","collector_role":"production","host_name":"MAIN-PC","session_id":"collector_main-sess-20260314T200940Z-3f6b5158","stream_session_id":"collector_main-stream-bitflyer-board_ws-20260314T201056Z-e40b261b","exchange":"bitflyer","market":"spot","symbol":"BTC_JPY","instrument_id":"bitflyer.spot.BTC_JPY","channel":"board_ws","transport":"websocket","source_event_id":null,"source_sequence":null,"sequence_id":105,"exchange_ts":null,"collector_ts":"2026-03-14T20:10:59Z","ingest_ts":"2026-03-14T20:10:59Z","event_ts":"2026-03-14T20:10:59Z","quality_flags":[],"is_partial":false,"is_reconstructed":false,"confidence_score":1.0,"payload":{"provider":"bitflyer_ws_board","exchange":"bitflyer","transport":"websocket","channel":"lightning_board_BTC_JPY","received_ts":"2026-03-14T20:10:59.376370Z","subscription_id":null,"message_id":null,"source_sequence":null,"raw_message_meta":{"raw_channel":"lightning_board_BTC_JPY","subscription_channel":"lightning_board_BTC_JPY","recv_timeout_sec":10,"ssl_verify":false,"socket_url":"wss://ws.lightstream.bitflyer.com/json-rpc"},"source_payload":{"mid_price":11306011.0,"bids":[{"price":11301489.0,"size":0.0},{"price":11300923.0,"size":0.0}],"asks":[]}}}
{"schema_version":"collector.vnext.raw","schema_contract":null,"schema_contract_version":null,"payload_contract_version":null,"record_type":"market.orderbook.diff","record_id":"collector_main-market-orderbook-diff-000000000107","collector_id":"collector_main","collector_role":"production","host_name":"MAIN-PC","session_id":"collector_main-sess-20260314T200940Z-3f6b5158","stream_session_id":"collector_main-stream-bitflyer-board_ws-20260314T201056Z-e40b261b","exchange":"bitflyer","market":"spot","symbol":"BTC_JPY","instrument_id":"bitflyer.spot.BTC_JPY","channel":"board_ws","transport":"websocket","source_event_id":null,"source_sequence":null,"sequence_id":107,"exchange_ts":null,"collector_ts":"2026-03-14T20:10:59Z","ingest_ts":"2026-03-14T20:10:59Z","event_ts":"2026-03-14T20:10:59Z","quality_flags":[],"is_partial":false,"is_reconstructed":false,"confidence_score":1.0,"payload":{"provider":"bitflyer_ws_board","exchange":"bitflyer","transport":"websocket","channel":"lightning_board_BTC_JPY","received_ts":"2026-03-14T20:10:59.656507Z","subscription_id":null,"message_id":null,"source_sequence":null,"raw_message_meta":{"raw_channel":"lightning_board_BTC_JPY","subscription_channel":"lightning_board_BTC_JPY","recv_timeout_sec":10,"ssl_verify":false,"socket_url":"wss://ws.lightstream.bitflyer.com/json-rpc"},"source_payload":{"mid_price":11306011.0,"bids":[{"price":11300923.0,"size":0.1275}],"asks":[]}}}
{"schema_version":"collector.vnext.raw","schema_contract":null,"schema_contract_version":null,"payload_contract_version":null,"record_type":"market.orderbook.diff","record_id":"collector_main-market-orderbook-diff-000000000109","collector_id":"collector_main","collector_role":"production","host_name":"MAIN-PC","session_id":"collector_main-sess-20260314T200940Z-3f6b5158","stream_session_id":"collector_main-stream-bitflyer-board_ws-20260314T201056Z-e40b261b","exchange":"bitflyer","market":"spot","symbol":"BTC_JPY","instrument_id":"bitflyer.spot.BTC_JPY","channel":"board_ws","transport":"websocket","source_event_id":null,"source_sequence":null,"sequence_id":109,"exchange_ts":null,"collector_ts":"2026-03-14T20:11:00Z","ingest_ts":"2026-03-14T20:11:00Z","event_ts":"2026-03-14T20:11:00Z","quality_flags":[],"is_partial":false,"is_reconstructed":false,"confidence_score":1.0,"payload":{"provider":"bitflyer_ws_board","exchange":"bitflyer","transport":"websocket","channel":"lightning_board_BTC_JPY","received_ts":"2026-03-14T20:11:00.047877Z","subscription_id":null,"message_id":null,"source_sequence":null,"raw_message_meta":{"raw_channel":"lightning_board_BTC_JPY","subscription_channel":"lightning_board_BTC_JPY","recv_timeout_sec":10,"ssl_verify":false,"socket_url":"wss://ws.lightstream.bitflyer.com/json-rpc"},"source_payload":{"mid_price":11306011.0,"bids":[],"asks":[{"price":11548144.0,"size":0.002}]}}}
{"schema_version":"collector.vnext.raw","schema_contract":null,"schema_contract_version":null,"payload_contract_version":null,"record_type":"market.orderbook.diff","record_id":"collector_main-market-orderbook-diff-000000000111","collector_id":"collector_main","collector_role":"production","host_name":"MAIN-PC","session_id":"collector_main-sess-20260314T200940Z-3f6b5158","stream_session_id":"collector_main-stream-bitflyer-board_ws-20260314T201056Z-e40b261b","exchange":"bitflyer","market":"spot","symbol":"BTC_JPY","instrument_id":"bitflyer.spot.BTC_JPY","channel":"board_ws","transport":"websocket","source_event_id":null,"source_sequence":null,"sequence_id":111,"exchange_ts":null,"collector_ts":"2026-03-14T20:11:00Z","ingest_ts":"2026-03-14T20:11:00Z","event_ts":"2026-03-14T20:11:00Z","quality_flags":[],"is_partial":false,"is_reconstructed":false,"confidence_score":1.0,"payload":{"provider":"bitflyer_ws_board","exchange":"bitflyer","transport":"websocket","channel":"lightning_board_BTC_JPY","received_ts":"2026-03-14T20:11:00.298030Z","subscription_id":null,"message_id":null,"source_sequence":null,"raw_message_meta":{"raw_channel":"lightning_board_BTC_JPY","subscription_channel":"lightning_board_BTC_JPY","recv_timeout_sec":10,"ssl_verify":false,"socket_url":"wss://ws.lightstream.bitflyer.com/json-rpc"},"source_payload":{"mid_price":11306011.0,"bids":[],"asks":[{"price":11540357.0,"size":0.002}]}}}
