{"schema_version":"collector.vnext.raw","schema_contract":null,"schema_contract_version":null,"payload_contract_version":null,"record_type":"market.orderbook.diff","record_id":"collector_main-market-orderbook-diff-000000000061","collector_id":"collector_main","collector_role":"production","host_name":"MAIN-PC","session_id":"collector_main-sess-20260314T235958Z-3e9eb3dd","stream_session_id":"collector_main-stream-bitflyer-board_ws-20260315T000000Z-4e37007e","exchange":"bitflyer","market":"spot","symbol":"BTC_JPY","instrument_id":"bitflyer.spot.BTC_JPY","channel":"board_ws","transport":"websocket","source_event_id":null,"source_sequence":null,"sequence_id":61,"exchange_ts":null,"collector_ts":"2026-03-15T00:00:00Z","ingest_ts":"2026-03-15T00:00:00Z","event_ts":"2026-03-15T00:00:00Z","quality_flags":[],"is_partial":false,"is_reconstructed":false,"confidence_score":1.0,"payload":{"provider":"bitflyer_ws_board","exchange":"bitflyer","transport":"websocket","channel":"lightning_board_BTC_JPY","received_ts":"2026-03-15T00:00:00.939928Z","subscription_id":null,"message_id":null,"source_sequence":null,"raw_message_meta":{"raw_channel":"lightning_board_BTC_JPY","subscription_channel":"lightning_board_BTC_JPY","recv_timeout_sec":10,"ssl_verify":false,"socket_url":"wss://ws.lightstream.bitflyer.com/json-rpc"},"source_payload":{"mid_price":11391621.0,"bids":[],"asks":[{"price":11405154.0,"size":0.0}]}}}
{"schema_version":"collector.vnext.raw","schema_contract":null,"schema_contract_version":null,"payload_contract_version":null,"record_type":"market.orderbook.diff","record_id":"collector_main-market-orderbook-diff-000000000065","collector_id":"collector_main","collector_role":"production","host_name":"MAIN-PC","session_id":"collector_main-sess-20260314T235958Z-3e9eb3dd","stream_session_id":"collector_main-stream-bitflyer-board_ws-20260315T000000Z-4e37007e","exchange":"bitflyer","market":"spot","symbol":"BTC_JPY","instrument_id":"bitflyer.spot.BTC_JPY","channel":"board_ws","transport":"websocket","source_event_id":null,"source_sequence":null,"sequence_id":65,"exchange_ts":null,"collector_ts":"2026-03-15T00:00:01Z","ingest_ts":"2026-03-15T00:00:01Z","event_ts":"2026-03-15T00:00:01Z","quality_flags":[],"is_partial":false,"is_reconstructed":false,"confidence_score":1.0,"payload":{"provider":"bitflyer_ws_board","exchange":"bitflyer","transport":"websocket","channel":"lightning_board_BTC_JPY","received_ts":"2026-03-15T00:00:01.061628Z","subscription_id":null,"message_id":null,"source_sequence":null,"raw_message_meta":{"raw_channel":"lightning_board_BTC_JPY","subscription_channel":"lightning_board_BTC_JPY","recv_timeout_sec":10,"ssl_verify":false,"socket_url":"wss://ws.lightstream.bitflyer.com/json-rpc"},"source_payload":{"mid_price":11391621.0,"bids":[],"asks":[{"price":11405901.0,"size":0.2}]}}}
{"schema_version":"collector.vnext.raw","schema_contract":null,"schema_contract_version":null,"payload_contract_version":null,"record_type":"market.orderbook.diff","record_id":"collector_main-market-orderbook-diff-000000000067","collector_id":"collector_main","collector_role":"production","host_name":"MAIN-PC","session_id":"collector_main-sess-20260314T235958Z-3e9eb3dd","stream_session_id":"collector_main-stream-bitflyer-board_ws-20260315T000000Z-4e37007e","exchange":"bitflyer","market":"spot","symbol":"BTC_JPY","instrument_id":"bitflyer.spot.BTC_JPY","channel":"board_ws","transport":"websocket","source_event_id":null,"source_sequence":null,"sequence_id":67,"exchange_ts":null,"collector_ts":"2026-03-15T00:00:01Z","ingest_ts":"2026-03-15T00:00:01Z","event_ts":"2026-03-15T00:00:01Z","quality_flags":[],"is_partial":false,"is_reconstructed":false,"confidence_score":1.0,"payload":{"provider":"bitflyer_ws_board","exchange":"bitflyer","transport":"websocket","channel":"lightning_board_BTC_JPY","received_ts":"2026-03-15T00:00:01.203909Z","subscription_id":null,"message_id":null,"source_sequence":null,"raw_message_meta":{"raw_channel":"lightning_board_BTC_JPY","subscription_channel":"lightning_board_BTC_JPY","recv_timeout_sec":10,"ssl_verify":false,"socket_url":"wss://ws.lightstream.bitflyer.com/json-rpc"},"source_payload":{"mid_price":11391621.0,"bids":[{"price":11365953.0,"size":0.002}],"asks":[]}}}
{"schema_version":"collector.vnext.raw","schema_contract":null,"schema_contract_version":null,"payload_contract_version":null,"record_type":"market.orderbook.diff","record_id":"collector_main-market-orderbook-diff-000000000069","collector_id":"collector_main","collector_role":"production","host_name":"MAIN-PC","session_id":"collector_main-sess-20260314T235958Z-3e9eb3dd","stream_session_id":"collector_main-stream-bitflyer-board_ws-20260315T000000Z-4e37007e","exchange":"bitflyer","market":"spot","symbol":"BTC_JPY","instrument_id":"bitflyer.spot.BTC_JPY","channel":"board_ws","transport":"websocket","source_event_id":null,"source_sequence":null,"sequence_id":69,"exchange_ts":null,"collector_ts":"2026-03-15T00:00:02Z","ingest_ts":"2026-03-15T00:00:02Z","event_ts":"2026-03-15T00:00:02Z","quality_flags":[],"is_partial":false,"is_reconstructed":false,"confidence_score":1.0,"payload":{"provider":"bitflyer_ws_board","exchange":"bitflyer","transport":"websocket","channel":"lightning_board_BTC_JPY","received_ts":"2026-03-15T00:00:02.454494Z","subscription_id":null,"message_id":null,"source_sequence":null,"raw_message_meta":{"raw_channel":"lightning_board_BTC_JPY","subscription_channel":"lightning_board_BTC_JPY","recv_timeout_sec":10,"ssl_verify":false,"socket_url":"wss://ws.lightstream.bitflyer.com/json-rpc"},"source_payload":{"mid_price":11391621.0,"bids":[],"asks":[{"price":11405901.0,"size":0.0}]}}}
{"schema_version":"collector.vnext.raw","schema_contract":null,"schema_contract_version":null,"payload_contract_version":null,"record_type":"market.orderbook.diff","record_id":"collector_main-market-orderbook-diff-000000000071","collector_id":"collector_main","collector_role":"production","host_name":"MAIN-PC","session_id":"collector_main-sess-20260314T235958Z-3e9eb3dd","stream_session_id":"collector_main-stream-bitflyer-board_ws-20260315T000000Z-4e37007e","exchange":"bitflyer","market":"spot","symbol":"BTC_JPY","instrument_id":"bitflyer.spot.BTC_JPY","channel":"board_ws","transport":"websocket","source_event_id":null,"source_sequence":null,"sequence_id":71,"exchange_ts":null,"collector_ts":"2026-03-15T00:00:02Z","ingest_ts":"2026-03-15T00:00:02Z","event_ts":"2026-03-15T00:00:02Z","quality_flags":[],"is_partial":false,"is_reconstructed":false,"confidence_score":1.0,"payload":{"provider":"bitflyer_ws_board","exchange":"bitflyer","transport":"websocket","channel":"lightning_board_BTC_JPY","received_ts":"2026-03-15T00:00:02.579374Z","subscription_id":null,"message_id":null,"source_sequence":null,"raw_message_meta":{"raw_channel":"lightning_board_BTC_JPY","subscription_channel":"lightning_board_BTC_JPY","recv_timeout_sec":10,"ssl_verify":false,"socket_url":"wss://ws.lightstream.bitflyer.com/json-rpc"},"source_payload":{"mid_price":11391621.0,"bids":[],"asks":[{"price":11405900.0,"size":0.0780453}]}}}
{"schema_version":"collector.vnext.raw","schema_contract":null,"schema_contract_version":null,"payload_contract_version":null,"record_type":"market.orderbook.diff","record_id":"collector_main-market-orderbook-diff-000000000073","collector_id":"collector_main","collector_role":"production","host_name":"MAIN-PC","session_id":"collector_main-sess-20260314T235958Z-3e9eb3dd","stream_session_id":"collector_main-stream-bitflyer-board_ws-20260315T000000Z-4e37007e","exchange":"bitflyer","market":"spot","symbol":"BTC_JPY","instrument_id":"bitflyer.spot.BTC_JPY","channel":"board_ws","transport":"websocket","source_event_id":null,"source_sequence":null,"sequence_id":73,"exchange_ts":null,"collector_ts":"2026-03-15T00:00:02Z","ingest_ts":"2026-03-15T00:00:02Z","event_ts":"2026-03-15T00:00:02Z","quality_flags":[],"is_partial":false,"is_reconstructed":false,"confidence_score":1.0,"payload":{"provider":"bitflyer_ws_board","exchange":"bitflyer","transport":"websocket","channel":"lightning_board_BTC_JPY","received_ts":"2026-03-15T00:00:02.863959Z","subscription_id":null,"message_id":null,"source_sequence":null,"raw_message_meta":{"raw_channel":"lightning_board_BTC_JPY","subscription_channel":"lightning_board_BTC_JPY","recv_timeout_sec":10,"ssl_verify":false,"socket_url":"wss://ws.lightstream.bitflyer.com/json-rpc"},"source_payload":{"mid_price":11391621.0,"bids":[{"price":11388855.0,"size":0.014592},{"price":11388157.0,"size":0.0}],"asks":[{"price":11395944.0,"size":0.0},{"price":11402548.0,"size":0.0}]}}}
{"schema_version":"collector.vnext.raw","schema_contract":null,"schema_contract_version":null,"payload_contract_version":null,"record_type":"market.orderbook.diff","record_id":"collector_main-market-orderbook-diff-000000000075","collector_id":"collector_main","collector_role":"production","host_name":"MAIN-PC","session_id":"collector_main-sess-20260314T235958Z-3e9eb3dd","stream_session_id":"collector_main-stream-bitflyer-board_ws-20260315T000000Z-4e37007e","exchange":"bitflyer","market":"spot","symbol":"BTC_JPY","instrument_id":"bitflyer.spot.BTC_JPY","channel":"board_ws","transport":"websocket","source_event_id":null,"source_sequence":null,"sequence_id":75,"exchange_ts":null,"collector_ts":"2026-03-15T00:00:03Z","ingest_ts":"2026-03-15T00:00:03Z","event_ts":"2026-03-15T00:00:03Z","quality_flags":[],"is_partial":false,"is_reconstructed":false,"confidence_score":1.0,"payload":{"provider":"bitflyer_ws_board","exchange":"bitflyer","transport":"websocket","channel":"lightning_board_BTC_JPY","received_ts":"2026-03-15T00:00:03.531335Z","subscription_id":null,"message_id":null,"source_sequence":null,"raw_message_meta":{"raw_channel":"lightning_board_BTC_JPY","subscription_channel":"lightning_board_BTC_JPY","recv_timeout_sec":10,"ssl_verify":false,"socket_url":"wss://ws.lightstream.bitflyer.com/json-rpc"},"source_payload":{"mid_price":11391621.0,"bids":[{"price":11388158.0,"size":0.0}],"asks":[{"price":11395943.0,"size":0.0}]}}}
{"schema_version":"collector.vnext.raw","schema_contract":null,"schema_contract_version":null,"payload_contract_version":null,"record_type":"market.orderbook.diff","record_id":"collector_main-market-orderbook-diff-000000000077","collector_id":"collector_main","collector_role":"production","host_name":"MAIN-PC","session_id":"collector_main-sess-20260314T235958Z-3e9eb3dd","stream_session_id":"collector_main-stream-bitflyer-board_ws-20260315T000000Z-4e37007e","exchange":"bitflyer","market":"spot","symbol":"BTC_JPY","instrument_id":"bitflyer.spot.BTC_JPY","channel":"board_ws","transport":"websocket","source_event_id":null,"source_sequence":null,"sequence_id":77,"exchange_ts":null,"collector_ts":"2026-03-15T00:00:03Z","ingest_ts":"2026-03-15T00:00:03Z","event_ts":"2026-03-15T00:00:03Z","quality_flags":[],"is_partial":false,"is_reconstructed":false,"confidence_score":1.0,"payload":{"provider":"bitflyer_ws_board","exchange":"bitflyer","transport":"websocket","channel":"lightning_board_BTC_JPY","received_ts":"2026-03-15T00:00:03.628938Z","subscription_id":null,"message_id":null,"source_sequence":null,"raw_message_meta":{"raw_channel":"lightning_board_BTC_JPY","subscription_channel":"lightning_board_BTC_JPY","recv_timeout_sec":10,"ssl_verify":false,"socket_url":"wss://ws.lightstream.bitflyer.com/json-rpc"},"source_payload":{"mid_price":11391621.0,"bids":[{"price":11378373.0,"size":0.11},{"price":11362535.0,"size":0.002},{"price":11379512.0,"size":0.06}],"asks":[]}}}
{"schema_version":"collector.vnext.raw","schema_contract":null,"schema_contract_version":null,"payload_contract_version":null,"record_type":"market.orderbook.snapshot","record_id":"collector_main-market-orderbook-snapshot-000000000079","collector_id":"collector_main","collector_role":"production","host_name":"MAIN-PC","session_id":"collector_main-sess-20260314T235958Z-3e9eb3dd","stream_session_id":"collector_main-stream-bitflyer-board_ws-20260315T000000Z-4e37007e","exchange":"bitflyer","market":"spot","symbol":"BTC_JPY","instrument_id":"bitflyer.spot.BTC_JPY","channel":"board_ws","transport":"websocket","source_event_id":null,"source_sequence":null,"sequence_id":79,"exchange_ts":null,"collector_ts":"2026-03-15T00:00:04Z","ingest_ts":"2026-03-15T00:00:04Z","event_ts":"2026-03-15T00:00:04Z","quality_flags":[],"is_partial":false,"is_reconstructed":false,"confidence_score":1.0,"payload":{"provider":"bitflyer_ws_board_snapshot","exchange":"bitflyer","transport":"websocket","channel":"lightning_board_snapshot_BTC_JPY","received_ts":"2026-03-15T00:00:04.023452Z","subscription_id":null,"message_id":null,"source_sequence":null,"raw_message_meta":{"raw_channel":"lightning_board_snapshot_BTC_JPY","subscription_channel":"lightning_board_snapshot_BTC_JPY","recv_timeout_sec":10,"ssl_verify":false,"socket_url":"wss://ws.lightstream.bitflyer.com/json-rpc"},"source_payload":{"mid_price":11392669.0,"bids":[{"price":11390002.0,"size":0.04604438},{"price":11390001.0,"size":0.005},{"price":11390000.0,"size":0.00878},{"price":11389194.0,"size":0.014796},{"price":11388855.0,"size":0.014592},{"price":11388650.0,"size":0.02},{"price":11388472.0,"size":0.015072},{"price":11388167.0,"size":0.02},{"price":11388166.0,"size":0.01506},{"price":11388161.0,"size":0.02},{"price":11388160.0,"size":0.01494},{"price":11388148.0,"size":0.13611052},{"price":11388010.0,"size":0.00999794},{"price":11385649.0,"size":0.0751},{"price":11385388.0,"size":0.5},{"price":11385167.0,"size":0.2},{"price":11385002.0,"size":0.01},{"price":11384160.0,"size":0.5},{"price":11382841.0,"size":0.053784},{"price":11380160.0,"size":3.11267151},{"price":11380159.0,"size":0.0527},{"price":11380121.0,"size":0.01},{"price":11379512.0,"size":0.06},{"price":11379414.0,"size":0.97620532},{"price":11378373.0,"size":0.11},{"price":11376255.0,"size":1.50015},{"price":11375000.0,"size":0.03},{"price":11374386.0,"size":0.24},{"price":11370000.0,"size":0.005},{"price":11369438.0,"size":0.3048},{"price":11368376.0,"size":0.01},{"price":11367661.0,"size":0.002},{"price":11366676.0,"size":0.2771},{"price":11365953.0,"size":0.002},{"price":11363915.0,"size":0.12856523},{"price":11363914.0,"size":0.2966},{"price":11363103.0,"size":0.002},{"price":11362535.0,"size":0.002},{"price":11362394.0,"size":1.484},{"price":11361677.0,"size":1.966},{"price":11361152.0,"size":0.2587},{"price":11358545.0,"size":0.002},{"price":11358376.0,"size":0.01},{"price":11357601.0,"size":0.22},{"price":11357513.0,"size":0.6},{"price":11350001.0,"size":0.31138056},{"price":11350000.0,"size":0.51},{"price":11349429.0,"size":0.002},{"price":11348380.0,"size":0.5},{"price":11348189.0,"size":0.003},{"price":11347667.0,"size":0.001},{"price":11344871.0,"size":0.002},{"price":11340313.0,"size":0.002},{"price":11340000.0,"size":0.005},{"price":11336383.0,"size":0.001},{"price":11336319.0,"size":0.00195},{"price":11335755.0,"size":0.002},{"price":11332840.0,"size":2.036},{"price":11331197.0,"size":0.002},{"price":11331000.0,"size":0.5},{"price":11330000.0,"size":0.02292},{"price":11326639.0,"size":0.002},{"price":11325101.0,"size":0.001},{"price":11320000.0,"size":0.05},{"price":11315000.0,"size":0.05},{"price":11314325.0,"size":1.951},{"price":11313996.0,"size":0.00195},{"price":11313819.0,"size":0.001},{"price":11310000.0,"size":0.01},{"price":11309999.0,"size":0.177},{"price":11307999.0,"size":0.01},{"price":11303918.0,"size":0.01},{"price":11303000.0,"size":0.5},{"price":11302535.0,"size":0.001},{"price":11302466.0,"size":0.001},{"price":11301268.0,"size":0.01},{"price":11300000.0,"size":3.01685256},{"price":11298000.0,"size":0.01},{"price":11297527.0,"size":1.13},{"price":11296865.0,"size":0.0015},{"price":11294756.0,"size":1.0},{"price":11291282.0,"size":0.001},{"price":11291268.0,"size":0.01},{"price":11291000.0,"size":0.5},{"price":11290000.0,"size":0.003},{"price":11281268.0,"size":0.01},{"price":11280000.0,"size":0.0163},{"price":11279960.0,"size":0.001},{"price":11279282.0,"size":0.0015},{"price":11278000.0,"size":0.0025},{"price":11275000.0,"size":0.001},{"price":11274588.0,"size":0.0047},{"price":11271268.0,"size":0.01},{"price":11271000.0,"size":0.003},{"price":11270000.0,"size":0.106},{"price":11269424.0,"size":0.8},{"price":11268871.0,"size":0.28},{"price":11268638.0,"size":0.001},{"price":11268411.0,"size":0.01},{"price":11266666.0,"size":0.04},{"price":11265000.0,"size":0.02},{"price":11263000.0,"size":0.006},{"price":11262564.0,"size":0.0015},{"price":11261268.0,"size":0.01},{"price":11260000.0,"size":0.3565},{"price":11257315.0,"size":0.001},{"price":11257000.0,"size":0.001},{"price":11255200.0,"size":0.001},{"price":11255115.0,"size":0.00377},{"price":11253814.0,"size":2.2},{"price":11253690.0,"size":0.01},{"price":11253000.0,"size":0.03189},{"price":11251405.0,"size":0.139},{"price":11251268.0,"size":0.01},{"price":11251111.0,"size":0.0015},{"price":11251000.0,"size":0.0131},{"price":11250250.0,"size":0.00105},{"price":11250200.0,"size":0.001},{"price":11250005.0,"size":0.001},{"price":11250001.0,"size":0.00104},{"price":11250000.0,"size":1.63712889},{"price":11245993.0,"size":0.001},{"price":11245141.0,"size":0.0031},{"price":11245000.0,"size":0.05},{"price":11244444.0,"size":0.04},{"price":11244243.0,"size":0.01},{"price":11240200.0,"size":0.001},{"price":11240000.0,"size":0.007304},{"price":11236190.0,"size":0.01},{"price":11235200.0,"size":0.001},{"price":11234670.0,"size":0.001},{"price":11232000.0,"size":0.089},{"price":11231243.0,"size":0.01},{"price":11231000.0,"size":0.105},{"price":11230200.0,"size":0.001},{"price":11230000.0,"size":0.0308},{"price":11226952.0,"size":0.972},{"price":11224500.0,"size":0.06},{"price":11223968.0,"size":0.001},{"price":11223348.0,"size":0.001},{"price":11223344.0,"size":0.01},{"price":11223000.0,"size":0.1},{"price":11222222.0,"size":0.093525},{"price":11221120.0,"size":0.001},{"price":11220200.0,"size":0.001},{"price":11220001.0,"size":0.004457},{"price":11220000.0,"size":0.321},{"price":11219000.0,"size":0.1},{"price":11217326.0,"size":0.02},{"price":11215200.0,"size":0.001},{"price":11213690.0,"size":0.01},{"price":11212025.0,"size":0.001},{"price":11211800.0,"size":0.001},{"price":11211111.0,"size":0.06},{"price":11210200.0,"size":0.001},{"price":11210000.0,"size":0.10622},{"price":11208032.0,"size":0.01},{"price":11206000.0,"size":0.09015},{"price":11205200.0,"size":0.001},{"price":11204578.0,"size":0.002},{"price":11201000.0,"size":0.01},{"price":11200800.0,"size":0.05},{"price":11200703.0,"size":0.001},{"price":11200425.0,"size":0.1},{"price":11200200.0,"size":0.001},{"price":11200198.0,"size":0.003},{"price":11200150.0,"size":0.002},{"price":11200002.0,"size":0.001},{"price":11200001.0,"size":0.01104},{"price":11200000.0,"size":1.15226728},{"price":11198508.0,"size":0.05},{"price":11198243.0,"size":0.01},{"price":11197134.0,"size":0.993},{"price":11197000.0,"size":0.0085},{"price":11194090.0,"size":0.03},{"price":11190770.0,"size":0.0309},{"price":11190000.0,"size":0.0010016},{"price":11189555.0,"size":0.5},{"price":11189381.0,"size":0.001},{"price":11188629.0,"size":0.01},{"price":11188382.0,"size":0.001},{"price":11185000.0,"size":0.0085},{"price":11180000.0,"size":0.225},{"price":11178058.0,"size":0.001},{"price":11170000.0,"size":0.001},{"price":11169662.0,"size":0.01},{"price":11169593.0,"size":0.001},{"price":11169243.0,"size":0.01},{"price":11166736.0,"size":0.001},{"price":11164029.0,"size":0.001},{"price":11160854.0,"size":0.1},{"price":11160000.0,"size":0.02376},{"price":11155413.0,"size":0.001},{"price":11155377.0,"size":0.00636009},{"price":11153999.0,"size":0.00101},{"price":11151000.0,"size":0.001},{"price":11150250.0,"size":0.00175},{"price":11150005.0,"size":0.001},{"price":11150001.0,"size":0.00104},{"price":11150000.0,"size":0.6548956},{"price":11148000.0,"size":0.08963},{"price":11147546.0,"size":0.02},{"price":11144091.0,"size":0.001},{"price":11144000.0,"size":0.0897},{"price":11143986.0,"size":0.02},{"price":11140139.0,"size":1.0},{"price":11140000.0,"size":0.2},{"price":11136243.0,"size":0.01},{"price":11135869.0,"size":0.1},{"price":11132768.0,"size":0.001},{"price":11130000.0,"size":0.116},{"price":11129979.0,"size":0.0053908},{"price":11124900.0,"size":0.00133},{"price":11121090.0,"size":0.1},{"price":11120000.0,"size":0.0033},{"price":11118078.0,"size":0.01},{"price":11111800.0,"size":0.001},{"price":11111111.0,"size":0.2919257},{"price":11111000.0,"size":0.003},{"price":11110594.0,"size":0.001},{"price":11110000.0,"size":0.021007},{"price":11109662.0,"size":0.01},{"price":11108008.0,"size":0.01},{"price":11102000.0,"size":0.5},{"price":11101297.0,"size":0.001},{"price":11100005.0,"size":0.001},{"price":11100001.0,"size":0.01104},{"price":11100000.0,"size":1.6532049},{"price":11099141.0,"size":0.01},{"price":11098833.0,"size":0.002},{"price":11096243.0,"size":0.01},{"price":11094090.0,"size":0.01},{"price":11088888.0,"size":0.001},{"price":11085245.0,"size":0.001},{"price":11080200.0,"size":0.001},{"price":11080000.0,"size":0.0223},{"price":11075100.0,"size":0.003},{"price":11070200.0,"size":0.001},{"price":11070000.0,"size":0.0902},{"price":11065200.0,"size":0.001},{"price":11064370.0,"size":0.00497091},{"price":11060200.0,"size":0.001},{"price":11060000.0,"size":0.145},{"price":11059689.0,"size":0.009},{"price":11056428.0,"size":0.002},{"price":11055500.0,"size":0.02},{"price":11055200.0,"size":0.001},{"price":11055100.0,"size":0.003},{"price":11050200.0,"size":0.001},{"price":11050005.0,"size":0.001},{"price":11050002.0,"size":0.001},{"price":11050001.0,"size":0.00104},{"price":11050000.0,"size":0.39576147},{"price":11048064.0,"size":2.0},{"price":11046420.0,"size":0.2},{"price":11044243.0,"size":0.01},{"price":11041380.0,"size":0.01},{"price":11040200.0,"size":0.001},{"price":11040000.0,"size":0.00777181},{"price":11035865.0,"size":0.1},{"price":11035200.0,"size":0.001},{"price":11035000.0,"size":0.0013},{"price":11030200.0,"size":0.001},{"price":11030000.0,"size":0.025},{"price":11025500.0,"size":0.009531},{"price":11025200.0,"size":0.001},{"price":11025000.0,"size":0.71497},{"price":11020772.0,"size":0.014},{"price":11020200.0,"size":0.002},{"price":11020000.0,"size":0.005},{"price":11015200.0,"size":0.001},{"price":11012000.0,"size":0.1},{"price":11011800.0,"size":0.001},{"price":11010200.0,"size":0.001},{"price":11010000.0,"size":0.347},{"price":11007277.0,"size":0.01},{"price":11005200.0,"size":0.001},{"price":11004890.0,"size":0.001535},{"price":11003000.0,"size":0.0155},{"price":11001000.0,"size":0.013},{"price":11000500.0,"size":0.05117658},{"price":11000200.0,"size":0.001},{"price":11000002.0,"size":0.004},{"price":11000001.0,"size":0.02604},{"price":11000000.0,"size":4.53923365},{"price":10999999.0,"size":0.003},{"price":10999000.0,"size":0.001},{"price":10996855.0,"size":0.0011},{"price":10995200.0,"size":0.001},{"price":10994499.0,"size":0.00169176},{"price":10990200.0,"size":0.001},{"price":10990000.0,"size":0.10219},{"price":10989001.0,"size":0.00197},{"price":10988999.0,"size":0.001},{"price":10988324.0,"size":0.002},{"price":10987654.0,"size":0.001},{"price":10985200.0,"size":0.001},{"price":10985150.0,"size":0.01},{"price":10980500.0,"size":0.005},{"price":10980200.0,"size":0.001}],"asks":[{"price":11395336.0,"size":0.04601982},{"price":11395337.0,"size":0.0175475},{"price":11395371.0,"size":0.02},{"price":11395372.0,"size":0.3022},{"price":11395699.0,"size":0.02},{"price":11395700.0,"size":0.00687018},{"price":11396235.0,"size":0.02},{"price":11396600.0,"size":0.014796},{"price":11398133.0,"size":0.02},{"price":11398134.0,"size":0.2684},{"price":11398443.0,"size":0.02},{"price":11398444.0,"size":0.001995},{"price":11398845.0,"size":0.001},{"price":11399162.0,"size":0.015108},{"price":11399449.0,"size":0.02},{"price":11399450.0,"size":0.014616},{"price":11399673.0,"size":0.0015},{"price":11399700.0,"size":0.001},{"price":11399930.0,"size":0.053784},{"price":11399999.0,"size":0.05},{"price":11400000.0,"size":0.74832841},{"price":11400896.0,"size":0.2634},{"price":11402569.0,"size":0.01},{"price":11403385.0,"size":0.57171271},{"price":11403472.0,"size":0.002},{"price":11403658.0,"size":0.2727},{"price":11403959.0,"size":0.01},{"price":11405000.0,"size":0.1275},{"price":11405243.0,"size":0.4249},{"price":11405900.0,"size":0.0780453},{"price":11408354.0,"size":0.0085},{"price":11408700.0,"size":0.001},{"price":11409415.0,"size":0.005},{"price":11409476.0,"size":1.189881},{"price":11409633.0,"size":1.189881},{"price":11410000.0,"size":0.3787},{"price":11410168.0,"size":0.001},{"price":11410853.0,"size":0.002},{"price":11412000.0,"size":0.0878},{"price":11415000.0,"size":0.1},{"price":11415141.0,"size":0.0041},{"price":11417481.0,"size":0.0015},{"price":11418170.0,"size":1.489},{"price":11418700.0,"size":0.001},{"price":11419000.0,"size":0.01},{"price":11420000.0,"size":0.151},{"price":11421268.0,"size":0.05},{"price":11421490.0,"size":0.001},{"price":11424296.0,"size":0.002},{"price":11425000.0,"size":0.029},{"price":11425951.0,"size":0.21},{"price":11426426.0,"size":0.002},{"price":11428121.0,"size":0.002},{"price":11428700.0,"size":0.001},{"price":11429302.0,"size":0.01},{"price":11430000.0,"size":0.8098},{"price":11432717.0,"size":1.53855676},{"price":11432718.0,"size":0.002},{"price":11432813.0,"size":0.001},{"price":11433211.0,"size":0.03},{"price":11433333.0,"size":0.001},{"price":11435877.0,"size":1.928},{"price":11437315.0,"size":0.002},{"price":11438525.0,"size":0.0011},{"price":11438700.0,"size":0.001},{"price":11439557.0,"size":0.001},{"price":11440000.0,"size":0.2538},{"price":11441911.0,"size":0.002},{"price":11442627.0,"size":2.018},{"price":11443629.0,"size":0.002},{"price":11444135.0,"size":0.001},{"price":11445433.0,"size":0.0015},{"price":11446508.0,"size":0.001},{"price":11447000.0,"size":0.01},{"price":11447071.0,"size":0.002},{"price":11448000.0,"size":0.0875},{"price":11448700.0,"size":0.001},{"price":11450000.0,"size":0.268},{"price":11451105.0,"size":0.002},{"price":11453321.0,"size":0.03},{"price":11455000.0,"size":0.001},{"price":11455457.0,"size":0.001},{"price":11455702.0,"size":0.002},{"price":11458700.0,"size":0.001},{"price":11458988.0,"size":0.01},{"price":11460000.0,"size":0.06702},{"price":11460299.0,"size":0.002},{"price":11463288.0,"size":0.01},{"price":11464896.0,"size":0.002},{"price":11465382.0,"size":0.00195},{"price":11465421.0,"size":1.943},{"price":11466780.0,"size":0.001},{"price":11468700.0,"size":0.001},{"price":11470000.0,"size":0.06},{"price":11471000.0,"size":0.01},{"price":11475000.0,"size":0.0028},{"price":11476929.0,"size":1.0},{"price":11478102.0,"size":0.001},{"price":11478431.0,"size":0.002},{"price":11478700.0,"size":0.001},{"price":11480000.0,"size":0.40191},{"price":11485000.0,"size":0.01},{"price":11485488.0,"size":2.0},{"price":11486555.0,"size":0.03},{"price":11487685.0,"size":0.01},{"price":11488000.0,"size":0.102},{"price":11488700.0,"size":0.001},{"price":11489425.0,"size":0.001},{"price":11490000.0,"size":0.05},{"price":11490841.0,"size":0.002},{"price":11495450.0,"size":0.002},{"price":11495850.0,"size":0.001},{"price":11498700.0,"size":0.001},{"price":11498917.0,"size":0.002},{"price":11499000.0,"size":0.01},{"price":11500000.0,"size":0.77159519},{"price":11500078.0,"size":0.93},{"price":11500747.0,"size":0.001},{"price":11502377.0,"size":0.002},{"price":11502800.0,"size":0.00132},{"price":11503108.0,"size":0.0198},{"price":11505000.0,"size":0.0028},{"price":11505001.0,"size":0.002},{"price":11505836.0,"size":0.003},{"price":11508431.0,"size":0.047},{"price":11508700.0,"size":0.001},{"price":11508888.0,"size":0.02},{"price":11510000.0,"size":0.1476},{"price":11512070.0,"size":0.001},{"price":11513633.0,"size":0.08},{"price":11514332.0,"size":0.02},{"price":11518700.0,"size":0.001},{"price":11518992.0,"size":0.002},{"price":11519855.0,"size":0.01},{"price":11520000.0,"size":0.001},{"price":11522388.0,"size":0.972},{"price":11523211.0,"size":0.01},{"price":11524999.0,"size":0.001},{"price":11528700.0,"size":0.001},{"price":11529852.0,"size":0.01},{"price":11530000.0,"size":0.261},{"price":11533985.0,"size":0.002},{"price":11534084.0,"size":0.001},{"price":11535321.0,"size":0.01},{"price":11538666.0,"size":0.002},{"price":11538700.0,"size":0.001},{"price":11540000.0,"size":0.0048},{"price":11540357.0,"size":0.002},{"price":11541011.0,"size":0.005},{"price":11541109.0,"size":0.01},{"price":11544663.0,"size":0.002},{"price":11545262.0,"size":0.002},{"price":11546541.0,"size":0.01},{"price":11548144.0,"size":0.002},{"price":11548700.0,"size":0.001},{"price":11550000.0,"size":0.014},{"price":11551109.0,"size":0.01},{"price":11551625.0,"size":0.002},{"price":11552111.0,"size":0.01},{"price":11553687.0,"size":0.1},{"price":11555106.0,"size":0.002},{"price":11555115.0,"size":0.001},{"price":11556000.0,"size":0.1},{"price":11558587.0,"size":0.002},{"price":11558700.0,"size":0.001},{"price":11559855.0,"size":0.01},{"price":11560831.0,"size":0.0198},{"price":11561109.0,"size":0.01},{"price":11562000.0,"size":0.087},{"price":11562068.0,"size":0.002},{"price":11563750.0,"size":0.08739676},{"price":11565548.0,"size":0.002},{"price":11566139.0,"size":0.0228},{"price":11566551.0,"size":0.01},{"price":11568700.0,"size":0.001},{"price":11569029.0,"size":0.002},{"price":11570196.0,"size":0.002},{"price":11571109.0,"size":0.01},{"price":11572510.0,"size":0.002},{"price":11573211.0,"size":0.01},{"price":11574840.0,"size":0.002},{"price":11575991.0,"size":0.001},{"price":11578700.0,"size":0.001},{"price":11579484.0,"size":0.002},{"price":11579851.0,"size":0.01},{"price":11580000.0,"size":0.7835},{"price":11581109.0,"size":0.01},{"price":11584128.0,"size":0.002},{"price":11585000.0,"size":0.002},{"price":11586532.0,"size":0.01},{"price":11587498.0,"size":0.0198},{"price":11588700.0,"size":0.001},{"price":11588800.0,"size":0.02},{"price":11590000.0,"size":0.1},{"price":11590749.0,"size":0.002},{"price":11590987.0,"size":0.012},{"price":11591109.0,"size":0.01},{"price":11593211.0,"size":0.01},{"price":11596753.0,"size":0.002},{"price":11598111.0,"size":0.1474},{"price":11598555.0,"size":0.01},{"price":11598700.0,"size":0.001},{"price":11599999.0,"size":0.001},{"price":11600000.0,"size":3.655},{"price":11601109.0,"size":0.02},{"price":11603764.0,"size":0.9},{"price":11606655.0,"size":0.01},{"price":11610000.0,"size":0.302},{"price":11611109.0,"size":0.01},{"price":11613321.0,"size":0.01},{"price":11620000.0,"size":1.35441682},{"price":11621011.0,"size":0.01},{"price":11621109.0,"size":0.01},{"price":11623096.0,"size":0.008},{"price":11629000.0,"size":0.1},{"price":11630000.0,"size":0.201},{"price":11631059.0,"size":0.01},{"price":11631479.0,"size":0.01},{"price":11631773.0,"size":0.00386871},{"price":11635950.0,"size":0.001},{"price":11638259.0,"size":0.001},{"price":11639700.0,"size":0.001},{"price":11640000.0,"size":1.0},{"price":11640820.0,"size":0.01},{"price":11649900.0,"size":0.02906},{"price":11649999.0,"size":0.001},{"price":11650000.0,"size":0.593},{"price":11651059.0,"size":0.01},{"price":11653658.0,"size":0.008},{"price":11654321.0,"size":0.001},{"price":11659700.0,"size":0.001},{"price":11661479.0,"size":0.01},{"price":11666000.0,"size":0.001},{"price":11666666.0,"size":0.013},{"price":11669700.0,"size":0.001},{"price":11671059.0,"size":0.01},{"price":11672562.0,"size":0.0198},{"price":11680000.0,"size":0.014},{"price":11681974.0,"size":0.012},{"price":11685000.0,"size":0.003},{"price":11688000.0,"size":0.001},{"price":11689732.0,"size":0.01},{"price":11690330.0,"size":0.0198},{"price":11691059.0,"size":0.01},{"price":11692558.0,"size":0.01},{"price":11695019.0,"size":0.0064},{"price":11698800.0,"size":0.00131},{"price":11699000.0,"size":0.001},{"price":11699631.0,"size":0.001},{"price":11699998.0,"size":0.01},{"price":11699999.0,"size":0.001},{"price":11700000.0,"size":1.2573},{"price":11701059.0,"size":0.01},{"price":11720000.0,"size":0.1},{"price":11721059.0,"size":0.01},{"price":11725000.0,"size":0.005},{"price":11726791.0,"size":0.01},{"price":11727418.0,"size":1.8},{"price":11728195.0,"size":0.05},{"price":11730000.0,"size":1.9712},{"price":11740000.0,"size":0.101},{"price":11741059.0,"size":0.01},{"price":11748937.0,"size":0.001},{"price":11749999.0,"size":0.001},{"price":11750000.0,"size":0.89537866},{"price":11750050.0,"size":0.2},{"price":11751151.0,"size":0.01},{"price":11755000.0,"size":0.001},{"price":11757860.0,"size":1.82},{"price":11759999.0,"size":0.001},{"price":11760000.0,"size":0.001},{"price":11761059.0,"size":0.02},{"price":11765432.0,"size":0.001},{"price":11768000.0,"size":0.01},{"price":11770000.0,"size":0.25464896},{"price":11771059.0,"size":0.01755555},{"price":11772000.0,"size":0.002},{"price":11772961.0,"size":0.012},{"price":11775000.0,"size":0.11593},{"price":11775222.0,"size":0.001657},{"price":11775577.0,"size":0.00013523},{"price":11775800.0,"size":0.001},{"price":11775900.0,"size":0.2},{"price":11775989.0,"size":0.005},{"price":11777000.0,"size":0.5956},{"price":11777777.0,"size":0.0067},{"price":11778541.0,"size":0.001},{"price":11779807.0,"size":0.001},{"price":11780000.0,"size":0.74298},{"price":11780800.0,"size":0.1},{"price":11781059.0,"size":0.01},{"price":11781238.0,"size":0.008},{"price":11785000.0,"size":0.055},{"price":11785040.0,"size":0.01},{"price":11786000.0,"size":0.585},{"price":11788000.0,"size":0.001},{"price":11788888.0,"size":0.005},{"price":11789000.0,"size":0.2},{"price":11789732.0,"size":0.01},{"price":11791100.0,"size":0.1}]}}}
{"schema_version":"collector.vnext.raw","schema_contract":null,"schema_contract_version":null,"payload_contract_version":null,"record_type":"market.orderbook.diff","record_id":"collector_main-market-orderbook-diff-000000000061","collector_id":"collector_main","collector_role":"production","host_name":"MAIN-PC","session_id":"collector_main-sess-20260315T000019Z-d85163b0","stream_session_id":"collector_main-stream-bitflyer-board_ws-20260315T000027Z-641c1a4f","exchange":"bitflyer","market":"spot","symbol":"BTC_JPY","instrument_id":"bitflyer.spot.BTC_JPY","channel":"board_ws","transport":"websocket","source_event_id":null,"source_sequence":null,"sequence_id":61,"exchange_ts":null,"collector_ts":"2026-03-15T00:00:27Z","ingest_ts":"2026-03-15T00:00:27Z","event_ts":"2026-03-15T00:00:27Z","quality_flags":[],"is_partial":false,"is_reconstructed":false,"confidence_score":1.0,"payload":{"provider":"bitflyer_ws_board","exchange":"bitflyer","transport":"websocket","channel":"lightning_board_BTC_JPY","received_ts":"2026-03-15T00:00:27.273238Z","subscription_id":null,"message_id":null,"source_sequence":null,"raw_message_meta":{"raw_channel":"lightning_board_BTC_JPY","subscription_channel":"lightning_board_BTC_JPY","recv_timeout_sec":10,"ssl_verify":false,"socket_url":"wss://ws.lightstream.bitflyer.com/json-rpc"},"source_payload":{"mid_price":11391353.0,"bids":[{"price":11387606.0,"size":0.0},{"price":11387608.0,"size":0.26}],"asks":[]}}}
{"schema_version":"collector.vnext.raw","schema_contract":null,"schema_contract_version":null,"payload_contract_version":null,"record_type":"market.orderbook.diff","record_id":"collector_main-market-orderbook-diff-000000000065","collector_id":"collector_main","collector_role":"production","host_name":"MAIN-PC","session_id":"collector_main-sess-20260315T000019Z-d85163b0","stream_session_id":"collector_main-stream-bitflyer-board_ws-20260315T000027Z-641c1a4f","exchange":"bitflyer","market":"spot","symbol":"BTC_JPY","instrument_id":"bitflyer.spot.BTC_JPY","channel":"board_ws","transport":"websocket","source_event_id":null,"source_sequence":null,"sequence_id":65,"exchange_ts":null,"collector_ts":"2026-03-15T00:00:27Z","ingest_ts":"2026-03-15T00:00:27Z","event_ts":"2026-03-15T00:00:27Z","quality_flags":[],"is_partial":false,"is_reconstructed":false,"confidence_score":1.0,"payload":{"provider":"bitflyer_ws_board","exchange":"bitflyer","transport":"websocket","channel":"lightning_board_BTC_JPY","received_ts":"2026-03-15T00:00:27.405845Z","subscription_id":null,"message_id":null,"source_sequence":null,"raw_message_meta":{"raw_channel":"lightning_board_BTC_JPY","subscription_channel":"lightning_board_BTC_JPY","recv_timeout_sec":10,"ssl_verify":false,"socket_url":"wss://ws.lightstream.bitflyer.com/json-rpc"},"source_payload":{"mid_price":11391353.0,"bids":[{"price":11370716.0,"size":0.35}],"asks":[]}}}
{"schema_version":"collector.vnext.raw","schema_contract":null,"schema_contract_version":null,"payload_contract_version":null,"record_type":"market.orderbook.diff","record_id":"collector_main-market-orderbook-diff-000000000067","collector_id":"collector_main","collector_role":"production","host_name":"MAIN-PC","session_id":"collector_main-sess-20260315T000019Z-d85163b0","stream_session_id":"collector_main-stream-bitflyer-board_ws-20260315T000027Z-641c1a4f","exchange":"bitflyer","market":"spot","symbol":"BTC_JPY","instrument_id":"bitflyer.spot.BTC_JPY","channel":"board_ws","transport":"websocket","source_event_id":null,"source_sequence":null,"sequence_id":67,"exchange_ts":null,"collector_ts":"2026-03-15T00:00:27Z","ingest_ts":"2026-03-15T00:00:27Z","event_ts":"2026-03-15T00:00:27Z","quality_flags":[],"is_partial":false,"is_reconstructed":false,"confidence_score":1.0,"payload":{"provider":"bitflyer_ws_board","exchange":"bitflyer","transport":"websocket","channel":"lightning_board_BTC_JPY","received_ts":"2026-03-15T00:00:27.508122Z","subscription_id":null,"message_id":null,"source_sequence":null,"raw_message_meta":{"raw_channel":"lightning_board_BTC_JPY","subscription_channel":"lightning_board_BTC_JPY","recv_timeout_sec":10,"ssl_verify":false,"socket_url":"wss://ws.lightstream.bitflyer.com/json-rpc"},"source_payload":{"mid_price":11391353.0,"bids":[{"price":11387607.0,"size":0.0},{"price":11383203.0,"size":0.0},{"price":11387609.0,"size":0.05538633},{"price":11383099.0,"size":0.0109109},{"price":11377445.0,"size":0.06}],"asks":[]}}}
{"schema_version":"collector.vnext.raw","schema_contract":null,"schema_contract_version":null,"payload_contract_version":null,"record_type":"market.orderbook.diff","record_id":"collector_main-market-orderbook-diff-000000000069","collector_id":"collector_main","collector_role":"production","host_name":"MAIN-PC","session_id":"collector_main-sess-20260315T000019Z-d85163b0","stream_session_id":"collector_main-stream-bitflyer-board_ws-20260315T000027Z-641c1a4f","exchange":"bitflyer","market":"spot","symbol":"BTC_JPY","instrument_id":"bitflyer.spot.BTC_JPY","channel":"board_ws","transport":"websocket","source_event_id":null,"source_sequence":null,"sequence_id":69,"exchange_ts":null,"collector_ts":"2026-03-15T00:00:27Z","ingest_ts":"2026-03-15T00:00:27Z","event_ts":"2026-03-15T00:00:27Z","quality_flags":[],"is_partial":false,"is_reconstructed":false,"confidence_score":1.0,"payload":{"provider":"bitflyer_ws_board","exchange":"bitflyer","transport":"websocket","channel":"lightning_board_BTC_JPY","received_ts":"2026-03-15T00:00:27.866583Z","subscription_id":null,"message_id":null,"source_sequence":null,"raw_message_meta":{"raw_channel":"lightning_board_BTC_JPY","subscription_channel":"lightning_board_BTC_JPY","recv_timeout_sec":10,"ssl_verify":false,"socket_url":"wss://ws.lightstream.bitflyer.com/json-rpc"},"source_payload":{"mid_price":11391353.0,"bids":[{"price":11387608.0,"size":0.0},{"price":11376410.0,"size":0.0}],"asks":[]}}}
{"schema_version":"collector.vnext.raw","schema_contract":null,"schema_contract_version":null,"payload_contract_version":null,"record_type":"market.orderbook.diff","record_id":"collector_main-market-orderbook-diff-000000000071","collector_id":"collector_main","collector_role":"production","host_name":"MAIN-PC","session_id":"collector_main-sess-20260315T000019Z-d85163b0","stream_session_id":"collector_main-stream-bitflyer-board_ws-20260315T000027Z-641c1a4f","exchange":"bitflyer","market":"spot","symbol":"BTC_JPY","instrument_id":"bitflyer.spot.BTC_JPY","channel":"board_ws","transport":"websocket","source_event_id":null,"source_sequence":null,"sequence_id":71,"exchange_ts":null,"collector_ts":"2026-03-15T00:00:27Z","ingest_ts":"2026-03-15T00:00:27Z","event_ts":"2026-03-15T00:00:27Z","quality_flags":[],"is_partial":false,"is_reconstructed":false,"confidence_score":1.0,"payload":{"provider":"bitflyer_ws_board","exchange":"bitflyer","transport":"websocket","channel":"lightning_board_BTC_JPY","received_ts":"2026-03-15T00:00:27.971530Z","subscription_id":null,"message_id":null,"source_sequence":null,"raw_message_meta":{"raw_channel":"lightning_board_BTC_JPY","subscription_channel":"lightning_board_BTC_JPY","recv_timeout_sec":10,"ssl_verify":false,"socket_url":"wss://ws.lightstream.bitflyer.com/json-rpc"},"source_payload":{"mid_price":11391353.0,"bids":[],"asks":[{"price":11395098.0,"size":0.02416685}]}}}
{"schema_version":"collector.vnext.raw","schema_contract":null,"schema_contract_version":null,"payload_contract_version":null,"record_type":"market.orderbook.diff","record_id":"collector_main-market-orderbook-diff-000000000073","collector_id":"collector_main","collector_role":"production","host_name":"MAIN-PC","session_id":"collector_main-sess-20260315T000019Z-d85163b0","stream_session_id":"collector_main-stream-bitflyer-board_ws-20260315T000027Z-641c1a4f","exchange":"bitflyer","market":"spot","symbol":"BTC_JPY","instrument_id":"bitflyer.spot.BTC_JPY","channel":"board_ws","transport":"websocket","source_event_id":null,"source_sequence":null,"sequence_id":73,"exchange_ts":null,"collector_ts":"2026-03-15T00:00:28Z","ingest_ts":"2026-03-15T00:00:28Z","event_ts":"2026-03-15T00:00:28Z","quality_flags":[],"is_partial":false,"is_reconstructed":false,"confidence_score":1.0,"payload":{"provider":"bitflyer_ws_board","exchange":"bitflyer","transport":"websocket","channel":"lightning_board_BTC_JPY","received_ts":"2026-03-15T00:00:28.076483Z","subscription_id":null,"message_id":null,"source_sequence":null,"raw_message_meta":{"raw_channel":"lightning_board_BTC_JPY","subscription_channel":"lightning_board_BTC_JPY","recv_timeout_sec":10,"ssl_verify":false,"socket_url":"wss://ws.lightstream.bitflyer.com/json-rpc"},"source_payload":{"mid_price":11391354.0,"bids":[{"price":11387610.0,"size":0.18},{"price":11387609.0,"size":0.0},{"price":11380160.0,"size":0.0}],"asks":[]}}}
{"schema_version":"collector.vnext.raw","schema_contract":null,"schema_contract_version":null,"payload_contract_version":null,"record_type":"market.orderbook.diff","record_id":"collector_main-market-orderbook-diff-000000000075","collector_id":"collector_main","collector_role":"production","host_name":"MAIN-PC","session_id":"collector_main-sess-20260315T000019Z-d85163b0","stream_session_id":"collector_main-stream-bitflyer-board_ws-20260315T000027Z-641c1a4f","exchange":"bitflyer","market":"spot","symbol":"BTC_JPY","instrument_id":"bitflyer.spot.BTC_JPY","channel":"board_ws","transport":"websocket","source_event_id":null,"source_sequence":null,"sequence_id":75,"exchange_ts":null,"collector_ts":"2026-03-15T00:00:28Z","ingest_ts":"2026-03-15T00:00:28Z","event_ts":"2026-03-15T00:00:28Z","quality_flags":[],"is_partial":false,"is_reconstructed":false,"confidence_score":1.0,"payload":{"provider":"bitflyer_ws_board","exchange":"bitflyer","transport":"websocket","channel":"lightning_board_BTC_JPY","received_ts":"2026-03-15T00:00:28.179767Z","subscription_id":null,"message_id":null,"source_sequence":null,"raw_message_meta":{"raw_channel":"lightning_board_BTC_JPY","subscription_channel":"lightning_board_BTC_JPY","recv_timeout_sec":10,"ssl_verify":false,"socket_url":"wss://ws.lightstream.bitflyer.com/json-rpc"},"source_payload":{"mid_price":11391354.0,"bids":[{"price":11387604.0,"size":0.06038673}],"asks":[]}}}
{"schema_version":"collector.vnext.raw","schema_contract":null,"schema_contract_version":null,"payload_contract_version":null,"record_type":"market.orderbook.diff","record_id":"collector_main-market-orderbook-diff-000000000077","collector_id":"collector_main","collector_role":"production","host_name":"MAIN-PC","session_id":"collector_main-sess-20260315T000019Z-d85163b0","stream_session_id":"collector_main-stream-bitflyer-board_ws-20260315T000027Z-641c1a4f","exchange":"bitflyer","market":"spot","symbol":"BTC_JPY","instrument_id":"bitflyer.spot.BTC_JPY","channel":"board_ws","transport":"websocket","source_event_id":null,"source_sequence":null,"sequence_id":77,"exchange_ts":null,"collector_ts":"2026-03-15T00:00:28Z","ingest_ts":"2026-03-15T00:00:28Z","event_ts":"2026-03-15T00:00:28Z","quality_flags":[],"is_partial":false,"is_reconstructed":false,"confidence_score":1.0,"payload":{"provider":"bitflyer_ws_board","exchange":"bitflyer","transport":"websocket","channel":"lightning_board_BTC_JPY","received_ts":"2026-03-15T00:00:28.302759Z","subscription_id":null,"message_id":null,"source_sequence":null,"raw_message_meta":{"raw_channel":"lightning_board_BTC_JPY","subscription_channel":"lightning_board_BTC_JPY","recv_timeout_sec":10,"ssl_verify":false,"socket_url":"wss://ws.lightstream.bitflyer.com/json-rpc"},"source_payload":{"mid_price":11391354.0,"bids":[{"price":11387604.0,"size":0.0}],"asks":[]}}}
{"schema_version":"collector.vnext.raw","schema_contract":null,"schema_contract_version":null,"payload_contract_version":null,"record_type":"market.orderbook.diff","record_id":"collector_main-market-orderbook-diff-000000000079","collector_id":"collector_main","collector_role":"production","host_name":"MAIN-PC","session_id":"collector_main-sess-20260315T000019Z-d85163b0","stream_session_id":"collector_main-stream-bitflyer-board_ws-20260315T000027Z-641c1a4f","exchange":"bitflyer","market":"spot","symbol":"BTC_JPY","instrument_id":"bitflyer.spot.BTC_JPY","channel":"board_ws","transport":"websocket","source_event_id":null,"source_sequence":null,"sequence_id":79,"exchange_ts":null,"collector_ts":"2026-03-15T00:00:28Z","ingest_ts":"2026-03-15T00:00:28Z","event_ts":"2026-03-15T00:00:28Z","quality_flags":[],"is_partial":false,"is_reconstructed":false,"confidence_score":1.0,"payload":{"provider":"bitflyer_ws_board","exchange":"bitflyer","transport":"websocket","channel":"lightning_board_BTC_JPY","received_ts":"2026-03-15T00:00:28.494922Z","subscription_id":null,"message_id":null,"source_sequence":null,"raw_message_meta":{"raw_channel":"lightning_board_BTC_JPY","subscription_channel":"lightning_board_BTC_JPY","recv_timeout_sec":10,"ssl_verify":false,"socket_url":"wss://ws.lightstream.bitflyer.com/json-rpc"},"source_payload":{"mid_price":11391354.0,"bids":[{"price":11387611.0,"size":0.05784777},{"price":11383099.0,"size":0.0},{"price":11377445.0,"size":0.0}],"asks":[]}}}
{"schema_version":"collector.vnext.raw","schema_contract":null,"schema_contract_version":null,"payload_contract_version":null,"record_type":"market.orderbook.diff","record_id":"collector_main-market-orderbook-diff-000000000081","collector_id":"collector_main","collector_role":"production","host_name":"MAIN-PC","session_id":"collector_main-sess-20260315T000019Z-d85163b0","stream_session_id":"collector_main-stream-bitflyer-board_ws-20260315T000027Z-641c1a4f","exchange":"bitflyer","market":"spot","symbol":"BTC_JPY","instrument_id":"bitflyer.spot.BTC_JPY","channel":"board_ws","transport":"websocket","source_event_id":null,"source_sequence":null,"sequence_id":81,"exchange_ts":null,"collector_ts":"2026-03-15T00:00:28Z","ingest_ts":"2026-03-15T00:00:28Z","event_ts":"2026-03-15T00:00:28Z","quality_flags":[],"is_partial":false,"is_reconstructed":false,"confidence_score":1.0,"payload":{"provider":"bitflyer_ws_board","exchange":"bitflyer","transport":"websocket","channel":"lightning_board_BTC_JPY","received_ts":"2026-03-15T00:00:28.606098Z","subscription_id":null,"message_id":null,"source_sequence":null,"raw_message_meta":{"raw_channel":"lightning_board_BTC_JPY","subscription_channel":"lightning_board_BTC_JPY","recv_timeout_sec":10,"ssl_verify":false,"socket_url":"wss://ws.lightstream.bitflyer.com/json-rpc"},"source_payload":{"mid_price":11391354.0,"bids":[{"price":11383159.0,"size":0.0111336},{"price":11376366.0,"size":0.1},{"price":11387610.0,"size":0.0}],"asks":[]}}}
{"schema_version":"collector.vnext.raw","schema_contract":null,"schema_contract_version":null,"payload_contract_version":null,"record_type":"market.orderbook.diff","record_id":"collector_main-market-orderbook-diff-000000000083","collector_id":"collector_main","collector_role":"production","host_name":"MAIN-PC","session_id":"collector_main-sess-20260315T000019Z-d85163b0","stream_session_id":"collector_main-stream-bitflyer-board_ws-20260315T000027Z-641c1a4f","exchange":"bitflyer","market":"spot","symbol":"BTC_JPY","instrument_id":"bitflyer.spot.BTC_JPY","channel":"board_ws","transport":"websocket","source_event_id":null,"source_sequence":null,"sequence_id":83,"exchange_ts":null,"collector_ts":"2026-03-15T00:00:28Z","ingest_ts":"2026-03-15T00:00:28Z","event_ts":"2026-03-15T00:00:28Z","quality_flags":[],"is_partial":false,"is_reconstructed":false,"confidence_score":1.0,"payload":{"provider":"bitflyer_ws_board","exchange":"bitflyer","transport":"websocket","channel":"lightning_board_BTC_JPY","received_ts":"2026-03-15T00:00:28.704159Z","subscription_id":null,"message_id":null,"source_sequence":null,"raw_message_meta":{"raw_channel":"lightning_board_BTC_JPY","subscription_channel":"lightning_board_BTC_JPY","recv_timeout_sec":10,"ssl_verify":false,"socket_url":"wss://ws.lightstream.bitflyer.com/json-rpc"},"source_payload":{"mid_price":11391354.0,"bids":[],"asks":[{"price":11395306.0,"size":0.0}]}}}
{"schema_version":"collector.vnext.raw","schema_contract":null,"schema_contract_version":null,"payload_contract_version":null,"record_type":"market.orderbook.diff","record_id":"collector_main-market-orderbook-diff-000000000085","collector_id":"collector_main","collector_role":"production","host_name":"MAIN-PC","session_id":"collector_main-sess-20260315T000019Z-d85163b0","stream_session_id":"collector_main-stream-bitflyer-board_ws-20260315T000027Z-641c1a4f","exchange":"bitflyer","market":"spot","symbol":"BTC_JPY","instrument_id":"bitflyer.spot.BTC_JPY","channel":"board_ws","transport":"websocket","source_event_id":null,"source_sequence":null,"sequence_id":85,"exchange_ts":null,"collector_ts":"2026-03-15T00:00:28Z","ingest_ts":"2026-03-15T00:00:28Z","event_ts":"2026-03-15T00:00:28Z","quality_flags":[],"is_partial":false,"is_reconstructed":false,"confidence_score":1.0,"payload":{"provider":"bitflyer_ws_board","exchange":"bitflyer","transport":"websocket","channel":"lightning_board_BTC_JPY","received_ts":"2026-03-15T00:00:28.845150Z","subscription_id":null,"message_id":null,"source_sequence":null,"raw_message_meta":{"raw_channel":"lightning_board_BTC_JPY","subscription_channel":"lightning_board_BTC_JPY","recv_timeout_sec":10,"ssl_verify":false,"socket_url":"wss://ws.lightstream.bitflyer.com/json-rpc"},"source_payload":{"mid_price":11391350.0,"bids":[{"price":11387611.0,"size":0.0}],"asks":[]}}}
{"schema_version":"collector.vnext.raw","schema_contract":null,"schema_contract_version":null,"payload_contract_version":null,"record_type":"market.orderbook.snapshot","record_id":"collector_main-market-orderbook-snapshot-000000000087","collector_id":"collector_main","collector_role":"production","host_name":"MAIN-PC","session_id":"collector_main-sess-20260315T000019Z-d85163b0","stream_session_id":"collector_main-stream-bitflyer-board_ws-20260315T000027Z-641c1a4f","exchange":"bitflyer","market":"spot","symbol":"BTC_JPY","instrument_id":"bitflyer.spot.BTC_JPY","channel":"board_ws","transport":"websocket","source_event_id":null,"source_sequence":null,"sequence_id":87,"exchange_ts":null,"collector_ts":"2026-03-15T00:00:29Z","ingest_ts":"2026-03-15T00:00:29Z","event_ts":"2026-03-15T00:00:29Z","quality_flags":[],"is_partial":false,"is_reconstructed":false,"confidence_score":1.0,"payload":{"provider":"bitflyer_ws_board_snapshot","exchange":"bitflyer","transport":"websocket","channel":"lightning_board_snapshot_BTC_JPY","received_ts":"2026-03-15T00:00:29.920365Z","subscription_id":null,"message_id":null,"source_sequence":null,"raw_message_meta":{"raw_channel":"lightning_board_snapshot_BTC_JPY","subscription_channel":"lightning_board_snapshot_BTC_JPY","recv_timeout_sec":10,"ssl_verify":false,"socket_url":"wss://ws.lightstream.bitflyer.com/json-rpc"},"source_payload":{"mid_price":11391351.0,"bids":[{"price":11387604.0,"size":0.0605431},{"price":11387603.0,"size":0.015324},{"price":11387599.0,"size":0.015144},{"price":11387553.0,"size":0.015012},{"price":11387551.0,"size":0.14045},{"price":11386643.0,"size":0.005},{"price":11386011.0,"size":0.00999794},{"price":11385177.0,"size":0.5},{"price":11385002.0,"size":0.01},{"price":11384050.0,"size":0.5},{"price":11383159.0,"size":0.0111336},{"price":11382812.0,"size":0.0554688},{"price":11380161.0,"size":3.11270527},{"price":11380159.0,"size":0.0527},{"price":11380121.0,"size":0.01},{"price":11379514.0,"size":0.34565489},{"price":11378702.0,"size":0.0751},{"price":11376893.0,"size":1.50015},{"price":11376366.0,"size":0.1},{"price":11375000.0,"size":0.03},{"price":11374387.0,"size":0.34267324},{"price":11373916.0,"size":0.07},{"price":11371189.0,"size":0.97658726},{"price":11371183.0,"size":0.24},{"price":11370955.0,"size":0.27},{"price":11370716.0,"size":0.35},{"price":11370000.0,"size":0.005},{"price":11368376.0,"size":0.01},{"price":11367661.0,"size":0.002},{"price":11366676.0,"size":0.3123},{"price":11365953.0,"size":0.002},{"price":11363915.0,"size":0.12856523},{"price":11363914.0,"size":0.2627},{"price":11363103.0,"size":0.002},{"price":11362535.0,"size":0.002},{"price":11362394.0,"size":1.484},{"price":11361152.0,"size":0.2587},{"price":11359117.0,"size":0.002},{"price":11358545.0,"size":0.002},{"price":11358390.0,"size":0.2599},{"price":11358376.0,"size":0.01},{"price":11357601.0,"size":0.22},{"price":11356870.0,"size":0.6},{"price":11355699.0,"size":0.002},{"price":11350000.0,"size":0.51},{"price":11349429.0,"size":0.002},{"price":11348863.0,"size":0.002},{"price":11348189.0,"size":0.003},{"price":11347667.0,"size":0.001},{"price":11345445.0,"size":0.002},{"price":11344871.0,"size":0.002},{"price":11342981.0,"size":1.966},{"price":11342027.0,"size":0.002},{"price":11340313.0,"size":0.002},{"price":11340000.0,"size":0.005},{"price":11338609.0,"size":0.002},{"price":11336383.0,"size":0.001},{"price":11336319.0,"size":0.00195},{"price":11335755.0,"size":0.002},{"price":11335191.0,"size":0.002},{"price":11332840.0,"size":2.036},{"price":11331197.0,"size":0.002},{"price":11331000.0,"size":0.5},{"price":11330000.0,"size":0.02442},{"price":11326639.0,"size":0.002},{"price":11325101.0,"size":0.001},{"price":11320000.0,"size":0.05},{"price":11315000.0,"size":0.05},{"price":11314325.0,"size":1.951},{"price":11313996.0,"size":0.00195},{"price":11313819.0,"size":0.001},{"price":11310000.0,"size":0.01},{"price":11309999.0,"size":0.177},{"price":11307999.0,"size":0.01},{"price":11303918.0,"size":0.01},{"price":11303000.0,"size":0.5},{"price":11302535.0,"size":0.001},{"price":11302466.0,"size":0.001},{"price":11301268.0,"size":0.01},{"price":11300000.0,"size":3.01685256},{"price":11298000.0,"size":0.01},{"price":11297527.0,"size":1.13},{"price":11296865.0,"size":0.0015},{"price":11294756.0,"size":1.0},{"price":11291282.0,"size":0.001},{"price":11291268.0,"size":0.01},{"price":11291000.0,"size":0.5},{"price":11290000.0,"size":0.003},{"price":11281268.0,"size":0.01},{"price":11280000.0,"size":0.0163},{"price":11279960.0,"size":0.001},{"price":11279282.0,"size":0.0015},{"price":11278000.0,"size":0.0025},{"price":11275000.0,"size":0.001},{"price":11274588.0,"size":0.0047},{"price":11271268.0,"size":0.01},{"price":11271000.0,"size":0.003},{"price":11270000.0,"size":0.106},{"price":11269424.0,"size":0.8},{"price":11268871.0,"size":0.28},{"price":11268638.0,"size":0.001},{"price":11268411.0,"size":0.01},{"price":11266666.0,"size":0.04},{"price":11265000.0,"size":0.02},{"price":11263000.0,"size":0.006},{"price":11262564.0,"size":0.0015},{"price":11261268.0,"size":0.01},{"price":11260000.0,"size":0.3565},{"price":11257315.0,"size":0.001},{"price":11257000.0,"size":0.001},{"price":11255200.0,"size":0.001},{"price":11255115.0,"size":0.00377},{"price":11253814.0,"size":2.2},{"price":11253690.0,"size":0.01},{"price":11253000.0,"size":0.03189},{"price":11251405.0,"size":0.139},{"price":11251268.0,"size":0.01},{"price":11251111.0,"size":0.0015},{"price":11251000.0,"size":0.0131},{"price":11250250.0,"size":0.00105},{"price":11250200.0,"size":0.001},{"price":11250005.0,"size":0.001},{"price":11250001.0,"size":0.00104},{"price":11250000.0,"size":1.62712889},{"price":11245993.0,"size":0.001},{"price":11245141.0,"size":0.0031},{"price":11245000.0,"size":0.05},{"price":11244444.0,"size":0.04},{"price":11244243.0,"size":0.01},{"price":11240200.0,"size":0.001},{"price":11240000.0,"size":0.007304},{"price":11236190.0,"size":0.01},{"price":11235200.0,"size":0.001},{"price":11234670.0,"size":0.001},{"price":11232000.0,"size":0.089},{"price":11231243.0,"size":0.01},{"price":11231000.0,"size":0.105},{"price":11230200.0,"size":0.001},{"price":11230000.0,"size":0.0308},{"price":11226952.0,"size":0.972},{"price":11224500.0,"size":0.06},{"price":11223968.0,"size":0.001},{"price":11223348.0,"size":0.001},{"price":11223344.0,"size":0.01},{"price":11223000.0,"size":0.1},{"price":11222222.0,"size":0.093525},{"price":11221120.0,"size":0.001},{"price":11220200.0,"size":0.001},{"price":11220001.0,"size":0.004457},{"price":11220000.0,"size":0.321},{"price":11219000.0,"size":0.1},{"price":11217326.0,"size":0.02},{"price":11215200.0,"size":0.001},{"price":11213690.0,"size":0.01},{"price":11212025.0,"size":0.001},{"price":11211800.0,"size":0.001},{"price":11211111.0,"size":0.06},{"price":11210200.0,"size":0.001},{"price":11210000.0,"size":0.10622},{"price":11208032.0,"size":0.01},{"price":11206000.0,"size":0.09015},{"price":11205200.0,"size":0.001},{"price":11204578.0,"size":0.002},{"price":11201000.0,"size":0.01},{"price":11200800.0,"size":0.05},{"price":11200703.0,"size":0.001},{"price":11200425.0,"size":0.1},{"price":11200200.0,"size":0.001},{"price":11200198.0,"size":0.003},{"price":11200150.0,"size":0.002},{"price":11200002.0,"size":0.001},{"price":11200001.0,"size":0.01104},{"price":11200000.0,"size":1.15226728},{"price":11198508.0,"size":0.05},{"price":11198243.0,"size":0.01},{"price":11197134.0,"size":0.993},{"price":11197000.0,"size":0.0085},{"price":11194090.0,"size":0.03},{"price":11190770.0,"size":0.0309},{"price":11190000.0,"size":0.0010016},{"price":11189555.0,"size":0.5},{"price":11189381.0,"size":0.001},{"price":11188629.0,"size":0.01},{"price":11188382.0,"size":0.001},{"price":11185000.0,"size":0.0085},{"price":11180000.0,"size":0.225},{"price":11178058.0,"size":0.001},{"price":11170000.0,"size":0.001},{"price":11169662.0,"size":0.01},{"price":11169593.0,"size":0.001},{"price":11169243.0,"size":0.01},{"price":11166736.0,"size":0.001},{"price":11164029.0,"size":0.001},{"price":11160854.0,"size":0.1},{"price":11160000.0,"size":0.02376},{"price":11155413.0,"size":0.001},{"price":11155377.0,"size":0.00636009},{"price":11153999.0,"size":0.00101},{"price":11151000.0,"size":0.001},{"price":11150250.0,"size":0.00175},{"price":11150005.0,"size":0.001},{"price":11150001.0,"size":0.00104},{"price":11150000.0,"size":0.6548956},{"price":11148000.0,"size":0.08963},{"price":11147546.0,"size":0.02},{"price":11144091.0,"size":0.001},{"price":11144000.0,"size":0.0897},{"price":11143986.0,"size":0.02},{"price":11140139.0,"size":1.0},{"price":11140000.0,"size":0.2},{"price":11136243.0,"size":0.01},{"price":11135869.0,"size":0.1},{"price":11132768.0,"size":0.001},{"price":11130000.0,"size":0.116},{"price":11129979.0,"size":0.0053908},{"price":11124900.0,"size":0.00133},{"price":11121090.0,"size":0.1},{"price":11120000.0,"size":0.0033},{"price":11118078.0,"size":0.01},{"price":11111800.0,"size":0.001},{"price":11111111.0,"size":0.2919257},{"price":11111000.0,"size":0.003},{"price":11110594.0,"size":0.001},{"price":11110000.0,"size":0.021007},{"price":11109662.0,"size":0.01},{"price":11108008.0,"size":0.01},{"price":11102000.0,"size":0.5},{"price":11101297.0,"size":0.001},{"price":11100005.0,"size":0.001},{"price":11100001.0,"size":0.01104},{"price":11100000.0,"size":1.6532049},{"price":11099141.0,"size":0.01},{"price":11098833.0,"size":0.002},{"price":11096243.0,"size":0.01},{"price":11094090.0,"size":0.01},{"price":11088888.0,"size":0.001},{"price":11085245.0,"size":0.001},{"price":11080200.0,"size":0.001},{"price":11080000.0,"size":0.0223},{"price":11075100.0,"size":0.003},{"price":11070200.0,"size":0.001},{"price":11070000.0,"size":0.0902},{"price":11065200.0,"size":0.001},{"price":11064370.0,"size":0.00497091},{"price":11060200.0,"size":0.001},{"price":11060000.0,"size":0.145},{"price":11059689.0,"size":0.009},{"price":11056428.0,"size":0.002},{"price":11055500.0,"size":0.02},{"price":11055200.0,"size":0.001},{"price":11055100.0,"size":0.003},{"price":11050200.0,"size":0.001},{"price":11050005.0,"size":0.001},{"price":11050002.0,"size":0.001},{"price":11050001.0,"size":0.00104},{"price":11050000.0,"size":0.39576147},{"price":11048064.0,"size":2.0},{"price":11046420.0,"size":0.2},{"price":11044243.0,"size":0.01},{"price":11041380.0,"size":0.01},{"price":11040200.0,"size":0.001},{"price":11040000.0,"size":0.00777181},{"price":11035865.0,"size":0.1},{"price":11035200.0,"size":0.001},{"price":11035000.0,"size":0.0013},{"price":11030200.0,"size":0.001},{"price":11030000.0,"size":0.025},{"price":11025500.0,"size":0.009531},{"price":11025200.0,"size":0.001},{"price":11025000.0,"size":0.71497},{"price":11020772.0,"size":0.014},{"price":11020200.0,"size":0.002},{"price":11020000.0,"size":0.005},{"price":11015200.0,"size":0.001},{"price":11012000.0,"size":0.1},{"price":11011800.0,"size":0.001},{"price":11010200.0,"size":0.001},{"price":11010000.0,"size":0.347},{"price":11007277.0,"size":0.01},{"price":11005200.0,"size":0.001},{"price":11004890.0,"size":0.001535},{"price":11003000.0,"size":0.0155},{"price":11001000.0,"size":0.013},{"price":11000500.0,"size":0.05117658},{"price":11000200.0,"size":0.001},{"price":11000002.0,"size":0.004},{"price":11000001.0,"size":0.02604},{"price":11000000.0,"size":4.53923365},{"price":10999999.0,"size":0.003},{"price":10999000.0,"size":0.001},{"price":10996855.0,"size":0.0011},{"price":10995200.0,"size":0.001},{"price":10994499.0,"size":0.00169176},{"price":10990200.0,"size":0.001},{"price":10990000.0,"size":0.10219},{"price":10989001.0,"size":0.00197},{"price":10988999.0,"size":0.001},{"price":10988324.0,"size":0.002},{"price":10987654.0,"size":0.001},{"price":10985200.0,"size":0.001}],"asks":[{"price":11395098.0,"size":0.02416685},{"price":11395099.0,"size":0.0509},{"price":11395341.0,"size":0.014568},{"price":11396000.0,"size":0.02},{"price":11396644.0,"size":0.00687018},{"price":11397218.0,"size":0.0147},{"price":11397517.0,"size":0.015144},{"price":11397805.0,"size":0.014988},{"price":11398134.0,"size":0.2684},{"price":11398297.0,"size":0.4249},{"price":11398444.0,"size":0.001995},{"price":11398845.0,"size":0.001},{"price":11399673.0,"size":0.0015},{"price":11399700.0,"size":0.001},{"price":11399900.0,"size":0.0554688},{"price":11399999.0,"size":0.05},{"price":11400000.0,"size":0.74832841},{"price":11400896.0,"size":0.2634},{"price":11402569.0,"size":0.01},{"price":11403472.0,"size":0.002},{"price":11403658.0,"size":0.2727},{"price":11403959.0,"size":0.01},{"price":11404999.0,"size":0.5717132},{"price":11405000.0,"size":0.1275},{"price":11405173.0,"size":0.0560475},{"price":11406420.0,"size":0.264},{"price":11408395.0,"size":0.0085},{"price":11408700.0,"size":0.001},{"price":11409415.0,"size":0.005},{"price":11409476.0,"size":1.189881},{"price":11409633.0,"size":1.189881},{"price":11410000.0,"size":0.3787},{"price":11410168.0,"size":0.001},{"price":11410853.0,"size":0.002},{"price":11412000.0,"size":0.0878},{"price":11415000.0,"size":0.1},{"price":11415141.0,"size":0.0041},{"price":11417481.0,"size":0.0015},{"price":11418700.0,"size":0.001},{"price":11419000.0,"size":0.01},{"price":11420000.0,"size":0.151},{"price":11421268.0,"size":0.05},{"price":11421490.0,"size":0.001},{"price":11424296.0,"size":0.002},{"price":11425000.0,"size":0.029},{"price":11425951.0,"size":0.21},{"price":11426426.0,"size":0.002},{"price":11428121.0,"size":0.002},{"price":11428700.0,"size":0.001},{"price":11429302.0,"size":0.01},{"price":11430000.0,"size":0.8098},{"price":11431752.0,"size":1.489},{"price":11432717.0,"size":1.53855676},{"price":11432718.0,"size":0.002},{"price":11432813.0,"size":0.001},{"price":11433211.0,"size":0.03},{"price":11433333.0,"size":0.001},{"price":11435877.0,"size":1.928},{"price":11437315.0,"size":0.002},{"price":11438525.0,"size":0.0011},{"price":11438700.0,"size":0.001},{"price":11439557.0,"size":0.001},{"price":11440000.0,"size":0.2538},{"price":11441911.0,"size":0.002},{"price":11442627.0,"size":2.018},{"price":11443629.0,"size":0.002},{"price":11444135.0,"size":0.001},{"price":11445433.0,"size":0.0015},{"price":11446508.0,"size":0.001},{"price":11447000.0,"size":0.01},{"price":11447071.0,"size":0.002},{"price":11448000.0,"size":0.0875},{"price":11448700.0,"size":0.001},{"price":11450000.0,"size":0.268},{"price":11451105.0,"size":0.002},{"price":11453321.0,"size":0.03},{"price":11455000.0,"size":0.001},{"price":11455457.0,"size":0.001},{"price":11455702.0,"size":0.002},{"price":11458700.0,"size":0.001},{"price":11458988.0,"size":0.01},{"price":11460000.0,"size":0.06702},{"price":11460299.0,"size":0.002},{"price":11463288.0,"size":0.01},{"price":11464896.0,"size":0.002},{"price":11465382.0,"size":0.00195},{"price":11465421.0,"size":1.943},{"price":11466780.0,"size":0.001},{"price":11468700.0,"size":0.001},{"price":11470000.0,"size":0.06},{"price":11471000.0,"size":0.01},{"price":11475000.0,"size":0.0028},{"price":11476929.0,"size":1.0},{"price":11478102.0,"size":0.001},{"price":11478431.0,"size":0.002},{"price":11478700.0,"size":0.001},{"price":11480000.0,"size":0.40191},{"price":11485000.0,"size":0.01},{"price":11485488.0,"size":2.0},{"price":11486555.0,"size":0.03},{"price":11487685.0,"size":0.01},{"price":11488000.0,"size":0.102},{"price":11488700.0,"size":0.001},{"price":11489425.0,"size":0.001},{"price":11490000.0,"size":0.05},{"price":11490841.0,"size":0.002},{"price":11495450.0,"size":0.002},{"price":11495850.0,"size":0.001},{"price":11498700.0,"size":0.001},{"price":11498917.0,"size":0.002},{"price":11499000.0,"size":0.01},{"price":11500000.0,"size":0.75959519},{"price":11500078.0,"size":0.93},{"price":11500747.0,"size":0.001},{"price":11502377.0,"size":0.002},{"price":11502800.0,"size":0.00132},{"price":11503108.0,"size":0.0198},{"price":11505000.0,"size":0.0028},{"price":11505001.0,"size":0.002},{"price":11505836.0,"size":0.003},{"price":11508431.0,"size":0.047},{"price":11508700.0,"size":0.001},{"price":11508888.0,"size":0.02},{"price":11510000.0,"size":0.1476},{"price":11512070.0,"size":0.001},{"price":11513633.0,"size":0.08},{"price":11514332.0,"size":0.02},{"price":11518700.0,"size":0.001},{"price":11518992.0,"size":0.002},{"price":11519855.0,"size":0.01},{"price":11520000.0,"size":0.001},{"price":11522388.0,"size":0.972},{"price":11523211.0,"size":0.01},{"price":11524999.0,"size":0.001},{"price":11528700.0,"size":0.001},{"price":11529852.0,"size":0.01},{"price":11530000.0,"size":0.261},{"price":11533985.0,"size":0.002},{"price":11534084.0,"size":0.001},{"price":11535321.0,"size":0.01},{"price":11538666.0,"size":0.002},{"price":11538700.0,"size":0.001},{"price":11540000.0,"size":0.0048},{"price":11540357.0,"size":0.002},{"price":11541011.0,"size":0.005},{"price":11541109.0,"size":0.01},{"price":11544663.0,"size":0.002},{"price":11545262.0,"size":0.002},{"price":11546541.0,"size":0.01},{"price":11548144.0,"size":0.002},{"price":11548700.0,"size":0.001},{"price":11550000.0,"size":0.014},{"price":11551109.0,"size":0.01},{"price":11551625.0,"size":0.002},{"price":11552111.0,"size":0.01},{"price":11553687.0,"size":0.1},{"price":11555106.0,"size":0.002},{"price":11555115.0,"size":0.001},{"price":11556000.0,"size":0.1},{"price":11558587.0,"size":0.002},{"price":11558700.0,"size":0.001},{"price":11559855.0,"size":0.01},{"price":11560831.0,"size":0.0198},{"price":11561109.0,"size":0.01},{"price":11562000.0,"size":0.087},{"price":11562068.0,"size":0.002},{"price":11563750.0,"size":0.08739676},{"price":11565548.0,"size":0.002},{"price":11566139.0,"size":0.0228},{"price":11566551.0,"size":0.01},{"price":11568700.0,"size":0.001},{"price":11569029.0,"size":0.002},{"price":11570196.0,"size":0.002},{"price":11571109.0,"size":0.01},{"price":11572510.0,"size":0.002},{"price":11573211.0,"size":0.01},{"price":11574840.0,"size":0.002},{"price":11575991.0,"size":0.001},{"price":11578700.0,"size":0.001},{"price":11579484.0,"size":0.002},{"price":11579851.0,"size":0.01},{"price":11580000.0,"size":0.7835},{"price":11581109.0,"size":0.01},{"price":11584128.0,"size":0.002},{"price":11585000.0,"size":0.002},{"price":11586532.0,"size":0.01},{"price":11587498.0,"size":0.0198},{"price":11588700.0,"size":0.001},{"price":11588800.0,"size":0.02},{"price":11590000.0,"size":0.1},{"price":11590749.0,"size":0.002},{"price":11591109.0,"size":0.01},{"price":11593211.0,"size":0.01},{"price":11596753.0,"size":0.002},{"price":11598111.0,"size":0.1474},{"price":11598555.0,"size":0.01},{"price":11598700.0,"size":0.001},{"price":11599999.0,"size":0.001},{"price":11600000.0,"size":3.655},{"price":11601109.0,"size":0.02},{"price":11603764.0,"size":0.9},{"price":11606655.0,"size":0.01},{"price":11610000.0,"size":0.302},{"price":11611109.0,"size":0.01},{"price":11613321.0,"size":0.01},{"price":11620000.0,"size":1.35441682},{"price":11621011.0,"size":0.01},{"price":11621109.0,"size":0.01},{"price":11623096.0,"size":0.008},{"price":11629000.0,"size":0.1},{"price":11630000.0,"size":0.201},{"price":11631059.0,"size":0.01},{"price":11631479.0,"size":0.01},{"price":11631773.0,"size":0.00386871},{"price":11635950.0,"size":0.001},{"price":11638259.0,"size":0.001},{"price":11639700.0,"size":0.001},{"price":11640000.0,"size":1.0},{"price":11640820.0,"size":0.01},{"price":11649900.0,"size":0.02906},{"price":11649999.0,"size":0.001},{"price":11650000.0,"size":0.593},{"price":11651059.0,"size":0.01},{"price":11653658.0,"size":0.008},{"price":11654321.0,"size":0.001},{"price":11659700.0,"size":0.001},{"price":11661479.0,"size":0.01},{"price":11666000.0,"size":0.001},{"price":11666666.0,"size":0.013},{"price":11669700.0,"size":0.001},{"price":11671059.0,"size":0.01},{"price":11672562.0,"size":0.0198},{"price":11680000.0,"size":0.014},{"price":11685000.0,"size":0.003},{"price":11688000.0,"size":0.001},{"price":11689732.0,"size":0.01},{"price":11690330.0,"size":0.0198},{"price":11691059.0,"size":0.01},{"price":11692558.0,"size":0.01},{"price":11695019.0,"size":0.0064},{"price":11698800.0,"size":0.00131},{"price":11699000.0,"size":0.001},{"price":11699631.0,"size":0.001},{"price":11699998.0,"size":0.01},{"price":11699999.0,"size":0.001},{"price":11700000.0,"size":1.2573},{"price":11701059.0,"size":0.01},{"price":11720000.0,"size":0.1},{"price":11721059.0,"size":0.01},{"price":11725000.0,"size":0.005},{"price":11726791.0,"size":0.01},{"price":11727418.0,"size":1.8},{"price":11728195.0,"size":0.05},{"price":11730000.0,"size":1.9712},{"price":11740000.0,"size":0.101},{"price":11741059.0,"size":0.01},{"price":11748937.0,"size":0.001},{"price":11749999.0,"size":0.001},{"price":11750000.0,"size":0.89537866},{"price":11750050.0,"size":0.2},{"price":11751151.0,"size":0.01},{"price":11755000.0,"size":0.001},{"price":11757860.0,"size":1.82},{"price":11759999.0,"size":0.001},{"price":11760000.0,"size":0.001},{"price":11761059.0,"size":0.02},{"price":11765432.0,"size":0.001},{"price":11768000.0,"size":0.01},{"price":11770000.0,"size":0.25464896},{"price":11771059.0,"size":0.01755555},{"price":11772000.0,"size":0.002},{"price":11775000.0,"size":0.11593},{"price":11775222.0,"size":0.001657},{"price":11775577.0,"size":0.00013523},{"price":11775800.0,"size":0.001},{"price":11775900.0,"size":0.2},{"price":11775989.0,"size":0.005},{"price":11777000.0,"size":0.5956},{"price":11777777.0,"size":0.0067},{"price":11778541.0,"size":0.001},{"price":11779807.0,"size":0.001},{"price":11780000.0,"size":0.74298},{"price":11780800.0,"size":0.1},{"price":11781059.0,"size":0.01},{"price":11781238.0,"size":0.008},{"price":11785000.0,"size":0.055},{"price":11785040.0,"size":0.01},{"price":11786000.0,"size":0.585},{"price":11788000.0,"size":0.001},{"price":11788888.0,"size":0.005},{"price":11789000.0,"size":0.2},{"price":11789732.0,"size":0.01},{"price":11791100.0,"size":0.1},{"price":11791151.0,"size":0.01},{"price":11795000.0,"size":0.021},{"price":11795040.0,"size":0.015},{"price":11796103.0,"size":0.01},{"price":11798800.0,"size":0.005},{"price":11798950.0,"size":0.001},{"price":11799000.0,"size":0.013}]}}}
{"schema_version":"collector.vnext.raw","schema_contract":null,"schema_contract_version":null,"payload_contract_version":null,"record_type":"market.orderbook.diff","record_id":"collector_main-market-orderbook-diff-000000000061","collector_id":"collector_main","collector_role":"production","host_name":"MAIN-PC","session_id":"collector_main-sess-20260315T000044Z-13a39d16","stream_session_id":"collector_main-stream-bitflyer-board_ws-20260315T000050Z-827c6880","exchange":"bitflyer","market":"spot","symbol":"BTC_JPY","instrument_id":"bitflyer.spot.BTC_JPY","channel":"board_ws","transport":"websocket","source_event_id":null,"source_sequence":null,"sequence_id":61,"exchange_ts":null,"collector_ts":"2026-03-15T00:00:51Z","ingest_ts":"2026-03-15T00:00:51Z","event_ts":"2026-03-15T00:00:51Z","quality_flags":[],"is_partial":false,"is_reconstructed":false,"confidence_score":1.0,"payload":{"provider":"bitflyer_ws_board","exchange":"bitflyer","transport":"websocket","channel":"lightning_board_BTC_JPY","received_ts":"2026-03-15T00:00:51.098800Z","subscription_id":null,"message_id":null,"source_sequence":null,"raw_message_meta":{"raw_channel":"lightning_board_BTC_JPY","subscription_channel":"lightning_board_BTC_JPY","recv_timeout_sec":10,"ssl_verify":false,"socket_url":"wss://ws.lightstream.bitflyer.com/json-rpc"},"source_payload":{"mid_price":11389162.0,"bids":[{"price":11386426.0,"size":0.0},{"price":11386083.0,"size":0.0}],"asks":[{"price":11394596.0,"size":0.0}]}}}
{"schema_version":"collector.vnext.raw","schema_contract":null,"schema_contract_version":null,"payload_contract_version":null,"record_type":"market.orderbook.diff","record_id":"collector_main-market-orderbook-diff-000000000065","collector_id":"collector_main","collector_role":"production","host_name":"MAIN-PC","session_id":"collector_main-sess-20260315T000044Z-13a39d16","stream_session_id":"collector_main-stream-bitflyer-board_ws-20260315T000050Z-827c6880","exchange":"bitflyer","market":"spot","symbol":"BTC_JPY","instrument_id":"bitflyer.spot.BTC_JPY","channel":"board_ws","transport":"websocket","source_event_id":null,"source_sequence":null,"sequence_id":65,"exchange_ts":null,"collector_ts":"2026-03-15T00:00:51Z","ingest_ts":"2026-03-15T00:00:51Z","event_ts":"2026-03-15T00:00:51Z","quality_flags":[],"is_partial":false,"is_reconstructed":false,"confidence_score":1.0,"payload":{"provider":"bitflyer_ws_board","exchange":"bitflyer","transport":"websocket","channel":"lightning_board_BTC_JPY","received_ts":"2026-03-15T00:00:51.249706Z","subscription_id":null,"message_id":null,"source_sequence":null,"raw_message_meta":{"raw_channel":"lightning_board_BTC_JPY","subscription_channel":"lightning_board_BTC_JPY","recv_timeout_sec":10,"ssl_verify":false,"socket_url":"wss://ws.lightstream.bitflyer.com/json-rpc"},"source_payload":{"mid_price":11389162.0,"bids":[{"price":11385461.0,"size":0.014904},{"price":11386427.0,"size":0.0},{"price":11385178.0,"size":0.06119712}],"asks":[{"price":11392865.0,"size":0.014904},{"price":11403658.0,"size":0.0},{"price":11391999.0,"size":0.0},{"price":11390000.0,"size":0.5705},{"price":11397218.0,"size":0.0}]}}}
{"schema_version":"collector.vnext.raw","schema_contract":null,"schema_contract_version":null,"payload_contract_version":null,"record_type":"market.orderbook.diff","record_id":"collector_main-market-orderbook-diff-000000000067","collector_id":"collector_main","collector_role":"production","host_name":"MAIN-PC","session_id":"collector_main-sess-20260315T000044Z-13a39d16","stream_session_id":"collector_main-stream-bitflyer-board_ws-20260315T000050Z-827c6880","exchange":"bitflyer","market":"spot","symbol":"BTC_JPY","instrument_id":"bitflyer.spot.BTC_JPY","channel":"board_ws","transport":"websocket","source_event_id":null,"source_sequence":null,"sequence_id":67,"exchange_ts":null,"collector_ts":"2026-03-15T00:00:51Z","ingest_ts":"2026-03-15T00:00:51Z","event_ts":"2026-03-15T00:00:51Z","quality_flags":[],"is_partial":false,"is_reconstructed":false,"confidence_score":1.0,"payload":{"provider":"bitflyer_ws_board","exchange":"bitflyer","transport":"websocket","channel":"lightning_board_BTC_JPY","received_ts":"2026-03-15T00:00:51.387023Z","subscription_id":null,"message_id":null,"source_sequence":null,"raw_message_meta":{"raw_channel":"lightning_board_BTC_JPY","subscription_channel":"lightning_board_BTC_JPY","recv_timeout_sec":10,"ssl_verify":false,"socket_url":"wss://ws.lightstream.bitflyer.com/json-rpc"},"source_payload":{"mid_price":11389162.0,"bids":[{"price":11385178.0,"size":0.0}],"asks":[{"price":11392610.0,"size":0.2592}]}}}
{"schema_version":"collector.vnext.raw","schema_contract":null,"schema_contract_version":null,"payload_contract_version":null,"record_type":"market.orderbook.diff","record_id":"collector_main-market-orderbook-diff-000000000069","collector_id":"collector_main","collector_role":"production","host_name":"MAIN-PC","session_id":"collector_main-sess-20260315T000044Z-13a39d16","stream_session_id":"collector_main-stream-bitflyer-board_ws-20260315T000050Z-827c6880","exchange":"bitflyer","market":"spot","symbol":"BTC_JPY","instrument_id":"bitflyer.spot.BTC_JPY","channel":"board_ws","transport":"websocket","source_event_id":null,"source_sequence":null,"sequence_id":69,"exchange_ts":null,"collector_ts":"2026-03-15T00:00:51Z","ingest_ts":"2026-03-15T00:00:51Z","event_ts":"2026-03-15T00:00:51Z","quality_flags":[],"is_partial":false,"is_reconstructed":false,"confidence_score":1.0,"payload":{"provider":"bitflyer_ws_board","exchange":"bitflyer","transport":"websocket","channel":"lightning_board_BTC_JPY","received_ts":"2026-03-15T00:00:51.505822Z","subscription_id":null,"message_id":null,"source_sequence":null,"raw_message_meta":{"raw_channel":"lightning_board_BTC_JPY","subscription_channel":"lightning_board_BTC_JPY","recv_timeout_sec":10,"ssl_verify":false,"socket_url":"wss://ws.lightstream.bitflyer.com/json-rpc"},"source_payload":{"mid_price":11389162.0,"bids":[],"asks":[{"price":11391998.0,"size":0.0}]}}}
{"schema_version":"collector.vnext.raw","schema_contract":null,"schema_contract_version":null,"payload_contract_version":null,"record_type":"market.orderbook.diff","record_id":"collector_main-market-orderbook-diff-000000000071","collector_id":"collector_main","collector_role":"production","host_name":"MAIN-PC","session_id":"collector_main-sess-20260315T000044Z-13a39d16","stream_session_id":"collector_main-stream-bitflyer-board_ws-20260315T000050Z-827c6880","exchange":"bitflyer","market":"spot","symbol":"BTC_JPY","instrument_id":"bitflyer.spot.BTC_JPY","channel":"board_ws","transport":"websocket","source_event_id":null,"source_sequence":null,"sequence_id":71,"exchange_ts":null,"collector_ts":"2026-03-15T00:00:51Z","ingest_ts":"2026-03-15T00:00:51Z","event_ts":"2026-03-15T00:00:51Z","quality_flags":[],"is_partial":false,"is_reconstructed":false,"confidence_score":1.0,"payload":{"provider":"bitflyer_ws_board","exchange":"bitflyer","transport":"websocket","channel":"lightning_board_BTC_JPY","received_ts":"2026-03-15T00:00:51.610821Z","subscription_id":null,"message_id":null,"source_sequence":null,"raw_message_meta":{"raw_channel":"lightning_board_BTC_JPY","subscription_channel":"lightning_board_BTC_JPY","recv_timeout_sec":10,"ssl_verify":false,"socket_url":"wss://ws.lightstream.bitflyer.com/json-rpc"},"source_payload":{"mid_price":11389162.0,"bids":[{"price":11385462.0,"size":0.05578116}],"asks":[{"price":11401753.0,"size":0.0},{"price":11392009.0,"size":0.0},{"price":11401752.0,"size":0.15}]}}}
{"schema_version":"collector.vnext.raw","schema_contract":null,"schema_contract_version":null,"payload_contract_version":null,"record_type":"market.orderbook.diff","record_id":"collector_main-market-orderbook-diff-000000000073","collector_id":"collector_main","collector_role":"production","host_name":"MAIN-PC","session_id":"collector_main-sess-20260315T000044Z-13a39d16","stream_session_id":"collector_main-stream-bitflyer-board_ws-20260315T000050Z-827c6880","exchange":"bitflyer","market":"spot","symbol":"BTC_JPY","instrument_id":"bitflyer.spot.BTC_JPY","channel":"board_ws","transport":"websocket","source_event_id":null,"source_sequence":null,"sequence_id":73,"exchange_ts":null,"collector_ts":"2026-03-15T00:00:51Z","ingest_ts":"2026-03-15T00:00:51Z","event_ts":"2026-03-15T00:00:51Z","quality_flags":[],"is_partial":false,"is_reconstructed":false,"confidence_score":1.0,"payload":{"provider":"bitflyer_ws_board","exchange":"bitflyer","transport":"websocket","channel":"lightning_board_BTC_JPY","received_ts":"2026-03-15T00:00:51.720539Z","subscription_id":null,"message_id":null,"source_sequence":null,"raw_message_meta":{"raw_channel":"lightning_board_BTC_JPY","subscription_channel":"lightning_board_BTC_JPY","recv_timeout_sec":10,"ssl_verify":false,"socket_url":"wss://ws.lightstream.bitflyer.com/json-rpc"},"source_payload":{"mid_price":11389162.0,"bids":[],"asks":[{"price":11391997.0,"size":0.0}]}}}
{"schema_version":"collector.vnext.raw","schema_contract":null,"schema_contract_version":null,"payload_contract_version":null,"record_type":"market.orderbook.diff","record_id":"collector_main-market-orderbook-diff-000000000075","collector_id":"collector_main","collector_role":"production","host_name":"MAIN-PC","session_id":"collector_main-sess-20260315T000044Z-13a39d16","stream_session_id":"collector_main-stream-bitflyer-board_ws-20260315T000050Z-827c6880","exchange":"bitflyer","market":"spot","symbol":"BTC_JPY","instrument_id":"bitflyer.spot.BTC_JPY","channel":"board_ws","transport":"websocket","source_event_id":null,"source_sequence":null,"sequence_id":75,"exchange_ts":null,"collector_ts":"2026-03-15T00:00:51Z","ingest_ts":"2026-03-15T00:00:51Z","event_ts":"2026-03-15T00:00:51Z","quality_flags":[],"is_partial":false,"is_reconstructed":false,"confidence_score":1.0,"payload":{"provider":"bitflyer_ws_board","exchange":"bitflyer","transport":"websocket","channel":"lightning_board_BTC_JPY","received_ts":"2026-03-15T00:00:51.832747Z","subscription_id":null,"message_id":null,"source_sequence":null,"raw_message_meta":{"raw_channel":"lightning_board_BTC_JPY","subscription_channel":"lightning_board_BTC_JPY","recv_timeout_sec":10,"ssl_verify":false,"socket_url":"wss://ws.lightstream.bitflyer.com/json-rpc"},"source_payload":{"mid_price":11389162.0,"bids":[],"asks":[{"price":11392009.0,"size":0.02351568}]}}}
{"schema_version":"collector.vnext.raw","schema_contract":null,"schema_contract_version":null,"payload_contract_version":null,"record_type":"market.orderbook.diff","record_id":"collector_main-market-orderbook-diff-000000000077","collector_id":"collector_main","collector_role":"production","host_name":"MAIN-PC","session_id":"collector_main-sess-20260315T000044Z-13a39d16","stream_session_id":"collector_main-stream-bitflyer-board_ws-20260315T000050Z-827c6880","exchange":"bitflyer","market":"spot","symbol":"BTC_JPY","instrument_id":"bitflyer.spot.BTC_JPY","channel":"board_ws","transport":"websocket","source_event_id":null,"source_sequence":null,"sequence_id":77,"exchange_ts":null,"collector_ts":"2026-03-15T00:00:51Z","ingest_ts":"2026-03-15T00:00:51Z","event_ts":"2026-03-15T00:00:51Z","quality_flags":[],"is_partial":false,"is_reconstructed":false,"confidence_score":1.0,"payload":{"provider":"bitflyer_ws_board","exchange":"bitflyer","transport":"websocket","channel":"lightning_board_BTC_JPY","received_ts":"2026-03-15T00:00:51.925763Z","subscription_id":null,"message_id":null,"source_sequence":null,"raw_message_meta":{"raw_channel":"lightning_board_BTC_JPY","subscription_channel":"lightning_board_BTC_JPY","recv_timeout_sec":10,"ssl_verify":false,"socket_url":"wss://ws.lightstream.bitflyer.com/json-rpc"},"source_payload":{"mid_price":11389163.0,"bids":[{"price":11388326.0,"size":0.27}],"asks":[]}}}
{"schema_version":"collector.vnext.raw","schema_contract":null,"schema_contract_version":null,"payload_contract_version":null,"record_type":"market.orderbook.diff","record_id":"collector_main-market-orderbook-diff-000000000079","collector_id":"collector_main","collector_role":"production","host_name":"MAIN-PC","session_id":"collector_main-sess-20260315T000044Z-13a39d16","stream_session_id":"collector_main-stream-bitflyer-board_ws-20260315T000050Z-827c6880","exchange":"bitflyer","market":"spot","symbol":"BTC_JPY","instrument_id":"bitflyer.spot.BTC_JPY","channel":"board_ws","transport":"websocket","source_event_id":null,"source_sequence":null,"sequence_id":79,"exchange_ts":null,"collector_ts":"2026-03-15T00:00:52Z","ingest_ts":"2026-03-15T00:00:52Z","event_ts":"2026-03-15T00:00:52Z","quality_flags":[],"is_partial":false,"is_reconstructed":false,"confidence_score":1.0,"payload":{"provider":"bitflyer_ws_board","exchange":"bitflyer","transport":"websocket","channel":"lightning_board_BTC_JPY","received_ts":"2026-03-15T00:00:52.463009Z","subscription_id":null,"message_id":null,"source_sequence":null,"raw_message_meta":{"raw_channel":"lightning_board_BTC_JPY","subscription_channel":"lightning_board_BTC_JPY","recv_timeout_sec":10,"ssl_verify":false,"socket_url":"wss://ws.lightstream.bitflyer.com/json-rpc"},"source_payload":{"mid_price":11389163.0,"bids":[{"price":11383090.0,"size":0.0},{"price":11383204.0,"size":0.01}],"asks":[]}}}
{"schema_version":"collector.vnext.raw","schema_contract":null,"schema_contract_version":null,"payload_contract_version":null,"record_type":"market.orderbook.diff","record_id":"collector_main-market-orderbook-diff-000000000081","collector_id":"collector_main","collector_role":"production","host_name":"MAIN-PC","session_id":"collector_main-sess-20260315T000044Z-13a39d16","stream_session_id":"collector_main-stream-bitflyer-board_ws-20260315T000050Z-827c6880","exchange":"bitflyer","market":"spot","symbol":"BTC_JPY","instrument_id":"bitflyer.spot.BTC_JPY","channel":"board_ws","transport":"websocket","source_event_id":null,"source_sequence":null,"sequence_id":81,"exchange_ts":null,"collector_ts":"2026-03-15T00:00:52Z","ingest_ts":"2026-03-15T00:00:52Z","event_ts":"2026-03-15T00:00:52Z","quality_flags":[],"is_partial":false,"is_reconstructed":false,"confidence_score":1.0,"payload":{"provider":"bitflyer_ws_board","exchange":"bitflyer","transport":"websocket","channel":"lightning_board_BTC_JPY","received_ts":"2026-03-15T00:00:52.578158Z","subscription_id":null,"message_id":null,"source_sequence":null,"raw_message_meta":{"raw_channel":"lightning_board_BTC_JPY","subscription_channel":"lightning_board_BTC_JPY","recv_timeout_sec":10,"ssl_verify":false,"socket_url":"wss://ws.lightstream.bitflyer.com/json-rpc"},"source_payload":{"mid_price":11389162.0,"bids":[{"price":11388326.0,"size":0.0}],"asks":[]}}}
{"schema_version":"collector.vnext.raw","schema_contract":null,"schema_contract_version":null,"payload_contract_version":null,"record_type":"market.orderbook.diff","record_id":"collector_main-market-orderbook-diff-000000000083","collector_id":"collector_main","collector_role":"production","host_name":"MAIN-PC","session_id":"collector_main-sess-20260315T000044Z-13a39d16","stream_session_id":"collector_main-stream-bitflyer-board_ws-20260315T000050Z-827c6880","exchange":"bitflyer","market":"spot","symbol":"BTC_JPY","instrument_id":"bitflyer.spot.BTC_JPY","channel":"board_ws","transport":"websocket","source_event_id":null,"source_sequence":null,"sequence_id":83,"exchange_ts":null,"collector_ts":"2026-03-15T00:00:52Z","ingest_ts":"2026-03-15T00:00:52Z","event_ts":"2026-03-15T00:00:52Z","quality_flags":[],"is_partial":false,"is_reconstructed":false,"confidence_score":1.0,"payload":{"provider":"bitflyer_ws_board","exchange":"bitflyer","transport":"websocket","channel":"lightning_board_BTC_JPY","received_ts":"2026-03-15T00:00:52.703564Z","subscription_id":null,"message_id":null,"source_sequence":null,"raw_message_meta":{"raw_channel":"lightning_board_BTC_JPY","subscription_channel":"lightning_board_BTC_JPY","recv_timeout_sec":10,"ssl_verify":false,"socket_url":"wss://ws.lightstream.bitflyer.com/json-rpc"},"source_payload":{"mid_price":11389163.0,"bids":[{"price":11388326.0,"size":0.29}],"asks":[]}}}
{"schema_version":"collector.vnext.raw","schema_contract":null,"schema_contract_version":null,"payload_contract_version":null,"record_type":"market.orderbook.diff","record_id":"collector_main-market-orderbook-diff-000000000085","collector_id":"collector_main","collector_role":"production","host_name":"MAIN-PC","session_id":"collector_main-sess-20260315T000044Z-13a39d16","stream_session_id":"collector_main-stream-bitflyer-board_ws-20260315T000050Z-827c6880","exchange":"bitflyer","market":"spot","symbol":"BTC_JPY","instrument_id":"bitflyer.spot.BTC_JPY","channel":"board_ws","transport":"websocket","source_event_id":null,"source_sequence":null,"sequence_id":85,"exchange_ts":null,"collector_ts":"2026-03-15T00:00:53Z","ingest_ts":"2026-03-15T00:00:53Z","event_ts":"2026-03-15T00:00:53Z","quality_flags":[],"is_partial":false,"is_reconstructed":false,"confidence_score":1.0,"payload":{"provider":"bitflyer_ws_board","exchange":"bitflyer","transport":"websocket","channel":"lightning_board_BTC_JPY","received_ts":"2026-03-15T00:00:53.112946Z","subscription_id":null,"message_id":null,"source_sequence":null,"raw_message_meta":{"raw_channel":"lightning_board_BTC_JPY","subscription_channel":"lightning_board_BTC_JPY","recv_timeout_sec":10,"ssl_verify":false,"socket_url":"wss://ws.lightstream.bitflyer.com/json-rpc"},"source_payload":{"mid_price":11389163.0,"bids":[{"price":11385002.0,"size":0.0}],"asks":[{"price":11402569.0,"size":0.0}]}}}
{"schema_version":"collector.vnext.raw","schema_contract":null,"schema_contract_version":null,"payload_contract_version":null,"record_type":"market.orderbook.diff","record_id":"collector_main-market-orderbook-diff-000000000087","collector_id":"collector_main","collector_role":"production","host_name":"MAIN-PC","session_id":"collector_main-sess-20260315T000044Z-13a39d16","stream_session_id":"collector_main-stream-bitflyer-board_ws-20260315T000050Z-827c6880","exchange":"bitflyer","market":"spot","symbol":"BTC_JPY","instrument_id":"bitflyer.spot.BTC_JPY","channel":"board_ws","transport":"websocket","source_event_id":null,"source_sequence":null,"sequence_id":87,"exchange_ts":null,"collector_ts":"2026-03-15T00:00:53Z","ingest_ts":"2026-03-15T00:00:53Z","event_ts":"2026-03-15T00:00:53Z","quality_flags":[],"is_partial":false,"is_reconstructed":false,"confidence_score":1.0,"payload":{"provider":"bitflyer_ws_board","exchange":"bitflyer","transport":"websocket","channel":"lightning_board_BTC_JPY","received_ts":"2026-03-15T00:00:53.213342Z","subscription_id":null,"message_id":null,"source_sequence":null,"raw_message_meta":{"raw_channel":"lightning_board_BTC_JPY","subscription_channel":"lightning_board_BTC_JPY","recv_timeout_sec":10,"ssl_verify":false,"socket_url":"wss://ws.lightstream.bitflyer.com/json-rpc"},"source_payload":{"mid_price":11389163.0,"bids":[],"asks":[{"price":11394858.0,"size":0.01}]}}}
{"schema_version":"collector.vnext.raw","schema_contract":null,"schema_contract_version":null,"payload_contract_version":null,"record_type":"market.orderbook.diff","record_id":"collector_main-market-orderbook-diff-000000000089","collector_id":"collector_main","collector_role":"production","host_name":"MAIN-PC","session_id":"collector_main-sess-20260315T000044Z-13a39d16","stream_session_id":"collector_main-stream-bitflyer-board_ws-20260315T000050Z-827c6880","exchange":"bitflyer","market":"spot","symbol":"BTC_JPY","instrument_id":"bitflyer.spot.BTC_JPY","channel":"board_ws","transport":"websocket","source_event_id":null,"source_sequence":null,"sequence_id":89,"exchange_ts":null,"collector_ts":"2026-03-15T00:00:53Z","ingest_ts":"2026-03-15T00:00:53Z","event_ts":"2026-03-15T00:00:53Z","quality_flags":[],"is_partial":false,"is_reconstructed":false,"confidence_score":1.0,"payload":{"provider":"bitflyer_ws_board","exchange":"bitflyer","transport":"websocket","channel":"lightning_board_BTC_JPY","received_ts":"2026-03-15T00:00:53.485060Z","subscription_id":null,"message_id":null,"source_sequence":null,"raw_message_meta":{"raw_channel":"lightning_board_BTC_JPY","subscription_channel":"lightning_board_BTC_JPY","recv_timeout_sec":10,"ssl_verify":false,"socket_url":"wss://ws.lightstream.bitflyer.com/json-rpc"},"source_payload":{"mid_price":11389162.0,"bids":[{"price":11383204.0,"size":0.0},{"price":11383090.0,"size":0.2}],"asks":[]}}}
{"schema_version":"collector.vnext.raw","schema_contract":null,"schema_contract_version":null,"payload_contract_version":null,"record_type":"market.orderbook.diff","record_id":"collector_main-market-orderbook-diff-000000000091","collector_id":"collector_main","collector_role":"production","host_name":"MAIN-PC","session_id":"collector_main-sess-20260315T000044Z-13a39d16","stream_session_id":"collector_main-stream-bitflyer-board_ws-20260315T000050Z-827c6880","exchange":"bitflyer","market":"spot","symbol":"BTC_JPY","instrument_id":"bitflyer.spot.BTC_JPY","channel":"board_ws","transport":"websocket","source_event_id":null,"source_sequence":null,"sequence_id":91,"exchange_ts":null,"collector_ts":"2026-03-15T00:00:54Z","ingest_ts":"2026-03-15T00:00:54Z","event_ts":"2026-03-15T00:00:54Z","quality_flags":[],"is_partial":false,"is_reconstructed":false,"confidence_score":1.0,"payload":{"provider":"bitflyer_ws_board","exchange":"bitflyer","transport":"websocket","channel":"lightning_board_BTC_JPY","received_ts":"2026-03-15T00:00:54.507300Z","subscription_id":null,"message_id":null,"source_sequence":null,"raw_message_meta":{"raw_channel":"lightning_board_BTC_JPY","subscription_channel":"lightning_board_BTC_JPY","recv_timeout_sec":10,"ssl_verify":false,"socket_url":"wss://ws.lightstream.bitflyer.com/json-rpc"},"source_payload":{"mid_price":11388710.0,"bids":[{"price":11388325.0,"size":0.0}],"asks":[{"price":11392009.0,"size":0.0}]}}}
{"schema_version":"collector.vnext.raw","schema_contract":null,"schema_contract_version":null,"payload_contract_version":null,"record_type":"market.orderbook.diff","record_id":"collector_main-market-orderbook-diff-000000000093","collector_id":"collector_main","collector_role":"production","host_name":"MAIN-PC","session_id":"collector_main-sess-20260315T000044Z-13a39d16","stream_session_id":"collector_main-stream-bitflyer-board_ws-20260315T000050Z-827c6880","exchange":"bitflyer","market":"spot","symbol":"BTC_JPY","instrument_id":"bitflyer.spot.BTC_JPY","channel":"board_ws","transport":"websocket","source_event_id":null,"source_sequence":null,"sequence_id":93,"exchange_ts":null,"collector_ts":"2026-03-15T00:00:54Z","ingest_ts":"2026-03-15T00:00:54Z","event_ts":"2026-03-15T00:00:54Z","quality_flags":[],"is_partial":false,"is_reconstructed":false,"confidence_score":1.0,"payload":{"provider":"bitflyer_ws_board","exchange":"bitflyer","transport":"websocket","channel":"lightning_board_BTC_JPY","received_ts":"2026-03-15T00:00:54.609890Z","subscription_id":null,"message_id":null,"source_sequence":null,"raw_message_meta":{"raw_channel":"lightning_board_BTC_JPY","subscription_channel":"lightning_board_BTC_JPY","recv_timeout_sec":10,"ssl_verify":false,"socket_url":"wss://ws.lightstream.bitflyer.com/json-rpc"},"source_payload":{"mid_price":11388709.0,"bids":[],"asks":[{"price":11389999.0,"size":0.02312182}]}}}
{"schema_version":"collector.vnext.raw","schema_contract":null,"schema_contract_version":null,"payload_contract_version":null,"record_type":"market.orderbook.diff","record_id":"collector_main-market-orderbook-diff-000000000095","collector_id":"collector_main","collector_role":"production","host_name":"MAIN-PC","session_id":"collector_main-sess-20260315T000044Z-13a39d16","stream_session_id":"collector_main-stream-bitflyer-board_ws-20260315T000050Z-827c6880","exchange":"bitflyer","market":"spot","symbol":"BTC_JPY","instrument_id":"bitflyer.spot.BTC_JPY","channel":"board_ws","transport":"websocket","source_event_id":null,"source_sequence":null,"sequence_id":95,"exchange_ts":null,"collector_ts":"2026-03-15T00:00:54Z","ingest_ts":"2026-03-15T00:00:54Z","event_ts":"2026-03-15T00:00:54Z","quality_flags":[],"is_partial":false,"is_reconstructed":false,"confidence_score":1.0,"payload":{"provider":"bitflyer_ws_board","exchange":"bitflyer","transport":"websocket","channel":"lightning_board_BTC_JPY","received_ts":"2026-03-15T00:00:54.848232Z","subscription_id":null,"message_id":null,"source_sequence":null,"raw_message_meta":{"raw_channel":"lightning_board_BTC_JPY","subscription_channel":"lightning_board_BTC_JPY","recv_timeout_sec":10,"ssl_verify":false,"socket_url":"wss://ws.lightstream.bitflyer.com/json-rpc"},"source_payload":{"mid_price":11388710.0,"bids":[{"price":11387421.0,"size":0.19}],"asks":[]}}}
{"schema_version":"collector.vnext.raw","schema_contract":null,"schema_contract_version":null,"payload_contract_version":null,"record_type":"market.orderbook.snapshot","record_id":"collector_main-market-orderbook-snapshot-000000000097","collector_id":"collector_main","collector_role":"production","host_name":"MAIN-PC","session_id":"collector_main-sess-20260315T000044Z-13a39d16","stream_session_id":"collector_main-stream-bitflyer-board_ws-20260315T000050Z-827c6880","exchange":"bitflyer","market":"spot","symbol":"BTC_JPY","instrument_id":"bitflyer.spot.BTC_JPY","channel":"board_ws","transport":"websocket","source_event_id":null,"source_sequence":null,"sequence_id":97,"exchange_ts":null,"collector_ts":"2026-03-15T00:00:54Z","ingest_ts":"2026-03-15T00:00:54Z","event_ts":"2026-03-15T00:00:54Z","quality_flags":[],"is_partial":false,"is_reconstructed":false,"confidence_score":1.0,"payload":{"provider":"bitflyer_ws_board_snapshot","exchange":"bitflyer","transport":"websocket","channel":"lightning_board_snapshot_BTC_JPY","received_ts":"2026-03-15T00:00:54.990259Z","subscription_id":null,"message_id":null,"source_sequence":null,"raw_message_meta":{"raw_channel":"lightning_board_snapshot_BTC_JPY","subscription_channel":"lightning_board_snapshot_BTC_JPY","recv_timeout_sec":10,"ssl_verify":false,"socket_url":"wss://ws.lightstream.bitflyer.com/json-rpc"},"source_payload":{"mid_price":11388710.0,"bids":[{"price":11387421.0,"size":0.19},{"price":11387420.0,"size":0.00999794},{"price":11385462.0,"size":0.05578116},{"price":11385461.0,"size":0.014904},{"price":11385177.0,"size":0.5},{"price":11384706.0,"size":0.014688},{"price":11384050.0,"size":0.5},{"price":11383090.0,"size":0.2},{"price":11382812.0,"size":0.0554688},{"price":11380159.0,"size":0.0527},{"price":11380121.0,"size":0.01},{"price":11378703.0,"size":3.11280004},{"price":11378702.0,"size":0.0751},{"price":11376893.0,"size":1.50015},{"price":11375000.0,"size":0.03},{"price":11371189.0,"size":0.97658726},{"price":11370955.0,"size":0.27},{"price":11370000.0,"size":0.005},{"price":11368376.0,"size":0.01},{"price":11367661.0,"size":0.002},{"price":11365953.0,"size":0.002},{"price":11363915.0,"size":0.12856523},{"price":11363914.0,"size":0.2627},{"price":11363103.0,"size":0.002},{"price":11362535.0,"size":0.002},{"price":11362394.0,"size":1.484},{"price":11361152.0,"size":0.2587},{"price":11359117.0,"size":0.002},{"price":11358545.0,"size":0.002},{"price":11358390.0,"size":0.2599},{"price":11358376.0,"size":0.01},{"price":11357601.0,"size":0.22},{"price":11356870.0,"size":0.6},{"price":11355699.0,"size":0.002},{"price":11355628.0,"size":0.2833},{"price":11350000.0,"size":0.51},{"price":11349429.0,"size":0.002},{"price":11348863.0,"size":0.002},{"price":11348823.0,"size":0.5},{"price":11348189.0,"size":0.003},{"price":11347667.0,"size":0.001},{"price":11345445.0,"size":0.002},{"price":11344871.0,"size":0.002},{"price":11342981.0,"size":1.966},{"price":11342027.0,"size":0.002},{"price":11340313.0,"size":0.002},{"price":11340000.0,"size":0.005},{"price":11338609.0,"size":0.002},{"price":11336383.0,"size":0.001},{"price":11336319.0,"size":0.00195},{"price":11335755.0,"size":0.002},{"price":11335191.0,"size":0.002},{"price":11332840.0,"size":2.036},{"price":11331197.0,"size":0.002},{"price":11331000.0,"size":0.5},{"price":11330000.0,"size":0.02442},{"price":11326639.0,"size":0.002},{"price":11325101.0,"size":0.001},{"price":11320000.0,"size":0.05},{"price":11315000.0,"size":0.05},{"price":11314325.0,"size":1.951},{"price":11313996.0,"size":0.00195},{"price":11313819.0,"size":0.001},{"price":11310000.0,"size":0.01},{"price":11309999.0,"size":0.177},{"price":11307999.0,"size":0.01},{"price":11303918.0,"size":0.01},{"price":11303000.0,"size":0.5},{"price":11302535.0,"size":0.001},{"price":11302466.0,"size":0.001},{"price":11301268.0,"size":0.01},{"price":11300000.0,"size":3.01685256},{"price":11298000.0,"size":0.01},{"price":11297527.0,"size":1.13},{"price":11296865.0,"size":0.0015},{"price":11294756.0,"size":1.0},{"price":11291282.0,"size":0.001},{"price":11291268.0,"size":0.01},{"price":11291000.0,"size":0.5},{"price":11290000.0,"size":0.003},{"price":11281268.0,"size":0.01},{"price":11280000.0,"size":0.0163},{"price":11279960.0,"size":0.001},{"price":11279282.0,"size":0.0015},{"price":11278000.0,"size":0.0025},{"price":11275000.0,"size":0.001},{"price":11274588.0,"size":0.0047},{"price":11271268.0,"size":0.01},{"price":11271000.0,"size":0.003},{"price":11270000.0,"size":0.106},{"price":11269424.0,"size":0.8},{"price":11268871.0,"size":0.28},{"price":11268638.0,"size":0.001},{"price":11268411.0,"size":0.01},{"price":11266666.0,"size":0.04},{"price":11265000.0,"size":0.02},{"price":11263000.0,"size":0.006},{"price":11262564.0,"size":0.0015},{"price":11261268.0,"size":0.01},{"price":11260000.0,"size":0.3565},{"price":11257315.0,"size":0.001},{"price":11257000.0,"size":0.001},{"price":11255200.0,"size":0.001},{"price":11255115.0,"size":0.00377},{"price":11253814.0,"size":2.2},{"price":11253690.0,"size":0.01},{"price":11253000.0,"size":0.03189},{"price":11251405.0,"size":0.139},{"price":11251268.0,"size":0.01},{"price":11251111.0,"size":0.0015},{"price":11251000.0,"size":0.0131},{"price":11250250.0,"size":0.00105},{"price":11250200.0,"size":0.001},{"price":11250005.0,"size":0.001},{"price":11250001.0,"size":0.00104},{"price":11250000.0,"size":1.62712889},{"price":11245993.0,"size":0.001},{"price":11245141.0,"size":0.0031},{"price":11245000.0,"size":0.05},{"price":11244444.0,"size":0.04},{"price":11244243.0,"size":0.01},{"price":11240200.0,"size":0.001},{"price":11240000.0,"size":0.007304},{"price":11236190.0,"size":0.01},{"price":11235200.0,"size":0.001},{"price":11234670.0,"size":0.001},{"price":11232000.0,"size":0.089},{"price":11231243.0,"size":0.01},{"price":11231000.0,"size":0.105},{"price":11230200.0,"size":0.001},{"price":11230000.0,"size":0.0308},{"price":11226952.0,"size":0.972},{"price":11224500.0,"size":0.06},{"price":11223968.0,"size":0.001},{"price":11223348.0,"size":0.001},{"price":11223344.0,"size":0.01},{"price":11223000.0,"size":0.1},{"price":11222222.0,"size":0.093525},{"price":11221120.0,"size":0.001},{"price":11220200.0,"size":0.001},{"price":11220001.0,"size":0.004457},{"price":11220000.0,"size":0.321},{"price":11219000.0,"size":0.1},{"price":11217326.0,"size":0.02},{"price":11215200.0,"size":0.001},{"price":11213690.0,"size":0.01},{"price":11212025.0,"size":0.001},{"price":11211800.0,"size":0.001},{"price":11211111.0,"size":0.06},{"price":11210200.0,"size":0.001},{"price":11210000.0,"size":0.10622},{"price":11208032.0,"size":0.01},{"price":11206000.0,"size":0.09015},{"price":11205200.0,"size":0.001},{"price":11204578.0,"size":0.002},{"price":11201000.0,"size":0.01},{"price":11200800.0,"size":0.05},{"price":11200703.0,"size":0.001},{"price":11200425.0,"size":0.1},{"price":11200200.0,"size":0.001},{"price":11200198.0,"size":0.003},{"price":11200150.0,"size":0.002},{"price":11200002.0,"size":0.001},{"price":11200001.0,"size":0.01104},{"price":11200000.0,"size":1.15226728},{"price":11198508.0,"size":0.05},{"price":11198243.0,"size":0.01},{"price":11197134.0,"size":0.993},{"price":11197000.0,"size":0.0085},{"price":11194090.0,"size":0.03},{"price":11190770.0,"size":0.0309},{"price":11190000.0,"size":0.0010016},{"price":11189555.0,"size":0.5},{"price":11189381.0,"size":0.001},{"price":11188629.0,"size":0.01},{"price":11188382.0,"size":0.001},{"price":11185000.0,"size":0.0085},{"price":11180000.0,"size":0.225},{"price":11178058.0,"size":0.001},{"price":11170000.0,"size":0.001},{"price":11169662.0,"size":0.01},{"price":11169593.0,"size":0.001},{"price":11169243.0,"size":0.01},{"price":11166736.0,"size":0.001},{"price":11164029.0,"size":0.001},{"price":11160854.0,"size":0.1},{"price":11160000.0,"size":0.02376},{"price":11155413.0,"size":0.001},{"price":11155377.0,"size":0.00636009},{"price":11153999.0,"size":0.00101},{"price":11151000.0,"size":0.001},{"price":11150250.0,"size":0.00175},{"price":11150005.0,"size":0.001},{"price":11150001.0,"size":0.00104},{"price":11150000.0,"size":0.6533956},{"price":11148000.0,"size":0.08963},{"price":11147546.0,"size":0.02},{"price":11144091.0,"size":0.001},{"price":11144000.0,"size":0.0897},{"price":11143986.0,"size":0.02},{"price":11140139.0,"size":1.0},{"price":11140000.0,"size":0.2},{"price":11136243.0,"size":0.01},{"price":11135869.0,"size":0.1},{"price":11132768.0,"size":0.001},{"price":11130000.0,"size":0.116},{"price":11129979.0,"size":0.0053908},{"price":11124900.0,"size":0.00133},{"price":11121090.0,"size":0.1},{"price":11120000.0,"size":0.0033},{"price":11118078.0,"size":0.01},{"price":11111800.0,"size":0.001},{"price":11111111.0,"size":0.2919257},{"price":11111000.0,"size":0.003},{"price":11110594.0,"size":0.001},{"price":11110000.0,"size":0.021007},{"price":11109662.0,"size":0.01},{"price":11108008.0,"size":0.01},{"price":11102000.0,"size":0.5},{"price":11101297.0,"size":0.001},{"price":11100005.0,"size":0.001},{"price":11100001.0,"size":0.01104},{"price":11100000.0,"size":1.6532049},{"price":11099141.0,"size":0.01},{"price":11098833.0,"size":0.002},{"price":11096243.0,"size":0.01},{"price":11094090.0,"size":0.01},{"price":11088888.0,"size":0.001},{"price":11085245.0,"size":0.001},{"price":11080200.0,"size":0.001},{"price":11080000.0,"size":0.0223},{"price":11075100.0,"size":0.003},{"price":11070200.0,"size":0.001},{"price":11070000.0,"size":0.0902},{"price":11065200.0,"size":0.001},{"price":11064370.0,"size":0.00497091},{"price":11060200.0,"size":0.001},{"price":11060000.0,"size":0.145},{"price":11059689.0,"size":0.009},{"price":11056428.0,"size":0.002},{"price":11055500.0,"size":0.02},{"price":11055200.0,"size":0.001},{"price":11055100.0,"size":0.003},{"price":11050200.0,"size":0.001},{"price":11050005.0,"size":0.001},{"price":11050002.0,"size":0.001},{"price":11050001.0,"size":0.00104},{"price":11050000.0,"size":0.39576147},{"price":11048064.0,"size":2.0},{"price":11046420.0,"size":0.2},{"price":11044243.0,"size":0.01},{"price":11041380.0,"size":0.01},{"price":11040200.0,"size":0.001},{"price":11040000.0,"size":0.00777181},{"price":11035865.0,"size":0.1},{"price":11035200.0,"size":0.001},{"price":11035000.0,"size":0.0013},{"price":11030200.0,"size":0.001},{"price":11030000.0,"size":0.025},{"price":11025500.0,"size":0.009531},{"price":11025200.0,"size":0.001},{"price":11025000.0,"size":0.71497},{"price":11020772.0,"size":0.014},{"price":11020200.0,"size":0.002},{"price":11020000.0,"size":0.005},{"price":11015200.0,"size":0.001},{"price":11012000.0,"size":0.1},{"price":11011800.0,"size":0.001},{"price":11010200.0,"size":0.001},{"price":11010000.0,"size":0.347},{"price":11007277.0,"size":0.01},{"price":11005200.0,"size":0.001},{"price":11004890.0,"size":0.001535},{"price":11003000.0,"size":0.0155},{"price":11001000.0,"size":0.013},{"price":11000500.0,"size":0.05117658},{"price":11000200.0,"size":0.001},{"price":11000002.0,"size":0.004},{"price":11000001.0,"size":0.02604},{"price":11000000.0,"size":4.53923365},{"price":10999999.0,"size":0.003},{"price":10999000.0,"size":0.001},{"price":10996855.0,"size":0.0011},{"price":10995200.0,"size":0.001},{"price":10994499.0,"size":0.00169176},{"price":10990200.0,"size":0.001},{"price":10990000.0,"size":0.10219},{"price":10989001.0,"size":0.00197},{"price":10988999.0,"size":0.001},{"price":10988324.0,"size":0.002},{"price":10987654.0,"size":0.001},{"price":10985200.0,"size":0.001},{"price":10985150.0,"size":0.01},{"price":10980500.0,"size":0.005},{"price":10980200.0,"size":0.001},{"price":10980002.0,"size":0.4},{"price":10980000.0,"size":0.028},{"price":10975200.0,"size":0.001},{"price":10975000.0,"size":0.1},{"price":10971261.0,"size":0.001}],"asks":[{"price":11389999.0,"size":0.02312182},{"price":11390000.0,"size":0.5705},{"price":11392010.0,"size":0.00142446},{"price":11392610.0,"size":0.2592},{"price":11392865.0,"size":0.014904},{"price":11393831.0,"size":0.014628},{"price":11394631.0,"size":0.014892},{"price":11394669.0,"size":0.00687018},{"price":11394858.0,"size":0.01},{"price":11395341.0,"size":0.014568},{"price":11395372.0,"size":0.2645},{"price":11397000.0,"size":0.02},{"price":11398134.0,"size":0.2684},{"price":11398297.0,"size":0.4249},{"price":11398444.0,"size":0.001995},{"price":11398845.0,"size":0.001},{"price":11399673.0,"size":0.0015},{"price":11399700.0,"size":0.001},{"price":11399900.0,"size":0.0554688},{"price":11399999.0,"size":0.05},{"price":11400000.0,"size":0.74832841},{"price":11400894.0,"size":0.57183323},{"price":11400896.0,"size":0.2634},{"price":11401752.0,"size":0.15},{"price":11403472.0,"size":0.002},{"price":11403959.0,"size":0.01},{"price":11405000.0,"size":0.1275},{"price":11407440.0,"size":0.0085},{"price":11408700.0,"size":0.001},{"price":11409415.0,"size":0.005},{"price":11409476.0,"size":1.189881},{"price":11409633.0,"size":1.189881},{"price":11410000.0,"size":0.3787},{"price":11410168.0,"size":0.001},{"price":11410853.0,"size":0.002},{"price":11412000.0,"size":0.0878},{"price":11415000.0,"size":0.1},{"price":11415141.0,"size":0.0041},{"price":11417481.0,"size":0.0015},{"price":11418700.0,"size":0.001},{"price":11419000.0,"size":0.01},{"price":11420000.0,"size":0.151},{"price":11421268.0,"size":0.05},{"price":11421490.0,"size":0.001},{"price":11424296.0,"size":0.002},{"price":11425000.0,"size":0.029},{"price":11425951.0,"size":0.21},{"price":11426426.0,"size":0.002},{"price":11428121.0,"size":0.002},{"price":11428700.0,"size":0.001},{"price":11429302.0,"size":0.01},{"price":11430000.0,"size":0.8098},{"price":11431752.0,"size":1.489},{"price":11432717.0,"size":1.53855676},{"price":11432718.0,"size":0.002},{"price":11432813.0,"size":0.001},{"price":11433211.0,"size":0.03},{"price":11433333.0,"size":0.001},{"price":11435877.0,"size":1.928},{"price":11437315.0,"size":0.002},{"price":11438525.0,"size":0.0011},{"price":11438700.0,"size":0.001},{"price":11439557.0,"size":0.001},{"price":11440000.0,"size":0.2538},{"price":11441911.0,"size":0.002},{"price":11442627.0,"size":2.018},{"price":11443629.0,"size":0.002},{"price":11444135.0,"size":0.001},{"price":11445433.0,"size":0.0015},{"price":11446508.0,"size":0.001},{"price":11447000.0,"size":0.01},{"price":11447071.0,"size":0.002},{"price":11448000.0,"size":0.0875},{"price":11448700.0,"size":0.001},{"price":11450000.0,"size":0.268},{"price":11451105.0,"size":0.002},{"price":11453321.0,"size":0.03},{"price":11455000.0,"size":0.001},{"price":11455457.0,"size":0.001},{"price":11455702.0,"size":0.002},{"price":11458700.0,"size":0.001},{"price":11458988.0,"size":0.01},{"price":11460000.0,"size":0.06702},{"price":11460299.0,"size":0.002},{"price":11463288.0,"size":0.01},{"price":11464896.0,"size":0.002},{"price":11465382.0,"size":0.00195},{"price":11465421.0,"size":1.943},{"price":11466780.0,"size":0.001},{"price":11468700.0,"size":0.001},{"price":11470000.0,"size":0.06},{"price":11471000.0,"size":0.01},{"price":11475000.0,"size":0.0028},{"price":11476929.0,"size":1.0},{"price":11478102.0,"size":0.001},{"price":11478431.0,"size":0.002},{"price":11478700.0,"size":0.001},{"price":11480000.0,"size":0.40191},{"price":11485000.0,"size":0.01},{"price":11485488.0,"size":2.0},{"price":11486555.0,"size":0.03},{"price":11487685.0,"size":0.01},{"price":11488000.0,"size":0.102},{"price":11488700.0,"size":0.001},{"price":11489425.0,"size":0.001},{"price":11490000.0,"size":0.05},{"price":11490841.0,"size":0.002},{"price":11495450.0,"size":0.002},{"price":11495850.0,"size":0.001},{"price":11498700.0,"size":0.001},{"price":11498917.0,"size":0.002},{"price":11499000.0,"size":0.01},{"price":11500000.0,"size":0.75959519},{"price":11500078.0,"size":0.93},{"price":11500747.0,"size":0.001},{"price":11502377.0,"size":0.002},{"price":11502800.0,"size":0.00132},{"price":11503108.0,"size":0.0198},{"price":11505000.0,"size":0.0028},{"price":11505001.0,"size":0.002},{"price":11505836.0,"size":0.003},{"price":11508431.0,"size":0.047},{"price":11508700.0,"size":0.001},{"price":11508888.0,"size":0.02},{"price":11510000.0,"size":0.1476},{"price":11512070.0,"size":0.001},{"price":11513633.0,"size":0.08},{"price":11514332.0,"size":0.02},{"price":11518700.0,"size":0.001},{"price":11518992.0,"size":0.002},{"price":11519855.0,"size":0.01},{"price":11520000.0,"size":0.001},{"price":11522388.0,"size":0.972},{"price":11523211.0,"size":0.01},{"price":11524999.0,"size":0.001},{"price":11528700.0,"size":0.001},{"price":11529852.0,"size":0.01},{"price":11530000.0,"size":0.261},{"price":11533985.0,"size":0.002},{"price":11534084.0,"size":0.001},{"price":11535321.0,"size":0.01},{"price":11538666.0,"size":0.002},{"price":11538700.0,"size":0.001},{"price":11540000.0,"size":0.0048},{"price":11540357.0,"size":0.002},{"price":11541011.0,"size":0.005},{"price":11541109.0,"size":0.01},{"price":11544663.0,"size":0.002},{"price":11545262.0,"size":0.002},{"price":11546541.0,"size":0.01},{"price":11548144.0,"size":0.002},{"price":11548700.0,"size":0.001},{"price":11550000.0,"size":0.014},{"price":11551109.0,"size":0.01},{"price":11551625.0,"size":0.002},{"price":11552111.0,"size":0.01},{"price":11553687.0,"size":0.1},{"price":11555106.0,"size":0.002},{"price":11555115.0,"size":0.001},{"price":11556000.0,"size":0.1},{"price":11558587.0,"size":0.002},{"price":11558700.0,"size":0.001},{"price":11559855.0,"size":0.01},{"price":11560831.0,"size":0.0198},{"price":11561109.0,"size":0.01},{"price":11562000.0,"size":0.087},{"price":11562068.0,"size":0.002},{"price":11563750.0,"size":0.08739676},{"price":11565548.0,"size":0.002},{"price":11566139.0,"size":0.0228},{"price":11566551.0,"size":0.01},{"price":11568700.0,"size":0.001},{"price":11569029.0,"size":0.002},{"price":11570196.0,"size":0.002},{"price":11571109.0,"size":0.01},{"price":11572510.0,"size":0.002},{"price":11573211.0,"size":0.01},{"price":11574840.0,"size":0.002},{"price":11575991.0,"size":0.001},{"price":11578700.0,"size":0.001},{"price":11579484.0,"size":0.002},{"price":11579851.0,"size":0.01},{"price":11580000.0,"size":0.7835},{"price":11581109.0,"size":0.01},{"price":11584128.0,"size":0.002},{"price":11585000.0,"size":0.002},{"price":11586532.0,"size":0.01},{"price":11587498.0,"size":0.0198},{"price":11588700.0,"size":0.001},{"price":11588800.0,"size":0.02},{"price":11590000.0,"size":0.1},{"price":11590749.0,"size":0.002},{"price":11591109.0,"size":0.01},{"price":11593211.0,"size":0.01},{"price":11596753.0,"size":0.002},{"price":11598111.0,"size":0.1474},{"price":11598555.0,"size":0.01},{"price":11598700.0,"size":0.001},{"price":11599999.0,"size":0.001},{"price":11600000.0,"size":3.655},{"price":11601109.0,"size":0.02},{"price":11603764.0,"size":0.9},{"price":11606655.0,"size":0.01},{"price":11610000.0,"size":0.302},{"price":11611109.0,"size":0.01},{"price":11613321.0,"size":0.01},{"price":11620000.0,"size":1.35441682},{"price":11621011.0,"size":0.01},{"price":11621109.0,"size":0.01},{"price":11623096.0,"size":0.008},{"price":11629000.0,"size":0.1},{"price":11630000.0,"size":0.201},{"price":11631059.0,"size":0.01},{"price":11631479.0,"size":0.01},{"price":11631773.0,"size":0.00386871},{"price":11635950.0,"size":0.001},{"price":11638259.0,"size":0.001},{"price":11639700.0,"size":0.001},{"price":11640000.0,"size":1.0},{"price":11640820.0,"size":0.01},{"price":11649900.0,"size":0.02906},{"price":11649999.0,"size":0.001},{"price":11650000.0,"size":0.593},{"price":11651059.0,"size":0.01},{"price":11653658.0,"size":0.008},{"price":11654321.0,"size":0.001},{"price":11659700.0,"size":0.001},{"price":11661479.0,"size":0.01},{"price":11666000.0,"size":0.001},{"price":11666666.0,"size":0.013},{"price":11669700.0,"size":0.001},{"price":11671059.0,"size":0.01},{"price":11672562.0,"size":0.0198},{"price":11680000.0,"size":0.014},{"price":11685000.0,"size":0.003},{"price":11688000.0,"size":0.001},{"price":11689732.0,"size":0.01},{"price":11690330.0,"size":0.0198},{"price":11691059.0,"size":0.01},{"price":11692558.0,"size":0.01},{"price":11695019.0,"size":0.0064},{"price":11698800.0,"size":0.00131},{"price":11699000.0,"size":0.001},{"price":11699631.0,"size":0.001},{"price":11699998.0,"size":0.01},{"price":11699999.0,"size":0.001},{"price":11700000.0,"size":1.2573},{"price":11701059.0,"size":0.01},{"price":11720000.0,"size":0.1},{"price":11721059.0,"size":0.01},{"price":11725000.0,"size":0.005},{"price":11726791.0,"size":0.01},{"price":11727418.0,"size":1.8},{"price":11728195.0,"size":0.05},{"price":11730000.0,"size":1.9712},{"price":11740000.0,"size":0.101},{"price":11741059.0,"size":0.01},{"price":11748937.0,"size":0.001},{"price":11749999.0,"size":0.001},{"price":11750000.0,"size":0.89537866},{"price":11750050.0,"size":0.2},{"price":11751151.0,"size":0.01},{"price":11755000.0,"size":0.001},{"price":11757860.0,"size":1.82},{"price":11759999.0,"size":0.001},{"price":11760000.0,"size":0.001},{"price":11761059.0,"size":0.02},{"price":11765432.0,"size":0.001},{"price":11768000.0,"size":0.01},{"price":11770000.0,"size":0.25464896},{"price":11771059.0,"size":0.01755555},{"price":11772000.0,"size":0.002},{"price":11775000.0,"size":0.11593},{"price":11775222.0,"size":0.001657},{"price":11775577.0,"size":0.00013523},{"price":11775800.0,"size":0.001},{"price":11775900.0,"size":0.2},{"price":11775989.0,"size":0.005},{"price":11777000.0,"size":0.5956},{"price":11777777.0,"size":0.0067},{"price":11778541.0,"size":0.001},{"price":11779807.0,"size":0.001},{"price":11780000.0,"size":0.74298},{"price":11780800.0,"size":0.1},{"price":11781059.0,"size":0.01},{"price":11781238.0,"size":0.008},{"price":11785000.0,"size":0.055},{"price":11785040.0,"size":0.01},{"price":11786000.0,"size":0.585},{"price":11788000.0,"size":0.001},{"price":11788888.0,"size":0.005},{"price":11789000.0,"size":0.2},{"price":11789732.0,"size":0.01},{"price":11791100.0,"size":0.1},{"price":11791151.0,"size":0.01},{"price":11795000.0,"size":0.021},{"price":11795040.0,"size":0.015},{"price":11796103.0,"size":0.01},{"price":11798800.0,"size":0.005},{"price":11798950.0,"size":0.001}]}}}
{"schema_version":"collector.vnext.raw","schema_contract":null,"schema_contract_version":null,"payload_contract_version":null,"record_type":"market.orderbook.diff","record_id":"collector_main-market-orderbook-diff-000000000061","collector_id":"collector_main","collector_role":"production","host_name":"MAIN-PC","session_id":"collector_main-sess-20260315T000110Z-24871cd1","stream_session_id":"collector_main-stream-bitflyer-board_ws-20260315T000114Z-f0264830","exchange":"bitflyer","market":"spot","symbol":"BTC_JPY","instrument_id":"bitflyer.spot.BTC_JPY","channel":"board_ws","transport":"websocket","source_event_id":null,"source_sequence":null,"sequence_id":61,"exchange_ts":null,"collector_ts":"2026-03-15T00:01:14Z","ingest_ts":"2026-03-15T00:01:14Z","event_ts":"2026-03-15T00:01:14Z","quality_flags":[],"is_partial":false,"is_reconstructed":false,"confidence_score":1.0,"payload":{"provider":"bitflyer_ws_board","exchange":"bitflyer","transport":"websocket","channel":"lightning_board_BTC_JPY","received_ts":"2026-03-15T00:01:14.594774Z","subscription_id":null,"message_id":null,"source_sequence":null,"raw_message_meta":{"raw_channel":"lightning_board_BTC_JPY","subscription_channel":"lightning_board_BTC_JPY","recv_timeout_sec":10,"ssl_verify":false,"socket_url":"wss://ws.lightstream.bitflyer.com/json-rpc"},"source_payload":{"mid_price":11388709.0,"bids":[{"price":11385009.0,"size":0.0},{"price":11387421.0,"size":0.26600885},{"price":11383469.0,"size":0.04349341},{"price":11383090.0,"size":0.0}],"asks":[{"price":11401961.0,"size":0.0}]}}}
{"schema_version":"collector.vnext.raw","schema_contract":null,"schema_contract_version":null,"payload_contract_version":null,"record_type":"market.orderbook.diff","record_id":"collector_main-market-orderbook-diff-000000000065","collector_id":"collector_main","collector_role":"production","host_name":"MAIN-PC","session_id":"collector_main-sess-20260315T000110Z-24871cd1","stream_session_id":"collector_main-stream-bitflyer-board_ws-20260315T000114Z-f0264830","exchange":"bitflyer","market":"spot","symbol":"BTC_JPY","instrument_id":"bitflyer.spot.BTC_JPY","channel":"board_ws","transport":"websocket","source_event_id":null,"source_sequence":null,"sequence_id":65,"exchange_ts":null,"collector_ts":"2026-03-15T00:01:14Z","ingest_ts":"2026-03-15T00:01:14Z","event_ts":"2026-03-15T00:01:14Z","quality_flags":[],"is_partial":false,"is_reconstructed":false,"confidence_score":1.0,"payload":{"provider":"bitflyer_ws_board","exchange":"bitflyer","transport":"websocket","channel":"lightning_board_BTC_JPY","received_ts":"2026-03-15T00:01:14.735581Z","subscription_id":null,"message_id":null,"source_sequence":null,"raw_message_meta":{"raw_channel":"lightning_board_BTC_JPY","subscription_channel":"lightning_board_BTC_JPY","recv_timeout_sec":10,"ssl_verify":false,"socket_url":"wss://ws.lightstream.bitflyer.com/json-rpc"},"source_payload":{"mid_price":11388709.0,"bids":[{"price":11380708.0,"size":0.2},{"price":11363916.0,"size":0.30275919},{"price":11352866.0,"size":0.267}],"asks":[{"price":11399856.0,"size":0.0560736},{"price":11389999.0,"size":0.0}]}}}
{"schema_version":"collector.vnext.raw","schema_contract":null,"schema_contract_version":null,"payload_contract_version":null,"record_type":"market.orderbook.diff","record_id":"collector_main-market-orderbook-diff-000000000067","collector_id":"collector_main","collector_role":"production","host_name":"MAIN-PC","session_id":"collector_main-sess-20260315T000110Z-24871cd1","stream_session_id":"collector_main-stream-bitflyer-board_ws-20260315T000114Z-f0264830","exchange":"bitflyer","market":"spot","symbol":"BTC_JPY","instrument_id":"bitflyer.spot.BTC_JPY","channel":"board_ws","transport":"websocket","source_event_id":null,"source_sequence":null,"sequence_id":67,"exchange_ts":null,"collector_ts":"2026-03-15T00:01:14Z","ingest_ts":"2026-03-15T00:01:14Z","event_ts":"2026-03-15T00:01:14Z","quality_flags":[],"is_partial":false,"is_reconstructed":false,"confidence_score":1.0,"payload":{"provider":"bitflyer_ws_board","exchange":"bitflyer","transport":"websocket","channel":"lightning_board_BTC_JPY","received_ts":"2026-03-15T00:01:14.871196Z","subscription_id":null,"message_id":null,"source_sequence":null,"raw_message_meta":{"raw_channel":"lightning_board_BTC_JPY","subscription_channel":"lightning_board_BTC_JPY","recv_timeout_sec":10,"ssl_verify":false,"socket_url":"wss://ws.lightstream.bitflyer.com/json-rpc"},"source_payload":{"mid_price":11388497.0,"bids":[{"price":11383584.0,"size":0.1275},{"price":11376894.0,"size":3.11342603},{"price":11383016.0,"size":0.0},{"price":11378881.0,"size":0.015}],"asks":[{"price":11389997.0,"size":0.03835229},{"price":11389574.0,"size":0.04999},{"price":11393999.0,"size":0.0},{"price":11392945.0,"size":0.0}]}}}
{"schema_version":"collector.vnext.raw","schema_contract":null,"schema_contract_version":null,"payload_contract_version":null,"record_type":"market.orderbook.diff","record_id":"collector_main-market-orderbook-diff-000000000069","collector_id":"collector_main","collector_role":"production","host_name":"MAIN-PC","session_id":"collector_main-sess-20260315T000110Z-24871cd1","stream_session_id":"collector_main-stream-bitflyer-board_ws-20260315T000114Z-f0264830","exchange":"bitflyer","market":"spot","symbol":"BTC_JPY","instrument_id":"bitflyer.spot.BTC_JPY","channel":"board_ws","transport":"websocket","source_event_id":null,"source_sequence":null,"sequence_id":69,"exchange_ts":null,"collector_ts":"2026-03-15T00:01:14Z","ingest_ts":"2026-03-15T00:01:14Z","event_ts":"2026-03-15T00:01:14Z","quality_flags":[],"is_partial":false,"is_reconstructed":false,"confidence_score":1.0,"payload":{"provider":"bitflyer_ws_board","exchange":"bitflyer","transport":"websocket","channel":"lightning_board_BTC_JPY","received_ts":"2026-03-15T00:01:14.985828Z","subscription_id":null,"message_id":null,"source_sequence":null,"raw_message_meta":{"raw_channel":"lightning_board_BTC_JPY","subscription_channel":"lightning_board_BTC_JPY","recv_timeout_sec":10,"ssl_verify":false,"socket_url":"wss://ws.lightstream.bitflyer.com/json-rpc"},"source_payload":{"mid_price":11388497.0,"bids":[{"price":11382012.0,"size":0.015504}],"asks":[{"price":11389997.0,"size":0.02300429},{"price":11392574.0,"size":0.02}]}}}
{"schema_version":"collector.vnext.raw","schema_contract":null,"schema_contract_version":null,"payload_contract_version":null,"record_type":"market.orderbook.snapshot","record_id":"collector_main-market-orderbook-snapshot-000000000071","collector_id":"collector_main","collector_role":"production","host_name":"MAIN-PC","session_id":"collector_main-sess-20260315T000110Z-24871cd1","stream_session_id":"collector_main-stream-bitflyer-board_ws-20260315T000114Z-f0264830","exchange":"bitflyer","market":"spot","symbol":"BTC_JPY","instrument_id":"bitflyer.spot.BTC_JPY","channel":"board_ws","transport":"websocket","source_event_id":null,"source_sequence":null,"sequence_id":71,"exchange_ts":null,"collector_ts":"2026-03-15T00:01:15Z","ingest_ts":"2026-03-15T00:01:15Z","event_ts":"2026-03-15T00:01:15Z","quality_flags":[],"is_partial":false,"is_reconstructed":false,"confidence_score":1.0,"payload":{"provider":"bitflyer_ws_board_snapshot","exchange":"bitflyer","transport":"websocket","channel":"lightning_board_snapshot_BTC_JPY","received_ts":"2026-03-15T00:01:15.047210Z","subscription_id":null,"message_id":null,"source_sequence":null,"raw_message_meta":{"raw_channel":"lightning_board_snapshot_BTC_JPY","subscription_channel":"lightning_board_snapshot_BTC_JPY","recv_timeout_sec":10,"ssl_verify":false,"socket_url":"wss://ws.lightstream.bitflyer.com/json-rpc"},"source_payload":{"mid_price":11388497.0,"bids":[{"price":11387421.0,"size":0.26600885},{"price":11387420.0,"size":0.00999794},{"price":11383584.0,"size":0.1275},{"price":11383468.0,"size":0.1275},{"price":11382012.0,"size":0.015504},{"price":11381983.0,"size":0.5},{"price":11380708.0,"size":0.2},{"price":11380426.0,"size":0.0555984},{"price":11380159.0,"size":0.0527},{"price":11380121.0,"size":0.01},{"price":11379705.0,"size":0.5},{"price":11378881.0,"size":0.015},{"price":11378702.0,"size":0.0751},{"price":11376894.0,"size":3.11342603},{"price":11375000.0,"size":0.03},{"price":11371189.0,"size":0.97658726},{"price":11370955.0,"size":0.27},{"price":11370000.0,"size":0.005},{"price":11368376.0,"size":0.01},{"price":11365953.0,"size":0.002},{"price":11363916.0,"size":0.30275919},{"price":11363915.0,"size":0.12856523},{"price":11362535.0,"size":0.002},{"price":11362394.0,"size":1.484},{"price":11361152.0,"size":0.2587},{"price":11359117.0,"size":0.002},{"price":11358390.0,"size":0.2599},{"price":11358376.0,"size":0.01},{"price":11357601.0,"size":0.22},{"price":11356870.0,"size":0.6},{"price":11355699.0,"size":0.002},{"price":11355628.0,"size":0.2833},{"price":11352866.0,"size":0.267},{"price":11350000.0,"size":0.51},{"price":11348863.0,"size":0.002},{"price":11348823.0,"size":0.5},{"price":11348189.0,"size":0.003},{"price":11347667.0,"size":0.001},{"price":11345445.0,"size":0.002},{"price":11342981.0,"size":1.966},{"price":11342027.0,"size":0.002},{"price":11340000.0,"size":0.005},{"price":11338609.0,"size":0.002},{"price":11336383.0,"size":0.001},{"price":11336319.0,"size":0.00195},{"price":11335191.0,"size":0.002},{"price":11332840.0,"size":2.036},{"price":11331000.0,"size":0.5},{"price":11330000.0,"size":0.02442},{"price":11325101.0,"size":0.001},{"price":11320000.0,"size":0.05},{"price":11315000.0,"size":0.05},{"price":11314325.0,"size":1.951},{"price":11313996.0,"size":0.00195},{"price":11313819.0,"size":0.001},{"price":11310000.0,"size":0.01},{"price":11309999.0,"size":0.177},{"price":11307999.0,"size":0.01},{"price":11303918.0,"size":0.01},{"price":11303000.0,"size":0.5},{"price":11302535.0,"size":0.001},{"price":11302466.0,"size":0.001},{"price":11301268.0,"size":0.01},{"price":11300000.0,"size":3.01685256},{"price":11298000.0,"size":0.01},{"price":11297527.0,"size":1.13},{"price":11296865.0,"size":0.0015},{"price":11294756.0,"size":1.0},{"price":11291282.0,"size":0.001},{"price":11291268.0,"size":0.01},{"price":11291000.0,"size":0.5},{"price":11290000.0,"size":0.003},{"price":11281268.0,"size":0.01},{"price":11280000.0,"size":0.0163},{"price":11279960.0,"size":0.001},{"price":11279282.0,"size":0.0015},{"price":11278000.0,"size":0.0025},{"price":11275000.0,"size":0.001},{"price":11274588.0,"size":0.0047},{"price":11271268.0,"size":0.01},{"price":11271000.0,"size":0.003},{"price":11270000.0,"size":0.106},{"price":11269424.0,"size":0.8},{"price":11268871.0,"size":0.28},{"price":11268638.0,"size":0.001},{"price":11268411.0,"size":0.01},{"price":11266666.0,"size":0.04},{"price":11265000.0,"size":0.02},{"price":11263000.0,"size":0.006},{"price":11262564.0,"size":0.0015},{"price":11261268.0,"size":0.01},{"price":11260000.0,"size":0.3565},{"price":11257315.0,"size":0.001},{"price":11257000.0,"size":0.001},{"price":11255200.0,"size":0.001},{"price":11255115.0,"size":0.00377},{"price":11253814.0,"size":2.2},{"price":11253690.0,"size":0.01},{"price":11253000.0,"size":0.03189},{"price":11251405.0,"size":0.139},{"price":11251268.0,"size":0.01},{"price":11251111.0,"size":0.0015},{"price":11251000.0,"size":0.0131},{"price":11250250.0,"size":0.00105},{"price":11250200.0,"size":0.001},{"price":11250005.0,"size":0.001},{"price":11250001.0,"size":0.00104},{"price":11250000.0,"size":1.62712889},{"price":11245993.0,"size":0.001},{"price":11245141.0,"size":0.0031},{"price":11245000.0,"size":0.05},{"price":11244444.0,"size":0.04},{"price":11244243.0,"size":0.01},{"price":11240200.0,"size":0.001},{"price":11240000.0,"size":0.007304},{"price":11236190.0,"size":0.01},{"price":11235200.0,"size":0.001},{"price":11234670.0,"size":0.001},{"price":11232000.0,"size":0.089},{"price":11231243.0,"size":0.01},{"price":11231000.0,"size":0.105},{"price":11230200.0,"size":0.001},{"price":11230000.0,"size":0.0308},{"price":11226952.0,"size":0.972},{"price":11224500.0,"size":0.06},{"price":11223968.0,"size":0.001},{"price":11223348.0,"size":0.001},{"price":11223344.0,"size":0.01},{"price":11223000.0,"size":0.1},{"price":11222222.0,"size":0.093525},{"price":11221120.0,"size":0.001},{"price":11220200.0,"size":0.001},{"price":11220001.0,"size":0.004457},{"price":11220000.0,"size":0.321},{"price":11219000.0,"size":0.1},{"price":11217326.0,"size":0.02},{"price":11215200.0,"size":0.001},{"price":11213690.0,"size":0.01},{"price":11212025.0,"size":0.001},{"price":11211800.0,"size":0.001},{"price":11211111.0,"size":0.06},{"price":11210200.0,"size":0.001},{"price":11210000.0,"size":0.10622},{"price":11208032.0,"size":0.01},{"price":11206000.0,"size":0.09015},{"price":11205200.0,"size":0.001},{"price":11204578.0,"size":0.002},{"price":11201000.0,"size":0.01},{"price":11200800.0,"size":0.05},{"price":11200703.0,"size":0.001},{"price":11200425.0,"size":0.1},{"price":11200200.0,"size":0.001},{"price":11200198.0,"size":0.003},{"price":11200150.0,"size":0.002},{"price":11200002.0,"size":0.001},{"price":11200001.0,"size":0.01104},{"price":11200000.0,"size":1.15226728},{"price":11198508.0,"size":0.05},{"price":11198243.0,"size":0.01},{"price":11197134.0,"size":0.993},{"price":11197000.0,"size":0.0085},{"price":11194090.0,"size":0.03},{"price":11190770.0,"size":0.0309},{"price":11190000.0,"size":0.0010016},{"price":11189555.0,"size":0.5},{"price":11189381.0,"size":0.001},{"price":11188629.0,"size":0.01},{"price":11188382.0,"size":0.001},{"price":11185000.0,"size":0.0085},{"price":11180000.0,"size":0.225},{"price":11178058.0,"size":0.001},{"price":11170000.0,"size":0.001},{"price":11169662.0,"size":0.01},{"price":11169593.0,"size":0.001},{"price":11169243.0,"size":0.01},{"price":11166736.0,"size":0.001},{"price":11164029.0,"size":0.001},{"price":11160854.0,"size":0.1},{"price":11160000.0,"size":0.02376},{"price":11155413.0,"size":0.001},{"price":11155377.0,"size":0.00636009},{"price":11153999.0,"size":0.00101},{"price":11151000.0,"size":0.001},{"price":11150250.0,"size":0.00175},{"price":11150005.0,"size":0.001},{"price":11150001.0,"size":0.00104},{"price":11150000.0,"size":0.6533956},{"price":11148000.0,"size":0.08963},{"price":11147546.0,"size":0.02},{"price":11144091.0,"size":0.001},{"price":11144000.0,"size":0.0897},{"price":11143986.0,"size":0.02},{"price":11140139.0,"size":1.0},{"price":11140000.0,"size":0.2},{"price":11136243.0,"size":0.01},{"price":11135869.0,"size":0.1},{"price":11132768.0,"size":0.001},{"price":11130000.0,"size":0.116},{"price":11129979.0,"size":0.0053908},{"price":11124900.0,"size":0.00133},{"price":11121090.0,"size":0.1},{"price":11120000.0,"size":0.0033},{"price":11118078.0,"size":0.01},{"price":11111800.0,"size":0.001},{"price":11111111.0,"size":0.2919257},{"price":11111000.0,"size":0.003},{"price":11110594.0,"size":0.001},{"price":11110000.0,"size":0.021007},{"price":11109662.0,"size":0.01},{"price":11108008.0,"size":0.01},{"price":11102000.0,"size":0.5},{"price":11101297.0,"size":0.001},{"price":11100005.0,"size":0.001},{"price":11100001.0,"size":0.01104},{"price":11100000.0,"size":1.6532049},{"price":11099141.0,"size":0.01},{"price":11098833.0,"size":0.002},{"price":11096243.0,"size":0.01},{"price":11094090.0,"size":0.01},{"price":11088888.0,"size":0.001},{"price":11085245.0,"size":0.001},{"price":11080200.0,"size":0.001},{"price":11080000.0,"size":0.0223},{"price":11075100.0,"size":0.003},{"price":11070200.0,"size":0.001},{"price":11070000.0,"size":0.0902},{"price":11065200.0,"size":0.001},{"price":11064370.0,"size":0.00497091},{"price":11060200.0,"size":0.001},{"price":11060000.0,"size":0.145},{"price":11059689.0,"size":0.009},{"price":11056428.0,"size":0.002},{"price":11055500.0,"size":0.02},{"price":11055200.0,"size":0.001},{"price":11055100.0,"size":0.003},{"price":11050200.0,"size":0.001},{"price":11050005.0,"size":0.001},{"price":11050002.0,"size":0.001},{"price":11050001.0,"size":0.00104},{"price":11050000.0,"size":0.39576147},{"price":11048064.0,"size":2.0},{"price":11046420.0,"size":0.2},{"price":11044243.0,"size":0.01},{"price":11041380.0,"size":0.01},{"price":11040200.0,"size":0.001},{"price":11040000.0,"size":0.00777181},{"price":11035865.0,"size":0.1},{"price":11035200.0,"size":0.001},{"price":11035000.0,"size":0.0013},{"price":11030200.0,"size":0.001},{"price":11030000.0,"size":0.025},{"price":11025500.0,"size":0.009531},{"price":11025200.0,"size":0.001},{"price":11025000.0,"size":0.71497},{"price":11020772.0,"size":0.014},{"price":11020200.0,"size":0.002},{"price":11020000.0,"size":0.005},{"price":11015200.0,"size":0.001},{"price":11012000.0,"size":0.1},{"price":11011800.0,"size":0.001},{"price":11010200.0,"size":0.001},{"price":11010000.0,"size":0.347},{"price":11007277.0,"size":0.01},{"price":11005200.0,"size":0.001},{"price":11004890.0,"size":0.001535},{"price":11003000.0,"size":0.0155},{"price":11001000.0,"size":0.013},{"price":11000500.0,"size":0.05117658},{"price":11000200.0,"size":0.001},{"price":11000002.0,"size":0.004},{"price":11000001.0,"size":0.02604},{"price":11000000.0,"size":4.53923365},{"price":10999999.0,"size":0.003},{"price":10999000.0,"size":0.001},{"price":10996855.0,"size":0.0011},{"price":10995200.0,"size":0.001},{"price":10994499.0,"size":0.00169176},{"price":10990200.0,"size":0.001},{"price":10990000.0,"size":0.10219},{"price":10989001.0,"size":0.00197},{"price":10988999.0,"size":0.001},{"price":10988324.0,"size":0.002},{"price":10987654.0,"size":0.001},{"price":10985200.0,"size":0.001},{"price":10985150.0,"size":0.01},{"price":10980500.0,"size":0.005},{"price":10980200.0,"size":0.001},{"price":10980002.0,"size":0.4},{"price":10980000.0,"size":0.028},{"price":10975200.0,"size":0.001},{"price":10975000.0,"size":0.1},{"price":10971261.0,"size":0.001},{"price":10971243.0,"size":0.01},{"price":10970200.0,"size":0.001},{"price":10970000.0,"size":0.09304},{"price":10966600.0,"size":0.001003},{"price":10965200.0,"size":0.001},{"price":10960200.0,"size":0.001},{"price":10960000.0,"size":0.0083},{"price":10956673.0,"size":0.01}],"asks":[{"price":11389574.0,"size":0.04999},{"price":11389998.0,"size":0.014808},{"price":11390000.0,"size":0.0505},{"price":11392010.0,"size":0.00142446},{"price":11392081.0,"size":0.014652},{"price":11392568.0,"size":0.014544},{"price":11392574.0,"size":0.02},{"price":11392581.0,"size":0.1032},{"price":11392610.0,"size":0.2592},{"price":11393536.0,"size":0.02},{"price":11393537.0,"size":0.01446},{"price":11393830.0,"size":0.02},{"price":11394000.0,"size":0.5},{"price":11394669.0,"size":0.00687018},{"price":11394858.0,"size":0.01},{"price":11395372.0,"size":0.2645},{"price":11397000.0,"size":0.02},{"price":11397511.0,"size":0.0555984},{"price":11398134.0,"size":0.2684},{"price":11398297.0,"size":0.4249},{"price":11398444.0,"size":0.001995},{"price":11398845.0,"size":0.001},{"price":11399673.0,"size":0.0015},{"price":11399700.0,"size":0.001},{"price":11399856.0,"size":0.0560736},{"price":11399999.0,"size":0.05},{"price":11400000.0,"size":0.74832841},{"price":11400594.0,"size":0.57190123},{"price":11400896.0,"size":0.2634},{"price":11403472.0,"size":0.002},{"price":11403959.0,"size":0.01},{"price":11405000.0,"size":0.1275},{"price":11407440.0,"size":0.0085},{"price":11408700.0,"size":0.001},{"price":11409415.0,"size":0.005},{"price":11409476.0,"size":1.189881},{"price":11409633.0,"size":1.189881},{"price":11410000.0,"size":0.3787},{"price":11410168.0,"size":0.001},{"price":11410853.0,"size":0.002},{"price":11412000.0,"size":0.0878},{"price":11415000.0,"size":0.1},{"price":11415141.0,"size":0.0041},{"price":11417481.0,"size":0.0015},{"price":11418545.0,"size":1.489},{"price":11418700.0,"size":0.001},{"price":11419000.0,"size":0.01},{"price":11420000.0,"size":0.161},{"price":11421268.0,"size":0.05},{"price":11421490.0,"size":0.001},{"price":11424296.0,"size":0.002},{"price":11425000.0,"size":0.029},{"price":11425951.0,"size":0.21},{"price":11426426.0,"size":0.002},{"price":11428121.0,"size":0.002},{"price":11428700.0,"size":0.001},{"price":11429302.0,"size":0.01},{"price":11430000.0,"size":0.8098},{"price":11432717.0,"size":1.53855676},{"price":11432718.0,"size":0.002},{"price":11432813.0,"size":0.001},{"price":11433211.0,"size":0.03},{"price":11433333.0,"size":0.001},{"price":11435877.0,"size":1.928},{"price":11437315.0,"size":0.002},{"price":11438525.0,"size":0.0011},{"price":11438700.0,"size":0.001},{"price":11439557.0,"size":0.001},{"price":11440000.0,"size":0.2538},{"price":11441911.0,"size":0.002},{"price":11442627.0,"size":2.018},{"price":11443629.0,"size":0.002},{"price":11444135.0,"size":0.001},{"price":11445433.0,"size":0.0015},{"price":11446508.0,"size":0.001},{"price":11447000.0,"size":0.01},{"price":11447071.0,"size":0.002},{"price":11448000.0,"size":0.0875},{"price":11448700.0,"size":0.001},{"price":11450000.0,"size":0.268},{"price":11451105.0,"size":0.002},{"price":11453321.0,"size":0.03},{"price":11455000.0,"size":0.001},{"price":11455457.0,"size":0.001},{"price":11455702.0,"size":0.002},{"price":11458700.0,"size":0.001},{"price":11458988.0,"size":0.01},{"price":11460000.0,"size":0.06702},{"price":11460299.0,"size":0.002},{"price":11463288.0,"size":0.01},{"price":11464896.0,"size":0.002},{"price":11465382.0,"size":0.00195},{"price":11465421.0,"size":1.943},{"price":11466780.0,"size":0.001},{"price":11468700.0,"size":0.001},{"price":11470000.0,"size":0.06},{"price":11471000.0,"size":0.01},{"price":11475000.0,"size":0.0028},{"price":11476929.0,"size":1.0},{"price":11478102.0,"size":0.001},{"price":11478431.0,"size":0.002},{"price":11478700.0,"size":0.001},{"price":11480000.0,"size":0.40191},{"price":11485000.0,"size":0.01},{"price":11485488.0,"size":2.0},{"price":11486555.0,"size":0.03},{"price":11487685.0,"size":0.01},{"price":11488000.0,"size":0.102},{"price":11488700.0,"size":0.001},{"price":11489425.0,"size":0.001},{"price":11490000.0,"size":0.05},{"price":11495850.0,"size":0.001},{"price":11498700.0,"size":0.001},{"price":11498917.0,"size":0.002},{"price":11499000.0,"size":0.01},{"price":11500000.0,"size":0.77159519},{"price":11500078.0,"size":0.93},{"price":11500747.0,"size":0.001},{"price":11502377.0,"size":0.002},{"price":11502800.0,"size":0.00132},{"price":11503108.0,"size":0.0198},{"price":11505000.0,"size":0.0028},{"price":11505001.0,"size":0.002},{"price":11505836.0,"size":0.003},{"price":11508431.0,"size":0.047},{"price":11508700.0,"size":0.001},{"price":11508888.0,"size":0.02},{"price":11510000.0,"size":0.1476},{"price":11512070.0,"size":0.001},{"price":11513633.0,"size":0.08},{"price":11514332.0,"size":0.02},{"price":11518700.0,"size":0.001},{"price":11519855.0,"size":0.01},{"price":11520000.0,"size":0.001},{"price":11522388.0,"size":0.972},{"price":11523211.0,"size":0.01},{"price":11524999.0,"size":0.001},{"price":11528700.0,"size":0.001},{"price":11529852.0,"size":0.01},{"price":11530000.0,"size":0.261},{"price":11533985.0,"size":0.002},{"price":11534084.0,"size":0.001},{"price":11535321.0,"size":0.01},{"price":11538666.0,"size":0.002},{"price":11538700.0,"size":0.001},{"price":11540000.0,"size":0.0048},{"price":11541011.0,"size":0.005},{"price":11541109.0,"size":0.01},{"price":11544663.0,"size":0.002},{"price":11546541.0,"size":0.01},{"price":11548144.0,"size":0.002},{"price":11548700.0,"size":0.001},{"price":11550000.0,"size":0.014},{"price":11551109.0,"size":0.01},{"price":11551625.0,"size":0.002},{"price":11552111.0,"size":0.01},{"price":11553687.0,"size":0.1},{"price":11555106.0,"size":0.002},{"price":11555115.0,"size":0.001},{"price":11556000.0,"size":0.1},{"price":11558587.0,"size":0.002},{"price":11558700.0,"size":0.001},{"price":11559855.0,"size":0.01},{"price":11560831.0,"size":0.0198},{"price":11561109.0,"size":0.01},{"price":11562000.0,"size":0.087},{"price":11562068.0,"size":0.002},{"price":11563750.0,"size":0.08739676},{"price":11565548.0,"size":0.002},{"price":11566139.0,"size":0.0228},{"price":11566551.0,"size":0.01},{"price":11568700.0,"size":0.001},{"price":11569029.0,"size":0.002},{"price":11571109.0,"size":0.01},{"price":11572510.0,"size":0.002},{"price":11573211.0,"size":0.01},{"price":11575991.0,"size":0.001},{"price":11578700.0,"size":0.001},{"price":11579851.0,"size":0.01},{"price":11580000.0,"size":0.7835},{"price":11581109.0,"size":0.01},{"price":11585000.0,"size":0.002},{"price":11586532.0,"size":0.01},{"price":11587498.0,"size":0.0198},{"price":11588700.0,"size":0.001},{"price":11588800.0,"size":0.02},{"price":11590000.0,"size":0.1},{"price":11590749.0,"size":0.002},{"price":11591109.0,"size":0.01},{"price":11593211.0,"size":0.01},{"price":11598111.0,"size":0.1474},{"price":11598555.0,"size":0.01},{"price":11598700.0,"size":0.001},{"price":11599999.0,"size":0.001},{"price":11600000.0,"size":3.655},{"price":11601109.0,"size":0.02},{"price":11603764.0,"size":0.9},{"price":11606655.0,"size":0.01},{"price":11610000.0,"size":0.302},{"price":11611109.0,"size":0.01},{"price":11613321.0,"size":0.01},{"price":11620000.0,"size":1.35441682},{"price":11621011.0,"size":0.01},{"price":11621109.0,"size":0.01},{"price":11623096.0,"size":0.008},{"price":11629000.0,"size":0.1},{"price":11630000.0,"size":0.201},{"price":11631059.0,"size":0.01},{"price":11631479.0,"size":0.01},{"price":11631773.0,"size":0.00386871},{"price":11635950.0,"size":0.001},{"price":11638259.0,"size":0.001},{"price":11639700.0,"size":0.001},{"price":11640000.0,"size":1.0},{"price":11640820.0,"size":0.01},{"price":11649900.0,"size":0.02906},{"price":11649999.0,"size":0.001},{"price":11650000.0,"size":0.593},{"price":11651059.0,"size":0.01},{"price":11653658.0,"size":0.008},{"price":11654321.0,"size":0.001},{"price":11659700.0,"size":0.001},{"price":11661479.0,"size":0.01},{"price":11666000.0,"size":0.001},{"price":11666666.0,"size":0.013},{"price":11669700.0,"size":0.001},{"price":11671059.0,"size":0.01},{"price":11672562.0,"size":0.0198},{"price":11680000.0,"size":0.014},{"price":11685000.0,"size":0.003},{"price":11688000.0,"size":0.001},{"price":11689732.0,"size":0.01},{"price":11690330.0,"size":0.0198},{"price":11691059.0,"size":0.01},{"price":11692558.0,"size":0.01},{"price":11695019.0,"size":0.0064},{"price":11698800.0,"size":0.00131},{"price":11699000.0,"size":0.001},{"price":11699631.0,"size":0.001},{"price":11699998.0,"size":0.01},{"price":11699999.0,"size":0.001},{"price":11700000.0,"size":1.2573},{"price":11701059.0,"size":0.01},{"price":11720000.0,"size":0.1},{"price":11721059.0,"size":0.01},{"price":11725000.0,"size":0.005},{"price":11726791.0,"size":0.01},{"price":11727418.0,"size":1.8},{"price":11728195.0,"size":0.05},{"price":11730000.0,"size":1.9712},{"price":11740000.0,"size":0.101},{"price":11741059.0,"size":0.01},{"price":11748937.0,"size":0.001},{"price":11749999.0,"size":0.001},{"price":11750000.0,"size":0.89537866},{"price":11750050.0,"size":0.2},{"price":11751151.0,"size":0.01},{"price":11755000.0,"size":0.001},{"price":11757860.0,"size":1.82},{"price":11759999.0,"size":0.001},{"price":11760000.0,"size":0.001},{"price":11761059.0,"size":0.02},{"price":11765432.0,"size":0.001},{"price":11768000.0,"size":0.01},{"price":11770000.0,"size":0.25464896},{"price":11771059.0,"size":0.01755555},{"price":11772000.0,"size":0.002},{"price":11775000.0,"size":0.11593},{"price":11775222.0,"size":0.001657},{"price":11775577.0,"size":0.00013523},{"price":11775800.0,"size":0.001},{"price":11775900.0,"size":0.2},{"price":11775989.0,"size":0.005},{"price":11777000.0,"size":0.5956},{"price":11777777.0,"size":0.0067},{"price":11778541.0,"size":0.001},{"price":11779807.0,"size":0.001},{"price":11780000.0,"size":0.74298},{"price":11780800.0,"size":0.1},{"price":11781059.0,"size":0.01},{"price":11781238.0,"size":0.008},{"price":11785000.0,"size":0.055},{"price":11785040.0,"size":0.01},{"price":11786000.0,"size":0.585},{"price":11788000.0,"size":0.001},{"price":11788888.0,"size":0.005},{"price":11789000.0,"size":0.2},{"price":11789732.0,"size":0.01},{"price":11791100.0,"size":0.1},{"price":11791151.0,"size":0.01},{"price":11795000.0,"size":0.021},{"price":11795040.0,"size":0.015},{"price":11796103.0,"size":0.01},{"price":11798800.0,"size":0.005},{"price":11798950.0,"size":0.001},{"price":11799000.0,"size":0.013},{"price":11799510.0,"size":0.001},{"price":11799639.0,"size":0.01},{"price":11799999.0,"size":0.00769493},{"price":11800000.0,"size":1.10095}]}}}
{"schema_version":"collector.vnext.raw","schema_contract":null,"schema_contract_version":null,"payload_contract_version":null,"record_type":"market.orderbook.diff","record_id":"collector_main-market-orderbook-diff-000000000061","collector_id":"collector_main","collector_role":"production","host_name":"MAIN-PC","session_id":"collector_main-sess-20260315T000130Z-819b0092","stream_session_id":"collector_main-stream-bitflyer-board_ws-20260315T000131Z-fd0d05f9","exchange":"bitflyer","market":"spot","symbol":"BTC_JPY","instrument_id":"bitflyer.spot.BTC_JPY","channel":"board_ws","transport":"websocket","source_event_id":null,"source_sequence":null,"sequence_id":61,"exchange_ts":null,"collector_ts":"2026-03-15T00:01:31Z","ingest_ts":"2026-03-15T00:01:31Z","event_ts":"2026-03-15T00:01:31Z","quality_flags":[],"is_partial":false,"is_reconstructed":false,"confidence_score":1.0,"payload":{"provider":"bitflyer_ws_board","exchange":"bitflyer","transport":"websocket","channel":"lightning_board_BTC_JPY","received_ts":"2026-03-15T00:01:31.406808Z","subscription_id":null,"message_id":null,"source_sequence":null,"raw_message_meta":{"raw_channel":"lightning_board_BTC_JPY","subscription_channel":"lightning_board_BTC_JPY","recv_timeout_sec":10,"ssl_verify":false,"socket_url":"wss://ws.lightstream.bitflyer.com/json-rpc"},"source_payload":{"mid_price":11386143.0,"bids":[{"price":11381493.0,"size":0.00999794},{"price":11350104.0,"size":0.2648}],"asks":[]}}}
{"schema_version":"collector.vnext.raw","schema_contract":null,"schema_contract_version":null,"payload_contract_version":null,"record_type":"market.orderbook.diff","record_id":"collector_main-market-orderbook-diff-000000000065","collector_id":"collector_main","collector_role":"production","host_name":"MAIN-PC","session_id":"collector_main-sess-20260315T000130Z-819b0092","stream_session_id":"collector_main-stream-bitflyer-board_ws-20260315T000131Z-fd0d05f9","exchange":"bitflyer","market":"spot","symbol":"BTC_JPY","instrument_id":"bitflyer.spot.BTC_JPY","channel":"board_ws","transport":"websocket","source_event_id":null,"source_sequence":null,"sequence_id":65,"exchange_ts":null,"collector_ts":"2026-03-15T00:01:31Z","ingest_ts":"2026-03-15T00:01:31Z","event_ts":"2026-03-15T00:01:31Z","quality_flags":[],"is_partial":false,"is_reconstructed":false,"confidence_score":1.0,"payload":{"provider":"bitflyer_ws_board","exchange":"bitflyer","transport":"websocket","channel":"lightning_board_BTC_JPY","received_ts":"2026-03-15T00:01:31.531648Z","subscription_id":null,"message_id":null,"source_sequence":null,"raw_message_meta":{"raw_channel":"lightning_board_BTC_JPY","subscription_channel":"lightning_board_BTC_JPY","recv_timeout_sec":10,"ssl_verify":false,"socket_url":"wss://ws.lightstream.bitflyer.com/json-rpc"},"source_payload":{"mid_price":11384484.0,"bids":[{"price":11384810.0,"size":0.0},{"price":11381875.0,"size":0.0},{"price":11381028.0,"size":0.0},{"price":11381874.0,"size":0.0},{"price":11375001.0,"size":0.0}],"asks":[{"price":11400594.0,"size":0.0},{"price":11387569.0,"size":0.0},{"price":11387570.0,"size":0.1032},{"price":11387476.0,"size":0.01963998},{"price":11387477.0,"size":0.11167},{"price":11434543.0,"size":0.0},{"price":11396833.0,"size":0.57209772},{"price":11433823.0,"size":0.0}]}}}
{"schema_version":"collector.vnext.raw","schema_contract":null,"schema_contract_version":null,"payload_contract_version":null,"record_type":"market.orderbook.diff","record_id":"collector_main-market-orderbook-diff-000000000067","collector_id":"collector_main","collector_role":"production","host_name":"MAIN-PC","session_id":"collector_main-sess-20260315T000130Z-819b0092","stream_session_id":"collector_main-stream-bitflyer-board_ws-20260315T000131Z-fd0d05f9","exchange":"bitflyer","market":"spot","symbol":"BTC_JPY","instrument_id":"bitflyer.spot.BTC_JPY","channel":"board_ws","transport":"websocket","source_event_id":null,"source_sequence":null,"sequence_id":67,"exchange_ts":null,"collector_ts":"2026-03-15T00:01:31Z","ingest_ts":"2026-03-15T00:01:31Z","event_ts":"2026-03-15T00:01:31Z","quality_flags":[],"is_partial":false,"is_reconstructed":false,"confidence_score":1.0,"payload":{"provider":"bitflyer_ws_board","exchange":"bitflyer","transport":"websocket","channel":"lightning_board_BTC_JPY","received_ts":"2026-03-15T00:01:31.657768Z","subscription_id":null,"message_id":null,"source_sequence":null,"raw_message_meta":{"raw_channel":"lightning_board_BTC_JPY","subscription_channel":"lightning_board_BTC_JPY","recv_timeout_sec":10,"ssl_verify":false,"socket_url":"wss://ws.lightstream.bitflyer.com/json-rpc"},"source_payload":{"mid_price":11384484.0,"bids":[{"price":11381066.0,"size":0.05109216},{"price":11379705.0,"size":0.0},{"price":11381407.0,"size":0.0}],"asks":[{"price":11388809.0,"size":0.01464},{"price":11387543.0,"size":0.0},{"price":11389240.0,"size":0.0},{"price":11392081.0,"size":0.0}]}}}
{"schema_version":"collector.vnext.raw","schema_contract":null,"schema_contract_version":null,"payload_contract_version":null,"record_type":"market.orderbook.diff","record_id":"collector_main-market-orderbook-diff-000000000069","collector_id":"collector_main","collector_role":"production","host_name":"MAIN-PC","session_id":"collector_main-sess-20260315T000130Z-819b0092","stream_session_id":"collector_main-stream-bitflyer-board_ws-20260315T000131Z-fd0d05f9","exchange":"bitflyer","market":"spot","symbol":"BTC_JPY","instrument_id":"bitflyer.spot.BTC_JPY","channel":"board_ws","transport":"websocket","source_event_id":null,"source_sequence":null,"sequence_id":69,"exchange_ts":null,"collector_ts":"2026-03-15T00:01:31Z","ingest_ts":"2026-03-15T00:01:31Z","event_ts":"2026-03-15T00:01:31Z","quality_flags":[],"is_partial":false,"is_reconstructed":false,"confidence_score":1.0,"payload":{"provider":"bitflyer_ws_board","exchange":"bitflyer","transport":"websocket","channel":"lightning_board_BTC_JPY","received_ts":"2026-03-15T00:01:31.890924Z","subscription_id":null,"message_id":null,"source_sequence":null,"raw_message_meta":{"raw_channel":"lightning_board_BTC_JPY","subscription_channel":"lightning_board_BTC_JPY","recv_timeout_sec":10,"ssl_verify":false,"socket_url":"wss://ws.lightstream.bitflyer.com/json-rpc"},"source_payload":{"mid_price":11384600.0,"bids":[{"price":11374732.0,"size":0.5},{"price":11381724.0,"size":0.14053}],"asks":[]}}}
{"schema_version":"collector.vnext.raw","schema_contract":null,"schema_contract_version":null,"payload_contract_version":null,"record_type":"market.orderbook.diff","record_id":"collector_main-market-orderbook-diff-000000000071","collector_id":"collector_main","collector_role":"production","host_name":"MAIN-PC","session_id":"collector_main-sess-20260315T000130Z-819b0092","stream_session_id":"collector_main-stream-bitflyer-board_ws-20260315T000131Z-fd0d05f9","exchange":"bitflyer","market":"spot","symbol":"BTC_JPY","instrument_id":"bitflyer.spot.BTC_JPY","channel":"board_ws","transport":"websocket","source_event_id":null,"source_sequence":null,"sequence_id":71,"exchange_ts":null,"collector_ts":"2026-03-15T00:01:31Z","ingest_ts":"2026-03-15T00:01:31Z","event_ts":"2026-03-15T00:01:31Z","quality_flags":[],"is_partial":false,"is_reconstructed":false,"confidence_score":1.0,"payload":{"provider":"bitflyer_ws_board","exchange":"bitflyer","transport":"websocket","channel":"lightning_board_BTC_JPY","received_ts":"2026-03-15T00:01:31.985510Z","subscription_id":null,"message_id":null,"source_sequence":null,"raw_message_meta":{"raw_channel":"lightning_board_BTC_JPY","subscription_channel":"lightning_board_BTC_JPY","recv_timeout_sec":10,"ssl_verify":false,"socket_url":"wss://ws.lightstream.bitflyer.com/json-rpc"},"source_payload":{"mid_price":11384600.0,"bids":[{"price":11380708.0,"size":0.0}],"asks":[]}}}
{"schema_version":"collector.vnext.raw","schema_contract":null,"schema_contract_version":null,"payload_contract_version":null,"record_type":"market.orderbook.diff","record_id":"collector_main-market-orderbook-diff-000000000073","collector_id":"collector_main","collector_role":"production","host_name":"MAIN-PC","session_id":"collector_main-sess-20260315T000130Z-819b0092","stream_session_id":"collector_main-stream-bitflyer-board_ws-20260315T000131Z-fd0d05f9","exchange":"bitflyer","market":"spot","symbol":"BTC_JPY","instrument_id":"bitflyer.spot.BTC_JPY","channel":"board_ws","transport":"websocket","source_event_id":null,"source_sequence":null,"sequence_id":73,"exchange_ts":null,"collector_ts":"2026-03-15T00:01:32Z","ingest_ts":"2026-03-15T00:01:32Z","event_ts":"2026-03-15T00:01:32Z","quality_flags":[],"is_partial":false,"is_reconstructed":false,"confidence_score":1.0,"payload":{"provider":"bitflyer_ws_board","exchange":"bitflyer","transport":"websocket","channel":"lightning_board_BTC_JPY","received_ts":"2026-03-15T00:01:32.110758Z","subscription_id":null,"message_id":null,"source_sequence":null,"raw_message_meta":{"raw_channel":"lightning_board_BTC_JPY","subscription_channel":"lightning_board_BTC_JPY","recv_timeout_sec":10,"ssl_verify":false,"socket_url":"wss://ws.lightstream.bitflyer.com/json-rpc"},"source_payload":{"mid_price":11384600.0,"bids":[{"price":11380514.0,"size":0.0044404},{"price":11381065.0,"size":0.0},{"price":11381024.0,"size":0.0}],"asks":[]}}}
{"schema_version":"collector.vnext.raw","schema_contract":null,"schema_contract_version":null,"payload_contract_version":null,"record_type":"market.orderbook.diff","record_id":"collector_main-market-orderbook-diff-000000000075","collector_id":"collector_main","collector_role":"production","host_name":"MAIN-PC","session_id":"collector_main-sess-20260315T000130Z-819b0092","stream_session_id":"collector_main-stream-bitflyer-board_ws-20260315T000131Z-fd0d05f9","exchange":"bitflyer","market":"spot","symbol":"BTC_JPY","instrument_id":"bitflyer.spot.BTC_JPY","channel":"board_ws","transport":"websocket","source_event_id":null,"source_sequence":null,"sequence_id":75,"exchange_ts":null,"collector_ts":"2026-03-15T00:01:32Z","ingest_ts":"2026-03-15T00:01:32Z","event_ts":"2026-03-15T00:01:32Z","quality_flags":[],"is_partial":false,"is_reconstructed":false,"confidence_score":1.0,"payload":{"provider":"bitflyer_ws_board","exchange":"bitflyer","transport":"websocket","channel":"lightning_board_BTC_JPY","received_ts":"2026-03-15T00:01:32.234827Z","subscription_id":null,"message_id":null,"source_sequence":null,"raw_message_meta":{"raw_channel":"lightning_board_BTC_JPY","subscription_channel":"lightning_board_BTC_JPY","recv_timeout_sec":10,"ssl_verify":false,"socket_url":"wss://ws.lightstream.bitflyer.com/json-rpc"},"source_payload":{"mid_price":11384600.0,"bids":[{"price":11344440.0,"size":0.002},{"price":11374204.0,"size":3.11455013}],"asks":[{"price":11387535.0,"size":0.0175595}]}}}
{"schema_version":"collector.vnext.raw","schema_contract":null,"schema_contract_version":null,"payload_contract_version":null,"record_type":"market.orderbook.diff","record_id":"collector_main-market-orderbook-diff-000000000077","collector_id":"collector_main","collector_role":"production","host_name":"MAIN-PC","session_id":"collector_main-sess-20260315T000130Z-819b0092","stream_session_id":"collector_main-stream-bitflyer-board_ws-20260315T000131Z-fd0d05f9","exchange":"bitflyer","market":"spot","symbol":"BTC_JPY","instrument_id":"bitflyer.spot.BTC_JPY","channel":"board_ws","transport":"websocket","source_event_id":null,"source_sequence":null,"sequence_id":77,"exchange_ts":null,"collector_ts":"2026-03-15T00:01:32Z","ingest_ts":"2026-03-15T00:01:32Z","event_ts":"2026-03-15T00:01:32Z","quality_flags":[],"is_partial":false,"is_reconstructed":false,"confidence_score":1.0,"payload":{"provider":"bitflyer_ws_board","exchange":"bitflyer","transport":"websocket","channel":"lightning_board_BTC_JPY","received_ts":"2026-03-15T00:01:32.375544Z","subscription_id":null,"message_id":null,"source_sequence":null,"raw_message_meta":{"raw_channel":"lightning_board_BTC_JPY","subscription_channel":"lightning_board_BTC_JPY","recv_timeout_sec":10,"ssl_verify":false,"socket_url":"wss://ws.lightstream.bitflyer.com/json-rpc"},"source_payload":{"mid_price":11384600.0,"bids":[{"price":11381066.0,"size":0.0},{"price":11381725.0,"size":0.24},{"price":11378907.0,"size":0.1275}],"asks":[]}}}
{"schema_version":"collector.vnext.raw","schema_contract":null,"schema_contract_version":null,"payload_contract_version":null,"record_type":"market.orderbook.diff","record_id":"collector_main-market-orderbook-diff-000000000079","collector_id":"collector_main","collector_role":"production","host_name":"MAIN-PC","session_id":"collector_main-sess-20260315T000130Z-819b0092","stream_session_id":"collector_main-stream-bitflyer-board_ws-20260315T000131Z-fd0d05f9","exchange":"bitflyer","market":"spot","symbol":"BTC_JPY","instrument_id":"bitflyer.spot.BTC_JPY","channel":"board_ws","transport":"websocket","source_event_id":null,"source_sequence":null,"sequence_id":79,"exchange_ts":null,"collector_ts":"2026-03-15T00:01:32Z","ingest_ts":"2026-03-15T00:01:32Z","event_ts":"2026-03-15T00:01:32Z","quality_flags":[],"is_partial":false,"is_reconstructed":false,"confidence_score":1.0,"payload":{"provider":"bitflyer_ws_board","exchange":"bitflyer","transport":"websocket","channel":"lightning_board_BTC_JPY","received_ts":"2026-03-15T00:01:32.478497Z","subscription_id":null,"message_id":null,"source_sequence":null,"raw_message_meta":{"raw_channel":"lightning_board_BTC_JPY","subscription_channel":"lightning_board_BTC_JPY","recv_timeout_sec":10,"ssl_verify":false,"socket_url":"wss://ws.lightstream.bitflyer.com/json-rpc"},"source_payload":{"mid_price":11384600.0,"bids":[{"price":11380515.0,"size":0.0483829}],"asks":[]}}}
{"schema_version":"collector.vnext.raw","schema_contract":null,"schema_contract_version":null,"payload_contract_version":null,"record_type":"market.orderbook.diff","record_id":"collector_main-market-orderbook-diff-000000000081","collector_id":"collector_main","collector_role":"production","host_name":"MAIN-PC","session_id":"collector_main-sess-20260315T000130Z-819b0092","stream_session_id":"collector_main-stream-bitflyer-board_ws-20260315T000131Z-fd0d05f9","exchange":"bitflyer","market":"spot","symbol":"BTC_JPY","instrument_id":"bitflyer.spot.BTC_JPY","channel":"board_ws","transport":"websocket","source_event_id":null,"source_sequence":null,"sequence_id":81,"exchange_ts":null,"collector_ts":"2026-03-15T00:01:32Z","ingest_ts":"2026-03-15T00:01:32Z","event_ts":"2026-03-15T00:01:32Z","quality_flags":[],"is_partial":false,"is_reconstructed":false,"confidence_score":1.0,"payload":{"provider":"bitflyer_ws_board","exchange":"bitflyer","transport":"websocket","channel":"lightning_board_BTC_JPY","received_ts":"2026-03-15T00:01:32.584608Z","subscription_id":null,"message_id":null,"source_sequence":null,"raw_message_meta":{"raw_channel":"lightning_board_BTC_JPY","subscription_channel":"lightning_board_BTC_JPY","recv_timeout_sec":10,"ssl_verify":false,"socket_url":"wss://ws.lightstream.bitflyer.com/json-rpc"},"source_payload":{"mid_price":11384600.0,"bids":[{"price":11381067.0,"size":0.0},{"price":11372077.0,"size":0.28280171},{"price":11380515.0,"size":0.0}],"asks":[{"price":11387477.0,"size":0.0514}]}}}
{"schema_version":"collector.vnext.raw","schema_contract":null,"schema_contract_version":null,"payload_contract_version":null,"record_type":"market.orderbook.diff","record_id":"collector_main-market-orderbook-diff-000000000083","collector_id":"collector_main","collector_role":"production","host_name":"MAIN-PC","session_id":"collector_main-sess-20260315T000130Z-819b0092","stream_session_id":"collector_main-stream-bitflyer-board_ws-20260315T000131Z-fd0d05f9","exchange":"bitflyer","market":"spot","symbol":"BTC_JPY","instrument_id":"bitflyer.spot.BTC_JPY","channel":"board_ws","transport":"websocket","source_event_id":null,"source_sequence":null,"sequence_id":83,"exchange_ts":null,"collector_ts":"2026-03-15T00:01:32Z","ingest_ts":"2026-03-15T00:01:32Z","event_ts":"2026-03-15T00:01:32Z","quality_flags":[],"is_partial":false,"is_reconstructed":false,"confidence_score":1.0,"payload":{"provider":"bitflyer_ws_board","exchange":"bitflyer","transport":"websocket","channel":"lightning_board_BTC_JPY","received_ts":"2026-03-15T00:01:32.711058Z","subscription_id":null,"message_id":null,"source_sequence":null,"raw_message_meta":{"raw_channel":"lightning_board_BTC_JPY","subscription_channel":"lightning_board_BTC_JPY","recv_timeout_sec":10,"ssl_verify":false,"socket_url":"wss://ws.lightstream.bitflyer.com/json-rpc"},"source_payload":{"mid_price":11384600.0,"bids":[{"price":11380471.0,"size":0.015312},{"price":11378907.0,"size":0.0},{"price":11381724.0,"size":0.0},{"price":11380515.0,"size":0.04993426}],"asks":[{"price":11387872.0,"size":0.015312},{"price":11430139.0,"size":0.05}]}}}
{"schema_version":"collector.vnext.raw","schema_contract":null,"schema_contract_version":null,"payload_contract_version":null,"record_type":"market.orderbook.diff","record_id":"collector_main-market-orderbook-diff-000000000085","collector_id":"collector_main","collector_role":"production","host_name":"MAIN-PC","session_id":"collector_main-sess-20260315T000130Z-819b0092","stream_session_id":"collector_main-stream-bitflyer-board_ws-20260315T000131Z-fd0d05f9","exchange":"bitflyer","market":"spot","symbol":"BTC_JPY","instrument_id":"bitflyer.spot.BTC_JPY","channel":"board_ws","transport":"websocket","source_event_id":null,"source_sequence":null,"sequence_id":85,"exchange_ts":null,"collector_ts":"2026-03-15T00:01:32Z","ingest_ts":"2026-03-15T00:01:32Z","event_ts":"2026-03-15T00:01:32Z","quality_flags":[],"is_partial":false,"is_reconstructed":false,"confidence_score":1.0,"payload":{"provider":"bitflyer_ws_board","exchange":"bitflyer","transport":"websocket","channel":"lightning_board_BTC_JPY","received_ts":"2026-03-15T00:01:32.813252Z","subscription_id":null,"message_id":null,"source_sequence":null,"raw_message_meta":{"raw_channel":"lightning_board_BTC_JPY","subscription_channel":"lightning_board_BTC_JPY","recv_timeout_sec":10,"ssl_verify":false,"socket_url":"wss://ws.lightstream.bitflyer.com/json-rpc"},"source_payload":{"mid_price":11384600.0,"bids":[],"asks":[{"price":11430709.0,"size":0.0497}]}}}
{"schema_version":"collector.vnext.raw","schema_contract":null,"schema_contract_version":null,"payload_contract_version":null,"record_type":"market.orderbook.diff","record_id":"collector_main-market-orderbook-diff-000000000087","collector_id":"collector_main","collector_role":"production","host_name":"MAIN-PC","session_id":"collector_main-sess-20260315T000130Z-819b0092","stream_session_id":"collector_main-stream-bitflyer-board_ws-20260315T000131Z-fd0d05f9","exchange":"bitflyer","market":"spot","symbol":"BTC_JPY","instrument_id":"bitflyer.spot.BTC_JPY","channel":"board_ws","transport":"websocket","source_event_id":null,"source_sequence":null,"sequence_id":87,"exchange_ts":null,"collector_ts":"2026-03-15T00:01:32Z","ingest_ts":"2026-03-15T00:01:32Z","event_ts":"2026-03-15T00:01:32Z","quality_flags":[],"is_partial":false,"is_reconstructed":false,"confidence_score":1.0,"payload":{"provider":"bitflyer_ws_board","exchange":"bitflyer","transport":"websocket","channel":"lightning_board_BTC_JPY","received_ts":"2026-03-15T00:01:32.938944Z","subscription_id":null,"message_id":null,"source_sequence":null,"raw_message_meta":{"raw_channel":"lightning_board_BTC_JPY","subscription_channel":"lightning_board_BTC_JPY","recv_timeout_sec":10,"ssl_verify":false,"socket_url":"wss://ws.lightstream.bitflyer.com/json-rpc"},"source_payload":{"mid_price":11385172.0,"bids":[{"price":11381754.0,"size":0.0},{"price":11382869.0,"size":0.14053},{"price":11378338.0,"size":0.1275},{"price":11381725.0,"size":0.0}],"asks":[{"price":11389998.0,"size":0.0},{"price":11402150.0,"size":0.0}]}}}
{"schema_version":"collector.vnext.raw","schema_contract":null,"schema_contract_version":null,"payload_contract_version":null,"record_type":"market.orderbook.diff","record_id":"collector_main-market-orderbook-diff-000000000089","collector_id":"collector_main","collector_role":"production","host_name":"MAIN-PC","session_id":"collector_main-sess-20260315T000130Z-819b0092","stream_session_id":"collector_main-stream-bitflyer-board_ws-20260315T000131Z-fd0d05f9","exchange":"bitflyer","market":"spot","symbol":"BTC_JPY","instrument_id":"bitflyer.spot.BTC_JPY","channel":"board_ws","transport":"websocket","source_event_id":null,"source_sequence":null,"sequence_id":89,"exchange_ts":null,"collector_ts":"2026-03-15T00:01:33Z","ingest_ts":"2026-03-15T00:01:33Z","event_ts":"2026-03-15T00:01:33Z","quality_flags":[],"is_partial":false,"is_reconstructed":false,"confidence_score":1.0,"payload":{"provider":"bitflyer_ws_board","exchange":"bitflyer","transport":"websocket","channel":"lightning_board_BTC_JPY","received_ts":"2026-03-15T00:01:33.078702Z","subscription_id":null,"message_id":null,"source_sequence":null,"raw_message_meta":{"raw_channel":"lightning_board_BTC_JPY","subscription_channel":"lightning_board_BTC_JPY","recv_timeout_sec":10,"ssl_verify":false,"socket_url":"wss://ws.lightstream.bitflyer.com/json-rpc"},"source_payload":{"mid_price":11385172.0,"bids":[],"asks":[{"price":11399792.0,"size":0.0526}]}}}
{"schema_version":"collector.vnext.raw","schema_contract":null,"schema_contract_version":null,"payload_contract_version":null,"record_type":"market.orderbook.diff","record_id":"collector_main-market-orderbook-diff-000000000091","collector_id":"collector_main","collector_role":"production","host_name":"MAIN-PC","session_id":"collector_main-sess-20260315T000130Z-819b0092","stream_session_id":"collector_main-stream-bitflyer-board_ws-20260315T000131Z-fd0d05f9","exchange":"bitflyer","market":"spot","symbol":"BTC_JPY","instrument_id":"bitflyer.spot.BTC_JPY","channel":"board_ws","transport":"websocket","source_event_id":null,"source_sequence":null,"sequence_id":91,"exchange_ts":null,"collector_ts":"2026-03-15T00:01:33Z","ingest_ts":"2026-03-15T00:01:33Z","event_ts":"2026-03-15T00:01:33Z","quality_flags":[],"is_partial":false,"is_reconstructed":false,"confidence_score":1.0,"payload":{"provider":"bitflyer_ws_board","exchange":"bitflyer","transport":"websocket","channel":"lightning_board_BTC_JPY","received_ts":"2026-03-15T00:01:33.204287Z","subscription_id":null,"message_id":null,"source_sequence":null,"raw_message_meta":{"raw_channel":"lightning_board_BTC_JPY","subscription_channel":"lightning_board_BTC_JPY","recv_timeout_sec":10,"ssl_verify":false,"socket_url":"wss://ws.lightstream.bitflyer.com/json-rpc"},"source_payload":{"mid_price":11385172.0,"bids":[{"price":11378341.0,"size":0.1275},{"price":11368030.0,"size":0.31}],"asks":[]}}}
{"schema_version":"collector.vnext.raw","schema_contract":null,"schema_contract_version":null,"payload_contract_version":null,"record_type":"market.orderbook.diff","record_id":"collector_main-market-orderbook-diff-000000000093","collector_id":"collector_main","collector_role":"production","host_name":"MAIN-PC","session_id":"collector_main-sess-20260315T000130Z-819b0092","stream_session_id":"collector_main-stream-bitflyer-board_ws-20260315T000131Z-fd0d05f9","exchange":"bitflyer","market":"spot","symbol":"BTC_JPY","instrument_id":"bitflyer.spot.BTC_JPY","channel":"board_ws","transport":"websocket","source_event_id":null,"source_sequence":null,"sequence_id":93,"exchange_ts":null,"collector_ts":"2026-03-15T00:01:33Z","ingest_ts":"2026-03-15T00:01:33Z","event_ts":"2026-03-15T00:01:33Z","quality_flags":[],"is_partial":false,"is_reconstructed":false,"confidence_score":1.0,"payload":{"provider":"bitflyer_ws_board","exchange":"bitflyer","transport":"websocket","channel":"lightning_board_BTC_JPY","received_ts":"2026-03-15T00:01:33.468956Z","subscription_id":null,"message_id":null,"source_sequence":null,"raw_message_meta":{"raw_channel":"lightning_board_BTC_JPY","subscription_channel":"lightning_board_BTC_JPY","recv_timeout_sec":10,"ssl_verify":false,"socket_url":"wss://ws.lightstream.bitflyer.com/json-rpc"},"source_payload":{"mid_price":11385172.0,"bids":[{"price":11339884.0,"size":0.002},{"price":11380496.0,"size":0.0},{"price":11380121.0,"size":0.0}],"asks":[]}}}
{"schema_version":"collector.vnext.raw","schema_contract":null,"schema_contract_version":null,"payload_contract_version":null,"record_type":"market.orderbook.diff","record_id":"collector_main-market-orderbook-diff-000000000095","collector_id":"collector_main","collector_role":"production","host_name":"MAIN-PC","session_id":"collector_main-sess-20260315T000130Z-819b0092","stream_session_id":"collector_main-stream-bitflyer-board_ws-20260315T000131Z-fd0d05f9","exchange":"bitflyer","market":"spot","symbol":"BTC_JPY","instrument_id":"bitflyer.spot.BTC_JPY","channel":"board_ws","transport":"websocket","source_event_id":null,"source_sequence":null,"sequence_id":95,"exchange_ts":null,"collector_ts":"2026-03-15T00:01:33Z","ingest_ts":"2026-03-15T00:01:33Z","event_ts":"2026-03-15T00:01:33Z","quality_flags":[],"is_partial":false,"is_reconstructed":false,"confidence_score":1.0,"payload":{"provider":"bitflyer_ws_board","exchange":"bitflyer","transport":"websocket","channel":"lightning_board_BTC_JPY","received_ts":"2026-03-15T00:01:33.735905Z","subscription_id":null,"message_id":null,"source_sequence":null,"raw_message_meta":{"raw_channel":"lightning_board_BTC_JPY","subscription_channel":"lightning_board_BTC_JPY","recv_timeout_sec":10,"ssl_verify":false,"socket_url":"wss://ws.lightstream.bitflyer.com/json-rpc"},"source_payload":{"mid_price":11385172.0,"bids":[{"price":11377452.0,"size":0.0},{"price":11380471.0,"size":0.0},{"price":11374204.0,"size":0.0}],"asks":[{"price":11394532.0,"size":0.0},{"price":11399792.0,"size":0.0}]}}}
{"schema_version":"collector.vnext.raw","schema_contract":null,"schema_contract_version":null,"payload_contract_version":null,"record_type":"market.orderbook.diff","record_id":"collector_main-market-orderbook-diff-000000000097","collector_id":"collector_main","collector_role":"production","host_name":"MAIN-PC","session_id":"collector_main-sess-20260315T000130Z-819b0092","stream_session_id":"collector_main-stream-bitflyer-board_ws-20260315T000131Z-fd0d05f9","exchange":"bitflyer","market":"spot","symbol":"BTC_JPY","instrument_id":"bitflyer.spot.BTC_JPY","channel":"board_ws","transport":"websocket","source_event_id":null,"source_sequence":null,"sequence_id":97,"exchange_ts":null,"collector_ts":"2026-03-15T00:01:33Z","ingest_ts":"2026-03-15T00:01:33Z","event_ts":"2026-03-15T00:01:33Z","quality_flags":[],"is_partial":false,"is_reconstructed":false,"confidence_score":1.0,"payload":{"provider":"bitflyer_ws_board","exchange":"bitflyer","transport":"websocket","channel":"lightning_board_BTC_JPY","received_ts":"2026-03-15T00:01:33.844611Z","subscription_id":null,"message_id":null,"source_sequence":null,"raw_message_meta":{"raw_channel":"lightning_board_BTC_JPY","subscription_channel":"lightning_board_BTC_JPY","recv_timeout_sec":10,"ssl_verify":false,"socket_url":"wss://ws.lightstream.bitflyer.com/json-rpc"},"source_payload":{"mid_price":11385171.0,"bids":[{"price":11379539.0,"size":0.015324},{"price":11374415.0,"size":0.0551664}],"asks":[{"price":11391490.0,"size":0.0551664},{"price":11387474.0,"size":0.015324},{"price":11409476.0,"size":0.0},{"price":11389572.0,"size":0.0}]}}}
{"schema_version":"collector.vnext.raw","schema_contract":null,"schema_contract_version":null,"payload_contract_version":null,"record_type":"market.orderbook.diff","record_id":"collector_main-market-orderbook-diff-000000000099","collector_id":"collector_main","collector_role":"production","host_name":"MAIN-PC","session_id":"collector_main-sess-20260315T000130Z-819b0092","stream_session_id":"collector_main-stream-bitflyer-board_ws-20260315T000131Z-fd0d05f9","exchange":"bitflyer","market":"spot","symbol":"BTC_JPY","instrument_id":"bitflyer.spot.BTC_JPY","channel":"board_ws","transport":"websocket","source_event_id":null,"source_sequence":null,"sequence_id":99,"exchange_ts":null,"collector_ts":"2026-03-15T00:01:33Z","ingest_ts":"2026-03-15T00:01:33Z","event_ts":"2026-03-15T00:01:33Z","quality_flags":[],"is_partial":false,"is_reconstructed":false,"confidence_score":1.0,"payload":{"provider":"bitflyer_ws_board","exchange":"bitflyer","transport":"websocket","channel":"lightning_board_BTC_JPY","received_ts":"2026-03-15T00:01:33.996436Z","subscription_id":null,"message_id":null,"source_sequence":null,"raw_message_meta":{"raw_channel":"lightning_board_BTC_JPY","subscription_channel":"lightning_board_BTC_JPY","recv_timeout_sec":10,"ssl_verify":false,"socket_url":"wss://ws.lightstream.bitflyer.com/json-rpc"},"source_payload":{"mid_price":11385171.0,"bids":[],"asks":[{"price":11399792.0,"size":0.0085}]}}}
{"schema_version":"collector.vnext.raw","schema_contract":null,"schema_contract_version":null,"payload_contract_version":null,"record_type":"market.orderbook.diff","record_id":"collector_main-market-orderbook-diff-000000000101","collector_id":"collector_main","collector_role":"production","host_name":"MAIN-PC","session_id":"collector_main-sess-20260315T000130Z-819b0092","stream_session_id":"collector_main-stream-bitflyer-board_ws-20260315T000131Z-fd0d05f9","exchange":"bitflyer","market":"spot","symbol":"BTC_JPY","instrument_id":"bitflyer.spot.BTC_JPY","channel":"board_ws","transport":"websocket","source_event_id":null,"source_sequence":null,"sequence_id":101,"exchange_ts":null,"collector_ts":"2026-03-15T00:01:34Z","ingest_ts":"2026-03-15T00:01:34Z","event_ts":"2026-03-15T00:01:34Z","quality_flags":[],"is_partial":false,"is_reconstructed":false,"confidence_score":1.0,"payload":{"provider":"bitflyer_ws_board","exchange":"bitflyer","transport":"websocket","channel":"lightning_board_BTC_JPY","received_ts":"2026-03-15T00:01:34.122477Z","subscription_id":null,"message_id":null,"source_sequence":null,"raw_message_meta":{"raw_channel":"lightning_board_BTC_JPY","subscription_channel":"lightning_board_BTC_JPY","recv_timeout_sec":10,"ssl_verify":false,"socket_url":"wss://ws.lightstream.bitflyer.com/json-rpc"},"source_payload":{"mid_price":11385171.0,"bids":[{"price":11372078.0,"size":3.11439333}],"asks":[{"price":11387476.0,"size":0.0},{"price":11387473.0,"size":0.01856801}]}}}
{"schema_version":"collector.vnext.raw","schema_contract":null,"schema_contract_version":null,"payload_contract_version":null,"record_type":"market.orderbook.diff","record_id":"collector_main-market-orderbook-diff-000000000103","collector_id":"collector_main","collector_role":"production","host_name":"MAIN-PC","session_id":"collector_main-sess-20260315T000130Z-819b0092","stream_session_id":"collector_main-stream-bitflyer-board_ws-20260315T000131Z-fd0d05f9","exchange":"bitflyer","market":"spot","symbol":"BTC_JPY","instrument_id":"bitflyer.spot.BTC_JPY","channel":"board_ws","transport":"websocket","source_event_id":null,"source_sequence":null,"sequence_id":103,"exchange_ts":null,"collector_ts":"2026-03-15T00:01:34Z","ingest_ts":"2026-03-15T00:01:34Z","event_ts":"2026-03-15T00:01:34Z","quality_flags":[],"is_partial":false,"is_reconstructed":false,"confidence_score":1.0,"payload":{"provider":"bitflyer_ws_board","exchange":"bitflyer","transport":"websocket","channel":"lightning_board_BTC_JPY","received_ts":"2026-03-15T00:01:34.235589Z","subscription_id":null,"message_id":null,"source_sequence":null,"raw_message_meta":{"raw_channel":"lightning_board_BTC_JPY","subscription_channel":"lightning_board_BTC_JPY","recv_timeout_sec":10,"ssl_verify":false,"socket_url":"wss://ws.lightstream.bitflyer.com/json-rpc"},"source_payload":{"mid_price":11385171.0,"bids":[],"asks":[{"price":11424296.0,"size":0.002}]}}}
{"schema_version":"collector.vnext.raw","schema_contract":null,"schema_contract_version":null,"payload_contract_version":null,"record_type":"market.orderbook.diff","record_id":"collector_main-market-orderbook-diff-000000000105","collector_id":"collector_main","collector_role":"production","host_name":"MAIN-PC","session_id":"collector_main-sess-20260315T000130Z-819b0092","stream_session_id":"collector_main-stream-bitflyer-board_ws-20260315T000131Z-fd0d05f9","exchange":"bitflyer","market":"spot","symbol":"BTC_JPY","instrument_id":"bitflyer.spot.BTC_JPY","channel":"board_ws","transport":"websocket","source_event_id":null,"source_sequence":null,"sequence_id":105,"exchange_ts":null,"collector_ts":"2026-03-15T00:01:34Z","ingest_ts":"2026-03-15T00:01:34Z","event_ts":"2026-03-15T00:01:34Z","quality_flags":[],"is_partial":false,"is_reconstructed":false,"confidence_score":1.0,"payload":{"provider":"bitflyer_ws_board","exchange":"bitflyer","transport":"websocket","channel":"lightning_board_BTC_JPY","received_ts":"2026-03-15T00:01:34.460084Z","subscription_id":null,"message_id":null,"source_sequence":null,"raw_message_meta":{"raw_channel":"lightning_board_BTC_JPY","subscription_channel":"lightning_board_BTC_JPY","recv_timeout_sec":10,"ssl_verify":false,"socket_url":"wss://ws.lightstream.bitflyer.com/json-rpc"},"source_payload":{"mid_price":11385170.0,"bids":[],"asks":[{"price":11387471.0,"size":0.015528},{"price":11409633.0,"size":0.0},{"price":11430709.0,"size":0.0},{"price":11430139.0,"size":0.0}]}}}
{"schema_version":"collector.vnext.raw","schema_contract":null,"schema_contract_version":null,"payload_contract_version":null,"record_type":"market.orderbook.diff","record_id":"collector_main-market-orderbook-diff-000000000107","collector_id":"collector_main","collector_role":"production","host_name":"MAIN-PC","session_id":"collector_main-sess-20260315T000130Z-819b0092","stream_session_id":"collector_main-stream-bitflyer-board_ws-20260315T000131Z-fd0d05f9","exchange":"bitflyer","market":"spot","symbol":"BTC_JPY","instrument_id":"bitflyer.spot.BTC_JPY","channel":"board_ws","transport":"websocket","source_event_id":null,"source_sequence":null,"sequence_id":107,"exchange_ts":null,"collector_ts":"2026-03-15T00:01:34Z","ingest_ts":"2026-03-15T00:01:34Z","event_ts":"2026-03-15T00:01:34Z","quality_flags":[],"is_partial":false,"is_reconstructed":false,"confidence_score":1.0,"payload":{"provider":"bitflyer_ws_board","exchange":"bitflyer","transport":"websocket","channel":"lightning_board_BTC_JPY","received_ts":"2026-03-15T00:01:34.563703Z","subscription_id":null,"message_id":null,"source_sequence":null,"raw_message_meta":{"raw_channel":"lightning_board_BTC_JPY","subscription_channel":"lightning_board_BTC_JPY","recv_timeout_sec":10,"ssl_verify":false,"socket_url":"wss://ws.lightstream.bitflyer.com/json-rpc"},"source_payload":{"mid_price":11385170.0,"bids":[],"asks":[{"price":11392609.0,"size":0.0},{"price":11389275.0,"size":0.0}]}}}
{"schema_version":"collector.vnext.raw","schema_contract":null,"schema_contract_version":null,"payload_contract_version":null,"record_type":"market.orderbook.diff","record_id":"collector_main-market-orderbook-diff-000000000109","collector_id":"collector_main","collector_role":"production","host_name":"MAIN-PC","session_id":"collector_main-sess-20260315T000130Z-819b0092","stream_session_id":"collector_main-stream-bitflyer-board_ws-20260315T000131Z-fd0d05f9","exchange":"bitflyer","market":"spot","symbol":"BTC_JPY","instrument_id":"bitflyer.spot.BTC_JPY","channel":"board_ws","transport":"websocket","source_event_id":null,"source_sequence":null,"sequence_id":109,"exchange_ts":null,"collector_ts":"2026-03-15T00:01:34Z","ingest_ts":"2026-03-15T00:01:34Z","event_ts":"2026-03-15T00:01:34Z","quality_flags":[],"is_partial":false,"is_reconstructed":false,"confidence_score":1.0,"payload":{"provider":"bitflyer_ws_board","exchange":"bitflyer","transport":"websocket","channel":"lightning_board_BTC_JPY","received_ts":"2026-03-15T00:01:34.708616Z","subscription_id":null,"message_id":null,"source_sequence":null,"raw_message_meta":{"raw_channel":"lightning_board_BTC_JPY","subscription_channel":"lightning_board_BTC_JPY","recv_timeout_sec":10,"ssl_verify":false,"socket_url":"wss://ws.lightstream.bitflyer.com/json-rpc"},"source_payload":{"mid_price":11385169.0,"bids":[{"price":11378338.0,"size":0.0}],"asks":[{"price":11387473.0,"size":0.0},{"price":11387470.0,"size":0.01889343}]}}}
{"schema_version":"collector.vnext.raw","schema_contract":null,"schema_contract_version":null,"payload_contract_version":null,"record_type":"market.orderbook.diff","record_id":"collector_main-market-orderbook-diff-000000000111","collector_id":"collector_main","collector_role":"production","host_name":"MAIN-PC","session_id":"collector_main-sess-20260315T000130Z-819b0092","stream_session_id":"collector_main-stream-bitflyer-board_ws-20260315T000131Z-fd0d05f9","exchange":"bitflyer","market":"spot","symbol":"BTC_JPY","instrument_id":"bitflyer.spot.BTC_JPY","channel":"board_ws","transport":"websocket","source_event_id":null,"source_sequence":null,"sequence_id":111,"exchange_ts":null,"collector_ts":"2026-03-15T00:01:34Z","ingest_ts":"2026-03-15T00:01:34Z","event_ts":"2026-03-15T00:01:34Z","quality_flags":[],"is_partial":false,"is_reconstructed":false,"confidence_score":1.0,"payload":{"provider":"bitflyer_ws_board","exchange":"bitflyer","transport":"websocket","channel":"lightning_board_BTC_JPY","received_ts":"2026-03-15T00:01:34.829159Z","subscription_id":null,"message_id":null,"source_sequence":null,"raw_message_meta":{"raw_channel":"lightning_board_BTC_JPY","subscription_channel":"lightning_board_BTC_JPY","recv_timeout_sec":10,"ssl_verify":false,"socket_url":"wss://ws.lightstream.bitflyer.com/json-rpc"},"source_payload":{"mid_price":11384481.0,"bids":[{"price":11380515.0,"size":0.0},{"price":11382869.0,"size":0.0},{"price":11379539.0,"size":0.0}],"asks":[{"price":13869000.0,"size":0.001}]}}}
{"schema_version":"collector.vnext.raw","schema_contract":null,"schema_contract_version":null,"payload_contract_version":null,"record_type":"market.orderbook.diff","record_id":"collector_main-market-orderbook-diff-000000000113","collector_id":"collector_main","collector_role":"production","host_name":"MAIN-PC","session_id":"collector_main-sess-20260315T000130Z-819b0092","stream_session_id":"collector_main-stream-bitflyer-board_ws-20260315T000131Z-fd0d05f9","exchange":"bitflyer","market":"spot","symbol":"BTC_JPY","instrument_id":"bitflyer.spot.BTC_JPY","channel":"board_ws","transport":"websocket","source_event_id":null,"source_sequence":null,"sequence_id":113,"exchange_ts":null,"collector_ts":"2026-03-15T00:01:34Z","ingest_ts":"2026-03-15T00:01:34Z","event_ts":"2026-03-15T00:01:34Z","quality_flags":[],"is_partial":false,"is_reconstructed":false,"confidence_score":1.0,"payload":{"provider":"bitflyer_ws_board","exchange":"bitflyer","transport":"websocket","channel":"lightning_board_BTC_JPY","received_ts":"2026-03-15T00:01:34.953551Z","subscription_id":null,"message_id":null,"source_sequence":null,"raw_message_meta":{"raw_channel":"lightning_board_BTC_JPY","subscription_channel":"lightning_board_BTC_JPY","recv_timeout_sec":10,"ssl_verify":false,"socket_url":"wss://ws.lightstream.bitflyer.com/json-rpc"},"source_payload":{"mid_price":11384481.0,"bids":[{"price":11380160.0,"size":0.0},{"price":11375840.0,"size":0.015408},{"price":11378881.0,"size":0.0},{"price":11379540.0,"size":0.04558758},{"price":11358390.0,"size":0.0}],"asks":[{"price":11401775.0,"size":1.189881},{"price":11387535.0,"size":0.0},{"price":13877500.0,"size":0.001}]}}}
{"schema_version":"collector.vnext.raw","schema_contract":null,"schema_contract_version":null,"payload_contract_version":null,"record_type":"market.orderbook.diff","record_id":"collector_main-market-orderbook-diff-000000000115","collector_id":"collector_main","collector_role":"production","host_name":"MAIN-PC","session_id":"collector_main-sess-20260315T000130Z-819b0092","stream_session_id":"collector_main-stream-bitflyer-board_ws-20260315T000131Z-fd0d05f9","exchange":"bitflyer","market":"spot","symbol":"BTC_JPY","instrument_id":"bitflyer.spot.BTC_JPY","channel":"board_ws","transport":"websocket","source_event_id":null,"source_sequence":null,"sequence_id":115,"exchange_ts":null,"collector_ts":"2026-03-15T00:01:35Z","ingest_ts":"2026-03-15T00:01:35Z","event_ts":"2026-03-15T00:01:35Z","quality_flags":[],"is_partial":false,"is_reconstructed":false,"confidence_score":1.0,"payload":{"provider":"bitflyer_ws_board","exchange":"bitflyer","transport":"websocket","channel":"lightning_board_BTC_JPY","received_ts":"2026-03-15T00:01:35.048362Z","subscription_id":null,"message_id":null,"source_sequence":null,"raw_message_meta":{"raw_channel":"lightning_board_BTC_JPY","subscription_channel":"lightning_board_BTC_JPY","recv_timeout_sec":10,"ssl_verify":false,"socket_url":"wss://ws.lightstream.bitflyer.com/json-rpc"},"source_payload":{"mid_price":11384481.0,"bids":[{"price":11378882.0,"size":0.0},{"price":11374922.0,"size":0.1275},{"price":11379540.0,"size":0.0}],"asks":[]}}}
