{"schema_version":"collector.vnext.raw","schema_contract":null,"schema_contract_version":null,"payload_contract_version":null,"record_type":"market.orderbook.snapshot","record_id":"collector_main-market-orderbook-snapshot-000000000073","collector_id":"collector_main","collector_role":"production","host_name":"MAIN-PC","session_id":"collector_main-sess-20260315T000305Z-e8d4fe47","stream_session_id":"collector_main-stream-bitflyer-board_ws-20260315T000309Z-2e8d2a57","exchange":"bitflyer","market":"spot","symbol":"BTC_JPY","instrument_id":"bitflyer.spot.BTC_JPY","channel":"board_ws","transport":"websocket","source_event_id":null,"source_sequence":null,"sequence_id":73,"exchange_ts":null,"collector_ts":"2026-03-15T00:03:10Z","ingest_ts":"2026-03-15T00:03:10Z","event_ts":"2026-03-15T00:03:10Z","quality_flags":[],"is_partial":false,"is_reconstructed":false,"confidence_score":1.0,"payload":{"provider":"bitflyer_ws_board_snapshot","exchange":"bitflyer","transport":"websocket","channel":"lightning_board_snapshot_BTC_JPY","received_ts":"2026-03-15T00:03:10.302091Z","subscription_id":null,"message_id":null,"source_sequence":null,"raw_message_meta":{"raw_channel":"lightning_board_snapshot_BTC_JPY","subscription_channel":"lightning_board_snapshot_BTC_JPY","recv_timeout_sec":10,"ssl_verify":false,"socket_url":"wss://ws.lightstream.bitflyer.com/json-rpc"},"source_payload":{"mid_price":11375720.0,"bids":[{"price":11374040.0,"size":0.005},{"price":11373655.0,"size":0.14061},{"price":11371587.0,"size":0.02},{"price":11371380.0,"size":0.02},{"price":11370999.0,"size":0.02},{"price":11370998.0,"size":0.26595698},{"price":11370398.0,"size":0.00999792},{"price":11370049.0,"size":0.5},{"price":11370007.0,"size":0.01518},{"price":11370000.0,"size":0.005},{"price":11369239.0,"size":0.015},{"price":11369013.0,"size":0.2},{"price":11368686.0,"size":0.055296},{"price":11368376.0,"size":0.01},{"price":11368353.0,"size":0.01},{"price":11363830.0,"size":3.11650632},{"price":11363829.0,"size":0.01},{"price":11363366.0,"size":0.1},{"price":11362550.0,"size":0.0528},{"price":11362278.0,"size":0.34924621},{"price":11362277.0,"size":0.9772867},{"price":11362229.0,"size":0.07},{"price":11361538.0,"size":1.50015},{"price":11358439.0,"size":0.002},{"price":11358376.0,"size":0.01},{"price":11357858.0,"size":0.24},{"price":11355023.0,"size":0.002},{"price":11354613.0,"size":0.05},{"price":11354044.0,"size":0.05},{"price":11353488.0,"size":0.27174084},{"price":11351280.0,"size":0.2739},{"price":11350000.0,"size":0.51},{"price":11348518.0,"size":0.2616},{"price":11348191.0,"size":0.002},{"price":11348189.0,"size":0.003},{"price":11347667.0,"size":0.001},{"price":11347661.0,"size":0.6},{"price":11345756.0,"size":0.267},{"price":11345154.0,"size":1.484},{"price":11344775.0,"size":0.002},{"price":11342994.0,"size":0.2664},{"price":11341672.0,"size":0.05739971},{"price":11341671.0,"size":0.23},{"price":11341359.0,"size":0.002},{"price":11340000.0,"size":0.005},{"price":11338046.0,"size":1.966},{"price":11337943.0,"size":0.002},{"price":11336383.0,"size":0.001},{"price":11336319.0,"size":0.00195},{"price":11334527.0,"size":0.002},{"price":11331111.0,"size":0.002},{"price":11331000.0,"size":0.5},{"price":11330490.0,"size":2.036},{"price":11330000.0,"size":0.02442},{"price":11327695.0,"size":0.002},{"price":11325101.0,"size":0.001},{"price":11320000.0,"size":0.05},{"price":11315000.0,"size":0.05},{"price":11314325.0,"size":1.951},{"price":11313996.0,"size":0.00195},{"price":11313819.0,"size":0.001},{"price":11310000.0,"size":0.01},{"price":11309999.0,"size":0.177},{"price":11307999.0,"size":0.01},{"price":11303918.0,"size":0.01},{"price":11303000.0,"size":0.5},{"price":11302535.0,"size":0.001},{"price":11302466.0,"size":0.001},{"price":11301268.0,"size":0.01},{"price":11300000.0,"size":3.01685256},{"price":11298000.0,"size":0.01},{"price":11296865.0,"size":0.0015},{"price":11294756.0,"size":1.0},{"price":11291282.0,"size":0.001},{"price":11291268.0,"size":0.01},{"price":11291000.0,"size":0.5},{"price":11290000.0,"size":0.003},{"price":11281268.0,"size":0.01},{"price":11280000.0,"size":0.0163},{"price":11279960.0,"size":0.001},{"price":11279282.0,"size":0.0015},{"price":11278000.0,"size":0.0025},{"price":11275000.0,"size":0.001},{"price":11274588.0,"size":0.0047},{"price":11271268.0,"size":0.01},{"price":11271000.0,"size":0.003},{"price":11270000.0,"size":0.106},{"price":11269424.0,"size":0.8},{"price":11268871.0,"size":0.28},{"price":11268638.0,"size":0.001},{"price":11268411.0,"size":0.01},{"price":11266666.0,"size":0.04},{"price":11265000.0,"size":0.02},{"price":11263000.0,"size":0.006},{"price":11262564.0,"size":0.0015},{"price":11261268.0,"size":0.01},{"price":11260000.0,"size":0.3565},{"price":11257315.0,"size":0.001},{"price":11257000.0,"size":0.001},{"price":11255200.0,"size":0.001},{"price":11255115.0,"size":0.00377},{"price":11253814.0,"size":2.2},{"price":11253690.0,"size":0.01},{"price":11253000.0,"size":0.03189},{"price":11251405.0,"size":0.139},{"price":11251268.0,"size":0.01},{"price":11251111.0,"size":0.0015},{"price":11251000.0,"size":0.0131},{"price":11250250.0,"size":0.00105},{"price":11250200.0,"size":0.001},{"price":11250005.0,"size":0.001},{"price":11250001.0,"size":0.00104},{"price":11250000.0,"size":1.62712889},{"price":11245993.0,"size":0.001},{"price":11245141.0,"size":0.0031},{"price":11245000.0,"size":0.05},{"price":11244444.0,"size":0.04},{"price":11244243.0,"size":0.01},{"price":11240200.0,"size":0.001},{"price":11240000.0,"size":0.007304},{"price":11236190.0,"size":0.01},{"price":11235200.0,"size":0.001},{"price":11234670.0,"size":0.001},{"price":11232000.0,"size":0.089},{"price":11231243.0,"size":0.01},{"price":11231000.0,"size":0.105},{"price":11230200.0,"size":0.001},{"price":11230000.0,"size":0.0308},{"price":11226952.0,"size":0.972},{"price":11224500.0,"size":0.06},{"price":11223968.0,"size":0.001},{"price":11223348.0,"size":0.001},{"price":11223344.0,"size":0.01},{"price":11223000.0,"size":0.1},{"price":11222222.0,"size":0.093525},{"price":11221120.0,"size":0.001},{"price":11220200.0,"size":0.001},{"price":11220001.0,"size":0.004457},{"price":11220000.0,"size":0.321},{"price":11219000.0,"size":0.1},{"price":11217326.0,"size":0.02},{"price":11215200.0,"size":0.001},{"price":11213690.0,"size":0.01},{"price":11212025.0,"size":0.001},{"price":11211800.0,"size":0.001},{"price":11211111.0,"size":0.06},{"price":11210200.0,"size":0.001},{"price":11210000.0,"size":0.10622},{"price":11208032.0,"size":0.01},{"price":11206000.0,"size":0.09015},{"price":11205200.0,"size":0.001},{"price":11204578.0,"size":0.002},{"price":11201000.0,"size":0.01},{"price":11200800.0,"size":0.05},{"price":11200703.0,"size":0.001},{"price":11200425.0,"size":0.1},{"price":11200200.0,"size":0.001},{"price":11200198.0,"size":0.003},{"price":11200150.0,"size":0.002},{"price":11200002.0,"size":0.001},{"price":11200001.0,"size":0.01104},{"price":11200000.0,"size":1.15226728},{"price":11198508.0,"size":0.05},{"price":11198243.0,"size":0.01},{"price":11197134.0,"size":0.993},{"price":11197000.0,"size":0.0085},{"price":11194090.0,"size":0.03},{"price":11190770.0,"size":0.0309},{"price":11190000.0,"size":0.0010016},{"price":11189555.0,"size":0.5},{"price":11189381.0,"size":0.001},{"price":11188629.0,"size":0.01},{"price":11188382.0,"size":0.001},{"price":11185000.0,"size":0.0085},{"price":11180000.0,"size":0.225},{"price":11178058.0,"size":0.001},{"price":11170000.0,"size":0.001},{"price":11169662.0,"size":0.01},{"price":11169593.0,"size":0.001},{"price":11169243.0,"size":0.01},{"price":11166736.0,"size":0.001},{"price":11164029.0,"size":0.001},{"price":11160854.0,"size":0.1},{"price":11160000.0,"size":0.02376},{"price":11155413.0,"size":0.001},{"price":11155377.0,"size":0.00636009},{"price":11153999.0,"size":0.00101},{"price":11151000.0,"size":0.001},{"price":11150250.0,"size":0.00175},{"price":11150005.0,"size":0.001},{"price":11150001.0,"size":0.00104},{"price":11150000.0,"size":0.6533956},{"price":11148000.0,"size":0.08963},{"price":11147546.0,"size":0.02},{"price":11144091.0,"size":0.001},{"price":11144000.0,"size":0.0897},{"price":11143986.0,"size":0.02},{"price":11140139.0,"size":1.0},{"price":11140000.0,"size":0.2},{"price":11136243.0,"size":0.01},{"price":11135869.0,"size":0.1},{"price":11132768.0,"size":0.001},{"price":11130000.0,"size":0.116},{"price":11129979.0,"size":0.0053908},{"price":11124900.0,"size":0.00133},{"price":11121090.0,"size":0.1},{"price":11120000.0,"size":0.0033},{"price":11118078.0,"size":0.01},{"price":11111800.0,"size":0.001},{"price":11111111.0,"size":0.2919257},{"price":11111000.0,"size":0.003},{"price":11110594.0,"size":0.001},{"price":11110000.0,"size":0.021007},{"price":11109662.0,"size":0.01},{"price":11108008.0,"size":0.01},{"price":11102000.0,"size":0.5},{"price":11101297.0,"size":0.001},{"price":11100005.0,"size":0.001},{"price":11100001.0,"size":0.01104},{"price":11100000.0,"size":1.6532049},{"price":11099141.0,"size":0.01},{"price":11098833.0,"size":0.002},{"price":11096243.0,"size":0.01},{"price":11094090.0,"size":0.01},{"price":11088888.0,"size":0.001},{"price":11085245.0,"size":0.001},{"price":11080200.0,"size":0.001},{"price":11080000.0,"size":0.0223},{"price":11075100.0,"size":0.003},{"price":11070200.0,"size":0.001},{"price":11070000.0,"size":0.0902},{"price":11065200.0,"size":0.001},{"price":11064370.0,"size":0.00497091},{"price":11060200.0,"size":0.001},{"price":11060000.0,"size":0.145},{"price":11059689.0,"size":0.009},{"price":11056428.0,"size":0.002},{"price":11055500.0,"size":0.02},{"price":11055200.0,"size":0.001},{"price":11055100.0,"size":0.003},{"price":11050200.0,"size":0.001},{"price":11050005.0,"size":0.001},{"price":11050002.0,"size":0.001},{"price":11050001.0,"size":0.00104},{"price":11050000.0,"size":0.39576147},{"price":11048064.0,"size":2.0},{"price":11046420.0,"size":0.2},{"price":11044243.0,"size":0.01},{"price":11041380.0,"size":0.01},{"price":11040200.0,"size":0.001},{"price":11040000.0,"size":0.00777181},{"price":11035865.0,"size":0.1},{"price":11035200.0,"size":0.001},{"price":11035000.0,"size":0.0013},{"price":11030200.0,"size":0.001},{"price":11030000.0,"size":0.025},{"price":11025500.0,"size":0.009531},{"price":11025200.0,"size":0.001},{"price":11025000.0,"size":0.71497},{"price":11020772.0,"size":0.014},{"price":11020200.0,"size":0.002},{"price":11020000.0,"size":0.005},{"price":11015200.0,"size":0.001},{"price":11012000.0,"size":0.1},{"price":11011800.0,"size":0.001},{"price":11010200.0,"size":0.001},{"price":11010000.0,"size":0.347},{"price":11007277.0,"size":0.01},{"price":11005200.0,"size":0.001},{"price":11004890.0,"size":0.001535},{"price":11003000.0,"size":0.0155},{"price":11001000.0,"size":0.013},{"price":11000500.0,"size":0.05117658},{"price":11000200.0,"size":0.001},{"price":11000002.0,"size":0.004},{"price":11000001.0,"size":0.02604},{"price":11000000.0,"size":4.53923365},{"price":10999999.0,"size":0.003},{"price":10999000.0,"size":0.001},{"price":10996855.0,"size":0.0011},{"price":10995200.0,"size":0.001},{"price":10994499.0,"size":0.00169176},{"price":10990200.0,"size":0.001},{"price":10990000.0,"size":0.10219},{"price":10989001.0,"size":0.00197},{"price":10988999.0,"size":0.001},{"price":10988324.0,"size":0.002},{"price":10987654.0,"size":0.001},{"price":10985200.0,"size":0.001},{"price":10985150.0,"size":0.01},{"price":10980500.0,"size":0.005},{"price":10980200.0,"size":0.001},{"price":10980002.0,"size":0.4},{"price":10980000.0,"size":0.028},{"price":10975200.0,"size":0.001},{"price":10975000.0,"size":0.1},{"price":10971261.0,"size":0.001},{"price":10971243.0,"size":0.01},{"price":10970200.0,"size":0.001},{"price":10970000.0,"size":0.09304}],"asks":[{"price":11377401.0,"size":0.01518},{"price":11379723.0,"size":0.014928},{"price":11380489.0,"size":0.04384228},{"price":11380490.0,"size":0.01536},{"price":11381532.0,"size":0.0175688},{"price":11382108.0,"size":0.02},{"price":11382109.0,"size":0.301},{"price":11382750.0,"size":0.234},{"price":11384871.0,"size":0.2657},{"price":11385094.0,"size":0.01},{"price":11385327.0,"size":0.0552096},{"price":11387174.0,"size":0.1},{"price":11387633.0,"size":0.2976},{"price":11388351.0,"size":0.57250538},{"price":11390311.0,"size":0.0869},{"price":11391432.0,"size":0.4249},{"price":11392010.0,"size":0.00142446},{"price":11392044.0,"size":0.0085},{"price":11393747.0,"size":1.189881},{"price":11394441.0,"size":1.189881},{"price":11395219.0,"size":0.0497},{"price":11395788.0,"size":0.05},{"price":11397000.0,"size":0.02},{"price":11398444.0,"size":0.001995},{"price":11398845.0,"size":0.001},{"price":11399673.0,"size":0.0015},{"price":11399700.0,"size":0.001},{"price":11399999.0,"size":0.05},{"price":11400000.0,"size":0.64832841},{"price":11403472.0,"size":0.002},{"price":11405000.0,"size":0.1575},{"price":11405422.0,"size":1.489},{"price":11408699.0,"size":1.15098095},{"price":11408700.0,"size":0.001},{"price":11409415.0,"size":0.005},{"price":11409925.0,"size":0.22},{"price":11410000.0,"size":0.3787},{"price":11410168.0,"size":0.001},{"price":11410853.0,"size":0.002},{"price":11412000.0,"size":0.0878},{"price":11415000.0,"size":0.1},{"price":11415141.0,"size":0.0041},{"price":11417459.0,"size":1.928},{"price":11417481.0,"size":0.0015},{"price":11418700.0,"size":0.001},{"price":11419000.0,"size":0.01},{"price":11420000.0,"size":0.661},{"price":11421268.0,"size":0.05},{"price":11421490.0,"size":0.001},{"price":11424296.0,"size":0.002},{"price":11425000.0,"size":0.029},{"price":11426426.0,"size":0.002},{"price":11428121.0,"size":0.002},{"price":11428700.0,"size":0.001},{"price":11429302.0,"size":0.01},{"price":11430000.0,"size":0.4098},{"price":11432718.0,"size":0.002},{"price":11432813.0,"size":0.001},{"price":11433211.0,"size":0.03},{"price":11433333.0,"size":0.001},{"price":11437315.0,"size":0.002},{"price":11438525.0,"size":0.0011},{"price":11438700.0,"size":0.001},{"price":11439557.0,"size":0.001},{"price":11440000.0,"size":0.2538},{"price":11441911.0,"size":0.002},{"price":11442627.0,"size":2.018},{"price":11443629.0,"size":0.002},{"price":11444135.0,"size":0.001},{"price":11445433.0,"size":0.0015},{"price":11446508.0,"size":0.001},{"price":11447000.0,"size":0.01},{"price":11447071.0,"size":0.002},{"price":11448000.0,"size":0.0875},{"price":11448700.0,"size":0.001},{"price":11450000.0,"size":0.268},{"price":11451105.0,"size":0.002},{"price":11453321.0,"size":0.03},{"price":11455000.0,"size":0.001},{"price":11455457.0,"size":0.001},{"price":11455702.0,"size":0.002},{"price":11458700.0,"size":0.001},{"price":11458988.0,"size":0.01},{"price":11460000.0,"size":0.06702},{"price":11460299.0,"size":0.002},{"price":11463288.0,"size":0.01},{"price":11464896.0,"size":0.002},{"price":11465382.0,"size":0.00195},{"price":11465421.0,"size":1.943},{"price":11466780.0,"size":0.001},{"price":11468700.0,"size":0.001},{"price":11470000.0,"size":0.06},{"price":11471000.0,"size":0.01},{"price":11475000.0,"size":0.0028},{"price":11476929.0,"size":1.0},{"price":11478102.0,"size":0.001},{"price":11478431.0,"size":0.002},{"price":11478700.0,"size":0.001},{"price":11480000.0,"size":0.40191},{"price":11485000.0,"size":0.01},{"price":11485488.0,"size":2.0},{"price":11486555.0,"size":0.03},{"price":11487685.0,"size":0.01},{"price":11488000.0,"size":0.102},{"price":11488700.0,"size":0.001},{"price":11489425.0,"size":0.001},{"price":11490000.0,"size":0.05},{"price":11490841.0,"size":0.002},{"price":11495450.0,"size":0.002},{"price":11495850.0,"size":0.001},{"price":11498700.0,"size":0.001},{"price":11498917.0,"size":0.002},{"price":11499000.0,"size":0.01},{"price":11500000.0,"size":0.77159519},{"price":11500078.0,"size":0.93},{"price":11500747.0,"size":0.001},{"price":11502377.0,"size":0.002},{"price":11502800.0,"size":0.00132},{"price":11503108.0,"size":0.0198},{"price":11505000.0,"size":0.0028},{"price":11505001.0,"size":0.002},{"price":11505836.0,"size":0.003},{"price":11508431.0,"size":0.047},{"price":11508700.0,"size":0.001},{"price":11508888.0,"size":0.02},{"price":11510000.0,"size":0.1476},{"price":11512070.0,"size":0.001},{"price":11513633.0,"size":0.08},{"price":11514332.0,"size":0.02},{"price":11518700.0,"size":0.001},{"price":11518992.0,"size":0.002},{"price":11519855.0,"size":0.01},{"price":11520000.0,"size":0.001},{"price":11522388.0,"size":0.972},{"price":11523211.0,"size":0.01},{"price":11524999.0,"size":0.001},{"price":11528700.0,"size":0.001},{"price":11529852.0,"size":0.01},{"price":11530000.0,"size":0.261},{"price":11533985.0,"size":0.002},{"price":11534084.0,"size":0.001},{"price":11535321.0,"size":0.01},{"price":11538666.0,"size":0.002},{"price":11538700.0,"size":0.001},{"price":11540000.0,"size":0.0048},{"price":11540357.0,"size":0.002},{"price":11541011.0,"size":0.005},{"price":11541109.0,"size":0.01},{"price":11544663.0,"size":0.002},{"price":11545262.0,"size":0.002},{"price":11546541.0,"size":0.01},{"price":11548144.0,"size":0.002},{"price":11548700.0,"size":0.001},{"price":11550000.0,"size":0.014},{"price":11551109.0,"size":0.01},{"price":11551625.0,"size":0.002},{"price":11552111.0,"size":0.01},{"price":11553687.0,"size":0.1},{"price":11555106.0,"size":0.002},{"price":11555115.0,"size":0.001},{"price":11556000.0,"size":0.1},{"price":11558587.0,"size":0.002},{"price":11558700.0,"size":0.001},{"price":11559855.0,"size":0.01},{"price":11560831.0,"size":0.0198},{"price":11561109.0,"size":0.01},{"price":11562000.0,"size":0.087},{"price":11562068.0,"size":0.002},{"price":11563750.0,"size":0.08739676},{"price":11565548.0,"size":0.002},{"price":11566139.0,"size":0.0228},{"price":11566551.0,"size":0.01},{"price":11568700.0,"size":0.001},{"price":11569029.0,"size":0.002},{"price":11570196.0,"size":0.002},{"price":11571109.0,"size":0.01},{"price":11572510.0,"size":0.002},{"price":11573211.0,"size":0.01},{"price":11574840.0,"size":0.002},{"price":11575991.0,"size":0.001},{"price":11578700.0,"size":0.001},{"price":11579484.0,"size":0.002},{"price":11579851.0,"size":0.01},{"price":11580000.0,"size":0.7835},{"price":11581109.0,"size":0.01},{"price":11584128.0,"size":0.002},{"price":11585000.0,"size":0.002},{"price":11586532.0,"size":0.01},{"price":11587498.0,"size":0.0198},{"price":11588700.0,"size":0.001},{"price":11588800.0,"size":0.02},{"price":11590000.0,"size":0.1},{"price":11590749.0,"size":0.002},{"price":11591109.0,"size":0.01},{"price":11593211.0,"size":0.01},{"price":11598111.0,"size":0.1474},{"price":11598555.0,"size":0.01},{"price":11598700.0,"size":0.001},{"price":11599999.0,"size":0.001},{"price":11600000.0,"size":3.655},{"price":11601109.0,"size":0.02},{"price":11603764.0,"size":0.9},{"price":11606655.0,"size":0.01},{"price":11610000.0,"size":0.302},{"price":11611109.0,"size":0.01},{"price":11613321.0,"size":0.01},{"price":11620000.0,"size":1.35441682},{"price":11621011.0,"size":0.01},{"price":11621109.0,"size":0.01},{"price":11623096.0,"size":0.008},{"price":11625703.0,"size":0.012},{"price":11629000.0,"size":0.1},{"price":11630000.0,"size":0.201},{"price":11631059.0,"size":0.01},{"price":11631479.0,"size":0.01},{"price":11631773.0,"size":0.00386871},{"price":11635950.0,"size":0.001},{"price":11638259.0,"size":0.001},{"price":11639700.0,"size":0.001},{"price":11640000.0,"size":1.0},{"price":11640820.0,"size":0.01},{"price":11649900.0,"size":0.02906},{"price":11649999.0,"size":0.001},{"price":11650000.0,"size":0.593},{"price":11651059.0,"size":0.01},{"price":11653658.0,"size":0.008},{"price":11654321.0,"size":0.001},{"price":11659700.0,"size":0.001},{"price":11661479.0,"size":0.01},{"price":11666000.0,"size":0.001},{"price":11666666.0,"size":0.013},{"price":11669700.0,"size":0.001},{"price":11671059.0,"size":0.01},{"price":11672562.0,"size":0.0198},{"price":11680000.0,"size":0.014},{"price":11685000.0,"size":0.003},{"price":11688000.0,"size":0.001},{"price":11689732.0,"size":0.01},{"price":11690330.0,"size":0.0198},{"price":11691059.0,"size":0.01},{"price":11692558.0,"size":0.01},{"price":11695019.0,"size":0.0064},{"price":11698800.0,"size":0.00131},{"price":11699000.0,"size":0.001},{"price":11699631.0,"size":0.001},{"price":11699998.0,"size":0.01},{"price":11699999.0,"size":0.001},{"price":11700000.0,"size":1.2573},{"price":11701059.0,"size":0.01},{"price":11720000.0,"size":0.1},{"price":11721059.0,"size":0.01},{"price":11725000.0,"size":0.005},{"price":11726791.0,"size":0.01},{"price":11727418.0,"size":1.8},{"price":11728195.0,"size":0.05},{"price":11730000.0,"size":1.9712},{"price":11740000.0,"size":0.101},{"price":11741059.0,"size":0.01},{"price":11748937.0,"size":0.001},{"price":11749999.0,"size":0.001},{"price":11750000.0,"size":0.89537866},{"price":11750050.0,"size":0.2},{"price":11751151.0,"size":0.01},{"price":11751406.0,"size":0.012},{"price":11755000.0,"size":0.001},{"price":11757860.0,"size":1.82},{"price":11759999.0,"size":0.001},{"price":11760000.0,"size":0.001},{"price":11761059.0,"size":0.02},{"price":11765432.0,"size":0.001},{"price":11768000.0,"size":0.01},{"price":11770000.0,"size":0.25464896},{"price":11771059.0,"size":0.01755555},{"price":11772000.0,"size":0.002},{"price":11775000.0,"size":0.11593},{"price":11775222.0,"size":0.001657},{"price":11775577.0,"size":0.00013523},{"price":11775800.0,"size":0.001},{"price":11775900.0,"size":0.2},{"price":11775989.0,"size":0.005},{"price":11777000.0,"size":0.5956},{"price":11777777.0,"size":0.0067},{"price":11778541.0,"size":0.001},{"price":11779807.0,"size":0.001},{"price":11780000.0,"size":0.74298},{"price":11780800.0,"size":0.1},{"price":11781059.0,"size":0.01},{"price":11781238.0,"size":0.008},{"price":11785000.0,"size":0.055},{"price":11785040.0,"size":0.01},{"price":11786000.0,"size":0.585},{"price":11788000.0,"size":0.001},{"price":11788888.0,"size":0.005},{"price":11789000.0,"size":0.2},{"price":11789732.0,"size":0.01},{"price":11791100.0,"size":0.1},{"price":11791151.0,"size":0.01},{"price":11795000.0,"size":0.021},{"price":11795040.0,"size":0.015},{"price":11796103.0,"size":0.01}]}}}
{"schema_version":"collector.vnext.raw","schema_contract":null,"schema_contract_version":null,"payload_contract_version":null,"record_type":"market.orderbook.diff","record_id":"collector_main-market-orderbook-diff-000000000061","collector_id":"collector_main","collector_role":"production","host_name":"MAIN-PC","session_id":"collector_main-sess-20260315T000325Z-c12e2118","stream_session_id":"collector_main-stream-bitflyer-board_ws-20260315T000328Z-d111ce49","exchange":"bitflyer","market":"spot","symbol":"BTC_JPY","instrument_id":"bitflyer.spot.BTC_JPY","channel":"board_ws","transport":"websocket","source_event_id":null,"source_sequence":null,"sequence_id":61,"exchange_ts":null,"collector_ts":"2026-03-15T00:03:28Z","ingest_ts":"2026-03-15T00:03:28Z","event_ts":"2026-03-15T00:03:28Z","quality_flags":[],"is_partial":false,"is_reconstructed":false,"confidence_score":1.0,"payload":{"provider":"bitflyer_ws_board","exchange":"bitflyer","transport":"websocket","channel":"lightning_board_BTC_JPY","received_ts":"2026-03-15T00:03:28.220204Z","subscription_id":null,"message_id":null,"source_sequence":null,"raw_message_meta":{"raw_channel":"lightning_board_BTC_JPY","subscription_channel":"lightning_board_BTC_JPY","recv_timeout_sec":10,"ssl_verify":false,"socket_url":"wss://ws.lightstream.bitflyer.com/json-rpc"},"source_payload":{"mid_price":11375650.0,"bids":[{"price":11364726.0,"size":0.09}],"asks":[{"price":11375688.0,"size":0.0},{"price":11377456.0,"size":0.0},{"price":11379162.0,"size":0.1275}]}}}
{"schema_version":"collector.vnext.raw","schema_contract":null,"schema_contract_version":null,"payload_contract_version":null,"record_type":"market.orderbook.diff","record_id":"collector_main-market-orderbook-diff-000000000065","collector_id":"collector_main","collector_role":"production","host_name":"MAIN-PC","session_id":"collector_main-sess-20260315T000325Z-c12e2118","stream_session_id":"collector_main-stream-bitflyer-board_ws-20260315T000328Z-d111ce49","exchange":"bitflyer","market":"spot","symbol":"BTC_JPY","instrument_id":"bitflyer.spot.BTC_JPY","channel":"board_ws","transport":"websocket","source_event_id":null,"source_sequence":null,"sequence_id":65,"exchange_ts":null,"collector_ts":"2026-03-15T00:03:28Z","ingest_ts":"2026-03-15T00:03:28Z","event_ts":"2026-03-15T00:03:28Z","quality_flags":[],"is_partial":false,"is_reconstructed":false,"confidence_score":1.0,"payload":{"provider":"bitflyer_ws_board","exchange":"bitflyer","transport":"websocket","channel":"lightning_board_BTC_JPY","received_ts":"2026-03-15T00:03:28.312988Z","subscription_id":null,"message_id":null,"source_sequence":null,"raw_message_meta":{"raw_channel":"lightning_board_BTC_JPY","subscription_channel":"lightning_board_BTC_JPY","recv_timeout_sec":10,"ssl_verify":false,"socket_url":"wss://ws.lightstream.bitflyer.com/json-rpc"},"source_payload":{"mid_price":11376348.0,"bids":[],"asks":[{"price":11377765.0,"size":0.0}]}}}
{"schema_version":"collector.vnext.raw","schema_contract":null,"schema_contract_version":null,"payload_contract_version":null,"record_type":"market.orderbook.diff","record_id":"collector_main-market-orderbook-diff-000000000067","collector_id":"collector_main","collector_role":"production","host_name":"MAIN-PC","session_id":"collector_main-sess-20260315T000325Z-c12e2118","stream_session_id":"collector_main-stream-bitflyer-board_ws-20260315T000328Z-d111ce49","exchange":"bitflyer","market":"spot","symbol":"BTC_JPY","instrument_id":"bitflyer.spot.BTC_JPY","channel":"board_ws","transport":"websocket","source_event_id":null,"source_sequence":null,"sequence_id":67,"exchange_ts":null,"collector_ts":"2026-03-15T00:03:28Z","ingest_ts":"2026-03-15T00:03:28Z","event_ts":"2026-03-15T00:03:28Z","quality_flags":[],"is_partial":false,"is_reconstructed":false,"confidence_score":1.0,"payload":{"provider":"bitflyer_ws_board","exchange":"bitflyer","transport":"websocket","channel":"lightning_board_BTC_JPY","received_ts":"2026-03-15T00:03:28.422009Z","subscription_id":null,"message_id":null,"source_sequence":null,"raw_message_meta":{"raw_channel":"lightning_board_BTC_JPY","subscription_channel":"lightning_board_BTC_JPY","recv_timeout_sec":10,"ssl_verify":false,"socket_url":"wss://ws.lightstream.bitflyer.com/json-rpc"},"source_payload":{"mid_price":11376012.0,"bids":[],"asks":[{"price":11378489.0,"size":0.015576}]}}}
{"schema_version":"collector.vnext.raw","schema_contract":null,"schema_contract_version":null,"payload_contract_version":null,"record_type":"market.orderbook.diff","record_id":"collector_main-market-orderbook-diff-000000000069","collector_id":"collector_main","collector_role":"production","host_name":"MAIN-PC","session_id":"collector_main-sess-20260315T000325Z-c12e2118","stream_session_id":"collector_main-stream-bitflyer-board_ws-20260315T000328Z-d111ce49","exchange":"bitflyer","market":"spot","symbol":"BTC_JPY","instrument_id":"bitflyer.spot.BTC_JPY","channel":"board_ws","transport":"websocket","source_event_id":null,"source_sequence":null,"sequence_id":69,"exchange_ts":null,"collector_ts":"2026-03-15T00:03:28Z","ingest_ts":"2026-03-15T00:03:28Z","event_ts":"2026-03-15T00:03:28Z","quality_flags":[],"is_partial":false,"is_reconstructed":false,"confidence_score":1.0,"payload":{"provider":"bitflyer_ws_board","exchange":"bitflyer","transport":"websocket","channel":"lightning_board_BTC_JPY","received_ts":"2026-03-15T00:03:28.563428Z","subscription_id":null,"message_id":null,"source_sequence":null,"raw_message_meta":{"raw_channel":"lightning_board_BTC_JPY","subscription_channel":"lightning_board_BTC_JPY","recv_timeout_sec":10,"ssl_verify":false,"socket_url":"wss://ws.lightstream.bitflyer.com/json-rpc"},"source_payload":{"mid_price":11375650.0,"bids":[{"price":11363588.0,"size":0.09}],"asks":[{"price":11390439.0,"size":0.0},{"price":11378489.0,"size":0.0},{"price":11390562.0,"size":0.0},{"price":11377765.0,"size":0.0633}]}}}
{"schema_version":"collector.vnext.raw","schema_contract":null,"schema_contract_version":null,"payload_contract_version":null,"record_type":"market.orderbook.diff","record_id":"collector_main-market-orderbook-diff-000000000071","collector_id":"collector_main","collector_role":"production","host_name":"MAIN-PC","session_id":"collector_main-sess-20260315T000325Z-c12e2118","stream_session_id":"collector_main-stream-bitflyer-board_ws-20260315T000328Z-d111ce49","exchange":"bitflyer","market":"spot","symbol":"BTC_JPY","instrument_id":"bitflyer.spot.BTC_JPY","channel":"board_ws","transport":"websocket","source_event_id":null,"source_sequence":null,"sequence_id":71,"exchange_ts":null,"collector_ts":"2026-03-15T00:03:28Z","ingest_ts":"2026-03-15T00:03:28Z","event_ts":"2026-03-15T00:03:28Z","quality_flags":[],"is_partial":false,"is_reconstructed":false,"confidence_score":1.0,"payload":{"provider":"bitflyer_ws_board","exchange":"bitflyer","transport":"websocket","channel":"lightning_board_BTC_JPY","received_ts":"2026-03-15T00:03:28.727372Z","subscription_id":null,"message_id":null,"source_sequence":null,"raw_message_meta":{"raw_channel":"lightning_board_BTC_JPY","subscription_channel":"lightning_board_BTC_JPY","recv_timeout_sec":10,"ssl_verify":false,"socket_url":"wss://ws.lightstream.bitflyer.com/json-rpc"},"source_payload":{"mid_price":11375650.0,"bids":[],"asks":[{"price":11379347.0,"size":0.0},{"price":11379063.0,"size":0.1275},{"price":11390563.0,"size":0.0561194},{"price":11379160.0,"size":0.015096}]}}}
{"schema_version":"collector.vnext.raw","schema_contract":null,"schema_contract_version":null,"payload_contract_version":null,"record_type":"market.orderbook.diff","record_id":"collector_main-market-orderbook-diff-000000000073","collector_id":"collector_main","collector_role":"production","host_name":"MAIN-PC","session_id":"collector_main-sess-20260315T000325Z-c12e2118","stream_session_id":"collector_main-stream-bitflyer-board_ws-20260315T000328Z-d111ce49","exchange":"bitflyer","market":"spot","symbol":"BTC_JPY","instrument_id":"bitflyer.spot.BTC_JPY","channel":"board_ws","transport":"websocket","source_event_id":null,"source_sequence":null,"sequence_id":73,"exchange_ts":null,"collector_ts":"2026-03-15T00:03:28Z","ingest_ts":"2026-03-15T00:03:28Z","event_ts":"2026-03-15T00:03:28Z","quality_flags":[],"is_partial":false,"is_reconstructed":false,"confidence_score":1.0,"payload":{"provider":"bitflyer_ws_board","exchange":"bitflyer","transport":"websocket","channel":"lightning_board_BTC_JPY","received_ts":"2026-03-15T00:03:28.859469Z","subscription_id":null,"message_id":null,"source_sequence":null,"raw_message_meta":{"raw_channel":"lightning_board_BTC_JPY","subscription_channel":"lightning_board_BTC_JPY","recv_timeout_sec":10,"ssl_verify":false,"socket_url":"wss://ws.lightstream.bitflyer.com/json-rpc"},"source_payload":{"mid_price":11375650.0,"bids":[],"asks":[{"price":11378566.0,"size":0.014484},{"price":11379347.0,"size":0.2952}]}}}
{"schema_version":"collector.vnext.raw","schema_contract":null,"schema_contract_version":null,"payload_contract_version":null,"record_type":"market.orderbook.diff","record_id":"collector_main-market-orderbook-diff-000000000075","collector_id":"collector_main","collector_role":"production","host_name":"MAIN-PC","session_id":"collector_main-sess-20260315T000325Z-c12e2118","stream_session_id":"collector_main-stream-bitflyer-board_ws-20260315T000328Z-d111ce49","exchange":"bitflyer","market":"spot","symbol":"BTC_JPY","instrument_id":"bitflyer.spot.BTC_JPY","channel":"board_ws","transport":"websocket","source_event_id":null,"source_sequence":null,"sequence_id":75,"exchange_ts":null,"collector_ts":"2026-03-15T00:03:28Z","ingest_ts":"2026-03-15T00:03:28Z","event_ts":"2026-03-15T00:03:28Z","quality_flags":[],"is_partial":false,"is_reconstructed":false,"confidence_score":1.0,"payload":{"provider":"bitflyer_ws_board","exchange":"bitflyer","transport":"websocket","channel":"lightning_board_BTC_JPY","received_ts":"2026-03-15T00:03:28.969603Z","subscription_id":null,"message_id":null,"source_sequence":null,"raw_message_meta":{"raw_channel":"lightning_board_BTC_JPY","subscription_channel":"lightning_board_BTC_JPY","recv_timeout_sec":10,"ssl_verify":false,"socket_url":"wss://ws.lightstream.bitflyer.com/json-rpc"},"source_payload":{"mid_price":11375650.0,"bids":[],"asks":[{"price":11379162.0,"size":0.0},{"price":11379856.0,"size":0.0},{"price":11379063.0,"size":0.0}]}}}
{"schema_version":"collector.vnext.raw","schema_contract":null,"schema_contract_version":null,"payload_contract_version":null,"record_type":"market.orderbook.diff","record_id":"collector_main-market-orderbook-diff-000000000077","collector_id":"collector_main","collector_role":"production","host_name":"MAIN-PC","session_id":"collector_main-sess-20260315T000325Z-c12e2118","stream_session_id":"collector_main-stream-bitflyer-board_ws-20260315T000328Z-d111ce49","exchange":"bitflyer","market":"spot","symbol":"BTC_JPY","instrument_id":"bitflyer.spot.BTC_JPY","channel":"board_ws","transport":"websocket","source_event_id":null,"source_sequence":null,"sequence_id":77,"exchange_ts":null,"collector_ts":"2026-03-15T00:03:29Z","ingest_ts":"2026-03-15T00:03:29Z","event_ts":"2026-03-15T00:03:29Z","quality_flags":[],"is_partial":false,"is_reconstructed":false,"confidence_score":1.0,"payload":{"provider":"bitflyer_ws_board","exchange":"bitflyer","transport":"websocket","channel":"lightning_board_BTC_JPY","received_ts":"2026-03-15T00:03:29.075524Z","subscription_id":null,"message_id":null,"source_sequence":null,"raw_message_meta":{"raw_channel":"lightning_board_BTC_JPY","subscription_channel":"lightning_board_BTC_JPY","recv_timeout_sec":10,"ssl_verify":false,"socket_url":"wss://ws.lightstream.bitflyer.com/json-rpc"},"source_payload":{"mid_price":11375650.0,"bids":[{"price":11364726.0,"size":0.0}],"asks":[]}}}
{"schema_version":"collector.vnext.raw","schema_contract":null,"schema_contract_version":null,"payload_contract_version":null,"record_type":"market.orderbook.diff","record_id":"collector_main-market-orderbook-diff-000000000079","collector_id":"collector_main","collector_role":"production","host_name":"MAIN-PC","session_id":"collector_main-sess-20260315T000325Z-c12e2118","stream_session_id":"collector_main-stream-bitflyer-board_ws-20260315T000328Z-d111ce49","exchange":"bitflyer","market":"spot","symbol":"BTC_JPY","instrument_id":"bitflyer.spot.BTC_JPY","channel":"board_ws","transport":"websocket","source_event_id":null,"source_sequence":null,"sequence_id":79,"exchange_ts":null,"collector_ts":"2026-03-15T00:03:29Z","ingest_ts":"2026-03-15T00:03:29Z","event_ts":"2026-03-15T00:03:29Z","quality_flags":[],"is_partial":false,"is_reconstructed":false,"confidence_score":1.0,"payload":{"provider":"bitflyer_ws_board","exchange":"bitflyer","transport":"websocket","channel":"lightning_board_BTC_JPY","received_ts":"2026-03-15T00:03:29.189935Z","subscription_id":null,"message_id":null,"source_sequence":null,"raw_message_meta":{"raw_channel":"lightning_board_BTC_JPY","subscription_channel":"lightning_board_BTC_JPY","recv_timeout_sec":10,"ssl_verify":false,"socket_url":"wss://ws.lightstream.bitflyer.com/json-rpc"},"source_payload":{"mid_price":11375650.0,"bids":[{"price":11370147.0,"size":0.02}],"asks":[{"price":11379855.0,"size":0.0}]}}}
{"schema_version":"collector.vnext.raw","schema_contract":null,"schema_contract_version":null,"payload_contract_version":null,"record_type":"market.orderbook.diff","record_id":"collector_main-market-orderbook-diff-000000000081","collector_id":"collector_main","collector_role":"production","host_name":"MAIN-PC","session_id":"collector_main-sess-20260315T000325Z-c12e2118","stream_session_id":"collector_main-stream-bitflyer-board_ws-20260315T000328Z-d111ce49","exchange":"bitflyer","market":"spot","symbol":"BTC_JPY","instrument_id":"bitflyer.spot.BTC_JPY","channel":"board_ws","transport":"websocket","source_event_id":null,"source_sequence":null,"sequence_id":81,"exchange_ts":null,"collector_ts":"2026-03-15T00:03:29Z","ingest_ts":"2026-03-15T00:03:29Z","event_ts":"2026-03-15T00:03:29Z","quality_flags":[],"is_partial":false,"is_reconstructed":false,"confidence_score":1.0,"payload":{"provider":"bitflyer_ws_board","exchange":"bitflyer","transport":"websocket","channel":"lightning_board_BTC_JPY","received_ts":"2026-03-15T00:03:29.297942Z","subscription_id":null,"message_id":null,"source_sequence":null,"raw_message_meta":{"raw_channel":"lightning_board_BTC_JPY","subscription_channel":"lightning_board_BTC_JPY","recv_timeout_sec":10,"ssl_verify":false,"socket_url":"wss://ws.lightstream.bitflyer.com/json-rpc"},"source_payload":{"mid_price":11375446.0,"bids":[{"price":11370374.0,"size":0.02}],"asks":[{"price":11377357.0,"size":0.1275},{"price":11380215.0,"size":0.04328279}]}}}
{"schema_version":"collector.vnext.raw","schema_contract":null,"schema_contract_version":null,"payload_contract_version":null,"record_type":"market.orderbook.diff","record_id":"collector_main-market-orderbook-diff-000000000083","collector_id":"collector_main","collector_role":"production","host_name":"MAIN-PC","session_id":"collector_main-sess-20260315T000325Z-c12e2118","stream_session_id":"collector_main-stream-bitflyer-board_ws-20260315T000328Z-d111ce49","exchange":"bitflyer","market":"spot","symbol":"BTC_JPY","instrument_id":"bitflyer.spot.BTC_JPY","channel":"board_ws","transport":"websocket","source_event_id":null,"source_sequence":null,"sequence_id":83,"exchange_ts":null,"collector_ts":"2026-03-15T00:03:29Z","ingest_ts":"2026-03-15T00:03:29Z","event_ts":"2026-03-15T00:03:29Z","quality_flags":[],"is_partial":false,"is_reconstructed":false,"confidence_score":1.0,"payload":{"provider":"bitflyer_ws_board","exchange":"bitflyer","transport":"websocket","channel":"lightning_board_BTC_JPY","received_ts":"2026-03-15T00:03:29.406005Z","subscription_id":null,"message_id":null,"source_sequence":null,"raw_message_meta":{"raw_channel":"lightning_board_BTC_JPY","subscription_channel":"lightning_board_BTC_JPY","recv_timeout_sec":10,"ssl_verify":false,"socket_url":"wss://ws.lightstream.bitflyer.com/json-rpc"},"source_payload":{"mid_price":11375446.0,"bids":[],"asks":[{"price":11379063.0,"size":0.1275}]}}}
{"schema_version":"collector.vnext.raw","schema_contract":null,"schema_contract_version":null,"payload_contract_version":null,"record_type":"market.orderbook.diff","record_id":"collector_main-market-orderbook-diff-000000000085","collector_id":"collector_main","collector_role":"production","host_name":"MAIN-PC","session_id":"collector_main-sess-20260315T000325Z-c12e2118","stream_session_id":"collector_main-stream-bitflyer-board_ws-20260315T000328Z-d111ce49","exchange":"bitflyer","market":"spot","symbol":"BTC_JPY","instrument_id":"bitflyer.spot.BTC_JPY","channel":"board_ws","transport":"websocket","source_event_id":null,"source_sequence":null,"sequence_id":85,"exchange_ts":null,"collector_ts":"2026-03-15T00:03:29Z","ingest_ts":"2026-03-15T00:03:29Z","event_ts":"2026-03-15T00:03:29Z","quality_flags":[],"is_partial":false,"is_reconstructed":false,"confidence_score":1.0,"payload":{"provider":"bitflyer_ws_board","exchange":"bitflyer","transport":"websocket","channel":"lightning_board_BTC_JPY","received_ts":"2026-03-15T00:03:29.511488Z","subscription_id":null,"message_id":null,"source_sequence":null,"raw_message_meta":{"raw_channel":"lightning_board_BTC_JPY","subscription_channel":"lightning_board_BTC_JPY","recv_timeout_sec":10,"ssl_verify":false,"socket_url":"wss://ws.lightstream.bitflyer.com/json-rpc"},"source_payload":{"mid_price":11375446.0,"bids":[{"price":11371738.0,"size":0.02},{"price":11357794.0,"size":0.0}],"asks":[{"price":11390563.0,"size":0.0},{"price":11379063.0,"size":0.0},{"price":11391372.0,"size":0.049875},{"price":11377765.0,"size":0.0}]}}}
{"schema_version":"collector.vnext.raw","schema_contract":null,"schema_contract_version":null,"payload_contract_version":null,"record_type":"market.orderbook.diff","record_id":"collector_main-market-orderbook-diff-000000000087","collector_id":"collector_main","collector_role":"production","host_name":"MAIN-PC","session_id":"collector_main-sess-20260315T000325Z-c12e2118","stream_session_id":"collector_main-stream-bitflyer-board_ws-20260315T000328Z-d111ce49","exchange":"bitflyer","market":"spot","symbol":"BTC_JPY","instrument_id":"bitflyer.spot.BTC_JPY","channel":"board_ws","transport":"websocket","source_event_id":null,"source_sequence":null,"sequence_id":87,"exchange_ts":null,"collector_ts":"2026-03-15T00:03:29Z","ingest_ts":"2026-03-15T00:03:29Z","event_ts":"2026-03-15T00:03:29Z","quality_flags":[],"is_partial":false,"is_reconstructed":false,"confidence_score":1.0,"payload":{"provider":"bitflyer_ws_board","exchange":"bitflyer","transport":"websocket","channel":"lightning_board_BTC_JPY","received_ts":"2026-03-15T00:03:29.619120Z","subscription_id":null,"message_id":null,"source_sequence":null,"raw_message_meta":{"raw_channel":"lightning_board_BTC_JPY","subscription_channel":"lightning_board_BTC_JPY","recv_timeout_sec":10,"ssl_verify":false,"socket_url":"wss://ws.lightstream.bitflyer.com/json-rpc"},"source_payload":{"mid_price":11375446.0,"bids":[{"price":11363588.0,"size":0.0}],"asks":[]}}}
{"schema_version":"collector.vnext.raw","schema_contract":null,"schema_contract_version":null,"payload_contract_version":null,"record_type":"market.orderbook.diff","record_id":"collector_main-market-orderbook-diff-000000000089","collector_id":"collector_main","collector_role":"production","host_name":"MAIN-PC","session_id":"collector_main-sess-20260315T000325Z-c12e2118","stream_session_id":"collector_main-stream-bitflyer-board_ws-20260315T000328Z-d111ce49","exchange":"bitflyer","market":"spot","symbol":"BTC_JPY","instrument_id":"bitflyer.spot.BTC_JPY","channel":"board_ws","transport":"websocket","source_event_id":null,"source_sequence":null,"sequence_id":89,"exchange_ts":null,"collector_ts":"2026-03-15T00:03:29Z","ingest_ts":"2026-03-15T00:03:29Z","event_ts":"2026-03-15T00:03:29Z","quality_flags":[],"is_partial":false,"is_reconstructed":false,"confidence_score":1.0,"payload":{"provider":"bitflyer_ws_board","exchange":"bitflyer","transport":"websocket","channel":"lightning_board_BTC_JPY","received_ts":"2026-03-15T00:03:29.720541Z","subscription_id":null,"message_id":null,"source_sequence":null,"raw_message_meta":{"raw_channel":"lightning_board_BTC_JPY","subscription_channel":"lightning_board_BTC_JPY","recv_timeout_sec":10,"ssl_verify":false,"socket_url":"wss://ws.lightstream.bitflyer.com/json-rpc"},"source_payload":{"mid_price":11375446.0,"bids":[{"price":11371119.0,"size":0.01464},{"price":11370147.0,"size":0.0},{"price":11371365.0,"size":0.02}],"asks":[{"price":11377357.0,"size":0.2073}]}}}
{"schema_version":"collector.vnext.raw","schema_contract":null,"schema_contract_version":null,"payload_contract_version":null,"record_type":"market.orderbook.diff","record_id":"collector_main-market-orderbook-diff-000000000091","collector_id":"collector_main","collector_role":"production","host_name":"MAIN-PC","session_id":"collector_main-sess-20260315T000325Z-c12e2118","stream_session_id":"collector_main-stream-bitflyer-board_ws-20260315T000328Z-d111ce49","exchange":"bitflyer","market":"spot","symbol":"BTC_JPY","instrument_id":"bitflyer.spot.BTC_JPY","channel":"board_ws","transport":"websocket","source_event_id":null,"source_sequence":null,"sequence_id":91,"exchange_ts":null,"collector_ts":"2026-03-15T00:03:29Z","ingest_ts":"2026-03-15T00:03:29Z","event_ts":"2026-03-15T00:03:29Z","quality_flags":[],"is_partial":false,"is_reconstructed":false,"confidence_score":1.0,"payload":{"provider":"bitflyer_ws_board","exchange":"bitflyer","transport":"websocket","channel":"lightning_board_BTC_JPY","received_ts":"2026-03-15T00:03:29.822109Z","subscription_id":null,"message_id":null,"source_sequence":null,"raw_message_meta":{"raw_channel":"lightning_board_BTC_JPY","subscription_channel":"lightning_board_BTC_JPY","recv_timeout_sec":10,"ssl_verify":false,"socket_url":"wss://ws.lightstream.bitflyer.com/json-rpc"},"source_payload":{"mid_price":11375344.0,"bids":[],"asks":[{"price":11377153.0,"size":0.1275}]}}}
{"schema_version":"collector.vnext.raw","schema_contract":null,"schema_contract_version":null,"payload_contract_version":null,"record_type":"market.orderbook.diff","record_id":"collector_main-market-orderbook-diff-000000000093","collector_id":"collector_main","collector_role":"production","host_name":"MAIN-PC","session_id":"collector_main-sess-20260315T000325Z-c12e2118","stream_session_id":"collector_main-stream-bitflyer-board_ws-20260315T000328Z-d111ce49","exchange":"bitflyer","market":"spot","symbol":"BTC_JPY","instrument_id":"bitflyer.spot.BTC_JPY","channel":"board_ws","transport":"websocket","source_event_id":null,"source_sequence":null,"sequence_id":93,"exchange_ts":null,"collector_ts":"2026-03-15T00:03:29Z","ingest_ts":"2026-03-15T00:03:29Z","event_ts":"2026-03-15T00:03:29Z","quality_flags":[],"is_partial":false,"is_reconstructed":false,"confidence_score":1.0,"payload":{"provider":"bitflyer_ws_board","exchange":"bitflyer","transport":"websocket","channel":"lightning_board_BTC_JPY","received_ts":"2026-03-15T00:03:29.929644Z","subscription_id":null,"message_id":null,"source_sequence":null,"raw_message_meta":{"raw_channel":"lightning_board_BTC_JPY","subscription_channel":"lightning_board_BTC_JPY","recv_timeout_sec":10,"ssl_verify":false,"socket_url":"wss://ws.lightstream.bitflyer.com/json-rpc"},"source_payload":{"mid_price":11375344.0,"bids":[{"price":11364726.0,"size":0.08}],"asks":[]}}}
{"schema_version":"collector.vnext.raw","schema_contract":null,"schema_contract_version":null,"payload_contract_version":null,"record_type":"market.orderbook.diff","record_id":"collector_main-market-orderbook-diff-000000000095","collector_id":"collector_main","collector_role":"production","host_name":"MAIN-PC","session_id":"collector_main-sess-20260315T000325Z-c12e2118","stream_session_id":"collector_main-stream-bitflyer-board_ws-20260315T000328Z-d111ce49","exchange":"bitflyer","market":"spot","symbol":"BTC_JPY","instrument_id":"bitflyer.spot.BTC_JPY","channel":"board_ws","transport":"websocket","source_event_id":null,"source_sequence":null,"sequence_id":95,"exchange_ts":null,"collector_ts":"2026-03-15T00:03:30Z","ingest_ts":"2026-03-15T00:03:30Z","event_ts":"2026-03-15T00:03:30Z","quality_flags":[],"is_partial":false,"is_reconstructed":false,"confidence_score":1.0,"payload":{"provider":"bitflyer_ws_board","exchange":"bitflyer","transport":"websocket","channel":"lightning_board_BTC_JPY","received_ts":"2026-03-15T00:03:30.060078Z","subscription_id":null,"message_id":null,"source_sequence":null,"raw_message_meta":{"raw_channel":"lightning_board_BTC_JPY","subscription_channel":"lightning_board_BTC_JPY","recv_timeout_sec":10,"ssl_verify":false,"socket_url":"wss://ws.lightstream.bitflyer.com/json-rpc"},"source_payload":{"mid_price":11375344.0,"bids":[{"price":11363588.0,"size":0.1}],"asks":[{"price":11391372.0,"size":0.0},{"price":11390337.0,"size":0.1275},{"price":11377357.0,"size":0.1275},{"price":11377153.0,"size":0.1907}]}}}
{"schema_version":"collector.vnext.raw","schema_contract":null,"schema_contract_version":null,"payload_contract_version":null,"record_type":"market.orderbook.diff","record_id":"collector_main-market-orderbook-diff-000000000097","collector_id":"collector_main","collector_role":"production","host_name":"MAIN-PC","session_id":"collector_main-sess-20260315T000325Z-c12e2118","stream_session_id":"collector_main-stream-bitflyer-board_ws-20260315T000328Z-d111ce49","exchange":"bitflyer","market":"spot","symbol":"BTC_JPY","instrument_id":"bitflyer.spot.BTC_JPY","channel":"board_ws","transport":"websocket","source_event_id":null,"source_sequence":null,"sequence_id":97,"exchange_ts":null,"collector_ts":"2026-03-15T00:03:30Z","ingest_ts":"2026-03-15T00:03:30Z","event_ts":"2026-03-15T00:03:30Z","quality_flags":[],"is_partial":false,"is_reconstructed":false,"confidence_score":1.0,"payload":{"provider":"bitflyer_ws_board","exchange":"bitflyer","transport":"websocket","channel":"lightning_board_BTC_JPY","received_ts":"2026-03-15T00:03:30.187998Z","subscription_id":null,"message_id":null,"source_sequence":null,"raw_message_meta":{"raw_channel":"lightning_board_BTC_JPY","subscription_channel":"lightning_board_BTC_JPY","recv_timeout_sec":10,"ssl_verify":false,"socket_url":"wss://ws.lightstream.bitflyer.com/json-rpc"},"source_payload":{"mid_price":11375344.0,"bids":[{"price":11370374.0,"size":0.0},{"price":11370373.0,"size":0.0},{"price":11371120.0,"size":0.02}],"asks":[{"price":11388995.0,"size":0.05}]}}}
{"schema_version":"collector.vnext.raw","schema_contract":null,"schema_contract_version":null,"payload_contract_version":null,"record_type":"market.orderbook.snapshot","record_id":"collector_main-market-orderbook-snapshot-000000000099","collector_id":"collector_main","collector_role":"production","host_name":"MAIN-PC","session_id":"collector_main-sess-20260315T000325Z-c12e2118","stream_session_id":"collector_main-stream-bitflyer-board_ws-20260315T000328Z-d111ce49","exchange":"bitflyer","market":"spot","symbol":"BTC_JPY","instrument_id":"bitflyer.spot.BTC_JPY","channel":"board_ws","transport":"websocket","source_event_id":null,"source_sequence":null,"sequence_id":99,"exchange_ts":null,"collector_ts":"2026-03-15T00:03:30Z","ingest_ts":"2026-03-15T00:03:30Z","event_ts":"2026-03-15T00:03:30Z","quality_flags":[],"is_partial":false,"is_reconstructed":false,"confidence_score":1.0,"payload":{"provider":"bitflyer_ws_board_snapshot","exchange":"bitflyer","transport":"websocket","channel":"lightning_board_snapshot_BTC_JPY","received_ts":"2026-03-15T00:03:30.336235Z","subscription_id":null,"message_id":null,"source_sequence":null,"raw_message_meta":{"raw_channel":"lightning_board_snapshot_BTC_JPY","subscription_channel":"lightning_board_snapshot_BTC_JPY","recv_timeout_sec":10,"ssl_verify":false,"socket_url":"wss://ws.lightstream.bitflyer.com/json-rpc"},"source_payload":{"mid_price":11375344.0,"bids":[{"price":11373535.0,"size":0.005},{"price":11373534.0,"size":0.00999792},{"price":11371738.0,"size":0.02},{"price":11371737.0,"size":0.0526},{"price":11371587.0,"size":0.02},{"price":11371380.0,"size":0.02},{"price":11371365.0,"size":0.02},{"price":11371364.0,"size":0.0328},{"price":11371120.0,"size":0.02},{"price":11371119.0,"size":0.01464},{"price":11370999.0,"size":0.02},{"price":11370998.0,"size":0.26595698},{"price":11370371.0,"size":0.01458},{"price":11370049.0,"size":0.5},{"price":11370007.0,"size":0.01518},{"price":11370000.0,"size":0.005},{"price":11369239.0,"size":0.015},{"price":11368686.0,"size":0.055296},{"price":11368376.0,"size":0.01},{"price":11368353.0,"size":0.01},{"price":11365275.0,"size":3.11651781},{"price":11365274.0,"size":0.0527},{"price":11364726.0,"size":0.08},{"price":11363829.0,"size":0.01},{"price":11363588.0,"size":0.1},{"price":11362345.0,"size":0.1},{"price":11362278.0,"size":0.34924621},{"price":11362277.0,"size":0.9772867},{"price":11361538.0,"size":1.50015},{"price":11358439.0,"size":0.002},{"price":11358376.0,"size":0.01},{"price":11357858.0,"size":0.24},{"price":11355023.0,"size":0.002},{"price":11354613.0,"size":0.05},{"price":11354044.0,"size":0.05},{"price":11353488.0,"size":0.27174084},{"price":11351280.0,"size":0.2739},{"price":11350744.0,"size":0.002},{"price":11350000.0,"size":0.51},{"price":11348518.0,"size":0.2616},{"price":11348191.0,"size":0.002},{"price":11348189.0,"size":0.003},{"price":11347667.0,"size":0.001},{"price":11347661.0,"size":0.6},{"price":11346193.0,"size":0.002},{"price":11345756.0,"size":0.267},{"price":11345154.0,"size":1.484},{"price":11344775.0,"size":0.002},{"price":11342994.0,"size":0.2708},{"price":11341672.0,"size":0.05739971},{"price":11341671.0,"size":0.23},{"price":11341642.0,"size":0.002},{"price":11341359.0,"size":0.002},{"price":11340000.0,"size":0.005},{"price":11338046.0,"size":1.966},{"price":11337943.0,"size":0.002},{"price":11337091.0,"size":0.002},{"price":11336383.0,"size":0.001},{"price":11336319.0,"size":0.00195},{"price":11334527.0,"size":0.002},{"price":11332540.0,"size":0.002},{"price":11331111.0,"size":0.002},{"price":11331000.0,"size":0.5},{"price":11330490.0,"size":2.036},{"price":11330000.0,"size":0.02442},{"price":11327989.0,"size":0.002},{"price":11327695.0,"size":0.002},{"price":11325101.0,"size":0.001},{"price":11323438.0,"size":0.002},{"price":11320000.0,"size":0.05},{"price":11318887.0,"size":0.002},{"price":11315000.0,"size":0.05},{"price":11314336.0,"size":0.002},{"price":11314325.0,"size":1.951},{"price":11313996.0,"size":0.00195},{"price":11313819.0,"size":0.001},{"price":11310000.0,"size":0.01},{"price":11309999.0,"size":0.177},{"price":11309785.0,"size":0.002},{"price":11307999.0,"size":0.01},{"price":11303918.0,"size":0.01},{"price":11303000.0,"size":0.5},{"price":11302535.0,"size":0.001},{"price":11302466.0,"size":0.001},{"price":11301268.0,"size":0.01},{"price":11300000.0,"size":3.01685256},{"price":11298000.0,"size":0.01},{"price":11296865.0,"size":0.0015},{"price":11294756.0,"size":1.0},{"price":11291282.0,"size":0.001},{"price":11291268.0,"size":0.01},{"price":11291000.0,"size":0.5},{"price":11290000.0,"size":0.003},{"price":11281268.0,"size":0.01},{"price":11280000.0,"size":0.0163},{"price":11279960.0,"size":0.001},{"price":11279282.0,"size":0.0015},{"price":11278000.0,"size":0.0025},{"price":11275000.0,"size":0.001},{"price":11274588.0,"size":0.0047},{"price":11271268.0,"size":0.01},{"price":11271000.0,"size":0.003},{"price":11270000.0,"size":0.106},{"price":11269424.0,"size":0.8},{"price":11268871.0,"size":0.28},{"price":11268638.0,"size":0.001},{"price":11268411.0,"size":0.01},{"price":11266666.0,"size":0.04},{"price":11265000.0,"size":0.02},{"price":11263000.0,"size":0.006},{"price":11262564.0,"size":0.0015},{"price":11261268.0,"size":0.01},{"price":11260000.0,"size":0.3565},{"price":11257315.0,"size":0.001},{"price":11257000.0,"size":0.001},{"price":11255200.0,"size":0.001},{"price":11255115.0,"size":0.00377},{"price":11253814.0,"size":2.2},{"price":11253690.0,"size":0.01},{"price":11253000.0,"size":0.03189},{"price":11251405.0,"size":0.139},{"price":11251268.0,"size":0.01},{"price":11251111.0,"size":0.0015},{"price":11251000.0,"size":0.0131},{"price":11250250.0,"size":0.00105},{"price":11250200.0,"size":0.001},{"price":11250005.0,"size":0.001},{"price":11250001.0,"size":0.00104},{"price":11250000.0,"size":1.62712889},{"price":11245993.0,"size":0.001},{"price":11245141.0,"size":0.0031},{"price":11245000.0,"size":0.05},{"price":11244444.0,"size":0.04},{"price":11244243.0,"size":0.01},{"price":11240200.0,"size":0.001},{"price":11240000.0,"size":0.007304},{"price":11236190.0,"size":0.01},{"price":11235200.0,"size":0.001},{"price":11234670.0,"size":0.001},{"price":11232000.0,"size":0.089},{"price":11231243.0,"size":0.01},{"price":11231000.0,"size":0.105},{"price":11230200.0,"size":0.001},{"price":11230000.0,"size":0.0308},{"price":11226952.0,"size":0.972},{"price":11224500.0,"size":0.06},{"price":11223968.0,"size":0.001},{"price":11223348.0,"size":0.001},{"price":11223344.0,"size":0.01},{"price":11223000.0,"size":0.1},{"price":11222222.0,"size":0.093525},{"price":11221120.0,"size":0.001},{"price":11220200.0,"size":0.001},{"price":11220001.0,"size":0.004457},{"price":11220000.0,"size":0.321},{"price":11219000.0,"size":0.1},{"price":11217326.0,"size":0.02},{"price":11215200.0,"size":0.001},{"price":11213690.0,"size":0.01},{"price":11212025.0,"size":0.001},{"price":11211800.0,"size":0.001},{"price":11211111.0,"size":0.06},{"price":11210200.0,"size":0.001},{"price":11210000.0,"size":0.10622},{"price":11208032.0,"size":0.01},{"price":11206000.0,"size":0.09015},{"price":11205200.0,"size":0.001},{"price":11204578.0,"size":0.002},{"price":11201000.0,"size":0.01},{"price":11200800.0,"size":0.05},{"price":11200703.0,"size":0.001},{"price":11200425.0,"size":0.1},{"price":11200200.0,"size":0.001},{"price":11200198.0,"size":0.003},{"price":11200150.0,"size":0.002},{"price":11200002.0,"size":0.001},{"price":11200001.0,"size":0.01104},{"price":11200000.0,"size":1.15226728},{"price":11198508.0,"size":0.05},{"price":11198243.0,"size":0.01},{"price":11197134.0,"size":0.993},{"price":11197000.0,"size":0.0085},{"price":11194090.0,"size":0.03},{"price":11190770.0,"size":0.0309},{"price":11190000.0,"size":0.0010016},{"price":11189555.0,"size":0.5},{"price":11189381.0,"size":0.001},{"price":11188629.0,"size":0.01},{"price":11188382.0,"size":0.001},{"price":11185000.0,"size":0.0085},{"price":11180000.0,"size":0.225},{"price":11178058.0,"size":0.001},{"price":11170000.0,"size":0.001},{"price":11169662.0,"size":0.01},{"price":11169593.0,"size":0.001},{"price":11169243.0,"size":0.01},{"price":11166736.0,"size":0.001},{"price":11164029.0,"size":0.001},{"price":11160854.0,"size":0.1},{"price":11160000.0,"size":0.02376},{"price":11155413.0,"size":0.001},{"price":11155377.0,"size":0.00636009},{"price":11153999.0,"size":0.00101},{"price":11151000.0,"size":0.001},{"price":11150250.0,"size":0.00175},{"price":11150005.0,"size":0.001},{"price":11150001.0,"size":0.00104},{"price":11150000.0,"size":0.6533956},{"price":11148000.0,"size":0.08963},{"price":11147546.0,"size":0.02},{"price":11144091.0,"size":0.001},{"price":11144000.0,"size":0.0897},{"price":11143986.0,"size":0.02},{"price":11140139.0,"size":1.0},{"price":11140000.0,"size":0.2},{"price":11136243.0,"size":0.01},{"price":11135869.0,"size":0.1},{"price":11132768.0,"size":0.001},{"price":11130000.0,"size":0.116},{"price":11129979.0,"size":0.0053908},{"price":11124900.0,"size":0.00133},{"price":11121090.0,"size":0.1},{"price":11120000.0,"size":0.0033},{"price":11118078.0,"size":0.01},{"price":11111800.0,"size":0.001},{"price":11111111.0,"size":0.2919257},{"price":11111000.0,"size":0.003},{"price":11110594.0,"size":0.001},{"price":11110000.0,"size":0.021007},{"price":11109662.0,"size":0.01},{"price":11108008.0,"size":0.01},{"price":11102000.0,"size":0.5},{"price":11101297.0,"size":0.001},{"price":11100005.0,"size":0.001},{"price":11100001.0,"size":0.01104},{"price":11100000.0,"size":1.6532049},{"price":11099141.0,"size":0.01},{"price":11098833.0,"size":0.002},{"price":11096243.0,"size":0.01},{"price":11094090.0,"size":0.01},{"price":11088888.0,"size":0.001},{"price":11085245.0,"size":0.001},{"price":11080200.0,"size":0.001},{"price":11080000.0,"size":0.0223},{"price":11075100.0,"size":0.003},{"price":11070200.0,"size":0.001},{"price":11070000.0,"size":0.0902},{"price":11065200.0,"size":0.001},{"price":11064370.0,"size":0.00497091},{"price":11060200.0,"size":0.001},{"price":11060000.0,"size":0.145},{"price":11059689.0,"size":0.009},{"price":11056428.0,"size":0.002},{"price":11055500.0,"size":0.02},{"price":11055200.0,"size":0.001},{"price":11055100.0,"size":0.003},{"price":11050200.0,"size":0.001},{"price":11050005.0,"size":0.001},{"price":11050002.0,"size":0.001},{"price":11050001.0,"size":0.00104},{"price":11050000.0,"size":0.39576147},{"price":11048064.0,"size":2.0},{"price":11046420.0,"size":0.2},{"price":11044243.0,"size":0.01},{"price":11041380.0,"size":0.01},{"price":11040200.0,"size":0.001},{"price":11040000.0,"size":0.00777181},{"price":11035865.0,"size":0.1},{"price":11035200.0,"size":0.001},{"price":11035000.0,"size":0.0013},{"price":11030200.0,"size":0.001},{"price":11030000.0,"size":0.025},{"price":11025500.0,"size":0.009531},{"price":11025200.0,"size":0.001},{"price":11025000.0,"size":0.71497},{"price":11020772.0,"size":0.014},{"price":11020200.0,"size":0.002},{"price":11020000.0,"size":0.005},{"price":11015200.0,"size":0.001},{"price":11012000.0,"size":0.1},{"price":11011800.0,"size":0.001},{"price":11010200.0,"size":0.001},{"price":11010000.0,"size":0.347},{"price":11007277.0,"size":0.01},{"price":11005200.0,"size":0.001},{"price":11004890.0,"size":0.001535},{"price":11003000.0,"size":0.0155},{"price":11001000.0,"size":0.013},{"price":11000500.0,"size":0.05117658},{"price":11000200.0,"size":0.001},{"price":11000002.0,"size":0.004},{"price":11000001.0,"size":0.02604},{"price":11000000.0,"size":4.53923365},{"price":10999999.0,"size":0.003},{"price":10999000.0,"size":0.001},{"price":10996855.0,"size":0.0011},{"price":10995200.0,"size":0.001},{"price":10994499.0,"size":0.00169176},{"price":10990200.0,"size":0.001},{"price":10990000.0,"size":0.10219}],"asks":[{"price":11377153.0,"size":0.1907},{"price":11377357.0,"size":0.1275},{"price":11378566.0,"size":0.014484},{"price":11379160.0,"size":0.015096},{"price":11379161.0,"size":0.015312},{"price":11379347.0,"size":0.2952},{"price":11379565.0,"size":0.014808},{"price":11380215.0,"size":0.04328279},{"price":11380216.0,"size":0.00994996},{"price":11382108.0,"size":0.02},{"price":11382109.0,"size":0.301},{"price":11382750.0,"size":0.234},{"price":11384871.0,"size":0.2657},{"price":11385094.0,"size":0.01},{"price":11385327.0,"size":0.0552096},{"price":11387174.0,"size":0.1},{"price":11387633.0,"size":0.2976},{"price":11388995.0,"size":0.05},{"price":11389573.0,"size":0.0044},{"price":11390311.0,"size":0.57243935},{"price":11390337.0,"size":0.1275},{"price":11390970.0,"size":0.0526},{"price":11391432.0,"size":0.4249},{"price":11392010.0,"size":0.00142446},{"price":11393747.0,"size":1.189881},{"price":11394441.0,"size":1.189881},{"price":11397000.0,"size":0.02},{"price":11398444.0,"size":0.001995},{"price":11398845.0,"size":0.001},{"price":11399673.0,"size":0.0015},{"price":11399700.0,"size":0.001},{"price":11399999.0,"size":0.05},{"price":11400000.0,"size":0.64832841},{"price":11403472.0,"size":0.002},{"price":11405000.0,"size":0.1575},{"price":11405422.0,"size":1.489},{"price":11408699.0,"size":1.15098095},{"price":11408700.0,"size":0.001},{"price":11409415.0,"size":0.005},{"price":11409925.0,"size":0.22},{"price":11410000.0,"size":0.3787},{"price":11410168.0,"size":0.001},{"price":11410853.0,"size":0.002},{"price":11412000.0,"size":0.0878},{"price":11415000.0,"size":0.1},{"price":11415141.0,"size":0.0041},{"price":11417459.0,"size":1.928},{"price":11417481.0,"size":0.0015},{"price":11418700.0,"size":0.001},{"price":11419000.0,"size":0.01},{"price":11420000.0,"size":0.661},{"price":11421268.0,"size":0.05},{"price":11421490.0,"size":0.001},{"price":11424296.0,"size":0.002},{"price":11425000.0,"size":0.029},{"price":11426426.0,"size":0.002},{"price":11428121.0,"size":0.002},{"price":11428700.0,"size":0.001},{"price":11429302.0,"size":0.01},{"price":11430000.0,"size":0.4098},{"price":11432718.0,"size":0.002},{"price":11432813.0,"size":0.001},{"price":11433211.0,"size":0.03},{"price":11433333.0,"size":0.001},{"price":11437315.0,"size":0.002},{"price":11438525.0,"size":0.0011},{"price":11438700.0,"size":0.001},{"price":11439557.0,"size":0.001},{"price":11440000.0,"size":0.2538},{"price":11441911.0,"size":0.002},{"price":11442627.0,"size":2.018},{"price":11443629.0,"size":0.002},{"price":11444135.0,"size":0.001},{"price":11445433.0,"size":0.0015},{"price":11446508.0,"size":0.001},{"price":11447000.0,"size":0.01},{"price":11447071.0,"size":0.002},{"price":11448000.0,"size":0.0875},{"price":11448700.0,"size":0.001},{"price":11450000.0,"size":0.268},{"price":11451105.0,"size":0.002},{"price":11453321.0,"size":0.03},{"price":11455000.0,"size":0.001},{"price":11455457.0,"size":0.001},{"price":11455702.0,"size":0.002},{"price":11458700.0,"size":0.001},{"price":11458988.0,"size":0.01},{"price":11460000.0,"size":0.06702},{"price":11460299.0,"size":0.002},{"price":11463288.0,"size":0.01},{"price":11464896.0,"size":0.002},{"price":11465382.0,"size":0.00195},{"price":11465421.0,"size":1.943},{"price":11466780.0,"size":0.001},{"price":11468700.0,"size":0.001},{"price":11470000.0,"size":0.06},{"price":11471000.0,"size":0.01},{"price":11475000.0,"size":0.0028},{"price":11476929.0,"size":1.0},{"price":11478102.0,"size":0.001},{"price":11478431.0,"size":0.002},{"price":11478700.0,"size":0.001},{"price":11480000.0,"size":0.40191},{"price":11485000.0,"size":0.01},{"price":11485488.0,"size":2.0},{"price":11486555.0,"size":0.03},{"price":11487685.0,"size":0.01},{"price":11488000.0,"size":0.102},{"price":11488700.0,"size":0.001},{"price":11489425.0,"size":0.001},{"price":11490000.0,"size":0.05},{"price":11490841.0,"size":0.002},{"price":11495450.0,"size":0.002},{"price":11495850.0,"size":0.001},{"price":11498700.0,"size":0.001},{"price":11498917.0,"size":0.002},{"price":11499000.0,"size":0.01},{"price":11500000.0,"size":0.77159519},{"price":11500078.0,"size":0.93},{"price":11500747.0,"size":0.001},{"price":11502377.0,"size":0.002},{"price":11502800.0,"size":0.00132},{"price":11503108.0,"size":0.0198},{"price":11505000.0,"size":0.0028},{"price":11505001.0,"size":0.002},{"price":11505836.0,"size":0.003},{"price":11508431.0,"size":0.047},{"price":11508700.0,"size":0.001},{"price":11508888.0,"size":0.02},{"price":11510000.0,"size":0.1476},{"price":11512070.0,"size":0.001},{"price":11513633.0,"size":0.08},{"price":11514332.0,"size":0.02},{"price":11518700.0,"size":0.001},{"price":11518992.0,"size":0.002},{"price":11519855.0,"size":0.01},{"price":11520000.0,"size":0.001},{"price":11522388.0,"size":0.972},{"price":11523211.0,"size":0.01},{"price":11524999.0,"size":0.001},{"price":11528700.0,"size":0.001},{"price":11529852.0,"size":0.01},{"price":11530000.0,"size":0.261},{"price":11533985.0,"size":0.002},{"price":11534084.0,"size":0.001},{"price":11535321.0,"size":0.01},{"price":11538666.0,"size":0.002},{"price":11538700.0,"size":0.001},{"price":11540000.0,"size":0.0048},{"price":11540357.0,"size":0.002},{"price":11541011.0,"size":0.005},{"price":11541109.0,"size":0.01},{"price":11544663.0,"size":0.002},{"price":11545262.0,"size":0.002},{"price":11546541.0,"size":0.01},{"price":11548144.0,"size":0.002},{"price":11548700.0,"size":0.001},{"price":11550000.0,"size":0.014},{"price":11551109.0,"size":0.01},{"price":11551625.0,"size":0.002},{"price":11552111.0,"size":0.01},{"price":11553687.0,"size":0.1},{"price":11555106.0,"size":0.002},{"price":11555115.0,"size":0.001},{"price":11556000.0,"size":0.1},{"price":11558587.0,"size":0.002},{"price":11558700.0,"size":0.001},{"price":11559855.0,"size":0.01},{"price":11560831.0,"size":0.0198},{"price":11561109.0,"size":0.01},{"price":11562000.0,"size":0.087},{"price":11562068.0,"size":0.002},{"price":11563750.0,"size":0.08739676},{"price":11565548.0,"size":0.002},{"price":11566139.0,"size":0.0228},{"price":11566551.0,"size":0.01},{"price":11568700.0,"size":0.001},{"price":11569029.0,"size":0.002},{"price":11570196.0,"size":0.002},{"price":11571109.0,"size":0.01},{"price":11572510.0,"size":0.002},{"price":11573211.0,"size":0.01},{"price":11574840.0,"size":0.002},{"price":11575991.0,"size":0.001},{"price":11578700.0,"size":0.001},{"price":11579484.0,"size":0.002},{"price":11579851.0,"size":0.01},{"price":11580000.0,"size":0.7835},{"price":11581109.0,"size":0.01},{"price":11584128.0,"size":0.002},{"price":11585000.0,"size":0.002},{"price":11586532.0,"size":0.01},{"price":11587498.0,"size":0.0198},{"price":11588700.0,"size":0.001},{"price":11588800.0,"size":0.02},{"price":11590000.0,"size":0.1},{"price":11590749.0,"size":0.002},{"price":11591109.0,"size":0.01},{"price":11593211.0,"size":0.01},{"price":11596753.0,"size":0.002},{"price":11598111.0,"size":0.1474},{"price":11598555.0,"size":0.01},{"price":11598700.0,"size":0.001},{"price":11599999.0,"size":0.001},{"price":11600000.0,"size":3.655},{"price":11601109.0,"size":0.02},{"price":11603764.0,"size":0.9},{"price":11606655.0,"size":0.01},{"price":11610000.0,"size":0.302},{"price":11611109.0,"size":0.01},{"price":11613321.0,"size":0.01},{"price":11620000.0,"size":1.35441682},{"price":11621011.0,"size":0.01},{"price":11621109.0,"size":0.01},{"price":11623096.0,"size":0.008},{"price":11625703.0,"size":0.012},{"price":11629000.0,"size":0.1},{"price":11630000.0,"size":0.201},{"price":11631059.0,"size":0.01},{"price":11631479.0,"size":0.01},{"price":11631773.0,"size":0.00386871},{"price":11635950.0,"size":0.001},{"price":11638259.0,"size":0.001},{"price":11639700.0,"size":0.001},{"price":11640000.0,"size":1.0},{"price":11640820.0,"size":0.01},{"price":11649900.0,"size":0.02906},{"price":11649999.0,"size":0.001},{"price":11650000.0,"size":0.593},{"price":11651059.0,"size":0.01},{"price":11653658.0,"size":0.008},{"price":11654321.0,"size":0.001},{"price":11659700.0,"size":0.001},{"price":11661479.0,"size":0.01},{"price":11666000.0,"size":0.001},{"price":11666666.0,"size":0.013},{"price":11669700.0,"size":0.001},{"price":11671059.0,"size":0.01},{"price":11672562.0,"size":0.0198},{"price":11680000.0,"size":0.014},{"price":11685000.0,"size":0.003},{"price":11688000.0,"size":0.001},{"price":11689732.0,"size":0.01},{"price":11690330.0,"size":0.0198},{"price":11691059.0,"size":0.01},{"price":11692558.0,"size":0.01},{"price":11695019.0,"size":0.0064},{"price":11698800.0,"size":0.00131},{"price":11699000.0,"size":0.001},{"price":11699631.0,"size":0.001},{"price":11699998.0,"size":0.01},{"price":11699999.0,"size":0.001},{"price":11700000.0,"size":1.2573},{"price":11701059.0,"size":0.01},{"price":11720000.0,"size":0.1},{"price":11721059.0,"size":0.01},{"price":11725000.0,"size":0.005},{"price":11726791.0,"size":0.01},{"price":11727418.0,"size":1.8},{"price":11728195.0,"size":0.05},{"price":11730000.0,"size":1.9712},{"price":11740000.0,"size":0.101},{"price":11741059.0,"size":0.01},{"price":11748937.0,"size":0.001},{"price":11749999.0,"size":0.001},{"price":11750000.0,"size":0.89537866},{"price":11750050.0,"size":0.2},{"price":11751151.0,"size":0.01},{"price":11751406.0,"size":0.012},{"price":11755000.0,"size":0.001},{"price":11757860.0,"size":1.82},{"price":11759999.0,"size":0.001},{"price":11760000.0,"size":0.001},{"price":11761059.0,"size":0.02},{"price":11765432.0,"size":0.001},{"price":11768000.0,"size":0.01},{"price":11770000.0,"size":0.25464896},{"price":11771059.0,"size":0.01755555},{"price":11772000.0,"size":0.002},{"price":11775000.0,"size":0.11593},{"price":11775222.0,"size":0.001657},{"price":11775577.0,"size":0.00013523},{"price":11775800.0,"size":0.001},{"price":11775900.0,"size":0.2},{"price":11775989.0,"size":0.005},{"price":11777000.0,"size":0.5956},{"price":11777777.0,"size":0.0067},{"price":11778541.0,"size":0.001},{"price":11779807.0,"size":0.001},{"price":11780000.0,"size":0.74298},{"price":11780800.0,"size":0.1},{"price":11781059.0,"size":0.01},{"price":11781238.0,"size":0.008},{"price":11785000.0,"size":0.055},{"price":11785040.0,"size":0.01},{"price":11786000.0,"size":0.585},{"price":11788000.0,"size":0.001},{"price":11788888.0,"size":0.005},{"price":11789000.0,"size":0.2},{"price":11789732.0,"size":0.01}]}}}
{"schema_version":"collector.vnext.raw","schema_contract":null,"schema_contract_version":null,"payload_contract_version":null,"record_type":"market.orderbook.diff","record_id":"collector_main-market-orderbook-diff-000000000061","collector_id":"collector_main","collector_role":"production","host_name":"MAIN-PC","session_id":"collector_main-sess-20260315T000345Z-92e50eca","stream_session_id":"collector_main-stream-bitflyer-board_ws-20260315T000346Z-4b14e58c","exchange":"bitflyer","market":"spot","symbol":"BTC_JPY","instrument_id":"bitflyer.spot.BTC_JPY","channel":"board_ws","transport":"websocket","source_event_id":null,"source_sequence":null,"sequence_id":61,"exchange_ts":null,"collector_ts":"2026-03-15T00:03:46Z","ingest_ts":"2026-03-15T00:03:46Z","event_ts":"2026-03-15T00:03:46Z","quality_flags":[],"is_partial":false,"is_reconstructed":false,"confidence_score":1.0,"payload":{"provider":"bitflyer_ws_board","exchange":"bitflyer","transport":"websocket","channel":"lightning_board_BTC_JPY","received_ts":"2026-03-15T00:03:46.720172Z","subscription_id":null,"message_id":null,"source_sequence":null,"raw_message_meta":{"raw_channel":"lightning_board_BTC_JPY","subscription_channel":"lightning_board_BTC_JPY","recv_timeout_sec":10,"ssl_verify":false,"socket_url":"wss://ws.lightstream.bitflyer.com/json-rpc"},"source_payload":{"mid_price":11374765.0,"bids":[{"price":11371352.0,"size":0.0},{"price":11371353.0,"size":0.02}],"asks":[{"price":11376569.0,"size":0.092},{"price":11376764.0,"size":0.0}]}}}
{"schema_version":"collector.vnext.raw","schema_contract":null,"schema_contract_version":null,"payload_contract_version":null,"record_type":"market.orderbook.diff","record_id":"collector_main-market-orderbook-diff-000000000065","collector_id":"collector_main","collector_role":"production","host_name":"MAIN-PC","session_id":"collector_main-sess-20260315T000345Z-92e50eca","stream_session_id":"collector_main-stream-bitflyer-board_ws-20260315T000346Z-4b14e58c","exchange":"bitflyer","market":"spot","symbol":"BTC_JPY","instrument_id":"bitflyer.spot.BTC_JPY","channel":"board_ws","transport":"websocket","source_event_id":null,"source_sequence":null,"sequence_id":65,"exchange_ts":null,"collector_ts":"2026-03-15T00:03:46Z","ingest_ts":"2026-03-15T00:03:46Z","event_ts":"2026-03-15T00:03:46Z","quality_flags":[],"is_partial":false,"is_reconstructed":false,"confidence_score":1.0,"payload":{"provider":"bitflyer_ws_board","exchange":"bitflyer","transport":"websocket","channel":"lightning_board_BTC_JPY","received_ts":"2026-03-15T00:03:46.939354Z","subscription_id":null,"message_id":null,"source_sequence":null,"raw_message_meta":{"raw_channel":"lightning_board_BTC_JPY","subscription_channel":"lightning_board_BTC_JPY","recv_timeout_sec":10,"ssl_verify":false,"socket_url":"wss://ws.lightstream.bitflyer.com/json-rpc"},"source_payload":{"mid_price":11374765.0,"bids":[{"price":11331227.0,"size":0.51}],"asks":[]}}}
{"schema_version":"collector.vnext.raw","schema_contract":null,"schema_contract_version":null,"payload_contract_version":null,"record_type":"market.orderbook.diff","record_id":"collector_main-market-orderbook-diff-000000000067","collector_id":"collector_main","collector_role":"production","host_name":"MAIN-PC","session_id":"collector_main-sess-20260315T000345Z-92e50eca","stream_session_id":"collector_main-stream-bitflyer-board_ws-20260315T000346Z-4b14e58c","exchange":"bitflyer","market":"spot","symbol":"BTC_JPY","instrument_id":"bitflyer.spot.BTC_JPY","channel":"board_ws","transport":"websocket","source_event_id":null,"source_sequence":null,"sequence_id":67,"exchange_ts":null,"collector_ts":"2026-03-15T00:03:47Z","ingest_ts":"2026-03-15T00:03:47Z","event_ts":"2026-03-15T00:03:47Z","quality_flags":[],"is_partial":false,"is_reconstructed":false,"confidence_score":1.0,"payload":{"provider":"bitflyer_ws_board","exchange":"bitflyer","transport":"websocket","channel":"lightning_board_BTC_JPY","received_ts":"2026-03-15T00:03:47.063154Z","subscription_id":null,"message_id":null,"source_sequence":null,"raw_message_meta":{"raw_channel":"lightning_board_BTC_JPY","subscription_channel":"lightning_board_BTC_JPY","recv_timeout_sec":10,"ssl_verify":false,"socket_url":"wss://ws.lightstream.bitflyer.com/json-rpc"},"source_payload":{"mid_price":11374765.0,"bids":[{"price":11371353.0,"size":0.0},{"price":11364620.0,"size":0.0}],"asks":[]}}}
{"schema_version":"collector.vnext.raw","schema_contract":null,"schema_contract_version":null,"payload_contract_version":null,"record_type":"market.orderbook.diff","record_id":"collector_main-market-orderbook-diff-000000000069","collector_id":"collector_main","collector_role":"production","host_name":"MAIN-PC","session_id":"collector_main-sess-20260315T000345Z-92e50eca","stream_session_id":"collector_main-stream-bitflyer-board_ws-20260315T000346Z-4b14e58c","exchange":"bitflyer","market":"spot","symbol":"BTC_JPY","instrument_id":"bitflyer.spot.BTC_JPY","channel":"board_ws","transport":"websocket","source_event_id":null,"source_sequence":null,"sequence_id":69,"exchange_ts":null,"collector_ts":"2026-03-15T00:03:47Z","ingest_ts":"2026-03-15T00:03:47Z","event_ts":"2026-03-15T00:03:47Z","quality_flags":[],"is_partial":false,"is_reconstructed":false,"confidence_score":1.0,"payload":{"provider":"bitflyer_ws_board","exchange":"bitflyer","transport":"websocket","channel":"lightning_board_BTC_JPY","received_ts":"2026-03-15T00:03:47.236781Z","subscription_id":null,"message_id":null,"source_sequence":null,"raw_message_meta":{"raw_channel":"lightning_board_BTC_JPY","subscription_channel":"lightning_board_BTC_JPY","recv_timeout_sec":10,"ssl_verify":false,"socket_url":"wss://ws.lightstream.bitflyer.com/json-rpc"},"source_payload":{"mid_price":11374765.0,"bids":[{"price":11371354.0,"size":0.02}],"asks":[]}}}
{"schema_version":"collector.vnext.raw","schema_contract":null,"schema_contract_version":null,"payload_contract_version":null,"record_type":"market.orderbook.diff","record_id":"collector_main-market-orderbook-diff-000000000071","collector_id":"collector_main","collector_role":"production","host_name":"MAIN-PC","session_id":"collector_main-sess-20260315T000345Z-92e50eca","stream_session_id":"collector_main-stream-bitflyer-board_ws-20260315T000346Z-4b14e58c","exchange":"bitflyer","market":"spot","symbol":"BTC_JPY","instrument_id":"bitflyer.spot.BTC_JPY","channel":"board_ws","transport":"websocket","source_event_id":null,"source_sequence":null,"sequence_id":71,"exchange_ts":null,"collector_ts":"2026-03-15T00:03:47Z","ingest_ts":"2026-03-15T00:03:47Z","event_ts":"2026-03-15T00:03:47Z","quality_flags":[],"is_partial":false,"is_reconstructed":false,"confidence_score":1.0,"payload":{"provider":"bitflyer_ws_board","exchange":"bitflyer","transport":"websocket","channel":"lightning_board_BTC_JPY","received_ts":"2026-03-15T00:03:47.750911Z","subscription_id":null,"message_id":null,"source_sequence":null,"raw_message_meta":{"raw_channel":"lightning_board_BTC_JPY","subscription_channel":"lightning_board_BTC_JPY","recv_timeout_sec":10,"ssl_verify":false,"socket_url":"wss://ws.lightstream.bitflyer.com/json-rpc"},"source_payload":{"mid_price":11374765.0,"bids":[{"price":11364620.0,"size":0.06}],"asks":[]}}}
{"schema_version":"collector.vnext.raw","schema_contract":null,"schema_contract_version":null,"payload_contract_version":null,"record_type":"market.orderbook.diff","record_id":"collector_main-market-orderbook-diff-000000000073","collector_id":"collector_main","collector_role":"production","host_name":"MAIN-PC","session_id":"collector_main-sess-20260315T000345Z-92e50eca","stream_session_id":"collector_main-stream-bitflyer-board_ws-20260315T000346Z-4b14e58c","exchange":"bitflyer","market":"spot","symbol":"BTC_JPY","instrument_id":"bitflyer.spot.BTC_JPY","channel":"board_ws","transport":"websocket","source_event_id":null,"source_sequence":null,"sequence_id":73,"exchange_ts":null,"collector_ts":"2026-03-15T00:03:48Z","ingest_ts":"2026-03-15T00:03:48Z","event_ts":"2026-03-15T00:03:48Z","quality_flags":[],"is_partial":false,"is_reconstructed":false,"confidence_score":1.0,"payload":{"provider":"bitflyer_ws_board","exchange":"bitflyer","transport":"websocket","channel":"lightning_board_BTC_JPY","received_ts":"2026-03-15T00:03:48.000694Z","subscription_id":null,"message_id":null,"source_sequence":null,"raw_message_meta":{"raw_channel":"lightning_board_BTC_JPY","subscription_channel":"lightning_board_BTC_JPY","recv_timeout_sec":10,"ssl_verify":false,"socket_url":"wss://ws.lightstream.bitflyer.com/json-rpc"},"source_payload":{"mid_price":11374716.0,"bids":[],"asks":[{"price":11376472.0,"size":0.1275}]}}}
{"schema_version":"collector.vnext.raw","schema_contract":null,"schema_contract_version":null,"payload_contract_version":null,"record_type":"market.orderbook.diff","record_id":"collector_main-market-orderbook-diff-000000000075","collector_id":"collector_main","collector_role":"production","host_name":"MAIN-PC","session_id":"collector_main-sess-20260315T000345Z-92e50eca","stream_session_id":"collector_main-stream-bitflyer-board_ws-20260315T000346Z-4b14e58c","exchange":"bitflyer","market":"spot","symbol":"BTC_JPY","instrument_id":"bitflyer.spot.BTC_JPY","channel":"board_ws","transport":"websocket","source_event_id":null,"source_sequence":null,"sequence_id":75,"exchange_ts":null,"collector_ts":"2026-03-15T00:03:48Z","ingest_ts":"2026-03-15T00:03:48Z","event_ts":"2026-03-15T00:03:48Z","quality_flags":[],"is_partial":false,"is_reconstructed":false,"confidence_score":1.0,"payload":{"provider":"bitflyer_ws_board","exchange":"bitflyer","transport":"websocket","channel":"lightning_board_BTC_JPY","received_ts":"2026-03-15T00:03:48.121303Z","subscription_id":null,"message_id":null,"source_sequence":null,"raw_message_meta":{"raw_channel":"lightning_board_BTC_JPY","subscription_channel":"lightning_board_BTC_JPY","recv_timeout_sec":10,"ssl_verify":false,"socket_url":"wss://ws.lightstream.bitflyer.com/json-rpc"},"source_payload":{"mid_price":11374716.0,"bids":[{"price":11371352.0,"size":0.0866},{"price":11371354.0,"size":0.0}],"asks":[{"price":11387846.0,"size":0.05},{"price":11426426.0,"size":0.002}]}}}
{"schema_version":"collector.vnext.raw","schema_contract":null,"schema_contract_version":null,"payload_contract_version":null,"record_type":"market.orderbook.diff","record_id":"collector_main-market-orderbook-diff-000000000077","collector_id":"collector_main","collector_role":"production","host_name":"MAIN-PC","session_id":"collector_main-sess-20260315T000345Z-92e50eca","stream_session_id":"collector_main-stream-bitflyer-board_ws-20260315T000346Z-4b14e58c","exchange":"bitflyer","market":"spot","symbol":"BTC_JPY","instrument_id":"bitflyer.spot.BTC_JPY","channel":"board_ws","transport":"websocket","source_event_id":null,"source_sequence":null,"sequence_id":77,"exchange_ts":null,"collector_ts":"2026-03-15T00:03:48Z","ingest_ts":"2026-03-15T00:03:48Z","event_ts":"2026-03-15T00:03:48Z","quality_flags":[],"is_partial":false,"is_reconstructed":false,"confidence_score":1.0,"payload":{"provider":"bitflyer_ws_board","exchange":"bitflyer","transport":"websocket","channel":"lightning_board_BTC_JPY","received_ts":"2026-03-15T00:03:48.235255Z","subscription_id":null,"message_id":null,"source_sequence":null,"raw_message_meta":{"raw_channel":"lightning_board_BTC_JPY","subscription_channel":"lightning_board_BTC_JPY","recv_timeout_sec":10,"ssl_verify":false,"socket_url":"wss://ws.lightstream.bitflyer.com/json-rpc"},"source_payload":{"mid_price":11374692.0,"bids":[],"asks":[{"price":11387229.0,"size":0.0484},{"price":11376569.0,"size":0.0},{"price":11376423.0,"size":0.1275}]}}}
{"schema_version":"collector.vnext.raw","schema_contract":null,"schema_contract_version":null,"payload_contract_version":null,"record_type":"market.orderbook.diff","record_id":"collector_main-market-orderbook-diff-000000000079","collector_id":"collector_main","collector_role":"production","host_name":"MAIN-PC","session_id":"collector_main-sess-20260315T000345Z-92e50eca","stream_session_id":"collector_main-stream-bitflyer-board_ws-20260315T000346Z-4b14e58c","exchange":"bitflyer","market":"spot","symbol":"BTC_JPY","instrument_id":"bitflyer.spot.BTC_JPY","channel":"board_ws","transport":"websocket","source_event_id":null,"source_sequence":null,"sequence_id":79,"exchange_ts":null,"collector_ts":"2026-03-15T00:03:48Z","ingest_ts":"2026-03-15T00:03:48Z","event_ts":"2026-03-15T00:03:48Z","quality_flags":[],"is_partial":false,"is_reconstructed":false,"confidence_score":1.0,"payload":{"provider":"bitflyer_ws_board","exchange":"bitflyer","transport":"websocket","channel":"lightning_board_BTC_JPY","received_ts":"2026-03-15T00:03:48.344476Z","subscription_id":null,"message_id":null,"source_sequence":null,"raw_message_meta":{"raw_channel":"lightning_board_BTC_JPY","subscription_channel":"lightning_board_BTC_JPY","recv_timeout_sec":10,"ssl_verify":false,"socket_url":"wss://ws.lightstream.bitflyer.com/json-rpc"},"source_payload":{"mid_price":11374692.0,"bids":[{"price":11363482.0,"size":0.07}],"asks":[{"price":11376472.0,"size":0.198}]}}}
{"schema_version":"collector.vnext.raw","schema_contract":null,"schema_contract_version":null,"payload_contract_version":null,"record_type":"market.orderbook.diff","record_id":"collector_main-market-orderbook-diff-000000000081","collector_id":"collector_main","collector_role":"production","host_name":"MAIN-PC","session_id":"collector_main-sess-20260315T000345Z-92e50eca","stream_session_id":"collector_main-stream-bitflyer-board_ws-20260315T000346Z-4b14e58c","exchange":"bitflyer","market":"spot","symbol":"BTC_JPY","instrument_id":"bitflyer.spot.BTC_JPY","channel":"board_ws","transport":"websocket","source_event_id":null,"source_sequence":null,"sequence_id":81,"exchange_ts":null,"collector_ts":"2026-03-15T00:03:48Z","ingest_ts":"2026-03-15T00:03:48Z","event_ts":"2026-03-15T00:03:48Z","quality_flags":[],"is_partial":false,"is_reconstructed":false,"confidence_score":1.0,"payload":{"provider":"bitflyer_ws_board","exchange":"bitflyer","transport":"websocket","channel":"lightning_board_BTC_JPY","received_ts":"2026-03-15T00:03:48.453807Z","subscription_id":null,"message_id":null,"source_sequence":null,"raw_message_meta":{"raw_channel":"lightning_board_BTC_JPY","subscription_channel":"lightning_board_BTC_JPY","recv_timeout_sec":10,"ssl_verify":false,"socket_url":"wss://ws.lightstream.bitflyer.com/json-rpc"},"source_payload":{"mid_price":11374692.0,"bids":[{"price":11371353.0,"size":0.02}],"asks":[{"price":11387229.0,"size":0.0},{"price":11387846.0,"size":0.0},{"price":11376472.0,"size":0.1275},{"price":11376423.0,"size":0.2077}]}}}
{"schema_version":"collector.vnext.raw","schema_contract":null,"schema_contract_version":null,"payload_contract_version":null,"record_type":"market.orderbook.diff","record_id":"collector_main-market-orderbook-diff-000000000083","collector_id":"collector_main","collector_role":"production","host_name":"MAIN-PC","session_id":"collector_main-sess-20260315T000345Z-92e50eca","stream_session_id":"collector_main-stream-bitflyer-board_ws-20260315T000346Z-4b14e58c","exchange":"bitflyer","market":"spot","symbol":"BTC_JPY","instrument_id":"bitflyer.spot.BTC_JPY","channel":"board_ws","transport":"websocket","source_event_id":null,"source_sequence":null,"sequence_id":83,"exchange_ts":null,"collector_ts":"2026-03-15T00:03:48Z","ingest_ts":"2026-03-15T00:03:48Z","event_ts":"2026-03-15T00:03:48Z","quality_flags":[],"is_partial":false,"is_reconstructed":false,"confidence_score":1.0,"payload":{"provider":"bitflyer_ws_board","exchange":"bitflyer","transport":"websocket","channel":"lightning_board_BTC_JPY","received_ts":"2026-03-15T00:03:48.735512Z","subscription_id":null,"message_id":null,"source_sequence":null,"raw_message_meta":{"raw_channel":"lightning_board_BTC_JPY","subscription_channel":"lightning_board_BTC_JPY","recv_timeout_sec":10,"ssl_verify":false,"socket_url":"wss://ws.lightstream.bitflyer.com/json-rpc"},"source_payload":{"mid_price":11374692.0,"bids":[{"price":11357794.0,"size":0.31},{"price":11364620.0,"size":0.0}],"asks":[]}}}
{"schema_version":"collector.vnext.raw","schema_contract":null,"schema_contract_version":null,"payload_contract_version":null,"record_type":"market.orderbook.diff","record_id":"collector_main-market-orderbook-diff-000000000085","collector_id":"collector_main","collector_role":"production","host_name":"MAIN-PC","session_id":"collector_main-sess-20260315T000345Z-92e50eca","stream_session_id":"collector_main-stream-bitflyer-board_ws-20260315T000346Z-4b14e58c","exchange":"bitflyer","market":"spot","symbol":"BTC_JPY","instrument_id":"bitflyer.spot.BTC_JPY","channel":"board_ws","transport":"websocket","source_event_id":null,"source_sequence":null,"sequence_id":85,"exchange_ts":null,"collector_ts":"2026-03-15T00:03:49Z","ingest_ts":"2026-03-15T00:03:49Z","event_ts":"2026-03-15T00:03:49Z","quality_flags":[],"is_partial":false,"is_reconstructed":false,"confidence_score":1.0,"payload":{"provider":"bitflyer_ws_board","exchange":"bitflyer","transport":"websocket","channel":"lightning_board_BTC_JPY","received_ts":"2026-03-15T00:03:49.050280Z","subscription_id":null,"message_id":null,"source_sequence":null,"raw_message_meta":{"raw_channel":"lightning_board_BTC_JPY","subscription_channel":"lightning_board_BTC_JPY","recv_timeout_sec":10,"ssl_verify":false,"socket_url":"wss://ws.lightstream.bitflyer.com/json-rpc"},"source_payload":{"mid_price":11374692.0,"bids":[{"price":11370999.0,"size":0.0},{"price":11361746.0,"size":0.00999891},{"price":11370705.0,"size":0.0}],"asks":[]}}}
{"schema_version":"collector.vnext.raw","schema_contract":null,"schema_contract_version":null,"payload_contract_version":null,"record_type":"market.orderbook.diff","record_id":"collector_main-market-orderbook-diff-000000000087","collector_id":"collector_main","collector_role":"production","host_name":"MAIN-PC","session_id":"collector_main-sess-20260315T000345Z-92e50eca","stream_session_id":"collector_main-stream-bitflyer-board_ws-20260315T000346Z-4b14e58c","exchange":"bitflyer","market":"spot","symbol":"BTC_JPY","instrument_id":"bitflyer.spot.BTC_JPY","channel":"board_ws","transport":"websocket","source_event_id":null,"source_sequence":null,"sequence_id":87,"exchange_ts":null,"collector_ts":"2026-03-15T00:03:49Z","ingest_ts":"2026-03-15T00:03:49Z","event_ts":"2026-03-15T00:03:49Z","quality_flags":[],"is_partial":false,"is_reconstructed":false,"confidence_score":1.0,"payload":{"provider":"bitflyer_ws_board","exchange":"bitflyer","transport":"websocket","channel":"lightning_board_BTC_JPY","received_ts":"2026-03-15T00:03:49.171872Z","subscription_id":null,"message_id":null,"source_sequence":null,"raw_message_meta":{"raw_channel":"lightning_board_BTC_JPY","subscription_channel":"lightning_board_BTC_JPY","recv_timeout_sec":10,"ssl_verify":false,"socket_url":"wss://ws.lightstream.bitflyer.com/json-rpc"},"source_payload":{"mid_price":11374692.0,"bids":[{"price":11371564.0,"size":0.00999792}],"asks":[]}}}
{"schema_version":"collector.vnext.raw","schema_contract":null,"schema_contract_version":null,"payload_contract_version":null,"record_type":"market.orderbook.diff","record_id":"collector_main-market-orderbook-diff-000000000089","collector_id":"collector_main","collector_role":"production","host_name":"MAIN-PC","session_id":"collector_main-sess-20260315T000345Z-92e50eca","stream_session_id":"collector_main-stream-bitflyer-board_ws-20260315T000346Z-4b14e58c","exchange":"bitflyer","market":"spot","symbol":"BTC_JPY","instrument_id":"bitflyer.spot.BTC_JPY","channel":"board_ws","transport":"websocket","source_event_id":null,"source_sequence":null,"sequence_id":89,"exchange_ts":null,"collector_ts":"2026-03-15T00:03:49Z","ingest_ts":"2026-03-15T00:03:49Z","event_ts":"2026-03-15T00:03:49Z","quality_flags":[],"is_partial":false,"is_reconstructed":false,"confidence_score":1.0,"payload":{"provider":"bitflyer_ws_board","exchange":"bitflyer","transport":"websocket","channel":"lightning_board_BTC_JPY","received_ts":"2026-03-15T00:03:49.283410Z","subscription_id":null,"message_id":null,"source_sequence":null,"raw_message_meta":{"raw_channel":"lightning_board_BTC_JPY","subscription_channel":"lightning_board_BTC_JPY","recv_timeout_sec":10,"ssl_verify":false,"socket_url":"wss://ws.lightstream.bitflyer.com/json-rpc"},"source_payload":{"mid_price":11374692.0,"bids":[{"price":11363482.0,"size":0.0}],"asks":[]}}}
{"schema_version":"collector.vnext.raw","schema_contract":null,"schema_contract_version":null,"payload_contract_version":null,"record_type":"market.orderbook.diff","record_id":"collector_main-market-orderbook-diff-000000000091","collector_id":"collector_main","collector_role":"production","host_name":"MAIN-PC","session_id":"collector_main-sess-20260315T000345Z-92e50eca","stream_session_id":"collector_main-stream-bitflyer-board_ws-20260315T000346Z-4b14e58c","exchange":"bitflyer","market":"spot","symbol":"BTC_JPY","instrument_id":"bitflyer.spot.BTC_JPY","channel":"board_ws","transport":"websocket","source_event_id":null,"source_sequence":null,"sequence_id":91,"exchange_ts":null,"collector_ts":"2026-03-15T00:03:49Z","ingest_ts":"2026-03-15T00:03:49Z","event_ts":"2026-03-15T00:03:49Z","quality_flags":[],"is_partial":false,"is_reconstructed":false,"confidence_score":1.0,"payload":{"provider":"bitflyer_ws_board","exchange":"bitflyer","transport":"websocket","channel":"lightning_board_BTC_JPY","received_ts":"2026-03-15T00:03:49.516823Z","subscription_id":null,"message_id":null,"source_sequence":null,"raw_message_meta":{"raw_channel":"lightning_board_BTC_JPY","subscription_channel":"lightning_board_BTC_JPY","recv_timeout_sec":10,"ssl_verify":false,"socket_url":"wss://ws.lightstream.bitflyer.com/json-rpc"},"source_payload":{"mid_price":11374692.0,"bids":[{"price":11364620.0,"size":0.1}],"asks":[]}}}
{"schema_version":"collector.vnext.raw","schema_contract":null,"schema_contract_version":null,"payload_contract_version":null,"record_type":"market.orderbook.diff","record_id":"collector_main-market-orderbook-diff-000000000093","collector_id":"collector_main","collector_role":"production","host_name":"MAIN-PC","session_id":"collector_main-sess-20260315T000345Z-92e50eca","stream_session_id":"collector_main-stream-bitflyer-board_ws-20260315T000346Z-4b14e58c","exchange":"bitflyer","market":"spot","symbol":"BTC_JPY","instrument_id":"bitflyer.spot.BTC_JPY","channel":"board_ws","transport":"websocket","source_event_id":null,"source_sequence":null,"sequence_id":93,"exchange_ts":null,"collector_ts":"2026-03-15T00:03:49Z","ingest_ts":"2026-03-15T00:03:49Z","event_ts":"2026-03-15T00:03:49Z","quality_flags":[],"is_partial":false,"is_reconstructed":false,"confidence_score":1.0,"payload":{"provider":"bitflyer_ws_board","exchange":"bitflyer","transport":"websocket","channel":"lightning_board_BTC_JPY","received_ts":"2026-03-15T00:03:49.781818Z","subscription_id":null,"message_id":null,"source_sequence":null,"raw_message_meta":{"raw_channel":"lightning_board_BTC_JPY","subscription_channel":"lightning_board_BTC_JPY","recv_timeout_sec":10,"ssl_verify":false,"socket_url":"wss://ws.lightstream.bitflyer.com/json-rpc"},"source_payload":{"mid_price":11374692.0,"bids":[],"asks":[{"price":11387205.0,"size":0.05},{"price":11443629.0,"size":0.002}]}}}
{"schema_version":"collector.vnext.raw","schema_contract":null,"schema_contract_version":null,"payload_contract_version":null,"record_type":"market.orderbook.diff","record_id":"collector_main-market-orderbook-diff-000000000095","collector_id":"collector_main","collector_role":"production","host_name":"MAIN-PC","session_id":"collector_main-sess-20260315T000345Z-92e50eca","stream_session_id":"collector_main-stream-bitflyer-board_ws-20260315T000346Z-4b14e58c","exchange":"bitflyer","market":"spot","symbol":"BTC_JPY","instrument_id":"bitflyer.spot.BTC_JPY","channel":"board_ws","transport":"websocket","source_event_id":null,"source_sequence":null,"sequence_id":95,"exchange_ts":null,"collector_ts":"2026-03-15T00:03:50Z","ingest_ts":"2026-03-15T00:03:50Z","event_ts":"2026-03-15T00:03:50Z","quality_flags":[],"is_partial":false,"is_reconstructed":false,"confidence_score":1.0,"payload":{"provider":"bitflyer_ws_board","exchange":"bitflyer","transport":"websocket","channel":"lightning_board_BTC_JPY","received_ts":"2026-03-15T00:03:50.000330Z","subscription_id":null,"message_id":null,"source_sequence":null,"raw_message_meta":{"raw_channel":"lightning_board_BTC_JPY","subscription_channel":"lightning_board_BTC_JPY","recv_timeout_sec":10,"ssl_verify":false,"socket_url":"wss://ws.lightstream.bitflyer.com/json-rpc"},"source_payload":{"mid_price":11374692.0,"bids":[{"price":11363482.0,"size":0.12}],"asks":[]}}}
{"schema_version":"collector.vnext.raw","schema_contract":null,"schema_contract_version":null,"payload_contract_version":null,"record_type":"market.orderbook.snapshot","record_id":"collector_main-market-orderbook-snapshot-000000000097","collector_id":"collector_main","collector_role":"production","host_name":"MAIN-PC","session_id":"collector_main-sess-20260315T000345Z-92e50eca","stream_session_id":"collector_main-stream-bitflyer-board_ws-20260315T000346Z-4b14e58c","exchange":"bitflyer","market":"spot","symbol":"BTC_JPY","instrument_id":"bitflyer.spot.BTC_JPY","channel":"board_ws","transport":"websocket","source_event_id":null,"source_sequence":null,"sequence_id":97,"exchange_ts":null,"collector_ts":"2026-03-15T00:03:50Z","ingest_ts":"2026-03-15T00:03:50Z","event_ts":"2026-03-15T00:03:50Z","quality_flags":[],"is_partial":false,"is_reconstructed":false,"confidence_score":1.0,"payload":{"provider":"bitflyer_ws_board_snapshot","exchange":"bitflyer","transport":"websocket","channel":"lightning_board_snapshot_BTC_JPY","received_ts":"2026-03-15T00:03:50.363818Z","subscription_id":null,"message_id":null,"source_sequence":null,"raw_message_meta":{"raw_channel":"lightning_board_snapshot_BTC_JPY","subscription_channel":"lightning_board_snapshot_BTC_JPY","recv_timeout_sec":10,"ssl_verify":false,"socket_url":"wss://ws.lightstream.bitflyer.com/json-rpc"},"source_payload":{"mid_price":11374692.0,"bids":[{"price":11372961.0,"size":0.14063},{"price":11372393.0,"size":0.005},{"price":11371587.0,"size":0.02},{"price":11371564.0,"size":0.00999792},{"price":11371380.0,"size":0.02},{"price":11371353.0,"size":0.02},{"price":11371352.0,"size":0.0866},{"price":11370998.0,"size":0.26595698},{"price":11370371.0,"size":0.01458},{"price":11370267.0,"size":0.2},{"price":11370049.0,"size":0.5},{"price":11370007.0,"size":0.01518},{"price":11370000.0,"size":0.015},{"price":11369239.0,"size":0.015},{"price":11368376.0,"size":0.01},{"price":11368353.0,"size":0.01},{"price":11366247.0,"size":0.036},{"price":11366008.0,"size":0.04},{"price":11365522.0,"size":3.11724327},{"price":11365521.0,"size":0.0520128},{"price":11365274.0,"size":0.0527},{"price":11364620.0,"size":0.1},{"price":11363829.0,"size":0.01},{"price":11363482.0,"size":0.12},{"price":11362277.0,"size":0.9772867},{"price":11361746.0,"size":0.00999891},{"price":11361538.0,"size":1.50015},{"price":11358376.0,"size":0.01},{"price":11357858.0,"size":0.24},{"price":11357794.0,"size":0.31},{"price":11354613.0,"size":0.05},{"price":11354044.0,"size":0.05},{"price":11353488.0,"size":0.27174084},{"price":11351280.0,"size":0.2739},{"price":11350744.0,"size":0.002},{"price":11350000.0,"size":0.51},{"price":11348518.0,"size":0.2616},{"price":11348189.0,"size":0.003},{"price":11347667.0,"size":0.001},{"price":11347661.0,"size":0.6},{"price":11346193.0,"size":0.002},{"price":11345756.0,"size":0.267},{"price":11345154.0,"size":1.484},{"price":11342994.0,"size":0.2708},{"price":11341672.0,"size":0.05739971},{"price":11341671.0,"size":0.23},{"price":11341642.0,"size":0.002},{"price":11340000.0,"size":0.005},{"price":11338046.0,"size":1.966},{"price":11337091.0,"size":0.002},{"price":11336383.0,"size":0.001},{"price":11336319.0,"size":0.00195},{"price":11332540.0,"size":0.002},{"price":11331227.0,"size":0.51},{"price":11331000.0,"size":0.5},{"price":11330490.0,"size":2.036},{"price":11330000.0,"size":0.02442},{"price":11327989.0,"size":0.002},{"price":11325101.0,"size":0.001},{"price":11323438.0,"size":0.002},{"price":11320000.0,"size":0.05},{"price":11318887.0,"size":0.002},{"price":11315000.0,"size":0.05},{"price":11314336.0,"size":0.002},{"price":11314325.0,"size":1.951},{"price":11313996.0,"size":0.00195},{"price":11313819.0,"size":0.001},{"price":11310000.0,"size":0.01},{"price":11309999.0,"size":0.177},{"price":11309785.0,"size":0.002},{"price":11307999.0,"size":0.01},{"price":11303918.0,"size":0.01},{"price":11303000.0,"size":0.5},{"price":11302535.0,"size":0.001},{"price":11302466.0,"size":0.001},{"price":11301268.0,"size":0.01},{"price":11300000.0,"size":3.01685256},{"price":11298000.0,"size":0.01},{"price":11296865.0,"size":0.0015},{"price":11294756.0,"size":1.0},{"price":11291282.0,"size":0.001},{"price":11291268.0,"size":0.01},{"price":11291000.0,"size":0.5},{"price":11290000.0,"size":0.003},{"price":11281268.0,"size":0.01},{"price":11280000.0,"size":0.0163},{"price":11279960.0,"size":0.001},{"price":11279282.0,"size":0.0015},{"price":11278000.0,"size":0.0025},{"price":11275000.0,"size":0.001},{"price":11274588.0,"size":0.0047},{"price":11271268.0,"size":0.01},{"price":11271000.0,"size":0.003},{"price":11270000.0,"size":0.106},{"price":11269424.0,"size":0.8},{"price":11268871.0,"size":0.28},{"price":11268638.0,"size":0.001},{"price":11268411.0,"size":0.01},{"price":11266666.0,"size":0.04},{"price":11265000.0,"size":0.02},{"price":11263000.0,"size":0.006},{"price":11262564.0,"size":0.0015},{"price":11261268.0,"size":0.01},{"price":11260000.0,"size":0.3565},{"price":11257315.0,"size":0.001},{"price":11257000.0,"size":0.001},{"price":11255200.0,"size":0.001},{"price":11255115.0,"size":0.00377},{"price":11253814.0,"size":2.2},{"price":11253690.0,"size":0.01},{"price":11253000.0,"size":0.03189},{"price":11251405.0,"size":0.139},{"price":11251268.0,"size":0.01},{"price":11251111.0,"size":0.0015},{"price":11251000.0,"size":0.0131},{"price":11250250.0,"size":0.00105},{"price":11250200.0,"size":0.001},{"price":11250005.0,"size":0.001},{"price":11250001.0,"size":0.00104},{"price":11250000.0,"size":1.62712889},{"price":11245993.0,"size":0.001},{"price":11245141.0,"size":0.0031},{"price":11245000.0,"size":0.05},{"price":11244444.0,"size":0.04},{"price":11244243.0,"size":0.01},{"price":11240200.0,"size":0.001},{"price":11240000.0,"size":0.007304},{"price":11236190.0,"size":0.01},{"price":11235200.0,"size":0.001},{"price":11234670.0,"size":0.001},{"price":11232000.0,"size":0.089},{"price":11231243.0,"size":0.01},{"price":11231000.0,"size":0.105},{"price":11230200.0,"size":0.001},{"price":11230000.0,"size":0.0308},{"price":11226952.0,"size":0.972},{"price":11224500.0,"size":0.06},{"price":11223968.0,"size":0.001},{"price":11223348.0,"size":0.001},{"price":11223344.0,"size":0.01},{"price":11223000.0,"size":0.1},{"price":11222222.0,"size":0.093525},{"price":11221120.0,"size":0.001},{"price":11220200.0,"size":0.001},{"price":11220001.0,"size":0.004457},{"price":11220000.0,"size":0.321},{"price":11219000.0,"size":0.1},{"price":11217326.0,"size":0.02},{"price":11215200.0,"size":0.001},{"price":11213690.0,"size":0.01},{"price":11212025.0,"size":0.001},{"price":11211800.0,"size":0.001},{"price":11211111.0,"size":0.06},{"price":11210200.0,"size":0.001},{"price":11210000.0,"size":0.10622},{"price":11208032.0,"size":0.01},{"price":11206000.0,"size":0.09015},{"price":11205200.0,"size":0.001},{"price":11204578.0,"size":0.002},{"price":11201000.0,"size":0.01},{"price":11200800.0,"size":0.05},{"price":11200703.0,"size":0.001},{"price":11200425.0,"size":0.1},{"price":11200200.0,"size":0.001},{"price":11200198.0,"size":0.003},{"price":11200150.0,"size":0.002},{"price":11200002.0,"size":0.001},{"price":11200001.0,"size":0.01104},{"price":11200000.0,"size":1.15226728},{"price":11198508.0,"size":0.05},{"price":11198243.0,"size":0.01},{"price":11197134.0,"size":0.993},{"price":11197000.0,"size":0.0085},{"price":11194090.0,"size":0.03},{"price":11190770.0,"size":0.0309},{"price":11190000.0,"size":0.0010016},{"price":11189555.0,"size":0.5},{"price":11189381.0,"size":0.001},{"price":11188629.0,"size":0.01},{"price":11188382.0,"size":0.001},{"price":11185000.0,"size":0.0085},{"price":11180000.0,"size":0.225},{"price":11178058.0,"size":0.001},{"price":11170000.0,"size":0.001},{"price":11169662.0,"size":0.01},{"price":11169593.0,"size":0.001},{"price":11169243.0,"size":0.01},{"price":11166736.0,"size":0.001},{"price":11164029.0,"size":0.001},{"price":11160854.0,"size":0.1},{"price":11160000.0,"size":0.02376},{"price":11155413.0,"size":0.001},{"price":11155377.0,"size":0.00636009},{"price":11153999.0,"size":0.00101},{"price":11151000.0,"size":0.001},{"price":11150250.0,"size":0.00175},{"price":11150005.0,"size":0.001},{"price":11150001.0,"size":0.00104},{"price":11150000.0,"size":0.6533956},{"price":11148000.0,"size":0.08963},{"price":11147546.0,"size":0.02},{"price":11144091.0,"size":0.001},{"price":11144000.0,"size":0.0897},{"price":11143986.0,"size":0.02},{"price":11140139.0,"size":1.0},{"price":11140000.0,"size":0.2},{"price":11136243.0,"size":0.01},{"price":11135869.0,"size":0.1},{"price":11132768.0,"size":0.001},{"price":11130000.0,"size":0.116},{"price":11129979.0,"size":0.0053908},{"price":11124900.0,"size":0.00133},{"price":11121090.0,"size":0.1},{"price":11120000.0,"size":0.0033},{"price":11118078.0,"size":0.01},{"price":11111800.0,"size":0.001},{"price":11111111.0,"size":0.2919257},{"price":11111000.0,"size":0.003},{"price":11110594.0,"size":0.001},{"price":11110000.0,"size":0.021007},{"price":11109662.0,"size":0.01},{"price":11108008.0,"size":0.01},{"price":11102000.0,"size":0.5},{"price":11101297.0,"size":0.001},{"price":11100005.0,"size":0.001},{"price":11100001.0,"size":0.01104},{"price":11100000.0,"size":1.6532049},{"price":11099141.0,"size":0.01},{"price":11098833.0,"size":0.002},{"price":11096243.0,"size":0.01},{"price":11094090.0,"size":0.01},{"price":11088888.0,"size":0.001},{"price":11085245.0,"size":0.001},{"price":11080200.0,"size":0.001},{"price":11080000.0,"size":0.0223},{"price":11075100.0,"size":0.003},{"price":11070200.0,"size":0.001},{"price":11070000.0,"size":0.0902},{"price":11065200.0,"size":0.001},{"price":11064370.0,"size":0.00497091},{"price":11060200.0,"size":0.001},{"price":11060000.0,"size":0.145},{"price":11059689.0,"size":0.009},{"price":11056428.0,"size":0.002},{"price":11055500.0,"size":0.02},{"price":11055200.0,"size":0.001},{"price":11055100.0,"size":0.003},{"price":11050200.0,"size":0.001},{"price":11050005.0,"size":0.001},{"price":11050002.0,"size":0.001},{"price":11050001.0,"size":0.00104},{"price":11050000.0,"size":0.39576147},{"price":11048064.0,"size":2.0},{"price":11046420.0,"size":0.2},{"price":11044243.0,"size":0.01},{"price":11041380.0,"size":0.01},{"price":11040200.0,"size":0.001},{"price":11040000.0,"size":0.00777181},{"price":11035865.0,"size":0.1},{"price":11035200.0,"size":0.001},{"price":11035000.0,"size":0.0013},{"price":11030200.0,"size":0.001},{"price":11030000.0,"size":0.025},{"price":11025500.0,"size":0.009531},{"price":11025200.0,"size":0.001},{"price":11025000.0,"size":0.71497},{"price":11020772.0,"size":0.014},{"price":11020200.0,"size":0.002},{"price":11020000.0,"size":0.005},{"price":11015200.0,"size":0.001},{"price":11012000.0,"size":0.1},{"price":11011800.0,"size":0.001},{"price":11010200.0,"size":0.001},{"price":11010000.0,"size":0.347},{"price":11007277.0,"size":0.01},{"price":11005200.0,"size":0.001},{"price":11004890.0,"size":0.001535},{"price":11003000.0,"size":0.0155},{"price":11001000.0,"size":0.013},{"price":11000500.0,"size":0.05117658},{"price":11000200.0,"size":0.001},{"price":11000002.0,"size":0.004},{"price":11000001.0,"size":0.02604},{"price":11000000.0,"size":4.53923365},{"price":10999999.0,"size":0.003},{"price":10999000.0,"size":0.001},{"price":10996855.0,"size":0.0011},{"price":10995200.0,"size":0.001},{"price":10994499.0,"size":0.00169176},{"price":10990200.0,"size":0.001},{"price":10990000.0,"size":0.10219},{"price":10989001.0,"size":0.00197},{"price":10988999.0,"size":0.001},{"price":10988324.0,"size":0.002},{"price":10987654.0,"size":0.001},{"price":10985200.0,"size":0.001},{"price":10985150.0,"size":0.01},{"price":10980500.0,"size":0.005},{"price":10980200.0,"size":0.001},{"price":10980002.0,"size":0.4}],"asks":[{"price":11376423.0,"size":0.20666035},{"price":11376472.0,"size":0.1275},{"price":11377849.0,"size":0.015264},{"price":11378272.0,"size":0.014556},{"price":11378282.0,"size":0.00994996},{"price":11378563.0,"size":0.0408007},{"price":11378564.0,"size":0.02},{"price":11378566.0,"size":0.014484},{"price":11379159.0,"size":0.02},{"price":11379160.0,"size":0.015096},{"price":11379346.0,"size":0.02},{"price":11379347.0,"size":0.2952},{"price":11382108.0,"size":0.02},{"price":11382109.0,"size":0.301},{"price":11382394.0,"size":0.0528336},{"price":11382750.0,"size":0.234},{"price":11384871.0,"size":0.2657},{"price":11385094.0,"size":0.01},{"price":11387173.0,"size":0.57257629},{"price":11387174.0,"size":0.1},{"price":11387205.0,"size":0.05},{"price":11387633.0,"size":0.2976},{"price":11388991.0,"size":0.15},{"price":11389573.0,"size":0.0044},{"price":11390970.0,"size":0.0526},{"price":11391432.0,"size":0.4249},{"price":11392010.0,"size":0.00142446},{"price":11393747.0,"size":1.189881},{"price":11394441.0,"size":1.189881},{"price":11397000.0,"size":0.02},{"price":11398444.0,"size":0.001995},{"price":11398845.0,"size":0.001},{"price":11399673.0,"size":0.0015},{"price":11399700.0,"size":0.001},{"price":11399999.0,"size":0.05},{"price":11400000.0,"size":0.64832841},{"price":11403472.0,"size":0.002},{"price":11405000.0,"size":0.1575},{"price":11405422.0,"size":1.489},{"price":11408699.0,"size":1.15098095},{"price":11408700.0,"size":0.001},{"price":11409415.0,"size":0.005},{"price":11409925.0,"size":0.22},{"price":11410000.0,"size":0.3787},{"price":11410168.0,"size":0.001},{"price":11410853.0,"size":0.002},{"price":11412000.0,"size":0.0878},{"price":11415000.0,"size":0.1},{"price":11415141.0,"size":0.0041},{"price":11417459.0,"size":1.928},{"price":11417481.0,"size":0.0015},{"price":11418700.0,"size":0.001},{"price":11419000.0,"size":0.01},{"price":11420000.0,"size":0.661},{"price":11421268.0,"size":0.05},{"price":11421490.0,"size":0.001},{"price":11424296.0,"size":0.002},{"price":11425000.0,"size":0.029},{"price":11426426.0,"size":0.002},{"price":11428121.0,"size":0.002},{"price":11428700.0,"size":0.001},{"price":11429302.0,"size":0.01},{"price":11430000.0,"size":0.4098},{"price":11432718.0,"size":0.002},{"price":11432813.0,"size":0.001},{"price":11433211.0,"size":0.03},{"price":11433333.0,"size":0.001},{"price":11437315.0,"size":0.002},{"price":11438525.0,"size":0.0011},{"price":11438700.0,"size":0.001},{"price":11439557.0,"size":0.001},{"price":11440000.0,"size":0.2538},{"price":11441911.0,"size":0.002},{"price":11442627.0,"size":2.018},{"price":11443629.0,"size":0.002},{"price":11444135.0,"size":0.001},{"price":11445433.0,"size":0.0015},{"price":11446508.0,"size":0.001},{"price":11447000.0,"size":0.01},{"price":11448000.0,"size":0.0875},{"price":11448700.0,"size":0.001},{"price":11450000.0,"size":0.268},{"price":11451105.0,"size":0.002},{"price":11453321.0,"size":0.03},{"price":11455000.0,"size":0.001},{"price":11455457.0,"size":0.001},{"price":11455702.0,"size":0.002},{"price":11458700.0,"size":0.001},{"price":11458988.0,"size":0.01},{"price":11460000.0,"size":0.06702},{"price":11460299.0,"size":0.002},{"price":11463288.0,"size":0.01},{"price":11464896.0,"size":0.002},{"price":11465382.0,"size":0.00195},{"price":11465421.0,"size":1.943},{"price":11466780.0,"size":0.001},{"price":11468700.0,"size":0.001},{"price":11470000.0,"size":0.06},{"price":11471000.0,"size":0.01},{"price":11475000.0,"size":0.0028},{"price":11476929.0,"size":1.0},{"price":11478102.0,"size":0.001},{"price":11478700.0,"size":0.001},{"price":11480000.0,"size":0.40191},{"price":11485000.0,"size":0.01},{"price":11485488.0,"size":2.0},{"price":11486555.0,"size":0.03},{"price":11487685.0,"size":0.01},{"price":11488000.0,"size":0.102},{"price":11488700.0,"size":0.001},{"price":11489425.0,"size":0.001},{"price":11490000.0,"size":0.05},{"price":11490841.0,"size":0.002},{"price":11495450.0,"size":0.002},{"price":11495850.0,"size":0.001},{"price":11498700.0,"size":0.001},{"price":11499000.0,"size":0.01},{"price":11500000.0,"size":0.77159519},{"price":11500078.0,"size":0.93},{"price":11500747.0,"size":0.001},{"price":11502800.0,"size":0.00132},{"price":11503108.0,"size":0.0198},{"price":11505000.0,"size":0.0028},{"price":11505001.0,"size":0.002},{"price":11505836.0,"size":0.001},{"price":11508431.0,"size":0.047},{"price":11508700.0,"size":0.001},{"price":11508888.0,"size":0.02},{"price":11510000.0,"size":0.1476},{"price":11512070.0,"size":0.001},{"price":11513633.0,"size":0.08},{"price":11514332.0,"size":0.02},{"price":11518700.0,"size":0.001},{"price":11518992.0,"size":0.002},{"price":11519855.0,"size":0.01},{"price":11520000.0,"size":0.001},{"price":11522388.0,"size":0.972},{"price":11523211.0,"size":0.01},{"price":11524999.0,"size":0.001},{"price":11528700.0,"size":0.001},{"price":11529852.0,"size":0.01},{"price":11530000.0,"size":0.261},{"price":11534084.0,"size":0.001},{"price":11535321.0,"size":0.01},{"price":11538700.0,"size":0.001},{"price":11540000.0,"size":0.0048},{"price":11540357.0,"size":0.002},{"price":11541011.0,"size":0.005},{"price":11541109.0,"size":0.01},{"price":11545262.0,"size":0.002},{"price":11546541.0,"size":0.01},{"price":11548700.0,"size":0.001},{"price":11550000.0,"size":0.014},{"price":11551109.0,"size":0.01},{"price":11552111.0,"size":0.01},{"price":11553687.0,"size":0.1},{"price":11555115.0,"size":0.001},{"price":11556000.0,"size":0.1},{"price":11558700.0,"size":0.001},{"price":11559855.0,"size":0.01},{"price":11560831.0,"size":0.0198},{"price":11561109.0,"size":0.01},{"price":11562000.0,"size":0.087},{"price":11563750.0,"size":0.08739676},{"price":11566139.0,"size":0.0228},{"price":11566551.0,"size":0.01},{"price":11568700.0,"size":0.001},{"price":11570196.0,"size":0.002},{"price":11571109.0,"size":0.01},{"price":11573211.0,"size":0.01},{"price":11574840.0,"size":0.002},{"price":11578700.0,"size":0.001},{"price":11579484.0,"size":0.002},{"price":11579851.0,"size":0.01},{"price":11580000.0,"size":0.7835},{"price":11581109.0,"size":0.01},{"price":11584128.0,"size":0.002},{"price":11585000.0,"size":0.002},{"price":11586532.0,"size":0.01},{"price":11587498.0,"size":0.0198},{"price":11588700.0,"size":0.001},{"price":11588800.0,"size":0.02},{"price":11590000.0,"size":0.1},{"price":11590749.0,"size":0.002},{"price":11591109.0,"size":0.01},{"price":11593211.0,"size":0.01},{"price":11596753.0,"size":0.002},{"price":11598111.0,"size":0.1474},{"price":11598555.0,"size":0.01},{"price":11598700.0,"size":0.001},{"price":11599999.0,"size":0.001},{"price":11600000.0,"size":3.655},{"price":11601109.0,"size":0.02},{"price":11603764.0,"size":0.9},{"price":11606655.0,"size":0.01},{"price":11610000.0,"size":0.302},{"price":11611109.0,"size":0.01},{"price":11613321.0,"size":0.01},{"price":11620000.0,"size":1.35441682},{"price":11621011.0,"size":0.01},{"price":11621109.0,"size":0.01},{"price":11623096.0,"size":0.008},{"price":11625703.0,"size":0.012},{"price":11629000.0,"size":0.1},{"price":11630000.0,"size":0.201},{"price":11631059.0,"size":0.01},{"price":11631479.0,"size":0.01},{"price":11631773.0,"size":0.00386871},{"price":11635950.0,"size":0.001},{"price":11638259.0,"size":0.001},{"price":11639700.0,"size":0.001},{"price":11640000.0,"size":1.0},{"price":11640820.0,"size":0.01},{"price":11649900.0,"size":0.02906},{"price":11649999.0,"size":0.001},{"price":11650000.0,"size":0.593},{"price":11651059.0,"size":0.01},{"price":11653658.0,"size":0.008},{"price":11654321.0,"size":0.001},{"price":11659700.0,"size":0.001},{"price":11661479.0,"size":0.01},{"price":11666000.0,"size":0.001},{"price":11666666.0,"size":0.013},{"price":11669700.0,"size":0.001},{"price":11671059.0,"size":0.01},{"price":11672562.0,"size":0.0198},{"price":11680000.0,"size":0.014},{"price":11685000.0,"size":0.003},{"price":11688000.0,"size":0.001},{"price":11689732.0,"size":0.01},{"price":11690330.0,"size":0.0198},{"price":11691059.0,"size":0.01},{"price":11692558.0,"size":0.01},{"price":11695019.0,"size":0.0064},{"price":11698800.0,"size":0.00131},{"price":11699000.0,"size":0.001},{"price":11699631.0,"size":0.001},{"price":11699998.0,"size":0.01},{"price":11699999.0,"size":0.001},{"price":11700000.0,"size":1.2573},{"price":11701059.0,"size":0.01},{"price":11720000.0,"size":0.1},{"price":11721059.0,"size":0.01},{"price":11725000.0,"size":0.005},{"price":11726791.0,"size":0.01},{"price":11727418.0,"size":1.8},{"price":11728195.0,"size":0.05},{"price":11730000.0,"size":1.9712},{"price":11740000.0,"size":0.101},{"price":11741059.0,"size":0.01},{"price":11748937.0,"size":0.001},{"price":11749999.0,"size":0.001},{"price":11750000.0,"size":0.89537866},{"price":11750050.0,"size":0.2},{"price":11751151.0,"size":0.01},{"price":11751406.0,"size":0.012},{"price":11755000.0,"size":0.001},{"price":11757860.0,"size":1.82},{"price":11759999.0,"size":0.001},{"price":11760000.0,"size":0.001},{"price":11761059.0,"size":0.02},{"price":11765432.0,"size":0.001},{"price":11768000.0,"size":0.01},{"price":11770000.0,"size":0.25464896},{"price":11771059.0,"size":0.01755555},{"price":11772000.0,"size":0.002},{"price":11775000.0,"size":0.11593},{"price":11775222.0,"size":0.001657},{"price":11775577.0,"size":0.00013523},{"price":11775800.0,"size":0.001},{"price":11775900.0,"size":0.2},{"price":11775989.0,"size":0.005},{"price":11777000.0,"size":0.5956},{"price":11777777.0,"size":0.0067},{"price":11778541.0,"size":0.001},{"price":11779807.0,"size":0.001},{"price":11780000.0,"size":0.74298},{"price":11780800.0,"size":0.1},{"price":11781059.0,"size":0.01},{"price":11781238.0,"size":0.008},{"price":11785000.0,"size":0.055},{"price":11785040.0,"size":0.01},{"price":11786000.0,"size":0.585},{"price":11788000.0,"size":0.001},{"price":11788888.0,"size":0.005},{"price":11789000.0,"size":0.2},{"price":11789732.0,"size":0.01},{"price":11791100.0,"size":0.1},{"price":11791151.0,"size":0.01},{"price":11795000.0,"size":0.021},{"price":11795040.0,"size":0.015},{"price":11796103.0,"size":0.01},{"price":11798800.0,"size":0.005},{"price":11798950.0,"size":0.001},{"price":11799000.0,"size":0.013},{"price":11799510.0,"size":0.001},{"price":11799639.0,"size":0.01},{"price":11799999.0,"size":0.00769493},{"price":11800000.0,"size":1.10095},{"price":11800050.0,"size":0.006}]}}}
{"schema_version":"collector.vnext.raw","schema_contract":null,"schema_contract_version":null,"payload_contract_version":null,"record_type":"market.orderbook.diff","record_id":"collector_main-market-orderbook-diff-000000000061","collector_id":"collector_main","collector_role":"production","host_name":"MAIN-PC","session_id":"collector_main-sess-20260315T000405Z-4c23736a","stream_session_id":"collector_main-stream-bitflyer-board_ws-20260315T000418Z-39c07a69","exchange":"bitflyer","market":"spot","symbol":"BTC_JPY","instrument_id":"bitflyer.spot.BTC_JPY","channel":"board_ws","transport":"websocket","source_event_id":null,"source_sequence":null,"sequence_id":61,"exchange_ts":null,"collector_ts":"2026-03-15T00:04:18Z","ingest_ts":"2026-03-15T00:04:18Z","event_ts":"2026-03-15T00:04:18Z","quality_flags":[],"is_partial":false,"is_reconstructed":false,"confidence_score":1.0,"payload":{"provider":"bitflyer_ws_board","exchange":"bitflyer","transport":"websocket","channel":"lightning_board_BTC_JPY","received_ts":"2026-03-15T00:04:18.703394Z","subscription_id":null,"message_id":null,"source_sequence":null,"raw_message_meta":{"raw_channel":"lightning_board_BTC_JPY","subscription_channel":"lightning_board_BTC_JPY","recv_timeout_sec":10,"ssl_verify":false,"socket_url":"wss://ws.lightstream.bitflyer.com/json-rpc"},"source_payload":{"mid_price":11377885.0,"bids":[{"price":11371715.0,"size":0.0}],"asks":[{"price":11380908.0,"size":0.0},{"price":11381272.0,"size":0.0}]}}}
{"schema_version":"collector.vnext.raw","schema_contract":null,"schema_contract_version":null,"payload_contract_version":null,"record_type":"market.orderbook.diff","record_id":"collector_main-market-orderbook-diff-000000000065","collector_id":"collector_main","collector_role":"production","host_name":"MAIN-PC","session_id":"collector_main-sess-20260315T000405Z-4c23736a","stream_session_id":"collector_main-stream-bitflyer-board_ws-20260315T000418Z-39c07a69","exchange":"bitflyer","market":"spot","symbol":"BTC_JPY","instrument_id":"bitflyer.spot.BTC_JPY","channel":"board_ws","transport":"websocket","source_event_id":null,"source_sequence":null,"sequence_id":65,"exchange_ts":null,"collector_ts":"2026-03-15T00:04:18Z","ingest_ts":"2026-03-15T00:04:18Z","event_ts":"2026-03-15T00:04:18Z","quality_flags":[],"is_partial":false,"is_reconstructed":false,"confidence_score":1.0,"payload":{"provider":"bitflyer_ws_board","exchange":"bitflyer","transport":"websocket","channel":"lightning_board_BTC_JPY","received_ts":"2026-03-15T00:04:18.918565Z","subscription_id":null,"message_id":null,"source_sequence":null,"raw_message_meta":{"raw_channel":"lightning_board_BTC_JPY","subscription_channel":"lightning_board_BTC_JPY","recv_timeout_sec":10,"ssl_verify":false,"socket_url":"wss://ws.lightstream.bitflyer.com/json-rpc"},"source_payload":{"mid_price":11377885.0,"bids":[],"asks":[{"price":11381271.0,"size":0.0}]}}}
{"schema_version":"collector.vnext.raw","schema_contract":null,"schema_contract_version":null,"payload_contract_version":null,"record_type":"market.orderbook.diff","record_id":"collector_main-market-orderbook-diff-000000000067","collector_id":"collector_main","collector_role":"production","host_name":"MAIN-PC","session_id":"collector_main-sess-20260315T000405Z-4c23736a","stream_session_id":"collector_main-stream-bitflyer-board_ws-20260315T000418Z-39c07a69","exchange":"bitflyer","market":"spot","symbol":"BTC_JPY","instrument_id":"bitflyer.spot.BTC_JPY","channel":"board_ws","transport":"websocket","source_event_id":null,"source_sequence":null,"sequence_id":67,"exchange_ts":null,"collector_ts":"2026-03-15T00:04:19Z","ingest_ts":"2026-03-15T00:04:19Z","event_ts":"2026-03-15T00:04:19Z","quality_flags":[],"is_partial":false,"is_reconstructed":false,"confidence_score":1.0,"payload":{"provider":"bitflyer_ws_board","exchange":"bitflyer","transport":"websocket","channel":"lightning_board_BTC_JPY","received_ts":"2026-03-15T00:04:19.046993Z","subscription_id":null,"message_id":null,"source_sequence":null,"raw_message_meta":{"raw_channel":"lightning_board_BTC_JPY","subscription_channel":"lightning_board_BTC_JPY","recv_timeout_sec":10,"ssl_verify":false,"socket_url":"wss://ws.lightstream.bitflyer.com/json-rpc"},"source_payload":{"mid_price":11377885.0,"bids":[{"price":11371716.0,"size":0.0}],"asks":[{"price":11380873.0,"size":0.0},{"price":11382107.0,"size":0.04915083},{"price":11391370.0,"size":0.0}]}}}
{"schema_version":"collector.vnext.raw","schema_contract":null,"schema_contract_version":null,"payload_contract_version":null,"record_type":"market.orderbook.diff","record_id":"collector_main-market-orderbook-diff-000000000069","collector_id":"collector_main","collector_role":"production","host_name":"MAIN-PC","session_id":"collector_main-sess-20260315T000405Z-4c23736a","stream_session_id":"collector_main-stream-bitflyer-board_ws-20260315T000418Z-39c07a69","exchange":"bitflyer","market":"spot","symbol":"BTC_JPY","instrument_id":"bitflyer.spot.BTC_JPY","channel":"board_ws","transport":"websocket","source_event_id":null,"source_sequence":null,"sequence_id":69,"exchange_ts":null,"collector_ts":"2026-03-15T00:04:19Z","ingest_ts":"2026-03-15T00:04:19Z","event_ts":"2026-03-15T00:04:19Z","quality_flags":[],"is_partial":false,"is_reconstructed":false,"confidence_score":1.0,"payload":{"provider":"bitflyer_ws_board","exchange":"bitflyer","transport":"websocket","channel":"lightning_board_BTC_JPY","received_ts":"2026-03-15T00:04:19.159348Z","subscription_id":null,"message_id":null,"source_sequence":null,"raw_message_meta":{"raw_channel":"lightning_board_BTC_JPY","subscription_channel":"lightning_board_BTC_JPY","recv_timeout_sec":10,"ssl_verify":false,"socket_url":"wss://ws.lightstream.bitflyer.com/json-rpc"},"source_payload":{"mid_price":11377885.0,"bids":[],"asks":[{"price":11391371.0,"size":0.2}]}}}
{"schema_version":"collector.vnext.raw","schema_contract":null,"schema_contract_version":null,"payload_contract_version":null,"record_type":"market.orderbook.diff","record_id":"collector_main-market-orderbook-diff-000000000071","collector_id":"collector_main","collector_role":"production","host_name":"MAIN-PC","session_id":"collector_main-sess-20260315T000405Z-4c23736a","stream_session_id":"collector_main-stream-bitflyer-board_ws-20260315T000418Z-39c07a69","exchange":"bitflyer","market":"spot","symbol":"BTC_JPY","instrument_id":"bitflyer.spot.BTC_JPY","channel":"board_ws","transport":"websocket","source_event_id":null,"source_sequence":null,"sequence_id":71,"exchange_ts":null,"collector_ts":"2026-03-15T00:04:19Z","ingest_ts":"2026-03-15T00:04:19Z","event_ts":"2026-03-15T00:04:19Z","quality_flags":[],"is_partial":false,"is_reconstructed":false,"confidence_score":1.0,"payload":{"provider":"bitflyer_ws_board","exchange":"bitflyer","transport":"websocket","channel":"lightning_board_BTC_JPY","received_ts":"2026-03-15T00:04:19.394899Z","subscription_id":null,"message_id":null,"source_sequence":null,"raw_message_meta":{"raw_channel":"lightning_board_BTC_JPY","subscription_channel":"lightning_board_BTC_JPY","recv_timeout_sec":10,"ssl_verify":false,"socket_url":"wss://ws.lightstream.bitflyer.com/json-rpc"},"source_payload":{"mid_price":11377885.0,"bids":[],"asks":[{"price":11382072.0,"size":0.0175679}]}}}
{"schema_version":"collector.vnext.raw","schema_contract":null,"schema_contract_version":null,"payload_contract_version":null,"record_type":"market.orderbook.diff","record_id":"collector_main-market-orderbook-diff-000000000073","collector_id":"collector_main","collector_role":"production","host_name":"MAIN-PC","session_id":"collector_main-sess-20260315T000405Z-4c23736a","stream_session_id":"collector_main-stream-bitflyer-board_ws-20260315T000418Z-39c07a69","exchange":"bitflyer","market":"spot","symbol":"BTC_JPY","instrument_id":"bitflyer.spot.BTC_JPY","channel":"board_ws","transport":"websocket","source_event_id":null,"source_sequence":null,"sequence_id":73,"exchange_ts":null,"collector_ts":"2026-03-15T00:04:19Z","ingest_ts":"2026-03-15T00:04:19Z","event_ts":"2026-03-15T00:04:19Z","quality_flags":[],"is_partial":false,"is_reconstructed":false,"confidence_score":1.0,"payload":{"provider":"bitflyer_ws_board","exchange":"bitflyer","transport":"websocket","channel":"lightning_board_BTC_JPY","received_ts":"2026-03-15T00:04:19.618454Z","subscription_id":null,"message_id":null,"source_sequence":null,"raw_message_meta":{"raw_channel":"lightning_board_BTC_JPY","subscription_channel":"lightning_board_BTC_JPY","recv_timeout_sec":10,"ssl_verify":false,"socket_url":"wss://ws.lightstream.bitflyer.com/json-rpc"},"source_payload":{"mid_price":11377885.0,"bids":[],"asks":[{"price":11382107.0,"size":0.0}]}}}
{"schema_version":"collector.vnext.raw","schema_contract":null,"schema_contract_version":null,"payload_contract_version":null,"record_type":"market.orderbook.diff","record_id":"collector_main-market-orderbook-diff-000000000075","collector_id":"collector_main","collector_role":"production","host_name":"MAIN-PC","session_id":"collector_main-sess-20260315T000405Z-4c23736a","stream_session_id":"collector_main-stream-bitflyer-board_ws-20260315T000418Z-39c07a69","exchange":"bitflyer","market":"spot","symbol":"BTC_JPY","instrument_id":"bitflyer.spot.BTC_JPY","channel":"board_ws","transport":"websocket","source_event_id":null,"source_sequence":null,"sequence_id":75,"exchange_ts":null,"collector_ts":"2026-03-15T00:04:19Z","ingest_ts":"2026-03-15T00:04:19Z","event_ts":"2026-03-15T00:04:19Z","quality_flags":[],"is_partial":false,"is_reconstructed":false,"confidence_score":1.0,"payload":{"provider":"bitflyer_ws_board","exchange":"bitflyer","transport":"websocket","channel":"lightning_board_BTC_JPY","received_ts":"2026-03-15T00:04:19.719440Z","subscription_id":null,"message_id":null,"source_sequence":null,"raw_message_meta":{"raw_channel":"lightning_board_BTC_JPY","subscription_channel":"lightning_board_BTC_JPY","recv_timeout_sec":10,"ssl_verify":false,"socket_url":"wss://ws.lightstream.bitflyer.com/json-rpc"},"source_payload":{"mid_price":11377885.0,"bids":[],"asks":[{"price":11382071.0,"size":0.05277953}]}}}
{"schema_version":"collector.vnext.raw","schema_contract":null,"schema_contract_version":null,"payload_contract_version":null,"record_type":"market.orderbook.diff","record_id":"collector_main-market-orderbook-diff-000000000077","collector_id":"collector_main","collector_role":"production","host_name":"MAIN-PC","session_id":"collector_main-sess-20260315T000405Z-4c23736a","stream_session_id":"collector_main-stream-bitflyer-board_ws-20260315T000418Z-39c07a69","exchange":"bitflyer","market":"spot","symbol":"BTC_JPY","instrument_id":"bitflyer.spot.BTC_JPY","channel":"board_ws","transport":"websocket","source_event_id":null,"source_sequence":null,"sequence_id":77,"exchange_ts":null,"collector_ts":"2026-03-15T00:04:19Z","ingest_ts":"2026-03-15T00:04:19Z","event_ts":"2026-03-15T00:04:19Z","quality_flags":[],"is_partial":false,"is_reconstructed":false,"confidence_score":1.0,"payload":{"provider":"bitflyer_ws_board","exchange":"bitflyer","transport":"websocket","channel":"lightning_board_BTC_JPY","received_ts":"2026-03-15T00:04:19.892538Z","subscription_id":null,"message_id":null,"source_sequence":null,"raw_message_meta":{"raw_channel":"lightning_board_BTC_JPY","subscription_channel":"lightning_board_BTC_JPY","recv_timeout_sec":10,"ssl_verify":false,"socket_url":"wss://ws.lightstream.bitflyer.com/json-rpc"},"source_payload":{"mid_price":11377885.0,"bids":[{"price":11371627.0,"size":0.0877}],"asks":[{"price":11381299.0,"size":0.1275}]}}}
{"schema_version":"collector.vnext.raw","schema_contract":null,"schema_contract_version":null,"payload_contract_version":null,"record_type":"market.orderbook.diff","record_id":"collector_main-market-orderbook-diff-000000000079","collector_id":"collector_main","collector_role":"production","host_name":"MAIN-PC","session_id":"collector_main-sess-20260315T000405Z-4c23736a","stream_session_id":"collector_main-stream-bitflyer-board_ws-20260315T000418Z-39c07a69","exchange":"bitflyer","market":"spot","symbol":"BTC_JPY","instrument_id":"bitflyer.spot.BTC_JPY","channel":"board_ws","transport":"websocket","source_event_id":null,"source_sequence":null,"sequence_id":79,"exchange_ts":null,"collector_ts":"2026-03-15T00:04:20Z","ingest_ts":"2026-03-15T00:04:20Z","event_ts":"2026-03-15T00:04:20Z","quality_flags":[],"is_partial":false,"is_reconstructed":false,"confidence_score":1.0,"payload":{"provider":"bitflyer_ws_board","exchange":"bitflyer","transport":"websocket","channel":"lightning_board_BTC_JPY","received_ts":"2026-03-15T00:04:20.169676Z","subscription_id":null,"message_id":null,"source_sequence":null,"raw_message_meta":{"raw_channel":"lightning_board_BTC_JPY","subscription_channel":"lightning_board_BTC_JPY","recv_timeout_sec":10,"ssl_verify":false,"socket_url":"wss://ws.lightstream.bitflyer.com/json-rpc"},"source_payload":{"mid_price":11377885.0,"bids":[],"asks":[{"price":11381298.0,"size":0.04511532},{"price":11381299.0,"size":0.0},{"price":11380730.0,"size":0.1275},{"price":11382071.0,"size":0.0}]}}}
{"schema_version":"collector.vnext.raw","schema_contract":null,"schema_contract_version":null,"payload_contract_version":null,"record_type":"market.orderbook.snapshot","record_id":"collector_main-market-orderbook-snapshot-000000000081","collector_id":"collector_main","collector_role":"production","host_name":"MAIN-PC","session_id":"collector_main-sess-20260315T000405Z-4c23736a","stream_session_id":"collector_main-stream-bitflyer-board_ws-20260315T000418Z-39c07a69","exchange":"bitflyer","market":"spot","symbol":"BTC_JPY","instrument_id":"bitflyer.spot.BTC_JPY","channel":"board_ws","transport":"websocket","source_event_id":null,"source_sequence":null,"sequence_id":81,"exchange_ts":null,"collector_ts":"2026-03-15T00:04:20Z","ingest_ts":"2026-03-15T00:04:20Z","event_ts":"2026-03-15T00:04:20Z","quality_flags":[],"is_partial":false,"is_reconstructed":false,"confidence_score":1.0,"payload":{"provider":"bitflyer_ws_board_snapshot","exchange":"bitflyer","transport":"websocket","channel":"lightning_board_snapshot_BTC_JPY","received_ts":"2026-03-15T00:04:20.398696Z","subscription_id":null,"message_id":null,"source_sequence":null,"raw_message_meta":{"raw_channel":"lightning_board_snapshot_BTC_JPY","subscription_channel":"lightning_board_snapshot_BTC_JPY","recv_timeout_sec":10,"ssl_verify":false,"socket_url":"wss://ws.lightstream.bitflyer.com/json-rpc"},"source_payload":{"mid_price":11377885.0,"bids":[{"price":11376423.0,"size":0.09},{"price":11375439.0,"size":0.005},{"price":11374878.0,"size":0.02},{"price":11374877.0,"size":0.14061},{"price":11374719.0,"size":0.00999792},{"price":11373370.0,"size":0.015},{"price":11372841.0,"size":0.014592},{"price":11371901.0,"size":0.02},{"price":11371900.0,"size":0.005},{"price":11371627.0,"size":0.0877},{"price":11371587.0,"size":0.02},{"price":11371380.0,"size":0.02},{"price":11371146.0,"size":0.02},{"price":11371145.0,"size":0.014592},{"price":11370998.0,"size":0.26595698},{"price":11370805.0,"size":0.014556},{"price":11370724.0,"size":0.2},{"price":11370049.0,"size":0.5},{"price":11370000.0,"size":0.015},{"price":11368516.0,"size":0.0526176},{"price":11368376.0,"size":0.01},{"price":11368353.0,"size":0.01},{"price":11366248.0,"size":3.11638806},{"price":11366247.0,"size":0.036},{"price":11366008.0,"size":0.04},{"price":11364930.0,"size":0.0527},{"price":11363829.0,"size":0.01},{"price":11362277.0,"size":0.9772867},{"price":11362045.0,"size":0.05},{"price":11361538.0,"size":1.50015},{"price":11361476.0,"size":0.05},{"price":11360557.0,"size":0.25},{"price":11358376.0,"size":0.01},{"price":11354042.0,"size":0.2872},{"price":11353488.0,"size":0.27174084},{"price":11351280.0,"size":0.2739},{"price":11350744.0,"size":0.002},{"price":11350000.0,"size":0.51},{"price":11348518.0,"size":0.2616},{"price":11348189.0,"size":0.003},{"price":11347667.0,"size":0.001},{"price":11347661.0,"size":0.6},{"price":11346193.0,"size":0.002},{"price":11345756.0,"size":0.267},{"price":11345154.0,"size":1.484},{"price":11341672.0,"size":0.05739971},{"price":11341671.0,"size":0.23},{"price":11341642.0,"size":0.002},{"price":11340000.0,"size":0.005},{"price":11337091.0,"size":0.002},{"price":11336383.0,"size":0.001},{"price":11336319.0,"size":0.00195},{"price":11332540.0,"size":0.002},{"price":11331227.0,"size":0.51},{"price":11331000.0,"size":0.5},{"price":11330000.0,"size":0.02442},{"price":11327989.0,"size":0.002},{"price":11325101.0,"size":0.001},{"price":11323438.0,"size":0.002},{"price":11320000.0,"size":0.05},{"price":11318887.0,"size":0.002},{"price":11315000.0,"size":0.05},{"price":11314336.0,"size":0.002},{"price":11314325.0,"size":1.951},{"price":11313996.0,"size":0.00195},{"price":11313819.0,"size":0.001},{"price":11310000.0,"size":0.01},{"price":11309999.0,"size":0.177},{"price":11309785.0,"size":0.002},{"price":11309119.0,"size":1.966},{"price":11307999.0,"size":0.01},{"price":11303918.0,"size":0.01},{"price":11303430.0,"size":2.036},{"price":11303000.0,"size":0.5},{"price":11302535.0,"size":0.001},{"price":11302466.0,"size":0.001},{"price":11301268.0,"size":0.01},{"price":11300000.0,"size":3.01685256},{"price":11298000.0,"size":0.01},{"price":11296865.0,"size":0.0015},{"price":11294756.0,"size":1.0},{"price":11291282.0,"size":0.001},{"price":11291268.0,"size":0.01},{"price":11291000.0,"size":0.5},{"price":11290000.0,"size":0.003},{"price":11281268.0,"size":0.01},{"price":11280000.0,"size":0.0163},{"price":11279960.0,"size":0.001},{"price":11279282.0,"size":0.0015},{"price":11278000.0,"size":0.0025},{"price":11275000.0,"size":0.001},{"price":11274588.0,"size":0.0047},{"price":11271268.0,"size":0.01},{"price":11271000.0,"size":0.003},{"price":11270000.0,"size":0.106},{"price":11269424.0,"size":0.8},{"price":11268871.0,"size":0.28},{"price":11268638.0,"size":0.001},{"price":11268411.0,"size":0.01},{"price":11266666.0,"size":0.04},{"price":11265000.0,"size":0.02},{"price":11263000.0,"size":0.006},{"price":11262564.0,"size":0.0015},{"price":11261268.0,"size":0.01},{"price":11260000.0,"size":0.3565},{"price":11257315.0,"size":0.001},{"price":11257000.0,"size":0.001},{"price":11255200.0,"size":0.001},{"price":11255115.0,"size":0.00377},{"price":11253814.0,"size":2.2},{"price":11253690.0,"size":0.01},{"price":11253000.0,"size":0.03189},{"price":11251405.0,"size":0.139},{"price":11251268.0,"size":0.01},{"price":11251111.0,"size":0.0015},{"price":11251000.0,"size":0.0131},{"price":11250250.0,"size":0.00105},{"price":11250200.0,"size":0.001},{"price":11250005.0,"size":0.001},{"price":11250001.0,"size":0.00104},{"price":11250000.0,"size":1.62712889},{"price":11245993.0,"size":0.001},{"price":11245141.0,"size":0.0031},{"price":11245000.0,"size":0.05},{"price":11244444.0,"size":0.04},{"price":11244243.0,"size":0.01},{"price":11240200.0,"size":0.001},{"price":11240000.0,"size":0.007304},{"price":11236190.0,"size":0.01},{"price":11235200.0,"size":0.001},{"price":11234670.0,"size":0.001},{"price":11232000.0,"size":0.089},{"price":11231243.0,"size":0.01},{"price":11231000.0,"size":0.105},{"price":11230200.0,"size":0.001},{"price":11230000.0,"size":0.0308},{"price":11226952.0,"size":0.972},{"price":11224500.0,"size":0.06},{"price":11223968.0,"size":0.001},{"price":11223348.0,"size":0.001},{"price":11223344.0,"size":0.01},{"price":11223000.0,"size":0.1},{"price":11222222.0,"size":0.093525},{"price":11221120.0,"size":0.001},{"price":11220200.0,"size":0.001},{"price":11220001.0,"size":0.004457},{"price":11220000.0,"size":0.321},{"price":11219000.0,"size":0.1},{"price":11217326.0,"size":0.02},{"price":11215200.0,"size":0.001},{"price":11213690.0,"size":0.01},{"price":11212025.0,"size":0.001},{"price":11211800.0,"size":0.001},{"price":11211111.0,"size":0.06},{"price":11210200.0,"size":0.001},{"price":11210000.0,"size":0.10622},{"price":11208032.0,"size":0.01},{"price":11206000.0,"size":0.09015},{"price":11205200.0,"size":0.001},{"price":11204578.0,"size":0.002},{"price":11201000.0,"size":0.01},{"price":11200800.0,"size":0.05},{"price":11200703.0,"size":0.001},{"price":11200425.0,"size":0.1},{"price":11200200.0,"size":0.001},{"price":11200198.0,"size":0.003},{"price":11200150.0,"size":0.002},{"price":11200002.0,"size":0.001},{"price":11200001.0,"size":0.01104},{"price":11200000.0,"size":1.15226728},{"price":11198508.0,"size":0.05},{"price":11198243.0,"size":0.01},{"price":11197134.0,"size":0.993},{"price":11197000.0,"size":0.0085},{"price":11194090.0,"size":0.03},{"price":11190770.0,"size":0.0309},{"price":11190000.0,"size":0.0010016},{"price":11189555.0,"size":0.5},{"price":11189381.0,"size":0.001},{"price":11188629.0,"size":0.01},{"price":11188382.0,"size":0.001},{"price":11185000.0,"size":0.0085},{"price":11180000.0,"size":0.225},{"price":11178058.0,"size":0.001},{"price":11170000.0,"size":0.001},{"price":11169662.0,"size":0.01},{"price":11169593.0,"size":0.001},{"price":11169243.0,"size":0.01},{"price":11166736.0,"size":0.001},{"price":11164029.0,"size":0.001},{"price":11160854.0,"size":0.1},{"price":11160000.0,"size":0.02376},{"price":11155413.0,"size":0.001},{"price":11155377.0,"size":0.00636009},{"price":11153999.0,"size":0.00101},{"price":11151000.0,"size":0.001},{"price":11150250.0,"size":0.00175},{"price":11150005.0,"size":0.001},{"price":11150001.0,"size":0.00104},{"price":11150000.0,"size":0.6533956},{"price":11148000.0,"size":0.08963},{"price":11147546.0,"size":0.02},{"price":11144091.0,"size":0.001},{"price":11144000.0,"size":0.0897},{"price":11143986.0,"size":0.02},{"price":11140139.0,"size":1.0},{"price":11140000.0,"size":0.2},{"price":11136243.0,"size":0.01},{"price":11135869.0,"size":0.1},{"price":11132768.0,"size":0.001},{"price":11130000.0,"size":0.116},{"price":11129979.0,"size":0.0053908},{"price":11124900.0,"size":0.00133},{"price":11121090.0,"size":0.1},{"price":11120000.0,"size":0.0033},{"price":11118078.0,"size":0.01},{"price":11111800.0,"size":0.001},{"price":11111111.0,"size":0.2919257},{"price":11111000.0,"size":0.003},{"price":11110594.0,"size":0.001},{"price":11110000.0,"size":0.021007},{"price":11109662.0,"size":0.01},{"price":11108008.0,"size":0.01},{"price":11102000.0,"size":0.5},{"price":11101297.0,"size":0.001},{"price":11100005.0,"size":0.001},{"price":11100001.0,"size":0.01104},{"price":11100000.0,"size":1.6532049},{"price":11099141.0,"size":0.01},{"price":11098833.0,"size":0.002},{"price":11096243.0,"size":0.01},{"price":11094090.0,"size":0.01},{"price":11088888.0,"size":0.001},{"price":11085245.0,"size":0.001},{"price":11080200.0,"size":0.001},{"price":11080000.0,"size":0.0223},{"price":11075100.0,"size":0.003},{"price":11070200.0,"size":0.001},{"price":11070000.0,"size":0.0902},{"price":11065200.0,"size":0.001},{"price":11064370.0,"size":0.00497091},{"price":11060200.0,"size":0.001},{"price":11060000.0,"size":0.145},{"price":11059689.0,"size":0.009},{"price":11056428.0,"size":0.002},{"price":11055500.0,"size":0.02},{"price":11055200.0,"size":0.001},{"price":11055100.0,"size":0.003},{"price":11050200.0,"size":0.001},{"price":11050005.0,"size":0.001},{"price":11050002.0,"size":0.001},{"price":11050001.0,"size":0.00104},{"price":11050000.0,"size":0.39576147},{"price":11048064.0,"size":2.0},{"price":11046420.0,"size":0.2},{"price":11044243.0,"size":0.01},{"price":11041380.0,"size":0.01},{"price":11040200.0,"size":0.001},{"price":11040000.0,"size":0.00777181},{"price":11035865.0,"size":0.1},{"price":11035200.0,"size":0.001},{"price":11035000.0,"size":0.0013},{"price":11030200.0,"size":0.001},{"price":11030000.0,"size":0.025},{"price":11025500.0,"size":0.009531},{"price":11025200.0,"size":0.001},{"price":11025000.0,"size":0.71497},{"price":11020772.0,"size":0.014},{"price":11020200.0,"size":0.002},{"price":11020000.0,"size":0.005},{"price":11015200.0,"size":0.001},{"price":11012000.0,"size":0.1},{"price":11011800.0,"size":0.001},{"price":11010200.0,"size":0.001},{"price":11010000.0,"size":0.347},{"price":11007277.0,"size":0.01},{"price":11005200.0,"size":0.001},{"price":11004890.0,"size":0.001535},{"price":11003000.0,"size":0.0155},{"price":11001000.0,"size":0.013},{"price":11000500.0,"size":0.05117658},{"price":11000200.0,"size":0.001},{"price":11000002.0,"size":0.004},{"price":11000001.0,"size":0.02604},{"price":11000000.0,"size":4.53923365},{"price":10999999.0,"size":0.003},{"price":10999000.0,"size":0.001},{"price":10996855.0,"size":0.0011},{"price":10995200.0,"size":0.001},{"price":10994499.0,"size":0.00169176},{"price":10990200.0,"size":0.001},{"price":10990000.0,"size":0.10219},{"price":10989001.0,"size":0.00197},{"price":10988999.0,"size":0.001},{"price":10988324.0,"size":0.002},{"price":10987654.0,"size":0.001},{"price":10985200.0,"size":0.001},{"price":10985150.0,"size":0.01},{"price":10980500.0,"size":0.005},{"price":10980200.0,"size":0.001}],"asks":[{"price":11379347.0,"size":0.08064963},{"price":11380724.0,"size":0.014892},{"price":11382108.0,"size":0.02},{"price":11382109.0,"size":0.301},{"price":11382142.0,"size":0.01001785},{"price":11382750.0,"size":0.234},{"price":11383854.0,"size":0.015},{"price":11384871.0,"size":0.2657},{"price":11385094.0,"size":0.01},{"price":11385583.0,"size":0.0526176},{"price":11387173.0,"size":0.57248225},{"price":11387174.0,"size":0.1},{"price":11387205.0,"size":0.05},{"price":11387633.0,"size":0.2976},{"price":11387773.0,"size":0.0484},{"price":11389573.0,"size":0.0044},{"price":11390395.0,"size":0.2948},{"price":11391371.0,"size":0.2},{"price":11391432.0,"size":0.4249},{"price":11392010.0,"size":0.00142446},{"price":11393747.0,"size":1.189881},{"price":11394441.0,"size":1.189881},{"price":11394975.0,"size":0.0526},{"price":11397000.0,"size":0.02},{"price":11398444.0,"size":0.001995},{"price":11398845.0,"size":0.001},{"price":11399673.0,"size":0.0015},{"price":11399700.0,"size":0.001},{"price":11399999.0,"size":0.05},{"price":11400000.0,"size":0.64832841},{"price":11403472.0,"size":0.002},{"price":11405000.0,"size":0.1575},{"price":11408699.0,"size":1.15098095},{"price":11408700.0,"size":0.001},{"price":11409415.0,"size":0.005},{"price":11409925.0,"size":0.22},{"price":11410000.0,"size":0.3787},{"price":11410168.0,"size":0.001},{"price":11410853.0,"size":0.002},{"price":11412000.0,"size":0.0878},{"price":11415000.0,"size":0.1},{"price":11415141.0,"size":0.0041},{"price":11417481.0,"size":0.0015},{"price":11418700.0,"size":0.001},{"price":11419000.0,"size":0.01},{"price":11420000.0,"size":0.261},{"price":11421268.0,"size":0.05},{"price":11421490.0,"size":0.001},{"price":11424296.0,"size":0.002},{"price":11425000.0,"size":0.029},{"price":11426426.0,"size":0.002},{"price":11428121.0,"size":0.002},{"price":11428700.0,"size":0.001},{"price":11429302.0,"size":0.01},{"price":11430000.0,"size":0.4098},{"price":11431675.0,"size":1.489},{"price":11432718.0,"size":0.002},{"price":11432813.0,"size":0.001},{"price":11433211.0,"size":0.03},{"price":11433333.0,"size":0.001},{"price":11437315.0,"size":0.002},{"price":11438525.0,"size":0.0011},{"price":11438700.0,"size":0.001},{"price":11439557.0,"size":0.001},{"price":11440000.0,"size":0.2538},{"price":11441911.0,"size":0.002},{"price":11442627.0,"size":2.018},{"price":11443629.0,"size":0.002},{"price":11444135.0,"size":0.001},{"price":11445433.0,"size":0.0015},{"price":11446508.0,"size":0.001},{"price":11447000.0,"size":0.01},{"price":11447071.0,"size":0.002},{"price":11448000.0,"size":0.0875},{"price":11448700.0,"size":0.001},{"price":11448747.0,"size":1.928},{"price":11450000.0,"size":0.268},{"price":11451105.0,"size":0.002},{"price":11453321.0,"size":0.03},{"price":11455000.0,"size":0.001},{"price":11455457.0,"size":0.001},{"price":11455702.0,"size":0.002},{"price":11458700.0,"size":0.001},{"price":11458988.0,"size":0.01},{"price":11460000.0,"size":0.06702},{"price":11460299.0,"size":0.002},{"price":11463288.0,"size":0.01},{"price":11464896.0,"size":0.002},{"price":11465382.0,"size":0.00195},{"price":11465421.0,"size":1.943},{"price":11466780.0,"size":0.001},{"price":11468700.0,"size":0.001},{"price":11470000.0,"size":0.06},{"price":11471000.0,"size":0.01},{"price":11475000.0,"size":0.0028},{"price":11476929.0,"size":1.0},{"price":11478102.0,"size":0.001},{"price":11478431.0,"size":0.002},{"price":11478700.0,"size":0.001},{"price":11480000.0,"size":0.40191},{"price":11485000.0,"size":0.01},{"price":11485488.0,"size":2.0},{"price":11486555.0,"size":0.03},{"price":11487685.0,"size":0.01},{"price":11488000.0,"size":0.102},{"price":11488700.0,"size":0.001},{"price":11489425.0,"size":0.001},{"price":11490000.0,"size":0.05},{"price":11490841.0,"size":0.002},{"price":11495450.0,"size":0.002},{"price":11495850.0,"size":0.001},{"price":11498700.0,"size":0.001},{"price":11498917.0,"size":0.002},{"price":11499000.0,"size":0.01},{"price":11500000.0,"size":0.77159519},{"price":11500078.0,"size":0.93},{"price":11500747.0,"size":0.001},{"price":11502377.0,"size":0.002},{"price":11502800.0,"size":0.00132},{"price":11503108.0,"size":0.0198},{"price":11505000.0,"size":0.0028},{"price":11505001.0,"size":0.002},{"price":11505836.0,"size":0.003},{"price":11508431.0,"size":0.047},{"price":11508700.0,"size":0.001},{"price":11508888.0,"size":0.02},{"price":11510000.0,"size":0.1476},{"price":11512070.0,"size":0.001},{"price":11513633.0,"size":0.08},{"price":11514332.0,"size":0.02},{"price":11518700.0,"size":0.001},{"price":11518992.0,"size":0.002},{"price":11519855.0,"size":0.01},{"price":11520000.0,"size":0.001},{"price":11522388.0,"size":0.972},{"price":11523211.0,"size":0.01},{"price":11524999.0,"size":0.001},{"price":11528700.0,"size":0.001},{"price":11529852.0,"size":0.01},{"price":11530000.0,"size":0.261},{"price":11533985.0,"size":0.002},{"price":11534084.0,"size":0.001},{"price":11535321.0,"size":0.01},{"price":11538666.0,"size":0.002},{"price":11538700.0,"size":0.001},{"price":11540000.0,"size":0.0048},{"price":11540357.0,"size":0.002},{"price":11541011.0,"size":0.005},{"price":11541109.0,"size":0.01},{"price":11544663.0,"size":0.002},{"price":11545262.0,"size":0.002},{"price":11546541.0,"size":0.01},{"price":11548144.0,"size":0.002},{"price":11548700.0,"size":0.001},{"price":11550000.0,"size":0.014},{"price":11551109.0,"size":0.01},{"price":11551625.0,"size":0.002},{"price":11552111.0,"size":0.01},{"price":11553687.0,"size":0.1},{"price":11555106.0,"size":0.002},{"price":11555115.0,"size":0.001},{"price":11556000.0,"size":0.1},{"price":11558587.0,"size":0.002},{"price":11558700.0,"size":0.001},{"price":11559855.0,"size":0.01},{"price":11560831.0,"size":0.0198},{"price":11561109.0,"size":0.01},{"price":11562000.0,"size":0.087},{"price":11562068.0,"size":0.002},{"price":11563750.0,"size":0.08739676},{"price":11565548.0,"size":0.002},{"price":11566139.0,"size":0.0228},{"price":11566551.0,"size":0.01},{"price":11568700.0,"size":0.001},{"price":11569029.0,"size":0.002},{"price":11570196.0,"size":0.002},{"price":11571109.0,"size":0.01},{"price":11572510.0,"size":0.002},{"price":11573211.0,"size":0.01},{"price":11574840.0,"size":0.002},{"price":11578700.0,"size":0.001},{"price":11579484.0,"size":0.002},{"price":11579851.0,"size":0.01},{"price":11580000.0,"size":0.7835},{"price":11581109.0,"size":0.01},{"price":11584128.0,"size":0.002},{"price":11585000.0,"size":0.002},{"price":11586532.0,"size":0.01},{"price":11587498.0,"size":0.0198},{"price":11588700.0,"size":0.001},{"price":11588800.0,"size":0.02},{"price":11590000.0,"size":0.1},{"price":11590749.0,"size":0.002},{"price":11591109.0,"size":0.01},{"price":11593211.0,"size":0.01},{"price":11596753.0,"size":0.002},{"price":11598111.0,"size":0.1474},{"price":11598555.0,"size":0.01},{"price":11598700.0,"size":0.001},{"price":11599999.0,"size":0.001},{"price":11600000.0,"size":3.655},{"price":11601109.0,"size":0.02},{"price":11603764.0,"size":0.9},{"price":11606655.0,"size":0.01},{"price":11610000.0,"size":0.302},{"price":11611109.0,"size":0.01},{"price":11613321.0,"size":0.01},{"price":11620000.0,"size":1.35441682},{"price":11621011.0,"size":0.01},{"price":11621109.0,"size":0.01},{"price":11623096.0,"size":0.008},{"price":11625703.0,"size":0.012},{"price":11629000.0,"size":0.1},{"price":11630000.0,"size":0.201},{"price":11631059.0,"size":0.01},{"price":11631479.0,"size":0.01},{"price":11631773.0,"size":0.00386871},{"price":11635950.0,"size":0.001},{"price":11638259.0,"size":0.001},{"price":11639700.0,"size":0.001},{"price":11640000.0,"size":1.0},{"price":11640820.0,"size":0.01},{"price":11649900.0,"size":0.02906},{"price":11649999.0,"size":0.001},{"price":11650000.0,"size":0.593},{"price":11651059.0,"size":0.01},{"price":11653658.0,"size":0.008},{"price":11654321.0,"size":0.001},{"price":11659700.0,"size":0.001},{"price":11661479.0,"size":0.01},{"price":11666000.0,"size":0.001},{"price":11666666.0,"size":0.013},{"price":11669700.0,"size":0.001},{"price":11671059.0,"size":0.01},{"price":11672562.0,"size":0.0198},{"price":11680000.0,"size":0.014},{"price":11685000.0,"size":0.003},{"price":11688000.0,"size":0.001},{"price":11689732.0,"size":0.01},{"price":11690330.0,"size":0.0198},{"price":11691059.0,"size":0.01},{"price":11692558.0,"size":0.01},{"price":11695019.0,"size":0.0064},{"price":11698800.0,"size":0.00131},{"price":11699000.0,"size":0.001},{"price":11699631.0,"size":0.001},{"price":11699998.0,"size":0.01},{"price":11699999.0,"size":0.001},{"price":11700000.0,"size":1.2573},{"price":11701059.0,"size":0.01},{"price":11720000.0,"size":0.1},{"price":11721059.0,"size":0.01},{"price":11725000.0,"size":0.005},{"price":11726791.0,"size":0.01},{"price":11727418.0,"size":1.8},{"price":11728195.0,"size":0.05},{"price":11730000.0,"size":1.9712},{"price":11740000.0,"size":0.101},{"price":11741059.0,"size":0.01},{"price":11748937.0,"size":0.001},{"price":11749999.0,"size":0.001},{"price":11750000.0,"size":0.89537866},{"price":11750050.0,"size":0.2},{"price":11751151.0,"size":0.01},{"price":11751406.0,"size":0.012},{"price":11755000.0,"size":0.001},{"price":11757860.0,"size":1.82},{"price":11759999.0,"size":0.001},{"price":11760000.0,"size":0.001},{"price":11761059.0,"size":0.02},{"price":11765432.0,"size":0.001},{"price":11768000.0,"size":0.01},{"price":11770000.0,"size":0.25464896},{"price":11771059.0,"size":0.01755555},{"price":11772000.0,"size":0.002},{"price":11775000.0,"size":0.11593},{"price":11775222.0,"size":0.001657},{"price":11775577.0,"size":0.00013523},{"price":11775800.0,"size":0.001},{"price":11775900.0,"size":0.2},{"price":11775989.0,"size":0.005},{"price":11777000.0,"size":0.5956},{"price":11777777.0,"size":0.0067},{"price":11778541.0,"size":0.001},{"price":11779807.0,"size":0.001},{"price":11780000.0,"size":0.74298},{"price":11780800.0,"size":0.1},{"price":11781059.0,"size":0.01},{"price":11781238.0,"size":0.008},{"price":11785000.0,"size":0.055},{"price":11785040.0,"size":0.01},{"price":11786000.0,"size":0.585},{"price":11788000.0,"size":0.001},{"price":11788888.0,"size":0.005},{"price":11789000.0,"size":0.2},{"price":11789732.0,"size":0.01},{"price":11791100.0,"size":0.1},{"price":11791151.0,"size":0.01},{"price":11795000.0,"size":0.021},{"price":11795040.0,"size":0.015}]}}}
{"schema_version":"collector.vnext.raw","schema_contract":null,"schema_contract_version":null,"payload_contract_version":null,"record_type":"market.orderbook.diff","record_id":"collector_main-market-orderbook-diff-000000000061","collector_id":"collector_main","collector_role":"production","host_name":"MAIN-PC","session_id":"collector_main-sess-20260315T000435Z-429fd61b","stream_session_id":"collector_main-stream-bitflyer-board_ws-20260315T000437Z-4e8fa7ca","exchange":"bitflyer","market":"spot","symbol":"BTC_JPY","instrument_id":"bitflyer.spot.BTC_JPY","channel":"board_ws","transport":"websocket","source_event_id":null,"source_sequence":null,"sequence_id":61,"exchange_ts":null,"collector_ts":"2026-03-15T00:04:37Z","ingest_ts":"2026-03-15T00:04:37Z","event_ts":"2026-03-15T00:04:37Z","quality_flags":[],"is_partial":false,"is_reconstructed":false,"confidence_score":1.0,"payload":{"provider":"bitflyer_ws_board","exchange":"bitflyer","transport":"websocket","channel":"lightning_board_BTC_JPY","received_ts":"2026-03-15T00:04:37.516995Z","subscription_id":null,"message_id":null,"source_sequence":null,"raw_message_meta":{"raw_channel":"lightning_board_BTC_JPY","subscription_channel":"lightning_board_BTC_JPY","recv_timeout_sec":10,"ssl_verify":false,"socket_url":"wss://ws.lightstream.bitflyer.com/json-rpc"},"source_payload":{"mid_price":11377594.0,"bids":[],"asks":[{"price":11379308.0,"size":0.19587974},{"price":11391368.0,"size":0.0},{"price":11392323.0,"size":0.0561107}]}}}
{"schema_version":"collector.vnext.raw","schema_contract":null,"schema_contract_version":null,"payload_contract_version":null,"record_type":"market.orderbook.diff","record_id":"collector_main-market-orderbook-diff-000000000065","collector_id":"collector_main","collector_role":"production","host_name":"MAIN-PC","session_id":"collector_main-sess-20260315T000435Z-429fd61b","stream_session_id":"collector_main-stream-bitflyer-board_ws-20260315T000437Z-4e8fa7ca","exchange":"bitflyer","market":"spot","symbol":"BTC_JPY","instrument_id":"bitflyer.spot.BTC_JPY","channel":"board_ws","transport":"websocket","source_event_id":null,"source_sequence":null,"sequence_id":65,"exchange_ts":null,"collector_ts":"2026-03-15T00:04:37Z","ingest_ts":"2026-03-15T00:04:37Z","event_ts":"2026-03-15T00:04:37Z","quality_flags":[],"is_partial":false,"is_reconstructed":false,"confidence_score":1.0,"payload":{"provider":"bitflyer_ws_board","exchange":"bitflyer","transport":"websocket","channel":"lightning_board_BTC_JPY","received_ts":"2026-03-15T00:04:37.659860Z","subscription_id":null,"message_id":null,"source_sequence":null,"raw_message_meta":{"raw_channel":"lightning_board_BTC_JPY","subscription_channel":"lightning_board_BTC_JPY","recv_timeout_sec":10,"ssl_verify":false,"socket_url":"wss://ws.lightstream.bitflyer.com/json-rpc"},"source_payload":{"mid_price":11377594.0,"bids":[{"price":11371627.0,"size":0.0},{"price":11363273.0,"size":0.11}],"asks":[{"price":11379308.0,"size":0.0695},{"price":11379321.0,"size":0.0}]}}}
{"schema_version":"collector.vnext.raw","schema_contract":null,"schema_contract_version":null,"payload_contract_version":null,"record_type":"market.orderbook.diff","record_id":"collector_main-market-orderbook-diff-000000000067","collector_id":"collector_main","collector_role":"production","host_name":"MAIN-PC","session_id":"collector_main-sess-20260315T000435Z-429fd61b","stream_session_id":"collector_main-stream-bitflyer-board_ws-20260315T000437Z-4e8fa7ca","exchange":"bitflyer","market":"spot","symbol":"BTC_JPY","instrument_id":"bitflyer.spot.BTC_JPY","channel":"board_ws","transport":"websocket","source_event_id":null,"source_sequence":null,"sequence_id":67,"exchange_ts":null,"collector_ts":"2026-03-15T00:04:37Z","ingest_ts":"2026-03-15T00:04:37Z","event_ts":"2026-03-15T00:04:37Z","quality_flags":[],"is_partial":false,"is_reconstructed":false,"confidence_score":1.0,"payload":{"provider":"bitflyer_ws_board","exchange":"bitflyer","transport":"websocket","channel":"lightning_board_BTC_JPY","received_ts":"2026-03-15T00:04:37.784971Z","subscription_id":null,"message_id":null,"source_sequence":null,"raw_message_meta":{"raw_channel":"lightning_board_BTC_JPY","subscription_channel":"lightning_board_BTC_JPY","recv_timeout_sec":10,"ssl_verify":false,"socket_url":"wss://ws.lightstream.bitflyer.com/json-rpc"},"source_payload":{"mid_price":11377594.0,"bids":[{"price":11364410.0,"size":0.1},{"price":11365548.0,"size":0.06}],"asks":[]}}}
{"schema_version":"collector.vnext.raw","schema_contract":null,"schema_contract_version":null,"payload_contract_version":null,"record_type":"market.orderbook.diff","record_id":"collector_main-market-orderbook-diff-000000000069","collector_id":"collector_main","collector_role":"production","host_name":"MAIN-PC","session_id":"collector_main-sess-20260315T000435Z-429fd61b","stream_session_id":"collector_main-stream-bitflyer-board_ws-20260315T000437Z-4e8fa7ca","exchange":"bitflyer","market":"spot","symbol":"BTC_JPY","instrument_id":"bitflyer.spot.BTC_JPY","channel":"board_ws","transport":"websocket","source_event_id":null,"source_sequence":null,"sequence_id":69,"exchange_ts":null,"collector_ts":"2026-03-15T00:04:37Z","ingest_ts":"2026-03-15T00:04:37Z","event_ts":"2026-03-15T00:04:37Z","quality_flags":[],"is_partial":false,"is_reconstructed":false,"confidence_score":1.0,"payload":{"provider":"bitflyer_ws_board","exchange":"bitflyer","transport":"websocket","channel":"lightning_board_BTC_JPY","received_ts":"2026-03-15T00:04:37.892755Z","subscription_id":null,"message_id":null,"source_sequence":null,"raw_message_meta":{"raw_channel":"lightning_board_BTC_JPY","subscription_channel":"lightning_board_BTC_JPY","recv_timeout_sec":10,"ssl_verify":false,"socket_url":"wss://ws.lightstream.bitflyer.com/json-rpc"},"source_payload":{"mid_price":11377594.0,"bids":[{"price":11314893.0,"size":0.0}],"asks":[{"price":11442567.0,"size":0.0},{"price":11425494.0,"size":0.0}]}}}
{"schema_version":"collector.vnext.raw","schema_contract":null,"schema_contract_version":null,"payload_contract_version":null,"record_type":"market.orderbook.diff","record_id":"collector_main-market-orderbook-diff-000000000071","collector_id":"collector_main","collector_role":"production","host_name":"MAIN-PC","session_id":"collector_main-sess-20260315T000435Z-429fd61b","stream_session_id":"collector_main-stream-bitflyer-board_ws-20260315T000437Z-4e8fa7ca","exchange":"bitflyer","market":"spot","symbol":"BTC_JPY","instrument_id":"bitflyer.spot.BTC_JPY","channel":"board_ws","transport":"websocket","source_event_id":null,"source_sequence":null,"sequence_id":71,"exchange_ts":null,"collector_ts":"2026-03-15T00:04:37Z","ingest_ts":"2026-03-15T00:04:37Z","event_ts":"2026-03-15T00:04:37Z","quality_flags":[],"is_partial":false,"is_reconstructed":false,"confidence_score":1.0,"payload":{"provider":"bitflyer_ws_board","exchange":"bitflyer","transport":"websocket","channel":"lightning_board_BTC_JPY","received_ts":"2026-03-15T00:04:37.989483Z","subscription_id":null,"message_id":null,"source_sequence":null,"raw_message_meta":{"raw_channel":"lightning_board_BTC_JPY","subscription_channel":"lightning_board_BTC_JPY","recv_timeout_sec":10,"ssl_verify":false,"socket_url":"wss://ws.lightstream.bitflyer.com/json-rpc"},"source_payload":{"mid_price":11377594.0,"bids":[{"price":11358722.0,"size":0.35},{"price":11309205.0,"size":0.0},{"price":11341752.0,"size":1.966},{"price":11330376.0,"size":2.036}],"asks":[{"price":11381297.0,"size":0.0175691},{"price":11415674.0,"size":1.928}]}}}
{"schema_version":"collector.vnext.raw","schema_contract":null,"schema_contract_version":null,"payload_contract_version":null,"record_type":"market.orderbook.diff","record_id":"collector_main-market-orderbook-diff-000000000073","collector_id":"collector_main","collector_role":"production","host_name":"MAIN-PC","session_id":"collector_main-sess-20260315T000435Z-429fd61b","stream_session_id":"collector_main-stream-bitflyer-board_ws-20260315T000437Z-4e8fa7ca","exchange":"bitflyer","market":"spot","symbol":"BTC_JPY","instrument_id":"bitflyer.spot.BTC_JPY","channel":"board_ws","transport":"websocket","source_event_id":null,"source_sequence":null,"sequence_id":73,"exchange_ts":null,"collector_ts":"2026-03-15T00:04:38Z","ingest_ts":"2026-03-15T00:04:38Z","event_ts":"2026-03-15T00:04:38Z","quality_flags":[],"is_partial":false,"is_reconstructed":false,"confidence_score":1.0,"payload":{"provider":"bitflyer_ws_board","exchange":"bitflyer","transport":"websocket","channel":"lightning_board_BTC_JPY","received_ts":"2026-03-15T00:04:38.094151Z","subscription_id":null,"message_id":null,"source_sequence":null,"raw_message_meta":{"raw_channel":"lightning_board_BTC_JPY","subscription_channel":"lightning_board_BTC_JPY","recv_timeout_sec":10,"ssl_verify":false,"socket_url":"wss://ws.lightstream.bitflyer.com/json-rpc"},"source_payload":{"mid_price":11377594.0,"bids":[],"asks":[{"price":11408363.0,"size":1.489}]}}}
{"schema_version":"collector.vnext.raw","schema_contract":null,"schema_contract_version":null,"payload_contract_version":null,"record_type":"market.orderbook.diff","record_id":"collector_main-market-orderbook-diff-000000000075","collector_id":"collector_main","collector_role":"production","host_name":"MAIN-PC","session_id":"collector_main-sess-20260315T000435Z-429fd61b","stream_session_id":"collector_main-stream-bitflyer-board_ws-20260315T000437Z-4e8fa7ca","exchange":"bitflyer","market":"spot","symbol":"BTC_JPY","instrument_id":"bitflyer.spot.BTC_JPY","channel":"board_ws","transport":"websocket","source_event_id":null,"source_sequence":null,"sequence_id":75,"exchange_ts":null,"collector_ts":"2026-03-15T00:04:38Z","ingest_ts":"2026-03-15T00:04:38Z","event_ts":"2026-03-15T00:04:38Z","quality_flags":[],"is_partial":false,"is_reconstructed":false,"confidence_score":1.0,"payload":{"provider":"bitflyer_ws_board","exchange":"bitflyer","transport":"websocket","channel":"lightning_board_BTC_JPY","received_ts":"2026-03-15T00:04:38.188161Z","subscription_id":null,"message_id":null,"source_sequence":null,"raw_message_meta":{"raw_channel":"lightning_board_BTC_JPY","subscription_channel":"lightning_board_BTC_JPY","recv_timeout_sec":10,"ssl_verify":false,"socket_url":"wss://ws.lightstream.bitflyer.com/json-rpc"},"source_payload":{"mid_price":11377594.0,"bids":[{"price":11327088.0,"size":0.002}],"asks":[{"price":11381332.0,"size":0.0},{"price":11381296.0,"size":0.04403324}]}}}
{"schema_version":"collector.vnext.raw","schema_contract":null,"schema_contract_version":null,"payload_contract_version":null,"record_type":"market.orderbook.diff","record_id":"collector_main-market-orderbook-diff-000000000077","collector_id":"collector_main","collector_role":"production","host_name":"MAIN-PC","session_id":"collector_main-sess-20260315T000435Z-429fd61b","stream_session_id":"collector_main-stream-bitflyer-board_ws-20260315T000437Z-4e8fa7ca","exchange":"bitflyer","market":"spot","symbol":"BTC_JPY","instrument_id":"bitflyer.spot.BTC_JPY","channel":"board_ws","transport":"websocket","source_event_id":null,"source_sequence":null,"sequence_id":77,"exchange_ts":null,"collector_ts":"2026-03-15T00:04:38Z","ingest_ts":"2026-03-15T00:04:38Z","event_ts":"2026-03-15T00:04:38Z","quality_flags":[],"is_partial":false,"is_reconstructed":false,"confidence_score":1.0,"payload":{"provider":"bitflyer_ws_board","exchange":"bitflyer","transport":"websocket","channel":"lightning_board_BTC_JPY","received_ts":"2026-03-15T00:04:38.298267Z","subscription_id":null,"message_id":null,"source_sequence":null,"raw_message_meta":{"raw_channel":"lightning_board_BTC_JPY","subscription_channel":"lightning_board_BTC_JPY","recv_timeout_sec":10,"ssl_verify":false,"socket_url":"wss://ws.lightstream.bitflyer.com/json-rpc"},"source_payload":{"mid_price":11377594.0,"bids":[],"asks":[{"price":11441911.0,"size":0.002}]}}}
{"schema_version":"collector.vnext.raw","schema_contract":null,"schema_contract_version":null,"payload_contract_version":null,"record_type":"market.orderbook.diff","record_id":"collector_main-market-orderbook-diff-000000000079","collector_id":"collector_main","collector_role":"production","host_name":"MAIN-PC","session_id":"collector_main-sess-20260315T000435Z-429fd61b","stream_session_id":"collector_main-stream-bitflyer-board_ws-20260315T000437Z-4e8fa7ca","exchange":"bitflyer","market":"spot","symbol":"BTC_JPY","instrument_id":"bitflyer.spot.BTC_JPY","channel":"board_ws","transport":"websocket","source_event_id":null,"source_sequence":null,"sequence_id":79,"exchange_ts":null,"collector_ts":"2026-03-15T00:04:38Z","ingest_ts":"2026-03-15T00:04:38Z","event_ts":"2026-03-15T00:04:38Z","quality_flags":[],"is_partial":false,"is_reconstructed":false,"confidence_score":1.0,"payload":{"provider":"bitflyer_ws_board","exchange":"bitflyer","transport":"websocket","channel":"lightning_board_BTC_JPY","received_ts":"2026-03-15T00:04:38.660943Z","subscription_id":null,"message_id":null,"source_sequence":null,"raw_message_meta":{"raw_channel":"lightning_board_BTC_JPY","subscription_channel":"lightning_board_BTC_JPY","recv_timeout_sec":10,"ssl_verify":false,"socket_url":"wss://ws.lightstream.bitflyer.com/json-rpc"},"source_payload":{"mid_price":11377594.0,"bids":[{"price":11364410.0,"size":0.0},{"price":11365548.0,"size":0.0}],"asks":[]}}}
{"schema_version":"collector.vnext.raw","schema_contract":null,"schema_contract_version":null,"payload_contract_version":null,"record_type":"market.orderbook.diff","record_id":"collector_main-market-orderbook-diff-000000000081","collector_id":"collector_main","collector_role":"production","host_name":"MAIN-PC","session_id":"collector_main-sess-20260315T000435Z-429fd61b","stream_session_id":"collector_main-stream-bitflyer-board_ws-20260315T000437Z-4e8fa7ca","exchange":"bitflyer","market":"spot","symbol":"BTC_JPY","instrument_id":"bitflyer.spot.BTC_JPY","channel":"board_ws","transport":"websocket","source_event_id":null,"source_sequence":null,"sequence_id":81,"exchange_ts":null,"collector_ts":"2026-03-15T00:04:38Z","ingest_ts":"2026-03-15T00:04:38Z","event_ts":"2026-03-15T00:04:38Z","quality_flags":[],"is_partial":false,"is_reconstructed":false,"confidence_score":1.0,"payload":{"provider":"bitflyer_ws_board","exchange":"bitflyer","transport":"websocket","channel":"lightning_board_BTC_JPY","received_ts":"2026-03-15T00:04:38.804595Z","subscription_id":null,"message_id":null,"source_sequence":null,"raw_message_meta":{"raw_channel":"lightning_board_BTC_JPY","subscription_channel":"lightning_board_BTC_JPY","recv_timeout_sec":10,"ssl_verify":false,"socket_url":"wss://ws.lightstream.bitflyer.com/json-rpc"},"source_payload":{"mid_price":11377594.0,"bids":[],"asks":[{"price":11381297.0,"size":0.0}]}}}
{"schema_version":"collector.vnext.raw","schema_contract":null,"schema_contract_version":null,"payload_contract_version":null,"record_type":"market.orderbook.diff","record_id":"collector_main-market-orderbook-diff-000000000083","collector_id":"collector_main","collector_role":"production","host_name":"MAIN-PC","session_id":"collector_main-sess-20260315T000435Z-429fd61b","stream_session_id":"collector_main-stream-bitflyer-board_ws-20260315T000437Z-4e8fa7ca","exchange":"bitflyer","market":"spot","symbol":"BTC_JPY","instrument_id":"bitflyer.spot.BTC_JPY","channel":"board_ws","transport":"websocket","source_event_id":null,"source_sequence":null,"sequence_id":83,"exchange_ts":null,"collector_ts":"2026-03-15T00:04:38Z","ingest_ts":"2026-03-15T00:04:38Z","event_ts":"2026-03-15T00:04:38Z","quality_flags":[],"is_partial":false,"is_reconstructed":false,"confidence_score":1.0,"payload":{"provider":"bitflyer_ws_board","exchange":"bitflyer","transport":"websocket","channel":"lightning_board_BTC_JPY","received_ts":"2026-03-15T00:04:38.933204Z","subscription_id":null,"message_id":null,"source_sequence":null,"raw_message_meta":{"raw_channel":"lightning_board_BTC_JPY","subscription_channel":"lightning_board_BTC_JPY","recv_timeout_sec":10,"ssl_verify":false,"socket_url":"wss://ws.lightstream.bitflyer.com/json-rpc"},"source_payload":{"mid_price":11377594.0,"bids":[{"price":11371905.0,"size":0.0888}],"asks":[{"price":11381008.0,"size":0.1275},{"price":11381296.0,"size":0.0}]}}}
{"schema_version":"collector.vnext.raw","schema_contract":null,"schema_contract_version":null,"payload_contract_version":null,"record_type":"market.orderbook.diff","record_id":"collector_main-market-orderbook-diff-000000000085","collector_id":"collector_main","collector_role":"production","host_name":"MAIN-PC","session_id":"collector_main-sess-20260315T000435Z-429fd61b","stream_session_id":"collector_main-stream-bitflyer-board_ws-20260315T000437Z-4e8fa7ca","exchange":"bitflyer","market":"spot","symbol":"BTC_JPY","instrument_id":"bitflyer.spot.BTC_JPY","channel":"board_ws","transport":"websocket","source_event_id":null,"source_sequence":null,"sequence_id":85,"exchange_ts":null,"collector_ts":"2026-03-15T00:04:39Z","ingest_ts":"2026-03-15T00:04:39Z","event_ts":"2026-03-15T00:04:39Z","quality_flags":[],"is_partial":false,"is_reconstructed":false,"confidence_score":1.0,"payload":{"provider":"bitflyer_ws_board","exchange":"bitflyer","transport":"websocket","channel":"lightning_board_BTC_JPY","received_ts":"2026-03-15T00:04:39.081686Z","subscription_id":null,"message_id":null,"source_sequence":null,"raw_message_meta":{"raw_channel":"lightning_board_BTC_JPY","subscription_channel":"lightning_board_BTC_JPY","recv_timeout_sec":10,"ssl_verify":false,"socket_url":"wss://ws.lightstream.bitflyer.com/json-rpc"},"source_payload":{"mid_price":11377594.0,"bids":[],"asks":[{"price":11381332.0,"size":0.0},{"price":11381008.0,"size":0.0}]}}}
{"schema_version":"collector.vnext.raw","schema_contract":null,"schema_contract_version":null,"payload_contract_version":null,"record_type":"market.orderbook.diff","record_id":"collector_main-market-orderbook-diff-000000000087","collector_id":"collector_main","collector_role":"production","host_name":"MAIN-PC","session_id":"collector_main-sess-20260315T000435Z-429fd61b","stream_session_id":"collector_main-stream-bitflyer-board_ws-20260315T000437Z-4e8fa7ca","exchange":"bitflyer","market":"spot","symbol":"BTC_JPY","instrument_id":"bitflyer.spot.BTC_JPY","channel":"board_ws","transport":"websocket","source_event_id":null,"source_sequence":null,"sequence_id":87,"exchange_ts":null,"collector_ts":"2026-03-15T00:04:39Z","ingest_ts":"2026-03-15T00:04:39Z","event_ts":"2026-03-15T00:04:39Z","quality_flags":[],"is_partial":false,"is_reconstructed":false,"confidence_score":1.0,"payload":{"provider":"bitflyer_ws_board","exchange":"bitflyer","transport":"websocket","channel":"lightning_board_BTC_JPY","received_ts":"2026-03-15T00:04:39.220001Z","subscription_id":null,"message_id":null,"source_sequence":null,"raw_message_meta":{"raw_channel":"lightning_board_BTC_JPY","subscription_channel":"lightning_board_BTC_JPY","recv_timeout_sec":10,"ssl_verify":false,"socket_url":"wss://ws.lightstream.bitflyer.com/json-rpc"},"source_payload":{"mid_price":11377594.0,"bids":[],"asks":[{"price":11381007.0,"size":0.04431423},{"price":11380439.0,"size":0.1275}]}}}
{"schema_version":"collector.vnext.raw","schema_contract":null,"schema_contract_version":null,"payload_contract_version":null,"record_type":"market.orderbook.diff","record_id":"collector_main-market-orderbook-diff-000000000089","collector_id":"collector_main","collector_role":"production","host_name":"MAIN-PC","session_id":"collector_main-sess-20260315T000435Z-429fd61b","stream_session_id":"collector_main-stream-bitflyer-board_ws-20260315T000437Z-4e8fa7ca","exchange":"bitflyer","market":"spot","symbol":"BTC_JPY","instrument_id":"bitflyer.spot.BTC_JPY","channel":"board_ws","transport":"websocket","source_event_id":null,"source_sequence":null,"sequence_id":89,"exchange_ts":null,"collector_ts":"2026-03-15T00:04:39Z","ingest_ts":"2026-03-15T00:04:39Z","event_ts":"2026-03-15T00:04:39Z","quality_flags":[],"is_partial":false,"is_reconstructed":false,"confidence_score":1.0,"payload":{"provider":"bitflyer_ws_board","exchange":"bitflyer","transport":"websocket","channel":"lightning_board_BTC_JPY","received_ts":"2026-03-15T00:04:39.345799Z","subscription_id":null,"message_id":null,"source_sequence":null,"raw_message_meta":{"raw_channel":"lightning_board_BTC_JPY","subscription_channel":"lightning_board_BTC_JPY","recv_timeout_sec":10,"ssl_verify":false,"socket_url":"wss://ws.lightstream.bitflyer.com/json-rpc"},"source_payload":{"mid_price":11377594.0,"bids":[{"price":11365548.0,"size":0.08},{"price":11364410.0,"size":0.09}],"asks":[]}}}
{"schema_version":"collector.vnext.raw","schema_contract":null,"schema_contract_version":null,"payload_contract_version":null,"record_type":"market.orderbook.diff","record_id":"collector_main-market-orderbook-diff-000000000091","collector_id":"collector_main","collector_role":"production","host_name":"MAIN-PC","session_id":"collector_main-sess-20260315T000435Z-429fd61b","stream_session_id":"collector_main-stream-bitflyer-board_ws-20260315T000437Z-4e8fa7ca","exchange":"bitflyer","market":"spot","symbol":"BTC_JPY","instrument_id":"bitflyer.spot.BTC_JPY","channel":"board_ws","transport":"websocket","source_event_id":null,"source_sequence":null,"sequence_id":91,"exchange_ts":null,"collector_ts":"2026-03-15T00:04:39Z","ingest_ts":"2026-03-15T00:04:39Z","event_ts":"2026-03-15T00:04:39Z","quality_flags":[],"is_partial":false,"is_reconstructed":false,"confidence_score":1.0,"payload":{"provider":"bitflyer_ws_board","exchange":"bitflyer","transport":"websocket","channel":"lightning_board_BTC_JPY","received_ts":"2026-03-15T00:04:39.460328Z","subscription_id":null,"message_id":null,"source_sequence":null,"raw_message_meta":{"raw_channel":"lightning_board_BTC_JPY","subscription_channel":"lightning_board_BTC_JPY","recv_timeout_sec":10,"ssl_verify":false,"socket_url":"wss://ws.lightstream.bitflyer.com/json-rpc"},"source_payload":{"mid_price":11377594.0,"bids":[],"asks":[{"price":11381008.0,"size":0.0},{"price":11381332.0,"size":0.04455747},{"price":11381007.0,"size":0.0},{"price":11381633.0,"size":0.0175686},{"price":11380439.0,"size":0.0}]}}}
{"schema_version":"collector.vnext.raw","schema_contract":null,"schema_contract_version":null,"payload_contract_version":null,"record_type":"market.orderbook.diff","record_id":"collector_main-market-orderbook-diff-000000000093","collector_id":"collector_main","collector_role":"production","host_name":"MAIN-PC","session_id":"collector_main-sess-20260315T000435Z-429fd61b","stream_session_id":"collector_main-stream-bitflyer-board_ws-20260315T000437Z-4e8fa7ca","exchange":"bitflyer","market":"spot","symbol":"BTC_JPY","instrument_id":"bitflyer.spot.BTC_JPY","channel":"board_ws","transport":"websocket","source_event_id":null,"source_sequence":null,"sequence_id":93,"exchange_ts":null,"collector_ts":"2026-03-15T00:04:39Z","ingest_ts":"2026-03-15T00:04:39Z","event_ts":"2026-03-15T00:04:39Z","quality_flags":[],"is_partial":false,"is_reconstructed":false,"confidence_score":1.0,"payload":{"provider":"bitflyer_ws_board","exchange":"bitflyer","transport":"websocket","channel":"lightning_board_BTC_JPY","received_ts":"2026-03-15T00:04:39.581453Z","subscription_id":null,"message_id":null,"source_sequence":null,"raw_message_meta":{"raw_channel":"lightning_board_BTC_JPY","subscription_channel":"lightning_board_BTC_JPY","recv_timeout_sec":10,"ssl_verify":false,"socket_url":"wss://ws.lightstream.bitflyer.com/json-rpc"},"source_payload":{"mid_price":11377590.0,"bids":[],"asks":[{"price":11392323.0,"size":0.0},{"price":11381332.0,"size":0.0},{"price":11392322.0,"size":0.0695},{"price":11381006.0,"size":0.04279066},{"price":11379301.0,"size":0.1275}]}}}
{"schema_version":"collector.vnext.raw","schema_contract":null,"schema_contract_version":null,"payload_contract_version":null,"record_type":"market.orderbook.diff","record_id":"collector_main-market-orderbook-diff-000000000095","collector_id":"collector_main","collector_role":"production","host_name":"MAIN-PC","session_id":"collector_main-sess-20260315T000435Z-429fd61b","stream_session_id":"collector_main-stream-bitflyer-board_ws-20260315T000437Z-4e8fa7ca","exchange":"bitflyer","market":"spot","symbol":"BTC_JPY","instrument_id":"bitflyer.spot.BTC_JPY","channel":"board_ws","transport":"websocket","source_event_id":null,"source_sequence":null,"sequence_id":95,"exchange_ts":null,"collector_ts":"2026-03-15T00:04:39Z","ingest_ts":"2026-03-15T00:04:39Z","event_ts":"2026-03-15T00:04:39Z","quality_flags":[],"is_partial":false,"is_reconstructed":false,"confidence_score":1.0,"payload":{"provider":"bitflyer_ws_board","exchange":"bitflyer","transport":"websocket","channel":"lightning_board_BTC_JPY","received_ts":"2026-03-15T00:04:39.690182Z","subscription_id":null,"message_id":null,"source_sequence":null,"raw_message_meta":{"raw_channel":"lightning_board_BTC_JPY","subscription_channel":"lightning_board_BTC_JPY","recv_timeout_sec":10,"ssl_verify":false,"socket_url":"wss://ws.lightstream.bitflyer.com/json-rpc"},"source_payload":{"mid_price":11377590.0,"bids":[],"asks":[{"price":11381006.0,"size":0.0},{"price":11381332.0,"size":0.04302362},{"price":11446508.0,"size":0.001},{"price":11381008.0,"size":0.1275}]}}}
{"schema_version":"collector.vnext.raw","schema_contract":null,"schema_contract_version":null,"payload_contract_version":null,"record_type":"market.orderbook.diff","record_id":"collector_main-market-orderbook-diff-000000000097","collector_id":"collector_main","collector_role":"production","host_name":"MAIN-PC","session_id":"collector_main-sess-20260315T000435Z-429fd61b","stream_session_id":"collector_main-stream-bitflyer-board_ws-20260315T000437Z-4e8fa7ca","exchange":"bitflyer","market":"spot","symbol":"BTC_JPY","instrument_id":"bitflyer.spot.BTC_JPY","channel":"board_ws","transport":"websocket","source_event_id":null,"source_sequence":null,"sequence_id":97,"exchange_ts":null,"collector_ts":"2026-03-15T00:04:39Z","ingest_ts":"2026-03-15T00:04:39Z","event_ts":"2026-03-15T00:04:39Z","quality_flags":[],"is_partial":false,"is_reconstructed":false,"confidence_score":1.0,"payload":{"provider":"bitflyer_ws_board","exchange":"bitflyer","transport":"websocket","channel":"lightning_board_BTC_JPY","received_ts":"2026-03-15T00:04:39.839395Z","subscription_id":null,"message_id":null,"source_sequence":null,"raw_message_meta":{"raw_channel":"lightning_board_BTC_JPY","subscription_channel":"lightning_board_BTC_JPY","recv_timeout_sec":10,"ssl_verify":false,"socket_url":"wss://ws.lightstream.bitflyer.com/json-rpc"},"source_payload":{"mid_price":11377590.0,"bids":[{"price":11373370.0,"size":0.0}],"asks":[{"price":11381008.0,"size":0.0}]}}}
{"schema_version":"collector.vnext.raw","schema_contract":null,"schema_contract_version":null,"payload_contract_version":null,"record_type":"market.orderbook.diff","record_id":"collector_main-market-orderbook-diff-000000000099","collector_id":"collector_main","collector_role":"production","host_name":"MAIN-PC","session_id":"collector_main-sess-20260315T000435Z-429fd61b","stream_session_id":"collector_main-stream-bitflyer-board_ws-20260315T000437Z-4e8fa7ca","exchange":"bitflyer","market":"spot","symbol":"BTC_JPY","instrument_id":"bitflyer.spot.BTC_JPY","channel":"board_ws","transport":"websocket","source_event_id":null,"source_sequence":null,"sequence_id":99,"exchange_ts":null,"collector_ts":"2026-03-15T00:04:39Z","ingest_ts":"2026-03-15T00:04:39Z","event_ts":"2026-03-15T00:04:39Z","quality_flags":[],"is_partial":false,"is_reconstructed":false,"confidence_score":1.0,"payload":{"provider":"bitflyer_ws_board","exchange":"bitflyer","transport":"websocket","channel":"lightning_board_BTC_JPY","received_ts":"2026-03-15T00:04:39.963530Z","subscription_id":null,"message_id":null,"source_sequence":null,"raw_message_meta":{"raw_channel":"lightning_board_BTC_JPY","subscription_channel":"lightning_board_BTC_JPY","recv_timeout_sec":10,"ssl_verify":false,"socket_url":"wss://ws.lightstream.bitflyer.com/json-rpc"},"source_payload":{"mid_price":11377590.0,"bids":[],"asks":[{"price":11381005.0,"size":0.0},{"price":11380256.0,"size":0.015336},{"price":11381332.0,"size":0.0},{"price":11383854.0,"size":0.0}]}}}
{"schema_version":"collector.vnext.raw","schema_contract":null,"schema_contract_version":null,"payload_contract_version":null,"record_type":"market.orderbook.diff","record_id":"collector_main-market-orderbook-diff-000000000101","collector_id":"collector_main","collector_role":"production","host_name":"MAIN-PC","session_id":"collector_main-sess-20260315T000435Z-429fd61b","stream_session_id":"collector_main-stream-bitflyer-board_ws-20260315T000437Z-4e8fa7ca","exchange":"bitflyer","market":"spot","symbol":"BTC_JPY","instrument_id":"bitflyer.spot.BTC_JPY","channel":"board_ws","transport":"websocket","source_event_id":null,"source_sequence":null,"sequence_id":101,"exchange_ts":null,"collector_ts":"2026-03-15T00:04:40Z","ingest_ts":"2026-03-15T00:04:40Z","event_ts":"2026-03-15T00:04:40Z","quality_flags":[],"is_partial":false,"is_reconstructed":false,"confidence_score":1.0,"payload":{"provider":"bitflyer_ws_board","exchange":"bitflyer","transport":"websocket","channel":"lightning_board_BTC_JPY","received_ts":"2026-03-15T00:04:40.062701Z","subscription_id":null,"message_id":null,"source_sequence":null,"raw_message_meta":{"raw_channel":"lightning_board_BTC_JPY","subscription_channel":"lightning_board_BTC_JPY","recv_timeout_sec":10,"ssl_verify":false,"socket_url":"wss://ws.lightstream.bitflyer.com/json-rpc"},"source_payload":{"mid_price":11377590.0,"bids":[],"asks":[{"price":11381332.0,"size":0.04699642}]}}}
{"schema_version":"collector.vnext.raw","schema_contract":null,"schema_contract_version":null,"payload_contract_version":null,"record_type":"market.orderbook.diff","record_id":"collector_main-market-orderbook-diff-000000000103","collector_id":"collector_main","collector_role":"production","host_name":"MAIN-PC","session_id":"collector_main-sess-20260315T000435Z-429fd61b","stream_session_id":"collector_main-stream-bitflyer-board_ws-20260315T000437Z-4e8fa7ca","exchange":"bitflyer","market":"spot","symbol":"BTC_JPY","instrument_id":"bitflyer.spot.BTC_JPY","channel":"board_ws","transport":"websocket","source_event_id":null,"source_sequence":null,"sequence_id":103,"exchange_ts":null,"collector_ts":"2026-03-15T00:04:40Z","ingest_ts":"2026-03-15T00:04:40Z","event_ts":"2026-03-15T00:04:40Z","quality_flags":[],"is_partial":false,"is_reconstructed":false,"confidence_score":1.0,"payload":{"provider":"bitflyer_ws_board","exchange":"bitflyer","transport":"websocket","channel":"lightning_board_BTC_JPY","received_ts":"2026-03-15T00:04:40.169988Z","subscription_id":null,"message_id":null,"source_sequence":null,"raw_message_meta":{"raw_channel":"lightning_board_BTC_JPY","subscription_channel":"lightning_board_BTC_JPY","recv_timeout_sec":10,"ssl_verify":false,"socket_url":"wss://ws.lightstream.bitflyer.com/json-rpc"},"source_payload":{"mid_price":11377589.0,"bids":[],"asks":[{"price":11379298.0,"size":0.1275}]}}}
{"schema_version":"collector.vnext.raw","schema_contract":null,"schema_contract_version":null,"payload_contract_version":null,"record_type":"market.orderbook.diff","record_id":"collector_main-market-orderbook-diff-000000000105","collector_id":"collector_main","collector_role":"production","host_name":"MAIN-PC","session_id":"collector_main-sess-20260315T000435Z-429fd61b","stream_session_id":"collector_main-stream-bitflyer-board_ws-20260315T000437Z-4e8fa7ca","exchange":"bitflyer","market":"spot","symbol":"BTC_JPY","instrument_id":"bitflyer.spot.BTC_JPY","channel":"board_ws","transport":"websocket","source_event_id":null,"source_sequence":null,"sequence_id":105,"exchange_ts":null,"collector_ts":"2026-03-15T00:04:40Z","ingest_ts":"2026-03-15T00:04:40Z","event_ts":"2026-03-15T00:04:40Z","quality_flags":[],"is_partial":false,"is_reconstructed":false,"confidence_score":1.0,"payload":{"provider":"bitflyer_ws_board","exchange":"bitflyer","transport":"websocket","channel":"lightning_board_BTC_JPY","received_ts":"2026-03-15T00:04:40.277511Z","subscription_id":null,"message_id":null,"source_sequence":null,"raw_message_meta":{"raw_channel":"lightning_board_BTC_JPY","subscription_channel":"lightning_board_BTC_JPY","recv_timeout_sec":10,"ssl_verify":false,"socket_url":"wss://ws.lightstream.bitflyer.com/json-rpc"},"source_payload":{"mid_price":11377589.0,"bids":[{"price":11358722.0,"size":0.0},{"price":11365548.0,"size":0.0},{"price":11364410.0,"size":0.0}],"asks":[{"price":11381633.0,"size":0.0}]}}}
