{"schema_version":"collector.vnext.raw","schema_contract":null,"schema_contract_version":null,"payload_contract_version":null,"record_type":"market.orderbook.snapshot","record_id":"collector_main-market-orderbook-snapshot-000000000107","collector_id":"collector_main","collector_role":"production","host_name":"MAIN-PC","session_id":"collector_main-sess-20260315T000435Z-429fd61b","stream_session_id":"collector_main-stream-bitflyer-board_ws-20260315T000437Z-4e8fa7ca","exchange":"bitflyer","market":"spot","symbol":"BTC_JPY","instrument_id":"bitflyer.spot.BTC_JPY","channel":"board_ws","transport":"websocket","source_event_id":null,"source_sequence":null,"sequence_id":107,"exchange_ts":null,"collector_ts":"2026-03-15T00:04:40Z","ingest_ts":"2026-03-15T00:04:40Z","event_ts":"2026-03-15T00:04:40Z","quality_flags":[],"is_partial":false,"is_reconstructed":false,"confidence_score":1.0,"payload":{"provider":"bitflyer_ws_board_snapshot","exchange":"bitflyer","transport":"websocket","channel":"lightning_board_snapshot_BTC_JPY","received_ts":"2026-03-15T00:04:40.422878Z","subscription_id":null,"message_id":null,"source_sequence":null,"raw_message_meta":{"raw_channel":"lightning_board_snapshot_BTC_JPY","subscription_channel":"lightning_board_snapshot_BTC_JPY","recv_timeout_sec":10,"ssl_verify":false,"socket_url":"wss://ws.lightstream.bitflyer.com/json-rpc"},"source_payload":{"mid_price":11377589.0,"bids":[{"price":11375880.0,"size":0.00999792},{"price":11375439.0,"size":0.005},{"price":11374878.0,"size":0.02},{"price":11374877.0,"size":0.14061},{"price":11372841.0,"size":0.014592},{"price":11371905.0,"size":0.0888},{"price":11371901.0,"size":0.02},{"price":11371900.0,"size":0.005},{"price":11371587.0,"size":0.02},{"price":11371380.0,"size":0.02},{"price":11371196.0,"size":0.005},{"price":11371146.0,"size":0.02},{"price":11371145.0,"size":0.014592},{"price":11370998.0,"size":0.26595698},{"price":11370049.0,"size":0.5},{"price":11370000.0,"size":0.015},{"price":11368516.0,"size":0.0526176},{"price":11368376.0,"size":0.01},{"price":11368353.0,"size":0.01},{"price":11366249.0,"size":3.11638806},{"price":11366247.0,"size":0.036},{"price":11366008.0,"size":0.04},{"price":11365761.0,"size":0.00999891},{"price":11364930.0,"size":0.0527},{"price":11363829.0,"size":0.01},{"price":11363273.0,"size":0.11},{"price":11362277.0,"size":0.9772867},{"price":11362045.0,"size":0.05},{"price":11361538.0,"size":1.50015},{"price":11361476.0,"size":0.05},{"price":11360557.0,"size":0.25},{"price":11358376.0,"size":0.01},{"price":11354042.0,"size":0.2872},{"price":11353488.0,"size":0.27174084},{"price":11351280.0,"size":0.2739},{"price":11350000.0,"size":0.51},{"price":11348518.0,"size":0.2616},{"price":11348189.0,"size":0.003},{"price":11347667.0,"size":0.001},{"price":11347661.0,"size":0.6},{"price":11347560.0,"size":0.002},{"price":11345756.0,"size":0.267},{"price":11345155.0,"size":0.0482554},{"price":11345154.0,"size":1.484},{"price":11344148.0,"size":0.002},{"price":11341752.0,"size":1.966},{"price":11341671.0,"size":0.23},{"price":11340736.0,"size":0.002},{"price":11340000.0,"size":0.005},{"price":11337324.0,"size":0.002},{"price":11336383.0,"size":0.001},{"price":11336319.0,"size":0.00195},{"price":11333912.0,"size":0.002},{"price":11331227.0,"size":0.51},{"price":11331000.0,"size":0.5},{"price":11330500.0,"size":0.002},{"price":11330376.0,"size":2.036},{"price":11330000.0,"size":0.02442},{"price":11327088.0,"size":0.002},{"price":11325101.0,"size":0.001},{"price":11320000.0,"size":0.05},{"price":11315000.0,"size":0.05},{"price":11314325.0,"size":1.951},{"price":11313996.0,"size":0.00195},{"price":11313819.0,"size":0.001},{"price":11310000.0,"size":0.01},{"price":11309999.0,"size":0.177},{"price":11307999.0,"size":0.01},{"price":11303918.0,"size":0.01},{"price":11303000.0,"size":0.5},{"price":11302535.0,"size":0.001},{"price":11302466.0,"size":0.001},{"price":11301268.0,"size":0.01},{"price":11300000.0,"size":3.01685256},{"price":11298000.0,"size":0.01},{"price":11296865.0,"size":0.0015},{"price":11294756.0,"size":1.0},{"price":11291282.0,"size":0.001},{"price":11291268.0,"size":0.01},{"price":11291000.0,"size":0.5},{"price":11290000.0,"size":0.003},{"price":11281268.0,"size":0.01},{"price":11280000.0,"size":0.0163},{"price":11279960.0,"size":0.001},{"price":11279282.0,"size":0.0015},{"price":11278000.0,"size":0.0025},{"price":11275000.0,"size":0.001},{"price":11274588.0,"size":0.0047},{"price":11271268.0,"size":0.01},{"price":11271000.0,"size":0.003},{"price":11270000.0,"size":0.106},{"price":11269424.0,"size":0.8},{"price":11268871.0,"size":0.28},{"price":11268638.0,"size":0.001},{"price":11268411.0,"size":0.01},{"price":11266666.0,"size":0.04},{"price":11265000.0,"size":0.02},{"price":11263000.0,"size":0.006},{"price":11262564.0,"size":0.0015},{"price":11261268.0,"size":0.01},{"price":11260000.0,"size":0.3565},{"price":11257315.0,"size":0.001},{"price":11257000.0,"size":0.001},{"price":11255200.0,"size":0.001},{"price":11255115.0,"size":0.00377},{"price":11253814.0,"size":2.2},{"price":11253690.0,"size":0.01},{"price":11253000.0,"size":0.03189},{"price":11251405.0,"size":0.139},{"price":11251268.0,"size":0.01},{"price":11251111.0,"size":0.0015},{"price":11251000.0,"size":0.0131},{"price":11250250.0,"size":0.00105},{"price":11250200.0,"size":0.001},{"price":11250005.0,"size":0.001},{"price":11250001.0,"size":0.00104},{"price":11250000.0,"size":1.62712889},{"price":11245993.0,"size":0.001},{"price":11245141.0,"size":0.0031},{"price":11245000.0,"size":0.05},{"price":11244444.0,"size":0.04},{"price":11244243.0,"size":0.01},{"price":11240200.0,"size":0.001},{"price":11240000.0,"size":0.007304},{"price":11236190.0,"size":0.01},{"price":11235200.0,"size":0.001},{"price":11234670.0,"size":0.001},{"price":11232000.0,"size":0.089},{"price":11231243.0,"size":0.01},{"price":11231000.0,"size":0.105},{"price":11230200.0,"size":0.001},{"price":11230000.0,"size":0.0308},{"price":11226952.0,"size":0.972},{"price":11224500.0,"size":0.06},{"price":11223968.0,"size":0.001},{"price":11223348.0,"size":0.001},{"price":11223344.0,"size":0.01},{"price":11223000.0,"size":0.1},{"price":11222222.0,"size":0.093525},{"price":11221120.0,"size":0.001},{"price":11220200.0,"size":0.001},{"price":11220001.0,"size":0.004457},{"price":11220000.0,"size":0.321},{"price":11219000.0,"size":0.1},{"price":11217326.0,"size":0.02},{"price":11215200.0,"size":0.001},{"price":11213690.0,"size":0.01},{"price":11212025.0,"size":0.001},{"price":11211800.0,"size":0.001},{"price":11211111.0,"size":0.06},{"price":11210200.0,"size":0.001},{"price":11210000.0,"size":0.10622},{"price":11208032.0,"size":0.01},{"price":11206000.0,"size":0.09015},{"price":11205200.0,"size":0.001},{"price":11204578.0,"size":0.002},{"price":11201000.0,"size":0.01},{"price":11200800.0,"size":0.05},{"price":11200703.0,"size":0.001},{"price":11200425.0,"size":0.1},{"price":11200200.0,"size":0.001},{"price":11200198.0,"size":0.003},{"price":11200150.0,"size":0.002},{"price":11200002.0,"size":0.001},{"price":11200001.0,"size":0.01104},{"price":11200000.0,"size":1.15226728},{"price":11198508.0,"size":0.05},{"price":11198243.0,"size":0.01},{"price":11197134.0,"size":0.993},{"price":11197000.0,"size":0.0085},{"price":11194090.0,"size":0.03},{"price":11190770.0,"size":0.0309},{"price":11190000.0,"size":0.0010016},{"price":11189555.0,"size":0.5},{"price":11189381.0,"size":0.001},{"price":11188629.0,"size":0.01},{"price":11188382.0,"size":0.001},{"price":11185000.0,"size":0.0085},{"price":11180000.0,"size":0.225},{"price":11178058.0,"size":0.001},{"price":11170000.0,"size":0.001},{"price":11169662.0,"size":0.01},{"price":11169593.0,"size":0.001},{"price":11169243.0,"size":0.01},{"price":11166736.0,"size":0.001},{"price":11164029.0,"size":0.001},{"price":11160854.0,"size":0.1},{"price":11160000.0,"size":0.02376},{"price":11155413.0,"size":0.001},{"price":11155377.0,"size":0.00636009},{"price":11153999.0,"size":0.00101},{"price":11151000.0,"size":0.001},{"price":11150250.0,"size":0.00175},{"price":11150005.0,"size":0.001},{"price":11150001.0,"size":0.00104},{"price":11150000.0,"size":0.6533956},{"price":11148000.0,"size":0.08963},{"price":11147546.0,"size":0.02},{"price":11144091.0,"size":0.001},{"price":11144000.0,"size":0.0897},{"price":11143986.0,"size":0.02},{"price":11140139.0,"size":1.0},{"price":11140000.0,"size":0.2},{"price":11136243.0,"size":0.01},{"price":11135869.0,"size":0.1},{"price":11132768.0,"size":0.001},{"price":11130000.0,"size":0.116},{"price":11129979.0,"size":0.0053908},{"price":11124900.0,"size":0.00133},{"price":11121090.0,"size":0.1},{"price":11120000.0,"size":0.0033},{"price":11118078.0,"size":0.01},{"price":11111800.0,"size":0.001},{"price":11111111.0,"size":0.2919257},{"price":11111000.0,"size":0.003},{"price":11110594.0,"size":0.001},{"price":11110000.0,"size":0.021007},{"price":11109662.0,"size":0.01},{"price":11108008.0,"size":0.01},{"price":11102000.0,"size":0.5},{"price":11101297.0,"size":0.001},{"price":11100005.0,"size":0.001},{"price":11100001.0,"size":0.01104},{"price":11100000.0,"size":1.6532049},{"price":11099141.0,"size":0.01},{"price":11098833.0,"size":0.002},{"price":11096243.0,"size":0.01},{"price":11094090.0,"size":0.01},{"price":11088888.0,"size":0.001},{"price":11085245.0,"size":0.001},{"price":11080200.0,"size":0.001},{"price":11080000.0,"size":0.0223},{"price":11075100.0,"size":0.003},{"price":11070200.0,"size":0.001},{"price":11070000.0,"size":0.0902},{"price":11065200.0,"size":0.001},{"price":11064370.0,"size":0.00497091},{"price":11060200.0,"size":0.001},{"price":11060000.0,"size":0.145},{"price":11059689.0,"size":0.009},{"price":11056428.0,"size":0.002},{"price":11055500.0,"size":0.02},{"price":11055200.0,"size":0.001},{"price":11055100.0,"size":0.003},{"price":11050200.0,"size":0.001},{"price":11050005.0,"size":0.001},{"price":11050002.0,"size":0.001},{"price":11050001.0,"size":0.00104},{"price":11050000.0,"size":0.39576147},{"price":11048064.0,"size":2.0},{"price":11046420.0,"size":0.2},{"price":11044243.0,"size":0.01},{"price":11041380.0,"size":0.01},{"price":11040200.0,"size":0.001},{"price":11040000.0,"size":0.00777181},{"price":11035865.0,"size":0.1},{"price":11035200.0,"size":0.001},{"price":11035000.0,"size":0.0013},{"price":11030200.0,"size":0.001},{"price":11030000.0,"size":0.025},{"price":11025500.0,"size":0.009531},{"price":11025200.0,"size":0.001},{"price":11025000.0,"size":0.71497},{"price":11020772.0,"size":0.014},{"price":11020200.0,"size":0.002},{"price":11020000.0,"size":0.005},{"price":11015200.0,"size":0.001},{"price":11012000.0,"size":0.1},{"price":11011800.0,"size":0.001},{"price":11010200.0,"size":0.001},{"price":11010000.0,"size":0.347},{"price":11007277.0,"size":0.01},{"price":11005200.0,"size":0.001},{"price":11004890.0,"size":0.001535},{"price":11003000.0,"size":0.0155},{"price":11001000.0,"size":0.013},{"price":11000500.0,"size":0.05117658},{"price":11000200.0,"size":0.001},{"price":11000002.0,"size":0.004},{"price":11000001.0,"size":0.02604},{"price":11000000.0,"size":4.53923365},{"price":10999999.0,"size":0.003},{"price":10999000.0,"size":0.001},{"price":10996855.0,"size":0.0011},{"price":10995200.0,"size":0.001},{"price":10994499.0,"size":0.00169176},{"price":10990200.0,"size":0.001},{"price":10990000.0,"size":0.10219},{"price":10989001.0,"size":0.00197},{"price":10988999.0,"size":0.001},{"price":10988324.0,"size":0.002},{"price":10987654.0,"size":0.001},{"price":10985200.0,"size":0.001},{"price":10985150.0,"size":0.01},{"price":10980500.0,"size":0.005},{"price":10980200.0,"size":0.001},{"price":10980002.0,"size":0.4},{"price":10980000.0,"size":0.028},{"price":10975200.0,"size":0.001},{"price":10975000.0,"size":0.1}],"asks":[{"price":11379298.0,"size":0.1275},{"price":11379301.0,"size":0.1275},{"price":11379308.0,"size":0.0695},{"price":11380256.0,"size":0.015336},{"price":11380661.0,"size":0.014988},{"price":11380890.0,"size":0.01001785},{"price":11381332.0,"size":0.04699642},{"price":11381333.0,"size":0.014964},{"price":11381668.0,"size":0.01482},{"price":11382109.0,"size":0.301},{"price":11382750.0,"size":0.234},{"price":11384871.0,"size":0.2657},{"price":11385094.0,"size":0.01},{"price":11385583.0,"size":0.0526176},{"price":11387174.0,"size":0.1},{"price":11387205.0,"size":0.05},{"price":11387633.0,"size":0.2976},{"price":11387773.0,"size":0.0484},{"price":11389572.0,"size":0.57242953},{"price":11389573.0,"size":0.0044},{"price":11390395.0,"size":0.2948},{"price":11391432.0,"size":0.4249},{"price":11392010.0,"size":0.00142446},{"price":11392322.0,"size":0.0695},{"price":11393747.0,"size":1.189881},{"price":11394441.0,"size":1.189881},{"price":11394975.0,"size":0.0526},{"price":11397000.0,"size":0.02},{"price":11398444.0,"size":0.001995},{"price":11398845.0,"size":0.001},{"price":11399673.0,"size":0.0015},{"price":11399700.0,"size":0.001},{"price":11399999.0,"size":0.05},{"price":11400000.0,"size":1.04832841},{"price":11403472.0,"size":0.002},{"price":11405000.0,"size":0.1575},{"price":11408363.0,"size":1.489},{"price":11408699.0,"size":1.15098095},{"price":11408700.0,"size":0.001},{"price":11409415.0,"size":0.005},{"price":11409925.0,"size":0.22},{"price":11410000.0,"size":0.3787},{"price":11410168.0,"size":0.001},{"price":11410853.0,"size":0.002},{"price":11412000.0,"size":0.0878},{"price":11415000.0,"size":0.1},{"price":11415141.0,"size":0.0041},{"price":11415674.0,"size":1.928},{"price":11417481.0,"size":0.0015},{"price":11418700.0,"size":0.001},{"price":11419000.0,"size":0.01},{"price":11420000.0,"size":0.261},{"price":11421268.0,"size":0.05},{"price":11421490.0,"size":0.001},{"price":11424296.0,"size":0.002},{"price":11425000.0,"size":0.029},{"price":11426426.0,"size":0.002},{"price":11428121.0,"size":0.002},{"price":11428700.0,"size":0.001},{"price":11429302.0,"size":0.01},{"price":11430000.0,"size":0.4098},{"price":11432718.0,"size":0.002},{"price":11432813.0,"size":0.001},{"price":11433211.0,"size":0.03},{"price":11433333.0,"size":0.001},{"price":11437315.0,"size":0.002},{"price":11438525.0,"size":0.0011},{"price":11438700.0,"size":0.001},{"price":11439557.0,"size":0.001},{"price":11440000.0,"size":0.2538},{"price":11441911.0,"size":0.002},{"price":11442627.0,"size":2.018},{"price":11443629.0,"size":0.002},{"price":11444135.0,"size":0.001},{"price":11445433.0,"size":0.0015},{"price":11446508.0,"size":0.001},{"price":11447000.0,"size":0.01},{"price":11447071.0,"size":0.002},{"price":11448000.0,"size":0.0875},{"price":11448700.0,"size":0.001},{"price":11450000.0,"size":0.268},{"price":11453321.0,"size":0.03},{"price":11455000.0,"size":0.001},{"price":11455457.0,"size":0.001},{"price":11458700.0,"size":0.001},{"price":11458988.0,"size":0.01},{"price":11460000.0,"size":0.06702},{"price":11463288.0,"size":0.01},{"price":11465382.0,"size":0.00195},{"price":11465421.0,"size":1.943},{"price":11466780.0,"size":0.001},{"price":11468700.0,"size":0.001},{"price":11470000.0,"size":0.06},{"price":11471000.0,"size":0.01},{"price":11475000.0,"size":0.0028},{"price":11476929.0,"size":1.0},{"price":11478102.0,"size":0.001},{"price":11478431.0,"size":0.002},{"price":11478700.0,"size":0.001},{"price":11480000.0,"size":0.40191},{"price":11485000.0,"size":0.01},{"price":11485488.0,"size":2.0},{"price":11486555.0,"size":0.03},{"price":11487685.0,"size":0.01},{"price":11488000.0,"size":0.102},{"price":11488700.0,"size":0.001},{"price":11489425.0,"size":0.001},{"price":11490000.0,"size":0.05},{"price":11495850.0,"size":0.001},{"price":11498700.0,"size":0.001},{"price":11498917.0,"size":0.002},{"price":11499000.0,"size":0.01},{"price":11500000.0,"size":0.77159519},{"price":11500078.0,"size":0.93},{"price":11500747.0,"size":0.001},{"price":11502377.0,"size":0.002},{"price":11502800.0,"size":0.00132},{"price":11503108.0,"size":0.0198},{"price":11505000.0,"size":0.0028},{"price":11505001.0,"size":0.002},{"price":11505836.0,"size":0.003},{"price":11508431.0,"size":0.047},{"price":11508700.0,"size":0.001},{"price":11508888.0,"size":0.02},{"price":11510000.0,"size":0.1476},{"price":11512070.0,"size":0.001},{"price":11513633.0,"size":0.08},{"price":11514332.0,"size":0.02},{"price":11518700.0,"size":0.001},{"price":11519855.0,"size":0.01},{"price":11520000.0,"size":0.001},{"price":11522388.0,"size":0.972},{"price":11523211.0,"size":0.01},{"price":11524999.0,"size":0.001},{"price":11528700.0,"size":0.001},{"price":11529852.0,"size":0.01},{"price":11530000.0,"size":0.261},{"price":11533985.0,"size":0.002},{"price":11534084.0,"size":0.001},{"price":11535321.0,"size":0.01},{"price":11538666.0,"size":0.002},{"price":11538700.0,"size":0.001},{"price":11540000.0,"size":0.0048},{"price":11541011.0,"size":0.005},{"price":11541109.0,"size":0.01},{"price":11544663.0,"size":0.002},{"price":11546541.0,"size":0.01},{"price":11548144.0,"size":0.002},{"price":11548700.0,"size":0.001},{"price":11550000.0,"size":0.014},{"price":11551109.0,"size":0.01},{"price":11551625.0,"size":0.002},{"price":11552111.0,"size":0.01},{"price":11553687.0,"size":0.1},{"price":11555106.0,"size":0.002},{"price":11555115.0,"size":0.001},{"price":11556000.0,"size":0.1},{"price":11558587.0,"size":0.002},{"price":11558700.0,"size":0.001},{"price":11559855.0,"size":0.01},{"price":11560831.0,"size":0.0198},{"price":11561109.0,"size":0.01},{"price":11562000.0,"size":0.087},{"price":11562068.0,"size":0.002},{"price":11563750.0,"size":0.08739676},{"price":11565548.0,"size":0.002},{"price":11566139.0,"size":0.0228},{"price":11566551.0,"size":0.01},{"price":11568700.0,"size":0.001},{"price":11569029.0,"size":0.002},{"price":11571109.0,"size":0.01},{"price":11572510.0,"size":0.002},{"price":11573211.0,"size":0.01},{"price":11575991.0,"size":0.001},{"price":11578700.0,"size":0.001},{"price":11579851.0,"size":0.01},{"price":11580000.0,"size":0.7835},{"price":11581109.0,"size":0.01},{"price":11585000.0,"size":0.002},{"price":11586532.0,"size":0.01},{"price":11587498.0,"size":0.0198},{"price":11588700.0,"size":0.001},{"price":11588800.0,"size":0.02},{"price":11590000.0,"size":0.1},{"price":11590749.0,"size":0.002},{"price":11591109.0,"size":0.01},{"price":11593211.0,"size":0.01},{"price":11598111.0,"size":0.1474},{"price":11598555.0,"size":0.01},{"price":11598700.0,"size":0.001},{"price":11599999.0,"size":0.001},{"price":11600000.0,"size":3.655},{"price":11601109.0,"size":0.02},{"price":11603764.0,"size":0.9},{"price":11606655.0,"size":0.01},{"price":11610000.0,"size":0.302},{"price":11611109.0,"size":0.01},{"price":11613321.0,"size":0.01},{"price":11620000.0,"size":1.35441682},{"price":11621011.0,"size":0.01},{"price":11621109.0,"size":0.01},{"price":11623096.0,"size":0.008},{"price":11625703.0,"size":0.012},{"price":11629000.0,"size":0.1},{"price":11630000.0,"size":0.201},{"price":11631059.0,"size":0.01},{"price":11631479.0,"size":0.01},{"price":11631773.0,"size":0.00386871},{"price":11635950.0,"size":0.001},{"price":11638259.0,"size":0.001},{"price":11639700.0,"size":0.001},{"price":11640000.0,"size":1.0},{"price":11640820.0,"size":0.01},{"price":11649900.0,"size":0.02906},{"price":11649999.0,"size":0.001},{"price":11650000.0,"size":0.593},{"price":11651059.0,"size":0.01},{"price":11653658.0,"size":0.008},{"price":11654321.0,"size":0.001},{"price":11659700.0,"size":0.001},{"price":11661479.0,"size":0.01},{"price":11666000.0,"size":0.001},{"price":11666666.0,"size":0.013},{"price":11669700.0,"size":0.001},{"price":11671059.0,"size":0.01},{"price":11672562.0,"size":0.0198},{"price":11680000.0,"size":0.014},{"price":11685000.0,"size":0.003},{"price":11688000.0,"size":0.001},{"price":11689732.0,"size":0.01},{"price":11690330.0,"size":0.0198},{"price":11691059.0,"size":0.01},{"price":11692558.0,"size":0.01},{"price":11695019.0,"size":0.0064},{"price":11698800.0,"size":0.00131},{"price":11699000.0,"size":0.001},{"price":11699631.0,"size":0.001},{"price":11699998.0,"size":0.01},{"price":11699999.0,"size":0.001},{"price":11700000.0,"size":1.2573},{"price":11701059.0,"size":0.01},{"price":11720000.0,"size":0.1},{"price":11721059.0,"size":0.01},{"price":11725000.0,"size":0.005},{"price":11726791.0,"size":0.01},{"price":11727418.0,"size":1.8},{"price":11728195.0,"size":0.05},{"price":11730000.0,"size":1.9712},{"price":11740000.0,"size":0.101},{"price":11741059.0,"size":0.01},{"price":11748937.0,"size":0.001},{"price":11749999.0,"size":0.001},{"price":11750000.0,"size":0.89537866},{"price":11750050.0,"size":0.2},{"price":11751151.0,"size":0.01},{"price":11751406.0,"size":0.012},{"price":11755000.0,"size":0.001},{"price":11757860.0,"size":1.82},{"price":11759999.0,"size":0.001},{"price":11760000.0,"size":0.001},{"price":11761059.0,"size":0.02},{"price":11765432.0,"size":0.001},{"price":11768000.0,"size":0.01},{"price":11770000.0,"size":0.25464896},{"price":11771059.0,"size":0.01755555},{"price":11772000.0,"size":0.002},{"price":11775000.0,"size":0.11593},{"price":11775222.0,"size":0.001657},{"price":11775577.0,"size":0.00013523},{"price":11775800.0,"size":0.001},{"price":11775900.0,"size":0.2},{"price":11775989.0,"size":0.005},{"price":11777000.0,"size":0.5956},{"price":11777777.0,"size":0.0067},{"price":11778541.0,"size":0.001},{"price":11779807.0,"size":0.001},{"price":11780000.0,"size":0.74298},{"price":11780800.0,"size":0.1},{"price":11781059.0,"size":0.01},{"price":11781238.0,"size":0.008},{"price":11785000.0,"size":0.055},{"price":11785040.0,"size":0.01},{"price":11786000.0,"size":0.585},{"price":11788000.0,"size":0.001},{"price":11788888.0,"size":0.005},{"price":11789000.0,"size":0.2},{"price":11789732.0,"size":0.01},{"price":11791100.0,"size":0.1},{"price":11791151.0,"size":0.01},{"price":11795000.0,"size":0.021},{"price":11795040.0,"size":0.015},{"price":11796103.0,"size":0.01},{"price":11798800.0,"size":0.005},{"price":11798950.0,"size":0.001},{"price":11799000.0,"size":0.013},{"price":11799510.0,"size":0.001},{"price":11799639.0,"size":0.01},{"price":11799999.0,"size":0.00769493},{"price":11800000.0,"size":1.10095},{"price":11800050.0,"size":0.006}]}}}
{"schema_version":"collector.vnext.raw","schema_contract":null,"schema_contract_version":null,"payload_contract_version":null,"record_type":"market.orderbook.diff","record_id":"collector_main-market-orderbook-diff-000000000061","collector_id":"collector_main","collector_role":"production","host_name":"MAIN-PC","session_id":"collector_main-sess-20260315T000455Z-36db0fad","stream_session_id":"collector_main-stream-bitflyer-board_ws-20260315T000456Z-f611786d","exchange":"bitflyer","market":"spot","symbol":"BTC_JPY","instrument_id":"bitflyer.spot.BTC_JPY","channel":"board_ws","transport":"websocket","source_event_id":null,"source_sequence":null,"sequence_id":61,"exchange_ts":null,"collector_ts":"2026-03-15T00:04:57Z","ingest_ts":"2026-03-15T00:04:57Z","event_ts":"2026-03-15T00:04:57Z","quality_flags":[],"is_partial":false,"is_reconstructed":false,"confidence_score":1.0,"payload":{"provider":"bitflyer_ws_board","exchange":"bitflyer","transport":"websocket","channel":"lightning_board_BTC_JPY","received_ts":"2026-03-15T00:04:57.063648Z","subscription_id":null,"message_id":null,"source_sequence":null,"raw_message_meta":{"raw_channel":"lightning_board_BTC_JPY","subscription_channel":"lightning_board_BTC_JPY","recv_timeout_sec":10,"ssl_verify":false,"socket_url":"wss://ws.lightstream.bitflyer.com/json-rpc"},"source_payload":{"mid_price":11380077.0,"bids":[],"asks":[{"price":11380154.0,"size":0.07854053}]}}}
{"schema_version":"collector.vnext.raw","schema_contract":null,"schema_contract_version":null,"payload_contract_version":null,"record_type":"market.orderbook.diff","record_id":"collector_main-market-orderbook-diff-000000000065","collector_id":"collector_main","collector_role":"production","host_name":"MAIN-PC","session_id":"collector_main-sess-20260315T000455Z-36db0fad","stream_session_id":"collector_main-stream-bitflyer-board_ws-20260315T000456Z-f611786d","exchange":"bitflyer","market":"spot","symbol":"BTC_JPY","instrument_id":"bitflyer.spot.BTC_JPY","channel":"board_ws","transport":"websocket","source_event_id":null,"source_sequence":null,"sequence_id":65,"exchange_ts":null,"collector_ts":"2026-03-15T00:04:57Z","ingest_ts":"2026-03-15T00:04:57Z","event_ts":"2026-03-15T00:04:57Z","quality_flags":[],"is_partial":false,"is_reconstructed":false,"confidence_score":1.0,"payload":{"provider":"bitflyer_ws_board","exchange":"bitflyer","transport":"websocket","channel":"lightning_board_BTC_JPY","received_ts":"2026-03-15T00:04:57.203740Z","subscription_id":null,"message_id":null,"source_sequence":null,"raw_message_meta":{"raw_channel":"lightning_board_BTC_JPY","subscription_channel":"lightning_board_BTC_JPY","recv_timeout_sec":10,"ssl_verify":false,"socket_url":"wss://ws.lightstream.bitflyer.com/json-rpc"},"source_payload":{"mid_price":11380077.0,"bids":[],"asks":[{"price":11596753.0,"size":0.002},{"price":11381632.0,"size":0.0}]}}}
{"schema_version":"collector.vnext.raw","schema_contract":null,"schema_contract_version":null,"payload_contract_version":null,"record_type":"market.orderbook.diff","record_id":"collector_main-market-orderbook-diff-000000000067","collector_id":"collector_main","collector_role":"production","host_name":"MAIN-PC","session_id":"collector_main-sess-20260315T000455Z-36db0fad","stream_session_id":"collector_main-stream-bitflyer-board_ws-20260315T000456Z-f611786d","exchange":"bitflyer","market":"spot","symbol":"BTC_JPY","instrument_id":"bitflyer.spot.BTC_JPY","channel":"board_ws","transport":"websocket","source_event_id":null,"source_sequence":null,"sequence_id":67,"exchange_ts":null,"collector_ts":"2026-03-15T00:04:57Z","ingest_ts":"2026-03-15T00:04:57Z","event_ts":"2026-03-15T00:04:57Z","quality_flags":[],"is_partial":false,"is_reconstructed":false,"confidence_score":1.0,"payload":{"provider":"bitflyer_ws_board","exchange":"bitflyer","transport":"websocket","channel":"lightning_board_BTC_JPY","received_ts":"2026-03-15T00:04:57.436672Z","subscription_id":null,"message_id":null,"source_sequence":null,"raw_message_meta":{"raw_channel":"lightning_board_BTC_JPY","subscription_channel":"lightning_board_BTC_JPY","recv_timeout_sec":10,"ssl_verify":false,"socket_url":"wss://ws.lightstream.bitflyer.com/json-rpc"},"source_payload":{"mid_price":11380077.0,"bids":[],"asks":[{"price":11381631.0,"size":0.0}]}}}
{"schema_version":"collector.vnext.raw","schema_contract":null,"schema_contract_version":null,"payload_contract_version":null,"record_type":"market.orderbook.diff","record_id":"collector_main-market-orderbook-diff-000000000069","collector_id":"collector_main","collector_role":"production","host_name":"MAIN-PC","session_id":"collector_main-sess-20260315T000455Z-36db0fad","stream_session_id":"collector_main-stream-bitflyer-board_ws-20260315T000456Z-f611786d","exchange":"bitflyer","market":"spot","symbol":"BTC_JPY","instrument_id":"bitflyer.spot.BTC_JPY","channel":"board_ws","transport":"websocket","source_event_id":null,"source_sequence":null,"sequence_id":69,"exchange_ts":null,"collector_ts":"2026-03-15T00:04:57Z","ingest_ts":"2026-03-15T00:04:57Z","event_ts":"2026-03-15T00:04:57Z","quality_flags":[],"is_partial":false,"is_reconstructed":false,"confidence_score":1.0,"payload":{"provider":"bitflyer_ws_board","exchange":"bitflyer","transport":"websocket","channel":"lightning_board_BTC_JPY","received_ts":"2026-03-15T00:04:57.564418Z","subscription_id":null,"message_id":null,"source_sequence":null,"raw_message_meta":{"raw_channel":"lightning_board_BTC_JPY","subscription_channel":"lightning_board_BTC_JPY","recv_timeout_sec":10,"ssl_verify":false,"socket_url":"wss://ws.lightstream.bitflyer.com/json-rpc"},"source_payload":{"mid_price":11380077.0,"bids":[{"price":11380000.0,"size":0.97493208}],"asks":[{"price":11381667.0,"size":0.04681225},{"price":11392320.0,"size":0.0}]}}}
{"schema_version":"collector.vnext.raw","schema_contract":null,"schema_contract_version":null,"payload_contract_version":null,"record_type":"market.orderbook.diff","record_id":"collector_main-market-orderbook-diff-000000000071","collector_id":"collector_main","collector_role":"production","host_name":"MAIN-PC","session_id":"collector_main-sess-20260315T000455Z-36db0fad","stream_session_id":"collector_main-stream-bitflyer-board_ws-20260315T000456Z-f611786d","exchange":"bitflyer","market":"spot","symbol":"BTC_JPY","instrument_id":"bitflyer.spot.BTC_JPY","channel":"board_ws","transport":"websocket","source_event_id":null,"source_sequence":null,"sequence_id":71,"exchange_ts":null,"collector_ts":"2026-03-15T00:04:57Z","ingest_ts":"2026-03-15T00:04:57Z","event_ts":"2026-03-15T00:04:57Z","quality_flags":[],"is_partial":false,"is_reconstructed":false,"confidence_score":1.0,"payload":{"provider":"bitflyer_ws_board","exchange":"bitflyer","transport":"websocket","channel":"lightning_board_BTC_JPY","received_ts":"2026-03-15T00:04:57.672191Z","subscription_id":null,"message_id":null,"source_sequence":null,"raw_message_meta":{"raw_channel":"lightning_board_BTC_JPY","subscription_channel":"lightning_board_BTC_JPY","recv_timeout_sec":10,"ssl_verify":false,"socket_url":"wss://ws.lightstream.bitflyer.com/json-rpc"},"source_payload":{"mid_price":11380077.0,"bids":[],"asks":[{"price":11392321.0,"size":0.2}]}}}
{"schema_version":"collector.vnext.raw","schema_contract":null,"schema_contract_version":null,"payload_contract_version":null,"record_type":"market.orderbook.diff","record_id":"collector_main-market-orderbook-diff-000000000073","collector_id":"collector_main","collector_role":"production","host_name":"MAIN-PC","session_id":"collector_main-sess-20260315T000455Z-36db0fad","stream_session_id":"collector_main-stream-bitflyer-board_ws-20260315T000456Z-f611786d","exchange":"bitflyer","market":"spot","symbol":"BTC_JPY","instrument_id":"bitflyer.spot.BTC_JPY","channel":"board_ws","transport":"websocket","source_event_id":null,"source_sequence":null,"sequence_id":73,"exchange_ts":null,"collector_ts":"2026-03-15T00:04:57Z","ingest_ts":"2026-03-15T00:04:57Z","event_ts":"2026-03-15T00:04:57Z","quality_flags":[],"is_partial":false,"is_reconstructed":false,"confidence_score":1.0,"payload":{"provider":"bitflyer_ws_board","exchange":"bitflyer","transport":"websocket","channel":"lightning_board_BTC_JPY","received_ts":"2026-03-15T00:04:57.782926Z","subscription_id":null,"message_id":null,"source_sequence":null,"raw_message_meta":{"raw_channel":"lightning_board_BTC_JPY","subscription_channel":"lightning_board_BTC_JPY","recv_timeout_sec":10,"ssl_verify":false,"socket_url":"wss://ws.lightstream.bitflyer.com/json-rpc"},"source_payload":{"mid_price":11380077.0,"bids":[{"price":11380000.0,"size":0.96594593}],"asks":[{"price":11382074.0,"size":0.0175679}]}}}
{"schema_version":"collector.vnext.raw","schema_contract":null,"schema_contract_version":null,"payload_contract_version":null,"record_type":"market.orderbook.diff","record_id":"collector_main-market-orderbook-diff-000000000075","collector_id":"collector_main","collector_role":"production","host_name":"MAIN-PC","session_id":"collector_main-sess-20260315T000455Z-36db0fad","stream_session_id":"collector_main-stream-bitflyer-board_ws-20260315T000456Z-f611786d","exchange":"bitflyer","market":"spot","symbol":"BTC_JPY","instrument_id":"bitflyer.spot.BTC_JPY","channel":"board_ws","transport":"websocket","source_event_id":null,"source_sequence":null,"sequence_id":75,"exchange_ts":null,"collector_ts":"2026-03-15T00:04:57Z","ingest_ts":"2026-03-15T00:04:57Z","event_ts":"2026-03-15T00:04:57Z","quality_flags":[],"is_partial":false,"is_reconstructed":false,"confidence_score":1.0,"payload":{"provider":"bitflyer_ws_board","exchange":"bitflyer","transport":"websocket","channel":"lightning_board_BTC_JPY","received_ts":"2026-03-15T00:04:57.973939Z","subscription_id":null,"message_id":null,"source_sequence":null,"raw_message_meta":{"raw_channel":"lightning_board_BTC_JPY","subscription_channel":"lightning_board_BTC_JPY","recv_timeout_sec":10,"ssl_verify":false,"socket_url":"wss://ws.lightstream.bitflyer.com/json-rpc"},"source_payload":{"mid_price":11380077.0,"bids":[{"price":11380000.0,"size":0.94806018}],"asks":[]}}}
{"schema_version":"collector.vnext.raw","schema_contract":null,"schema_contract_version":null,"payload_contract_version":null,"record_type":"market.orderbook.diff","record_id":"collector_main-market-orderbook-diff-000000000077","collector_id":"collector_main","collector_role":"production","host_name":"MAIN-PC","session_id":"collector_main-sess-20260315T000455Z-36db0fad","stream_session_id":"collector_main-stream-bitflyer-board_ws-20260315T000456Z-f611786d","exchange":"bitflyer","market":"spot","symbol":"BTC_JPY","instrument_id":"bitflyer.spot.BTC_JPY","channel":"board_ws","transport":"websocket","source_event_id":null,"source_sequence":null,"sequence_id":77,"exchange_ts":null,"collector_ts":"2026-03-15T00:04:58Z","ingest_ts":"2026-03-15T00:04:58Z","event_ts":"2026-03-15T00:04:58Z","quality_flags":[],"is_partial":false,"is_reconstructed":false,"confidence_score":1.0,"payload":{"provider":"bitflyer_ws_board","exchange":"bitflyer","transport":"websocket","channel":"lightning_board_BTC_JPY","received_ts":"2026-03-15T00:04:58.188003Z","subscription_id":null,"message_id":null,"source_sequence":null,"raw_message_meta":{"raw_channel":"lightning_board_BTC_JPY","subscription_channel":"lightning_board_BTC_JPY","recv_timeout_sec":10,"ssl_verify":false,"socket_url":"wss://ws.lightstream.bitflyer.com/json-rpc"},"source_payload":{"mid_price":11380077.0,"bids":[{"price":11380000.0,"size":0.92622184}],"asks":[]}}}
{"schema_version":"collector.vnext.raw","schema_contract":null,"schema_contract_version":null,"payload_contract_version":null,"record_type":"market.orderbook.diff","record_id":"collector_main-market-orderbook-diff-000000000079","collector_id":"collector_main","collector_role":"production","host_name":"MAIN-PC","session_id":"collector_main-sess-20260315T000455Z-36db0fad","stream_session_id":"collector_main-stream-bitflyer-board_ws-20260315T000456Z-f611786d","exchange":"bitflyer","market":"spot","symbol":"BTC_JPY","instrument_id":"bitflyer.spot.BTC_JPY","channel":"board_ws","transport":"websocket","source_event_id":null,"source_sequence":null,"sequence_id":79,"exchange_ts":null,"collector_ts":"2026-03-15T00:04:58Z","ingest_ts":"2026-03-15T00:04:58Z","event_ts":"2026-03-15T00:04:58Z","quality_flags":[],"is_partial":false,"is_reconstructed":false,"confidence_score":1.0,"payload":{"provider":"bitflyer_ws_board","exchange":"bitflyer","transport":"websocket","channel":"lightning_board_BTC_JPY","received_ts":"2026-03-15T00:04:58.469778Z","subscription_id":null,"message_id":null,"source_sequence":null,"raw_message_meta":{"raw_channel":"lightning_board_BTC_JPY","subscription_channel":"lightning_board_BTC_JPY","recv_timeout_sec":10,"ssl_verify":false,"socket_url":"wss://ws.lightstream.bitflyer.com/json-rpc"},"source_payload":{"mid_price":11380077.0,"bids":[{"price":11380000.0,"size":0.91165842},{"price":11347461.0,"size":0.002}],"asks":[]}}}
{"schema_version":"collector.vnext.raw","schema_contract":null,"schema_contract_version":null,"payload_contract_version":null,"record_type":"market.orderbook.diff","record_id":"collector_main-market-orderbook-diff-000000000081","collector_id":"collector_main","collector_role":"production","host_name":"MAIN-PC","session_id":"collector_main-sess-20260315T000455Z-36db0fad","stream_session_id":"collector_main-stream-bitflyer-board_ws-20260315T000456Z-f611786d","exchange":"bitflyer","market":"spot","symbol":"BTC_JPY","instrument_id":"bitflyer.spot.BTC_JPY","channel":"board_ws","transport":"websocket","source_event_id":null,"source_sequence":null,"sequence_id":81,"exchange_ts":null,"collector_ts":"2026-03-15T00:04:58Z","ingest_ts":"2026-03-15T00:04:58Z","event_ts":"2026-03-15T00:04:58Z","quality_flags":[],"is_partial":false,"is_reconstructed":false,"confidence_score":1.0,"payload":{"provider":"bitflyer_ws_board","exchange":"bitflyer","transport":"websocket","channel":"lightning_board_BTC_JPY","received_ts":"2026-03-15T00:04:58.597314Z","subscription_id":null,"message_id":null,"source_sequence":null,"raw_message_meta":{"raw_channel":"lightning_board_BTC_JPY","subscription_channel":"lightning_board_BTC_JPY","recv_timeout_sec":10,"ssl_verify":false,"socket_url":"wss://ws.lightstream.bitflyer.com/json-rpc"},"source_payload":{"mid_price":11380077.0,"bids":[{"price":11380000.0,"size":0.86945016}],"asks":[{"price":11392321.0,"size":0.0},{"price":11392320.0,"size":0.0785405}]}}}
{"schema_version":"collector.vnext.raw","schema_contract":null,"schema_contract_version":null,"payload_contract_version":null,"record_type":"market.orderbook.diff","record_id":"collector_main-market-orderbook-diff-000000000083","collector_id":"collector_main","collector_role":"production","host_name":"MAIN-PC","session_id":"collector_main-sess-20260315T000455Z-36db0fad","stream_session_id":"collector_main-stream-bitflyer-board_ws-20260315T000456Z-f611786d","exchange":"bitflyer","market":"spot","symbol":"BTC_JPY","instrument_id":"bitflyer.spot.BTC_JPY","channel":"board_ws","transport":"websocket","source_event_id":null,"source_sequence":null,"sequence_id":83,"exchange_ts":null,"collector_ts":"2026-03-15T00:04:58Z","ingest_ts":"2026-03-15T00:04:58Z","event_ts":"2026-03-15T00:04:58Z","quality_flags":[],"is_partial":false,"is_reconstructed":false,"confidence_score":1.0,"payload":{"provider":"bitflyer_ws_board","exchange":"bitflyer","transport":"websocket","channel":"lightning_board_BTC_JPY","received_ts":"2026-03-15T00:04:58.689894Z","subscription_id":null,"message_id":null,"source_sequence":null,"raw_message_meta":{"raw_channel":"lightning_board_BTC_JPY","subscription_channel":"lightning_board_BTC_JPY","recv_timeout_sec":10,"ssl_verify":false,"socket_url":"wss://ws.lightstream.bitflyer.com/json-rpc"},"source_payload":{"mid_price":11380077.0,"bids":[],"asks":[{"price":11382074.0,"size":0.0}]}}}
{"schema_version":"collector.vnext.raw","schema_contract":null,"schema_contract_version":null,"payload_contract_version":null,"record_type":"market.orderbook.diff","record_id":"collector_main-market-orderbook-diff-000000000085","collector_id":"collector_main","collector_role":"production","host_name":"MAIN-PC","session_id":"collector_main-sess-20260315T000455Z-36db0fad","stream_session_id":"collector_main-stream-bitflyer-board_ws-20260315T000456Z-f611786d","exchange":"bitflyer","market":"spot","symbol":"BTC_JPY","instrument_id":"bitflyer.spot.BTC_JPY","channel":"board_ws","transport":"websocket","source_event_id":null,"source_sequence":null,"sequence_id":85,"exchange_ts":null,"collector_ts":"2026-03-15T00:04:58Z","ingest_ts":"2026-03-15T00:04:58Z","event_ts":"2026-03-15T00:04:58Z","quality_flags":[],"is_partial":false,"is_reconstructed":false,"confidence_score":1.0,"payload":{"provider":"bitflyer_ws_board","exchange":"bitflyer","transport":"websocket","channel":"lightning_board_BTC_JPY","received_ts":"2026-03-15T00:04:58.999269Z","subscription_id":null,"message_id":null,"source_sequence":null,"raw_message_meta":{"raw_channel":"lightning_board_BTC_JPY","subscription_channel":"lightning_board_BTC_JPY","recv_timeout_sec":10,"ssl_verify":false,"socket_url":"wss://ws.lightstream.bitflyer.com/json-rpc"},"source_payload":{"mid_price":11380077.0,"bids":[{"price":11380000.0,"size":0.85761134}],"asks":[{"price":11387173.0,"size":0.0},{"price":11387172.0,"size":0.57248417}]}}}
{"schema_version":"collector.vnext.raw","schema_contract":null,"schema_contract_version":null,"payload_contract_version":null,"record_type":"market.orderbook.diff","record_id":"collector_main-market-orderbook-diff-000000000087","collector_id":"collector_main","collector_role":"production","host_name":"MAIN-PC","session_id":"collector_main-sess-20260315T000455Z-36db0fad","stream_session_id":"collector_main-stream-bitflyer-board_ws-20260315T000456Z-f611786d","exchange":"bitflyer","market":"spot","symbol":"BTC_JPY","instrument_id":"bitflyer.spot.BTC_JPY","channel":"board_ws","transport":"websocket","source_event_id":null,"source_sequence":null,"sequence_id":87,"exchange_ts":null,"collector_ts":"2026-03-15T00:04:59Z","ingest_ts":"2026-03-15T00:04:59Z","event_ts":"2026-03-15T00:04:59Z","quality_flags":[],"is_partial":false,"is_reconstructed":false,"confidence_score":1.0,"payload":{"provider":"bitflyer_ws_board","exchange":"bitflyer","transport":"websocket","channel":"lightning_board_BTC_JPY","received_ts":"2026-03-15T00:04:59.120346Z","subscription_id":null,"message_id":null,"source_sequence":null,"raw_message_meta":{"raw_channel":"lightning_board_BTC_JPY","subscription_channel":"lightning_board_BTC_JPY","recv_timeout_sec":10,"ssl_verify":false,"socket_url":"wss://ws.lightstream.bitflyer.com/json-rpc"},"source_payload":{"mid_price":11380077.0,"bids":[{"price":11366250.0,"size":0.0}],"asks":[]}}}
{"schema_version":"collector.vnext.raw","schema_contract":null,"schema_contract_version":null,"payload_contract_version":null,"record_type":"market.orderbook.diff","record_id":"collector_main-market-orderbook-diff-000000000089","collector_id":"collector_main","collector_role":"production","host_name":"MAIN-PC","session_id":"collector_main-sess-20260315T000455Z-36db0fad","stream_session_id":"collector_main-stream-bitflyer-board_ws-20260315T000456Z-f611786d","exchange":"bitflyer","market":"spot","symbol":"BTC_JPY","instrument_id":"bitflyer.spot.BTC_JPY","channel":"board_ws","transport":"websocket","source_event_id":null,"source_sequence":null,"sequence_id":89,"exchange_ts":null,"collector_ts":"2026-03-15T00:04:59Z","ingest_ts":"2026-03-15T00:04:59Z","event_ts":"2026-03-15T00:04:59Z","quality_flags":[],"is_partial":false,"is_reconstructed":false,"confidence_score":1.0,"payload":{"provider":"bitflyer_ws_board","exchange":"bitflyer","transport":"websocket","channel":"lightning_board_BTC_JPY","received_ts":"2026-03-15T00:04:59.282401Z","subscription_id":null,"message_id":null,"source_sequence":null,"raw_message_meta":{"raw_channel":"lightning_board_BTC_JPY","subscription_channel":"lightning_board_BTC_JPY","recv_timeout_sec":10,"ssl_verify":false,"socket_url":"wss://ws.lightstream.bitflyer.com/json-rpc"},"source_payload":{"mid_price":11380077.0,"bids":[],"asks":[{"price":11381632.0,"size":0.0175686}]}}}
{"schema_version":"collector.vnext.raw","schema_contract":null,"schema_contract_version":null,"payload_contract_version":null,"record_type":"market.orderbook.diff","record_id":"collector_main-market-orderbook-diff-000000000091","collector_id":"collector_main","collector_role":"production","host_name":"MAIN-PC","session_id":"collector_main-sess-20260315T000455Z-36db0fad","stream_session_id":"collector_main-stream-bitflyer-board_ws-20260315T000456Z-f611786d","exchange":"bitflyer","market":"spot","symbol":"BTC_JPY","instrument_id":"bitflyer.spot.BTC_JPY","channel":"board_ws","transport":"websocket","source_event_id":null,"source_sequence":null,"sequence_id":91,"exchange_ts":null,"collector_ts":"2026-03-15T00:04:59Z","ingest_ts":"2026-03-15T00:04:59Z","event_ts":"2026-03-15T00:04:59Z","quality_flags":[],"is_partial":false,"is_reconstructed":false,"confidence_score":1.0,"payload":{"provider":"bitflyer_ws_board","exchange":"bitflyer","transport":"websocket","channel":"lightning_board_BTC_JPY","received_ts":"2026-03-15T00:04:59.406435Z","subscription_id":null,"message_id":null,"source_sequence":null,"raw_message_meta":{"raw_channel":"lightning_board_BTC_JPY","subscription_channel":"lightning_board_BTC_JPY","recv_timeout_sec":10,"ssl_verify":false,"socket_url":"wss://ws.lightstream.bitflyer.com/json-rpc"},"source_payload":{"mid_price":11380077.0,"bids":[{"price":11366248.0,"size":3.11578742}],"asks":[]}}}
{"schema_version":"collector.vnext.raw","schema_contract":null,"schema_contract_version":null,"payload_contract_version":null,"record_type":"market.orderbook.diff","record_id":"collector_main-market-orderbook-diff-000000000093","collector_id":"collector_main","collector_role":"production","host_name":"MAIN-PC","session_id":"collector_main-sess-20260315T000455Z-36db0fad","stream_session_id":"collector_main-stream-bitflyer-board_ws-20260315T000456Z-f611786d","exchange":"bitflyer","market":"spot","symbol":"BTC_JPY","instrument_id":"bitflyer.spot.BTC_JPY","channel":"board_ws","transport":"websocket","source_event_id":null,"source_sequence":null,"sequence_id":93,"exchange_ts":null,"collector_ts":"2026-03-15T00:04:59Z","ingest_ts":"2026-03-15T00:04:59Z","event_ts":"2026-03-15T00:04:59Z","quality_flags":[],"is_partial":false,"is_reconstructed":false,"confidence_score":1.0,"payload":{"provider":"bitflyer_ws_board","exchange":"bitflyer","transport":"websocket","channel":"lightning_board_BTC_JPY","received_ts":"2026-03-15T00:04:59.518256Z","subscription_id":null,"message_id":null,"source_sequence":null,"raw_message_meta":{"raw_channel":"lightning_board_BTC_JPY","subscription_channel":"lightning_board_BTC_JPY","recv_timeout_sec":10,"ssl_verify":false,"socket_url":"wss://ws.lightstream.bitflyer.com/json-rpc"},"source_payload":{"mid_price":11380077.0,"bids":[{"price":11380000.0,"size":0.85051197}],"asks":[{"price":11381667.0,"size":0.0}]}}}
{"schema_version":"collector.vnext.raw","schema_contract":null,"schema_contract_version":null,"payload_contract_version":null,"record_type":"market.orderbook.diff","record_id":"collector_main-market-orderbook-diff-000000000095","collector_id":"collector_main","collector_role":"production","host_name":"MAIN-PC","session_id":"collector_main-sess-20260315T000455Z-36db0fad","stream_session_id":"collector_main-stream-bitflyer-board_ws-20260315T000456Z-f611786d","exchange":"bitflyer","market":"spot","symbol":"BTC_JPY","instrument_id":"bitflyer.spot.BTC_JPY","channel":"board_ws","transport":"websocket","source_event_id":null,"source_sequence":null,"sequence_id":95,"exchange_ts":null,"collector_ts":"2026-03-15T00:04:59Z","ingest_ts":"2026-03-15T00:04:59Z","event_ts":"2026-03-15T00:04:59Z","quality_flags":[],"is_partial":false,"is_reconstructed":false,"confidence_score":1.0,"payload":{"provider":"bitflyer_ws_board","exchange":"bitflyer","transport":"websocket","channel":"lightning_board_BTC_JPY","received_ts":"2026-03-15T00:04:59.627046Z","subscription_id":null,"message_id":null,"source_sequence":null,"raw_message_meta":{"raw_channel":"lightning_board_BTC_JPY","subscription_channel":"lightning_board_BTC_JPY","recv_timeout_sec":10,"ssl_verify":false,"socket_url":"wss://ws.lightstream.bitflyer.com/json-rpc"},"source_payload":{"mid_price":11380077.0,"bids":[],"asks":[{"price":11381631.0,"size":0.04472658}]}}}
{"schema_version":"collector.vnext.raw","schema_contract":null,"schema_contract_version":null,"payload_contract_version":null,"record_type":"market.orderbook.diff","record_id":"collector_main-market-orderbook-diff-000000000097","collector_id":"collector_main","collector_role":"production","host_name":"MAIN-PC","session_id":"collector_main-sess-20260315T000455Z-36db0fad","stream_session_id":"collector_main-stream-bitflyer-board_ws-20260315T000456Z-f611786d","exchange":"bitflyer","market":"spot","symbol":"BTC_JPY","instrument_id":"bitflyer.spot.BTC_JPY","channel":"board_ws","transport":"websocket","source_event_id":null,"source_sequence":null,"sequence_id":97,"exchange_ts":null,"collector_ts":"2026-03-15T00:04:59Z","ingest_ts":"2026-03-15T00:04:59Z","event_ts":"2026-03-15T00:04:59Z","quality_flags":[],"is_partial":false,"is_reconstructed":false,"confidence_score":1.0,"payload":{"provider":"bitflyer_ws_board","exchange":"bitflyer","transport":"websocket","channel":"lightning_board_BTC_JPY","received_ts":"2026-03-15T00:04:59.759151Z","subscription_id":null,"message_id":null,"source_sequence":null,"raw_message_meta":{"raw_channel":"lightning_board_BTC_JPY","subscription_channel":"lightning_board_BTC_JPY","recv_timeout_sec":10,"ssl_verify":false,"socket_url":"wss://ws.lightstream.bitflyer.com/json-rpc"},"source_payload":{"mid_price":11380077.0,"bids":[{"price":11380000.0,"size":0.84270201},{"price":11342910.0,"size":0.002}],"asks":[]}}}
{"schema_version":"collector.vnext.raw","schema_contract":null,"schema_contract_version":null,"payload_contract_version":null,"record_type":"market.orderbook.diff","record_id":"collector_main-market-orderbook-diff-000000000099","collector_id":"collector_main","collector_role":"production","host_name":"MAIN-PC","session_id":"collector_main-sess-20260315T000455Z-36db0fad","stream_session_id":"collector_main-stream-bitflyer-board_ws-20260315T000456Z-f611786d","exchange":"bitflyer","market":"spot","symbol":"BTC_JPY","instrument_id":"bitflyer.spot.BTC_JPY","channel":"board_ws","transport":"websocket","source_event_id":null,"source_sequence":null,"sequence_id":99,"exchange_ts":null,"collector_ts":"2026-03-15T00:04:59Z","ingest_ts":"2026-03-15T00:04:59Z","event_ts":"2026-03-15T00:04:59Z","quality_flags":[],"is_partial":false,"is_reconstructed":false,"confidence_score":1.0,"payload":{"provider":"bitflyer_ws_board","exchange":"bitflyer","transport":"websocket","channel":"lightning_board_BTC_JPY","received_ts":"2026-03-15T00:04:59.885130Z","subscription_id":null,"message_id":null,"source_sequence":null,"raw_message_meta":{"raw_channel":"lightning_board_BTC_JPY","subscription_channel":"lightning_board_BTC_JPY","recv_timeout_sec":10,"ssl_verify":false,"socket_url":"wss://ws.lightstream.bitflyer.com/json-rpc"},"source_payload":{"mid_price":11380077.0,"bids":[],"asks":[{"price":11387773.0,"size":0.0},{"price":11387205.0,"size":0.0}]}}}
{"schema_version":"collector.vnext.raw","schema_contract":null,"schema_contract_version":null,"payload_contract_version":null,"record_type":"market.orderbook.diff","record_id":"collector_main-market-orderbook-diff-000000000101","collector_id":"collector_main","collector_role":"production","host_name":"MAIN-PC","session_id":"collector_main-sess-20260315T000455Z-36db0fad","stream_session_id":"collector_main-stream-bitflyer-board_ws-20260315T000456Z-f611786d","exchange":"bitflyer","market":"spot","symbol":"BTC_JPY","instrument_id":"bitflyer.spot.BTC_JPY","channel":"board_ws","transport":"websocket","source_event_id":null,"source_sequence":null,"sequence_id":101,"exchange_ts":null,"collector_ts":"2026-03-15T00:05:00Z","ingest_ts":"2026-03-15T00:05:00Z","event_ts":"2026-03-15T00:05:00Z","quality_flags":[],"is_partial":false,"is_reconstructed":false,"confidence_score":1.0,"payload":{"provider":"bitflyer_ws_board","exchange":"bitflyer","transport":"websocket","channel":"lightning_board_BTC_JPY","received_ts":"2026-03-15T00:05:00.001015Z","subscription_id":null,"message_id":null,"source_sequence":null,"raw_message_meta":{"raw_channel":"lightning_board_BTC_JPY","subscription_channel":"lightning_board_BTC_JPY","recv_timeout_sec":10,"ssl_verify":false,"socket_url":"wss://ws.lightstream.bitflyer.com/json-rpc"},"source_payload":{"mid_price":11380077.0,"bids":[{"price":11380000.0,"size":0.49950473},{"price":11374877.0,"size":0.0},{"price":11374403.0,"size":0.0}],"asks":[{"price":11381129.0,"size":0.014712}]}}}
{"schema_version":"collector.vnext.raw","schema_contract":null,"schema_contract_version":null,"payload_contract_version":null,"record_type":"market.orderbook.diff","record_id":"collector_main-market-orderbook-diff-000000000103","collector_id":"collector_main","collector_role":"production","host_name":"MAIN-PC","session_id":"collector_main-sess-20260315T000455Z-36db0fad","stream_session_id":"collector_main-stream-bitflyer-board_ws-20260315T000456Z-f611786d","exchange":"bitflyer","market":"spot","symbol":"BTC_JPY","instrument_id":"bitflyer.spot.BTC_JPY","channel":"board_ws","transport":"websocket","source_event_id":null,"source_sequence":null,"sequence_id":103,"exchange_ts":null,"collector_ts":"2026-03-15T00:05:00Z","ingest_ts":"2026-03-15T00:05:00Z","event_ts":"2026-03-15T00:05:00Z","quality_flags":[],"is_partial":false,"is_reconstructed":false,"confidence_score":1.0,"payload":{"provider":"bitflyer_ws_board","exchange":"bitflyer","transport":"websocket","channel":"lightning_board_BTC_JPY","received_ts":"2026-03-15T00:05:00.184119Z","subscription_id":null,"message_id":null,"source_sequence":null,"raw_message_meta":{"raw_channel":"lightning_board_BTC_JPY","subscription_channel":"lightning_board_BTC_JPY","recv_timeout_sec":10,"ssl_verify":false,"socket_url":"wss://ws.lightstream.bitflyer.com/json-rpc"},"source_payload":{"mid_price":11378619.0,"bids":[{"price":11373732.0,"size":0.014712},{"price":11380000.0,"size":0.0},{"price":11375439.0,"size":0.0}],"asks":[{"price":11381631.0,"size":0.0},{"price":11381632.0,"size":0.0}]}}}
{"schema_version":"collector.vnext.raw","schema_contract":null,"schema_contract_version":null,"payload_contract_version":null,"record_type":"market.orderbook.diff","record_id":"collector_main-market-orderbook-diff-000000000105","collector_id":"collector_main","collector_role":"production","host_name":"MAIN-PC","session_id":"collector_main-sess-20260315T000455Z-36db0fad","stream_session_id":"collector_main-stream-bitflyer-board_ws-20260315T000456Z-f611786d","exchange":"bitflyer","market":"spot","symbol":"BTC_JPY","instrument_id":"bitflyer.spot.BTC_JPY","channel":"board_ws","transport":"websocket","source_event_id":null,"source_sequence":null,"sequence_id":105,"exchange_ts":null,"collector_ts":"2026-03-15T00:05:00Z","ingest_ts":"2026-03-15T00:05:00Z","event_ts":"2026-03-15T00:05:00Z","quality_flags":[],"is_partial":false,"is_reconstructed":false,"confidence_score":1.0,"payload":{"provider":"bitflyer_ws_board","exchange":"bitflyer","transport":"websocket","channel":"lightning_board_BTC_JPY","received_ts":"2026-03-15T00:05:00.324486Z","subscription_id":null,"message_id":null,"source_sequence":null,"raw_message_meta":{"raw_channel":"lightning_board_BTC_JPY","subscription_channel":"lightning_board_BTC_JPY","recv_timeout_sec":10,"ssl_verify":false,"socket_url":"wss://ws.lightstream.bitflyer.com/json-rpc"},"source_payload":{"mid_price":11378618.0,"bids":[{"price":11373732.0,"size":0.0}],"asks":[{"price":11380153.0,"size":0.04800739},{"price":11381595.0,"size":0.02},{"price":11387172.0,"size":0.0}]}}}
{"schema_version":"collector.vnext.raw","schema_contract":null,"schema_contract_version":null,"payload_contract_version":null,"record_type":"market.orderbook.diff","record_id":"collector_main-market-orderbook-diff-000000000107","collector_id":"collector_main","collector_role":"production","host_name":"MAIN-PC","session_id":"collector_main-sess-20260315T000455Z-36db0fad","stream_session_id":"collector_main-stream-bitflyer-board_ws-20260315T000456Z-f611786d","exchange":"bitflyer","market":"spot","symbol":"BTC_JPY","instrument_id":"bitflyer.spot.BTC_JPY","channel":"board_ws","transport":"websocket","source_event_id":null,"source_sequence":null,"sequence_id":107,"exchange_ts":null,"collector_ts":"2026-03-15T00:05:00Z","ingest_ts":"2026-03-15T00:05:00Z","event_ts":"2026-03-15T00:05:00Z","quality_flags":[],"is_partial":false,"is_reconstructed":false,"confidence_score":1.0,"payload":{"provider":"bitflyer_ws_board","exchange":"bitflyer","transport":"websocket","channel":"lightning_board_BTC_JPY","received_ts":"2026-03-15T00:05:00.438181Z","subscription_id":null,"message_id":null,"source_sequence":null,"raw_message_meta":{"raw_channel":"lightning_board_BTC_JPY","subscription_channel":"lightning_board_BTC_JPY","recv_timeout_sec":10,"ssl_verify":false,"socket_url":"wss://ws.lightstream.bitflyer.com/json-rpc"},"source_payload":{"mid_price":11378618.0,"bids":[{"price":11362278.0,"size":0.31206306}],"asks":[{"price":11381234.0,"size":0.02},{"price":11380742.0,"size":0.014652}]}}}
{"schema_version":"collector.vnext.raw","schema_contract":null,"schema_contract_version":null,"payload_contract_version":null,"record_type":"market.orderbook.snapshot","record_id":"collector_main-market-orderbook-snapshot-000000000109","collector_id":"collector_main","collector_role":"production","host_name":"MAIN-PC","session_id":"collector_main-sess-20260315T000455Z-36db0fad","stream_session_id":"collector_main-stream-bitflyer-board_ws-20260315T000456Z-f611786d","exchange":"bitflyer","market":"spot","symbol":"BTC_JPY","instrument_id":"bitflyer.spot.BTC_JPY","channel":"board_ws","transport":"websocket","source_event_id":null,"source_sequence":null,"sequence_id":109,"exchange_ts":null,"collector_ts":"2026-03-15T00:05:00Z","ingest_ts":"2026-03-15T00:05:00Z","event_ts":"2026-03-15T00:05:00Z","quality_flags":[],"is_partial":false,"is_reconstructed":false,"confidence_score":1.0,"payload":{"provider":"bitflyer_ws_board_snapshot","exchange":"bitflyer","transport":"websocket","channel":"lightning_board_snapshot_BTC_JPY","received_ts":"2026-03-15T00:05:00.534643Z","subscription_id":null,"message_id":null,"source_sequence":null,"raw_message_meta":{"raw_channel":"lightning_board_snapshot_BTC_JPY","subscription_channel":"lightning_board_snapshot_BTC_JPY","recv_timeout_sec":10,"ssl_verify":false,"socket_url":"wss://ws.lightstream.bitflyer.com/json-rpc"},"source_payload":{"mid_price":11376497.0,"bids":[{"price":11372841.0,"size":0.014592},{"price":11371999.0,"size":0.005},{"price":11371900.0,"size":0.005},{"price":11371145.0,"size":0.014592},{"price":11370998.0,"size":0.26595698},{"price":11370049.0,"size":0.5},{"price":11370000.0,"size":0.015},{"price":11368516.0,"size":0.0526176},{"price":11368376.0,"size":0.01},{"price":11368353.0,"size":0.01},{"price":11366248.0,"size":3.11578742},{"price":11366247.0,"size":0.036},{"price":11366008.0,"size":0.04},{"price":11364930.0,"size":0.0527},{"price":11363829.0,"size":0.01},{"price":11362278.0,"size":0.31206306},{"price":11362277.0,"size":0.9772867},{"price":11362045.0,"size":0.05},{"price":11361538.0,"size":1.50015},{"price":11361476.0,"size":0.05},{"price":11358376.0,"size":0.01},{"price":11354042.0,"size":0.2872},{"price":11353488.0,"size":0.27174084},{"price":11351280.0,"size":0.2739},{"price":11350000.0,"size":0.51},{"price":11348518.0,"size":0.2616},{"price":11348189.0,"size":0.003},{"price":11347667.0,"size":0.001},{"price":11347661.0,"size":0.6},{"price":11347560.0,"size":0.002},{"price":11347461.0,"size":0.002},{"price":11345756.0,"size":0.267},{"price":11345155.0,"size":0.0482554},{"price":11345154.0,"size":1.484},{"price":11344148.0,"size":0.002},{"price":11342910.0,"size":0.002},{"price":11341752.0,"size":1.966},{"price":11341671.0,"size":0.23},{"price":11340736.0,"size":0.002},{"price":11340000.0,"size":0.005},{"price":11337324.0,"size":0.002},{"price":11336383.0,"size":0.001},{"price":11336319.0,"size":0.00195},{"price":11333912.0,"size":0.002},{"price":11331227.0,"size":0.51},{"price":11331000.0,"size":0.5},{"price":11330500.0,"size":0.002},{"price":11330376.0,"size":2.036},{"price":11330000.0,"size":0.02442},{"price":11327088.0,"size":0.002},{"price":11325101.0,"size":0.001},{"price":11323676.0,"size":0.002},{"price":11320264.0,"size":0.002},{"price":11320000.0,"size":0.05},{"price":11316852.0,"size":0.002},{"price":11315000.0,"size":0.05},{"price":11314325.0,"size":1.951},{"price":11313996.0,"size":0.00195},{"price":11313819.0,"size":0.001},{"price":11310000.0,"size":0.01},{"price":11309999.0,"size":0.177},{"price":11307999.0,"size":0.01},{"price":11303918.0,"size":0.01},{"price":11303000.0,"size":0.5},{"price":11302535.0,"size":0.001},{"price":11302466.0,"size":0.001},{"price":11301268.0,"size":0.01},{"price":11300000.0,"size":3.01685256},{"price":11298000.0,"size":0.01},{"price":11296865.0,"size":0.0015},{"price":11294756.0,"size":1.0},{"price":11291282.0,"size":0.001},{"price":11291268.0,"size":0.01},{"price":11291000.0,"size":0.5},{"price":11290000.0,"size":0.003},{"price":11281268.0,"size":0.01},{"price":11280000.0,"size":0.0163},{"price":11279960.0,"size":0.001},{"price":11279282.0,"size":0.0015},{"price":11278000.0,"size":0.0025},{"price":11275000.0,"size":0.001},{"price":11274588.0,"size":0.0047},{"price":11271268.0,"size":0.01},{"price":11271000.0,"size":0.003},{"price":11270000.0,"size":0.106},{"price":11269424.0,"size":0.8},{"price":11268871.0,"size":0.28},{"price":11268638.0,"size":0.001},{"price":11268411.0,"size":0.01},{"price":11266666.0,"size":0.04},{"price":11265000.0,"size":0.02},{"price":11263000.0,"size":0.006},{"price":11262564.0,"size":0.0015},{"price":11261268.0,"size":0.01},{"price":11260000.0,"size":0.3565},{"price":11257315.0,"size":0.001},{"price":11257000.0,"size":0.001},{"price":11255200.0,"size":0.001},{"price":11255115.0,"size":0.00377},{"price":11253814.0,"size":2.2},{"price":11253690.0,"size":0.01},{"price":11253000.0,"size":0.03189},{"price":11251405.0,"size":0.139},{"price":11251268.0,"size":0.01},{"price":11251111.0,"size":0.0015},{"price":11251000.0,"size":0.0131},{"price":11250250.0,"size":0.00105},{"price":11250200.0,"size":0.001},{"price":11250005.0,"size":0.001},{"price":11250001.0,"size":0.00104},{"price":11250000.0,"size":1.62712889},{"price":11245993.0,"size":0.001},{"price":11245141.0,"size":0.0031},{"price":11245000.0,"size":0.05},{"price":11244444.0,"size":0.04},{"price":11244243.0,"size":0.01},{"price":11240200.0,"size":0.001},{"price":11240000.0,"size":0.007304},{"price":11236190.0,"size":0.01},{"price":11235200.0,"size":0.001},{"price":11234670.0,"size":0.001},{"price":11232000.0,"size":0.089},{"price":11231243.0,"size":0.01},{"price":11231000.0,"size":0.105},{"price":11230200.0,"size":0.001},{"price":11230000.0,"size":0.0308},{"price":11226952.0,"size":0.972},{"price":11224500.0,"size":0.06},{"price":11223968.0,"size":0.001},{"price":11223348.0,"size":0.001},{"price":11223344.0,"size":0.01},{"price":11223000.0,"size":0.1},{"price":11222222.0,"size":0.093525},{"price":11221120.0,"size":0.001},{"price":11220200.0,"size":0.001},{"price":11220001.0,"size":0.004457},{"price":11220000.0,"size":0.321},{"price":11219000.0,"size":0.1},{"price":11217326.0,"size":0.02},{"price":11215200.0,"size":0.001},{"price":11213690.0,"size":0.01},{"price":11212025.0,"size":0.001},{"price":11211800.0,"size":0.001},{"price":11211111.0,"size":0.06},{"price":11210200.0,"size":0.001},{"price":11210000.0,"size":0.10622},{"price":11208032.0,"size":0.01},{"price":11206000.0,"size":0.09015},{"price":11205200.0,"size":0.001},{"price":11204578.0,"size":0.002},{"price":11201000.0,"size":0.01},{"price":11200800.0,"size":0.05},{"price":11200703.0,"size":0.001},{"price":11200425.0,"size":0.1},{"price":11200200.0,"size":0.001},{"price":11200198.0,"size":0.003},{"price":11200150.0,"size":0.002},{"price":11200002.0,"size":0.001},{"price":11200001.0,"size":0.01104},{"price":11200000.0,"size":1.15226728},{"price":11198508.0,"size":0.05},{"price":11198243.0,"size":0.01},{"price":11197134.0,"size":0.993},{"price":11197000.0,"size":0.0085},{"price":11194090.0,"size":0.03},{"price":11190770.0,"size":0.0309},{"price":11190000.0,"size":0.0010016},{"price":11189555.0,"size":0.5},{"price":11189381.0,"size":0.001},{"price":11188629.0,"size":0.01},{"price":11188382.0,"size":0.001},{"price":11185000.0,"size":0.0085},{"price":11180000.0,"size":0.225},{"price":11178058.0,"size":0.001},{"price":11170000.0,"size":0.001},{"price":11169662.0,"size":0.01},{"price":11169593.0,"size":0.001},{"price":11169243.0,"size":0.01},{"price":11166736.0,"size":0.001},{"price":11164029.0,"size":0.001},{"price":11160854.0,"size":0.1},{"price":11160000.0,"size":0.02376},{"price":11155413.0,"size":0.001},{"price":11155377.0,"size":0.00636009},{"price":11153999.0,"size":0.00101},{"price":11151000.0,"size":0.001},{"price":11150250.0,"size":0.00175},{"price":11150005.0,"size":0.001},{"price":11150001.0,"size":0.00104},{"price":11150000.0,"size":0.6533956},{"price":11148000.0,"size":0.08963},{"price":11147546.0,"size":0.02},{"price":11144091.0,"size":0.001},{"price":11144000.0,"size":0.0897},{"price":11143986.0,"size":0.02},{"price":11140139.0,"size":1.0},{"price":11140000.0,"size":0.2},{"price":11136243.0,"size":0.01},{"price":11135869.0,"size":0.1},{"price":11132768.0,"size":0.001},{"price":11130000.0,"size":0.116},{"price":11129979.0,"size":0.0053908},{"price":11124900.0,"size":0.00133},{"price":11121090.0,"size":0.1},{"price":11120000.0,"size":0.0033},{"price":11118078.0,"size":0.01},{"price":11111800.0,"size":0.001},{"price":11111111.0,"size":0.2919257},{"price":11111000.0,"size":0.003},{"price":11110594.0,"size":0.001},{"price":11110000.0,"size":0.021007},{"price":11109662.0,"size":0.01},{"price":11108008.0,"size":0.01},{"price":11102000.0,"size":0.5},{"price":11101297.0,"size":0.001},{"price":11100005.0,"size":0.001},{"price":11100001.0,"size":0.01104},{"price":11100000.0,"size":1.6532049},{"price":11099141.0,"size":0.01},{"price":11098833.0,"size":0.002},{"price":11096243.0,"size":0.01},{"price":11094090.0,"size":0.01},{"price":11088888.0,"size":0.001},{"price":11085245.0,"size":0.001},{"price":11080200.0,"size":0.001},{"price":11080000.0,"size":0.0223},{"price":11075100.0,"size":0.003},{"price":11070200.0,"size":0.001},{"price":11070000.0,"size":0.0902},{"price":11065200.0,"size":0.001},{"price":11064370.0,"size":0.00497091},{"price":11060200.0,"size":0.001},{"price":11060000.0,"size":0.145},{"price":11059689.0,"size":0.009},{"price":11056428.0,"size":0.002},{"price":11055500.0,"size":0.02},{"price":11055200.0,"size":0.001},{"price":11055100.0,"size":0.003},{"price":11050200.0,"size":0.001},{"price":11050005.0,"size":0.001},{"price":11050002.0,"size":0.001},{"price":11050001.0,"size":0.00104},{"price":11050000.0,"size":0.39576147},{"price":11048064.0,"size":2.0},{"price":11046420.0,"size":0.2},{"price":11044243.0,"size":0.01},{"price":11041380.0,"size":0.01},{"price":11040200.0,"size":0.001},{"price":11040000.0,"size":0.00777181},{"price":11035865.0,"size":0.1},{"price":11035200.0,"size":0.001},{"price":11035000.0,"size":0.0013},{"price":11030200.0,"size":0.001},{"price":11030000.0,"size":0.025},{"price":11025500.0,"size":0.009531},{"price":11025200.0,"size":0.001},{"price":11025000.0,"size":0.71497},{"price":11020772.0,"size":0.014},{"price":11020200.0,"size":0.002},{"price":11020000.0,"size":0.005},{"price":11015200.0,"size":0.001},{"price":11012000.0,"size":0.1},{"price":11011800.0,"size":0.001},{"price":11010200.0,"size":0.001},{"price":11010000.0,"size":0.347},{"price":11007277.0,"size":0.01},{"price":11005200.0,"size":0.001},{"price":11004890.0,"size":0.001535},{"price":11003000.0,"size":0.0155},{"price":11001000.0,"size":0.013},{"price":11000500.0,"size":0.05117658},{"price":11000200.0,"size":0.001},{"price":11000002.0,"size":0.004},{"price":11000001.0,"size":0.02604},{"price":11000000.0,"size":4.53923365},{"price":10999999.0,"size":0.003},{"price":10999000.0,"size":0.001},{"price":10996855.0,"size":0.0011},{"price":10995200.0,"size":0.001},{"price":10994499.0,"size":0.00169176},{"price":10990200.0,"size":0.001},{"price":10990000.0,"size":0.10219},{"price":10989001.0,"size":0.00197},{"price":10988999.0,"size":0.001},{"price":10988324.0,"size":0.002},{"price":10987654.0,"size":0.001},{"price":10985200.0,"size":0.001},{"price":10985150.0,"size":0.01},{"price":10980500.0,"size":0.005},{"price":10980200.0,"size":0.001},{"price":10980002.0,"size":0.4},{"price":10980000.0,"size":0.028},{"price":10975200.0,"size":0.001},{"price":10975000.0,"size":0.1},{"price":10971261.0,"size":0.001},{"price":10971243.0,"size":0.01},{"price":10970200.0,"size":0.001},{"price":10970000.0,"size":0.09304},{"price":10966600.0,"size":0.001003},{"price":10965200.0,"size":0.001}],"asks":[{"price":11380153.0,"size":0.04800739},{"price":11380154.0,"size":0.07854053},{"price":11380742.0,"size":0.014652},{"price":11381129.0,"size":0.014712},{"price":11381234.0,"size":0.02},{"price":11381595.0,"size":0.02},{"price":11381668.0,"size":0.01482},{"price":11382077.0,"size":0.01001785},{"price":11382109.0,"size":0.301},{"price":11382750.0,"size":0.234},{"price":11384871.0,"size":0.2657},{"price":11384930.0,"size":0.01566},{"price":11385583.0,"size":0.0526176},{"price":11387174.0,"size":0.1},{"price":11387633.0,"size":0.2976},{"price":11389572.0,"size":0.57250406},{"price":11389573.0,"size":0.0044},{"price":11390395.0,"size":0.2948},{"price":11391432.0,"size":0.4249},{"price":11392010.0,"size":0.00142446},{"price":11393747.0,"size":1.189881},{"price":11394441.0,"size":1.189881},{"price":11394975.0,"size":0.0526},{"price":11397000.0,"size":0.02},{"price":11398444.0,"size":0.001995},{"price":11398845.0,"size":0.001},{"price":11399673.0,"size":0.0015},{"price":11399700.0,"size":0.001},{"price":11399999.0,"size":0.05},{"price":11400000.0,"size":1.04832841},{"price":11403472.0,"size":0.002},{"price":11405000.0,"size":0.1575},{"price":11408363.0,"size":1.489},{"price":11408700.0,"size":0.001},{"price":11409414.0,"size":1.60199848},{"price":11409415.0,"size":0.005},{"price":11409925.0,"size":0.22},{"price":11410000.0,"size":0.3787},{"price":11410168.0,"size":0.001},{"price":11410853.0,"size":0.002},{"price":11412000.0,"size":0.0878},{"price":11415000.0,"size":0.1},{"price":11415141.0,"size":0.0041},{"price":11415674.0,"size":1.928},{"price":11417481.0,"size":0.0015},{"price":11418700.0,"size":0.001},{"price":11419000.0,"size":0.01},{"price":11420000.0,"size":0.261},{"price":11421268.0,"size":0.05},{"price":11421490.0,"size":0.001},{"price":11424296.0,"size":0.002},{"price":11425000.0,"size":0.029},{"price":11426426.0,"size":0.002},{"price":11428121.0,"size":0.002},{"price":11428700.0,"size":0.001},{"price":11429302.0,"size":0.01},{"price":11430000.0,"size":0.4098},{"price":11432718.0,"size":0.002},{"price":11432813.0,"size":0.001},{"price":11433211.0,"size":0.03},{"price":11433333.0,"size":0.001},{"price":11437315.0,"size":0.002},{"price":11438525.0,"size":0.0011},{"price":11438700.0,"size":0.001},{"price":11439557.0,"size":0.001},{"price":11440000.0,"size":0.2538},{"price":11441911.0,"size":0.002},{"price":11442627.0,"size":2.018},{"price":11443629.0,"size":0.002},{"price":11444135.0,"size":0.001},{"price":11445433.0,"size":0.0015},{"price":11446508.0,"size":0.001},{"price":11447000.0,"size":0.01},{"price":11447071.0,"size":0.002},{"price":11448000.0,"size":0.0875},{"price":11448700.0,"size":0.001},{"price":11450000.0,"size":0.268},{"price":11451105.0,"size":0.002},{"price":11453321.0,"size":0.03},{"price":11455000.0,"size":0.001},{"price":11455457.0,"size":0.001},{"price":11455702.0,"size":0.002},{"price":11458700.0,"size":0.001},{"price":11458988.0,"size":0.01},{"price":11460000.0,"size":0.06702},{"price":11460299.0,"size":0.002},{"price":11463288.0,"size":0.01},{"price":11464896.0,"size":0.002},{"price":11465382.0,"size":0.00195},{"price":11465421.0,"size":1.943},{"price":11466780.0,"size":0.001},{"price":11468700.0,"size":0.001},{"price":11470000.0,"size":0.06},{"price":11471000.0,"size":0.01},{"price":11475000.0,"size":0.0028},{"price":11476929.0,"size":1.0},{"price":11478102.0,"size":0.001},{"price":11478431.0,"size":0.002},{"price":11478700.0,"size":0.001},{"price":11480000.0,"size":0.40191},{"price":11485000.0,"size":0.01},{"price":11485488.0,"size":2.0},{"price":11486555.0,"size":0.03},{"price":11487685.0,"size":0.01},{"price":11488000.0,"size":0.102},{"price":11488700.0,"size":0.001},{"price":11489425.0,"size":0.001},{"price":11490000.0,"size":0.05},{"price":11490841.0,"size":0.002},{"price":11495450.0,"size":0.002},{"price":11495850.0,"size":0.001},{"price":11498700.0,"size":0.001},{"price":11498917.0,"size":0.002},{"price":11499000.0,"size":0.01},{"price":11500000.0,"size":0.77159519},{"price":11500078.0,"size":0.93},{"price":11500747.0,"size":0.001},{"price":11502377.0,"size":0.002},{"price":11502800.0,"size":0.00132},{"price":11503108.0,"size":0.0198},{"price":11505000.0,"size":0.0028},{"price":11505001.0,"size":0.002},{"price":11505836.0,"size":0.003},{"price":11508431.0,"size":0.047},{"price":11508700.0,"size":0.001},{"price":11508888.0,"size":0.02},{"price":11510000.0,"size":0.1476},{"price":11512070.0,"size":0.001},{"price":11513633.0,"size":0.08},{"price":11514332.0,"size":0.02},{"price":11518700.0,"size":0.001},{"price":11518992.0,"size":0.002},{"price":11519855.0,"size":0.01},{"price":11520000.0,"size":0.001},{"price":11522388.0,"size":0.972},{"price":11523211.0,"size":0.01},{"price":11524999.0,"size":0.001},{"price":11528700.0,"size":0.001},{"price":11529852.0,"size":0.01},{"price":11530000.0,"size":0.261},{"price":11533985.0,"size":0.002},{"price":11534084.0,"size":0.001},{"price":11535321.0,"size":0.01},{"price":11538666.0,"size":0.002},{"price":11538700.0,"size":0.001},{"price":11540000.0,"size":0.0048},{"price":11540357.0,"size":0.002},{"price":11541011.0,"size":0.005},{"price":11541109.0,"size":0.01},{"price":11544663.0,"size":0.002},{"price":11545262.0,"size":0.002},{"price":11546541.0,"size":0.01},{"price":11548144.0,"size":0.002},{"price":11548700.0,"size":0.001},{"price":11550000.0,"size":0.014},{"price":11551109.0,"size":0.01},{"price":11551625.0,"size":0.002},{"price":11552111.0,"size":0.01},{"price":11553687.0,"size":0.1},{"price":11555106.0,"size":0.002},{"price":11555115.0,"size":0.001},{"price":11556000.0,"size":0.1},{"price":11558587.0,"size":0.002},{"price":11558700.0,"size":0.001},{"price":11559855.0,"size":0.01},{"price":11560831.0,"size":0.0198},{"price":11561109.0,"size":0.01},{"price":11562000.0,"size":0.087},{"price":11562068.0,"size":0.002},{"price":11563750.0,"size":0.08739676},{"price":11565548.0,"size":0.002},{"price":11566139.0,"size":0.0228},{"price":11566551.0,"size":0.01},{"price":11568700.0,"size":0.001},{"price":11569029.0,"size":0.002},{"price":11570196.0,"size":0.002},{"price":11571109.0,"size":0.01},{"price":11572510.0,"size":0.002},{"price":11573211.0,"size":0.01},{"price":11574840.0,"size":0.002},{"price":11575991.0,"size":0.001},{"price":11578700.0,"size":0.001},{"price":11579484.0,"size":0.002},{"price":11579851.0,"size":0.01},{"price":11580000.0,"size":0.7835},{"price":11581109.0,"size":0.01},{"price":11584128.0,"size":0.002},{"price":11585000.0,"size":0.002},{"price":11586532.0,"size":0.01},{"price":11587498.0,"size":0.0198},{"price":11588700.0,"size":0.001},{"price":11588800.0,"size":0.02},{"price":11590000.0,"size":0.1},{"price":11590749.0,"size":0.002},{"price":11591109.0,"size":0.01},{"price":11593211.0,"size":0.01},{"price":11596753.0,"size":0.002},{"price":11598111.0,"size":0.1474},{"price":11598555.0,"size":0.01},{"price":11598700.0,"size":0.001},{"price":11599999.0,"size":0.001},{"price":11600000.0,"size":3.655},{"price":11601109.0,"size":0.02},{"price":11603764.0,"size":0.9},{"price":11606655.0,"size":0.01},{"price":11610000.0,"size":0.302},{"price":11611109.0,"size":0.01},{"price":11613321.0,"size":0.01},{"price":11620000.0,"size":1.35441682},{"price":11621011.0,"size":0.01},{"price":11621109.0,"size":0.01},{"price":11623096.0,"size":0.008},{"price":11625703.0,"size":0.012},{"price":11629000.0,"size":0.1},{"price":11630000.0,"size":0.201},{"price":11631059.0,"size":0.01},{"price":11631479.0,"size":0.01},{"price":11631773.0,"size":0.00386871},{"price":11635950.0,"size":0.001},{"price":11638259.0,"size":0.001},{"price":11639700.0,"size":0.001},{"price":11640000.0,"size":1.0},{"price":11640820.0,"size":0.01},{"price":11649900.0,"size":0.02906},{"price":11649999.0,"size":0.001},{"price":11650000.0,"size":0.593},{"price":11651059.0,"size":0.01},{"price":11653658.0,"size":0.008},{"price":11654321.0,"size":0.001},{"price":11659700.0,"size":0.001},{"price":11661479.0,"size":0.01},{"price":11666000.0,"size":0.001},{"price":11666666.0,"size":0.013},{"price":11669700.0,"size":0.001},{"price":11671059.0,"size":0.01},{"price":11672562.0,"size":0.0198},{"price":11680000.0,"size":0.014},{"price":11685000.0,"size":0.003},{"price":11688000.0,"size":0.001},{"price":11689732.0,"size":0.01},{"price":11690330.0,"size":0.0198},{"price":11691059.0,"size":0.01},{"price":11692558.0,"size":0.01},{"price":11695019.0,"size":0.0064},{"price":11698800.0,"size":0.00131},{"price":11699000.0,"size":0.001},{"price":11699631.0,"size":0.001},{"price":11699998.0,"size":0.01},{"price":11699999.0,"size":0.001},{"price":11700000.0,"size":1.2573},{"price":11701059.0,"size":0.01},{"price":11720000.0,"size":0.1},{"price":11721059.0,"size":0.01},{"price":11725000.0,"size":0.005},{"price":11726791.0,"size":0.01},{"price":11727418.0,"size":1.8},{"price":11728195.0,"size":0.05},{"price":11730000.0,"size":1.9712},{"price":11740000.0,"size":0.101},{"price":11741059.0,"size":0.01},{"price":11748937.0,"size":0.001},{"price":11749999.0,"size":0.001},{"price":11750000.0,"size":0.89537866},{"price":11750050.0,"size":0.2},{"price":11751151.0,"size":0.01},{"price":11751406.0,"size":0.012},{"price":11755000.0,"size":0.001},{"price":11757860.0,"size":1.82},{"price":11759999.0,"size":0.001},{"price":11760000.0,"size":0.001},{"price":11761059.0,"size":0.02},{"price":11765432.0,"size":0.001},{"price":11768000.0,"size":0.01},{"price":11770000.0,"size":0.25464896},{"price":11771059.0,"size":0.01755555},{"price":11772000.0,"size":0.002},{"price":11775000.0,"size":0.11593},{"price":11775222.0,"size":0.001657},{"price":11775577.0,"size":0.00013523},{"price":11775800.0,"size":0.001},{"price":11775900.0,"size":0.2},{"price":11775989.0,"size":0.005},{"price":11777000.0,"size":0.5956},{"price":11777777.0,"size":0.0067},{"price":11778541.0,"size":0.001},{"price":11779807.0,"size":0.001},{"price":11780000.0,"size":0.74298},{"price":11780800.0,"size":0.1},{"price":11781059.0,"size":0.01},{"price":11781238.0,"size":0.008},{"price":11785000.0,"size":0.055},{"price":11785040.0,"size":0.01},{"price":11786000.0,"size":0.585},{"price":11788000.0,"size":0.001},{"price":11788888.0,"size":0.005},{"price":11789000.0,"size":0.2},{"price":11789732.0,"size":0.01},{"price":11791100.0,"size":0.1},{"price":11791151.0,"size":0.01},{"price":11795000.0,"size":0.021}]}}}
{"schema_version":"collector.vnext.raw","schema_contract":null,"schema_contract_version":null,"payload_contract_version":null,"record_type":"market.orderbook.diff","record_id":"collector_main-market-orderbook-diff-000000000061","collector_id":"collector_main","collector_role":"production","host_name":"MAIN-PC","session_id":"collector_main-sess-20260315T000515Z-beb502e7","stream_session_id":"collector_main-stream-bitflyer-board_ws-20260315T000523Z-812bdb19","exchange":"bitflyer","market":"spot","symbol":"BTC_JPY","instrument_id":"bitflyer.spot.BTC_JPY","channel":"board_ws","transport":"websocket","source_event_id":null,"source_sequence":null,"sequence_id":61,"exchange_ts":null,"collector_ts":"2026-03-15T00:05:23Z","ingest_ts":"2026-03-15T00:05:23Z","event_ts":"2026-03-15T00:05:23Z","quality_flags":[],"is_partial":false,"is_reconstructed":false,"confidence_score":1.0,"payload":{"provider":"bitflyer_ws_board","exchange":"bitflyer","transport":"websocket","channel":"lightning_board_BTC_JPY","received_ts":"2026-03-15T00:05:23.525049Z","subscription_id":null,"message_id":null,"source_sequence":null,"raw_message_meta":{"raw_channel":"lightning_board_BTC_JPY","subscription_channel":"lightning_board_BTC_JPY","recv_timeout_sec":10,"ssl_verify":false,"socket_url":"wss://ws.lightstream.bitflyer.com/json-rpc"},"source_payload":{"mid_price":11384926.0,"bids":[{"price":11382806.0,"size":0.0}],"asks":[{"price":11386771.0,"size":0.06187484},{"price":11389569.0,"size":0.04360643}]}}}
{"schema_version":"collector.vnext.raw","schema_contract":null,"schema_contract_version":null,"payload_contract_version":null,"record_type":"market.orderbook.diff","record_id":"collector_main-market-orderbook-diff-000000000065","collector_id":"collector_main","collector_role":"production","host_name":"MAIN-PC","session_id":"collector_main-sess-20260315T000515Z-beb502e7","stream_session_id":"collector_main-stream-bitflyer-board_ws-20260315T000523Z-812bdb19","exchange":"bitflyer","market":"spot","symbol":"BTC_JPY","instrument_id":"bitflyer.spot.BTC_JPY","channel":"board_ws","transport":"websocket","source_event_id":null,"source_sequence":null,"sequence_id":65,"exchange_ts":null,"collector_ts":"2026-03-15T00:05:23Z","ingest_ts":"2026-03-15T00:05:23Z","event_ts":"2026-03-15T00:05:23Z","quality_flags":[],"is_partial":false,"is_reconstructed":false,"confidence_score":1.0,"payload":{"provider":"bitflyer_ws_board","exchange":"bitflyer","transport":"websocket","channel":"lightning_board_BTC_JPY","received_ts":"2026-03-15T00:05:23.625413Z","subscription_id":null,"message_id":null,"source_sequence":null,"raw_message_meta":{"raw_channel":"lightning_board_BTC_JPY","subscription_channel":"lightning_board_BTC_JPY","recv_timeout_sec":10,"ssl_verify":false,"socket_url":"wss://ws.lightstream.bitflyer.com/json-rpc"},"source_payload":{"mid_price":11384926.0,"bids":[{"price":11383080.0,"size":0.0}],"asks":[{"price":11390047.0,"size":0.0}]}}}
{"schema_version":"collector.vnext.raw","schema_contract":null,"schema_contract_version":null,"payload_contract_version":null,"record_type":"market.orderbook.diff","record_id":"collector_main-market-orderbook-diff-000000000067","collector_id":"collector_main","collector_role":"production","host_name":"MAIN-PC","session_id":"collector_main-sess-20260315T000515Z-beb502e7","stream_session_id":"collector_main-stream-bitflyer-board_ws-20260315T000523Z-812bdb19","exchange":"bitflyer","market":"spot","symbol":"BTC_JPY","instrument_id":"bitflyer.spot.BTC_JPY","channel":"board_ws","transport":"websocket","source_event_id":null,"source_sequence":null,"sequence_id":67,"exchange_ts":null,"collector_ts":"2026-03-15T00:05:23Z","ingest_ts":"2026-03-15T00:05:23Z","event_ts":"2026-03-15T00:05:23Z","quality_flags":[],"is_partial":false,"is_reconstructed":false,"confidence_score":1.0,"payload":{"provider":"bitflyer_ws_board","exchange":"bitflyer","transport":"websocket","channel":"lightning_board_BTC_JPY","received_ts":"2026-03-15T00:05:23.732203Z","subscription_id":null,"message_id":null,"source_sequence":null,"raw_message_meta":{"raw_channel":"lightning_board_BTC_JPY","subscription_channel":"lightning_board_BTC_JPY","recv_timeout_sec":10,"ssl_verify":false,"socket_url":"wss://ws.lightstream.bitflyer.com/json-rpc"},"source_payload":{"mid_price":11384926.0,"bids":[{"price":11371638.0,"size":0.07},{"price":11382448.0,"size":0.0108987}],"asks":[{"price":11389672.0,"size":0.02},{"price":11389570.0,"size":0.0}]}}}
{"schema_version":"collector.vnext.raw","schema_contract":null,"schema_contract_version":null,"payload_contract_version":null,"record_type":"market.orderbook.diff","record_id":"collector_main-market-orderbook-diff-000000000069","collector_id":"collector_main","collector_role":"production","host_name":"MAIN-PC","session_id":"collector_main-sess-20260315T000515Z-beb502e7","stream_session_id":"collector_main-stream-bitflyer-board_ws-20260315T000523Z-812bdb19","exchange":"bitflyer","market":"spot","symbol":"BTC_JPY","instrument_id":"bitflyer.spot.BTC_JPY","channel":"board_ws","transport":"websocket","source_event_id":null,"source_sequence":null,"sequence_id":69,"exchange_ts":null,"collector_ts":"2026-03-15T00:05:23Z","ingest_ts":"2026-03-15T00:05:23Z","event_ts":"2026-03-15T00:05:23Z","quality_flags":[],"is_partial":false,"is_reconstructed":false,"confidence_score":1.0,"payload":{"provider":"bitflyer_ws_board","exchange":"bitflyer","transport":"websocket","channel":"lightning_board_BTC_JPY","received_ts":"2026-03-15T00:05:23.829415Z","subscription_id":null,"message_id":null,"source_sequence":null,"raw_message_meta":{"raw_channel":"lightning_board_BTC_JPY","subscription_channel":"lightning_board_BTC_JPY","recv_timeout_sec":10,"ssl_verify":false,"socket_url":"wss://ws.lightstream.bitflyer.com/json-rpc"},"source_payload":{"mid_price":11384609.0,"bids":[{"price":11383081.0,"size":0.0}],"asks":[]}}}
{"schema_version":"collector.vnext.raw","schema_contract":null,"schema_contract_version":null,"payload_contract_version":null,"record_type":"market.orderbook.diff","record_id":"collector_main-market-orderbook-diff-000000000071","collector_id":"collector_main","collector_role":"production","host_name":"MAIN-PC","session_id":"collector_main-sess-20260315T000515Z-beb502e7","stream_session_id":"collector_main-stream-bitflyer-board_ws-20260315T000523Z-812bdb19","exchange":"bitflyer","market":"spot","symbol":"BTC_JPY","instrument_id":"bitflyer.spot.BTC_JPY","channel":"board_ws","transport":"websocket","source_event_id":null,"source_sequence":null,"sequence_id":71,"exchange_ts":null,"collector_ts":"2026-03-15T00:05:23Z","ingest_ts":"2026-03-15T00:05:23Z","event_ts":"2026-03-15T00:05:23Z","quality_flags":[],"is_partial":false,"is_reconstructed":false,"confidence_score":1.0,"payload":{"provider":"bitflyer_ws_board","exchange":"bitflyer","transport":"websocket","channel":"lightning_board_BTC_JPY","received_ts":"2026-03-15T00:05:23.942410Z","subscription_id":null,"message_id":null,"source_sequence":null,"raw_message_meta":{"raw_channel":"lightning_board_BTC_JPY","subscription_channel":"lightning_board_BTC_JPY","recv_timeout_sec":10,"ssl_verify":false,"socket_url":"wss://ws.lightstream.bitflyer.com/json-rpc"},"source_payload":{"mid_price":11384609.0,"bids":[{"price":11370500.0,"size":0.07},{"price":11372777.0,"size":0.08}],"asks":[]}}}
{"schema_version":"collector.vnext.raw","schema_contract":null,"schema_contract_version":null,"payload_contract_version":null,"record_type":"market.orderbook.diff","record_id":"collector_main-market-orderbook-diff-000000000073","collector_id":"collector_main","collector_role":"production","host_name":"MAIN-PC","session_id":"collector_main-sess-20260315T000515Z-beb502e7","stream_session_id":"collector_main-stream-bitflyer-board_ws-20260315T000523Z-812bdb19","exchange":"bitflyer","market":"spot","symbol":"BTC_JPY","instrument_id":"bitflyer.spot.BTC_JPY","channel":"board_ws","transport":"websocket","source_event_id":null,"source_sequence":null,"sequence_id":73,"exchange_ts":null,"collector_ts":"2026-03-15T00:05:24Z","ingest_ts":"2026-03-15T00:05:24Z","event_ts":"2026-03-15T00:05:24Z","quality_flags":[],"is_partial":false,"is_reconstructed":false,"confidence_score":1.0,"payload":{"provider":"bitflyer_ws_board","exchange":"bitflyer","transport":"websocket","channel":"lightning_board_BTC_JPY","received_ts":"2026-03-15T00:05:24.053002Z","subscription_id":null,"message_id":null,"source_sequence":null,"raw_message_meta":{"raw_channel":"lightning_board_BTC_JPY","subscription_channel":"lightning_board_BTC_JPY","recv_timeout_sec":10,"ssl_verify":false,"socket_url":"wss://ws.lightstream.bitflyer.com/json-rpc"},"source_payload":{"mid_price":11384609.0,"bids":[{"price":11368223.0,"size":0.23},{"price":11378083.0,"size":0.0}],"asks":[{"price":11389569.0,"size":0.0},{"price":11389571.0,"size":0.04159623},{"price":11389360.0,"size":0.0},{"price":11390046.0,"size":0.0}]}}}
{"schema_version":"collector.vnext.raw","schema_contract":null,"schema_contract_version":null,"payload_contract_version":null,"record_type":"market.orderbook.diff","record_id":"collector_main-market-orderbook-diff-000000000075","collector_id":"collector_main","collector_role":"production","host_name":"MAIN-PC","session_id":"collector_main-sess-20260315T000515Z-beb502e7","stream_session_id":"collector_main-stream-bitflyer-board_ws-20260315T000523Z-812bdb19","exchange":"bitflyer","market":"spot","symbol":"BTC_JPY","instrument_id":"bitflyer.spot.BTC_JPY","channel":"board_ws","transport":"websocket","source_event_id":null,"source_sequence":null,"sequence_id":75,"exchange_ts":null,"collector_ts":"2026-03-15T00:05:24Z","ingest_ts":"2026-03-15T00:05:24Z","event_ts":"2026-03-15T00:05:24Z","quality_flags":[],"is_partial":false,"is_reconstructed":false,"confidence_score":1.0,"payload":{"provider":"bitflyer_ws_board","exchange":"bitflyer","transport":"websocket","channel":"lightning_board_BTC_JPY","received_ts":"2026-03-15T00:05:24.160691Z","subscription_id":null,"message_id":null,"source_sequence":null,"raw_message_meta":{"raw_channel":"lightning_board_BTC_JPY","subscription_channel":"lightning_board_BTC_JPY","recv_timeout_sec":10,"ssl_verify":false,"socket_url":"wss://ws.lightstream.bitflyer.com/json-rpc"},"source_payload":{"mid_price":11384609.0,"bids":[{"price":11378428.0,"size":0.005}],"asks":[{"price":11399534.0,"size":0.2},{"price":11398458.0,"size":0.0},{"price":11389571.0,"size":0.0},{"price":11389568.0,"size":0.06144315}]}}}
{"schema_version":"collector.vnext.raw","schema_contract":null,"schema_contract_version":null,"payload_contract_version":null,"record_type":"market.orderbook.diff","record_id":"collector_main-market-orderbook-diff-000000000077","collector_id":"collector_main","collector_role":"production","host_name":"MAIN-PC","session_id":"collector_main-sess-20260315T000515Z-beb502e7","stream_session_id":"collector_main-stream-bitflyer-board_ws-20260315T000523Z-812bdb19","exchange":"bitflyer","market":"spot","symbol":"BTC_JPY","instrument_id":"bitflyer.spot.BTC_JPY","channel":"board_ws","transport":"websocket","source_event_id":null,"source_sequence":null,"sequence_id":77,"exchange_ts":null,"collector_ts":"2026-03-15T00:05:24Z","ingest_ts":"2026-03-15T00:05:24Z","event_ts":"2026-03-15T00:05:24Z","quality_flags":[],"is_partial":false,"is_reconstructed":false,"confidence_score":1.0,"payload":{"provider":"bitflyer_ws_board","exchange":"bitflyer","transport":"websocket","channel":"lightning_board_BTC_JPY","received_ts":"2026-03-15T00:05:24.266441Z","subscription_id":null,"message_id":null,"source_sequence":null,"raw_message_meta":{"raw_channel":"lightning_board_BTC_JPY","subscription_channel":"lightning_board_BTC_JPY","recv_timeout_sec":10,"ssl_verify":false,"socket_url":"wss://ws.lightstream.bitflyer.com/json-rpc"},"source_payload":{"mid_price":11384609.0,"bids":[],"asks":[{"price":11389568.0,"size":0.02},{"price":11390045.0,"size":0.02},{"price":11389571.0,"size":0.04108111}]}}}
{"schema_version":"collector.vnext.raw","schema_contract":null,"schema_contract_version":null,"payload_contract_version":null,"record_type":"market.orderbook.diff","record_id":"collector_main-market-orderbook-diff-000000000079","collector_id":"collector_main","collector_role":"production","host_name":"MAIN-PC","session_id":"collector_main-sess-20260315T000515Z-beb502e7","stream_session_id":"collector_main-stream-bitflyer-board_ws-20260315T000523Z-812bdb19","exchange":"bitflyer","market":"spot","symbol":"BTC_JPY","instrument_id":"bitflyer.spot.BTC_JPY","channel":"board_ws","transport":"websocket","source_event_id":null,"source_sequence":null,"sequence_id":79,"exchange_ts":null,"collector_ts":"2026-03-15T00:05:24Z","ingest_ts":"2026-03-15T00:05:24Z","event_ts":"2026-03-15T00:05:24Z","quality_flags":[],"is_partial":false,"is_reconstructed":false,"confidence_score":1.0,"payload":{"provider":"bitflyer_ws_board","exchange":"bitflyer","transport":"websocket","channel":"lightning_board_BTC_JPY","received_ts":"2026-03-15T00:05:24.494526Z","subscription_id":null,"message_id":null,"source_sequence":null,"raw_message_meta":{"raw_channel":"lightning_board_BTC_JPY","subscription_channel":"lightning_board_BTC_JPY","recv_timeout_sec":10,"ssl_verify":false,"socket_url":"wss://ws.lightstream.bitflyer.com/json-rpc"},"source_payload":{"mid_price":11384609.0,"bids":[],"asks":[{"price":11389395.0,"size":0.0154534},{"price":11389571.0,"size":0.0}]}}}
{"schema_version":"collector.vnext.raw","schema_contract":null,"schema_contract_version":null,"payload_contract_version":null,"record_type":"market.orderbook.diff","record_id":"collector_main-market-orderbook-diff-000000000081","collector_id":"collector_main","collector_role":"production","host_name":"MAIN-PC","session_id":"collector_main-sess-20260315T000515Z-beb502e7","stream_session_id":"collector_main-stream-bitflyer-board_ws-20260315T000523Z-812bdb19","exchange":"bitflyer","market":"spot","symbol":"BTC_JPY","instrument_id":"bitflyer.spot.BTC_JPY","channel":"board_ws","transport":"websocket","source_event_id":null,"source_sequence":null,"sequence_id":81,"exchange_ts":null,"collector_ts":"2026-03-15T00:05:24Z","ingest_ts":"2026-03-15T00:05:24Z","event_ts":"2026-03-15T00:05:24Z","quality_flags":[],"is_partial":false,"is_reconstructed":false,"confidence_score":1.0,"payload":{"provider":"bitflyer_ws_board","exchange":"bitflyer","transport":"websocket","channel":"lightning_board_BTC_JPY","received_ts":"2026-03-15T00:05:24.594490Z","subscription_id":null,"message_id":null,"source_sequence":null,"raw_message_meta":{"raw_channel":"lightning_board_BTC_JPY","subscription_channel":"lightning_board_BTC_JPY","recv_timeout_sec":10,"ssl_verify":false,"socket_url":"wss://ws.lightstream.bitflyer.com/json-rpc"},"source_payload":{"mid_price":11384609.0,"bids":[],"asks":[{"price":11389567.0,"size":0.04499521},{"price":11389568.0,"size":0.0},{"price":11390045.0,"size":0.0},{"price":11389570.0,"size":0.02}]}}}
{"schema_version":"collector.vnext.raw","schema_contract":null,"schema_contract_version":null,"payload_contract_version":null,"record_type":"market.orderbook.diff","record_id":"collector_main-market-orderbook-diff-000000000083","collector_id":"collector_main","collector_role":"production","host_name":"MAIN-PC","session_id":"collector_main-sess-20260315T000515Z-beb502e7","stream_session_id":"collector_main-stream-bitflyer-board_ws-20260315T000523Z-812bdb19","exchange":"bitflyer","market":"spot","symbol":"BTC_JPY","instrument_id":"bitflyer.spot.BTC_JPY","channel":"board_ws","transport":"websocket","source_event_id":null,"source_sequence":null,"sequence_id":83,"exchange_ts":null,"collector_ts":"2026-03-15T00:05:24Z","ingest_ts":"2026-03-15T00:05:24Z","event_ts":"2026-03-15T00:05:24Z","quality_flags":[],"is_partial":false,"is_reconstructed":false,"confidence_score":1.0,"payload":{"provider":"bitflyer_ws_board","exchange":"bitflyer","transport":"websocket","channel":"lightning_board_BTC_JPY","received_ts":"2026-03-15T00:05:24.705075Z","subscription_id":null,"message_id":null,"source_sequence":null,"raw_message_meta":{"raw_channel":"lightning_board_BTC_JPY","subscription_channel":"lightning_board_BTC_JPY","recv_timeout_sec":10,"ssl_verify":false,"socket_url":"wss://ws.lightstream.bitflyer.com/json-rpc"},"source_payload":{"mid_price":11384592.0,"bids":[{"price":11382448.0,"size":0.0},{"price":11371638.0,"size":0.0}],"asks":[{"price":11389164.0,"size":0.0223}]}}}
{"schema_version":"collector.vnext.raw","schema_contract":null,"schema_contract_version":null,"payload_contract_version":null,"record_type":"market.orderbook.diff","record_id":"collector_main-market-orderbook-diff-000000000085","collector_id":"collector_main","collector_role":"production","host_name":"MAIN-PC","session_id":"collector_main-sess-20260315T000515Z-beb502e7","stream_session_id":"collector_main-stream-bitflyer-board_ws-20260315T000523Z-812bdb19","exchange":"bitflyer","market":"spot","symbol":"BTC_JPY","instrument_id":"bitflyer.spot.BTC_JPY","channel":"board_ws","transport":"websocket","source_event_id":null,"source_sequence":null,"sequence_id":85,"exchange_ts":null,"collector_ts":"2026-03-15T00:05:24Z","ingest_ts":"2026-03-15T00:05:24Z","event_ts":"2026-03-15T00:05:24Z","quality_flags":[],"is_partial":false,"is_reconstructed":false,"confidence_score":1.0,"payload":{"provider":"bitflyer_ws_board","exchange":"bitflyer","transport":"websocket","channel":"lightning_board_BTC_JPY","received_ts":"2026-03-15T00:05:24.829086Z","subscription_id":null,"message_id":null,"source_sequence":null,"raw_message_meta":{"raw_channel":"lightning_board_BTC_JPY","subscription_channel":"lightning_board_BTC_JPY","recv_timeout_sec":10,"ssl_verify":false,"socket_url":"wss://ws.lightstream.bitflyer.com/json-rpc"},"source_payload":{"mid_price":11384836.0,"bids":[{"price":11382901.0,"size":0.1275}],"asks":[{"price":11389567.0,"size":0.0},{"price":11389569.0,"size":0.04173365}]}}}
{"schema_version":"collector.vnext.raw","schema_contract":null,"schema_contract_version":null,"payload_contract_version":null,"record_type":"market.orderbook.diff","record_id":"collector_main-market-orderbook-diff-000000000087","collector_id":"collector_main","collector_role":"production","host_name":"MAIN-PC","session_id":"collector_main-sess-20260315T000515Z-beb502e7","stream_session_id":"collector_main-stream-bitflyer-board_ws-20260315T000523Z-812bdb19","exchange":"bitflyer","market":"spot","symbol":"BTC_JPY","instrument_id":"bitflyer.spot.BTC_JPY","channel":"board_ws","transport":"websocket","source_event_id":null,"source_sequence":null,"sequence_id":87,"exchange_ts":null,"collector_ts":"2026-03-15T00:05:24Z","ingest_ts":"2026-03-15T00:05:24Z","event_ts":"2026-03-15T00:05:24Z","quality_flags":[],"is_partial":false,"is_reconstructed":false,"confidence_score":1.0,"payload":{"provider":"bitflyer_ws_board","exchange":"bitflyer","transport":"websocket","channel":"lightning_board_BTC_JPY","received_ts":"2026-03-15T00:05:24.980052Z","subscription_id":null,"message_id":null,"source_sequence":null,"raw_message_meta":{"raw_channel":"lightning_board_BTC_JPY","subscription_channel":"lightning_board_BTC_JPY","recv_timeout_sec":10,"ssl_verify":false,"socket_url":"wss://ws.lightstream.bitflyer.com/json-rpc"},"source_payload":{"mid_price":11384836.0,"bids":[{"price":11382449.0,"size":0.044},{"price":11372777.0,"size":0.0}],"asks":[{"price":11389570.0,"size":0.0}]}}}
{"schema_version":"collector.vnext.raw","schema_contract":null,"schema_contract_version":null,"payload_contract_version":null,"record_type":"market.orderbook.diff","record_id":"collector_main-market-orderbook-diff-000000000089","collector_id":"collector_main","collector_role":"production","host_name":"MAIN-PC","session_id":"collector_main-sess-20260315T000515Z-beb502e7","stream_session_id":"collector_main-stream-bitflyer-board_ws-20260315T000523Z-812bdb19","exchange":"bitflyer","market":"spot","symbol":"BTC_JPY","instrument_id":"bitflyer.spot.BTC_JPY","channel":"board_ws","transport":"websocket","source_event_id":null,"source_sequence":null,"sequence_id":89,"exchange_ts":null,"collector_ts":"2026-03-15T00:05:25Z","ingest_ts":"2026-03-15T00:05:25Z","event_ts":"2026-03-15T00:05:25Z","quality_flags":[],"is_partial":false,"is_reconstructed":false,"confidence_score":1.0,"payload":{"provider":"bitflyer_ws_board","exchange":"bitflyer","transport":"websocket","channel":"lightning_board_BTC_JPY","received_ts":"2026-03-15T00:05:25.078374Z","subscription_id":null,"message_id":null,"source_sequence":null,"raw_message_meta":{"raw_channel":"lightning_board_BTC_JPY","subscription_channel":"lightning_board_BTC_JPY","recv_timeout_sec":10,"ssl_verify":false,"socket_url":"wss://ws.lightstream.bitflyer.com/json-rpc"},"source_payload":{"mid_price":11384836.0,"bids":[{"price":11382884.0,"size":0.1275}],"asks":[{"price":11389566.0,"size":0.02}]}}}
{"schema_version":"collector.vnext.raw","schema_contract":null,"schema_contract_version":null,"payload_contract_version":null,"record_type":"market.orderbook.diff","record_id":"collector_main-market-orderbook-diff-000000000091","collector_id":"collector_main","collector_role":"production","host_name":"MAIN-PC","session_id":"collector_main-sess-20260315T000515Z-beb502e7","stream_session_id":"collector_main-stream-bitflyer-board_ws-20260315T000523Z-812bdb19","exchange":"bitflyer","market":"spot","symbol":"BTC_JPY","instrument_id":"bitflyer.spot.BTC_JPY","channel":"board_ws","transport":"websocket","source_event_id":null,"source_sequence":null,"sequence_id":91,"exchange_ts":null,"collector_ts":"2026-03-15T00:05:25Z","ingest_ts":"2026-03-15T00:05:25Z","event_ts":"2026-03-15T00:05:25Z","quality_flags":[],"is_partial":false,"is_reconstructed":false,"confidence_score":1.0,"payload":{"provider":"bitflyer_ws_board","exchange":"bitflyer","transport":"websocket","channel":"lightning_board_BTC_JPY","received_ts":"2026-03-15T00:05:25.188767Z","subscription_id":null,"message_id":null,"source_sequence":null,"raw_message_meta":{"raw_channel":"lightning_board_BTC_JPY","subscription_channel":"lightning_board_BTC_JPY","recv_timeout_sec":10,"ssl_verify":false,"socket_url":"wss://ws.lightstream.bitflyer.com/json-rpc"},"source_payload":{"mid_price":11384836.0,"bids":[],"asks":[{"price":11390206.0,"size":0.0},{"price":11389568.0,"size":0.02}]}}}
{"schema_version":"collector.vnext.raw","schema_contract":null,"schema_contract_version":null,"payload_contract_version":null,"record_type":"market.orderbook.diff","record_id":"collector_main-market-orderbook-diff-000000000093","collector_id":"collector_main","collector_role":"production","host_name":"MAIN-PC","session_id":"collector_main-sess-20260315T000515Z-beb502e7","stream_session_id":"collector_main-stream-bitflyer-board_ws-20260315T000523Z-812bdb19","exchange":"bitflyer","market":"spot","symbol":"BTC_JPY","instrument_id":"bitflyer.spot.BTC_JPY","channel":"board_ws","transport":"websocket","source_event_id":null,"source_sequence":null,"sequence_id":93,"exchange_ts":null,"collector_ts":"2026-03-15T00:05:25Z","ingest_ts":"2026-03-15T00:05:25Z","event_ts":"2026-03-15T00:05:25Z","quality_flags":[],"is_partial":false,"is_reconstructed":false,"confidence_score":1.0,"payload":{"provider":"bitflyer_ws_board","exchange":"bitflyer","transport":"websocket","channel":"lightning_board_BTC_JPY","received_ts":"2026-03-15T00:05:25.282690Z","subscription_id":null,"message_id":null,"source_sequence":null,"raw_message_meta":{"raw_channel":"lightning_board_BTC_JPY","subscription_channel":"lightning_board_BTC_JPY","recv_timeout_sec":10,"ssl_verify":false,"socket_url":"wss://ws.lightstream.bitflyer.com/json-rpc"},"source_payload":{"mid_price":11384836.0,"bids":[{"price":11382448.0,"size":0.0108987}],"asks":[{"price":11389569.0,"size":0.0},{"price":11389571.0,"size":0.04454473},{"price":11389395.0,"size":0.0},{"price":11389566.0,"size":0.0}]}}}
{"schema_version":"collector.vnext.raw","schema_contract":null,"schema_contract_version":null,"payload_contract_version":null,"record_type":"market.orderbook.diff","record_id":"collector_main-market-orderbook-diff-000000000095","collector_id":"collector_main","collector_role":"production","host_name":"MAIN-PC","session_id":"collector_main-sess-20260315T000515Z-beb502e7","stream_session_id":"collector_main-stream-bitflyer-board_ws-20260315T000523Z-812bdb19","exchange":"bitflyer","market":"spot","symbol":"BTC_JPY","instrument_id":"bitflyer.spot.BTC_JPY","channel":"board_ws","transport":"websocket","source_event_id":null,"source_sequence":null,"sequence_id":95,"exchange_ts":null,"collector_ts":"2026-03-15T00:05:25Z","ingest_ts":"2026-03-15T00:05:25Z","event_ts":"2026-03-15T00:05:25Z","quality_flags":[],"is_partial":false,"is_reconstructed":false,"confidence_score":1.0,"payload":{"provider":"bitflyer_ws_board","exchange":"bitflyer","transport":"websocket","channel":"lightning_board_BTC_JPY","received_ts":"2026-03-15T00:05:25.406328Z","subscription_id":null,"message_id":null,"source_sequence":null,"raw_message_meta":{"raw_channel":"lightning_board_BTC_JPY","subscription_channel":"lightning_board_BTC_JPY","recv_timeout_sec":10,"ssl_verify":false,"socket_url":"wss://ws.lightstream.bitflyer.com/json-rpc"},"source_payload":{"mid_price":11384836.0,"bids":[],"asks":[{"price":11389163.0,"size":0.02},{"price":11389565.0,"size":0.04243117},{"price":11389571.0,"size":0.0}]}}}
{"schema_version":"collector.vnext.raw","schema_contract":null,"schema_contract_version":null,"payload_contract_version":null,"record_type":"market.orderbook.snapshot","record_id":"collector_main-market-orderbook-snapshot-000000000097","collector_id":"collector_main","collector_role":"production","host_name":"MAIN-PC","session_id":"collector_main-sess-20260315T000515Z-beb502e7","stream_session_id":"collector_main-stream-bitflyer-board_ws-20260315T000523Z-812bdb19","exchange":"bitflyer","market":"spot","symbol":"BTC_JPY","instrument_id":"bitflyer.spot.BTC_JPY","channel":"board_ws","transport":"websocket","source_event_id":null,"source_sequence":null,"sequence_id":97,"exchange_ts":null,"collector_ts":"2026-03-15T00:05:25Z","ingest_ts":"2026-03-15T00:05:25Z","event_ts":"2026-03-15T00:05:25Z","quality_flags":[],"is_partial":false,"is_reconstructed":false,"confidence_score":1.0,"payload":{"provider":"bitflyer_ws_board_snapshot","exchange":"bitflyer","transport":"websocket","channel":"lightning_board_snapshot_BTC_JPY","received_ts":"2026-03-15T00:05:25.562970Z","subscription_id":null,"message_id":null,"source_sequence":null,"raw_message_meta":{"raw_channel":"lightning_board_snapshot_BTC_JPY","subscription_channel":"lightning_board_snapshot_BTC_JPY","recv_timeout_sec":10,"ssl_verify":false,"socket_url":"wss://ws.lightstream.bitflyer.com/json-rpc"},"source_payload":{"mid_price":11384836.0,"bids":[{"price":11382901.0,"size":0.1275},{"price":11382884.0,"size":0.1275},{"price":11382448.0,"size":0.0108987},{"price":11382413.0,"size":0.1405},{"price":11382257.0,"size":0.005},{"price":11382256.0,"size":0.00999733},{"price":11382029.0,"size":0.014556},{"price":11381035.0,"size":0.015024},{"price":11380465.0,"size":0.014892},{"price":11380046.0,"size":0.02},{"price":11380045.0,"size":0.014448},{"price":11379042.0,"size":0.053784},{"price":11378822.0,"size":0.01},{"price":11378428.0,"size":0.005},{"price":11378097.0,"size":0.266},{"price":11375465.0,"size":0.5},{"price":11374281.0,"size":3.11476765},{"price":11372897.0,"size":0.06},{"price":11372777.0,"size":0.08},{"price":11372266.0,"size":0.0527},{"price":11371900.0,"size":0.005},{"price":11371638.0,"size":0.12},{"price":11370500.0,"size":0.07},{"price":11370000.0,"size":0.01},{"price":11368376.0,"size":0.01},{"price":11368223.0,"size":0.23},{"price":11366249.0,"size":0.31694876},{"price":11366247.0,"size":0.036},{"price":11366008.0,"size":0.04},{"price":11365378.0,"size":0.05},{"price":11364809.0,"size":0.05},{"price":11362328.0,"size":0.3023},{"price":11362278.0,"size":0.31206306},{"price":11362277.0,"size":0.9772867},{"price":11361538.0,"size":1.50015},{"price":11359566.0,"size":0.2881},{"price":11358376.0,"size":0.01},{"price":11356804.0,"size":0.3083},{"price":11356706.0,"size":1.484},{"price":11354042.0,"size":0.2729},{"price":11353488.0,"size":0.27174084},{"price":11351281.0,"size":0.08163399},{"price":11350000.0,"size":0.51},{"price":11348189.0,"size":0.003},{"price":11347667.0,"size":0.001},{"price":11347661.0,"size":0.6},{"price":11347560.0,"size":0.002},{"price":11347461.0,"size":0.002},{"price":11344148.0,"size":0.002},{"price":11342910.0,"size":0.002},{"price":11342072.0,"size":1.966},{"price":11341671.0,"size":0.23},{"price":11340736.0,"size":0.002},{"price":11340000.0,"size":0.005},{"price":11338359.0,"size":0.002},{"price":11337324.0,"size":0.002},{"price":11336383.0,"size":0.001},{"price":11336319.0,"size":0.00195},{"price":11333912.0,"size":0.002},{"price":11333808.0,"size":0.002},{"price":11331227.0,"size":0.51},{"price":11331000.0,"size":0.5},{"price":11330500.0,"size":0.002},{"price":11330000.0,"size":0.02442},{"price":11329257.0,"size":0.002},{"price":11328186.0,"size":2.036},{"price":11327088.0,"size":0.002},{"price":11325101.0,"size":0.001},{"price":11324706.0,"size":0.002},{"price":11323676.0,"size":0.002},{"price":11320264.0,"size":0.002},{"price":11320155.0,"size":0.002},{"price":11320000.0,"size":0.05},{"price":11316852.0,"size":0.002},{"price":11315604.0,"size":0.002},{"price":11315000.0,"size":0.05},{"price":11313996.0,"size":0.00195},{"price":11313819.0,"size":0.001},{"price":11311053.0,"size":0.002},{"price":11310000.0,"size":0.01},{"price":11309999.0,"size":0.177},{"price":11307999.0,"size":0.01},{"price":11305439.0,"size":1.951},{"price":11303918.0,"size":0.01},{"price":11303000.0,"size":0.5},{"price":11302535.0,"size":0.001},{"price":11302466.0,"size":0.001},{"price":11301268.0,"size":0.01},{"price":11300000.0,"size":3.01685256},{"price":11298000.0,"size":0.01},{"price":11296865.0,"size":0.0015},{"price":11294756.0,"size":1.0},{"price":11291282.0,"size":0.001},{"price":11291268.0,"size":0.01},{"price":11291000.0,"size":0.5},{"price":11290000.0,"size":0.003},{"price":11281268.0,"size":0.01},{"price":11280000.0,"size":0.0163},{"price":11279960.0,"size":0.001},{"price":11279282.0,"size":0.0015},{"price":11278000.0,"size":0.0025},{"price":11275000.0,"size":0.001},{"price":11274588.0,"size":0.0047},{"price":11271268.0,"size":0.01},{"price":11271000.0,"size":0.003},{"price":11270000.0,"size":0.106},{"price":11269424.0,"size":0.8},{"price":11268871.0,"size":0.28},{"price":11268638.0,"size":0.001},{"price":11268411.0,"size":0.01},{"price":11266666.0,"size":0.04},{"price":11265000.0,"size":0.02},{"price":11263000.0,"size":0.006},{"price":11262564.0,"size":0.0015},{"price":11261268.0,"size":0.01},{"price":11260000.0,"size":0.3565},{"price":11257315.0,"size":0.001},{"price":11257000.0,"size":0.001},{"price":11255200.0,"size":0.001},{"price":11255115.0,"size":0.00377},{"price":11253814.0,"size":2.2},{"price":11253690.0,"size":0.01},{"price":11253000.0,"size":0.03189},{"price":11251405.0,"size":0.139},{"price":11251268.0,"size":0.01},{"price":11251111.0,"size":0.0015},{"price":11251000.0,"size":0.0131},{"price":11250250.0,"size":0.00105},{"price":11250200.0,"size":0.001},{"price":11250005.0,"size":0.001},{"price":11250001.0,"size":0.00104},{"price":11250000.0,"size":1.62712889},{"price":11245993.0,"size":0.001},{"price":11245141.0,"size":0.0031},{"price":11245000.0,"size":0.05},{"price":11244444.0,"size":0.04},{"price":11244243.0,"size":0.01},{"price":11240200.0,"size":0.001},{"price":11240000.0,"size":0.007304},{"price":11236190.0,"size":0.01},{"price":11235200.0,"size":0.001},{"price":11234670.0,"size":0.001},{"price":11232000.0,"size":0.089},{"price":11231243.0,"size":0.01},{"price":11231000.0,"size":0.105},{"price":11230200.0,"size":0.001},{"price":11230000.0,"size":0.0308},{"price":11226952.0,"size":0.972},{"price":11224500.0,"size":0.06},{"price":11223968.0,"size":0.001},{"price":11223348.0,"size":0.001},{"price":11223344.0,"size":0.01},{"price":11223000.0,"size":0.1},{"price":11222222.0,"size":0.093525},{"price":11221120.0,"size":0.001},{"price":11220200.0,"size":0.001},{"price":11220001.0,"size":0.004457},{"price":11220000.0,"size":0.321},{"price":11219000.0,"size":0.1},{"price":11217326.0,"size":0.02},{"price":11215200.0,"size":0.001},{"price":11213690.0,"size":0.01},{"price":11212025.0,"size":0.001},{"price":11211800.0,"size":0.001},{"price":11211111.0,"size":0.06},{"price":11210200.0,"size":0.001},{"price":11210000.0,"size":0.10622},{"price":11208032.0,"size":0.01},{"price":11206000.0,"size":0.09015},{"price":11205200.0,"size":0.001},{"price":11204578.0,"size":0.002},{"price":11201000.0,"size":0.01},{"price":11200800.0,"size":0.05},{"price":11200703.0,"size":0.001},{"price":11200425.0,"size":0.1},{"price":11200200.0,"size":0.001},{"price":11200198.0,"size":0.003},{"price":11200150.0,"size":0.002},{"price":11200002.0,"size":0.001},{"price":11200001.0,"size":0.01104},{"price":11200000.0,"size":1.15226728},{"price":11198508.0,"size":0.05},{"price":11198243.0,"size":0.01},{"price":11197134.0,"size":0.993},{"price":11197000.0,"size":0.0085},{"price":11194090.0,"size":0.03},{"price":11190770.0,"size":0.0309},{"price":11190000.0,"size":0.0010016},{"price":11189555.0,"size":0.5},{"price":11189381.0,"size":0.001},{"price":11188629.0,"size":0.01},{"price":11188382.0,"size":0.001},{"price":11185000.0,"size":0.0085},{"price":11180000.0,"size":0.225},{"price":11178058.0,"size":0.001},{"price":11170000.0,"size":0.001},{"price":11169662.0,"size":0.01},{"price":11169593.0,"size":0.001},{"price":11169243.0,"size":0.01},{"price":11166736.0,"size":0.001},{"price":11164029.0,"size":0.001},{"price":11160854.0,"size":0.1},{"price":11160000.0,"size":0.02376},{"price":11155413.0,"size":0.001},{"price":11155377.0,"size":0.00636009},{"price":11153999.0,"size":0.00101},{"price":11151000.0,"size":0.001},{"price":11150250.0,"size":0.00175},{"price":11150005.0,"size":0.001},{"price":11150001.0,"size":0.00104},{"price":11150000.0,"size":0.6533956},{"price":11148000.0,"size":0.08963},{"price":11147546.0,"size":0.02},{"price":11144091.0,"size":0.001},{"price":11144000.0,"size":0.0897},{"price":11143986.0,"size":0.02},{"price":11140139.0,"size":1.0},{"price":11140000.0,"size":0.2},{"price":11136243.0,"size":0.01},{"price":11135869.0,"size":0.1},{"price":11132768.0,"size":0.001},{"price":11130000.0,"size":0.116},{"price":11129979.0,"size":0.0053908},{"price":11124900.0,"size":0.00133},{"price":11121090.0,"size":0.1},{"price":11120000.0,"size":0.0033},{"price":11118078.0,"size":0.01},{"price":11111800.0,"size":0.001},{"price":11111111.0,"size":0.2919257},{"price":11111000.0,"size":0.003},{"price":11110594.0,"size":0.001},{"price":11110000.0,"size":0.021007},{"price":11109662.0,"size":0.01},{"price":11108008.0,"size":0.01},{"price":11102000.0,"size":0.5},{"price":11101297.0,"size":0.001},{"price":11100005.0,"size":0.001},{"price":11100001.0,"size":0.01104},{"price":11100000.0,"size":1.6532049},{"price":11099141.0,"size":0.01},{"price":11098833.0,"size":0.002},{"price":11096243.0,"size":0.01},{"price":11094090.0,"size":0.01},{"price":11088888.0,"size":0.001},{"price":11085245.0,"size":0.001},{"price":11080200.0,"size":0.001},{"price":11080000.0,"size":0.0223},{"price":11075100.0,"size":0.003},{"price":11070200.0,"size":0.001},{"price":11070000.0,"size":0.0902},{"price":11065200.0,"size":0.001},{"price":11064370.0,"size":0.00497091},{"price":11060200.0,"size":0.001},{"price":11060000.0,"size":0.145},{"price":11059689.0,"size":0.009},{"price":11056428.0,"size":0.002},{"price":11055500.0,"size":0.02},{"price":11055200.0,"size":0.001},{"price":11055100.0,"size":0.003},{"price":11050200.0,"size":0.001},{"price":11050005.0,"size":0.001},{"price":11050002.0,"size":0.001},{"price":11050001.0,"size":0.00104},{"price":11050000.0,"size":0.39576147},{"price":11048064.0,"size":2.0},{"price":11046420.0,"size":0.2},{"price":11044243.0,"size":0.01},{"price":11041380.0,"size":0.01},{"price":11040200.0,"size":0.001},{"price":11040000.0,"size":0.00777181},{"price":11035865.0,"size":0.1},{"price":11035200.0,"size":0.001},{"price":11035000.0,"size":0.0013},{"price":11030200.0,"size":0.001},{"price":11030000.0,"size":0.025},{"price":11025500.0,"size":0.009531},{"price":11025200.0,"size":0.001},{"price":11025000.0,"size":0.71497},{"price":11020772.0,"size":0.014},{"price":11020200.0,"size":0.002},{"price":11020000.0,"size":0.005},{"price":11015200.0,"size":0.001},{"price":11012000.0,"size":0.1},{"price":11011800.0,"size":0.001},{"price":11010200.0,"size":0.001},{"price":11010000.0,"size":0.347},{"price":11007277.0,"size":0.01},{"price":11005200.0,"size":0.001},{"price":11004890.0,"size":0.001535},{"price":11003000.0,"size":0.0155},{"price":11001000.0,"size":0.013},{"price":11000500.0,"size":0.05117658},{"price":11000200.0,"size":0.001},{"price":11000002.0,"size":0.004},{"price":11000001.0,"size":0.02604},{"price":11000000.0,"size":4.53923365},{"price":10999999.0,"size":0.003},{"price":10999000.0,"size":0.001},{"price":10996855.0,"size":0.0011},{"price":10995200.0,"size":0.001}],"asks":[{"price":11386771.0,"size":0.06187484},{"price":11389163.0,"size":0.02},{"price":11389164.0,"size":0.0223},{"price":11389430.0,"size":0.02},{"price":11389431.0,"size":0.014556},{"price":11389568.0,"size":0.02},{"price":11389572.0,"size":0.02},{"price":11389573.0,"size":0.0044},{"price":11389672.0,"size":0.02},{"price":11389673.0,"size":0.01000441},{"price":11390205.0,"size":0.02},{"price":11390374.0,"size":0.02},{"price":11390375.0,"size":0.234},{"price":11390394.0,"size":0.02},{"price":11390395.0,"size":0.2948},{"price":11390998.0,"size":0.014892},{"price":11391432.0,"size":0.4249},{"price":11392010.0,"size":0.00142446},{"price":11393157.0,"size":0.2829},{"price":11395664.0,"size":0.57205973},{"price":11395665.0,"size":0.05},{"price":11395919.0,"size":0.298},{"price":11396125.0,"size":0.053784},{"price":11397000.0,"size":0.02},{"price":11398444.0,"size":0.001995},{"price":11398681.0,"size":0.3093},{"price":11398845.0,"size":0.001},{"price":11399533.0,"size":0.0618748},{"price":11399673.0,"size":0.0015},{"price":11399700.0,"size":0.001},{"price":11399999.0,"size":0.05},{"price":11400000.0,"size":1.04832841},{"price":11400402.0,"size":1.189881},{"price":11400703.0,"size":0.0526},{"price":11401107.0,"size":1.189881},{"price":11401431.0,"size":0.05},{"price":11401591.0,"size":0.0384},{"price":11403472.0,"size":0.002},{"price":11405000.0,"size":0.1575},{"price":11408700.0,"size":0.001},{"price":11409413.0,"size":0.29418471},{"price":11409414.0,"size":1.60199848},{"price":11409415.0,"size":0.005},{"price":11409925.0,"size":0.22},{"price":11410000.0,"size":0.3787},{"price":11410168.0,"size":0.001},{"price":11410853.0,"size":0.002},{"price":11412000.0,"size":0.0878},{"price":11415000.0,"size":0.1},{"price":11415141.0,"size":0.0041},{"price":11417481.0,"size":0.0015},{"price":11418700.0,"size":0.001},{"price":11419000.0,"size":0.01},{"price":11420000.0,"size":0.261},{"price":11421268.0,"size":0.05},{"price":11421490.0,"size":0.001},{"price":11422413.0,"size":1.928},{"price":11424296.0,"size":0.002},{"price":11425000.0,"size":0.029},{"price":11426188.0,"size":1.489},{"price":11426426.0,"size":0.002},{"price":11428121.0,"size":0.002},{"price":11428700.0,"size":0.001},{"price":11429302.0,"size":0.01},{"price":11430000.0,"size":0.4098},{"price":11432718.0,"size":0.002},{"price":11432813.0,"size":0.001},{"price":11433211.0,"size":0.03},{"price":11433333.0,"size":0.001},{"price":11437315.0,"size":0.002},{"price":11438525.0,"size":0.0011},{"price":11438700.0,"size":0.001},{"price":11439557.0,"size":0.001},{"price":11440000.0,"size":0.2538},{"price":11441911.0,"size":0.002},{"price":11443629.0,"size":0.002},{"price":11444135.0,"size":0.001},{"price":11445433.0,"size":0.0015},{"price":11446508.0,"size":0.001},{"price":11447000.0,"size":0.01},{"price":11447071.0,"size":0.002},{"price":11448000.0,"size":0.0875},{"price":11448700.0,"size":0.001},{"price":11448964.0,"size":2.018},{"price":11450000.0,"size":0.268},{"price":11451105.0,"size":0.002},{"price":11453321.0,"size":0.03},{"price":11455000.0,"size":0.001},{"price":11455457.0,"size":0.001},{"price":11455702.0,"size":0.002},{"price":11458700.0,"size":0.001},{"price":11458988.0,"size":0.01},{"price":11460000.0,"size":0.06702},{"price":11460299.0,"size":0.002},{"price":11463288.0,"size":0.01},{"price":11464896.0,"size":0.002},{"price":11465382.0,"size":0.00195},{"price":11465421.0,"size":1.943},{"price":11466780.0,"size":0.001},{"price":11468700.0,"size":0.001},{"price":11470000.0,"size":0.06},{"price":11471000.0,"size":0.01},{"price":11475000.0,"size":0.0028},{"price":11476929.0,"size":1.0},{"price":11478102.0,"size":0.001},{"price":11478431.0,"size":0.002},{"price":11478700.0,"size":0.001},{"price":11480000.0,"size":0.40191},{"price":11485000.0,"size":0.01},{"price":11485488.0,"size":2.0},{"price":11486555.0,"size":0.03},{"price":11487685.0,"size":0.01},{"price":11488000.0,"size":0.102},{"price":11488700.0,"size":0.001},{"price":11489425.0,"size":0.001},{"price":11490000.0,"size":0.05},{"price":11490841.0,"size":0.002},{"price":11495450.0,"size":0.002},{"price":11495850.0,"size":0.001},{"price":11498700.0,"size":0.001},{"price":11498917.0,"size":0.002},{"price":11499000.0,"size":0.01},{"price":11500000.0,"size":0.77159519},{"price":11500078.0,"size":0.93},{"price":11500747.0,"size":0.001},{"price":11502377.0,"size":0.002},{"price":11502800.0,"size":0.00132},{"price":11503108.0,"size":0.0198},{"price":11505000.0,"size":0.0028},{"price":11505001.0,"size":0.002},{"price":11505836.0,"size":0.003},{"price":11508431.0,"size":0.047},{"price":11508700.0,"size":0.001},{"price":11508888.0,"size":0.02},{"price":11510000.0,"size":0.1476},{"price":11512070.0,"size":0.001},{"price":11513633.0,"size":0.08},{"price":11514332.0,"size":0.02},{"price":11518700.0,"size":0.001},{"price":11518992.0,"size":0.002},{"price":11519855.0,"size":0.01},{"price":11520000.0,"size":0.001},{"price":11522388.0,"size":0.972},{"price":11523211.0,"size":0.01},{"price":11524999.0,"size":0.001},{"price":11528700.0,"size":0.001},{"price":11529852.0,"size":0.01},{"price":11530000.0,"size":0.261},{"price":11533985.0,"size":0.002},{"price":11534084.0,"size":0.001},{"price":11535321.0,"size":0.01},{"price":11538666.0,"size":0.002},{"price":11538700.0,"size":0.001},{"price":11540000.0,"size":0.0048},{"price":11540357.0,"size":0.002},{"price":11541011.0,"size":0.005},{"price":11541109.0,"size":0.01},{"price":11544663.0,"size":0.002},{"price":11545262.0,"size":0.002},{"price":11546541.0,"size":0.01},{"price":11548144.0,"size":0.002},{"price":11548700.0,"size":0.001},{"price":11550000.0,"size":0.014},{"price":11551109.0,"size":0.01},{"price":11551625.0,"size":0.002},{"price":11552111.0,"size":0.01},{"price":11553687.0,"size":0.1},{"price":11555106.0,"size":0.002},{"price":11555115.0,"size":0.001},{"price":11556000.0,"size":0.1},{"price":11558587.0,"size":0.002},{"price":11558700.0,"size":0.001},{"price":11559855.0,"size":0.01},{"price":11560831.0,"size":0.0198},{"price":11561109.0,"size":0.01},{"price":11562000.0,"size":0.087},{"price":11562068.0,"size":0.002},{"price":11563750.0,"size":0.08739676},{"price":11565548.0,"size":0.002},{"price":11566139.0,"size":0.0228},{"price":11566551.0,"size":0.01},{"price":11568700.0,"size":0.001},{"price":11569029.0,"size":0.002},{"price":11570196.0,"size":0.002},{"price":11571109.0,"size":0.01},{"price":11572510.0,"size":0.002},{"price":11573211.0,"size":0.01},{"price":11574840.0,"size":0.002},{"price":11575991.0,"size":0.001},{"price":11578700.0,"size":0.001},{"price":11579484.0,"size":0.002},{"price":11579851.0,"size":0.01},{"price":11580000.0,"size":0.7835},{"price":11581109.0,"size":0.01},{"price":11584128.0,"size":0.002},{"price":11585000.0,"size":0.002},{"price":11586532.0,"size":0.01},{"price":11587498.0,"size":0.0198},{"price":11588700.0,"size":0.001},{"price":11588800.0,"size":0.02},{"price":11590000.0,"size":0.1},{"price":11590749.0,"size":0.002},{"price":11591109.0,"size":0.01},{"price":11593211.0,"size":0.01},{"price":11596753.0,"size":0.002},{"price":11598111.0,"size":0.1474},{"price":11598555.0,"size":0.01},{"price":11598700.0,"size":0.001},{"price":11599999.0,"size":0.001},{"price":11600000.0,"size":3.655},{"price":11601109.0,"size":0.02},{"price":11603764.0,"size":0.9},{"price":11606655.0,"size":0.01},{"price":11610000.0,"size":0.302},{"price":11611109.0,"size":0.01},{"price":11613321.0,"size":0.01},{"price":11620000.0,"size":1.35441682},{"price":11621011.0,"size":0.01},{"price":11621109.0,"size":0.01},{"price":11623096.0,"size":0.008},{"price":11625703.0,"size":0.012},{"price":11629000.0,"size":0.1},{"price":11630000.0,"size":0.201},{"price":11631059.0,"size":0.01},{"price":11631479.0,"size":0.01},{"price":11631773.0,"size":0.00386871},{"price":11635950.0,"size":0.001},{"price":11638259.0,"size":0.001},{"price":11639700.0,"size":0.001},{"price":11640000.0,"size":1.0},{"price":11640820.0,"size":0.01},{"price":11649900.0,"size":0.02906},{"price":11649999.0,"size":0.001},{"price":11650000.0,"size":0.593},{"price":11651059.0,"size":0.01},{"price":11653658.0,"size":0.008},{"price":11654321.0,"size":0.001},{"price":11659700.0,"size":0.001},{"price":11661479.0,"size":0.01},{"price":11666000.0,"size":0.001},{"price":11666666.0,"size":0.013},{"price":11669700.0,"size":0.001},{"price":11671059.0,"size":0.01},{"price":11672562.0,"size":0.0198},{"price":11680000.0,"size":0.014},{"price":11685000.0,"size":0.003},{"price":11688000.0,"size":0.001},{"price":11689732.0,"size":0.01},{"price":11690330.0,"size":0.0198},{"price":11691059.0,"size":0.01},{"price":11692558.0,"size":0.01},{"price":11695019.0,"size":0.0064},{"price":11698800.0,"size":0.00131},{"price":11699000.0,"size":0.001},{"price":11699631.0,"size":0.001},{"price":11699998.0,"size":0.01},{"price":11699999.0,"size":0.001},{"price":11700000.0,"size":1.2573},{"price":11701059.0,"size":0.01},{"price":11720000.0,"size":0.1},{"price":11721059.0,"size":0.01},{"price":11725000.0,"size":0.005},{"price":11726791.0,"size":0.01},{"price":11727418.0,"size":1.8},{"price":11728195.0,"size":0.05},{"price":11730000.0,"size":1.9712},{"price":11740000.0,"size":0.101},{"price":11741059.0,"size":0.01},{"price":11748937.0,"size":0.001},{"price":11749999.0,"size":0.001},{"price":11750000.0,"size":0.89537866},{"price":11750050.0,"size":0.2},{"price":11751151.0,"size":0.01},{"price":11751406.0,"size":0.012},{"price":11755000.0,"size":0.001},{"price":11757860.0,"size":1.82},{"price":11759999.0,"size":0.001},{"price":11760000.0,"size":0.001},{"price":11761059.0,"size":0.02},{"price":11765432.0,"size":0.001},{"price":11768000.0,"size":0.01},{"price":11770000.0,"size":0.25464896},{"price":11771059.0,"size":0.01755555},{"price":11772000.0,"size":0.002},{"price":11775000.0,"size":0.11593},{"price":11775222.0,"size":0.001657},{"price":11775577.0,"size":0.00013523},{"price":11775800.0,"size":0.001},{"price":11775900.0,"size":0.2},{"price":11775989.0,"size":0.005},{"price":11777000.0,"size":0.5956},{"price":11777777.0,"size":0.0067},{"price":11778541.0,"size":0.001},{"price":11779807.0,"size":0.001},{"price":11780000.0,"size":0.74298},{"price":11780800.0,"size":0.1},{"price":11781059.0,"size":0.01},{"price":11781238.0,"size":0.008},{"price":11785000.0,"size":0.055},{"price":11785040.0,"size":0.01}]}}}
{"schema_version":"collector.vnext.raw","schema_contract":null,"schema_contract_version":null,"payload_contract_version":null,"record_type":"market.orderbook.diff","record_id":"collector_main-market-orderbook-diff-000000000061","collector_id":"collector_main","collector_role":"production","host_name":"MAIN-PC","session_id":"collector_main-sess-20260315T000540Z-fe3e7262","stream_session_id":"collector_main-stream-bitflyer-board_ws-20260315T000541Z-6f3df026","exchange":"bitflyer","market":"spot","symbol":"BTC_JPY","instrument_id":"bitflyer.spot.BTC_JPY","channel":"board_ws","transport":"websocket","source_event_id":null,"source_sequence":null,"sequence_id":61,"exchange_ts":null,"collector_ts":"2026-03-15T00:05:41Z","ingest_ts":"2026-03-15T00:05:41Z","event_ts":"2026-03-15T00:05:41Z","quality_flags":[],"is_partial":false,"is_reconstructed":false,"confidence_score":1.0,"payload":{"provider":"bitflyer_ws_board","exchange":"bitflyer","transport":"websocket","channel":"lightning_board_BTC_JPY","received_ts":"2026-03-15T00:05:41.954582Z","subscription_id":null,"message_id":null,"source_sequence":null,"raw_message_meta":{"raw_channel":"lightning_board_BTC_JPY","subscription_channel":"lightning_board_BTC_JPY","recv_timeout_sec":10,"ssl_verify":false,"socket_url":"wss://ws.lightstream.bitflyer.com/json-rpc"},"source_payload":{"mid_price":11384744.0,"bids":[{"price":11378482.0,"size":0.1275},{"price":11382943.0,"size":0.0},{"price":11371763.0,"size":0.0},{"price":11379621.0,"size":0.0}],"asks":[]}}}
{"schema_version":"collector.vnext.raw","schema_contract":null,"schema_contract_version":null,"payload_contract_version":null,"record_type":"market.orderbook.diff","record_id":"collector_main-market-orderbook-diff-000000000065","collector_id":"collector_main","collector_role":"production","host_name":"MAIN-PC","session_id":"collector_main-sess-20260315T000540Z-fe3e7262","stream_session_id":"collector_main-stream-bitflyer-board_ws-20260315T000541Z-6f3df026","exchange":"bitflyer","market":"spot","symbol":"BTC_JPY","instrument_id":"bitflyer.spot.BTC_JPY","channel":"board_ws","transport":"websocket","source_event_id":null,"source_sequence":null,"sequence_id":65,"exchange_ts":null,"collector_ts":"2026-03-15T00:05:42Z","ingest_ts":"2026-03-15T00:05:42Z","event_ts":"2026-03-15T00:05:42Z","quality_flags":[],"is_partial":false,"is_reconstructed":false,"confidence_score":1.0,"payload":{"provider":"bitflyer_ws_board","exchange":"bitflyer","transport":"websocket","channel":"lightning_board_BTC_JPY","received_ts":"2026-03-15T00:05:42.080476Z","subscription_id":null,"message_id":null,"source_sequence":null,"raw_message_meta":{"raw_channel":"lightning_board_BTC_JPY","subscription_channel":"lightning_board_BTC_JPY","recv_timeout_sec":10,"ssl_verify":false,"socket_url":"wss://ws.lightstream.bitflyer.com/json-rpc"},"source_payload":{"mid_price":11384744.0,"bids":[{"price":11378482.0,"size":0.0},{"price":11373701.0,"size":0.0},{"price":11372771.0,"size":0.00999891}],"asks":[{"price":11399531.0,"size":0.0},{"price":11399532.0,"size":0.2}]}}}
{"schema_version":"collector.vnext.raw","schema_contract":null,"schema_contract_version":null,"payload_contract_version":null,"record_type":"market.orderbook.diff","record_id":"collector_main-market-orderbook-diff-000000000067","collector_id":"collector_main","collector_role":"production","host_name":"MAIN-PC","session_id":"collector_main-sess-20260315T000540Z-fe3e7262","stream_session_id":"collector_main-stream-bitflyer-board_ws-20260315T000541Z-6f3df026","exchange":"bitflyer","market":"spot","symbol":"BTC_JPY","instrument_id":"bitflyer.spot.BTC_JPY","channel":"board_ws","transport":"websocket","source_event_id":null,"source_sequence":null,"sequence_id":67,"exchange_ts":null,"collector_ts":"2026-03-15T00:05:42Z","ingest_ts":"2026-03-15T00:05:42Z","event_ts":"2026-03-15T00:05:42Z","quality_flags":[],"is_partial":false,"is_reconstructed":false,"confidence_score":1.0,"payload":{"provider":"bitflyer_ws_board","exchange":"bitflyer","transport":"websocket","channel":"lightning_board_BTC_JPY","received_ts":"2026-03-15T00:05:42.189942Z","subscription_id":null,"message_id":null,"source_sequence":null,"raw_message_meta":{"raw_channel":"lightning_board_BTC_JPY","subscription_channel":"lightning_board_BTC_JPY","recv_timeout_sec":10,"ssl_verify":false,"socket_url":"wss://ws.lightstream.bitflyer.com/json-rpc"},"source_payload":{"mid_price":11385185.0,"bids":[{"price":11383825.0,"size":0.00999733}],"asks":[]}}}
{"schema_version":"collector.vnext.raw","schema_contract":null,"schema_contract_version":null,"payload_contract_version":null,"record_type":"market.orderbook.diff","record_id":"collector_main-market-orderbook-diff-000000000069","collector_id":"collector_main","collector_role":"production","host_name":"MAIN-PC","session_id":"collector_main-sess-20260315T000540Z-fe3e7262","stream_session_id":"collector_main-stream-bitflyer-board_ws-20260315T000541Z-6f3df026","exchange":"bitflyer","market":"spot","symbol":"BTC_JPY","instrument_id":"bitflyer.spot.BTC_JPY","channel":"board_ws","transport":"websocket","source_event_id":null,"source_sequence":null,"sequence_id":69,"exchange_ts":null,"collector_ts":"2026-03-15T00:05:42Z","ingest_ts":"2026-03-15T00:05:42Z","event_ts":"2026-03-15T00:05:42Z","quality_flags":[],"is_partial":false,"is_reconstructed":false,"confidence_score":1.0,"payload":{"provider":"bitflyer_ws_board","exchange":"bitflyer","transport":"websocket","channel":"lightning_board_BTC_JPY","received_ts":"2026-03-15T00:05:42.298168Z","subscription_id":null,"message_id":null,"source_sequence":null,"raw_message_meta":{"raw_channel":"lightning_board_BTC_JPY","subscription_channel":"lightning_board_BTC_JPY","recv_timeout_sec":10,"ssl_verify":false,"socket_url":"wss://ws.lightstream.bitflyer.com/json-rpc"},"source_payload":{"mid_price":11385185.0,"bids":[{"price":11372562.0,"size":0.08},{"price":11379052.0,"size":0.1275},{"price":11382944.0,"size":0.0}],"asks":[]}}}
{"schema_version":"collector.vnext.raw","schema_contract":null,"schema_contract_version":null,"payload_contract_version":null,"record_type":"market.orderbook.diff","record_id":"collector_main-market-orderbook-diff-000000000071","collector_id":"collector_main","collector_role":"production","host_name":"MAIN-PC","session_id":"collector_main-sess-20260315T000540Z-fe3e7262","stream_session_id":"collector_main-stream-bitflyer-board_ws-20260315T000541Z-6f3df026","exchange":"bitflyer","market":"spot","symbol":"BTC_JPY","instrument_id":"bitflyer.spot.BTC_JPY","channel":"board_ws","transport":"websocket","source_event_id":null,"source_sequence":null,"sequence_id":71,"exchange_ts":null,"collector_ts":"2026-03-15T00:05:42Z","ingest_ts":"2026-03-15T00:05:42Z","event_ts":"2026-03-15T00:05:42Z","quality_flags":[],"is_partial":false,"is_reconstructed":false,"confidence_score":1.0,"payload":{"provider":"bitflyer_ws_board","exchange":"bitflyer","transport":"websocket","channel":"lightning_board_BTC_JPY","received_ts":"2026-03-15T00:05:42.435935Z","subscription_id":null,"message_id":null,"source_sequence":null,"raw_message_meta":{"raw_channel":"lightning_board_BTC_JPY","subscription_channel":"lightning_board_BTC_JPY","recv_timeout_sec":10,"ssl_verify":false,"socket_url":"wss://ws.lightstream.bitflyer.com/json-rpc"},"source_payload":{"mid_price":11385185.0,"bids":[{"price":11378482.0,"size":0.1275},{"price":11380719.0,"size":0.01458}],"asks":[{"price":11387479.0,"size":0.0},{"price":11387811.0,"size":0.0},{"price":11388120.0,"size":0.01458}]}}}
{"schema_version":"collector.vnext.raw","schema_contract":null,"schema_contract_version":null,"payload_contract_version":null,"record_type":"market.orderbook.diff","record_id":"collector_main-market-orderbook-diff-000000000073","collector_id":"collector_main","collector_role":"production","host_name":"MAIN-PC","session_id":"collector_main-sess-20260315T000540Z-fe3e7262","stream_session_id":"collector_main-stream-bitflyer-board_ws-20260315T000541Z-6f3df026","exchange":"bitflyer","market":"spot","symbol":"BTC_JPY","instrument_id":"bitflyer.spot.BTC_JPY","channel":"board_ws","transport":"websocket","source_event_id":null,"source_sequence":null,"sequence_id":73,"exchange_ts":null,"collector_ts":"2026-03-15T00:05:42Z","ingest_ts":"2026-03-15T00:05:42Z","event_ts":"2026-03-15T00:05:42Z","quality_flags":[],"is_partial":false,"is_reconstructed":false,"confidence_score":1.0,"payload":{"provider":"bitflyer_ws_board","exchange":"bitflyer","transport":"websocket","channel":"lightning_board_BTC_JPY","received_ts":"2026-03-15T00:05:42.562775Z","subscription_id":null,"message_id":null,"source_sequence":null,"raw_message_meta":{"raw_channel":"lightning_board_BTC_JPY","subscription_channel":"lightning_board_BTC_JPY","recv_timeout_sec":10,"ssl_verify":false,"socket_url":"wss://ws.lightstream.bitflyer.com/json-rpc"},"source_payload":{"mid_price":11385185.0,"bids":[{"price":11378482.0,"size":0.0}],"asks":[]}}}
{"schema_version":"collector.vnext.raw","schema_contract":null,"schema_contract_version":null,"payload_contract_version":null,"record_type":"market.orderbook.diff","record_id":"collector_main-market-orderbook-diff-000000000075","collector_id":"collector_main","collector_role":"production","host_name":"MAIN-PC","session_id":"collector_main-sess-20260315T000540Z-fe3e7262","stream_session_id":"collector_main-stream-bitflyer-board_ws-20260315T000541Z-6f3df026","exchange":"bitflyer","market":"spot","symbol":"BTC_JPY","instrument_id":"bitflyer.spot.BTC_JPY","channel":"board_ws","transport":"websocket","source_event_id":null,"source_sequence":null,"sequence_id":75,"exchange_ts":null,"collector_ts":"2026-03-15T00:05:42Z","ingest_ts":"2026-03-15T00:05:42Z","event_ts":"2026-03-15T00:05:42Z","quality_flags":[],"is_partial":false,"is_reconstructed":false,"confidence_score":1.0,"payload":{"provider":"bitflyer_ws_board","exchange":"bitflyer","transport":"websocket","channel":"lightning_board_BTC_JPY","received_ts":"2026-03-15T00:05:42.673308Z","subscription_id":null,"message_id":null,"source_sequence":null,"raw_message_meta":{"raw_channel":"lightning_board_BTC_JPY","subscription_channel":"lightning_board_BTC_JPY","recv_timeout_sec":10,"ssl_verify":false,"socket_url":"wss://ws.lightstream.bitflyer.com/json-rpc"},"source_payload":{"mid_price":11385185.0,"bids":[],"asks":[{"price":11387810.0,"size":0.0},{"price":11387840.0,"size":0.04553581}]}}}
{"schema_version":"collector.vnext.raw","schema_contract":null,"schema_contract_version":null,"payload_contract_version":null,"record_type":"market.orderbook.diff","record_id":"collector_main-market-orderbook-diff-000000000077","collector_id":"collector_main","collector_role":"production","host_name":"MAIN-PC","session_id":"collector_main-sess-20260315T000540Z-fe3e7262","stream_session_id":"collector_main-stream-bitflyer-board_ws-20260315T000541Z-6f3df026","exchange":"bitflyer","market":"spot","symbol":"BTC_JPY","instrument_id":"bitflyer.spot.BTC_JPY","channel":"board_ws","transport":"websocket","source_event_id":null,"source_sequence":null,"sequence_id":77,"exchange_ts":null,"collector_ts":"2026-03-15T00:05:42Z","ingest_ts":"2026-03-15T00:05:42Z","event_ts":"2026-03-15T00:05:42Z","quality_flags":[],"is_partial":false,"is_reconstructed":false,"confidence_score":1.0,"payload":{"provider":"bitflyer_ws_board","exchange":"bitflyer","transport":"websocket","channel":"lightning_board_BTC_JPY","received_ts":"2026-03-15T00:05:42.781379Z","subscription_id":null,"message_id":null,"source_sequence":null,"raw_message_meta":{"raw_channel":"lightning_board_BTC_JPY","subscription_channel":"lightning_board_BTC_JPY","recv_timeout_sec":10,"ssl_verify":false,"socket_url":"wss://ws.lightstream.bitflyer.com/json-rpc"},"source_payload":{"mid_price":11385185.0,"bids":[{"price":11380061.0,"size":0.1275}],"asks":[]}}}
{"schema_version":"collector.vnext.raw","schema_contract":null,"schema_contract_version":null,"payload_contract_version":null,"record_type":"market.orderbook.diff","record_id":"collector_main-market-orderbook-diff-000000000079","collector_id":"collector_main","collector_role":"production","host_name":"MAIN-PC","session_id":"collector_main-sess-20260315T000540Z-fe3e7262","stream_session_id":"collector_main-stream-bitflyer-board_ws-20260315T000541Z-6f3df026","exchange":"bitflyer","market":"spot","symbol":"BTC_JPY","instrument_id":"bitflyer.spot.BTC_JPY","channel":"board_ws","transport":"websocket","source_event_id":null,"source_sequence":null,"sequence_id":79,"exchange_ts":null,"collector_ts":"2026-03-15T00:05:42Z","ingest_ts":"2026-03-15T00:05:42Z","event_ts":"2026-03-15T00:05:42Z","quality_flags":[],"is_partial":false,"is_reconstructed":false,"confidence_score":1.0,"payload":{"provider":"bitflyer_ws_board","exchange":"bitflyer","transport":"websocket","channel":"lightning_board_BTC_JPY","received_ts":"2026-03-15T00:05:42.906573Z","subscription_id":null,"message_id":null,"source_sequence":null,"raw_message_meta":{"raw_channel":"lightning_board_BTC_JPY","subscription_channel":"lightning_board_BTC_JPY","recv_timeout_sec":10,"ssl_verify":false,"socket_url":"wss://ws.lightstream.bitflyer.com/json-rpc"},"source_payload":{"mid_price":11385185.0,"bids":[{"price":11373701.0,"size":0.07},{"price":11379052.0,"size":0.0},{"price":11380061.0,"size":0.0}],"asks":[]}}}
{"schema_version":"collector.vnext.raw","schema_contract":null,"schema_contract_version":null,"payload_contract_version":null,"record_type":"market.orderbook.diff","record_id":"collector_main-market-orderbook-diff-000000000081","collector_id":"collector_main","collector_role":"production","host_name":"MAIN-PC","session_id":"collector_main-sess-20260315T000540Z-fe3e7262","stream_session_id":"collector_main-stream-bitflyer-board_ws-20260315T000541Z-6f3df026","exchange":"bitflyer","market":"spot","symbol":"BTC_JPY","instrument_id":"bitflyer.spot.BTC_JPY","channel":"board_ws","transport":"websocket","source_event_id":null,"source_sequence":null,"sequence_id":81,"exchange_ts":null,"collector_ts":"2026-03-15T00:05:43Z","ingest_ts":"2026-03-15T00:05:43Z","event_ts":"2026-03-15T00:05:43Z","quality_flags":[],"is_partial":false,"is_reconstructed":false,"confidence_score":1.0,"payload":{"provider":"bitflyer_ws_board","exchange":"bitflyer","transport":"websocket","channel":"lightning_board_BTC_JPY","received_ts":"2026-03-15T00:05:43.063114Z","subscription_id":null,"message_id":null,"source_sequence":null,"raw_message_meta":{"raw_channel":"lightning_board_BTC_JPY","subscription_channel":"lightning_board_BTC_JPY","recv_timeout_sec":10,"ssl_verify":false,"socket_url":"wss://ws.lightstream.bitflyer.com/json-rpc"},"source_payload":{"mid_price":11385185.0,"bids":[{"price":11372562.0,"size":0.0}],"asks":[]}}}
{"schema_version":"collector.vnext.raw","schema_contract":null,"schema_contract_version":null,"payload_contract_version":null,"record_type":"market.orderbook.diff","record_id":"collector_main-market-orderbook-diff-000000000083","collector_id":"collector_main","collector_role":"production","host_name":"MAIN-PC","session_id":"collector_main-sess-20260315T000540Z-fe3e7262","stream_session_id":"collector_main-stream-bitflyer-board_ws-20260315T000541Z-6f3df026","exchange":"bitflyer","market":"spot","symbol":"BTC_JPY","instrument_id":"bitflyer.spot.BTC_JPY","channel":"board_ws","transport":"websocket","source_event_id":null,"source_sequence":null,"sequence_id":83,"exchange_ts":null,"collector_ts":"2026-03-15T00:05:43Z","ingest_ts":"2026-03-15T00:05:43Z","event_ts":"2026-03-15T00:05:43Z","quality_flags":[],"is_partial":false,"is_reconstructed":false,"confidence_score":1.0,"payload":{"provider":"bitflyer_ws_board","exchange":"bitflyer","transport":"websocket","channel":"lightning_board_BTC_JPY","received_ts":"2026-03-15T00:05:43.173347Z","subscription_id":null,"message_id":null,"source_sequence":null,"raw_message_meta":{"raw_channel":"lightning_board_BTC_JPY","subscription_channel":"lightning_board_BTC_JPY","recv_timeout_sec":10,"ssl_verify":false,"socket_url":"wss://ws.lightstream.bitflyer.com/json-rpc"},"source_payload":{"mid_price":11385185.0,"bids":[{"price":11378353.0,"size":0.1275}],"asks":[]}}}
{"schema_version":"collector.vnext.raw","schema_contract":null,"schema_contract_version":null,"payload_contract_version":null,"record_type":"market.orderbook.diff","record_id":"collector_main-market-orderbook-diff-000000000085","collector_id":"collector_main","collector_role":"production","host_name":"MAIN-PC","session_id":"collector_main-sess-20260315T000540Z-fe3e7262","stream_session_id":"collector_main-stream-bitflyer-board_ws-20260315T000541Z-6f3df026","exchange":"bitflyer","market":"spot","symbol":"BTC_JPY","instrument_id":"bitflyer.spot.BTC_JPY","channel":"board_ws","transport":"websocket","source_event_id":null,"source_sequence":null,"sequence_id":85,"exchange_ts":null,"collector_ts":"2026-03-15T00:05:43Z","ingest_ts":"2026-03-15T00:05:43Z","event_ts":"2026-03-15T00:05:43Z","quality_flags":[],"is_partial":false,"is_reconstructed":false,"confidence_score":1.0,"payload":{"provider":"bitflyer_ws_board","exchange":"bitflyer","transport":"websocket","channel":"lightning_board_BTC_JPY","received_ts":"2026-03-15T00:05:43.328428Z","subscription_id":null,"message_id":null,"source_sequence":null,"raw_message_meta":{"raw_channel":"lightning_board_BTC_JPY","subscription_channel":"lightning_board_BTC_JPY","recv_timeout_sec":10,"ssl_verify":false,"socket_url":"wss://ws.lightstream.bitflyer.com/json-rpc"},"source_payload":{"mid_price":11385185.0,"bids":[{"price":11383826.0,"size":0.037},{"price":11370500.0,"size":0.0},{"price":11378353.0,"size":0.0}],"asks":[]}}}
{"schema_version":"collector.vnext.raw","schema_contract":null,"schema_contract_version":null,"payload_contract_version":null,"record_type":"market.orderbook.diff","record_id":"collector_main-market-orderbook-diff-000000000087","collector_id":"collector_main","collector_role":"production","host_name":"MAIN-PC","session_id":"collector_main-sess-20260315T000540Z-fe3e7262","stream_session_id":"collector_main-stream-bitflyer-board_ws-20260315T000541Z-6f3df026","exchange":"bitflyer","market":"spot","symbol":"BTC_JPY","instrument_id":"bitflyer.spot.BTC_JPY","channel":"board_ws","transport":"websocket","source_event_id":null,"source_sequence":null,"sequence_id":87,"exchange_ts":null,"collector_ts":"2026-03-15T00:05:43Z","ingest_ts":"2026-03-15T00:05:43Z","event_ts":"2026-03-15T00:05:43Z","quality_flags":[],"is_partial":false,"is_reconstructed":false,"confidence_score":1.0,"payload":{"provider":"bitflyer_ws_board","exchange":"bitflyer","transport":"websocket","channel":"lightning_board_BTC_JPY","received_ts":"2026-03-15T00:05:43.446933Z","subscription_id":null,"message_id":null,"source_sequence":null,"raw_message_meta":{"raw_channel":"lightning_board_BTC_JPY","subscription_channel":"lightning_board_BTC_JPY","recv_timeout_sec":10,"ssl_verify":false,"socket_url":"wss://ws.lightstream.bitflyer.com/json-rpc"},"source_payload":{"mid_price":11385185.0,"bids":[{"price":11378923.0,"size":0.1275}],"asks":[{"price":11399532.0,"size":0.0}]}}}
{"schema_version":"collector.vnext.raw","schema_contract":null,"schema_contract_version":null,"payload_contract_version":null,"record_type":"market.orderbook.diff","record_id":"collector_main-market-orderbook-diff-000000000089","collector_id":"collector_main","collector_role":"production","host_name":"MAIN-PC","session_id":"collector_main-sess-20260315T000540Z-fe3e7262","stream_session_id":"collector_main-stream-bitflyer-board_ws-20260315T000541Z-6f3df026","exchange":"bitflyer","market":"spot","symbol":"BTC_JPY","instrument_id":"bitflyer.spot.BTC_JPY","channel":"board_ws","transport":"websocket","source_event_id":null,"source_sequence":null,"sequence_id":89,"exchange_ts":null,"collector_ts":"2026-03-15T00:05:43Z","ingest_ts":"2026-03-15T00:05:43Z","event_ts":"2026-03-15T00:05:43Z","quality_flags":[],"is_partial":false,"is_reconstructed":false,"confidence_score":1.0,"payload":{"provider":"bitflyer_ws_board","exchange":"bitflyer","transport":"websocket","channel":"lightning_board_BTC_JPY","received_ts":"2026-03-15T00:05:43.719842Z","subscription_id":null,"message_id":null,"source_sequence":null,"raw_message_meta":{"raw_channel":"lightning_board_BTC_JPY","subscription_channel":"lightning_board_BTC_JPY","recv_timeout_sec":10,"ssl_verify":false,"socket_url":"wss://ws.lightstream.bitflyer.com/json-rpc"},"source_payload":{"mid_price":11385185.0,"bids":[],"asks":[{"price":11399531.0,"size":0.0898437}]}}}
{"schema_version":"collector.vnext.raw","schema_contract":null,"schema_contract_version":null,"payload_contract_version":null,"record_type":"market.orderbook.diff","record_id":"collector_main-market-orderbook-diff-000000000091","collector_id":"collector_main","collector_role":"production","host_name":"MAIN-PC","session_id":"collector_main-sess-20260315T000540Z-fe3e7262","stream_session_id":"collector_main-stream-bitflyer-board_ws-20260315T000541Z-6f3df026","exchange":"bitflyer","market":"spot","symbol":"BTC_JPY","instrument_id":"bitflyer.spot.BTC_JPY","channel":"board_ws","transport":"websocket","source_event_id":null,"source_sequence":null,"sequence_id":91,"exchange_ts":null,"collector_ts":"2026-03-15T00:05:43Z","ingest_ts":"2026-03-15T00:05:43Z","event_ts":"2026-03-15T00:05:43Z","quality_flags":[],"is_partial":false,"is_reconstructed":false,"confidence_score":1.0,"payload":{"provider":"bitflyer_ws_board","exchange":"bitflyer","transport":"websocket","channel":"lightning_board_BTC_JPY","received_ts":"2026-03-15T00:05:43.844883Z","subscription_id":null,"message_id":null,"source_sequence":null,"raw_message_meta":{"raw_channel":"lightning_board_BTC_JPY","subscription_channel":"lightning_board_BTC_JPY","recv_timeout_sec":10,"ssl_verify":false,"socket_url":"wss://ws.lightstream.bitflyer.com/json-rpc"},"source_payload":{"mid_price":11385185.0,"bids":[{"price":11378354.0,"size":0.1275},{"price":11378923.0,"size":0.0},{"price":11373701.0,"size":0.0}],"asks":[]}}}
{"schema_version":"collector.vnext.raw","schema_contract":null,"schema_contract_version":null,"payload_contract_version":null,"record_type":"market.orderbook.diff","record_id":"collector_main-market-orderbook-diff-000000000093","collector_id":"collector_main","collector_role":"production","host_name":"MAIN-PC","session_id":"collector_main-sess-20260315T000540Z-fe3e7262","stream_session_id":"collector_main-stream-bitflyer-board_ws-20260315T000541Z-6f3df026","exchange":"bitflyer","market":"spot","symbol":"BTC_JPY","instrument_id":"bitflyer.spot.BTC_JPY","channel":"board_ws","transport":"websocket","source_event_id":null,"source_sequence":null,"sequence_id":93,"exchange_ts":null,"collector_ts":"2026-03-15T00:05:43Z","ingest_ts":"2026-03-15T00:05:43Z","event_ts":"2026-03-15T00:05:43Z","quality_flags":[],"is_partial":false,"is_reconstructed":false,"confidence_score":1.0,"payload":{"provider":"bitflyer_ws_board","exchange":"bitflyer","transport":"websocket","channel":"lightning_board_BTC_JPY","received_ts":"2026-03-15T00:05:43.946239Z","subscription_id":null,"message_id":null,"source_sequence":null,"raw_message_meta":{"raw_channel":"lightning_board_BTC_JPY","subscription_channel":"lightning_board_BTC_JPY","recv_timeout_sec":10,"ssl_verify":false,"socket_url":"wss://ws.lightstream.bitflyer.com/json-rpc"},"source_payload":{"mid_price":11385185.0,"bids":[{"price":11372562.0,"size":0.09},{"price":11380062.0,"size":0.1275},{"price":11366629.0,"size":0.0}],"asks":[]}}}
{"schema_version":"collector.vnext.raw","schema_contract":null,"schema_contract_version":null,"payload_contract_version":null,"record_type":"market.orderbook.diff","record_id":"collector_main-market-orderbook-diff-000000000095","collector_id":"collector_main","collector_role":"production","host_name":"MAIN-PC","session_id":"collector_main-sess-20260315T000540Z-fe3e7262","stream_session_id":"collector_main-stream-bitflyer-board_ws-20260315T000541Z-6f3df026","exchange":"bitflyer","market":"spot","symbol":"BTC_JPY","instrument_id":"bitflyer.spot.BTC_JPY","channel":"board_ws","transport":"websocket","source_event_id":null,"source_sequence":null,"sequence_id":95,"exchange_ts":null,"collector_ts":"2026-03-15T00:05:44Z","ingest_ts":"2026-03-15T00:05:44Z","event_ts":"2026-03-15T00:05:44Z","quality_flags":[],"is_partial":false,"is_reconstructed":false,"confidence_score":1.0,"payload":{"provider":"bitflyer_ws_board","exchange":"bitflyer","transport":"websocket","channel":"lightning_board_BTC_JPY","received_ts":"2026-03-15T00:05:44.086417Z","subscription_id":null,"message_id":null,"source_sequence":null,"raw_message_meta":{"raw_channel":"lightning_board_BTC_JPY","subscription_channel":"lightning_board_BTC_JPY","recv_timeout_sec":10,"ssl_verify":false,"socket_url":"wss://ws.lightstream.bitflyer.com/json-rpc"},"source_payload":{"mid_price":11385185.0,"bids":[{"price":11380062.0,"size":0.0},{"price":11378354.0,"size":0.0}],"asks":[]}}}
{"schema_version":"collector.vnext.raw","schema_contract":null,"schema_contract_version":null,"payload_contract_version":null,"record_type":"market.orderbook.diff","record_id":"collector_main-market-orderbook-diff-000000000097","collector_id":"collector_main","collector_role":"production","host_name":"MAIN-PC","session_id":"collector_main-sess-20260315T000540Z-fe3e7262","stream_session_id":"collector_main-stream-bitflyer-board_ws-20260315T000541Z-6f3df026","exchange":"bitflyer","market":"spot","symbol":"BTC_JPY","instrument_id":"bitflyer.spot.BTC_JPY","channel":"board_ws","transport":"websocket","source_event_id":null,"source_sequence":null,"sequence_id":97,"exchange_ts":null,"collector_ts":"2026-03-15T00:05:44Z","ingest_ts":"2026-03-15T00:05:44Z","event_ts":"2026-03-15T00:05:44Z","quality_flags":[],"is_partial":false,"is_reconstructed":false,"confidence_score":1.0,"payload":{"provider":"bitflyer_ws_board","exchange":"bitflyer","transport":"websocket","channel":"lightning_board_BTC_JPY","received_ts":"2026-03-15T00:05:44.329965Z","subscription_id":null,"message_id":null,"source_sequence":null,"raw_message_meta":{"raw_channel":"lightning_board_BTC_JPY","subscription_channel":"lightning_board_BTC_JPY","recv_timeout_sec":10,"ssl_verify":false,"socket_url":"wss://ws.lightstream.bitflyer.com/json-rpc"},"source_payload":{"mid_price":11385185.0,"bids":[{"price":11378354.0,"size":0.1275}],"asks":[]}}}
{"schema_version":"collector.vnext.raw","schema_contract":null,"schema_contract_version":null,"payload_contract_version":null,"record_type":"market.orderbook.diff","record_id":"collector_main-market-orderbook-diff-000000000099","collector_id":"collector_main","collector_role":"production","host_name":"MAIN-PC","session_id":"collector_main-sess-20260315T000540Z-fe3e7262","stream_session_id":"collector_main-stream-bitflyer-board_ws-20260315T000541Z-6f3df026","exchange":"bitflyer","market":"spot","symbol":"BTC_JPY","instrument_id":"bitflyer.spot.BTC_JPY","channel":"board_ws","transport":"websocket","source_event_id":null,"source_sequence":null,"sequence_id":99,"exchange_ts":null,"collector_ts":"2026-03-15T00:05:44Z","ingest_ts":"2026-03-15T00:05:44Z","event_ts":"2026-03-15T00:05:44Z","quality_flags":[],"is_partial":false,"is_reconstructed":false,"confidence_score":1.0,"payload":{"provider":"bitflyer_ws_board","exchange":"bitflyer","transport":"websocket","channel":"lightning_board_BTC_JPY","received_ts":"2026-03-15T00:05:44.572537Z","subscription_id":null,"message_id":null,"source_sequence":null,"raw_message_meta":{"raw_channel":"lightning_board_BTC_JPY","subscription_channel":"lightning_board_BTC_JPY","recv_timeout_sec":10,"ssl_verify":false,"socket_url":"wss://ws.lightstream.bitflyer.com/json-rpc"},"source_payload":{"mid_price":11385185.0,"bids":[{"price":11378923.0,"size":0.1275}],"asks":[{"price":11390529.0,"size":0.0}]}}}
{"schema_version":"collector.vnext.raw","schema_contract":null,"schema_contract_version":null,"payload_contract_version":null,"record_type":"market.orderbook.diff","record_id":"collector_main-market-orderbook-diff-000000000101","collector_id":"collector_main","collector_role":"production","host_name":"MAIN-PC","session_id":"collector_main-sess-20260315T000540Z-fe3e7262","stream_session_id":"collector_main-stream-bitflyer-board_ws-20260315T000541Z-6f3df026","exchange":"bitflyer","market":"spot","symbol":"BTC_JPY","instrument_id":"bitflyer.spot.BTC_JPY","channel":"board_ws","transport":"websocket","source_event_id":null,"source_sequence":null,"sequence_id":101,"exchange_ts":null,"collector_ts":"2026-03-15T00:05:44Z","ingest_ts":"2026-03-15T00:05:44Z","event_ts":"2026-03-15T00:05:44Z","quality_flags":[],"is_partial":false,"is_reconstructed":false,"confidence_score":1.0,"payload":{"provider":"bitflyer_ws_board","exchange":"bitflyer","transport":"websocket","channel":"lightning_board_BTC_JPY","received_ts":"2026-03-15T00:05:44.688457Z","subscription_id":null,"message_id":null,"source_sequence":null,"raw_message_meta":{"raw_channel":"lightning_board_BTC_JPY","subscription_channel":"lightning_board_BTC_JPY","recv_timeout_sec":10,"ssl_verify":false,"socket_url":"wss://ws.lightstream.bitflyer.com/json-rpc"},"source_payload":{"mid_price":11385185.0,"bids":[{"price":11373701.0,"size":0.07},{"price":11378354.0,"size":0.0}],"asks":[]}}}
{"schema_version":"collector.vnext.raw","schema_contract":null,"schema_contract_version":null,"payload_contract_version":null,"record_type":"market.orderbook.diff","record_id":"collector_main-market-orderbook-diff-000000000103","collector_id":"collector_main","collector_role":"production","host_name":"MAIN-PC","session_id":"collector_main-sess-20260315T000540Z-fe3e7262","stream_session_id":"collector_main-stream-bitflyer-board_ws-20260315T000541Z-6f3df026","exchange":"bitflyer","market":"spot","symbol":"BTC_JPY","instrument_id":"bitflyer.spot.BTC_JPY","channel":"board_ws","transport":"websocket","source_event_id":null,"source_sequence":null,"sequence_id":103,"exchange_ts":null,"collector_ts":"2026-03-15T00:05:44Z","ingest_ts":"2026-03-15T00:05:44Z","event_ts":"2026-03-15T00:05:44Z","quality_flags":[],"is_partial":false,"is_reconstructed":false,"confidence_score":1.0,"payload":{"provider":"bitflyer_ws_board","exchange":"bitflyer","transport":"websocket","channel":"lightning_board_BTC_JPY","received_ts":"2026-03-15T00:05:44.828336Z","subscription_id":null,"message_id":null,"source_sequence":null,"raw_message_meta":{"raw_channel":"lightning_board_BTC_JPY","subscription_channel":"lightning_board_BTC_JPY","recv_timeout_sec":10,"ssl_verify":false,"socket_url":"wss://ws.lightstream.bitflyer.com/json-rpc"},"source_payload":{"mid_price":11385185.0,"bids":[{"price":11378923.0,"size":0.0},{"price":11372562.0,"size":0.0}],"asks":[]}}}
{"schema_version":"collector.vnext.raw","schema_contract":null,"schema_contract_version":null,"payload_contract_version":null,"record_type":"market.orderbook.diff","record_id":"collector_main-market-orderbook-diff-000000000105","collector_id":"collector_main","collector_role":"production","host_name":"MAIN-PC","session_id":"collector_main-sess-20260315T000540Z-fe3e7262","stream_session_id":"collector_main-stream-bitflyer-board_ws-20260315T000541Z-6f3df026","exchange":"bitflyer","market":"spot","symbol":"BTC_JPY","instrument_id":"bitflyer.spot.BTC_JPY","channel":"board_ws","transport":"websocket","source_event_id":null,"source_sequence":null,"sequence_id":105,"exchange_ts":null,"collector_ts":"2026-03-15T00:05:44Z","ingest_ts":"2026-03-15T00:05:44Z","event_ts":"2026-03-15T00:05:44Z","quality_flags":[],"is_partial":false,"is_reconstructed":false,"confidence_score":1.0,"payload":{"provider":"bitflyer_ws_board","exchange":"bitflyer","transport":"websocket","channel":"lightning_board_BTC_JPY","received_ts":"2026-03-15T00:05:44.969875Z","subscription_id":null,"message_id":null,"source_sequence":null,"raw_message_meta":{"raw_channel":"lightning_board_BTC_JPY","subscription_channel":"lightning_board_BTC_JPY","recv_timeout_sec":10,"ssl_verify":false,"socket_url":"wss://ws.lightstream.bitflyer.com/json-rpc"},"source_payload":{"mid_price":11385185.0,"bids":[{"price":11380062.0,"size":0.1275}],"asks":[]}}}
{"schema_version":"collector.vnext.raw","schema_contract":null,"schema_contract_version":null,"payload_contract_version":null,"record_type":"market.orderbook.diff","record_id":"collector_main-market-orderbook-diff-000000000107","collector_id":"collector_main","collector_role":"production","host_name":"MAIN-PC","session_id":"collector_main-sess-20260315T000540Z-fe3e7262","stream_session_id":"collector_main-stream-bitflyer-board_ws-20260315T000541Z-6f3df026","exchange":"bitflyer","market":"spot","symbol":"BTC_JPY","instrument_id":"bitflyer.spot.BTC_JPY","channel":"board_ws","transport":"websocket","source_event_id":null,"source_sequence":null,"sequence_id":107,"exchange_ts":null,"collector_ts":"2026-03-15T00:05:45Z","ingest_ts":"2026-03-15T00:05:45Z","event_ts":"2026-03-15T00:05:45Z","quality_flags":[],"is_partial":false,"is_reconstructed":false,"confidence_score":1.0,"payload":{"provider":"bitflyer_ws_board","exchange":"bitflyer","transport":"websocket","channel":"lightning_board_BTC_JPY","received_ts":"2026-03-15T00:05:45.141102Z","subscription_id":null,"message_id":null,"source_sequence":null,"raw_message_meta":{"raw_channel":"lightning_board_BTC_JPY","subscription_channel":"lightning_board_BTC_JPY","recv_timeout_sec":10,"ssl_verify":false,"socket_url":"wss://ws.lightstream.bitflyer.com/json-rpc"},"source_payload":{"mid_price":11385185.0,"bids":[{"price":11378354.0,"size":0.1275},{"price":11380062.0,"size":0.0}],"asks":[]}}}
{"schema_version":"collector.vnext.raw","schema_contract":null,"schema_contract_version":null,"payload_contract_version":null,"record_type":"market.orderbook.diff","record_id":"collector_main-market-orderbook-diff-000000000109","collector_id":"collector_main","collector_role":"production","host_name":"MAIN-PC","session_id":"collector_main-sess-20260315T000540Z-fe3e7262","stream_session_id":"collector_main-stream-bitflyer-board_ws-20260315T000541Z-6f3df026","exchange":"bitflyer","market":"spot","symbol":"BTC_JPY","instrument_id":"bitflyer.spot.BTC_JPY","channel":"board_ws","transport":"websocket","source_event_id":null,"source_sequence":null,"sequence_id":109,"exchange_ts":null,"collector_ts":"2026-03-15T00:05:45Z","ingest_ts":"2026-03-15T00:05:45Z","event_ts":"2026-03-15T00:05:45Z","quality_flags":[],"is_partial":false,"is_reconstructed":false,"confidence_score":1.0,"payload":{"provider":"bitflyer_ws_board","exchange":"bitflyer","transport":"websocket","channel":"lightning_board_BTC_JPY","received_ts":"2026-03-15T00:05:45.375465Z","subscription_id":null,"message_id":null,"source_sequence":null,"raw_message_meta":{"raw_channel":"lightning_board_BTC_JPY","subscription_channel":"lightning_board_BTC_JPY","recv_timeout_sec":10,"ssl_verify":false,"socket_url":"wss://ws.lightstream.bitflyer.com/json-rpc"},"source_payload":{"mid_price":11385185.0,"bids":[{"price":11378923.0,"size":0.1275}],"asks":[]}}}
{"schema_version":"collector.vnext.raw","schema_contract":null,"schema_contract_version":null,"payload_contract_version":null,"record_type":"market.orderbook.diff","record_id":"collector_main-market-orderbook-diff-000000000111","collector_id":"collector_main","collector_role":"production","host_name":"MAIN-PC","session_id":"collector_main-sess-20260315T000540Z-fe3e7262","stream_session_id":"collector_main-stream-bitflyer-board_ws-20260315T000541Z-6f3df026","exchange":"bitflyer","market":"spot","symbol":"BTC_JPY","instrument_id":"bitflyer.spot.BTC_JPY","channel":"board_ws","transport":"websocket","source_event_id":null,"source_sequence":null,"sequence_id":111,"exchange_ts":null,"collector_ts":"2026-03-15T00:05:45Z","ingest_ts":"2026-03-15T00:05:45Z","event_ts":"2026-03-15T00:05:45Z","quality_flags":[],"is_partial":false,"is_reconstructed":false,"confidence_score":1.0,"payload":{"provider":"bitflyer_ws_board","exchange":"bitflyer","transport":"websocket","channel":"lightning_board_BTC_JPY","received_ts":"2026-03-15T00:05:45.515839Z","subscription_id":null,"message_id":null,"source_sequence":null,"raw_message_meta":{"raw_channel":"lightning_board_BTC_JPY","subscription_channel":"lightning_board_BTC_JPY","recv_timeout_sec":10,"ssl_verify":false,"socket_url":"wss://ws.lightstream.bitflyer.com/json-rpc"},"source_payload":{"mid_price":11385185.0,"bids":[{"price":11378354.0,"size":0.0}],"asks":[]}}}
{"schema_version":"collector.vnext.raw","schema_contract":null,"schema_contract_version":null,"payload_contract_version":null,"record_type":"market.orderbook.snapshot","record_id":"collector_main-market-orderbook-snapshot-000000000113","collector_id":"collector_main","collector_role":"production","host_name":"MAIN-PC","session_id":"collector_main-sess-20260315T000540Z-fe3e7262","stream_session_id":"collector_main-stream-bitflyer-board_ws-20260315T000541Z-6f3df026","exchange":"bitflyer","market":"spot","symbol":"BTC_JPY","instrument_id":"bitflyer.spot.BTC_JPY","channel":"board_ws","transport":"websocket","source_event_id":null,"source_sequence":null,"sequence_id":113,"exchange_ts":null,"collector_ts":"2026-03-15T00:05:45Z","ingest_ts":"2026-03-15T00:05:45Z","event_ts":"2026-03-15T00:05:45Z","quality_flags":[],"is_partial":false,"is_reconstructed":false,"confidence_score":1.0,"payload":{"provider":"bitflyer_ws_board_snapshot","exchange":"bitflyer","transport":"websocket","channel":"lightning_board_snapshot_BTC_JPY","received_ts":"2026-03-15T00:05:45.593841Z","subscription_id":null,"message_id":null,"source_sequence":null,"raw_message_meta":{"raw_channel":"lightning_board_snapshot_BTC_JPY","subscription_channel":"lightning_board_snapshot_BTC_JPY","recv_timeout_sec":10,"ssl_verify":false,"socket_url":"wss://ws.lightstream.bitflyer.com/json-rpc"},"source_payload":{"mid_price":11385185.0,"bids":[{"price":11383826.0,"size":0.037},{"price":11383825.0,"size":0.00999733},{"price":11380719.0,"size":0.01458},{"price":11380081.0,"size":0.0109042},{"price":11380046.0,"size":0.02},{"price":11380045.0,"size":0.014448},{"price":11379353.0,"size":0.005},{"price":11378923.0,"size":0.1275},{"price":11378822.0,"size":0.01},{"price":11378097.0,"size":0.266},{"price":11376948.0,"size":0.01548},{"price":11376171.0,"size":0.0553392},{"price":11375466.0,"size":3.11448561},{"price":11375465.0,"size":0.5},{"price":11373701.0,"size":0.07},{"price":11372897.0,"size":0.06},{"price":11372771.0,"size":0.00999891},{"price":11372266.0,"size":0.0527},{"price":11371900.0,"size":0.005},{"price":11370000.0,"size":0.01},{"price":11368376.0,"size":0.01},{"price":11368223.0,"size":0.23},{"price":11366247.0,"size":0.036},{"price":11366008.0,"size":0.04},{"price":11365378.0,"size":0.05},{"price":11364809.0,"size":0.05},{"price":11362842.0,"size":0.29759641},{"price":11362278.0,"size":0.31206306},{"price":11362277.0,"size":0.9772867},{"price":11361538.0,"size":1.50015},{"price":11359891.0,"size":0.3002},{"price":11358376.0,"size":0.01},{"price":11357129.0,"size":0.297},{"price":11356706.0,"size":1.484},{"price":11354367.0,"size":0.3124},{"price":11353489.0,"size":0.09525901},{"price":11353488.0,"size":0.27174084},{"price":11351605.0,"size":0.3082},{"price":11350000.0,"size":0.51},{"price":11348189.0,"size":0.003},{"price":11347667.0,"size":0.001},{"price":11347661.0,"size":0.6},{"price":11347560.0,"size":0.002},{"price":11347461.0,"size":0.002},{"price":11344148.0,"size":0.002},{"price":11342910.0,"size":0.002},{"price":11342072.0,"size":1.966},{"price":11341671.0,"size":0.23},{"price":11340736.0,"size":0.002},{"price":11340000.0,"size":0.005},{"price":11338359.0,"size":0.002},{"price":11337324.0,"size":0.002},{"price":11336383.0,"size":0.001},{"price":11336319.0,"size":0.00195},{"price":11333912.0,"size":0.002},{"price":11333808.0,"size":0.002},{"price":11331227.0,"size":0.51},{"price":11331000.0,"size":0.5},{"price":11330500.0,"size":0.002},{"price":11330000.0,"size":0.02442},{"price":11329257.0,"size":0.002},{"price":11328186.0,"size":2.036},{"price":11327088.0,"size":0.002},{"price":11325101.0,"size":0.001},{"price":11324706.0,"size":0.002},{"price":11323676.0,"size":0.002},{"price":11320264.0,"size":0.002},{"price":11320155.0,"size":0.002},{"price":11320000.0,"size":0.05},{"price":11316852.0,"size":0.002},{"price":11315604.0,"size":0.002},{"price":11315000.0,"size":0.05},{"price":11313996.0,"size":0.00195},{"price":11313819.0,"size":0.001},{"price":11311053.0,"size":0.002},{"price":11310000.0,"size":0.01},{"price":11309999.0,"size":0.177},{"price":11307999.0,"size":0.01},{"price":11305439.0,"size":1.951},{"price":11304836.0,"size":1.12},{"price":11303918.0,"size":0.01},{"price":11303000.0,"size":0.5},{"price":11302535.0,"size":0.001},{"price":11302466.0,"size":0.001},{"price":11301268.0,"size":0.01},{"price":11300000.0,"size":3.01685256},{"price":11298000.0,"size":0.01},{"price":11296865.0,"size":0.0015},{"price":11294756.0,"size":1.0},{"price":11291282.0,"size":0.001},{"price":11291268.0,"size":0.01},{"price":11291000.0,"size":0.5},{"price":11290000.0,"size":0.003},{"price":11281268.0,"size":0.01},{"price":11280000.0,"size":0.0163},{"price":11279960.0,"size":0.001},{"price":11279282.0,"size":0.0015},{"price":11278000.0,"size":0.0025},{"price":11275000.0,"size":0.001},{"price":11274588.0,"size":0.0047},{"price":11271268.0,"size":0.01},{"price":11271000.0,"size":0.003},{"price":11270000.0,"size":0.106},{"price":11269424.0,"size":0.8},{"price":11268871.0,"size":0.28},{"price":11268638.0,"size":0.001},{"price":11268411.0,"size":0.01},{"price":11266666.0,"size":0.04},{"price":11265000.0,"size":0.02},{"price":11263000.0,"size":0.006},{"price":11262564.0,"size":0.0015},{"price":11261268.0,"size":0.01},{"price":11260000.0,"size":0.3565},{"price":11257315.0,"size":0.001},{"price":11257000.0,"size":0.001},{"price":11255200.0,"size":0.001},{"price":11255115.0,"size":0.00377},{"price":11253814.0,"size":2.2},{"price":11253690.0,"size":0.01},{"price":11253000.0,"size":0.03189},{"price":11251405.0,"size":0.139},{"price":11251268.0,"size":0.01},{"price":11251111.0,"size":0.0015},{"price":11251000.0,"size":0.0131},{"price":11250250.0,"size":0.00105},{"price":11250200.0,"size":0.001},{"price":11250005.0,"size":0.001},{"price":11250001.0,"size":0.00104},{"price":11250000.0,"size":1.62712889},{"price":11245993.0,"size":0.001},{"price":11245141.0,"size":0.0031},{"price":11245000.0,"size":0.05},{"price":11244444.0,"size":0.04},{"price":11244243.0,"size":0.01},{"price":11240200.0,"size":0.001},{"price":11240000.0,"size":0.007304},{"price":11236190.0,"size":0.01},{"price":11235200.0,"size":0.001},{"price":11234670.0,"size":0.001},{"price":11232000.0,"size":0.089},{"price":11231243.0,"size":0.01},{"price":11231000.0,"size":0.105},{"price":11230200.0,"size":0.001},{"price":11230000.0,"size":0.0308},{"price":11226952.0,"size":0.972},{"price":11224500.0,"size":0.06},{"price":11223968.0,"size":0.001},{"price":11223348.0,"size":0.001},{"price":11223344.0,"size":0.01},{"price":11223000.0,"size":0.1},{"price":11222222.0,"size":0.093525},{"price":11221120.0,"size":0.001},{"price":11220200.0,"size":0.001},{"price":11220001.0,"size":0.004457},{"price":11220000.0,"size":0.321},{"price":11219000.0,"size":0.1},{"price":11217326.0,"size":0.02},{"price":11215200.0,"size":0.001},{"price":11213690.0,"size":0.01},{"price":11212025.0,"size":0.001},{"price":11211800.0,"size":0.001},{"price":11211111.0,"size":0.06},{"price":11210200.0,"size":0.001},{"price":11210000.0,"size":0.10622},{"price":11208032.0,"size":0.01},{"price":11206000.0,"size":0.09015},{"price":11205200.0,"size":0.001},{"price":11204578.0,"size":0.002},{"price":11201000.0,"size":0.01},{"price":11200800.0,"size":0.05},{"price":11200703.0,"size":0.001},{"price":11200425.0,"size":0.1},{"price":11200200.0,"size":0.001},{"price":11200198.0,"size":0.003},{"price":11200150.0,"size":0.002},{"price":11200002.0,"size":0.001},{"price":11200001.0,"size":0.01104},{"price":11200000.0,"size":1.15226728},{"price":11198508.0,"size":0.05},{"price":11198243.0,"size":0.01},{"price":11197134.0,"size":0.993},{"price":11197000.0,"size":0.0085},{"price":11194090.0,"size":0.03},{"price":11190770.0,"size":0.0309},{"price":11190000.0,"size":0.0010016},{"price":11189555.0,"size":0.5},{"price":11189381.0,"size":0.001},{"price":11188629.0,"size":0.01},{"price":11188382.0,"size":0.001},{"price":11185000.0,"size":0.0085},{"price":11180000.0,"size":0.225},{"price":11178058.0,"size":0.001},{"price":11170000.0,"size":0.001},{"price":11169662.0,"size":0.01},{"price":11169593.0,"size":0.001},{"price":11169243.0,"size":0.01},{"price":11166736.0,"size":0.001},{"price":11164029.0,"size":0.001},{"price":11160854.0,"size":0.1},{"price":11160000.0,"size":0.02376},{"price":11155413.0,"size":0.001},{"price":11155377.0,"size":0.00636009},{"price":11153999.0,"size":0.00101},{"price":11151000.0,"size":0.001},{"price":11150250.0,"size":0.00175},{"price":11150005.0,"size":0.001},{"price":11150001.0,"size":0.00104},{"price":11150000.0,"size":0.6533956},{"price":11148000.0,"size":0.08963},{"price":11147546.0,"size":0.02},{"price":11144091.0,"size":0.001},{"price":11144000.0,"size":0.0897},{"price":11143986.0,"size":0.02},{"price":11140139.0,"size":1.0},{"price":11140000.0,"size":0.2},{"price":11136243.0,"size":0.01},{"price":11135869.0,"size":0.1},{"price":11132768.0,"size":0.001},{"price":11130000.0,"size":0.116},{"price":11129979.0,"size":0.0053908},{"price":11124900.0,"size":0.00133},{"price":11121090.0,"size":0.1},{"price":11120000.0,"size":0.0033},{"price":11118078.0,"size":0.01},{"price":11111800.0,"size":0.001},{"price":11111111.0,"size":0.2919257},{"price":11111000.0,"size":0.003},{"price":11110594.0,"size":0.001},{"price":11110000.0,"size":0.021007},{"price":11109662.0,"size":0.01},{"price":11108008.0,"size":0.01},{"price":11102000.0,"size":0.5},{"price":11101297.0,"size":0.001},{"price":11100005.0,"size":0.001},{"price":11100001.0,"size":0.01104},{"price":11100000.0,"size":1.6532049},{"price":11099141.0,"size":0.01},{"price":11098833.0,"size":0.002},{"price":11096243.0,"size":0.01},{"price":11094090.0,"size":0.01},{"price":11088888.0,"size":0.001},{"price":11085245.0,"size":0.001},{"price":11080200.0,"size":0.001},{"price":11080000.0,"size":0.0223},{"price":11075100.0,"size":0.003},{"price":11070200.0,"size":0.001},{"price":11070000.0,"size":0.0902},{"price":11065200.0,"size":0.001},{"price":11064370.0,"size":0.00497091},{"price":11060200.0,"size":0.001},{"price":11060000.0,"size":0.145},{"price":11059689.0,"size":0.009},{"price":11056428.0,"size":0.002},{"price":11055500.0,"size":0.02},{"price":11055200.0,"size":0.001},{"price":11055100.0,"size":0.003},{"price":11050200.0,"size":0.001},{"price":11050005.0,"size":0.001},{"price":11050002.0,"size":0.001},{"price":11050001.0,"size":0.00104},{"price":11050000.0,"size":0.39576147},{"price":11048064.0,"size":2.0},{"price":11046420.0,"size":0.2},{"price":11044243.0,"size":0.01},{"price":11041380.0,"size":0.01},{"price":11040200.0,"size":0.001},{"price":11040000.0,"size":0.00777181},{"price":11035865.0,"size":0.1},{"price":11035200.0,"size":0.001},{"price":11035000.0,"size":0.0013},{"price":11030200.0,"size":0.001},{"price":11030000.0,"size":0.025},{"price":11025500.0,"size":0.009531},{"price":11025200.0,"size":0.001},{"price":11025000.0,"size":0.71497},{"price":11020772.0,"size":0.014},{"price":11020200.0,"size":0.002},{"price":11020000.0,"size":0.005},{"price":11015200.0,"size":0.001},{"price":11012000.0,"size":0.1},{"price":11011800.0,"size":0.001},{"price":11010200.0,"size":0.001},{"price":11010000.0,"size":0.347},{"price":11007277.0,"size":0.01},{"price":11005200.0,"size":0.001},{"price":11004890.0,"size":0.001535},{"price":11003000.0,"size":0.0155},{"price":11001000.0,"size":0.013},{"price":11000500.0,"size":0.05117658},{"price":11000200.0,"size":0.001},{"price":11000002.0,"size":0.004},{"price":11000001.0,"size":0.02604},{"price":11000000.0,"size":4.53923365},{"price":10999999.0,"size":0.003},{"price":10999000.0,"size":0.001},{"price":10996855.0,"size":0.0011},{"price":10995200.0,"size":0.001},{"price":10994499.0,"size":0.00169176},{"price":10990200.0,"size":0.001},{"price":10990000.0,"size":0.10219}],"asks":[{"price":11386545.0,"size":0.08984374},{"price":11387840.0,"size":0.04553581},{"price":11387841.0,"size":0.0154534},{"price":11387876.0,"size":0.2965},{"price":11388120.0,"size":0.01458},{"price":11388481.0,"size":0.014412},{"price":11388676.0,"size":0.01000441},{"price":11389430.0,"size":0.02},{"price":11389431.0,"size":0.014556},{"price":11389572.0,"size":0.02},{"price":11389573.0,"size":0.0044},{"price":11390374.0,"size":0.02},{"price":11390375.0,"size":0.234},{"price":11390638.0,"size":0.2612},{"price":11391432.0,"size":0.4249},{"price":11392010.0,"size":0.00142446},{"price":11393250.0,"size":0.0553392},{"price":11393400.0,"size":0.2943},{"price":11395000.0,"size":0.02},{"price":11395211.0,"size":0.572076},{"price":11395665.0,"size":0.05},{"price":11396162.0,"size":0.3068},{"price":11397000.0,"size":0.02},{"price":11397637.0,"size":0.05},{"price":11398444.0,"size":0.001995},{"price":11398776.0,"size":0.0384},{"price":11398845.0,"size":0.001},{"price":11399531.0,"size":0.0898437},{"price":11399673.0,"size":0.0015},{"price":11399700.0,"size":0.001},{"price":11399999.0,"size":0.05},{"price":11400000.0,"size":1.04832841},{"price":11400402.0,"size":1.189881},{"price":11400703.0,"size":0.0526},{"price":11401107.0,"size":1.189881},{"price":11403472.0,"size":0.002},{"price":11405000.0,"size":0.1575},{"price":11408700.0,"size":0.001},{"price":11409413.0,"size":0.29418471},{"price":11409414.0,"size":1.60199848},{"price":11409415.0,"size":0.005},{"price":11409925.0,"size":0.22},{"price":11410000.0,"size":0.3787},{"price":11410168.0,"size":0.001},{"price":11410853.0,"size":0.002},{"price":11412000.0,"size":0.0878},{"price":11415000.0,"size":0.1},{"price":11415141.0,"size":0.0041},{"price":11417481.0,"size":0.0015},{"price":11418700.0,"size":0.001},{"price":11419000.0,"size":0.01},{"price":11420000.0,"size":0.261},{"price":11421268.0,"size":0.05},{"price":11421490.0,"size":0.001},{"price":11422413.0,"size":1.928},{"price":11424296.0,"size":0.002},{"price":11425000.0,"size":0.029},{"price":11426188.0,"size":1.489},{"price":11426426.0,"size":0.002},{"price":11428121.0,"size":0.002},{"price":11428700.0,"size":0.001},{"price":11429302.0,"size":0.01},{"price":11430000.0,"size":0.4098},{"price":11432718.0,"size":0.002},{"price":11432813.0,"size":0.001},{"price":11433211.0,"size":0.03},{"price":11433333.0,"size":0.001},{"price":11437315.0,"size":0.002},{"price":11438525.0,"size":0.0011},{"price":11438700.0,"size":0.001},{"price":11439557.0,"size":0.001},{"price":11440000.0,"size":0.2538},{"price":11441911.0,"size":0.002},{"price":11443629.0,"size":0.002},{"price":11444135.0,"size":0.001},{"price":11445433.0,"size":0.0015},{"price":11446508.0,"size":0.001},{"price":11447000.0,"size":0.01},{"price":11447071.0,"size":0.002},{"price":11448000.0,"size":0.0875},{"price":11448700.0,"size":0.001},{"price":11448964.0,"size":2.018},{"price":11450000.0,"size":0.268},{"price":11451105.0,"size":0.002},{"price":11453321.0,"size":0.03},{"price":11455000.0,"size":0.001},{"price":11455457.0,"size":0.001},{"price":11455702.0,"size":0.002},{"price":11458700.0,"size":0.001},{"price":11458988.0,"size":0.01},{"price":11460000.0,"size":0.06702},{"price":11460299.0,"size":0.002},{"price":11463288.0,"size":0.01},{"price":11464896.0,"size":0.002},{"price":11465382.0,"size":0.00195},{"price":11465421.0,"size":1.943},{"price":11466780.0,"size":0.001},{"price":11468700.0,"size":0.001},{"price":11470000.0,"size":0.06},{"price":11471000.0,"size":0.01},{"price":11475000.0,"size":0.0028},{"price":11476929.0,"size":1.0},{"price":11478102.0,"size":0.001},{"price":11478431.0,"size":0.002},{"price":11478700.0,"size":0.001},{"price":11480000.0,"size":0.40191},{"price":11485000.0,"size":0.01},{"price":11485488.0,"size":2.0},{"price":11486555.0,"size":0.03},{"price":11487685.0,"size":0.01},{"price":11488000.0,"size":0.102},{"price":11488700.0,"size":0.001},{"price":11489425.0,"size":0.001},{"price":11490000.0,"size":0.05},{"price":11490841.0,"size":0.002},{"price":11495450.0,"size":0.002},{"price":11495850.0,"size":0.001},{"price":11498700.0,"size":0.001},{"price":11498917.0,"size":0.002},{"price":11499000.0,"size":0.01},{"price":11500000.0,"size":0.77159519},{"price":11500078.0,"size":0.93},{"price":11500747.0,"size":0.001},{"price":11502377.0,"size":0.002},{"price":11502800.0,"size":0.00132},{"price":11503108.0,"size":0.0198},{"price":11505000.0,"size":0.0028},{"price":11505001.0,"size":0.002},{"price":11505836.0,"size":0.003},{"price":11508431.0,"size":0.047},{"price":11508700.0,"size":0.001},{"price":11508888.0,"size":0.02},{"price":11510000.0,"size":0.1476},{"price":11512070.0,"size":0.001},{"price":11513633.0,"size":0.08},{"price":11514332.0,"size":0.02},{"price":11518700.0,"size":0.001},{"price":11518992.0,"size":0.002},{"price":11519855.0,"size":0.01},{"price":11520000.0,"size":0.001},{"price":11522388.0,"size":0.972},{"price":11523211.0,"size":0.01},{"price":11524999.0,"size":0.001},{"price":11528700.0,"size":0.001},{"price":11529852.0,"size":0.01},{"price":11530000.0,"size":0.261},{"price":11533985.0,"size":0.002},{"price":11534084.0,"size":0.001},{"price":11535321.0,"size":0.01},{"price":11538666.0,"size":0.002},{"price":11538700.0,"size":0.001},{"price":11540000.0,"size":0.0048},{"price":11540357.0,"size":0.002},{"price":11541011.0,"size":0.005},{"price":11541109.0,"size":0.01},{"price":11544663.0,"size":0.002},{"price":11545262.0,"size":0.002},{"price":11546541.0,"size":0.01},{"price":11548144.0,"size":0.002},{"price":11548700.0,"size":0.001},{"price":11550000.0,"size":0.014},{"price":11551109.0,"size":0.01},{"price":11551625.0,"size":0.002},{"price":11552111.0,"size":0.01},{"price":11553687.0,"size":0.1},{"price":11555106.0,"size":0.002},{"price":11555115.0,"size":0.001},{"price":11556000.0,"size":0.1},{"price":11558587.0,"size":0.002},{"price":11558700.0,"size":0.001},{"price":11559855.0,"size":0.01},{"price":11560831.0,"size":0.0198},{"price":11561109.0,"size":0.01},{"price":11562000.0,"size":0.087},{"price":11562068.0,"size":0.002},{"price":11563750.0,"size":0.08739676},{"price":11565548.0,"size":0.002},{"price":11566139.0,"size":0.0228},{"price":11566551.0,"size":0.01},{"price":11568700.0,"size":0.001},{"price":11569029.0,"size":0.002},{"price":11570196.0,"size":0.002},{"price":11571109.0,"size":0.01},{"price":11572510.0,"size":0.002},{"price":11573211.0,"size":0.01},{"price":11574840.0,"size":0.002},{"price":11575991.0,"size":0.001},{"price":11578700.0,"size":0.001},{"price":11579484.0,"size":0.002},{"price":11579851.0,"size":0.01},{"price":11580000.0,"size":0.7835},{"price":11581109.0,"size":0.01},{"price":11584128.0,"size":0.002},{"price":11585000.0,"size":0.002},{"price":11586532.0,"size":0.01},{"price":11587498.0,"size":0.0198},{"price":11588700.0,"size":0.001},{"price":11588800.0,"size":0.02},{"price":11590000.0,"size":0.1},{"price":11590749.0,"size":0.002},{"price":11591109.0,"size":0.01},{"price":11593211.0,"size":0.01},{"price":11596753.0,"size":0.002},{"price":11598111.0,"size":0.1474},{"price":11598555.0,"size":0.01},{"price":11598700.0,"size":0.001},{"price":11599999.0,"size":0.001},{"price":11600000.0,"size":3.655},{"price":11601109.0,"size":0.02},{"price":11603764.0,"size":0.9},{"price":11606655.0,"size":0.01},{"price":11610000.0,"size":0.302},{"price":11611109.0,"size":0.01},{"price":11613321.0,"size":0.01},{"price":11620000.0,"size":1.35441682},{"price":11621011.0,"size":0.01},{"price":11621109.0,"size":0.01},{"price":11623096.0,"size":0.008},{"price":11625703.0,"size":0.012},{"price":11629000.0,"size":0.1},{"price":11630000.0,"size":0.201},{"price":11631059.0,"size":0.01},{"price":11631479.0,"size":0.01},{"price":11631773.0,"size":0.00386871},{"price":11635950.0,"size":0.001},{"price":11638259.0,"size":0.001},{"price":11639700.0,"size":0.001},{"price":11640000.0,"size":1.0},{"price":11640820.0,"size":0.01},{"price":11649900.0,"size":0.02906},{"price":11649999.0,"size":0.001},{"price":11650000.0,"size":0.593},{"price":11651059.0,"size":0.01},{"price":11653658.0,"size":0.008},{"price":11654321.0,"size":0.001},{"price":11659700.0,"size":0.001},{"price":11661479.0,"size":0.01},{"price":11666000.0,"size":0.001},{"price":11666666.0,"size":0.013},{"price":11669700.0,"size":0.001},{"price":11671059.0,"size":0.01},{"price":11672562.0,"size":0.0198},{"price":11680000.0,"size":0.014},{"price":11685000.0,"size":0.003},{"price":11688000.0,"size":0.001},{"price":11689732.0,"size":0.01},{"price":11690330.0,"size":0.0198},{"price":11691059.0,"size":0.01},{"price":11692558.0,"size":0.01},{"price":11695019.0,"size":0.0064},{"price":11698800.0,"size":0.00131},{"price":11699000.0,"size":0.001},{"price":11699631.0,"size":0.001},{"price":11699998.0,"size":0.01},{"price":11699999.0,"size":0.001},{"price":11700000.0,"size":1.2573},{"price":11701059.0,"size":0.01},{"price":11720000.0,"size":0.1},{"price":11721059.0,"size":0.01},{"price":11725000.0,"size":0.005},{"price":11726791.0,"size":0.01},{"price":11727418.0,"size":1.8},{"price":11728195.0,"size":0.05},{"price":11730000.0,"size":1.9712},{"price":11740000.0,"size":0.101},{"price":11741059.0,"size":0.01},{"price":11748937.0,"size":0.001},{"price":11749999.0,"size":0.001},{"price":11750000.0,"size":0.89537866},{"price":11750050.0,"size":0.2},{"price":11751151.0,"size":0.01},{"price":11751406.0,"size":0.012},{"price":11755000.0,"size":0.001},{"price":11757860.0,"size":1.82},{"price":11759999.0,"size":0.001},{"price":11760000.0,"size":0.001},{"price":11761059.0,"size":0.02},{"price":11765432.0,"size":0.001},{"price":11768000.0,"size":0.01},{"price":11770000.0,"size":0.25464896},{"price":11771059.0,"size":0.01755555},{"price":11772000.0,"size":0.002},{"price":11775000.0,"size":0.11593},{"price":11775222.0,"size":0.001657},{"price":11775577.0,"size":0.00013523},{"price":11775800.0,"size":0.001},{"price":11775900.0,"size":0.2},{"price":11775989.0,"size":0.005},{"price":11777000.0,"size":0.5956},{"price":11777777.0,"size":0.0067},{"price":11778541.0,"size":0.001},{"price":11779807.0,"size":0.001},{"price":11780000.0,"size":0.74298},{"price":11780800.0,"size":0.1},{"price":11781059.0,"size":0.01},{"price":11781238.0,"size":0.008},{"price":11785000.0,"size":0.055},{"price":11785040.0,"size":0.01},{"price":11786000.0,"size":0.585},{"price":11788000.0,"size":0.001}]}}}
{"schema_version":"collector.vnext.raw","schema_contract":null,"schema_contract_version":null,"payload_contract_version":null,"record_type":"market.orderbook.diff","record_id":"collector_main-market-orderbook-diff-000000000061","collector_id":"collector_main","collector_role":"production","host_name":"MAIN-PC","session_id":"collector_main-sess-20260315T000600Z-d96f2367","stream_session_id":"collector_main-stream-bitflyer-board_ws-20260315T000618Z-b839cc7f","exchange":"bitflyer","market":"spot","symbol":"BTC_JPY","instrument_id":"bitflyer.spot.BTC_JPY","channel":"board_ws","transport":"websocket","source_event_id":null,"source_sequence":null,"sequence_id":61,"exchange_ts":null,"collector_ts":"2026-03-15T00:06:18Z","ingest_ts":"2026-03-15T00:06:18Z","event_ts":"2026-03-15T00:06:18Z","quality_flags":[],"is_partial":false,"is_reconstructed":false,"confidence_score":1.0,"payload":{"provider":"bitflyer_ws_board","exchange":"bitflyer","transport":"websocket","channel":"lightning_board_BTC_JPY","received_ts":"2026-03-15T00:06:18.926870Z","subscription_id":null,"message_id":null,"source_sequence":null,"raw_message_meta":{"raw_channel":"lightning_board_BTC_JPY","subscription_channel":"lightning_board_BTC_JPY","recv_timeout_sec":10,"ssl_verify":false,"socket_url":"wss://ws.lightstream.bitflyer.com/json-rpc"},"source_payload":{"mid_price":11383527.0,"bids":[{"price":11375558.0,"size":0.1275}],"asks":[]}}}
{"schema_version":"collector.vnext.raw","schema_contract":null,"schema_contract_version":null,"payload_contract_version":null,"record_type":"market.orderbook.diff","record_id":"collector_main-market-orderbook-diff-000000000065","collector_id":"collector_main","collector_role":"production","host_name":"MAIN-PC","session_id":"collector_main-sess-20260315T000600Z-d96f2367","stream_session_id":"collector_main-stream-bitflyer-board_ws-20260315T000618Z-b839cc7f","exchange":"bitflyer","market":"spot","symbol":"BTC_JPY","instrument_id":"bitflyer.spot.BTC_JPY","channel":"board_ws","transport":"websocket","source_event_id":null,"source_sequence":null,"sequence_id":65,"exchange_ts":null,"collector_ts":"2026-03-15T00:06:19Z","ingest_ts":"2026-03-15T00:06:19Z","event_ts":"2026-03-15T00:06:19Z","quality_flags":[],"is_partial":false,"is_reconstructed":false,"confidence_score":1.0,"payload":{"provider":"bitflyer_ws_board","exchange":"bitflyer","transport":"websocket","channel":"lightning_board_BTC_JPY","received_ts":"2026-03-15T00:06:19.046143Z","subscription_id":null,"message_id":null,"source_sequence":null,"raw_message_meta":{"raw_channel":"lightning_board_BTC_JPY","subscription_channel":"lightning_board_BTC_JPY","recv_timeout_sec":10,"ssl_verify":false,"socket_url":"wss://ws.lightstream.bitflyer.com/json-rpc"},"source_payload":{"mid_price":11383526.0,"bids":[{"price":11370675.0,"size":0.30929795}],"asks":[{"price":11385498.0,"size":0.0},{"price":11385500.0,"size":0.015132},{"price":11385499.0,"size":0.014988},{"price":11385504.0,"size":0.0621}]}}}
{"schema_version":"collector.vnext.raw","schema_contract":null,"schema_contract_version":null,"payload_contract_version":null,"record_type":"market.orderbook.diff","record_id":"collector_main-market-orderbook-diff-000000000067","collector_id":"collector_main","collector_role":"production","host_name":"MAIN-PC","session_id":"collector_main-sess-20260315T000600Z-d96f2367","stream_session_id":"collector_main-stream-bitflyer-board_ws-20260315T000618Z-b839cc7f","exchange":"bitflyer","market":"spot","symbol":"BTC_JPY","instrument_id":"bitflyer.spot.BTC_JPY","channel":"board_ws","transport":"websocket","source_event_id":null,"source_sequence":null,"sequence_id":67,"exchange_ts":null,"collector_ts":"2026-03-15T00:06:19Z","ingest_ts":"2026-03-15T00:06:19Z","event_ts":"2026-03-15T00:06:19Z","quality_flags":[],"is_partial":false,"is_reconstructed":false,"confidence_score":1.0,"payload":{"provider":"bitflyer_ws_board","exchange":"bitflyer","transport":"websocket","channel":"lightning_board_BTC_JPY","received_ts":"2026-03-15T00:06:19.151244Z","subscription_id":null,"message_id":null,"source_sequence":null,"raw_message_meta":{"raw_channel":"lightning_board_BTC_JPY","subscription_channel":"lightning_board_BTC_JPY","recv_timeout_sec":10,"ssl_verify":false,"socket_url":"wss://ws.lightstream.bitflyer.com/json-rpc"},"source_payload":{"mid_price":11383527.0,"bids":[{"price":11379010.0,"size":0.0109067},{"price":11378976.0,"size":0.05296074}],"asks":[{"price":11385501.0,"size":0.05244367},{"price":11385500.0,"size":0.0},{"price":11385499.0,"size":0.0}]}}}
{"schema_version":"collector.vnext.raw","schema_contract":null,"schema_contract_version":null,"payload_contract_version":null,"record_type":"market.orderbook.diff","record_id":"collector_main-market-orderbook-diff-000000000069","collector_id":"collector_main","collector_role":"production","host_name":"MAIN-PC","session_id":"collector_main-sess-20260315T000600Z-d96f2367","stream_session_id":"collector_main-stream-bitflyer-board_ws-20260315T000618Z-b839cc7f","exchange":"bitflyer","market":"spot","symbol":"BTC_JPY","instrument_id":"bitflyer.spot.BTC_JPY","channel":"board_ws","transport":"websocket","source_event_id":null,"source_sequence":null,"sequence_id":69,"exchange_ts":null,"collector_ts":"2026-03-15T00:06:19Z","ingest_ts":"2026-03-15T00:06:19Z","event_ts":"2026-03-15T00:06:19Z","quality_flags":[],"is_partial":false,"is_reconstructed":false,"confidence_score":1.0,"payload":{"provider":"bitflyer_ws_board","exchange":"bitflyer","transport":"websocket","channel":"lightning_board_BTC_JPY","received_ts":"2026-03-15T00:06:19.282791Z","subscription_id":null,"message_id":null,"source_sequence":null,"raw_message_meta":{"raw_channel":"lightning_board_BTC_JPY","subscription_channel":"lightning_board_BTC_JPY","recv_timeout_sec":10,"ssl_verify":false,"socket_url":"wss://ws.lightstream.bitflyer.com/json-rpc"},"source_payload":{"mid_price":11383527.0,"bids":[],"asks":[{"price":11385502.0,"size":0.014628},{"price":11385501.0,"size":0.0}]}}}
{"schema_version":"collector.vnext.raw","schema_contract":null,"schema_contract_version":null,"payload_contract_version":null,"record_type":"market.orderbook.diff","record_id":"collector_main-market-orderbook-diff-000000000071","collector_id":"collector_main","collector_role":"production","host_name":"MAIN-PC","session_id":"collector_main-sess-20260315T000600Z-d96f2367","stream_session_id":"collector_main-stream-bitflyer-board_ws-20260315T000618Z-b839cc7f","exchange":"bitflyer","market":"spot","symbol":"BTC_JPY","instrument_id":"bitflyer.spot.BTC_JPY","channel":"board_ws","transport":"websocket","source_event_id":null,"source_sequence":null,"sequence_id":71,"exchange_ts":null,"collector_ts":"2026-03-15T00:06:19Z","ingest_ts":"2026-03-15T00:06:19Z","event_ts":"2026-03-15T00:06:19Z","quality_flags":[],"is_partial":false,"is_reconstructed":false,"confidence_score":1.0,"payload":{"provider":"bitflyer_ws_board","exchange":"bitflyer","transport":"websocket","channel":"lightning_board_BTC_JPY","received_ts":"2026-03-15T00:06:19.375700Z","subscription_id":null,"message_id":null,"source_sequence":null,"raw_message_meta":{"raw_channel":"lightning_board_BTC_JPY","subscription_channel":"lightning_board_BTC_JPY","recv_timeout_sec":10,"ssl_verify":false,"socket_url":"wss://ws.lightstream.bitflyer.com/json-rpc"},"source_payload":{"mid_price":11383527.0,"bids":[{"price":11378976.0,"size":0.0}],"asks":[{"price":11385498.0,"size":0.0}]}}}
{"schema_version":"collector.vnext.raw","schema_contract":null,"schema_contract_version":null,"payload_contract_version":null,"record_type":"market.orderbook.diff","record_id":"collector_main-market-orderbook-diff-000000000073","collector_id":"collector_main","collector_role":"production","host_name":"MAIN-PC","session_id":"collector_main-sess-20260315T000600Z-d96f2367","stream_session_id":"collector_main-stream-bitflyer-board_ws-20260315T000618Z-b839cc7f","exchange":"bitflyer","market":"spot","symbol":"BTC_JPY","instrument_id":"bitflyer.spot.BTC_JPY","channel":"board_ws","transport":"websocket","source_event_id":null,"source_sequence":null,"sequence_id":73,"exchange_ts":null,"collector_ts":"2026-03-15T00:06:19Z","ingest_ts":"2026-03-15T00:06:19Z","event_ts":"2026-03-15T00:06:19Z","quality_flags":[],"is_partial":false,"is_reconstructed":false,"confidence_score":1.0,"payload":{"provider":"bitflyer_ws_board","exchange":"bitflyer","transport":"websocket","channel":"lightning_board_BTC_JPY","received_ts":"2026-03-15T00:06:19.501303Z","subscription_id":null,"message_id":null,"source_sequence":null,"raw_message_meta":{"raw_channel":"lightning_board_BTC_JPY","subscription_channel":"lightning_board_BTC_JPY","recv_timeout_sec":10,"ssl_verify":false,"socket_url":"wss://ws.lightstream.bitflyer.com/json-rpc"},"source_payload":{"mid_price":11383527.0,"bids":[{"price":11379011.0,"size":0.05323396}],"asks":[{"price":11385501.0,"size":0.05488669}]}}}
{"schema_version":"collector.vnext.raw","schema_contract":null,"schema_contract_version":null,"payload_contract_version":null,"record_type":"market.orderbook.diff","record_id":"collector_main-market-orderbook-diff-000000000075","collector_id":"collector_main","collector_role":"production","host_name":"MAIN-PC","session_id":"collector_main-sess-20260315T000600Z-d96f2367","stream_session_id":"collector_main-stream-bitflyer-board_ws-20260315T000618Z-b839cc7f","exchange":"bitflyer","market":"spot","symbol":"BTC_JPY","instrument_id":"bitflyer.spot.BTC_JPY","channel":"board_ws","transport":"websocket","source_event_id":null,"source_sequence":null,"sequence_id":75,"exchange_ts":null,"collector_ts":"2026-03-15T00:06:19Z","ingest_ts":"2026-03-15T00:06:19Z","event_ts":"2026-03-15T00:06:19Z","quality_flags":[],"is_partial":false,"is_reconstructed":false,"confidence_score":1.0,"payload":{"provider":"bitflyer_ws_board","exchange":"bitflyer","transport":"websocket","channel":"lightning_board_BTC_JPY","received_ts":"2026-03-15T00:06:19.609821Z","subscription_id":null,"message_id":null,"source_sequence":null,"raw_message_meta":{"raw_channel":"lightning_board_BTC_JPY","subscription_channel":"lightning_board_BTC_JPY","recv_timeout_sec":10,"ssl_verify":false,"socket_url":"wss://ws.lightstream.bitflyer.com/json-rpc"},"source_payload":{"mid_price":11383527.0,"bids":[],"asks":[{"price":11395800.0,"size":0.0},{"price":11387286.0,"size":0.0154534},{"price":11397531.0,"size":0.2}]}}}
{"schema_version":"collector.vnext.raw","schema_contract":null,"schema_contract_version":null,"payload_contract_version":null,"record_type":"market.orderbook.diff","record_id":"collector_main-market-orderbook-diff-000000000077","collector_id":"collector_main","collector_role":"production","host_name":"MAIN-PC","session_id":"collector_main-sess-20260315T000600Z-d96f2367","stream_session_id":"collector_main-stream-bitflyer-board_ws-20260315T000618Z-b839cc7f","exchange":"bitflyer","market":"spot","symbol":"BTC_JPY","instrument_id":"bitflyer.spot.BTC_JPY","channel":"board_ws","transport":"websocket","source_event_id":null,"source_sequence":null,"sequence_id":77,"exchange_ts":null,"collector_ts":"2026-03-15T00:06:19Z","ingest_ts":"2026-03-15T00:06:19Z","event_ts":"2026-03-15T00:06:19Z","quality_flags":[],"is_partial":false,"is_reconstructed":false,"confidence_score":1.0,"payload":{"provider":"bitflyer_ws_board","exchange":"bitflyer","transport":"websocket","channel":"lightning_board_BTC_JPY","received_ts":"2026-03-15T00:06:19.741001Z","subscription_id":null,"message_id":null,"source_sequence":null,"raw_message_meta":{"raw_channel":"lightning_board_BTC_JPY","subscription_channel":"lightning_board_BTC_JPY","recv_timeout_sec":10,"ssl_verify":false,"socket_url":"wss://ws.lightstream.bitflyer.com/json-rpc"},"source_payload":{"mid_price":11383526.0,"bids":[{"price":11370051.0,"size":0.12},{"price":11371189.0,"size":0.11}],"asks":[{"price":11385499.0,"size":0.015276}]}}}
{"schema_version":"collector.vnext.raw","schema_contract":null,"schema_contract_version":null,"payload_contract_version":null,"record_type":"market.orderbook.diff","record_id":"collector_main-market-orderbook-diff-000000000079","collector_id":"collector_main","collector_role":"production","host_name":"MAIN-PC","session_id":"collector_main-sess-20260315T000600Z-d96f2367","stream_session_id":"collector_main-stream-bitflyer-board_ws-20260315T000618Z-b839cc7f","exchange":"bitflyer","market":"spot","symbol":"BTC_JPY","instrument_id":"bitflyer.spot.BTC_JPY","channel":"board_ws","transport":"websocket","source_event_id":null,"source_sequence":null,"sequence_id":79,"exchange_ts":null,"collector_ts":"2026-03-15T00:06:19Z","ingest_ts":"2026-03-15T00:06:19Z","event_ts":"2026-03-15T00:06:19Z","quality_flags":[],"is_partial":false,"is_reconstructed":false,"confidence_score":1.0,"payload":{"provider":"bitflyer_ws_board","exchange":"bitflyer","transport":"websocket","channel":"lightning_board_BTC_JPY","received_ts":"2026-03-15T00:06:19.873735Z","subscription_id":null,"message_id":null,"source_sequence":null,"raw_message_meta":{"raw_channel":"lightning_board_BTC_JPY","subscription_channel":"lightning_board_BTC_JPY","recv_timeout_sec":10,"ssl_verify":false,"socket_url":"wss://ws.lightstream.bitflyer.com/json-rpc"},"source_payload":{"mid_price":11383526.0,"bids":[],"asks":[{"price":11544663.0,"size":0.002}]}}}
{"schema_version":"collector.vnext.raw","schema_contract":null,"schema_contract_version":null,"payload_contract_version":null,"record_type":"market.orderbook.diff","record_id":"collector_main-market-orderbook-diff-000000000081","collector_id":"collector_main","collector_role":"production","host_name":"MAIN-PC","session_id":"collector_main-sess-20260315T000600Z-d96f2367","stream_session_id":"collector_main-stream-bitflyer-board_ws-20260315T000618Z-b839cc7f","exchange":"bitflyer","market":"spot","symbol":"BTC_JPY","instrument_id":"bitflyer.spot.BTC_JPY","channel":"board_ws","transport":"websocket","source_event_id":null,"source_sequence":null,"sequence_id":81,"exchange_ts":null,"collector_ts":"2026-03-15T00:06:19Z","ingest_ts":"2026-03-15T00:06:19Z","event_ts":"2026-03-15T00:06:19Z","quality_flags":[],"is_partial":false,"is_reconstructed":false,"confidence_score":1.0,"payload":{"provider":"bitflyer_ws_board","exchange":"bitflyer","transport":"websocket","channel":"lightning_board_BTC_JPY","received_ts":"2026-03-15T00:06:19.986589Z","subscription_id":null,"message_id":null,"source_sequence":null,"raw_message_meta":{"raw_channel":"lightning_board_BTC_JPY","subscription_channel":"lightning_board_BTC_JPY","recv_timeout_sec":10,"ssl_verify":false,"socket_url":"wss://ws.lightstream.bitflyer.com/json-rpc"},"source_payload":{"mid_price":11383525.0,"bids":[],"asks":[{"price":11428121.0,"size":0.002},{"price":11385501.0,"size":0.0},{"price":11385498.0,"size":0.05659079},{"price":11397531.0,"size":0.0}]}}}
{"schema_version":"collector.vnext.raw","schema_contract":null,"schema_contract_version":null,"payload_contract_version":null,"record_type":"market.orderbook.diff","record_id":"collector_main-market-orderbook-diff-000000000083","collector_id":"collector_main","collector_role":"production","host_name":"MAIN-PC","session_id":"collector_main-sess-20260315T000600Z-d96f2367","stream_session_id":"collector_main-stream-bitflyer-board_ws-20260315T000618Z-b839cc7f","exchange":"bitflyer","market":"spot","symbol":"BTC_JPY","instrument_id":"bitflyer.spot.BTC_JPY","channel":"board_ws","transport":"websocket","source_event_id":null,"source_sequence":null,"sequence_id":83,"exchange_ts":null,"collector_ts":"2026-03-15T00:06:20Z","ingest_ts":"2026-03-15T00:06:20Z","event_ts":"2026-03-15T00:06:20Z","quality_flags":[],"is_partial":false,"is_reconstructed":false,"confidence_score":1.0,"payload":{"provider":"bitflyer_ws_board","exchange":"bitflyer","transport":"websocket","channel":"lightning_board_BTC_JPY","received_ts":"2026-03-15T00:06:20.094701Z","subscription_id":null,"message_id":null,"source_sequence":null,"raw_message_meta":{"raw_channel":"lightning_board_BTC_JPY","subscription_channel":"lightning_board_BTC_JPY","recv_timeout_sec":10,"ssl_verify":false,"socket_url":"wss://ws.lightstream.bitflyer.com/json-rpc"},"source_payload":{"mid_price":11383525.0,"bids":[{"price":11377159.0,"size":0.014832}],"asks":[{"price":11395239.0,"size":0.0560964}]}}}
