{"schema_version":"collector.vnext.raw","schema_contract":null,"schema_contract_version":null,"payload_contract_version":null,"record_type":"market.orderbook.diff","record_id":"collector_main-market-orderbook-diff-000000000085","collector_id":"collector_main","collector_role":"production","host_name":"MAIN-PC","session_id":"collector_main-sess-20260315T000600Z-d96f2367","stream_session_id":"collector_main-stream-bitflyer-board_ws-20260315T000618Z-b839cc7f","exchange":"bitflyer","market":"spot","symbol":"BTC_JPY","instrument_id":"bitflyer.spot.BTC_JPY","channel":"board_ws","transport":"websocket","source_event_id":null,"source_sequence":null,"sequence_id":85,"exchange_ts":null,"collector_ts":"2026-03-15T00:06:20Z","ingest_ts":"2026-03-15T00:06:20Z","event_ts":"2026-03-15T00:06:20Z","quality_flags":[],"is_partial":false,"is_reconstructed":false,"confidence_score":1.0,"payload":{"provider":"bitflyer_ws_board","exchange":"bitflyer","transport":"websocket","channel":"lightning_board_BTC_JPY","received_ts":"2026-03-15T00:06:20.220597Z","subscription_id":null,"message_id":null,"source_sequence":null,"raw_message_meta":{"raw_channel":"lightning_board_BTC_JPY","subscription_channel":"lightning_board_BTC_JPY","recv_timeout_sec":10,"ssl_verify":false,"socket_url":"wss://ws.lightstream.bitflyer.com/json-rpc"},"source_payload":{"mid_price":11383524.0,"bids":[],"asks":[{"price":11385496.0,"size":0.01536},{"price":11387286.0,"size":0.0}]}}}
{"schema_version":"collector.vnext.raw","schema_contract":null,"schema_contract_version":null,"payload_contract_version":null,"record_type":"market.orderbook.diff","record_id":"collector_main-market-orderbook-diff-000000000087","collector_id":"collector_main","collector_role":"production","host_name":"MAIN-PC","session_id":"collector_main-sess-20260315T000600Z-d96f2367","stream_session_id":"collector_main-stream-bitflyer-board_ws-20260315T000618Z-b839cc7f","exchange":"bitflyer","market":"spot","symbol":"BTC_JPY","instrument_id":"bitflyer.spot.BTC_JPY","channel":"board_ws","transport":"websocket","source_event_id":null,"source_sequence":null,"sequence_id":87,"exchange_ts":null,"collector_ts":"2026-03-15T00:06:20Z","ingest_ts":"2026-03-15T00:06:20Z","event_ts":"2026-03-15T00:06:20Z","quality_flags":[],"is_partial":false,"is_reconstructed":false,"confidence_score":1.0,"payload":{"provider":"bitflyer_ws_board","exchange":"bitflyer","transport":"websocket","channel":"lightning_board_BTC_JPY","received_ts":"2026-03-15T00:06:20.349717Z","subscription_id":null,"message_id":null,"source_sequence":null,"raw_message_meta":{"raw_channel":"lightning_board_BTC_JPY","subscription_channel":"lightning_board_BTC_JPY","recv_timeout_sec":10,"ssl_verify":false,"socket_url":"wss://ws.lightstream.bitflyer.com/json-rpc"},"source_payload":{"mid_price":11383524.0,"bids":[],"asks":[{"price":11385498.0,"size":0.0}]}}}
{"schema_version":"collector.vnext.raw","schema_contract":null,"schema_contract_version":null,"payload_contract_version":null,"record_type":"market.orderbook.diff","record_id":"collector_main-market-orderbook-diff-000000000089","collector_id":"collector_main","collector_role":"production","host_name":"MAIN-PC","session_id":"collector_main-sess-20260315T000600Z-d96f2367","stream_session_id":"collector_main-stream-bitflyer-board_ws-20260315T000618Z-b839cc7f","exchange":"bitflyer","market":"spot","symbol":"BTC_JPY","instrument_id":"bitflyer.spot.BTC_JPY","channel":"board_ws","transport":"websocket","source_event_id":null,"source_sequence":null,"sequence_id":89,"exchange_ts":null,"collector_ts":"2026-03-15T00:06:20Z","ingest_ts":"2026-03-15T00:06:20Z","event_ts":"2026-03-15T00:06:20Z","quality_flags":[],"is_partial":false,"is_reconstructed":false,"confidence_score":1.0,"payload":{"provider":"bitflyer_ws_board","exchange":"bitflyer","transport":"websocket","channel":"lightning_board_BTC_JPY","received_ts":"2026-03-15T00:06:20.470338Z","subscription_id":null,"message_id":null,"source_sequence":null,"raw_message_meta":{"raw_channel":"lightning_board_BTC_JPY","subscription_channel":"lightning_board_BTC_JPY","recv_timeout_sec":10,"ssl_verify":false,"socket_url":"wss://ws.lightstream.bitflyer.com/json-rpc"},"source_payload":{"mid_price":11383527.0,"bids":[{"price":11376840.0,"size":0.0}],"asks":[{"price":11385499.0,"size":0.0},{"price":11385496.0,"size":0.0}]}}}
{"schema_version":"collector.vnext.raw","schema_contract":null,"schema_contract_version":null,"payload_contract_version":null,"record_type":"market.orderbook.diff","record_id":"collector_main-market-orderbook-diff-000000000091","collector_id":"collector_main","collector_role":"production","host_name":"MAIN-PC","session_id":"collector_main-sess-20260315T000600Z-d96f2367","stream_session_id":"collector_main-stream-bitflyer-board_ws-20260315T000618Z-b839cc7f","exchange":"bitflyer","market":"spot","symbol":"BTC_JPY","instrument_id":"bitflyer.spot.BTC_JPY","channel":"board_ws","transport":"websocket","source_event_id":null,"source_sequence":null,"sequence_id":91,"exchange_ts":null,"collector_ts":"2026-03-15T00:06:20Z","ingest_ts":"2026-03-15T00:06:20Z","event_ts":"2026-03-15T00:06:20Z","quality_flags":[],"is_partial":false,"is_reconstructed":false,"confidence_score":1.0,"payload":{"provider":"bitflyer_ws_board","exchange":"bitflyer","transport":"websocket","channel":"lightning_board_BTC_JPY","received_ts":"2026-03-15T00:06:20.578222Z","subscription_id":null,"message_id":null,"source_sequence":null,"raw_message_meta":{"raw_channel":"lightning_board_BTC_JPY","subscription_channel":"lightning_board_BTC_JPY","recv_timeout_sec":10,"ssl_verify":false,"socket_url":"wss://ws.lightstream.bitflyer.com/json-rpc"},"source_payload":{"mid_price":11383527.0,"bids":[{"price":11376873.0,"size":0.005}],"asks":[]}}}
{"schema_version":"collector.vnext.raw","schema_contract":null,"schema_contract_version":null,"payload_contract_version":null,"record_type":"market.orderbook.snapshot","record_id":"collector_main-market-orderbook-snapshot-000000000093","collector_id":"collector_main","collector_role":"production","host_name":"MAIN-PC","session_id":"collector_main-sess-20260315T000600Z-d96f2367","stream_session_id":"collector_main-stream-bitflyer-board_ws-20260315T000618Z-b839cc7f","exchange":"bitflyer","market":"spot","symbol":"BTC_JPY","instrument_id":"bitflyer.spot.BTC_JPY","channel":"board_ws","transport":"websocket","source_event_id":null,"source_sequence":null,"sequence_id":93,"exchange_ts":null,"collector_ts":"2026-03-15T00:06:20Z","ingest_ts":"2026-03-15T00:06:20Z","event_ts":"2026-03-15T00:06:20Z","quality_flags":[],"is_partial":false,"is_reconstructed":false,"confidence_score":1.0,"payload":{"provider":"bitflyer_ws_board_snapshot","exchange":"bitflyer","transport":"websocket","channel":"lightning_board_snapshot_BTC_JPY","received_ts":"2026-03-15T00:06:20.646107Z","subscription_id":null,"message_id":null,"source_sequence":null,"raw_message_meta":{"raw_channel":"lightning_board_snapshot_BTC_JPY","subscription_channel":"lightning_board_snapshot_BTC_JPY","recv_timeout_sec":10,"ssl_verify":false,"socket_url":"wss://ws.lightstream.bitflyer.com/json-rpc"},"source_payload":{"mid_price":11383524.0,"bids":[{"price":11381553.0,"size":0.00999733},{"price":11379011.0,"size":0.05323396},{"price":11379010.0,"size":0.0109067},{"price":11378975.0,"size":0.1275},{"price":11378097.0,"size":0.266},{"price":11377422.0,"size":0.01},{"price":11377159.0,"size":0.014832},{"price":11376873.0,"size":0.005},{"price":11376714.0,"size":0.015276},{"price":11375558.0,"size":0.1275},{"price":11375465.0,"size":0.5},{"price":11373773.0,"size":0.0141},{"price":11372900.0,"size":0.0554256},{"price":11372897.0,"size":0.06},{"price":11371900.0,"size":0.005},{"price":11371189.0,"size":0.11},{"price":11370675.0,"size":0.30929795},{"price":11370674.0,"size":2.8027288},{"price":11370673.0,"size":0.0527},{"price":11370051.0,"size":0.12},{"price":11370000.0,"size":0.01},{"price":11368376.0,"size":0.01},{"price":11368223.0,"size":0.23},{"price":11366247.0,"size":0.036},{"price":11366008.0,"size":0.04},{"price":11365378.0,"size":0.05},{"price":11364810.0,"size":0.38448},{"price":11364809.0,"size":0.05},{"price":11362278.0,"size":0.31206306},{"price":11362277.0,"size":0.9772867},{"price":11361538.0,"size":1.50015},{"price":11358413.0,"size":0.2754},{"price":11358376.0,"size":0.01},{"price":11356706.0,"size":1.484},{"price":11355651.0,"size":0.2657},{"price":11355348.0,"size":0.6},{"price":11353489.0,"size":0.09525901},{"price":11353488.0,"size":0.27174084},{"price":11352889.0,"size":0.2587},{"price":11350127.0,"size":0.3046},{"price":11350000.0,"size":0.51},{"price":11348189.0,"size":0.003},{"price":11347667.0,"size":0.001},{"price":11342072.0,"size":1.966},{"price":11341671.0,"size":0.23},{"price":11340000.0,"size":0.005},{"price":11336383.0,"size":0.001},{"price":11336319.0,"size":0.00195},{"price":11331227.0,"size":0.51},{"price":11331000.0,"size":0.5},{"price":11330000.0,"size":0.02442},{"price":11328186.0,"size":2.036},{"price":11325101.0,"size":0.001},{"price":11320000.0,"size":0.05},{"price":11315000.0,"size":0.05},{"price":11313996.0,"size":0.00195},{"price":11313819.0,"size":0.001},{"price":11310000.0,"size":0.01},{"price":11309999.0,"size":0.177},{"price":11307999.0,"size":0.01},{"price":11305439.0,"size":1.951},{"price":11304836.0,"size":1.12},{"price":11303918.0,"size":0.01},{"price":11303000.0,"size":0.5},{"price":11302535.0,"size":0.001},{"price":11302466.0,"size":0.001},{"price":11301268.0,"size":0.01},{"price":11300000.0,"size":3.01685256},{"price":11298000.0,"size":0.01},{"price":11296865.0,"size":0.0015},{"price":11294756.0,"size":1.0},{"price":11291282.0,"size":0.001},{"price":11291268.0,"size":0.01},{"price":11291000.0,"size":0.5},{"price":11290000.0,"size":0.003},{"price":11281268.0,"size":0.01},{"price":11280000.0,"size":0.0163},{"price":11279960.0,"size":0.001},{"price":11279282.0,"size":0.0015},{"price":11278000.0,"size":0.0025},{"price":11275000.0,"size":0.001},{"price":11274588.0,"size":0.0047},{"price":11271268.0,"size":0.01},{"price":11271000.0,"size":0.003},{"price":11270000.0,"size":0.106},{"price":11269424.0,"size":0.8},{"price":11268871.0,"size":0.28},{"price":11268638.0,"size":0.001},{"price":11268411.0,"size":0.01},{"price":11266666.0,"size":0.04},{"price":11265000.0,"size":0.02},{"price":11263000.0,"size":0.006},{"price":11262564.0,"size":0.0015},{"price":11261268.0,"size":0.01},{"price":11260000.0,"size":0.3565},{"price":11257315.0,"size":0.001},{"price":11257000.0,"size":0.001},{"price":11255200.0,"size":0.001},{"price":11255115.0,"size":0.00377},{"price":11253814.0,"size":2.2},{"price":11253690.0,"size":0.01},{"price":11253000.0,"size":0.03189},{"price":11251405.0,"size":0.139},{"price":11251268.0,"size":0.01},{"price":11251111.0,"size":0.0015},{"price":11251000.0,"size":0.0131},{"price":11250250.0,"size":0.00105},{"price":11250200.0,"size":0.001},{"price":11250005.0,"size":0.001},{"price":11250001.0,"size":0.00104},{"price":11250000.0,"size":1.62712889},{"price":11245993.0,"size":0.001},{"price":11245141.0,"size":0.0031},{"price":11245000.0,"size":0.05},{"price":11244444.0,"size":0.04},{"price":11244243.0,"size":0.01},{"price":11240200.0,"size":0.001},{"price":11240000.0,"size":0.007304},{"price":11236190.0,"size":0.01},{"price":11235200.0,"size":0.001},{"price":11234670.0,"size":0.001},{"price":11234512.0,"size":0.0015},{"price":11232000.0,"size":0.089},{"price":11231243.0,"size":0.01},{"price":11231000.0,"size":0.105},{"price":11230200.0,"size":0.001},{"price":11230000.0,"size":0.0308},{"price":11226952.0,"size":0.972},{"price":11224500.0,"size":0.06},{"price":11223968.0,"size":0.001},{"price":11223348.0,"size":0.001},{"price":11223344.0,"size":0.01},{"price":11223000.0,"size":0.1},{"price":11222222.0,"size":0.093525},{"price":11221120.0,"size":0.001},{"price":11220200.0,"size":0.001},{"price":11220001.0,"size":0.004457},{"price":11220000.0,"size":0.321},{"price":11219000.0,"size":0.1},{"price":11217326.0,"size":0.02},{"price":11215200.0,"size":0.001},{"price":11213690.0,"size":0.01},{"price":11212764.0,"size":0.0015},{"price":11212025.0,"size":0.001},{"price":11211800.0,"size":0.001},{"price":11211111.0,"size":0.06},{"price":11210200.0,"size":0.001},{"price":11210000.0,"size":0.10622},{"price":11208032.0,"size":0.01},{"price":11206000.0,"size":0.09015},{"price":11205200.0,"size":0.001},{"price":11204578.0,"size":0.002},{"price":11201000.0,"size":0.01},{"price":11200800.0,"size":0.05},{"price":11200703.0,"size":0.001},{"price":11200425.0,"size":0.1},{"price":11200200.0,"size":0.001},{"price":11200198.0,"size":0.003},{"price":11200150.0,"size":0.002},{"price":11200002.0,"size":0.001},{"price":11200001.0,"size":0.01104},{"price":11200000.0,"size":1.15226728},{"price":11198508.0,"size":0.05},{"price":11198243.0,"size":0.01},{"price":11197134.0,"size":0.993},{"price":11197000.0,"size":0.0085},{"price":11194090.0,"size":0.03},{"price":11190770.0,"size":0.0309},{"price":11190000.0,"size":0.0010016},{"price":11189555.0,"size":0.5},{"price":11189381.0,"size":0.001},{"price":11188629.0,"size":0.01},{"price":11188382.0,"size":0.001},{"price":11185000.0,"size":0.0085},{"price":11180000.0,"size":0.225},{"price":11178058.0,"size":0.001},{"price":11170000.0,"size":0.001},{"price":11169662.0,"size":0.01},{"price":11169593.0,"size":0.001},{"price":11169243.0,"size":0.01},{"price":11166736.0,"size":0.001},{"price":11164029.0,"size":0.001},{"price":11160854.0,"size":0.1},{"price":11160000.0,"size":0.02376},{"price":11155413.0,"size":0.001},{"price":11155377.0,"size":0.00636009},{"price":11153999.0,"size":0.00101},{"price":11151000.0,"size":0.001},{"price":11150250.0,"size":0.00175},{"price":11150005.0,"size":0.001},{"price":11150001.0,"size":0.00104},{"price":11150000.0,"size":0.6533956},{"price":11148000.0,"size":0.08963},{"price":11147546.0,"size":0.02},{"price":11144091.0,"size":0.001},{"price":11144000.0,"size":0.0897},{"price":11143986.0,"size":0.02},{"price":11140139.0,"size":1.0},{"price":11140000.0,"size":0.2},{"price":11136243.0,"size":0.01},{"price":11135869.0,"size":0.1},{"price":11132768.0,"size":0.001},{"price":11130000.0,"size":0.116},{"price":11129979.0,"size":0.0053908},{"price":11124900.0,"size":0.00133},{"price":11121090.0,"size":0.1},{"price":11120000.0,"size":0.0033},{"price":11118078.0,"size":0.01},{"price":11111800.0,"size":0.001},{"price":11111111.0,"size":0.2919257},{"price":11111000.0,"size":0.003},{"price":11110594.0,"size":0.001},{"price":11110000.0,"size":0.021007},{"price":11109662.0,"size":0.01},{"price":11108008.0,"size":0.01},{"price":11102000.0,"size":0.5},{"price":11101297.0,"size":0.001},{"price":11100005.0,"size":0.001},{"price":11100001.0,"size":0.01104},{"price":11100000.0,"size":1.6532049},{"price":11099141.0,"size":0.01},{"price":11098833.0,"size":0.002},{"price":11096243.0,"size":0.01},{"price":11094090.0,"size":0.01},{"price":11088888.0,"size":0.001},{"price":11085245.0,"size":0.001},{"price":11080200.0,"size":0.001},{"price":11080000.0,"size":0.0223},{"price":11075100.0,"size":0.003},{"price":11070200.0,"size":0.001},{"price":11070000.0,"size":0.0902},{"price":11065200.0,"size":0.001},{"price":11064370.0,"size":0.00497091},{"price":11060200.0,"size":0.001},{"price":11060000.0,"size":0.145},{"price":11059689.0,"size":0.009},{"price":11056428.0,"size":0.002},{"price":11055500.0,"size":0.02},{"price":11055200.0,"size":0.001},{"price":11055100.0,"size":0.003},{"price":11050200.0,"size":0.001},{"price":11050005.0,"size":0.001},{"price":11050002.0,"size":0.001},{"price":11050001.0,"size":0.00104},{"price":11050000.0,"size":0.39576147},{"price":11048064.0,"size":2.0},{"price":11046420.0,"size":0.2},{"price":11044243.0,"size":0.01},{"price":11041380.0,"size":0.01},{"price":11040200.0,"size":0.001},{"price":11040000.0,"size":0.00777181},{"price":11035865.0,"size":0.1},{"price":11035200.0,"size":0.001},{"price":11035000.0,"size":0.0013},{"price":11030200.0,"size":0.001},{"price":11030000.0,"size":0.025},{"price":11025500.0,"size":0.009531},{"price":11025200.0,"size":0.001},{"price":11025000.0,"size":0.71497},{"price":11020772.0,"size":0.014},{"price":11020200.0,"size":0.002},{"price":11020000.0,"size":0.005},{"price":11015200.0,"size":0.001},{"price":11012000.0,"size":0.1},{"price":11011800.0,"size":0.001},{"price":11010200.0,"size":0.001},{"price":11010000.0,"size":0.347},{"price":11007277.0,"size":0.01},{"price":11005200.0,"size":0.001},{"price":11004890.0,"size":0.001535},{"price":11003000.0,"size":0.0155},{"price":11001000.0,"size":0.013},{"price":11000500.0,"size":0.05117658},{"price":11000200.0,"size":0.001},{"price":11000002.0,"size":0.004},{"price":11000001.0,"size":0.02604},{"price":11000000.0,"size":4.53923365},{"price":10999999.0,"size":0.003},{"price":10999000.0,"size":0.001},{"price":10996855.0,"size":0.0011},{"price":10995200.0,"size":0.001},{"price":10994499.0,"size":0.00169176},{"price":10990200.0,"size":0.001},{"price":10990000.0,"size":0.10219},{"price":10989001.0,"size":0.00197},{"price":10988999.0,"size":0.001},{"price":10988324.0,"size":0.002},{"price":10987654.0,"size":0.001},{"price":10985200.0,"size":0.001},{"price":10985150.0,"size":0.01},{"price":10980500.0,"size":0.005},{"price":10980200.0,"size":0.001},{"price":10980002.0,"size":0.4},{"price":10980000.0,"size":0.028},{"price":10975200.0,"size":0.001},{"price":10975000.0,"size":0.1},{"price":10971261.0,"size":0.001},{"price":10971243.0,"size":0.01},{"price":10970200.0,"size":0.001},{"price":10970000.0,"size":0.09304}],"asks":[{"price":11385495.0,"size":0.05200467},{"price":11385502.0,"size":0.014628},{"price":11385504.0,"size":0.0621},{"price":11385531.0,"size":0.014928},{"price":11385539.0,"size":0.02},{"price":11386282.0,"size":0.005},{"price":11387321.0,"size":0.3125},{"price":11387499.0,"size":0.01000441},{"price":11389573.0,"size":0.0044},{"price":11389974.0,"size":0.0554256},{"price":11390083.0,"size":0.2626},{"price":11390375.0,"size":0.234},{"price":11390878.0,"size":0.01},{"price":11391432.0,"size":0.4249},{"price":11392010.0,"size":0.00142446},{"price":11392845.0,"size":0.2819},{"price":11393399.0,"size":0.57223603},{"price":11395000.0,"size":0.02},{"price":11395239.0,"size":0.0560964},{"price":11395607.0,"size":0.2962},{"price":11395665.0,"size":0.05},{"price":11397000.0,"size":0.02},{"price":11398444.0,"size":0.001995},{"price":11398845.0,"size":0.001},{"price":11399673.0,"size":0.0015},{"price":11399700.0,"size":0.001},{"price":11399998.0,"size":0.33543393},{"price":11399999.0,"size":0.05},{"price":11400000.0,"size":1.04832841},{"price":11400402.0,"size":1.189881},{"price":11400703.0,"size":0.0526},{"price":11401107.0,"size":1.189881},{"price":11403472.0,"size":0.002},{"price":11405000.0,"size":0.1575},{"price":11408700.0,"size":0.001},{"price":11409413.0,"size":0.29418471},{"price":11409414.0,"size":1.60199848},{"price":11409415.0,"size":0.005},{"price":11409925.0,"size":0.22},{"price":11410000.0,"size":0.3787},{"price":11410168.0,"size":0.001},{"price":11410853.0,"size":0.002},{"price":11412000.0,"size":0.0878},{"price":11413461.0,"size":1.489},{"price":11415000.0,"size":0.1},{"price":11415141.0,"size":0.0041},{"price":11417481.0,"size":0.0015},{"price":11418700.0,"size":0.001},{"price":11419000.0,"size":0.01},{"price":11420000.0,"size":0.261},{"price":11421268.0,"size":0.05},{"price":11421490.0,"size":0.001},{"price":11422413.0,"size":1.928},{"price":11424296.0,"size":0.002},{"price":11426426.0,"size":0.002},{"price":11428121.0,"size":0.002},{"price":11428700.0,"size":0.001},{"price":11429302.0,"size":0.01},{"price":11430000.0,"size":2.62388164},{"price":11432813.0,"size":0.001},{"price":11433211.0,"size":0.03},{"price":11433333.0,"size":0.001},{"price":11438525.0,"size":0.0011},{"price":11438700.0,"size":0.001},{"price":11439557.0,"size":0.001},{"price":11440000.0,"size":0.2538},{"price":11443629.0,"size":0.002},{"price":11444135.0,"size":0.001},{"price":11445433.0,"size":0.0015},{"price":11447000.0,"size":0.01},{"price":11447071.0,"size":0.002},{"price":11448000.0,"size":0.0875},{"price":11448700.0,"size":0.001},{"price":11448964.0,"size":2.018},{"price":11450000.0,"size":0.268},{"price":11453321.0,"size":0.03},{"price":11455000.0,"size":0.001},{"price":11455457.0,"size":0.001},{"price":11458700.0,"size":0.001},{"price":11458988.0,"size":0.01},{"price":11460000.0,"size":0.06702},{"price":11463288.0,"size":0.01},{"price":11465382.0,"size":0.00195},{"price":11465421.0,"size":1.943},{"price":11466780.0,"size":0.001},{"price":11468700.0,"size":0.001},{"price":11470000.0,"size":0.06},{"price":11471000.0,"size":0.01},{"price":11475000.0,"size":0.0028},{"price":11476929.0,"size":1.0},{"price":11478102.0,"size":0.001},{"price":11478431.0,"size":0.002},{"price":11478700.0,"size":0.001},{"price":11480000.0,"size":0.40191},{"price":11485000.0,"size":0.01},{"price":11485488.0,"size":2.0},{"price":11486555.0,"size":0.03},{"price":11487685.0,"size":0.01},{"price":11488000.0,"size":0.102},{"price":11488700.0,"size":0.001},{"price":11489425.0,"size":0.001},{"price":11490000.0,"size":0.05},{"price":11495488.0,"size":0.0015},{"price":11495850.0,"size":0.001},{"price":11498700.0,"size":0.001},{"price":11498917.0,"size":0.002},{"price":11499000.0,"size":0.01},{"price":11500000.0,"size":0.77159519},{"price":11500078.0,"size":0.93},{"price":11500747.0,"size":0.001},{"price":11502377.0,"size":0.002},{"price":11502800.0,"size":0.00132},{"price":11503108.0,"size":0.0198},{"price":11505000.0,"size":0.0028},{"price":11505001.0,"size":0.002},{"price":11505836.0,"size":0.003},{"price":11508431.0,"size":0.047},{"price":11508700.0,"size":0.001},{"price":11508888.0,"size":0.02},{"price":11510000.0,"size":0.1476},{"price":11512070.0,"size":0.001},{"price":11513633.0,"size":0.08},{"price":11514332.0,"size":0.02},{"price":11517236.0,"size":0.0015},{"price":11518700.0,"size":0.001},{"price":11519855.0,"size":0.01},{"price":11520000.0,"size":0.001},{"price":11522388.0,"size":0.972},{"price":11523211.0,"size":0.01},{"price":11524999.0,"size":0.001},{"price":11528700.0,"size":0.001},{"price":11529852.0,"size":0.01},{"price":11530000.0,"size":0.261},{"price":11533985.0,"size":0.002},{"price":11534084.0,"size":0.001},{"price":11535321.0,"size":0.01},{"price":11538666.0,"size":0.002},{"price":11538700.0,"size":0.001},{"price":11540000.0,"size":0.0048},{"price":11541011.0,"size":0.005},{"price":11541109.0,"size":0.01},{"price":11544663.0,"size":0.002},{"price":11546541.0,"size":0.01},{"price":11548700.0,"size":0.001},{"price":11550000.0,"size":0.014},{"price":11551109.0,"size":0.01},{"price":11552111.0,"size":0.01},{"price":11553687.0,"size":0.1},{"price":11555115.0,"size":0.001},{"price":11556000.0,"size":0.1},{"price":11558700.0,"size":0.001},{"price":11559855.0,"size":0.01},{"price":11560831.0,"size":0.0198},{"price":11561109.0,"size":0.01},{"price":11562000.0,"size":0.087},{"price":11563750.0,"size":0.08739676},{"price":11566139.0,"size":0.0228},{"price":11566551.0,"size":0.01},{"price":11568700.0,"size":0.001},{"price":11571109.0,"size":0.01},{"price":11573211.0,"size":0.01},{"price":11578700.0,"size":0.001},{"price":11579851.0,"size":0.01},{"price":11580000.0,"size":0.7835},{"price":11581109.0,"size":0.01},{"price":11585000.0,"size":0.002},{"price":11586532.0,"size":0.01},{"price":11587498.0,"size":0.0198},{"price":11588700.0,"size":0.001},{"price":11588800.0,"size":0.02},{"price":11590000.0,"size":0.1},{"price":11590749.0,"size":0.002},{"price":11591109.0,"size":0.01},{"price":11593211.0,"size":0.01},{"price":11598111.0,"size":0.1474},{"price":11598555.0,"size":0.01},{"price":11598700.0,"size":0.001},{"price":11599999.0,"size":0.001},{"price":11600000.0,"size":3.655},{"price":11601109.0,"size":0.02},{"price":11603764.0,"size":0.9},{"price":11606655.0,"size":0.01},{"price":11610000.0,"size":0.302},{"price":11611109.0,"size":0.01},{"price":11613321.0,"size":0.01},{"price":11620000.0,"size":1.35441682},{"price":11621011.0,"size":0.01},{"price":11621109.0,"size":0.01},{"price":11623096.0,"size":0.008},{"price":11625703.0,"size":0.012},{"price":11629000.0,"size":0.1},{"price":11630000.0,"size":0.201},{"price":11631059.0,"size":0.01},{"price":11631479.0,"size":0.01},{"price":11631773.0,"size":0.00386871},{"price":11635950.0,"size":0.001},{"price":11638259.0,"size":0.001},{"price":11639700.0,"size":0.001},{"price":11640000.0,"size":1.0},{"price":11640820.0,"size":0.01},{"price":11649900.0,"size":0.02906},{"price":11649999.0,"size":0.001},{"price":11650000.0,"size":0.593},{"price":11651059.0,"size":0.01},{"price":11653658.0,"size":0.008},{"price":11654321.0,"size":0.001},{"price":11659700.0,"size":0.001},{"price":11661479.0,"size":0.01},{"price":11666000.0,"size":0.001},{"price":11666666.0,"size":0.013},{"price":11669700.0,"size":0.001},{"price":11671059.0,"size":0.01},{"price":11672562.0,"size":0.0198},{"price":11680000.0,"size":0.014},{"price":11685000.0,"size":0.003},{"price":11688000.0,"size":0.001},{"price":11689732.0,"size":0.01},{"price":11690330.0,"size":0.0198},{"price":11691059.0,"size":0.01},{"price":11692558.0,"size":0.01},{"price":11695019.0,"size":0.0064},{"price":11698800.0,"size":0.00131},{"price":11699000.0,"size":0.001},{"price":11699631.0,"size":0.001},{"price":11699998.0,"size":0.01},{"price":11699999.0,"size":0.001},{"price":11700000.0,"size":1.2573},{"price":11701059.0,"size":0.01},{"price":11720000.0,"size":0.1},{"price":11721059.0,"size":0.01},{"price":11725000.0,"size":0.005},{"price":11726791.0,"size":0.01},{"price":11727418.0,"size":1.8},{"price":11728195.0,"size":0.05},{"price":11730000.0,"size":1.9712},{"price":11740000.0,"size":0.101},{"price":11741059.0,"size":0.01},{"price":11748937.0,"size":0.001},{"price":11749999.0,"size":0.001},{"price":11750000.0,"size":0.89537866},{"price":11750050.0,"size":0.2},{"price":11751151.0,"size":0.01},{"price":11751406.0,"size":0.012},{"price":11755000.0,"size":0.001},{"price":11757860.0,"size":1.82},{"price":11759999.0,"size":0.001},{"price":11760000.0,"size":0.001},{"price":11761059.0,"size":0.02},{"price":11765432.0,"size":0.001},{"price":11768000.0,"size":0.01},{"price":11770000.0,"size":0.25464896},{"price":11771059.0,"size":0.01755555},{"price":11772000.0,"size":0.002},{"price":11775000.0,"size":0.11593},{"price":11775222.0,"size":0.001657},{"price":11775577.0,"size":0.00013523},{"price":11775800.0,"size":0.001},{"price":11775900.0,"size":0.2},{"price":11775989.0,"size":0.005},{"price":11777000.0,"size":0.5956},{"price":11777777.0,"size":0.0067},{"price":11778541.0,"size":0.001},{"price":11779807.0,"size":0.001},{"price":11780000.0,"size":0.74298},{"price":11780800.0,"size":0.1},{"price":11781059.0,"size":0.01},{"price":11781238.0,"size":0.008},{"price":11785000.0,"size":0.055},{"price":11785040.0,"size":0.01},{"price":11786000.0,"size":0.585},{"price":11788000.0,"size":0.001},{"price":11788888.0,"size":0.005},{"price":11789000.0,"size":0.2},{"price":11789732.0,"size":0.01},{"price":11791100.0,"size":0.1},{"price":11791151.0,"size":0.01},{"price":11795000.0,"size":0.021},{"price":11795040.0,"size":0.015},{"price":11796103.0,"size":0.01},{"price":11798800.0,"size":0.005},{"price":11798950.0,"size":0.001},{"price":11799000.0,"size":0.013},{"price":11799510.0,"size":0.001},{"price":11799639.0,"size":0.01},{"price":11799999.0,"size":0.00769493},{"price":11800000.0,"size":1.10095},{"price":11800050.0,"size":0.006},{"price":11801059.0,"size":0.01},{"price":11802200.0,"size":0.2},{"price":11802222.0,"size":0.001},{"price":11803080.0,"size":0.001},{"price":11804746.0,"size":0.001},{"price":11804977.0,"size":0.001},{"price":11807789.0,"size":0.001},{"price":11809946.0,"size":0.02},{"price":11810000.0,"size":0.01},{"price":11811063.0,"size":0.006},{"price":11811386.0,"size":0.001},{"price":11815000.0,"size":0.086},{"price":11820000.0,"size":0.0699}]}}}
{"schema_version":"collector.vnext.raw","schema_contract":null,"schema_contract_version":null,"payload_contract_version":null,"record_type":"market.orderbook.diff","record_id":"collector_main-market-orderbook-diff-000000000061","collector_id":"collector_main","collector_role":"production","host_name":"MAIN-PC","session_id":"collector_main-sess-20260315T000635Z-0301843f","stream_session_id":"collector_main-stream-bitflyer-board_ws-20260315T000716Z-b7de660c","exchange":"bitflyer","market":"spot","symbol":"BTC_JPY","instrument_id":"bitflyer.spot.BTC_JPY","channel":"board_ws","transport":"websocket","source_event_id":null,"source_sequence":null,"sequence_id":61,"exchange_ts":null,"collector_ts":"2026-03-15T00:07:16Z","ingest_ts":"2026-03-15T00:07:16Z","event_ts":"2026-03-15T00:07:16Z","quality_flags":[],"is_partial":false,"is_reconstructed":false,"confidence_score":1.0,"payload":{"provider":"bitflyer_ws_board","exchange":"bitflyer","transport":"websocket","channel":"lightning_board_BTC_JPY","received_ts":"2026-03-15T00:07:16.734810Z","subscription_id":null,"message_id":null,"source_sequence":null,"raw_message_meta":{"raw_channel":"lightning_board_BTC_JPY","subscription_channel":"lightning_board_BTC_JPY","recv_timeout_sec":10,"ssl_verify":false,"socket_url":"wss://ws.lightstream.bitflyer.com/json-rpc"},"source_payload":{"mid_price":11381276.0,"bids":[{"price":11364242.0,"size":0.36},{"price":11371072.0,"size":0.09}],"asks":[]}}}
{"schema_version":"collector.vnext.raw","schema_contract":null,"schema_contract_version":null,"payload_contract_version":null,"record_type":"market.orderbook.diff","record_id":"collector_main-market-orderbook-diff-000000000065","collector_id":"collector_main","collector_role":"production","host_name":"MAIN-PC","session_id":"collector_main-sess-20260315T000635Z-0301843f","stream_session_id":"collector_main-stream-bitflyer-board_ws-20260315T000716Z-b7de660c","exchange":"bitflyer","market":"spot","symbol":"BTC_JPY","instrument_id":"bitflyer.spot.BTC_JPY","channel":"board_ws","transport":"websocket","source_event_id":null,"source_sequence":null,"sequence_id":65,"exchange_ts":null,"collector_ts":"2026-03-15T00:07:16Z","ingest_ts":"2026-03-15T00:07:16Z","event_ts":"2026-03-15T00:07:16Z","quality_flags":[],"is_partial":false,"is_reconstructed":false,"confidence_score":1.0,"payload":{"provider":"bitflyer_ws_board","exchange":"bitflyer","transport":"websocket","channel":"lightning_board_BTC_JPY","received_ts":"2026-03-15T00:07:16.877814Z","subscription_id":null,"message_id":null,"source_sequence":null,"raw_message_meta":{"raw_channel":"lightning_board_BTC_JPY","subscription_channel":"lightning_board_BTC_JPY","recv_timeout_sec":10,"ssl_verify":false,"socket_url":"wss://ws.lightstream.bitflyer.com/json-rpc"},"source_payload":{"mid_price":11381276.0,"bids":[{"price":11369933.0,"size":0.0}],"asks":[]}}}
{"schema_version":"collector.vnext.raw","schema_contract":null,"schema_contract_version":null,"payload_contract_version":null,"record_type":"market.orderbook.diff","record_id":"collector_main-market-orderbook-diff-000000000067","collector_id":"collector_main","collector_role":"production","host_name":"MAIN-PC","session_id":"collector_main-sess-20260315T000635Z-0301843f","stream_session_id":"collector_main-stream-bitflyer-board_ws-20260315T000716Z-b7de660c","exchange":"bitflyer","market":"spot","symbol":"BTC_JPY","instrument_id":"bitflyer.spot.BTC_JPY","channel":"board_ws","transport":"websocket","source_event_id":null,"source_sequence":null,"sequence_id":67,"exchange_ts":null,"collector_ts":"2026-03-15T00:07:17Z","ingest_ts":"2026-03-15T00:07:17Z","event_ts":"2026-03-15T00:07:17Z","quality_flags":[],"is_partial":false,"is_reconstructed":false,"confidence_score":1.0,"payload":{"provider":"bitflyer_ws_board","exchange":"bitflyer","transport":"websocket","channel":"lightning_board_BTC_JPY","received_ts":"2026-03-15T00:07:17.138110Z","subscription_id":null,"message_id":null,"source_sequence":null,"raw_message_meta":{"raw_channel":"lightning_board_BTC_JPY","subscription_channel":"lightning_board_BTC_JPY","recv_timeout_sec":10,"ssl_verify":false,"socket_url":"wss://ws.lightstream.bitflyer.com/json-rpc"},"source_payload":{"mid_price":11381275.0,"bids":[],"asks":[{"price":11384278.0,"size":0.015144}]}}}
{"schema_version":"collector.vnext.raw","schema_contract":null,"schema_contract_version":null,"payload_contract_version":null,"record_type":"market.orderbook.diff","record_id":"collector_main-market-orderbook-diff-000000000069","collector_id":"collector_main","collector_role":"production","host_name":"MAIN-PC","session_id":"collector_main-sess-20260315T000635Z-0301843f","stream_session_id":"collector_main-stream-bitflyer-board_ws-20260315T000716Z-b7de660c","exchange":"bitflyer","market":"spot","symbol":"BTC_JPY","instrument_id":"bitflyer.spot.BTC_JPY","channel":"board_ws","transport":"websocket","source_event_id":null,"source_sequence":null,"sequence_id":69,"exchange_ts":null,"collector_ts":"2026-03-15T00:07:17Z","ingest_ts":"2026-03-15T00:07:17Z","event_ts":"2026-03-15T00:07:17Z","quality_flags":[],"is_partial":false,"is_reconstructed":false,"confidence_score":1.0,"payload":{"provider":"bitflyer_ws_board","exchange":"bitflyer","transport":"websocket","channel":"lightning_board_BTC_JPY","received_ts":"2026-03-15T00:07:17.376329Z","subscription_id":null,"message_id":null,"source_sequence":null,"raw_message_meta":{"raw_channel":"lightning_board_BTC_JPY","subscription_channel":"lightning_board_BTC_JPY","recv_timeout_sec":10,"ssl_verify":false,"socket_url":"wss://ws.lightstream.bitflyer.com/json-rpc"},"source_payload":{"mid_price":11381275.0,"bids":[],"asks":[{"price":11384280.0,"size":0.0},{"price":11384277.0,"size":0.0530533}]}}}
{"schema_version":"collector.vnext.raw","schema_contract":null,"schema_contract_version":null,"payload_contract_version":null,"record_type":"market.orderbook.diff","record_id":"collector_main-market-orderbook-diff-000000000071","collector_id":"collector_main","collector_role":"production","host_name":"MAIN-PC","session_id":"collector_main-sess-20260315T000635Z-0301843f","stream_session_id":"collector_main-stream-bitflyer-board_ws-20260315T000716Z-b7de660c","exchange":"bitflyer","market":"spot","symbol":"BTC_JPY","instrument_id":"bitflyer.spot.BTC_JPY","channel":"board_ws","transport":"websocket","source_event_id":null,"source_sequence":null,"sequence_id":71,"exchange_ts":null,"collector_ts":"2026-03-15T00:07:17Z","ingest_ts":"2026-03-15T00:07:17Z","event_ts":"2026-03-15T00:07:17Z","quality_flags":[],"is_partial":false,"is_reconstructed":false,"confidence_score":1.0,"payload":{"provider":"bitflyer_ws_board","exchange":"bitflyer","transport":"websocket","channel":"lightning_board_BTC_JPY","received_ts":"2026-03-15T00:07:17.519530Z","subscription_id":null,"message_id":null,"source_sequence":null,"raw_message_meta":{"raw_channel":"lightning_board_BTC_JPY","subscription_channel":"lightning_board_BTC_JPY","recv_timeout_sec":10,"ssl_verify":false,"socket_url":"wss://ws.lightstream.bitflyer.com/json-rpc"},"source_payload":{"mid_price":11381275.0,"bids":[{"price":11376722.0,"size":0.0}],"asks":[]}}}
{"schema_version":"collector.vnext.raw","schema_contract":null,"schema_contract_version":null,"payload_contract_version":null,"record_type":"market.orderbook.diff","record_id":"collector_main-market-orderbook-diff-000000000073","collector_id":"collector_main","collector_role":"production","host_name":"MAIN-PC","session_id":"collector_main-sess-20260315T000635Z-0301843f","stream_session_id":"collector_main-stream-bitflyer-board_ws-20260315T000716Z-b7de660c","exchange":"bitflyer","market":"spot","symbol":"BTC_JPY","instrument_id":"bitflyer.spot.BTC_JPY","channel":"board_ws","transport":"websocket","source_event_id":null,"source_sequence":null,"sequence_id":73,"exchange_ts":null,"collector_ts":"2026-03-15T00:07:17Z","ingest_ts":"2026-03-15T00:07:17Z","event_ts":"2026-03-15T00:07:17Z","quality_flags":[],"is_partial":false,"is_reconstructed":false,"confidence_score":1.0,"payload":{"provider":"bitflyer_ws_board","exchange":"bitflyer","transport":"websocket","channel":"lightning_board_BTC_JPY","received_ts":"2026-03-15T00:07:17.613927Z","subscription_id":null,"message_id":null,"source_sequence":null,"raw_message_meta":{"raw_channel":"lightning_board_BTC_JPY","subscription_channel":"lightning_board_BTC_JPY","recv_timeout_sec":10,"ssl_verify":false,"socket_url":"wss://ws.lightstream.bitflyer.com/json-rpc"},"source_payload":{"mid_price":11381275.0,"bids":[{"price":11371072.0,"size":0.0},{"price":11376717.0,"size":0.005}],"asks":[]}}}
{"schema_version":"collector.vnext.raw","schema_contract":null,"schema_contract_version":null,"payload_contract_version":null,"record_type":"market.orderbook.diff","record_id":"collector_main-market-orderbook-diff-000000000075","collector_id":"collector_main","collector_role":"production","host_name":"MAIN-PC","session_id":"collector_main-sess-20260315T000635Z-0301843f","stream_session_id":"collector_main-stream-bitflyer-board_ws-20260315T000716Z-b7de660c","exchange":"bitflyer","market":"spot","symbol":"BTC_JPY","instrument_id":"bitflyer.spot.BTC_JPY","channel":"board_ws","transport":"websocket","source_event_id":null,"source_sequence":null,"sequence_id":75,"exchange_ts":null,"collector_ts":"2026-03-15T00:07:17Z","ingest_ts":"2026-03-15T00:07:17Z","event_ts":"2026-03-15T00:07:17Z","quality_flags":[],"is_partial":false,"is_reconstructed":false,"confidence_score":1.0,"payload":{"provider":"bitflyer_ws_board","exchange":"bitflyer","transport":"websocket","channel":"lightning_board_BTC_JPY","received_ts":"2026-03-15T00:07:17.872597Z","subscription_id":null,"message_id":null,"source_sequence":null,"raw_message_meta":{"raw_channel":"lightning_board_BTC_JPY","subscription_channel":"lightning_board_BTC_JPY","recv_timeout_sec":10,"ssl_verify":false,"socket_url":"wss://ws.lightstream.bitflyer.com/json-rpc"},"source_payload":{"mid_price":11381275.0,"bids":[{"price":11369928.0,"size":0.11}],"asks":[]}}}
{"schema_version":"collector.vnext.raw","schema_contract":null,"schema_contract_version":null,"payload_contract_version":null,"record_type":"market.orderbook.diff","record_id":"collector_main-market-orderbook-diff-000000000077","collector_id":"collector_main","collector_role":"production","host_name":"MAIN-PC","session_id":"collector_main-sess-20260315T000635Z-0301843f","stream_session_id":"collector_main-stream-bitflyer-board_ws-20260315T000716Z-b7de660c","exchange":"bitflyer","market":"spot","symbol":"BTC_JPY","instrument_id":"bitflyer.spot.BTC_JPY","channel":"board_ws","transport":"websocket","source_event_id":null,"source_sequence":null,"sequence_id":77,"exchange_ts":null,"collector_ts":"2026-03-15T00:07:18Z","ingest_ts":"2026-03-15T00:07:18Z","event_ts":"2026-03-15T00:07:18Z","quality_flags":[],"is_partial":false,"is_reconstructed":false,"confidence_score":1.0,"payload":{"provider":"bitflyer_ws_board","exchange":"bitflyer","transport":"websocket","channel":"lightning_board_BTC_JPY","received_ts":"2026-03-15T00:07:18.449975Z","subscription_id":null,"message_id":null,"source_sequence":null,"raw_message_meta":{"raw_channel":"lightning_board_BTC_JPY","subscription_channel":"lightning_board_BTC_JPY","recv_timeout_sec":10,"ssl_verify":false,"socket_url":"wss://ws.lightstream.bitflyer.com/json-rpc"},"source_payload":{"mid_price":11381275.0,"bids":[{"price":11371067.0,"size":0.08}],"asks":[]}}}
{"schema_version":"collector.vnext.raw","schema_contract":null,"schema_contract_version":null,"payload_contract_version":null,"record_type":"market.orderbook.diff","record_id":"collector_main-market-orderbook-diff-000000000079","collector_id":"collector_main","collector_role":"production","host_name":"MAIN-PC","session_id":"collector_main-sess-20260315T000635Z-0301843f","stream_session_id":"collector_main-stream-bitflyer-board_ws-20260315T000716Z-b7de660c","exchange":"bitflyer","market":"spot","symbol":"BTC_JPY","instrument_id":"bitflyer.spot.BTC_JPY","channel":"board_ws","transport":"websocket","source_event_id":null,"source_sequence":null,"sequence_id":79,"exchange_ts":null,"collector_ts":"2026-03-15T00:07:18Z","ingest_ts":"2026-03-15T00:07:18Z","event_ts":"2026-03-15T00:07:18Z","quality_flags":[],"is_partial":false,"is_reconstructed":false,"confidence_score":1.0,"payload":{"provider":"bitflyer_ws_board","exchange":"bitflyer","transport":"websocket","channel":"lightning_board_BTC_JPY","received_ts":"2026-03-15T00:07:18.852149Z","subscription_id":null,"message_id":null,"source_sequence":null,"raw_message_meta":{"raw_channel":"lightning_board_BTC_JPY","subscription_channel":"lightning_board_BTC_JPY","recv_timeout_sec":10,"ssl_verify":false,"socket_url":"wss://ws.lightstream.bitflyer.com/json-rpc"},"source_payload":{"mid_price":11381275.0,"bids":[{"price":11364242.0,"size":0.0},{"price":11369928.0,"size":0.0}],"asks":[]}}}
{"schema_version":"collector.vnext.raw","schema_contract":null,"schema_contract_version":null,"payload_contract_version":null,"record_type":"market.orderbook.diff","record_id":"collector_main-market-orderbook-diff-000000000081","collector_id":"collector_main","collector_role":"production","host_name":"MAIN-PC","session_id":"collector_main-sess-20260315T000635Z-0301843f","stream_session_id":"collector_main-stream-bitflyer-board_ws-20260315T000716Z-b7de660c","exchange":"bitflyer","market":"spot","symbol":"BTC_JPY","instrument_id":"bitflyer.spot.BTC_JPY","channel":"board_ws","transport":"websocket","source_event_id":null,"source_sequence":null,"sequence_id":81,"exchange_ts":null,"collector_ts":"2026-03-15T00:07:18Z","ingest_ts":"2026-03-15T00:07:18Z","event_ts":"2026-03-15T00:07:18Z","quality_flags":[],"is_partial":false,"is_reconstructed":false,"confidence_score":1.0,"payload":{"provider":"bitflyer_ws_board","exchange":"bitflyer","transport":"websocket","channel":"lightning_board_BTC_JPY","received_ts":"2026-03-15T00:07:18.979638Z","subscription_id":null,"message_id":null,"source_sequence":null,"raw_message_meta":{"raw_channel":"lightning_board_BTC_JPY","subscription_channel":"lightning_board_BTC_JPY","recv_timeout_sec":10,"ssl_verify":false,"socket_url":"wss://ws.lightstream.bitflyer.com/json-rpc"},"source_payload":{"mid_price":11381275.0,"bids":[{"price":11376895.0,"size":0.0}],"asks":[]}}}
{"schema_version":"collector.vnext.raw","schema_contract":null,"schema_contract_version":null,"payload_contract_version":null,"record_type":"market.orderbook.diff","record_id":"collector_main-market-orderbook-diff-000000000083","collector_id":"collector_main","collector_role":"production","host_name":"MAIN-PC","session_id":"collector_main-sess-20260315T000635Z-0301843f","stream_session_id":"collector_main-stream-bitflyer-board_ws-20260315T000716Z-b7de660c","exchange":"bitflyer","market":"spot","symbol":"BTC_JPY","instrument_id":"bitflyer.spot.BTC_JPY","channel":"board_ws","transport":"websocket","source_event_id":null,"source_sequence":null,"sequence_id":83,"exchange_ts":null,"collector_ts":"2026-03-15T00:07:19Z","ingest_ts":"2026-03-15T00:07:19Z","event_ts":"2026-03-15T00:07:19Z","quality_flags":[],"is_partial":false,"is_reconstructed":false,"confidence_score":1.0,"payload":{"provider":"bitflyer_ws_board","exchange":"bitflyer","transport":"websocket","channel":"lightning_board_BTC_JPY","received_ts":"2026-03-15T00:07:19.078413Z","subscription_id":null,"message_id":null,"source_sequence":null,"raw_message_meta":{"raw_channel":"lightning_board_BTC_JPY","subscription_channel":"lightning_board_BTC_JPY","recv_timeout_sec":10,"ssl_verify":false,"socket_url":"wss://ws.lightstream.bitflyer.com/json-rpc"},"source_payload":{"mid_price":11381274.0,"bids":[],"asks":[{"price":11384275.0,"size":0.014628}]}}}
{"schema_version":"collector.vnext.raw","schema_contract":null,"schema_contract_version":null,"payload_contract_version":null,"record_type":"market.orderbook.diff","record_id":"collector_main-market-orderbook-diff-000000000085","collector_id":"collector_main","collector_role":"production","host_name":"MAIN-PC","session_id":"collector_main-sess-20260315T000635Z-0301843f","stream_session_id":"collector_main-stream-bitflyer-board_ws-20260315T000716Z-b7de660c","exchange":"bitflyer","market":"spot","symbol":"BTC_JPY","instrument_id":"bitflyer.spot.BTC_JPY","channel":"board_ws","transport":"websocket","source_event_id":null,"source_sequence":null,"sequence_id":85,"exchange_ts":null,"collector_ts":"2026-03-15T00:07:19Z","ingest_ts":"2026-03-15T00:07:19Z","event_ts":"2026-03-15T00:07:19Z","quality_flags":[],"is_partial":false,"is_reconstructed":false,"confidence_score":1.0,"payload":{"provider":"bitflyer_ws_board","exchange":"bitflyer","transport":"websocket","channel":"lightning_board_BTC_JPY","received_ts":"2026-03-15T00:07:19.188098Z","subscription_id":null,"message_id":null,"source_sequence":null,"raw_message_meta":{"raw_channel":"lightning_board_BTC_JPY","subscription_channel":"lightning_board_BTC_JPY","recv_timeout_sec":10,"ssl_verify":false,"socket_url":"wss://ws.lightstream.bitflyer.com/json-rpc"},"source_payload":{"mid_price":11381274.0,"bids":[],"asks":[{"price":11387970.0,"size":0.0},{"price":11384277.0,"size":0.0}]}}}
{"schema_version":"collector.vnext.raw","schema_contract":null,"schema_contract_version":null,"payload_contract_version":null,"record_type":"market.orderbook.diff","record_id":"collector_main-market-orderbook-diff-000000000087","collector_id":"collector_main","collector_role":"production","host_name":"MAIN-PC","session_id":"collector_main-sess-20260315T000635Z-0301843f","stream_session_id":"collector_main-stream-bitflyer-board_ws-20260315T000716Z-b7de660c","exchange":"bitflyer","market":"spot","symbol":"BTC_JPY","instrument_id":"bitflyer.spot.BTC_JPY","channel":"board_ws","transport":"websocket","source_event_id":null,"source_sequence":null,"sequence_id":87,"exchange_ts":null,"collector_ts":"2026-03-15T00:07:19Z","ingest_ts":"2026-03-15T00:07:19Z","event_ts":"2026-03-15T00:07:19Z","quality_flags":[],"is_partial":false,"is_reconstructed":false,"confidence_score":1.0,"payload":{"provider":"bitflyer_ws_board","exchange":"bitflyer","transport":"websocket","channel":"lightning_board_BTC_JPY","received_ts":"2026-03-15T00:07:19.328679Z","subscription_id":null,"message_id":null,"source_sequence":null,"raw_message_meta":{"raw_channel":"lightning_board_BTC_JPY","subscription_channel":"lightning_board_BTC_JPY","recv_timeout_sec":10,"ssl_verify":false,"socket_url":"wss://ws.lightstream.bitflyer.com/json-rpc"},"source_payload":{"mid_price":11381273.0,"bids":[],"asks":[{"price":11384274.0,"size":0.05413623}]}}}
{"schema_version":"collector.vnext.raw","schema_contract":null,"schema_contract_version":null,"payload_contract_version":null,"record_type":"market.orderbook.diff","record_id":"collector_main-market-orderbook-diff-000000000089","collector_id":"collector_main","collector_role":"production","host_name":"MAIN-PC","session_id":"collector_main-sess-20260315T000635Z-0301843f","stream_session_id":"collector_main-stream-bitflyer-board_ws-20260315T000716Z-b7de660c","exchange":"bitflyer","market":"spot","symbol":"BTC_JPY","instrument_id":"bitflyer.spot.BTC_JPY","channel":"board_ws","transport":"websocket","source_event_id":null,"source_sequence":null,"sequence_id":89,"exchange_ts":null,"collector_ts":"2026-03-15T00:07:19Z","ingest_ts":"2026-03-15T00:07:19Z","event_ts":"2026-03-15T00:07:19Z","quality_flags":[],"is_partial":false,"is_reconstructed":false,"confidence_score":1.0,"payload":{"provider":"bitflyer_ws_board","exchange":"bitflyer","transport":"websocket","channel":"lightning_board_BTC_JPY","received_ts":"2026-03-15T00:07:19.447744Z","subscription_id":null,"message_id":null,"source_sequence":null,"raw_message_meta":{"raw_channel":"lightning_board_BTC_JPY","subscription_channel":"lightning_board_BTC_JPY","recv_timeout_sec":10,"ssl_verify":false,"socket_url":"wss://ws.lightstream.bitflyer.com/json-rpc"},"source_payload":{"mid_price":11381273.0,"bids":[],"asks":[{"price":11384275.0,"size":0.0},{"price":11384278.0,"size":0.0}]}}}
{"schema_version":"collector.vnext.raw","schema_contract":null,"schema_contract_version":null,"payload_contract_version":null,"record_type":"market.orderbook.diff","record_id":"collector_main-market-orderbook-diff-000000000091","collector_id":"collector_main","collector_role":"production","host_name":"MAIN-PC","session_id":"collector_main-sess-20260315T000635Z-0301843f","stream_session_id":"collector_main-stream-bitflyer-board_ws-20260315T000716Z-b7de660c","exchange":"bitflyer","market":"spot","symbol":"BTC_JPY","instrument_id":"bitflyer.spot.BTC_JPY","channel":"board_ws","transport":"websocket","source_event_id":null,"source_sequence":null,"sequence_id":91,"exchange_ts":null,"collector_ts":"2026-03-15T00:07:19Z","ingest_ts":"2026-03-15T00:07:19Z","event_ts":"2026-03-15T00:07:19Z","quality_flags":[],"is_partial":false,"is_reconstructed":false,"confidence_score":1.0,"payload":{"provider":"bitflyer_ws_board","exchange":"bitflyer","transport":"websocket","channel":"lightning_board_BTC_JPY","received_ts":"2026-03-15T00:07:19.547869Z","subscription_id":null,"message_id":null,"source_sequence":null,"raw_message_meta":{"raw_channel":"lightning_board_BTC_JPY","subscription_channel":"lightning_board_BTC_JPY","recv_timeout_sec":10,"ssl_verify":false,"socket_url":"wss://ws.lightstream.bitflyer.com/json-rpc"},"source_payload":{"mid_price":11381273.0,"bids":[{"price":11371067.0,"size":0.0}],"asks":[{"price":11384279.0,"size":0.015288},{"price":11384540.0,"size":0.0}]}}}
{"schema_version":"collector.vnext.raw","schema_contract":null,"schema_contract_version":null,"payload_contract_version":null,"record_type":"market.orderbook.diff","record_id":"collector_main-market-orderbook-diff-000000000093","collector_id":"collector_main","collector_role":"production","host_name":"MAIN-PC","session_id":"collector_main-sess-20260315T000635Z-0301843f","stream_session_id":"collector_main-stream-bitflyer-board_ws-20260315T000716Z-b7de660c","exchange":"bitflyer","market":"spot","symbol":"BTC_JPY","instrument_id":"bitflyer.spot.BTC_JPY","channel":"board_ws","transport":"websocket","source_event_id":null,"source_sequence":null,"sequence_id":93,"exchange_ts":null,"collector_ts":"2026-03-15T00:07:19Z","ingest_ts":"2026-03-15T00:07:19Z","event_ts":"2026-03-15T00:07:19Z","quality_flags":[],"is_partial":false,"is_reconstructed":false,"confidence_score":1.0,"payload":{"provider":"bitflyer_ws_board","exchange":"bitflyer","transport":"websocket","channel":"lightning_board_BTC_JPY","received_ts":"2026-03-15T00:07:19.673031Z","subscription_id":null,"message_id":null,"source_sequence":null,"raw_message_meta":{"raw_channel":"lightning_board_BTC_JPY","subscription_channel":"lightning_board_BTC_JPY","recv_timeout_sec":10,"ssl_verify":false,"socket_url":"wss://ws.lightstream.bitflyer.com/json-rpc"},"source_payload":{"mid_price":11381272.0,"bids":[{"price":11369928.0,"size":0.11}],"asks":[{"price":11384272.0,"size":0.015312},{"price":11384274.0,"size":0.0},{"price":11384280.0,"size":0.05238438}]}}}
{"schema_version":"collector.vnext.raw","schema_contract":null,"schema_contract_version":null,"payload_contract_version":null,"record_type":"market.orderbook.diff","record_id":"collector_main-market-orderbook-diff-000000000095","collector_id":"collector_main","collector_role":"production","host_name":"MAIN-PC","session_id":"collector_main-sess-20260315T000635Z-0301843f","stream_session_id":"collector_main-stream-bitflyer-board_ws-20260315T000716Z-b7de660c","exchange":"bitflyer","market":"spot","symbol":"BTC_JPY","instrument_id":"bitflyer.spot.BTC_JPY","channel":"board_ws","transport":"websocket","source_event_id":null,"source_sequence":null,"sequence_id":95,"exchange_ts":null,"collector_ts":"2026-03-15T00:07:19Z","ingest_ts":"2026-03-15T00:07:19Z","event_ts":"2026-03-15T00:07:19Z","quality_flags":[],"is_partial":false,"is_reconstructed":false,"confidence_score":1.0,"payload":{"provider":"bitflyer_ws_board","exchange":"bitflyer","transport":"websocket","channel":"lightning_board_BTC_JPY","received_ts":"2026-03-15T00:07:19.783509Z","subscription_id":null,"message_id":null,"source_sequence":null,"raw_message_meta":{"raw_channel":"lightning_board_BTC_JPY","subscription_channel":"lightning_board_BTC_JPY","recv_timeout_sec":10,"ssl_verify":false,"socket_url":"wss://ws.lightstream.bitflyer.com/json-rpc"},"source_payload":{"mid_price":11381272.0,"bids":[],"asks":[{"price":11384280.0,"size":0.0},{"price":11384278.0,"size":0.0544413}]}}}
{"schema_version":"collector.vnext.raw","schema_contract":null,"schema_contract_version":null,"payload_contract_version":null,"record_type":"market.orderbook.diff","record_id":"collector_main-market-orderbook-diff-000000000097","collector_id":"collector_main","collector_role":"production","host_name":"MAIN-PC","session_id":"collector_main-sess-20260315T000635Z-0301843f","stream_session_id":"collector_main-stream-bitflyer-board_ws-20260315T000716Z-b7de660c","exchange":"bitflyer","market":"spot","symbol":"BTC_JPY","instrument_id":"bitflyer.spot.BTC_JPY","channel":"board_ws","transport":"websocket","source_event_id":null,"source_sequence":null,"sequence_id":97,"exchange_ts":null,"collector_ts":"2026-03-15T00:07:19Z","ingest_ts":"2026-03-15T00:07:19Z","event_ts":"2026-03-15T00:07:19Z","quality_flags":[],"is_partial":false,"is_reconstructed":false,"confidence_score":1.0,"payload":{"provider":"bitflyer_ws_board","exchange":"bitflyer","transport":"websocket","channel":"lightning_board_BTC_JPY","received_ts":"2026-03-15T00:07:19.908002Z","subscription_id":null,"message_id":null,"source_sequence":null,"raw_message_meta":{"raw_channel":"lightning_board_BTC_JPY","subscription_channel":"lightning_board_BTC_JPY","recv_timeout_sec":10,"ssl_verify":false,"socket_url":"wss://ws.lightstream.bitflyer.com/json-rpc"},"source_payload":{"mid_price":11381272.0,"bids":[],"asks":[{"price":11384272.0,"size":0.0},{"price":11384278.0,"size":0.0},{"price":11384327.0,"size":0.0154534},{"price":11384271.0,"size":0.05438116}]}}}
{"schema_version":"collector.vnext.raw","schema_contract":null,"schema_contract_version":null,"payload_contract_version":null,"record_type":"market.orderbook.diff","record_id":"collector_main-market-orderbook-diff-000000000099","collector_id":"collector_main","collector_role":"production","host_name":"MAIN-PC","session_id":"collector_main-sess-20260315T000635Z-0301843f","stream_session_id":"collector_main-stream-bitflyer-board_ws-20260315T000716Z-b7de660c","exchange":"bitflyer","market":"spot","symbol":"BTC_JPY","instrument_id":"bitflyer.spot.BTC_JPY","channel":"board_ws","transport":"websocket","source_event_id":null,"source_sequence":null,"sequence_id":99,"exchange_ts":null,"collector_ts":"2026-03-15T00:07:20Z","ingest_ts":"2026-03-15T00:07:20Z","event_ts":"2026-03-15T00:07:20Z","quality_flags":[],"is_partial":false,"is_reconstructed":false,"confidence_score":1.0,"payload":{"provider":"bitflyer_ws_board","exchange":"bitflyer","transport":"websocket","channel":"lightning_board_BTC_JPY","received_ts":"2026-03-15T00:07:20.019159Z","subscription_id":null,"message_id":null,"source_sequence":null,"raw_message_meta":{"raw_channel":"lightning_board_BTC_JPY","subscription_channel":"lightning_board_BTC_JPY","recv_timeout_sec":10,"ssl_verify":false,"socket_url":"wss://ws.lightstream.bitflyer.com/json-rpc"},"source_payload":{"mid_price":11381272.0,"bids":[{"price":11371067.0,"size":0.1}],"asks":[{"price":11384276.0,"size":0.015372}]}}}
{"schema_version":"collector.vnext.raw","schema_contract":null,"schema_contract_version":null,"payload_contract_version":null,"record_type":"market.orderbook.diff","record_id":"collector_main-market-orderbook-diff-000000000101","collector_id":"collector_main","collector_role":"production","host_name":"MAIN-PC","session_id":"collector_main-sess-20260315T000635Z-0301843f","stream_session_id":"collector_main-stream-bitflyer-board_ws-20260315T000716Z-b7de660c","exchange":"bitflyer","market":"spot","symbol":"BTC_JPY","instrument_id":"bitflyer.spot.BTC_JPY","channel":"board_ws","transport":"websocket","source_event_id":null,"source_sequence":null,"sequence_id":101,"exchange_ts":null,"collector_ts":"2026-03-15T00:07:20Z","ingest_ts":"2026-03-15T00:07:20Z","event_ts":"2026-03-15T00:07:20Z","quality_flags":[],"is_partial":false,"is_reconstructed":false,"confidence_score":1.0,"payload":{"provider":"bitflyer_ws_board","exchange":"bitflyer","transport":"websocket","channel":"lightning_board_BTC_JPY","received_ts":"2026-03-15T00:07:20.144656Z","subscription_id":null,"message_id":null,"source_sequence":null,"raw_message_meta":{"raw_channel":"lightning_board_BTC_JPY","subscription_channel":"lightning_board_BTC_JPY","recv_timeout_sec":10,"ssl_verify":false,"socket_url":"wss://ws.lightstream.bitflyer.com/json-rpc"},"source_payload":{"mid_price":11381274.0,"bids":[],"asks":[{"price":11384271.0,"size":0.0}]}}}
{"schema_version":"collector.vnext.raw","schema_contract":null,"schema_contract_version":null,"payload_contract_version":null,"record_type":"market.orderbook.diff","record_id":"collector_main-market-orderbook-diff-000000000103","collector_id":"collector_main","collector_role":"production","host_name":"MAIN-PC","session_id":"collector_main-sess-20260315T000635Z-0301843f","stream_session_id":"collector_main-stream-bitflyer-board_ws-20260315T000716Z-b7de660c","exchange":"bitflyer","market":"spot","symbol":"BTC_JPY","instrument_id":"bitflyer.spot.BTC_JPY","channel":"board_ws","transport":"websocket","source_event_id":null,"source_sequence":null,"sequence_id":103,"exchange_ts":null,"collector_ts":"2026-03-15T00:07:20Z","ingest_ts":"2026-03-15T00:07:20Z","event_ts":"2026-03-15T00:07:20Z","quality_flags":[],"is_partial":false,"is_reconstructed":false,"confidence_score":1.0,"payload":{"provider":"bitflyer_ws_board","exchange":"bitflyer","transport":"websocket","channel":"lightning_board_BTC_JPY","received_ts":"2026-03-15T00:07:20.247241Z","subscription_id":null,"message_id":null,"source_sequence":null,"raw_message_meta":{"raw_channel":"lightning_board_BTC_JPY","subscription_channel":"lightning_board_BTC_JPY","recv_timeout_sec":10,"ssl_verify":false,"socket_url":"wss://ws.lightstream.bitflyer.com/json-rpc"},"source_payload":{"mid_price":11381271.0,"bids":[],"asks":[{"price":11384269.0,"size":0.015384},{"price":11384278.0,"size":0.0}]}}}
{"schema_version":"collector.vnext.raw","schema_contract":null,"schema_contract_version":null,"payload_contract_version":null,"record_type":"market.orderbook.diff","record_id":"collector_main-market-orderbook-diff-000000000105","collector_id":"collector_main","collector_role":"production","host_name":"MAIN-PC","session_id":"collector_main-sess-20260315T000635Z-0301843f","stream_session_id":"collector_main-stream-bitflyer-board_ws-20260315T000716Z-b7de660c","exchange":"bitflyer","market":"spot","symbol":"BTC_JPY","instrument_id":"bitflyer.spot.BTC_JPY","channel":"board_ws","transport":"websocket","source_event_id":null,"source_sequence":null,"sequence_id":105,"exchange_ts":null,"collector_ts":"2026-03-15T00:07:20Z","ingest_ts":"2026-03-15T00:07:20Z","event_ts":"2026-03-15T00:07:20Z","quality_flags":[],"is_partial":false,"is_reconstructed":false,"confidence_score":1.0,"payload":{"provider":"bitflyer_ws_board","exchange":"bitflyer","transport":"websocket","channel":"lightning_board_BTC_JPY","received_ts":"2026-03-15T00:07:20.355302Z","subscription_id":null,"message_id":null,"source_sequence":null,"raw_message_meta":{"raw_channel":"lightning_board_BTC_JPY","subscription_channel":"lightning_board_BTC_JPY","recv_timeout_sec":10,"ssl_verify":false,"socket_url":"wss://ws.lightstream.bitflyer.com/json-rpc"},"source_payload":{"mid_price":11381274.0,"bids":[],"asks":[{"price":11384270.0,"size":0.0},{"price":11384880.0,"size":0.0},{"price":11384269.0,"size":0.0}]}}}
{"schema_version":"collector.vnext.raw","schema_contract":null,"schema_contract_version":null,"payload_contract_version":null,"record_type":"market.orderbook.diff","record_id":"collector_main-market-orderbook-diff-000000000107","collector_id":"collector_main","collector_role":"production","host_name":"MAIN-PC","session_id":"collector_main-sess-20260315T000635Z-0301843f","stream_session_id":"collector_main-stream-bitflyer-board_ws-20260315T000716Z-b7de660c","exchange":"bitflyer","market":"spot","symbol":"BTC_JPY","instrument_id":"bitflyer.spot.BTC_JPY","channel":"board_ws","transport":"websocket","source_event_id":null,"source_sequence":null,"sequence_id":107,"exchange_ts":null,"collector_ts":"2026-03-15T00:07:20Z","ingest_ts":"2026-03-15T00:07:20Z","event_ts":"2026-03-15T00:07:20Z","quality_flags":[],"is_partial":false,"is_reconstructed":false,"confidence_score":1.0,"payload":{"provider":"bitflyer_ws_board","exchange":"bitflyer","transport":"websocket","channel":"lightning_board_BTC_JPY","received_ts":"2026-03-15T00:07:20.469878Z","subscription_id":null,"message_id":null,"source_sequence":null,"raw_message_meta":{"raw_channel":"lightning_board_BTC_JPY","subscription_channel":"lightning_board_BTC_JPY","recv_timeout_sec":10,"ssl_verify":false,"socket_url":"wss://ws.lightstream.bitflyer.com/json-rpc"},"source_payload":{"mid_price":11381270.0,"bids":[],"asks":[{"price":11384275.0,"size":0.0},{"price":11384276.0,"size":0.0},{"price":11384267.0,"size":0.01542},{"price":11384268.0,"size":0.05090509},{"price":11384281.0,"size":0.0}]}}}
{"schema_version":"collector.vnext.raw","schema_contract":null,"schema_contract_version":null,"payload_contract_version":null,"record_type":"market.orderbook.diff","record_id":"collector_main-market-orderbook-diff-000000000109","collector_id":"collector_main","collector_role":"production","host_name":"MAIN-PC","session_id":"collector_main-sess-20260315T000635Z-0301843f","stream_session_id":"collector_main-stream-bitflyer-board_ws-20260315T000716Z-b7de660c","exchange":"bitflyer","market":"spot","symbol":"BTC_JPY","instrument_id":"bitflyer.spot.BTC_JPY","channel":"board_ws","transport":"websocket","source_event_id":null,"source_sequence":null,"sequence_id":109,"exchange_ts":null,"collector_ts":"2026-03-15T00:07:20Z","ingest_ts":"2026-03-15T00:07:20Z","event_ts":"2026-03-15T00:07:20Z","quality_flags":[],"is_partial":false,"is_reconstructed":false,"confidence_score":1.0,"payload":{"provider":"bitflyer_ws_board","exchange":"bitflyer","transport":"websocket","channel":"lightning_board_BTC_JPY","received_ts":"2026-03-15T00:07:20.580026Z","subscription_id":null,"message_id":null,"source_sequence":null,"raw_message_meta":{"raw_channel":"lightning_board_BTC_JPY","subscription_channel":"lightning_board_BTC_JPY","recv_timeout_sec":10,"ssl_verify":false,"socket_url":"wss://ws.lightstream.bitflyer.com/json-rpc"},"source_payload":{"mid_price":11381270.0,"bids":[{"price":11369928.0,"size":0.0},{"price":11375584.0,"size":0.01}],"asks":[{"price":11384269.0,"size":0.0631},{"price":11384268.0,"size":0.0}]}}}
{"schema_version":"collector.vnext.raw","schema_contract":null,"schema_contract_version":null,"payload_contract_version":null,"record_type":"market.orderbook.diff","record_id":"collector_main-market-orderbook-diff-000000000111","collector_id":"collector_main","collector_role":"production","host_name":"MAIN-PC","session_id":"collector_main-sess-20260315T000635Z-0301843f","stream_session_id":"collector_main-stream-bitflyer-board_ws-20260315T000716Z-b7de660c","exchange":"bitflyer","market":"spot","symbol":"BTC_JPY","instrument_id":"bitflyer.spot.BTC_JPY","channel":"board_ws","transport":"websocket","source_event_id":null,"source_sequence":null,"sequence_id":111,"exchange_ts":null,"collector_ts":"2026-03-15T00:07:20Z","ingest_ts":"2026-03-15T00:07:20Z","event_ts":"2026-03-15T00:07:20Z","quality_flags":[],"is_partial":false,"is_reconstructed":false,"confidence_score":1.0,"payload":{"provider":"bitflyer_ws_board","exchange":"bitflyer","transport":"websocket","channel":"lightning_board_BTC_JPY","received_ts":"2026-03-15T00:07:20.688067Z","subscription_id":null,"message_id":null,"source_sequence":null,"raw_message_meta":{"raw_channel":"lightning_board_BTC_JPY","subscription_channel":"lightning_board_BTC_JPY","recv_timeout_sec":10,"ssl_verify":false,"socket_url":"wss://ws.lightstream.bitflyer.com/json-rpc"},"source_payload":{"mid_price":11381271.0,"bids":[],"asks":[{"price":11384275.0,"size":0.0},{"price":11384267.0,"size":0.0},{"price":11384327.0,"size":0.0}]}}}
{"schema_version":"collector.vnext.raw","schema_contract":null,"schema_contract_version":null,"payload_contract_version":null,"record_type":"market.orderbook.snapshot","record_id":"collector_main-market-orderbook-snapshot-000000000113","collector_id":"collector_main","collector_role":"production","host_name":"MAIN-PC","session_id":"collector_main-sess-20260315T000635Z-0301843f","stream_session_id":"collector_main-stream-bitflyer-board_ws-20260315T000716Z-b7de660c","exchange":"bitflyer","market":"spot","symbol":"BTC_JPY","instrument_id":"bitflyer.spot.BTC_JPY","channel":"board_ws","transport":"websocket","source_event_id":null,"source_sequence":null,"sequence_id":113,"exchange_ts":null,"collector_ts":"2026-03-15T00:07:20Z","ingest_ts":"2026-03-15T00:07:20Z","event_ts":"2026-03-15T00:07:20Z","quality_flags":[],"is_partial":false,"is_reconstructed":false,"confidence_score":1.0,"payload":{"provider":"bitflyer_ws_board_snapshot","exchange":"bitflyer","transport":"websocket","channel":"lightning_board_snapshot_BTC_JPY","received_ts":"2026-03-15T00:07:20.719250Z","subscription_id":null,"message_id":null,"source_sequence":null,"raw_message_meta":{"raw_channel":"lightning_board_snapshot_BTC_JPY","subscription_channel":"lightning_board_snapshot_BTC_JPY","recv_timeout_sec":10,"ssl_verify":false,"socket_url":"wss://ws.lightstream.bitflyer.com/json-rpc"},"source_payload":{"mid_price":11381269.0,"bids":[{"price":11378273.0,"size":0.04056443},{"price":11378272.0,"size":0.00999733},{"price":11377328.0,"size":0.0109106},{"price":11377293.0,"size":0.1275},{"price":11376724.0,"size":0.1275},{"price":11376717.0,"size":0.005},{"price":11376680.0,"size":0.005},{"price":11376363.0,"size":0.01482},{"price":11376061.0,"size":0.014736},{"price":11375584.0,"size":0.01},{"price":11375465.0,"size":0.5},{"price":11373968.0,"size":0.266},{"price":11373826.0,"size":0.0523584},{"price":11373718.0,"size":0.015792},{"price":11372897.0,"size":0.06},{"price":11371900.0,"size":0.005},{"price":11371073.0,"size":3.11545966},{"price":11371067.0,"size":0.1},{"price":11370000.0,"size":0.0185},{"price":11368751.0,"size":0.07},{"price":11368376.0,"size":0.01},{"price":11366936.0,"size":0.36363565},{"price":11366935.0,"size":0.0527},{"price":11366247.0,"size":0.036},{"price":11366148.0,"size":0.21},{"price":11366008.0,"size":0.04},{"price":11365378.0,"size":0.05},{"price":11364809.0,"size":0.05},{"price":11362278.0,"size":0.31206306},{"price":11362277.0,"size":0.9772867},{"price":11361538.0,"size":1.50015},{"price":11358907.0,"size":1.484},{"price":11358376.0,"size":0.01},{"price":11358206.0,"size":0.002},{"price":11357286.0,"size":0.002},{"price":11355651.0,"size":0.2657},{"price":11355348.0,"size":0.6},{"price":11353489.0,"size":0.09525901},{"price":11352889.0,"size":0.2587},{"price":11350456.0,"size":0.002},{"price":11350127.0,"size":0.3046},{"price":11350000.0,"size":0.51},{"price":11349098.0,"size":0.002},{"price":11348189.0,"size":0.003},{"price":11347667.0,"size":0.001},{"price":11347365.0,"size":0.3041},{"price":11347041.0,"size":0.002},{"price":11344544.0,"size":0.002},{"price":11343626.0,"size":0.002},{"price":11341671.0,"size":0.23},{"price":11341349.0,"size":0.51},{"price":11340532.0,"size":1.966},{"price":11340211.0,"size":0.002},{"price":11340000.0,"size":0.005},{"price":11339990.0,"size":0.002},{"price":11336796.0,"size":0.002},{"price":11336383.0,"size":0.001},{"price":11336319.0,"size":0.00195},{"price":11335436.0,"size":0.002},{"price":11333381.0,"size":0.002},{"price":11331000.0,"size":0.5},{"price":11330882.0,"size":0.002},{"price":11330000.0,"size":0.02442},{"price":11329966.0,"size":0.002},{"price":11329213.0,"size":2.036},{"price":11326551.0,"size":0.002},{"price":11326328.0,"size":0.002},{"price":11325101.0,"size":0.001},{"price":11321774.0,"size":0.002},{"price":11320000.0,"size":0.05},{"price":11317220.0,"size":0.002},{"price":11315000.0,"size":0.05},{"price":11313996.0,"size":0.00195},{"price":11313819.0,"size":0.001},{"price":11310000.0,"size":0.01},{"price":11309999.0,"size":0.177},{"price":11307999.0,"size":0.01},{"price":11305439.0,"size":1.951},{"price":11304836.0,"size":1.12},{"price":11303918.0,"size":0.01},{"price":11303000.0,"size":0.5},{"price":11302535.0,"size":0.001},{"price":11302466.0,"size":0.001},{"price":11301268.0,"size":0.01},{"price":11300000.0,"size":3.01685256},{"price":11298000.0,"size":0.01},{"price":11296865.0,"size":0.0015},{"price":11294756.0,"size":1.0},{"price":11291282.0,"size":0.001},{"price":11291268.0,"size":0.01},{"price":11291000.0,"size":0.5},{"price":11290000.0,"size":0.003},{"price":11281268.0,"size":0.01},{"price":11280000.0,"size":0.0163},{"price":11279960.0,"size":0.001},{"price":11279282.0,"size":0.0015},{"price":11278000.0,"size":0.0025},{"price":11275000.0,"size":0.001},{"price":11274588.0,"size":0.0047},{"price":11271268.0,"size":0.01},{"price":11271000.0,"size":0.003},{"price":11270000.0,"size":0.106},{"price":11269424.0,"size":0.8},{"price":11268871.0,"size":0.28},{"price":11268638.0,"size":0.001},{"price":11268411.0,"size":0.01},{"price":11266666.0,"size":0.04},{"price":11265000.0,"size":0.02},{"price":11263000.0,"size":0.006},{"price":11262564.0,"size":0.0015},{"price":11261268.0,"size":0.01},{"price":11260000.0,"size":0.3565},{"price":11257315.0,"size":0.001},{"price":11257000.0,"size":0.001},{"price":11255200.0,"size":0.001},{"price":11255115.0,"size":0.00377},{"price":11253814.0,"size":2.2},{"price":11253690.0,"size":0.01},{"price":11253000.0,"size":0.03189},{"price":11251405.0,"size":0.139},{"price":11251268.0,"size":0.01},{"price":11251111.0,"size":0.0015},{"price":11251000.0,"size":0.0131},{"price":11250250.0,"size":0.00105},{"price":11250200.0,"size":0.001},{"price":11250005.0,"size":0.001},{"price":11250001.0,"size":0.00104},{"price":11250000.0,"size":1.62712889},{"price":11245993.0,"size":0.001},{"price":11245141.0,"size":0.0031},{"price":11245000.0,"size":0.05},{"price":11244444.0,"size":0.04},{"price":11244243.0,"size":0.01},{"price":11240200.0,"size":0.001},{"price":11240000.0,"size":0.007304},{"price":11236190.0,"size":0.01},{"price":11235200.0,"size":0.001},{"price":11234670.0,"size":0.001},{"price":11234512.0,"size":0.0015},{"price":11232000.0,"size":0.089},{"price":11231243.0,"size":0.01},{"price":11231000.0,"size":0.105},{"price":11230200.0,"size":0.001},{"price":11230000.0,"size":0.0308},{"price":11226952.0,"size":0.972},{"price":11224500.0,"size":0.06},{"price":11223968.0,"size":0.001},{"price":11223348.0,"size":0.001},{"price":11223344.0,"size":0.01},{"price":11223000.0,"size":0.1},{"price":11222222.0,"size":0.093525},{"price":11221120.0,"size":0.001},{"price":11220200.0,"size":0.001},{"price":11220001.0,"size":0.004457},{"price":11220000.0,"size":0.321},{"price":11219000.0,"size":0.1},{"price":11217326.0,"size":0.02},{"price":11215200.0,"size":0.001},{"price":11213690.0,"size":0.01},{"price":11212764.0,"size":0.0015},{"price":11212025.0,"size":0.001},{"price":11211800.0,"size":0.001},{"price":11211111.0,"size":0.06},{"price":11210200.0,"size":0.001},{"price":11210000.0,"size":0.10622},{"price":11208032.0,"size":0.01},{"price":11206000.0,"size":0.09015},{"price":11205200.0,"size":0.001},{"price":11204578.0,"size":0.002},{"price":11201000.0,"size":0.01},{"price":11200800.0,"size":0.05},{"price":11200703.0,"size":0.001},{"price":11200425.0,"size":0.1},{"price":11200200.0,"size":0.001},{"price":11200198.0,"size":0.003},{"price":11200150.0,"size":0.002},{"price":11200002.0,"size":0.001},{"price":11200001.0,"size":0.01104},{"price":11200000.0,"size":1.15226728},{"price":11198508.0,"size":0.05},{"price":11198243.0,"size":0.01},{"price":11197134.0,"size":0.993},{"price":11197000.0,"size":0.0085},{"price":11194090.0,"size":0.03},{"price":11190770.0,"size":0.0309},{"price":11190000.0,"size":0.0010016},{"price":11189555.0,"size":0.5},{"price":11189381.0,"size":0.001},{"price":11188629.0,"size":0.01},{"price":11188382.0,"size":0.001},{"price":11185000.0,"size":0.0085},{"price":11180000.0,"size":0.225},{"price":11178058.0,"size":0.001},{"price":11170000.0,"size":0.001},{"price":11169662.0,"size":0.01},{"price":11169593.0,"size":0.001},{"price":11169243.0,"size":0.01},{"price":11166736.0,"size":0.001},{"price":11164029.0,"size":0.001},{"price":11160854.0,"size":0.1},{"price":11160000.0,"size":0.02376},{"price":11155413.0,"size":0.001},{"price":11155377.0,"size":0.00636009},{"price":11153999.0,"size":0.00101},{"price":11151000.0,"size":0.001},{"price":11150250.0,"size":0.00175},{"price":11150005.0,"size":0.001},{"price":11150001.0,"size":0.00104},{"price":11150000.0,"size":0.6533956},{"price":11148000.0,"size":0.08963},{"price":11147546.0,"size":0.02},{"price":11144091.0,"size":0.001},{"price":11144000.0,"size":0.0897},{"price":11143986.0,"size":0.02},{"price":11140139.0,"size":1.0},{"price":11140000.0,"size":0.2},{"price":11136243.0,"size":0.01},{"price":11135869.0,"size":0.1},{"price":11132768.0,"size":0.001},{"price":11130000.0,"size":0.116},{"price":11129979.0,"size":0.0053908},{"price":11124900.0,"size":0.00133},{"price":11121090.0,"size":0.1},{"price":11120000.0,"size":0.0033},{"price":11118078.0,"size":0.01},{"price":11111800.0,"size":0.001},{"price":11111111.0,"size":0.2919257},{"price":11111000.0,"size":0.003},{"price":11110594.0,"size":0.001},{"price":11110000.0,"size":0.021007},{"price":11109662.0,"size":0.01},{"price":11108008.0,"size":0.01},{"price":11102000.0,"size":0.5},{"price":11101297.0,"size":0.001},{"price":11100005.0,"size":0.001},{"price":11100001.0,"size":0.01104},{"price":11100000.0,"size":1.6532049},{"price":11099141.0,"size":0.01},{"price":11098833.0,"size":0.002},{"price":11096243.0,"size":0.01},{"price":11094090.0,"size":0.01},{"price":11088888.0,"size":0.001},{"price":11085245.0,"size":0.001},{"price":11080200.0,"size":0.001},{"price":11080000.0,"size":0.0223},{"price":11075100.0,"size":0.003},{"price":11070200.0,"size":0.001},{"price":11070000.0,"size":0.0902},{"price":11065200.0,"size":0.001},{"price":11064370.0,"size":0.00497091},{"price":11060200.0,"size":0.001},{"price":11060000.0,"size":0.145},{"price":11059689.0,"size":0.009},{"price":11056428.0,"size":0.002},{"price":11055500.0,"size":0.02},{"price":11055200.0,"size":0.001},{"price":11055100.0,"size":0.003},{"price":11050200.0,"size":0.001},{"price":11050005.0,"size":0.001},{"price":11050002.0,"size":0.001},{"price":11050001.0,"size":0.00104},{"price":11050000.0,"size":0.39576147},{"price":11048064.0,"size":2.0},{"price":11046420.0,"size":0.2},{"price":11044243.0,"size":0.01},{"price":11041380.0,"size":0.01},{"price":11040200.0,"size":0.001},{"price":11040000.0,"size":0.00777181},{"price":11035865.0,"size":0.1},{"price":11035200.0,"size":0.001},{"price":11035000.0,"size":0.0013},{"price":11030200.0,"size":0.001},{"price":11030000.0,"size":0.025},{"price":11025500.0,"size":0.009531},{"price":11025200.0,"size":0.001},{"price":11025000.0,"size":0.71497},{"price":11020772.0,"size":0.014},{"price":11020200.0,"size":0.002},{"price":11020000.0,"size":0.005},{"price":11015200.0,"size":0.001},{"price":11012000.0,"size":0.1},{"price":11011800.0,"size":0.001},{"price":11010200.0,"size":0.001},{"price":11010000.0,"size":0.347},{"price":11007277.0,"size":0.01},{"price":11005200.0,"size":0.001},{"price":11004890.0,"size":0.001535},{"price":11003000.0,"size":0.0155},{"price":11001000.0,"size":0.013},{"price":11000500.0,"size":0.05117658},{"price":11000200.0,"size":0.001},{"price":11000002.0,"size":0.004},{"price":11000001.0,"size":0.02604},{"price":11000000.0,"size":4.53923365},{"price":10999999.0,"size":0.003},{"price":10999000.0,"size":0.001},{"price":10996855.0,"size":0.0011},{"price":10995200.0,"size":0.001},{"price":10994499.0,"size":0.00169176},{"price":10990200.0,"size":0.001}],"asks":[{"price":11384266.0,"size":0.06622162},{"price":11384269.0,"size":0.0631},{"price":11384279.0,"size":0.015288},{"price":11384362.0,"size":0.02},{"price":11384498.0,"size":0.005},{"price":11384575.0,"size":0.014448},{"price":11384915.0,"size":0.01000441},{"price":11387320.0,"size":0.02},{"price":11387321.0,"size":0.3125},{"price":11389573.0,"size":0.0044},{"price":11390083.0,"size":0.2626},{"price":11390196.0,"size":0.0550368},{"price":11390375.0,"size":0.234},{"price":11390878.0,"size":0.01},{"price":11391431.0,"size":0.57229092},{"price":11391432.0,"size":0.4249},{"price":11392010.0,"size":0.00142446},{"price":11392845.0,"size":0.2819},{"price":11395000.0,"size":0.02},{"price":11395175.0,"size":0.0526},{"price":11395285.0,"size":0.2},{"price":11395607.0,"size":0.2962},{"price":11395665.0,"size":0.05},{"price":11396674.0,"size":0.05},{"price":11397000.0,"size":0.02},{"price":11397243.0,"size":0.0384},{"price":11398444.0,"size":0.001995},{"price":11398845.0,"size":0.001},{"price":11399673.0,"size":0.0015},{"price":11399700.0,"size":0.001},{"price":11399998.0,"size":0.33543393},{"price":11399999.0,"size":0.05},{"price":11400000.0,"size":1.04832841},{"price":11400402.0,"size":1.189881},{"price":11401107.0,"size":1.189881},{"price":11403472.0,"size":0.002},{"price":11405000.0,"size":0.1575},{"price":11408700.0,"size":0.001},{"price":11409413.0,"size":0.29418471},{"price":11409414.0,"size":1.60199848},{"price":11409415.0,"size":0.005},{"price":11409925.0,"size":0.22},{"price":11410000.0,"size":0.6285},{"price":11410168.0,"size":0.001},{"price":11410853.0,"size":0.002},{"price":11412000.0,"size":0.0878},{"price":11412889.0,"size":1.489},{"price":11415000.0,"size":0.1},{"price":11415141.0,"size":0.0041},{"price":11417481.0,"size":0.0015},{"price":11418700.0,"size":0.001},{"price":11419000.0,"size":0.01},{"price":11420000.0,"size":0.261},{"price":11420064.0,"size":1.928},{"price":11421268.0,"size":0.05},{"price":11421490.0,"size":0.001},{"price":11424296.0,"size":0.002},{"price":11426426.0,"size":0.002},{"price":11428121.0,"size":0.002},{"price":11428700.0,"size":0.001},{"price":11429302.0,"size":0.01},{"price":11430000.0,"size":2.62388164},{"price":11432718.0,"size":0.002},{"price":11432813.0,"size":0.001},{"price":11433211.0,"size":0.03},{"price":11433333.0,"size":0.001},{"price":11437315.0,"size":0.002},{"price":11438525.0,"size":0.0011},{"price":11438700.0,"size":0.001},{"price":11439557.0,"size":0.001},{"price":11440000.0,"size":0.2538},{"price":11441911.0,"size":0.002},{"price":11443629.0,"size":0.002},{"price":11444135.0,"size":0.001},{"price":11445000.0,"size":0.029},{"price":11445433.0,"size":0.0015},{"price":11446508.0,"size":0.001},{"price":11447000.0,"size":0.01},{"price":11447071.0,"size":0.002},{"price":11448000.0,"size":0.0875},{"price":11448700.0,"size":0.001},{"price":11448964.0,"size":2.018},{"price":11450000.0,"size":0.268},{"price":11451105.0,"size":0.002},{"price":11453321.0,"size":0.03},{"price":11455000.0,"size":0.001},{"price":11455457.0,"size":0.001},{"price":11455702.0,"size":0.002},{"price":11458700.0,"size":0.001},{"price":11458988.0,"size":0.01},{"price":11460000.0,"size":0.06702},{"price":11460299.0,"size":0.002},{"price":11463288.0,"size":0.01},{"price":11464896.0,"size":0.002},{"price":11465382.0,"size":0.00195},{"price":11465421.0,"size":1.943},{"price":11466780.0,"size":0.001},{"price":11468700.0,"size":0.001},{"price":11470000.0,"size":0.06},{"price":11471000.0,"size":0.01},{"price":11475000.0,"size":0.0028},{"price":11476929.0,"size":1.0},{"price":11478102.0,"size":0.001},{"price":11478431.0,"size":0.002},{"price":11478700.0,"size":0.001},{"price":11480000.0,"size":0.40191},{"price":11485000.0,"size":0.01},{"price":11485488.0,"size":2.0},{"price":11486555.0,"size":0.03},{"price":11487685.0,"size":0.01},{"price":11488000.0,"size":0.102},{"price":11488700.0,"size":0.001},{"price":11489425.0,"size":0.001},{"price":11490000.0,"size":0.05},{"price":11490841.0,"size":0.002},{"price":11495450.0,"size":0.002},{"price":11495488.0,"size":0.0015},{"price":11495850.0,"size":0.001},{"price":11498700.0,"size":0.001},{"price":11498917.0,"size":0.002},{"price":11499000.0,"size":0.01},{"price":11500000.0,"size":0.77159519},{"price":11500078.0,"size":0.93},{"price":11500747.0,"size":0.001},{"price":11502377.0,"size":0.002},{"price":11502800.0,"size":0.00132},{"price":11503108.0,"size":0.0198},{"price":11505000.0,"size":0.0028},{"price":11505001.0,"size":0.002},{"price":11505836.0,"size":0.003},{"price":11508431.0,"size":0.047},{"price":11508700.0,"size":0.001},{"price":11508888.0,"size":0.02},{"price":11510000.0,"size":0.1476},{"price":11512070.0,"size":0.001},{"price":11513633.0,"size":0.08},{"price":11514332.0,"size":0.02},{"price":11517236.0,"size":0.0015},{"price":11518700.0,"size":0.001},{"price":11518992.0,"size":0.002},{"price":11519855.0,"size":0.01},{"price":11520000.0,"size":0.001},{"price":11522388.0,"size":0.972},{"price":11523211.0,"size":0.01},{"price":11524999.0,"size":0.001},{"price":11528700.0,"size":0.001},{"price":11529852.0,"size":0.01},{"price":11530000.0,"size":0.261},{"price":11533985.0,"size":0.002},{"price":11534084.0,"size":0.001},{"price":11535321.0,"size":0.01},{"price":11538666.0,"size":0.002},{"price":11538700.0,"size":0.001},{"price":11540000.0,"size":0.0048},{"price":11540357.0,"size":0.002},{"price":11541011.0,"size":0.005},{"price":11541109.0,"size":0.01},{"price":11544663.0,"size":0.002},{"price":11545262.0,"size":0.002},{"price":11546541.0,"size":0.01},{"price":11548144.0,"size":0.002},{"price":11548700.0,"size":0.001},{"price":11550000.0,"size":0.014},{"price":11551109.0,"size":0.01},{"price":11551625.0,"size":0.002},{"price":11552111.0,"size":0.01},{"price":11553687.0,"size":0.1},{"price":11555106.0,"size":0.002},{"price":11555115.0,"size":0.001},{"price":11556000.0,"size":0.1},{"price":11558587.0,"size":0.002},{"price":11558700.0,"size":0.001},{"price":11559855.0,"size":0.01},{"price":11560831.0,"size":0.0198},{"price":11561109.0,"size":0.01},{"price":11562000.0,"size":0.087},{"price":11562068.0,"size":0.002},{"price":11563750.0,"size":0.08739676},{"price":11565548.0,"size":0.002},{"price":11566139.0,"size":0.0228},{"price":11566551.0,"size":0.01},{"price":11568700.0,"size":0.001},{"price":11569029.0,"size":0.002},{"price":11570196.0,"size":0.002},{"price":11571109.0,"size":0.01},{"price":11572510.0,"size":0.002},{"price":11573211.0,"size":0.01},{"price":11574840.0,"size":0.002},{"price":11575991.0,"size":0.001},{"price":11578700.0,"size":0.001},{"price":11579484.0,"size":0.002},{"price":11579851.0,"size":0.01},{"price":11580000.0,"size":0.7835},{"price":11581109.0,"size":0.01},{"price":11584128.0,"size":0.002},{"price":11585000.0,"size":0.002},{"price":11586532.0,"size":0.01},{"price":11587498.0,"size":0.0198},{"price":11588700.0,"size":0.001},{"price":11588800.0,"size":0.02},{"price":11590000.0,"size":0.1},{"price":11590749.0,"size":0.002},{"price":11591109.0,"size":0.01},{"price":11593211.0,"size":0.01},{"price":11596753.0,"size":0.002},{"price":11598111.0,"size":0.1474},{"price":11598555.0,"size":0.01},{"price":11598700.0,"size":0.001},{"price":11599999.0,"size":0.001},{"price":11600000.0,"size":3.655},{"price":11601109.0,"size":0.02},{"price":11603764.0,"size":0.9},{"price":11606655.0,"size":0.01},{"price":11610000.0,"size":0.302},{"price":11611109.0,"size":0.01},{"price":11613321.0,"size":0.01},{"price":11620000.0,"size":1.35441682},{"price":11621011.0,"size":0.01},{"price":11621109.0,"size":0.01},{"price":11623096.0,"size":0.008},{"price":11625703.0,"size":0.012},{"price":11629000.0,"size":0.1},{"price":11630000.0,"size":0.201},{"price":11631059.0,"size":0.01},{"price":11631479.0,"size":0.01},{"price":11631773.0,"size":0.00386871},{"price":11635950.0,"size":0.001},{"price":11638259.0,"size":0.001},{"price":11639700.0,"size":0.001},{"price":11640000.0,"size":1.0},{"price":11640820.0,"size":0.01},{"price":11649900.0,"size":0.02906},{"price":11649999.0,"size":0.001},{"price":11650000.0,"size":0.593},{"price":11651059.0,"size":0.01},{"price":11653658.0,"size":0.008},{"price":11654321.0,"size":0.001},{"price":11659700.0,"size":0.001},{"price":11661479.0,"size":0.01},{"price":11666000.0,"size":0.001},{"price":11666666.0,"size":0.013},{"price":11669700.0,"size":0.001},{"price":11671059.0,"size":0.01},{"price":11672562.0,"size":0.0198},{"price":11680000.0,"size":0.014},{"price":11685000.0,"size":0.003},{"price":11688000.0,"size":0.001},{"price":11689732.0,"size":0.01},{"price":11690330.0,"size":0.0198},{"price":11691059.0,"size":0.01},{"price":11692558.0,"size":0.01},{"price":11695019.0,"size":0.0064},{"price":11698800.0,"size":0.00131},{"price":11699000.0,"size":0.001},{"price":11699631.0,"size":0.001},{"price":11699998.0,"size":0.01},{"price":11699999.0,"size":0.001},{"price":11700000.0,"size":1.2573},{"price":11701059.0,"size":0.01},{"price":11720000.0,"size":0.1},{"price":11721059.0,"size":0.01},{"price":11725000.0,"size":0.005},{"price":11726791.0,"size":0.01},{"price":11727418.0,"size":1.8},{"price":11728195.0,"size":0.05},{"price":11730000.0,"size":1.9712},{"price":11740000.0,"size":0.101},{"price":11741059.0,"size":0.01},{"price":11748937.0,"size":0.001},{"price":11749999.0,"size":0.001},{"price":11750000.0,"size":0.89537866},{"price":11750050.0,"size":0.2},{"price":11751151.0,"size":0.01},{"price":11751406.0,"size":0.012},{"price":11755000.0,"size":0.001},{"price":11757860.0,"size":1.82},{"price":11759999.0,"size":0.001},{"price":11760000.0,"size":0.001},{"price":11761059.0,"size":0.02},{"price":11765432.0,"size":0.001},{"price":11768000.0,"size":0.01},{"price":11770000.0,"size":0.25464896},{"price":11771059.0,"size":0.01755555},{"price":11772000.0,"size":0.002},{"price":11775000.0,"size":0.11593},{"price":11775222.0,"size":0.001657},{"price":11775577.0,"size":0.00013523},{"price":11775800.0,"size":0.001},{"price":11775900.0,"size":0.2},{"price":11775989.0,"size":0.005},{"price":11777000.0,"size":0.5956},{"price":11777777.0,"size":0.0067},{"price":11778541.0,"size":0.001},{"price":11779807.0,"size":0.001},{"price":11780000.0,"size":0.74298},{"price":11780800.0,"size":0.1},{"price":11781059.0,"size":0.01},{"price":11781238.0,"size":0.008},{"price":11785000.0,"size":0.055},{"price":11785040.0,"size":0.01}]}}}
{"schema_version":"collector.vnext.raw","schema_contract":null,"schema_contract_version":null,"payload_contract_version":null,"record_type":"market.orderbook.diff","record_id":"collector_main-market-orderbook-diff-000000000061","collector_id":"collector_main","collector_role":"production","host_name":"MAIN-PC","session_id":"collector_main-sess-20260315T000735Z-a5915a6a","stream_session_id":"collector_main-stream-bitflyer-board_ws-20260315T000806Z-40ac6a26","exchange":"bitflyer","market":"spot","symbol":"BTC_JPY","instrument_id":"bitflyer.spot.BTC_JPY","channel":"board_ws","transport":"websocket","source_event_id":null,"source_sequence":null,"sequence_id":61,"exchange_ts":null,"collector_ts":"2026-03-15T00:08:06Z","ingest_ts":"2026-03-15T00:08:06Z","event_ts":"2026-03-15T00:08:06Z","quality_flags":[],"is_partial":false,"is_reconstructed":false,"confidence_score":1.0,"payload":{"provider":"bitflyer_ws_board","exchange":"bitflyer","transport":"websocket","channel":"lightning_board_BTC_JPY","received_ts":"2026-03-15T00:08:06.854600Z","subscription_id":null,"message_id":null,"source_sequence":null,"raw_message_meta":{"raw_channel":"lightning_board_BTC_JPY","subscription_channel":"lightning_board_BTC_JPY","recv_timeout_sec":10,"ssl_verify":false,"socket_url":"wss://ws.lightstream.bitflyer.com/json-rpc"},"source_payload":{"mid_price":11377861.0,"bids":[{"price":11374164.0,"size":0.0}],"asks":[]}}}
{"schema_version":"collector.vnext.raw","schema_contract":null,"schema_contract_version":null,"payload_contract_version":null,"record_type":"market.orderbook.diff","record_id":"collector_main-market-orderbook-diff-000000000065","collector_id":"collector_main","collector_role":"production","host_name":"MAIN-PC","session_id":"collector_main-sess-20260315T000735Z-a5915a6a","stream_session_id":"collector_main-stream-bitflyer-board_ws-20260315T000806Z-40ac6a26","exchange":"bitflyer","market":"spot","symbol":"BTC_JPY","instrument_id":"bitflyer.spot.BTC_JPY","channel":"board_ws","transport":"websocket","source_event_id":null,"source_sequence":null,"sequence_id":65,"exchange_ts":null,"collector_ts":"2026-03-15T00:08:07Z","ingest_ts":"2026-03-15T00:08:07Z","event_ts":"2026-03-15T00:08:07Z","quality_flags":[],"is_partial":false,"is_reconstructed":false,"confidence_score":1.0,"payload":{"provider":"bitflyer_ws_board","exchange":"bitflyer","transport":"websocket","channel":"lightning_board_BTC_JPY","received_ts":"2026-03-15T00:08:07.015814Z","subscription_id":null,"message_id":null,"source_sequence":null,"raw_message_meta":{"raw_channel":"lightning_board_BTC_JPY","subscription_channel":"lightning_board_BTC_JPY","recv_timeout_sec":10,"ssl_verify":false,"socket_url":"wss://ws.lightstream.bitflyer.com/json-rpc"},"source_payload":{"mid_price":11377861.0,"bids":[{"price":11374848.0,"size":0.0}],"asks":[]}}}
{"schema_version":"collector.vnext.raw","schema_contract":null,"schema_contract_version":null,"payload_contract_version":null,"record_type":"market.orderbook.diff","record_id":"collector_main-market-orderbook-diff-000000000067","collector_id":"collector_main","collector_role":"production","host_name":"MAIN-PC","session_id":"collector_main-sess-20260315T000735Z-a5915a6a","stream_session_id":"collector_main-stream-bitflyer-board_ws-20260315T000806Z-40ac6a26","exchange":"bitflyer","market":"spot","symbol":"BTC_JPY","instrument_id":"bitflyer.spot.BTC_JPY","channel":"board_ws","transport":"websocket","source_event_id":null,"source_sequence":null,"sequence_id":67,"exchange_ts":null,"collector_ts":"2026-03-15T00:08:07Z","ingest_ts":"2026-03-15T00:08:07Z","event_ts":"2026-03-15T00:08:07Z","quality_flags":[],"is_partial":false,"is_reconstructed":false,"confidence_score":1.0,"payload":{"provider":"bitflyer_ws_board","exchange":"bitflyer","transport":"websocket","channel":"lightning_board_BTC_JPY","received_ts":"2026-03-15T00:08:07.137285Z","subscription_id":null,"message_id":null,"source_sequence":null,"raw_message_meta":{"raw_channel":"lightning_board_BTC_JPY","subscription_channel":"lightning_board_BTC_JPY","recv_timeout_sec":10,"ssl_verify":false,"socket_url":"wss://ws.lightstream.bitflyer.com/json-rpc"},"source_payload":{"mid_price":11377860.0,"bids":[{"price":11374199.0,"size":0.0109178},{"price":11370465.0,"size":0.1275},{"price":11375118.0,"size":0.03308965},{"price":11366948.0,"size":0.08}],"asks":[{"price":11380896.0,"size":0.0},{"price":11380603.0,"size":0.014652}]}}}
{"schema_version":"collector.vnext.raw","schema_contract":null,"schema_contract_version":null,"payload_contract_version":null,"record_type":"market.orderbook.diff","record_id":"collector_main-market-orderbook-diff-000000000069","collector_id":"collector_main","collector_role":"production","host_name":"MAIN-PC","session_id":"collector_main-sess-20260315T000735Z-a5915a6a","stream_session_id":"collector_main-stream-bitflyer-board_ws-20260315T000806Z-40ac6a26","exchange":"bitflyer","market":"spot","symbol":"BTC_JPY","instrument_id":"bitflyer.spot.BTC_JPY","channel":"board_ws","transport":"websocket","source_event_id":null,"source_sequence":null,"sequence_id":69,"exchange_ts":null,"collector_ts":"2026-03-15T00:08:07Z","ingest_ts":"2026-03-15T00:08:07Z","event_ts":"2026-03-15T00:08:07Z","quality_flags":[],"is_partial":false,"is_reconstructed":false,"confidence_score":1.0,"payload":{"provider":"bitflyer_ws_board","exchange":"bitflyer","transport":"websocket","channel":"lightning_board_BTC_JPY","received_ts":"2026-03-15T00:08:07.244548Z","subscription_id":null,"message_id":null,"source_sequence":null,"raw_message_meta":{"raw_channel":"lightning_board_BTC_JPY","subscription_channel":"lightning_board_BTC_JPY","recv_timeout_sec":10,"ssl_verify":false,"socket_url":"wss://ws.lightstream.bitflyer.com/json-rpc"},"source_payload":{"mid_price":11377860.0,"bids":[{"price":11373712.0,"size":0.0},{"price":11373747.0,"size":0.0},{"price":11372582.0,"size":0.0},{"price":11374847.0,"size":0.0}],"asks":[]}}}
{"schema_version":"collector.vnext.raw","schema_contract":null,"schema_contract_version":null,"payload_contract_version":null,"record_type":"market.orderbook.diff","record_id":"collector_main-market-orderbook-diff-000000000071","collector_id":"collector_main","collector_role":"production","host_name":"MAIN-PC","session_id":"collector_main-sess-20260315T000735Z-a5915a6a","stream_session_id":"collector_main-stream-bitflyer-board_ws-20260315T000806Z-40ac6a26","exchange":"bitflyer","market":"spot","symbol":"BTC_JPY","instrument_id":"bitflyer.spot.BTC_JPY","channel":"board_ws","transport":"websocket","source_event_id":null,"source_sequence":null,"sequence_id":71,"exchange_ts":null,"collector_ts":"2026-03-15T00:08:07Z","ingest_ts":"2026-03-15T00:08:07Z","event_ts":"2026-03-15T00:08:07Z","quality_flags":[],"is_partial":false,"is_reconstructed":false,"confidence_score":1.0,"payload":{"provider":"bitflyer_ws_board","exchange":"bitflyer","transport":"websocket","channel":"lightning_board_BTC_JPY","received_ts":"2026-03-15T00:08:07.376390Z","subscription_id":null,"message_id":null,"source_sequence":null,"raw_message_meta":{"raw_channel":"lightning_board_BTC_JPY","subscription_channel":"lightning_board_BTC_JPY","recv_timeout_sec":10,"ssl_verify":false,"socket_url":"wss://ws.lightstream.bitflyer.com/json-rpc"},"source_payload":{"mid_price":11377627.0,"bids":[{"price":11371380.0,"size":0.02},{"price":11371033.0,"size":0.1275},{"price":11372597.0,"size":0.02}],"asks":[{"price":11380652.0,"size":0.0},{"price":11380617.0,"size":0.014664},{"price":11380605.0,"size":0.0},{"price":11380137.0,"size":0.022},{"price":11380602.0,"size":0.05360649}]}}}
{"schema_version":"collector.vnext.raw","schema_contract":null,"schema_contract_version":null,"payload_contract_version":null,"record_type":"market.orderbook.diff","record_id":"collector_main-market-orderbook-diff-000000000073","collector_id":"collector_main","collector_role":"production","host_name":"MAIN-PC","session_id":"collector_main-sess-20260315T000735Z-a5915a6a","stream_session_id":"collector_main-stream-bitflyer-board_ws-20260315T000806Z-40ac6a26","exchange":"bitflyer","market":"spot","symbol":"BTC_JPY","instrument_id":"bitflyer.spot.BTC_JPY","channel":"board_ws","transport":"websocket","source_event_id":null,"source_sequence":null,"sequence_id":73,"exchange_ts":null,"collector_ts":"2026-03-15T00:08:07Z","ingest_ts":"2026-03-15T00:08:07Z","event_ts":"2026-03-15T00:08:07Z","quality_flags":[],"is_partial":false,"is_reconstructed":false,"confidence_score":1.0,"payload":{"provider":"bitflyer_ws_board","exchange":"bitflyer","transport":"websocket","channel":"lightning_board_BTC_JPY","received_ts":"2026-03-15T00:08:07.547124Z","subscription_id":null,"message_id":null,"source_sequence":null,"raw_message_meta":{"raw_channel":"lightning_board_BTC_JPY","subscription_channel":"lightning_board_BTC_JPY","recv_timeout_sec":10,"ssl_verify":false,"socket_url":"wss://ws.lightstream.bitflyer.com/json-rpc"},"source_payload":{"mid_price":11377627.0,"bids":[{"price":11365810.0,"size":0.0}],"asks":[{"price":11380602.0,"size":0.0}]}}}
{"schema_version":"collector.vnext.raw","schema_contract":null,"schema_contract_version":null,"payload_contract_version":null,"record_type":"market.orderbook.diff","record_id":"collector_main-market-orderbook-diff-000000000075","collector_id":"collector_main","collector_role":"production","host_name":"MAIN-PC","session_id":"collector_main-sess-20260315T000735Z-a5915a6a","stream_session_id":"collector_main-stream-bitflyer-board_ws-20260315T000806Z-40ac6a26","exchange":"bitflyer","market":"spot","symbol":"BTC_JPY","instrument_id":"bitflyer.spot.BTC_JPY","channel":"board_ws","transport":"websocket","source_event_id":null,"source_sequence":null,"sequence_id":75,"exchange_ts":null,"collector_ts":"2026-03-15T00:08:07Z","ingest_ts":"2026-03-15T00:08:07Z","event_ts":"2026-03-15T00:08:07Z","quality_flags":[],"is_partial":false,"is_reconstructed":false,"confidence_score":1.0,"payload":{"provider":"bitflyer_ws_board","exchange":"bitflyer","transport":"websocket","channel":"lightning_board_BTC_JPY","received_ts":"2026-03-15T00:08:07.656905Z","subscription_id":null,"message_id":null,"source_sequence":null,"raw_message_meta":{"raw_channel":"lightning_board_BTC_JPY","subscription_channel":"lightning_board_BTC_JPY","recv_timeout_sec":10,"ssl_verify":false,"socket_url":"wss://ws.lightstream.bitflyer.com/json-rpc"},"source_payload":{"mid_price":11377626.0,"bids":[],"asks":[{"price":11380135.0,"size":0.015276},{"price":11380608.0,"size":0.0},{"price":11380136.0,"size":0.04591777}]}}}
{"schema_version":"collector.vnext.raw","schema_contract":null,"schema_contract_version":null,"payload_contract_version":null,"record_type":"market.orderbook.diff","record_id":"collector_main-market-orderbook-diff-000000000077","collector_id":"collector_main","collector_role":"production","host_name":"MAIN-PC","session_id":"collector_main-sess-20260315T000735Z-a5915a6a","stream_session_id":"collector_main-stream-bitflyer-board_ws-20260315T000806Z-40ac6a26","exchange":"bitflyer","market":"spot","symbol":"BTC_JPY","instrument_id":"bitflyer.spot.BTC_JPY","channel":"board_ws","transport":"websocket","source_event_id":null,"source_sequence":null,"sequence_id":77,"exchange_ts":null,"collector_ts":"2026-03-15T00:08:07Z","ingest_ts":"2026-03-15T00:08:07Z","event_ts":"2026-03-15T00:08:07Z","quality_flags":[],"is_partial":false,"is_reconstructed":false,"confidence_score":1.0,"payload":{"provider":"bitflyer_ws_board","exchange":"bitflyer","transport":"websocket","channel":"lightning_board_BTC_JPY","received_ts":"2026-03-15T00:08:07.765995Z","subscription_id":null,"message_id":null,"source_sequence":null,"raw_message_meta":{"raw_channel":"lightning_board_BTC_JPY","subscription_channel":"lightning_board_BTC_JPY","recv_timeout_sec":10,"ssl_verify":false,"socket_url":"wss://ws.lightstream.bitflyer.com/json-rpc"},"source_payload":{"mid_price":11377626.0,"bids":[{"price":11371587.0,"size":0.02},{"price":11374199.0,"size":0.0}],"asks":[{"price":11380137.0,"size":0.1112},{"price":11380617.0,"size":0.0}]}}}
{"schema_version":"collector.vnext.raw","schema_contract":null,"schema_contract_version":null,"payload_contract_version":null,"record_type":"market.orderbook.diff","record_id":"collector_main-market-orderbook-diff-000000000079","collector_id":"collector_main","collector_role":"production","host_name":"MAIN-PC","session_id":"collector_main-sess-20260315T000735Z-a5915a6a","stream_session_id":"collector_main-stream-bitflyer-board_ws-20260315T000806Z-40ac6a26","exchange":"bitflyer","market":"spot","symbol":"BTC_JPY","instrument_id":"bitflyer.spot.BTC_JPY","channel":"board_ws","transport":"websocket","source_event_id":null,"source_sequence":null,"sequence_id":79,"exchange_ts":null,"collector_ts":"2026-03-15T00:08:07Z","ingest_ts":"2026-03-15T00:08:07Z","event_ts":"2026-03-15T00:08:07Z","quality_flags":[],"is_partial":false,"is_reconstructed":false,"confidence_score":1.0,"payload":{"provider":"bitflyer_ws_board","exchange":"bitflyer","transport":"websocket","channel":"lightning_board_BTC_JPY","received_ts":"2026-03-15T00:08:07.890997Z","subscription_id":null,"message_id":null,"source_sequence":null,"raw_message_meta":{"raw_channel":"lightning_board_BTC_JPY","subscription_channel":"lightning_board_BTC_JPY","recv_timeout_sec":10,"ssl_verify":false,"socket_url":"wss://ws.lightstream.bitflyer.com/json-rpc"},"source_payload":{"mid_price":11377626.0,"bids":[{"price":11371791.0,"size":0.02}],"asks":[{"price":11381762.0,"size":0.0154534},{"price":11441911.0,"size":0.002},{"price":11380136.0,"size":0.0}]}}}
{"schema_version":"collector.vnext.raw","schema_contract":null,"schema_contract_version":null,"payload_contract_version":null,"record_type":"market.orderbook.diff","record_id":"collector_main-market-orderbook-diff-000000000081","collector_id":"collector_main","collector_role":"production","host_name":"MAIN-PC","session_id":"collector_main-sess-20260315T000735Z-a5915a6a","stream_session_id":"collector_main-stream-bitflyer-board_ws-20260315T000806Z-40ac6a26","exchange":"bitflyer","market":"spot","symbol":"BTC_JPY","instrument_id":"bitflyer.spot.BTC_JPY","channel":"board_ws","transport":"websocket","source_event_id":null,"source_sequence":null,"sequence_id":81,"exchange_ts":null,"collector_ts":"2026-03-15T00:08:08Z","ingest_ts":"2026-03-15T00:08:08Z","event_ts":"2026-03-15T00:08:08Z","quality_flags":[],"is_partial":false,"is_reconstructed":false,"confidence_score":1.0,"payload":{"provider":"bitflyer_ws_board","exchange":"bitflyer","transport":"websocket","channel":"lightning_board_BTC_JPY","received_ts":"2026-03-15T00:08:08.003426Z","subscription_id":null,"message_id":null,"source_sequence":null,"raw_message_meta":{"raw_channel":"lightning_board_BTC_JPY","subscription_channel":"lightning_board_BTC_JPY","recv_timeout_sec":10,"ssl_verify":false,"socket_url":"wss://ws.lightstream.bitflyer.com/json-rpc"},"source_payload":{"mid_price":11377626.0,"bids":[{"price":11366948.0,"size":0.0}],"asks":[{"price":11380134.0,"size":0.04933792}]}}}
{"schema_version":"collector.vnext.raw","schema_contract":null,"schema_contract_version":null,"payload_contract_version":null,"record_type":"market.orderbook.diff","record_id":"collector_main-market-orderbook-diff-000000000083","collector_id":"collector_main","collector_role":"production","host_name":"MAIN-PC","session_id":"collector_main-sess-20260315T000735Z-a5915a6a","stream_session_id":"collector_main-stream-bitflyer-board_ws-20260315T000806Z-40ac6a26","exchange":"bitflyer","market":"spot","symbol":"BTC_JPY","instrument_id":"bitflyer.spot.BTC_JPY","channel":"board_ws","transport":"websocket","source_event_id":null,"source_sequence":null,"sequence_id":83,"exchange_ts":null,"collector_ts":"2026-03-15T00:08:08Z","ingest_ts":"2026-03-15T00:08:08Z","event_ts":"2026-03-15T00:08:08Z","quality_flags":[],"is_partial":false,"is_reconstructed":false,"confidence_score":1.0,"payload":{"provider":"bitflyer_ws_board","exchange":"bitflyer","transport":"websocket","channel":"lightning_board_BTC_JPY","received_ts":"2026-03-15T00:08:08.095240Z","subscription_id":null,"message_id":null,"source_sequence":null,"raw_message_meta":{"raw_channel":"lightning_board_BTC_JPY","subscription_channel":"lightning_board_BTC_JPY","recv_timeout_sec":10,"ssl_verify":false,"socket_url":"wss://ws.lightstream.bitflyer.com/json-rpc"},"source_payload":{"mid_price":11377626.0,"bids":[{"price":11370465.0,"size":0.0}],"asks":[]}}}
{"schema_version":"collector.vnext.raw","schema_contract":null,"schema_contract_version":null,"payload_contract_version":null,"record_type":"market.orderbook.diff","record_id":"collector_main-market-orderbook-diff-000000000085","collector_id":"collector_main","collector_role":"production","host_name":"MAIN-PC","session_id":"collector_main-sess-20260315T000735Z-a5915a6a","stream_session_id":"collector_main-stream-bitflyer-board_ws-20260315T000806Z-40ac6a26","exchange":"bitflyer","market":"spot","symbol":"BTC_JPY","instrument_id":"bitflyer.spot.BTC_JPY","channel":"board_ws","transport":"websocket","source_event_id":null,"source_sequence":null,"sequence_id":85,"exchange_ts":null,"collector_ts":"2026-03-15T00:08:08Z","ingest_ts":"2026-03-15T00:08:08Z","event_ts":"2026-03-15T00:08:08Z","quality_flags":[],"is_partial":false,"is_reconstructed":false,"confidence_score":1.0,"payload":{"provider":"bitflyer_ws_board","exchange":"bitflyer","transport":"websocket","channel":"lightning_board_BTC_JPY","received_ts":"2026-03-15T00:08:08.203228Z","subscription_id":null,"message_id":null,"source_sequence":null,"raw_message_meta":{"raw_channel":"lightning_board_BTC_JPY","subscription_channel":"lightning_board_BTC_JPY","recv_timeout_sec":10,"ssl_verify":false,"socket_url":"wss://ws.lightstream.bitflyer.com/json-rpc"},"source_payload":{"mid_price":11377626.0,"bids":[{"price":11371901.0,"size":0.02}],"asks":[]}}}
{"schema_version":"collector.vnext.raw","schema_contract":null,"schema_contract_version":null,"payload_contract_version":null,"record_type":"market.orderbook.diff","record_id":"collector_main-market-orderbook-diff-000000000087","collector_id":"collector_main","collector_role":"production","host_name":"MAIN-PC","session_id":"collector_main-sess-20260315T000735Z-a5915a6a","stream_session_id":"collector_main-stream-bitflyer-board_ws-20260315T000806Z-40ac6a26","exchange":"bitflyer","market":"spot","symbol":"BTC_JPY","instrument_id":"bitflyer.spot.BTC_JPY","channel":"board_ws","transport":"websocket","source_event_id":null,"source_sequence":null,"sequence_id":87,"exchange_ts":null,"collector_ts":"2026-03-15T00:08:08Z","ingest_ts":"2026-03-15T00:08:08Z","event_ts":"2026-03-15T00:08:08Z","quality_flags":[],"is_partial":false,"is_reconstructed":false,"confidence_score":1.0,"payload":{"provider":"bitflyer_ws_board","exchange":"bitflyer","transport":"websocket","channel":"lightning_board_BTC_JPY","received_ts":"2026-03-15T00:08:08.320415Z","subscription_id":null,"message_id":null,"source_sequence":null,"raw_message_meta":{"raw_channel":"lightning_board_BTC_JPY","subscription_channel":"lightning_board_BTC_JPY","recv_timeout_sec":10,"ssl_verify":false,"socket_url":"wss://ws.lightstream.bitflyer.com/json-rpc"},"source_payload":{"mid_price":11377626.0,"bids":[{"price":11372614.0,"size":0.0109215},{"price":11373074.0,"size":0.1275}],"asks":[]}}}
{"schema_version":"collector.vnext.raw","schema_contract":null,"schema_contract_version":null,"payload_contract_version":null,"record_type":"market.orderbook.diff","record_id":"collector_main-market-orderbook-diff-000000000089","collector_id":"collector_main","collector_role":"production","host_name":"MAIN-PC","session_id":"collector_main-sess-20260315T000735Z-a5915a6a","stream_session_id":"collector_main-stream-bitflyer-board_ws-20260315T000806Z-40ac6a26","exchange":"bitflyer","market":"spot","symbol":"BTC_JPY","instrument_id":"bitflyer.spot.BTC_JPY","channel":"board_ws","transport":"websocket","source_event_id":null,"source_sequence":null,"sequence_id":89,"exchange_ts":null,"collector_ts":"2026-03-15T00:08:08Z","ingest_ts":"2026-03-15T00:08:08Z","event_ts":"2026-03-15T00:08:08Z","quality_flags":[],"is_partial":false,"is_reconstructed":false,"confidence_score":1.0,"payload":{"provider":"bitflyer_ws_board","exchange":"bitflyer","transport":"websocket","channel":"lightning_board_BTC_JPY","received_ts":"2026-03-15T00:08:08.512504Z","subscription_id":null,"message_id":null,"source_sequence":null,"raw_message_meta":{"raw_channel":"lightning_board_BTC_JPY","subscription_channel":"lightning_board_BTC_JPY","recv_timeout_sec":10,"ssl_verify":false,"socket_url":"wss://ws.lightstream.bitflyer.com/json-rpc"},"source_payload":{"mid_price":11377626.0,"bids":[{"price":11373074.0,"size":0.0}],"asks":[]}}}
{"schema_version":"collector.vnext.raw","schema_contract":null,"schema_contract_version":null,"payload_contract_version":null,"record_type":"market.orderbook.diff","record_id":"collector_main-market-orderbook-diff-000000000091","collector_id":"collector_main","collector_role":"production","host_name":"MAIN-PC","session_id":"collector_main-sess-20260315T000735Z-a5915a6a","stream_session_id":"collector_main-stream-bitflyer-board_ws-20260315T000806Z-40ac6a26","exchange":"bitflyer","market":"spot","symbol":"BTC_JPY","instrument_id":"bitflyer.spot.BTC_JPY","channel":"board_ws","transport":"websocket","source_event_id":null,"source_sequence":null,"sequence_id":91,"exchange_ts":null,"collector_ts":"2026-03-15T00:08:08Z","ingest_ts":"2026-03-15T00:08:08Z","event_ts":"2026-03-15T00:08:08Z","quality_flags":[],"is_partial":false,"is_reconstructed":false,"confidence_score":1.0,"payload":{"provider":"bitflyer_ws_board","exchange":"bitflyer","transport":"websocket","channel":"lightning_board_BTC_JPY","received_ts":"2026-03-15T00:08:08.672290Z","subscription_id":null,"message_id":null,"source_sequence":null,"raw_message_meta":{"raw_channel":"lightning_board_BTC_JPY","subscription_channel":"lightning_board_BTC_JPY","recv_timeout_sec":10,"ssl_verify":false,"socket_url":"wss://ws.lightstream.bitflyer.com/json-rpc"},"source_payload":{"mid_price":11377626.0,"bids":[],"asks":[{"price":11381762.0,"size":0.0}]}}}
{"schema_version":"collector.vnext.raw","schema_contract":null,"schema_contract_version":null,"payload_contract_version":null,"record_type":"market.orderbook.diff","record_id":"collector_main-market-orderbook-diff-000000000093","collector_id":"collector_main","collector_role":"production","host_name":"MAIN-PC","session_id":"collector_main-sess-20260315T000735Z-a5915a6a","stream_session_id":"collector_main-stream-bitflyer-board_ws-20260315T000806Z-40ac6a26","exchange":"bitflyer","market":"spot","symbol":"BTC_JPY","instrument_id":"bitflyer.spot.BTC_JPY","channel":"board_ws","transport":"websocket","source_event_id":null,"source_sequence":null,"sequence_id":93,"exchange_ts":null,"collector_ts":"2026-03-15T00:08:08Z","ingest_ts":"2026-03-15T00:08:08Z","event_ts":"2026-03-15T00:08:08Z","quality_flags":[],"is_partial":false,"is_reconstructed":false,"confidence_score":1.0,"payload":{"provider":"bitflyer_ws_board","exchange":"bitflyer","transport":"websocket","channel":"lightning_board_BTC_JPY","received_ts":"2026-03-15T00:08:08.798593Z","subscription_id":null,"message_id":null,"source_sequence":null,"raw_message_meta":{"raw_channel":"lightning_board_BTC_JPY","subscription_channel":"lightning_board_BTC_JPY","recv_timeout_sec":10,"ssl_verify":false,"socket_url":"wss://ws.lightstream.bitflyer.com/json-rpc"},"source_payload":{"mid_price":11377626.0,"bids":[{"price":11371380.0,"size":0.0},{"price":11373074.0,"size":0.1275},{"price":11372615.0,"size":0.02}],"asks":[]}}}
{"schema_version":"collector.vnext.raw","schema_contract":null,"schema_contract_version":null,"payload_contract_version":null,"record_type":"market.orderbook.diff","record_id":"collector_main-market-orderbook-diff-000000000095","collector_id":"collector_main","collector_role":"production","host_name":"MAIN-PC","session_id":"collector_main-sess-20260315T000735Z-a5915a6a","stream_session_id":"collector_main-stream-bitflyer-board_ws-20260315T000806Z-40ac6a26","exchange":"bitflyer","market":"spot","symbol":"BTC_JPY","instrument_id":"bitflyer.spot.BTC_JPY","channel":"board_ws","transport":"websocket","source_event_id":null,"source_sequence":null,"sequence_id":95,"exchange_ts":null,"collector_ts":"2026-03-15T00:08:08Z","ingest_ts":"2026-03-15T00:08:08Z","event_ts":"2026-03-15T00:08:08Z","quality_flags":[],"is_partial":false,"is_reconstructed":false,"confidence_score":1.0,"payload":{"provider":"bitflyer_ws_board","exchange":"bitflyer","transport":"websocket","channel":"lightning_board_BTC_JPY","received_ts":"2026-03-15T00:08:08.907835Z","subscription_id":null,"message_id":null,"source_sequence":null,"raw_message_meta":{"raw_channel":"lightning_board_BTC_JPY","subscription_channel":"lightning_board_BTC_JPY","recv_timeout_sec":10,"ssl_verify":false,"socket_url":"wss://ws.lightstream.bitflyer.com/json-rpc"},"source_payload":{"mid_price":11377626.0,"bids":[{"price":11371033.0,"size":0.0},{"price":11373074.0,"size":0.0},{"price":11372614.0,"size":0.0}],"asks":[]}}}
{"schema_version":"collector.vnext.raw","schema_contract":null,"schema_contract_version":null,"payload_contract_version":null,"record_type":"market.orderbook.diff","record_id":"collector_main-market-orderbook-diff-000000000097","collector_id":"collector_main","collector_role":"production","host_name":"MAIN-PC","session_id":"collector_main-sess-20260315T000735Z-a5915a6a","stream_session_id":"collector_main-stream-bitflyer-board_ws-20260315T000806Z-40ac6a26","exchange":"bitflyer","market":"spot","symbol":"BTC_JPY","instrument_id":"bitflyer.spot.BTC_JPY","channel":"board_ws","transport":"websocket","source_event_id":null,"source_sequence":null,"sequence_id":97,"exchange_ts":null,"collector_ts":"2026-03-15T00:08:09Z","ingest_ts":"2026-03-15T00:08:09Z","event_ts":"2026-03-15T00:08:09Z","quality_flags":[],"is_partial":false,"is_reconstructed":false,"confidence_score":1.0,"payload":{"provider":"bitflyer_ws_board","exchange":"bitflyer","transport":"websocket","channel":"lightning_board_BTC_JPY","received_ts":"2026-03-15T00:08:09.079815Z","subscription_id":null,"message_id":null,"source_sequence":null,"raw_message_meta":{"raw_channel":"lightning_board_BTC_JPY","subscription_channel":"lightning_board_BTC_JPY","recv_timeout_sec":10,"ssl_verify":false,"socket_url":"wss://ws.lightstream.bitflyer.com/json-rpc"},"source_payload":{"mid_price":11377626.0,"bids":[],"asks":[{"price":11446508.0,"size":0.001}]}}}
{"schema_version":"collector.vnext.raw","schema_contract":null,"schema_contract_version":null,"payload_contract_version":null,"record_type":"market.orderbook.diff","record_id":"collector_main-market-orderbook-diff-000000000099","collector_id":"collector_main","collector_role":"production","host_name":"MAIN-PC","session_id":"collector_main-sess-20260315T000735Z-a5915a6a","stream_session_id":"collector_main-stream-bitflyer-board_ws-20260315T000806Z-40ac6a26","exchange":"bitflyer","market":"spot","symbol":"BTC_JPY","instrument_id":"bitflyer.spot.BTC_JPY","channel":"board_ws","transport":"websocket","source_event_id":null,"source_sequence":null,"sequence_id":99,"exchange_ts":null,"collector_ts":"2026-03-15T00:08:09Z","ingest_ts":"2026-03-15T00:08:09Z","event_ts":"2026-03-15T00:08:09Z","quality_flags":[],"is_partial":false,"is_reconstructed":false,"confidence_score":1.0,"payload":{"provider":"bitflyer_ws_board","exchange":"bitflyer","transport":"websocket","channel":"lightning_board_BTC_JPY","received_ts":"2026-03-15T00:08:09.187814Z","subscription_id":null,"message_id":null,"source_sequence":null,"raw_message_meta":{"raw_channel":"lightning_board_BTC_JPY","subscription_channel":"lightning_board_BTC_JPY","recv_timeout_sec":10,"ssl_verify":false,"socket_url":"wss://ws.lightstream.bitflyer.com/json-rpc"},"source_payload":{"mid_price":11377610.0,"bids":[{"price":11371938.0,"size":0.01},{"price":11372615.0,"size":0.0},{"price":11365810.0,"size":0.11},{"price":11373074.0,"size":0.1275},{"price":11366948.0,"size":0.1}],"asks":[{"price":11380102.0,"size":0.0154534}]}}}
{"schema_version":"collector.vnext.raw","schema_contract":null,"schema_contract_version":null,"payload_contract_version":null,"record_type":"market.orderbook.diff","record_id":"collector_main-market-orderbook-diff-000000000101","collector_id":"collector_main","collector_role":"production","host_name":"MAIN-PC","session_id":"collector_main-sess-20260315T000735Z-a5915a6a","stream_session_id":"collector_main-stream-bitflyer-board_ws-20260315T000806Z-40ac6a26","exchange":"bitflyer","market":"spot","symbol":"BTC_JPY","instrument_id":"bitflyer.spot.BTC_JPY","channel":"board_ws","transport":"websocket","source_event_id":null,"source_sequence":null,"sequence_id":101,"exchange_ts":null,"collector_ts":"2026-03-15T00:08:09Z","ingest_ts":"2026-03-15T00:08:09Z","event_ts":"2026-03-15T00:08:09Z","quality_flags":[],"is_partial":false,"is_reconstructed":false,"confidence_score":1.0,"payload":{"provider":"bitflyer_ws_board","exchange":"bitflyer","transport":"websocket","channel":"lightning_board_BTC_JPY","received_ts":"2026-03-15T00:08:09.361219Z","subscription_id":null,"message_id":null,"source_sequence":null,"raw_message_meta":{"raw_channel":"lightning_board_BTC_JPY","subscription_channel":"lightning_board_BTC_JPY","recv_timeout_sec":10,"ssl_verify":false,"socket_url":"wss://ws.lightstream.bitflyer.com/json-rpc"},"source_payload":{"mid_price":11377610.0,"bids":[{"price":11372616.0,"size":0.02},{"price":11373084.0,"size":0.015252}],"asks":[{"price":11380135.0,"size":0.0},{"price":11380614.0,"size":0.0}]}}}
{"schema_version":"collector.vnext.raw","schema_contract":null,"schema_contract_version":null,"payload_contract_version":null,"record_type":"market.orderbook.diff","record_id":"collector_main-market-orderbook-diff-000000000103","collector_id":"collector_main","collector_role":"production","host_name":"MAIN-PC","session_id":"collector_main-sess-20260315T000735Z-a5915a6a","stream_session_id":"collector_main-stream-bitflyer-board_ws-20260315T000806Z-40ac6a26","exchange":"bitflyer","market":"spot","symbol":"BTC_JPY","instrument_id":"bitflyer.spot.BTC_JPY","channel":"board_ws","transport":"websocket","source_event_id":null,"source_sequence":null,"sequence_id":103,"exchange_ts":null,"collector_ts":"2026-03-15T00:08:09Z","ingest_ts":"2026-03-15T00:08:09Z","event_ts":"2026-03-15T00:08:09Z","quality_flags":[],"is_partial":false,"is_reconstructed":false,"confidence_score":1.0,"payload":{"provider":"bitflyer_ws_board","exchange":"bitflyer","transport":"websocket","channel":"lightning_board_BTC_JPY","received_ts":"2026-03-15T00:08:09.476633Z","subscription_id":null,"message_id":null,"source_sequence":null,"raw_message_meta":{"raw_channel":"lightning_board_BTC_JPY","subscription_channel":"lightning_board_BTC_JPY","recv_timeout_sec":10,"ssl_verify":false,"socket_url":"wss://ws.lightstream.bitflyer.com/json-rpc"},"source_payload":{"mid_price":11377609.0,"bids":[{"price":11373627.0,"size":0.1275},{"price":11373109.0,"size":0.0109204}],"asks":[{"price":11383315.0,"size":0.01},{"price":11380134.0,"size":0.0},{"price":11380101.0,"size":0.04446609},{"price":11380137.0,"size":0.022}]}}}
{"schema_version":"collector.vnext.raw","schema_contract":null,"schema_contract_version":null,"payload_contract_version":null,"record_type":"market.orderbook.diff","record_id":"collector_main-market-orderbook-diff-000000000105","collector_id":"collector_main","collector_role":"production","host_name":"MAIN-PC","session_id":"collector_main-sess-20260315T000735Z-a5915a6a","stream_session_id":"collector_main-stream-bitflyer-board_ws-20260315T000806Z-40ac6a26","exchange":"bitflyer","market":"spot","symbol":"BTC_JPY","instrument_id":"bitflyer.spot.BTC_JPY","channel":"board_ws","transport":"websocket","source_event_id":null,"source_sequence":null,"sequence_id":105,"exchange_ts":null,"collector_ts":"2026-03-15T00:08:09Z","ingest_ts":"2026-03-15T00:08:09Z","event_ts":"2026-03-15T00:08:09Z","quality_flags":[],"is_partial":false,"is_reconstructed":false,"confidence_score":1.0,"payload":{"provider":"bitflyer_ws_board","exchange":"bitflyer","transport":"websocket","channel":"lightning_board_BTC_JPY","received_ts":"2026-03-15T00:08:09.578274Z","subscription_id":null,"message_id":null,"source_sequence":null,"raw_message_meta":{"raw_channel":"lightning_board_BTC_JPY","subscription_channel":"lightning_board_BTC_JPY","recv_timeout_sec":10,"ssl_verify":false,"socket_url":"wss://ws.lightstream.bitflyer.com/json-rpc"},"source_payload":{"mid_price":11377609.0,"bids":[{"price":11370232.0,"size":0.0}],"asks":[{"price":11380102.0,"size":0.0733534}]}}}
{"schema_version":"collector.vnext.raw","schema_contract":null,"schema_contract_version":null,"payload_contract_version":null,"record_type":"market.orderbook.diff","record_id":"collector_main-market-orderbook-diff-000000000107","collector_id":"collector_main","collector_role":"production","host_name":"MAIN-PC","session_id":"collector_main-sess-20260315T000735Z-a5915a6a","stream_session_id":"collector_main-stream-bitflyer-board_ws-20260315T000806Z-40ac6a26","exchange":"bitflyer","market":"spot","symbol":"BTC_JPY","instrument_id":"bitflyer.spot.BTC_JPY","channel":"board_ws","transport":"websocket","source_event_id":null,"source_sequence":null,"sequence_id":107,"exchange_ts":null,"collector_ts":"2026-03-15T00:08:09Z","ingest_ts":"2026-03-15T00:08:09Z","event_ts":"2026-03-15T00:08:09Z","quality_flags":[],"is_partial":false,"is_reconstructed":false,"confidence_score":1.0,"payload":{"provider":"bitflyer_ws_board","exchange":"bitflyer","transport":"websocket","channel":"lightning_board_BTC_JPY","received_ts":"2026-03-15T00:08:09.672984Z","subscription_id":null,"message_id":null,"source_sequence":null,"raw_message_meta":{"raw_channel":"lightning_board_BTC_JPY","subscription_channel":"lightning_board_BTC_JPY","recv_timeout_sec":10,"ssl_verify":false,"socket_url":"wss://ws.lightstream.bitflyer.com/json-rpc"},"source_payload":{"mid_price":11377609.0,"bids":[{"price":11372616.0,"size":0.0},{"price":11373085.0,"size":0.02},{"price":11373627.0,"size":0.0}],"asks":[]}}}
{"schema_version":"collector.vnext.raw","schema_contract":null,"schema_contract_version":null,"payload_contract_version":null,"record_type":"market.orderbook.diff","record_id":"collector_main-market-orderbook-diff-000000000109","collector_id":"collector_main","collector_role":"production","host_name":"MAIN-PC","session_id":"collector_main-sess-20260315T000735Z-a5915a6a","stream_session_id":"collector_main-stream-bitflyer-board_ws-20260315T000806Z-40ac6a26","exchange":"bitflyer","market":"spot","symbol":"BTC_JPY","instrument_id":"bitflyer.spot.BTC_JPY","channel":"board_ws","transport":"websocket","source_event_id":null,"source_sequence":null,"sequence_id":109,"exchange_ts":null,"collector_ts":"2026-03-15T00:08:09Z","ingest_ts":"2026-03-15T00:08:09Z","event_ts":"2026-03-15T00:08:09Z","quality_flags":[],"is_partial":false,"is_reconstructed":false,"confidence_score":1.0,"payload":{"provider":"bitflyer_ws_board","exchange":"bitflyer","transport":"websocket","channel":"lightning_board_BTC_JPY","received_ts":"2026-03-15T00:08:09.782477Z","subscription_id":null,"message_id":null,"source_sequence":null,"raw_message_meta":{"raw_channel":"lightning_board_BTC_JPY","subscription_channel":"lightning_board_BTC_JPY","recv_timeout_sec":10,"ssl_verify":false,"socket_url":"wss://ws.lightstream.bitflyer.com/json-rpc"},"source_payload":{"mid_price":11377609.0,"bids":[{"price":11371587.0,"size":0.0},{"price":11373628.0,"size":0.02},{"price":11371791.0,"size":0.0}],"asks":[]}}}
{"schema_version":"collector.vnext.raw","schema_contract":null,"schema_contract_version":null,"payload_contract_version":null,"record_type":"market.orderbook.diff","record_id":"collector_main-market-orderbook-diff-000000000111","collector_id":"collector_main","collector_role":"production","host_name":"MAIN-PC","session_id":"collector_main-sess-20260315T000735Z-a5915a6a","stream_session_id":"collector_main-stream-bitflyer-board_ws-20260315T000806Z-40ac6a26","exchange":"bitflyer","market":"spot","symbol":"BTC_JPY","instrument_id":"bitflyer.spot.BTC_JPY","channel":"board_ws","transport":"websocket","source_event_id":null,"source_sequence":null,"sequence_id":111,"exchange_ts":null,"collector_ts":"2026-03-15T00:08:09Z","ingest_ts":"2026-03-15T00:08:09Z","event_ts":"2026-03-15T00:08:09Z","quality_flags":[],"is_partial":false,"is_reconstructed":false,"confidence_score":1.0,"payload":{"provider":"bitflyer_ws_board","exchange":"bitflyer","transport":"websocket","channel":"lightning_board_BTC_JPY","received_ts":"2026-03-15T00:08:09.923562Z","subscription_id":null,"message_id":null,"source_sequence":null,"raw_message_meta":{"raw_channel":"lightning_board_BTC_JPY","subscription_channel":"lightning_board_BTC_JPY","recv_timeout_sec":10,"ssl_verify":false,"socket_url":"wss://ws.lightstream.bitflyer.com/json-rpc"},"source_payload":{"mid_price":11377609.0,"bids":[{"price":11371939.0,"size":0.02}],"asks":[]}}}
{"schema_version":"collector.vnext.raw","schema_contract":null,"schema_contract_version":null,"payload_contract_version":null,"record_type":"market.orderbook.diff","record_id":"collector_main-market-orderbook-diff-000000000113","collector_id":"collector_main","collector_role":"production","host_name":"MAIN-PC","session_id":"collector_main-sess-20260315T000735Z-a5915a6a","stream_session_id":"collector_main-stream-bitflyer-board_ws-20260315T000806Z-40ac6a26","exchange":"bitflyer","market":"spot","symbol":"BTC_JPY","instrument_id":"bitflyer.spot.BTC_JPY","channel":"board_ws","transport":"websocket","source_event_id":null,"source_sequence":null,"sequence_id":113,"exchange_ts":null,"collector_ts":"2026-03-15T00:08:10Z","ingest_ts":"2026-03-15T00:08:10Z","event_ts":"2026-03-15T00:08:10Z","quality_flags":[],"is_partial":false,"is_reconstructed":false,"confidence_score":1.0,"payload":{"provider":"bitflyer_ws_board","exchange":"bitflyer","transport":"websocket","channel":"lightning_board_BTC_JPY","received_ts":"2026-03-15T00:08:10.037240Z","subscription_id":null,"message_id":null,"source_sequence":null,"raw_message_meta":{"raw_channel":"lightning_board_BTC_JPY","subscription_channel":"lightning_board_BTC_JPY","recv_timeout_sec":10,"ssl_verify":false,"socket_url":"wss://ws.lightstream.bitflyer.com/json-rpc"},"source_payload":{"mid_price":11377610.0,"bids":[{"price":11373627.0,"size":0.1275}],"asks":[{"price":11380102.0,"size":0.0579},{"price":11380101.0,"size":0.0}]}}}
{"schema_version":"collector.vnext.raw","schema_contract":null,"schema_contract_version":null,"payload_contract_version":null,"record_type":"market.orderbook.diff","record_id":"collector_main-market-orderbook-diff-000000000115","collector_id":"collector_main","collector_role":"production","host_name":"MAIN-PC","session_id":"collector_main-sess-20260315T000735Z-a5915a6a","stream_session_id":"collector_main-stream-bitflyer-board_ws-20260315T000806Z-40ac6a26","exchange":"bitflyer","market":"spot","symbol":"BTC_JPY","instrument_id":"bitflyer.spot.BTC_JPY","channel":"board_ws","transport":"websocket","source_event_id":null,"source_sequence":null,"sequence_id":115,"exchange_ts":null,"collector_ts":"2026-03-15T00:08:10Z","ingest_ts":"2026-03-15T00:08:10Z","event_ts":"2026-03-15T00:08:10Z","quality_flags":[],"is_partial":false,"is_reconstructed":false,"confidence_score":1.0,"payload":{"provider":"bitflyer_ws_board","exchange":"bitflyer","transport":"websocket","channel":"lightning_board_BTC_JPY","received_ts":"2026-03-15T00:08:10.142879Z","subscription_id":null,"message_id":null,"source_sequence":null,"raw_message_meta":{"raw_channel":"lightning_board_BTC_JPY","subscription_channel":"lightning_board_BTC_JPY","recv_timeout_sec":10,"ssl_verify":false,"socket_url":"wss://ws.lightstream.bitflyer.com/json-rpc"},"source_payload":{"mid_price":11377610.0,"bids":[{"price":11373628.0,"size":0.0},{"price":11365810.0,"size":0.0}],"asks":[{"price":11380822.0,"size":0.04462587}]}}}
{"schema_version":"collector.vnext.raw","schema_contract":null,"schema_contract_version":null,"payload_contract_version":null,"record_type":"market.orderbook.diff","record_id":"collector_main-market-orderbook-diff-000000000117","collector_id":"collector_main","collector_role":"production","host_name":"MAIN-PC","session_id":"collector_main-sess-20260315T000735Z-a5915a6a","stream_session_id":"collector_main-stream-bitflyer-board_ws-20260315T000806Z-40ac6a26","exchange":"bitflyer","market":"spot","symbol":"BTC_JPY","instrument_id":"bitflyer.spot.BTC_JPY","channel":"board_ws","transport":"websocket","source_event_id":null,"source_sequence":null,"sequence_id":117,"exchange_ts":null,"collector_ts":"2026-03-15T00:08:10Z","ingest_ts":"2026-03-15T00:08:10Z","event_ts":"2026-03-15T00:08:10Z","quality_flags":[],"is_partial":false,"is_reconstructed":false,"confidence_score":1.0,"payload":{"provider":"bitflyer_ws_board","exchange":"bitflyer","transport":"websocket","channel":"lightning_board_BTC_JPY","received_ts":"2026-03-15T00:08:10.286176Z","subscription_id":null,"message_id":null,"source_sequence":null,"raw_message_meta":{"raw_channel":"lightning_board_BTC_JPY","subscription_channel":"lightning_board_BTC_JPY","recv_timeout_sec":10,"ssl_verify":false,"socket_url":"wss://ws.lightstream.bitflyer.com/json-rpc"},"source_payload":{"mid_price":11377610.0,"bids":[{"price":11373627.0,"size":0.0},{"price":11373109.0,"size":0.0},{"price":11373074.0,"size":0.0},{"price":11366948.0,"size":0.0}],"asks":[]}}}
{"schema_version":"collector.vnext.raw","schema_contract":null,"schema_contract_version":null,"payload_contract_version":null,"record_type":"market.orderbook.diff","record_id":"collector_main-market-orderbook-diff-000000000119","collector_id":"collector_main","collector_role":"production","host_name":"MAIN-PC","session_id":"collector_main-sess-20260315T000735Z-a5915a6a","stream_session_id":"collector_main-stream-bitflyer-board_ws-20260315T000806Z-40ac6a26","exchange":"bitflyer","market":"spot","symbol":"BTC_JPY","instrument_id":"bitflyer.spot.BTC_JPY","channel":"board_ws","transport":"websocket","source_event_id":null,"source_sequence":null,"sequence_id":119,"exchange_ts":null,"collector_ts":"2026-03-15T00:08:10Z","ingest_ts":"2026-03-15T00:08:10Z","event_ts":"2026-03-15T00:08:10Z","quality_flags":[],"is_partial":false,"is_reconstructed":false,"confidence_score":1.0,"payload":{"provider":"bitflyer_ws_board","exchange":"bitflyer","transport":"websocket","channel":"lightning_board_BTC_JPY","received_ts":"2026-03-15T00:08:10.389568Z","subscription_id":null,"message_id":null,"source_sequence":null,"raw_message_meta":{"raw_channel":"lightning_board_BTC_JPY","subscription_channel":"lightning_board_BTC_JPY","recv_timeout_sec":10,"ssl_verify":false,"socket_url":"wss://ws.lightstream.bitflyer.com/json-rpc"},"source_payload":{"mid_price":11377610.0,"bids":[{"price":11373075.0,"size":0.02}],"asks":[{"price":11380602.0,"size":0.0},{"price":11451105.0,"size":0.002}]}}}
{"schema_version":"collector.vnext.raw","schema_contract":null,"schema_contract_version":null,"payload_contract_version":null,"record_type":"market.orderbook.diff","record_id":"collector_main-market-orderbook-diff-000000000121","collector_id":"collector_main","collector_role":"production","host_name":"MAIN-PC","session_id":"collector_main-sess-20260315T000735Z-a5915a6a","stream_session_id":"collector_main-stream-bitflyer-board_ws-20260315T000806Z-40ac6a26","exchange":"bitflyer","market":"spot","symbol":"BTC_JPY","instrument_id":"bitflyer.spot.BTC_JPY","channel":"board_ws","transport":"websocket","source_event_id":null,"source_sequence":null,"sequence_id":121,"exchange_ts":null,"collector_ts":"2026-03-15T00:08:10Z","ingest_ts":"2026-03-15T00:08:10Z","event_ts":"2026-03-15T00:08:10Z","quality_flags":[],"is_partial":false,"is_reconstructed":false,"confidence_score":1.0,"payload":{"provider":"bitflyer_ws_board","exchange":"bitflyer","transport":"websocket","channel":"lightning_board_BTC_JPY","received_ts":"2026-03-15T00:08:10.497726Z","subscription_id":null,"message_id":null,"source_sequence":null,"raw_message_meta":{"raw_channel":"lightning_board_BTC_JPY","subscription_channel":"lightning_board_BTC_JPY","recv_timeout_sec":10,"ssl_verify":false,"socket_url":"wss://ws.lightstream.bitflyer.com/json-rpc"},"source_payload":{"mid_price":11377610.0,"bids":[],"asks":[{"price":11380787.0,"size":0.0154534}]}}}
{"schema_version":"collector.vnext.raw","schema_contract":null,"schema_contract_version":null,"payload_contract_version":null,"record_type":"market.orderbook.diff","record_id":"collector_main-market-orderbook-diff-000000000123","collector_id":"collector_main","collector_role":"production","host_name":"MAIN-PC","session_id":"collector_main-sess-20260315T000735Z-a5915a6a","stream_session_id":"collector_main-stream-bitflyer-board_ws-20260315T000806Z-40ac6a26","exchange":"bitflyer","market":"spot","symbol":"BTC_JPY","instrument_id":"bitflyer.spot.BTC_JPY","channel":"board_ws","transport":"websocket","source_event_id":null,"source_sequence":null,"sequence_id":123,"exchange_ts":null,"collector_ts":"2026-03-15T00:08:10Z","ingest_ts":"2026-03-15T00:08:10Z","event_ts":"2026-03-15T00:08:10Z","quality_flags":[],"is_partial":false,"is_reconstructed":false,"confidence_score":1.0,"payload":{"provider":"bitflyer_ws_board","exchange":"bitflyer","transport":"websocket","channel":"lightning_board_BTC_JPY","received_ts":"2026-03-15T00:08:10.599228Z","subscription_id":null,"message_id":null,"source_sequence":null,"raw_message_meta":{"raw_channel":"lightning_board_BTC_JPY","subscription_channel":"lightning_board_BTC_JPY","recv_timeout_sec":10,"ssl_verify":false,"socket_url":"wss://ws.lightstream.bitflyer.com/json-rpc"},"source_payload":{"mid_price":11377610.0,"bids":[{"price":11373627.0,"size":0.1275},{"price":11373075.0,"size":0.0},{"price":11360106.0,"size":0.31},{"price":11364672.0,"size":0.13}],"asks":[{"price":11390710.0,"size":0.0},{"price":11392007.0,"size":0.2}]}}}
{"schema_version":"collector.vnext.raw","schema_contract":null,"schema_contract_version":null,"payload_contract_version":null,"record_type":"market.orderbook.diff","record_id":"collector_main-market-orderbook-diff-000000000125","collector_id":"collector_main","collector_role":"production","host_name":"MAIN-PC","session_id":"collector_main-sess-20260315T000735Z-a5915a6a","stream_session_id":"collector_main-stream-bitflyer-board_ws-20260315T000806Z-40ac6a26","exchange":"bitflyer","market":"spot","symbol":"BTC_JPY","instrument_id":"bitflyer.spot.BTC_JPY","channel":"board_ws","transport":"websocket","source_event_id":null,"source_sequence":null,"sequence_id":125,"exchange_ts":null,"collector_ts":"2026-03-15T00:08:10Z","ingest_ts":"2026-03-15T00:08:10Z","event_ts":"2026-03-15T00:08:10Z","quality_flags":[],"is_partial":false,"is_reconstructed":false,"confidence_score":1.0,"payload":{"provider":"bitflyer_ws_board","exchange":"bitflyer","transport":"websocket","channel":"lightning_board_BTC_JPY","received_ts":"2026-03-15T00:08:10.735307Z","subscription_id":null,"message_id":null,"source_sequence":null,"raw_message_meta":{"raw_channel":"lightning_board_BTC_JPY","subscription_channel":"lightning_board_BTC_JPY","recv_timeout_sec":10,"ssl_verify":false,"socket_url":"wss://ws.lightstream.bitflyer.com/json-rpc"},"source_payload":{"mid_price":11377610.0,"bids":[{"price":11373110.0,"size":0.0109204},{"price":11366948.0,"size":0.08},{"price":11365810.0,"size":0.09},{"price":9170000.0,"size":0.007}],"asks":[{"price":11380822.0,"size":0.0},{"price":11380786.0,"size":0.0416161}]}}}
{"schema_version":"collector.vnext.raw","schema_contract":null,"schema_contract_version":null,"payload_contract_version":null,"record_type":"market.orderbook.snapshot","record_id":"collector_main-market-orderbook-snapshot-000000000127","collector_id":"collector_main","collector_role":"production","host_name":"MAIN-PC","session_id":"collector_main-sess-20260315T000735Z-a5915a6a","stream_session_id":"collector_main-stream-bitflyer-board_ws-20260315T000806Z-40ac6a26","exchange":"bitflyer","market":"spot","symbol":"BTC_JPY","instrument_id":"bitflyer.spot.BTC_JPY","channel":"board_ws","transport":"websocket","source_event_id":null,"source_sequence":null,"sequence_id":127,"exchange_ts":null,"collector_ts":"2026-03-15T00:08:10Z","ingest_ts":"2026-03-15T00:08:10Z","event_ts":"2026-03-15T00:08:10Z","quality_flags":[],"is_partial":false,"is_reconstructed":false,"confidence_score":1.0,"payload":{"provider":"bitflyer_ws_board_snapshot","exchange":"bitflyer","transport":"websocket","channel":"lightning_board_snapshot_BTC_JPY","received_ts":"2026-03-15T00:08:10.822660Z","subscription_id":null,"message_id":null,"source_sequence":null,"raw_message_meta":{"raw_channel":"lightning_board_snapshot_BTC_JPY","subscription_channel":"lightning_board_snapshot_BTC_JPY","recv_timeout_sec":10,"ssl_verify":false,"socket_url":"wss://ws.lightstream.bitflyer.com/json-rpc"},"source_payload":{"mid_price":11377610.0,"bids":[{"price":11375118.0,"size":0.03308965},{"price":11375117.0,"size":0.00999779},{"price":11374774.0,"size":0.001},{"price":11374196.0,"size":0.1275},{"price":11373110.0,"size":0.0109204},{"price":11373085.0,"size":0.02},{"price":11373084.0,"size":0.015252},{"price":11373076.0,"size":0.02},{"price":11372597.0,"size":0.02},{"price":11372596.0,"size":0.005},{"price":11372579.0,"size":0.02},{"price":11372578.0,"size":0.015024},{"price":11372162.0,"size":0.02},{"price":11372161.0,"size":0.01482},{"price":11371939.0,"size":0.02},{"price":11371938.0,"size":0.01},{"price":11371901.0,"size":0.02},{"price":11371900.0,"size":0.005},{"price":11371790.0,"size":0.014616},{"price":11370948.0,"size":0.05},{"price":11370152.0,"size":0.5},{"price":11370115.0,"size":0.266},{"price":11370000.0,"size":0.0185},{"price":11368376.0,"size":0.01},{"price":11368078.0,"size":0.0530496},{"price":11366948.0,"size":0.08},{"price":11366835.0,"size":3.1164105},{"price":11366369.0,"size":0.04},{"price":11366247.0,"size":0.036},{"price":11366008.0,"size":0.04},{"price":11365810.0,"size":0.09},{"price":11365378.0,"size":0.05},{"price":11365368.0,"size":0.0527},{"price":11364672.0,"size":0.13},{"price":11363762.0,"size":0.00999891},{"price":11362818.0,"size":0.33304501},{"price":11362817.0,"size":0.27},{"price":11362278.0,"size":0.31206306},{"price":11362277.0,"size":0.9772867},{"price":11361554.0,"size":0.6},{"price":11361538.0,"size":1.50015},{"price":11360106.0,"size":0.31},{"price":11358907.0,"size":1.484},{"price":11358376.0,"size":0.01},{"price":11352889.0,"size":0.2587},{"price":11350127.0,"size":0.3046},{"price":11350000.0,"size":0.51},{"price":11348189.0,"size":0.003},{"price":11347667.0,"size":0.001},{"price":11347365.0,"size":0.3041},{"price":11344604.0,"size":0.08046751},{"price":11344603.0,"size":0.2991},{"price":11341671.0,"size":0.23},{"price":11340532.0,"size":1.966},{"price":11340000.0,"size":0.005},{"price":11339141.0,"size":0.51},{"price":11336383.0,"size":0.001},{"price":11336319.0,"size":0.00195},{"price":11331000.0,"size":0.5},{"price":11330000.0,"size":0.02442},{"price":11329213.0,"size":2.036},{"price":11325101.0,"size":0.001},{"price":11320000.0,"size":0.05},{"price":11315000.0,"size":0.05},{"price":11313996.0,"size":0.00195},{"price":11313819.0,"size":0.001},{"price":11310000.0,"size":0.01},{"price":11309999.0,"size":0.177},{"price":11307999.0,"size":0.01},{"price":11305439.0,"size":1.951},{"price":11304836.0,"size":1.12},{"price":11303918.0,"size":0.01},{"price":11303000.0,"size":0.5},{"price":11302535.0,"size":0.001},{"price":11302466.0,"size":0.001},{"price":11301268.0,"size":0.01},{"price":11300000.0,"size":3.01685256},{"price":11298000.0,"size":0.01},{"price":11296865.0,"size":0.0015},{"price":11294756.0,"size":1.0},{"price":11291282.0,"size":0.001},{"price":11291268.0,"size":0.01},{"price":11291000.0,"size":0.5},{"price":11290000.0,"size":0.003},{"price":11281268.0,"size":0.01},{"price":11280000.0,"size":0.0163},{"price":11279960.0,"size":0.001},{"price":11279282.0,"size":0.0015},{"price":11278000.0,"size":0.0025},{"price":11275000.0,"size":0.001},{"price":11274588.0,"size":0.0047},{"price":11271268.0,"size":0.01},{"price":11271000.0,"size":0.003},{"price":11270000.0,"size":0.106},{"price":11269424.0,"size":0.8},{"price":11268871.0,"size":0.28},{"price":11268638.0,"size":0.001},{"price":11268411.0,"size":0.01},{"price":11266666.0,"size":0.04},{"price":11265000.0,"size":0.02},{"price":11263000.0,"size":0.006},{"price":11262564.0,"size":0.0015},{"price":11261268.0,"size":0.01},{"price":11260000.0,"size":0.3565},{"price":11257315.0,"size":0.001},{"price":11257000.0,"size":0.001},{"price":11255200.0,"size":0.001},{"price":11255115.0,"size":0.00377},{"price":11253814.0,"size":2.2},{"price":11253690.0,"size":0.01},{"price":11253000.0,"size":0.03189},{"price":11251405.0,"size":0.139},{"price":11251268.0,"size":0.01},{"price":11251111.0,"size":0.0015},{"price":11251000.0,"size":0.0131},{"price":11250250.0,"size":0.00105},{"price":11250200.0,"size":0.001},{"price":11250005.0,"size":0.001},{"price":11250001.0,"size":0.00104},{"price":11250000.0,"size":1.62712889},{"price":11245993.0,"size":0.001},{"price":11245141.0,"size":0.0031},{"price":11245000.0,"size":0.05},{"price":11244444.0,"size":0.04},{"price":11244243.0,"size":0.01},{"price":11240200.0,"size":0.001},{"price":11240000.0,"size":0.007304},{"price":11236190.0,"size":0.01},{"price":11235200.0,"size":0.001},{"price":11234670.0,"size":0.001},{"price":11234512.0,"size":0.0015},{"price":11232000.0,"size":0.089},{"price":11231243.0,"size":0.01},{"price":11231000.0,"size":0.105},{"price":11230200.0,"size":0.001},{"price":11230000.0,"size":0.0308},{"price":11226952.0,"size":0.972},{"price":11224500.0,"size":0.06},{"price":11223968.0,"size":0.001},{"price":11223348.0,"size":0.001},{"price":11223344.0,"size":0.01},{"price":11223000.0,"size":0.1},{"price":11222222.0,"size":0.093525},{"price":11221120.0,"size":0.001},{"price":11220200.0,"size":0.001},{"price":11220001.0,"size":0.004457},{"price":11220000.0,"size":0.321},{"price":11219000.0,"size":0.1},{"price":11217326.0,"size":0.02},{"price":11215200.0,"size":0.001},{"price":11213690.0,"size":0.01},{"price":11212764.0,"size":0.0015},{"price":11212025.0,"size":0.001},{"price":11211800.0,"size":0.001},{"price":11211111.0,"size":0.06},{"price":11210200.0,"size":0.001},{"price":11210000.0,"size":0.10622},{"price":11208032.0,"size":0.01},{"price":11206000.0,"size":0.09015},{"price":11205200.0,"size":0.001},{"price":11204578.0,"size":0.002},{"price":11201000.0,"size":0.01},{"price":11200800.0,"size":0.05},{"price":11200703.0,"size":0.001},{"price":11200425.0,"size":0.1},{"price":11200200.0,"size":0.001},{"price":11200198.0,"size":0.003},{"price":11200150.0,"size":0.002},{"price":11200002.0,"size":0.001},{"price":11200001.0,"size":0.01104},{"price":11200000.0,"size":1.15226728},{"price":11198508.0,"size":0.05},{"price":11198243.0,"size":0.01},{"price":11197134.0,"size":0.993},{"price":11197000.0,"size":0.0085},{"price":11194090.0,"size":0.03},{"price":11190770.0,"size":0.0309},{"price":11190000.0,"size":0.0010016},{"price":11189555.0,"size":0.5},{"price":11189381.0,"size":0.001},{"price":11188629.0,"size":0.01},{"price":11188382.0,"size":0.001},{"price":11185000.0,"size":0.0085},{"price":11180000.0,"size":0.225},{"price":11178058.0,"size":0.001},{"price":11170000.0,"size":0.001},{"price":11169662.0,"size":0.01},{"price":11169593.0,"size":0.001},{"price":11169243.0,"size":0.01},{"price":11166736.0,"size":0.001},{"price":11164029.0,"size":0.001},{"price":11160854.0,"size":0.1},{"price":11160000.0,"size":0.02376},{"price":11155413.0,"size":0.001},{"price":11155377.0,"size":0.00636009},{"price":11153999.0,"size":0.00101},{"price":11151000.0,"size":0.001},{"price":11150250.0,"size":0.00175},{"price":11150005.0,"size":0.001},{"price":11150001.0,"size":0.00104},{"price":11150000.0,"size":0.6533956},{"price":11148000.0,"size":0.08963},{"price":11147546.0,"size":0.02},{"price":11144091.0,"size":0.001},{"price":11144000.0,"size":0.0897},{"price":11143986.0,"size":0.02},{"price":11140139.0,"size":1.0},{"price":11140000.0,"size":0.2},{"price":11136243.0,"size":0.01},{"price":11135869.0,"size":0.1},{"price":11132768.0,"size":0.001},{"price":11130000.0,"size":0.116},{"price":11129979.0,"size":0.0053908},{"price":11124900.0,"size":0.00133},{"price":11121090.0,"size":0.1},{"price":11120000.0,"size":0.0033},{"price":11118078.0,"size":0.01},{"price":11111800.0,"size":0.001},{"price":11111111.0,"size":0.2919257},{"price":11111000.0,"size":0.003},{"price":11110594.0,"size":0.001},{"price":11110000.0,"size":0.021007},{"price":11109662.0,"size":0.01},{"price":11108008.0,"size":0.01},{"price":11102000.0,"size":0.5},{"price":11101297.0,"size":0.001},{"price":11100005.0,"size":0.001},{"price":11100001.0,"size":0.01104},{"price":11100000.0,"size":1.6532049},{"price":11099141.0,"size":0.01},{"price":11098833.0,"size":0.002},{"price":11096243.0,"size":0.01},{"price":11094090.0,"size":0.01},{"price":11088888.0,"size":0.001},{"price":11085245.0,"size":0.001},{"price":11080200.0,"size":0.001},{"price":11080000.0,"size":0.0223},{"price":11075100.0,"size":0.003},{"price":11070200.0,"size":0.001},{"price":11070000.0,"size":0.0902},{"price":11065200.0,"size":0.001},{"price":11064370.0,"size":0.00497091},{"price":11060200.0,"size":0.001},{"price":11060000.0,"size":0.145},{"price":11059689.0,"size":0.009},{"price":11056428.0,"size":0.002},{"price":11055500.0,"size":0.02},{"price":11055200.0,"size":0.001},{"price":11055100.0,"size":0.003},{"price":11050200.0,"size":0.001},{"price":11050005.0,"size":0.001},{"price":11050002.0,"size":0.001},{"price":11050001.0,"size":0.00104},{"price":11050000.0,"size":0.39576147},{"price":11048064.0,"size":2.0},{"price":11046420.0,"size":0.2},{"price":11044243.0,"size":0.01},{"price":11041380.0,"size":0.01},{"price":11040200.0,"size":0.001},{"price":11040000.0,"size":0.00777181},{"price":11035865.0,"size":0.1},{"price":11035200.0,"size":0.001},{"price":11035000.0,"size":0.0013},{"price":11030200.0,"size":0.001},{"price":11030000.0,"size":0.025},{"price":11025500.0,"size":0.009531},{"price":11025200.0,"size":0.001},{"price":11025000.0,"size":0.71497},{"price":11020772.0,"size":0.014},{"price":11020200.0,"size":0.002},{"price":11020000.0,"size":0.005},{"price":11015200.0,"size":0.001},{"price":11012000.0,"size":0.1},{"price":11011800.0,"size":0.001},{"price":11010200.0,"size":0.001},{"price":11010000.0,"size":0.347},{"price":11007277.0,"size":0.01},{"price":11005200.0,"size":0.001},{"price":11004890.0,"size":0.001535},{"price":11003000.0,"size":0.0155},{"price":11001000.0,"size":0.013},{"price":11000500.0,"size":0.05117658},{"price":11000200.0,"size":0.001},{"price":11000002.0,"size":0.004},{"price":11000001.0,"size":0.02604},{"price":11000000.0,"size":4.53923365},{"price":10999999.0,"size":0.003},{"price":10999000.0,"size":0.001},{"price":10996855.0,"size":0.0011},{"price":10995200.0,"size":0.001},{"price":10994499.0,"size":0.00169176},{"price":10990200.0,"size":0.001},{"price":10990000.0,"size":0.10219},{"price":10989001.0,"size":0.00197},{"price":10988999.0,"size":0.001},{"price":10988324.0,"size":0.002},{"price":10987654.0,"size":0.001},{"price":10985200.0,"size":0.001},{"price":10985150.0,"size":0.01},{"price":10980500.0,"size":0.005}],"asks":[{"price":11380102.0,"size":0.0579},{"price":11380137.0,"size":0.022},{"price":11380603.0,"size":0.014652},{"price":11380606.0,"size":0.01512},{"price":11380786.0,"size":0.0416161},{"price":11380787.0,"size":0.0154534},{"price":11380823.0,"size":0.005},{"price":11381350.0,"size":0.01000441},{"price":11381797.0,"size":0.2857},{"price":11382326.0,"size":0.0384},{"price":11382327.0,"size":0.05},{"price":11383315.0,"size":0.01},{"price":11384226.0,"size":0.0549504},{"price":11384559.0,"size":0.3129},{"price":11386539.0,"size":0.57257014},{"price":11386542.0,"size":0.234},{"price":11387321.0,"size":0.3125},{"price":11389573.0,"size":0.0044},{"price":11390083.0,"size":0.2626},{"price":11390433.0,"size":0.0526},{"price":11391432.0,"size":0.4249},{"price":11392007.0,"size":0.2},{"price":11392010.0,"size":0.00142446},{"price":11395000.0,"size":0.02},{"price":11395665.0,"size":0.05},{"price":11397000.0,"size":0.02},{"price":11398444.0,"size":0.001995},{"price":11398845.0,"size":0.001},{"price":11399673.0,"size":0.0015},{"price":11399700.0,"size":0.001},{"price":11399998.0,"size":0.33543393},{"price":11399999.0,"size":0.39725145},{"price":11400000.0,"size":1.04832841},{"price":11400402.0,"size":1.189881},{"price":11401107.0,"size":1.189881},{"price":11403472.0,"size":0.002},{"price":11405000.0,"size":0.1575},{"price":11408700.0,"size":0.001},{"price":11409412.0,"size":1.60199848},{"price":11409413.0,"size":0.29418471},{"price":11409415.0,"size":0.005},{"price":11409925.0,"size":0.22},{"price":11410000.0,"size":0.6285},{"price":11410168.0,"size":0.001},{"price":11410853.0,"size":0.002},{"price":11412000.0,"size":0.0878},{"price":11412889.0,"size":1.489},{"price":11415000.0,"size":0.1},{"price":11415141.0,"size":0.0041},{"price":11417481.0,"size":0.0015},{"price":11418700.0,"size":0.001},{"price":11419000.0,"size":0.01},{"price":11420000.0,"size":0.261},{"price":11420064.0,"size":1.928},{"price":11421268.0,"size":0.05},{"price":11421490.0,"size":0.001},{"price":11427001.0,"size":2.018},{"price":11428121.0,"size":0.002},{"price":11428700.0,"size":0.001},{"price":11429302.0,"size":0.01},{"price":11430000.0,"size":2.62388164},{"price":11432718.0,"size":0.002},{"price":11432813.0,"size":0.001},{"price":11433211.0,"size":0.03},{"price":11433333.0,"size":0.001},{"price":11437315.0,"size":0.002},{"price":11438525.0,"size":0.0011},{"price":11438700.0,"size":0.001},{"price":11439557.0,"size":0.001},{"price":11440000.0,"size":0.2538},{"price":11441911.0,"size":0.002},{"price":11444135.0,"size":0.001},{"price":11445000.0,"size":0.029},{"price":11445433.0,"size":0.0015},{"price":11446508.0,"size":0.001},{"price":11447000.0,"size":0.01},{"price":11448000.0,"size":0.0875},{"price":11448700.0,"size":0.001},{"price":11450000.0,"size":0.268},{"price":11451105.0,"size":0.002},{"price":11453321.0,"size":0.03},{"price":11455000.0,"size":0.001},{"price":11455457.0,"size":0.001},{"price":11458700.0,"size":0.001},{"price":11458988.0,"size":0.01},{"price":11460000.0,"size":0.06702},{"price":11463288.0,"size":0.01},{"price":11465382.0,"size":0.00195},{"price":11465421.0,"size":1.943},{"price":11466780.0,"size":0.001},{"price":11468700.0,"size":0.001},{"price":11470000.0,"size":0.06},{"price":11471000.0,"size":0.01},{"price":11475000.0,"size":0.0028},{"price":11476929.0,"size":1.0},{"price":11478102.0,"size":0.001},{"price":11478700.0,"size":0.001},{"price":11480000.0,"size":0.40191},{"price":11485000.0,"size":0.01},{"price":11485488.0,"size":2.0},{"price":11486555.0,"size":0.03},{"price":11487685.0,"size":0.01},{"price":11488000.0,"size":0.102},{"price":11488700.0,"size":0.001},{"price":11489425.0,"size":0.001},{"price":11490000.0,"size":0.05},{"price":11495488.0,"size":0.0015},{"price":11495850.0,"size":0.001},{"price":11498700.0,"size":0.001},{"price":11499000.0,"size":0.01},{"price":11500000.0,"size":0.77159519},{"price":11500078.0,"size":0.93},{"price":11500747.0,"size":0.001},{"price":11502800.0,"size":0.00132},{"price":11503108.0,"size":0.0198},{"price":11505000.0,"size":0.0028},{"price":11505001.0,"size":0.002},{"price":11505836.0,"size":0.001},{"price":11508431.0,"size":0.047},{"price":11508700.0,"size":0.001},{"price":11508888.0,"size":0.02},{"price":11510000.0,"size":0.1476},{"price":11512070.0,"size":0.001},{"price":11513633.0,"size":0.08},{"price":11514332.0,"size":0.02},{"price":11517236.0,"size":0.0015},{"price":11518700.0,"size":0.001},{"price":11519855.0,"size":0.01},{"price":11520000.0,"size":0.001},{"price":11522388.0,"size":0.972},{"price":11523211.0,"size":0.01},{"price":11524999.0,"size":0.001},{"price":11528700.0,"size":0.001},{"price":11529852.0,"size":0.01},{"price":11530000.0,"size":0.261},{"price":11534084.0,"size":0.001},{"price":11535321.0,"size":0.01},{"price":11538700.0,"size":0.001},{"price":11540000.0,"size":0.0048},{"price":11541011.0,"size":0.005},{"price":11541109.0,"size":0.01},{"price":11546541.0,"size":0.01},{"price":11548700.0,"size":0.001},{"price":11550000.0,"size":0.014},{"price":11551109.0,"size":0.01},{"price":11552111.0,"size":0.01},{"price":11553687.0,"size":0.1},{"price":11555115.0,"size":0.001},{"price":11556000.0,"size":0.1},{"price":11558700.0,"size":0.001},{"price":11559855.0,"size":0.01},{"price":11560831.0,"size":0.0198},{"price":11561109.0,"size":0.01},{"price":11562000.0,"size":0.087},{"price":11563750.0,"size":0.08739676},{"price":11566139.0,"size":0.0228},{"price":11566551.0,"size":0.01},{"price":11568700.0,"size":0.001},{"price":11571109.0,"size":0.01},{"price":11573211.0,"size":0.01},{"price":11578700.0,"size":0.001},{"price":11579851.0,"size":0.01},{"price":11580000.0,"size":0.7835},{"price":11581109.0,"size":0.01},{"price":11585000.0,"size":0.002},{"price":11586532.0,"size":0.01},{"price":11587498.0,"size":0.0198},{"price":11588700.0,"size":0.001},{"price":11588800.0,"size":0.02},{"price":11590000.0,"size":0.1},{"price":11590749.0,"size":0.002},{"price":11591109.0,"size":0.01},{"price":11593211.0,"size":0.01},{"price":11598111.0,"size":0.1474},{"price":11598555.0,"size":0.01},{"price":11598700.0,"size":0.001},{"price":11599999.0,"size":0.001},{"price":11600000.0,"size":3.655},{"price":11601109.0,"size":0.02},{"price":11603764.0,"size":0.9},{"price":11606655.0,"size":0.01},{"price":11610000.0,"size":0.302},{"price":11611109.0,"size":0.01},{"price":11613321.0,"size":0.01},{"price":11620000.0,"size":1.35441682},{"price":11621011.0,"size":0.01},{"price":11621109.0,"size":0.01},{"price":11623096.0,"size":0.008},{"price":11625703.0,"size":0.012},{"price":11629000.0,"size":0.1},{"price":11630000.0,"size":0.201},{"price":11631059.0,"size":0.01},{"price":11631479.0,"size":0.01},{"price":11631773.0,"size":0.00386871},{"price":11635950.0,"size":0.001},{"price":11638259.0,"size":0.001},{"price":11639700.0,"size":0.001},{"price":11640000.0,"size":1.0},{"price":11640820.0,"size":0.01},{"price":11649900.0,"size":0.02906},{"price":11649999.0,"size":0.001},{"price":11650000.0,"size":0.593},{"price":11651059.0,"size":0.01},{"price":11653658.0,"size":0.008},{"price":11654321.0,"size":0.001},{"price":11659700.0,"size":0.001},{"price":11661479.0,"size":0.01},{"price":11666000.0,"size":0.001},{"price":11666666.0,"size":0.013},{"price":11669700.0,"size":0.001},{"price":11671059.0,"size":0.01},{"price":11672562.0,"size":0.0198},{"price":11680000.0,"size":0.014},{"price":11685000.0,"size":0.003},{"price":11688000.0,"size":0.001},{"price":11689732.0,"size":0.01},{"price":11690330.0,"size":0.0198},{"price":11691059.0,"size":0.01},{"price":11692558.0,"size":0.01},{"price":11695019.0,"size":0.0064},{"price":11698800.0,"size":0.00131},{"price":11699000.0,"size":0.001},{"price":11699631.0,"size":0.001},{"price":11699998.0,"size":0.01},{"price":11699999.0,"size":0.001},{"price":11700000.0,"size":1.2573},{"price":11701059.0,"size":0.01},{"price":11720000.0,"size":0.1},{"price":11721059.0,"size":0.01},{"price":11725000.0,"size":0.005},{"price":11726791.0,"size":0.01},{"price":11727418.0,"size":1.8},{"price":11728195.0,"size":0.05},{"price":11730000.0,"size":1.9712},{"price":11740000.0,"size":0.101},{"price":11741059.0,"size":0.01},{"price":11748937.0,"size":0.001},{"price":11749999.0,"size":0.001},{"price":11750000.0,"size":0.89537866},{"price":11750050.0,"size":0.2},{"price":11751151.0,"size":0.01},{"price":11751406.0,"size":0.012},{"price":11755000.0,"size":0.001},{"price":11757860.0,"size":1.82},{"price":11759999.0,"size":0.001},{"price":11760000.0,"size":0.001},{"price":11761059.0,"size":0.02},{"price":11765432.0,"size":0.001},{"price":11768000.0,"size":0.01},{"price":11770000.0,"size":0.25464896},{"price":11771059.0,"size":0.01755555},{"price":11772000.0,"size":0.002},{"price":11775000.0,"size":0.11593},{"price":11775222.0,"size":0.001657},{"price":11775577.0,"size":0.00013523},{"price":11775800.0,"size":0.001},{"price":11775900.0,"size":0.2},{"price":11775989.0,"size":0.005},{"price":11777000.0,"size":0.5956},{"price":11777777.0,"size":0.0067},{"price":11778541.0,"size":0.001},{"price":11779807.0,"size":0.001},{"price":11780000.0,"size":0.74298},{"price":11780800.0,"size":0.1},{"price":11781059.0,"size":0.01},{"price":11781238.0,"size":0.008},{"price":11785000.0,"size":0.055},{"price":11785040.0,"size":0.01},{"price":11786000.0,"size":0.585},{"price":11788000.0,"size":0.001},{"price":11788888.0,"size":0.005},{"price":11789000.0,"size":0.2},{"price":11789732.0,"size":0.01},{"price":11791100.0,"size":0.1},{"price":11791151.0,"size":0.01},{"price":11795000.0,"size":0.021},{"price":11795040.0,"size":0.015},{"price":11796103.0,"size":0.01},{"price":11798800.0,"size":0.005},{"price":11798950.0,"size":0.001},{"price":11799000.0,"size":0.013},{"price":11799510.0,"size":0.001},{"price":11799639.0,"size":0.01},{"price":11799999.0,"size":0.00769493},{"price":11800000.0,"size":1.10095},{"price":11800050.0,"size":0.006},{"price":11801059.0,"size":0.01},{"price":11802200.0,"size":0.2},{"price":11802222.0,"size":0.001},{"price":11803080.0,"size":0.001},{"price":11804746.0,"size":0.001},{"price":11804977.0,"size":0.001},{"price":11807789.0,"size":0.001},{"price":11809946.0,"size":0.02},{"price":11810000.0,"size":0.01},{"price":11811063.0,"size":0.006},{"price":11811386.0,"size":0.001},{"price":11815000.0,"size":0.086},{"price":11820000.0,"size":0.0699},{"price":11820008.0,"size":1.0}]}}}
{"schema_version":"collector.vnext.raw","schema_contract":null,"schema_contract_version":null,"payload_contract_version":null,"record_type":"market.orderbook.diff","record_id":"collector_main-market-orderbook-diff-000000000061","collector_id":"collector_main","collector_role":"production","host_name":"MAIN-PC","session_id":"collector_main-sess-20260315T000825Z-e08d1610","stream_session_id":"collector_main-stream-bitflyer-board_ws-20260315T000832Z-8ed81adf","exchange":"bitflyer","market":"spot","symbol":"BTC_JPY","instrument_id":"bitflyer.spot.BTC_JPY","channel":"board_ws","transport":"websocket","source_event_id":null,"source_sequence":null,"sequence_id":61,"exchange_ts":null,"collector_ts":"2026-03-15T00:08:32Z","ingest_ts":"2026-03-15T00:08:32Z","event_ts":"2026-03-15T00:08:32Z","quality_flags":[],"is_partial":false,"is_reconstructed":false,"confidence_score":1.0,"payload":{"provider":"bitflyer_ws_board","exchange":"bitflyer","transport":"websocket","channel":"lightning_board_BTC_JPY","received_ts":"2026-03-15T00:08:32.309326Z","subscription_id":null,"message_id":null,"source_sequence":null,"raw_message_meta":{"raw_channel":"lightning_board_BTC_JPY","subscription_channel":"lightning_board_BTC_JPY","recv_timeout_sec":10,"ssl_verify":false,"socket_url":"wss://ws.lightstream.bitflyer.com/json-rpc"},"source_payload":{"mid_price":11375792.0,"bids":[{"price":11372757.0,"size":0.0},{"price":11372843.0,"size":0.0}],"asks":[]}}}
{"schema_version":"collector.vnext.raw","schema_contract":null,"schema_contract_version":null,"payload_contract_version":null,"record_type":"market.orderbook.diff","record_id":"collector_main-market-orderbook-diff-000000000065","collector_id":"collector_main","collector_role":"production","host_name":"MAIN-PC","session_id":"collector_main-sess-20260315T000825Z-e08d1610","stream_session_id":"collector_main-stream-bitflyer-board_ws-20260315T000832Z-8ed81adf","exchange":"bitflyer","market":"spot","symbol":"BTC_JPY","instrument_id":"bitflyer.spot.BTC_JPY","channel":"board_ws","transport":"websocket","source_event_id":null,"source_sequence":null,"sequence_id":65,"exchange_ts":null,"collector_ts":"2026-03-15T00:08:32Z","ingest_ts":"2026-03-15T00:08:32Z","event_ts":"2026-03-15T00:08:32Z","quality_flags":[],"is_partial":false,"is_reconstructed":false,"confidence_score":1.0,"payload":{"provider":"bitflyer_ws_board","exchange":"bitflyer","transport":"websocket","channel":"lightning_board_BTC_JPY","received_ts":"2026-03-15T00:08:32.409120Z","subscription_id":null,"message_id":null,"source_sequence":null,"raw_message_meta":{"raw_channel":"lightning_board_BTC_JPY","subscription_channel":"lightning_board_BTC_JPY","recv_timeout_sec":10,"ssl_verify":false,"socket_url":"wss://ws.lightstream.bitflyer.com/json-rpc"},"source_payload":{"mid_price":11375792.0,"bids":[{"price":11367031.0,"size":0.0}],"asks":[{"price":11378706.0,"size":0.0675}]}}}
{"schema_version":"collector.vnext.raw","schema_contract":null,"schema_contract_version":null,"payload_contract_version":null,"record_type":"market.orderbook.diff","record_id":"collector_main-market-orderbook-diff-000000000067","collector_id":"collector_main","collector_role":"production","host_name":"MAIN-PC","session_id":"collector_main-sess-20260315T000825Z-e08d1610","stream_session_id":"collector_main-stream-bitflyer-board_ws-20260315T000832Z-8ed81adf","exchange":"bitflyer","market":"spot","symbol":"BTC_JPY","instrument_id":"bitflyer.spot.BTC_JPY","channel":"board_ws","transport":"websocket","source_event_id":null,"source_sequence":null,"sequence_id":67,"exchange_ts":null,"collector_ts":"2026-03-15T00:08:32Z","ingest_ts":"2026-03-15T00:08:32Z","event_ts":"2026-03-15T00:08:32Z","quality_flags":[],"is_partial":false,"is_reconstructed":false,"confidence_score":1.0,"payload":{"provider":"bitflyer_ws_board","exchange":"bitflyer","transport":"websocket","channel":"lightning_board_BTC_JPY","received_ts":"2026-03-15T00:08:32.500814Z","subscription_id":null,"message_id":null,"source_sequence":null,"raw_message_meta":{"raw_channel":"lightning_board_BTC_JPY","subscription_channel":"lightning_board_BTC_JPY","recv_timeout_sec":10,"ssl_verify":false,"socket_url":"wss://ws.lightstream.bitflyer.com/json-rpc"},"source_payload":{"mid_price":11375792.0,"bids":[{"price":11372879.0,"size":0.0}],"asks":[]}}}
{"schema_version":"collector.vnext.raw","schema_contract":null,"schema_contract_version":null,"payload_contract_version":null,"record_type":"market.orderbook.diff","record_id":"collector_main-market-orderbook-diff-000000000069","collector_id":"collector_main","collector_role":"production","host_name":"MAIN-PC","session_id":"collector_main-sess-20260315T000825Z-e08d1610","stream_session_id":"collector_main-stream-bitflyer-board_ws-20260315T000832Z-8ed81adf","exchange":"bitflyer","market":"spot","symbol":"BTC_JPY","instrument_id":"bitflyer.spot.BTC_JPY","channel":"board_ws","transport":"websocket","source_event_id":null,"source_sequence":null,"sequence_id":69,"exchange_ts":null,"collector_ts":"2026-03-15T00:08:32Z","ingest_ts":"2026-03-15T00:08:32Z","event_ts":"2026-03-15T00:08:32Z","quality_flags":[],"is_partial":false,"is_reconstructed":false,"confidence_score":1.0,"payload":{"provider":"bitflyer_ws_board","exchange":"bitflyer","transport":"websocket","channel":"lightning_board_BTC_JPY","received_ts":"2026-03-15T00:08:32.640987Z","subscription_id":null,"message_id":null,"source_sequence":null,"raw_message_meta":{"raw_channel":"lightning_board_BTC_JPY","subscription_channel":"lightning_board_BTC_JPY","recv_timeout_sec":10,"ssl_verify":false,"socket_url":"wss://ws.lightstream.bitflyer.com/json-rpc"},"source_payload":{"mid_price":11375792.0,"bids":[],"asks":[{"price":11390739.0,"size":0.0},{"price":11390740.0,"size":0.2}]}}}
{"schema_version":"collector.vnext.raw","schema_contract":null,"schema_contract_version":null,"payload_contract_version":null,"record_type":"market.orderbook.diff","record_id":"collector_main-market-orderbook-diff-000000000071","collector_id":"collector_main","collector_role":"production","host_name":"MAIN-PC","session_id":"collector_main-sess-20260315T000825Z-e08d1610","stream_session_id":"collector_main-stream-bitflyer-board_ws-20260315T000832Z-8ed81adf","exchange":"bitflyer","market":"spot","symbol":"BTC_JPY","instrument_id":"bitflyer.spot.BTC_JPY","channel":"board_ws","transport":"websocket","source_event_id":null,"source_sequence":null,"sequence_id":71,"exchange_ts":null,"collector_ts":"2026-03-15T00:08:32Z","ingest_ts":"2026-03-15T00:08:32Z","event_ts":"2026-03-15T00:08:32Z","quality_flags":[],"is_partial":false,"is_reconstructed":false,"confidence_score":1.0,"payload":{"provider":"bitflyer_ws_board","exchange":"bitflyer","transport":"websocket","channel":"lightning_board_BTC_JPY","received_ts":"2026-03-15T00:08:32.767780Z","subscription_id":null,"message_id":null,"source_sequence":null,"raw_message_meta":{"raw_channel":"lightning_board_BTC_JPY","subscription_channel":"lightning_board_BTC_JPY","recv_timeout_sec":10,"ssl_verify":false,"socket_url":"wss://ws.lightstream.bitflyer.com/json-rpc"},"source_payload":{"mid_price":11375692.0,"bids":[{"price":11367008.0,"size":0.0},{"price":11365893.0,"size":0.09},{"price":11372880.0,"size":0.0},{"price":11372680.0,"size":0.03405058},{"price":11352889.0,"size":0.0}],"asks":[]}}}
{"schema_version":"collector.vnext.raw","schema_contract":null,"schema_contract_version":null,"payload_contract_version":null,"record_type":"market.orderbook.diff","record_id":"collector_main-market-orderbook-diff-000000000073","collector_id":"collector_main","collector_role":"production","host_name":"MAIN-PC","session_id":"collector_main-sess-20260315T000825Z-e08d1610","stream_session_id":"collector_main-stream-bitflyer-board_ws-20260315T000832Z-8ed81adf","exchange":"bitflyer","market":"spot","symbol":"BTC_JPY","instrument_id":"bitflyer.spot.BTC_JPY","channel":"board_ws","transport":"websocket","source_event_id":null,"source_sequence":null,"sequence_id":73,"exchange_ts":null,"collector_ts":"2026-03-15T00:08:32Z","ingest_ts":"2026-03-15T00:08:32Z","event_ts":"2026-03-15T00:08:32Z","quality_flags":[],"is_partial":false,"is_reconstructed":false,"confidence_score":1.0,"payload":{"provider":"bitflyer_ws_board","exchange":"bitflyer","transport":"websocket","channel":"lightning_board_BTC_JPY","received_ts":"2026-03-15T00:08:32.876175Z","subscription_id":null,"message_id":null,"source_sequence":null,"raw_message_meta":{"raw_channel":"lightning_board_BTC_JPY","subscription_channel":"lightning_board_BTC_JPY","recv_timeout_sec":10,"ssl_verify":false,"socket_url":"wss://ws.lightstream.bitflyer.com/json-rpc"},"source_payload":{"mid_price":11375793.0,"bids":[{"price":11372680.0,"size":0.0},{"price":11372881.0,"size":0.03533616},{"price":11370105.0,"size":0.01}],"asks":[]}}}
{"schema_version":"collector.vnext.raw","schema_contract":null,"schema_contract_version":null,"payload_contract_version":null,"record_type":"market.orderbook.diff","record_id":"collector_main-market-orderbook-diff-000000000075","collector_id":"collector_main","collector_role":"production","host_name":"MAIN-PC","session_id":"collector_main-sess-20260315T000825Z-e08d1610","stream_session_id":"collector_main-stream-bitflyer-board_ws-20260315T000832Z-8ed81adf","exchange":"bitflyer","market":"spot","symbol":"BTC_JPY","instrument_id":"bitflyer.spot.BTC_JPY","channel":"board_ws","transport":"websocket","source_event_id":null,"source_sequence":null,"sequence_id":75,"exchange_ts":null,"collector_ts":"2026-03-15T00:08:33Z","ingest_ts":"2026-03-15T00:08:33Z","event_ts":"2026-03-15T00:08:33Z","quality_flags":[],"is_partial":false,"is_reconstructed":false,"confidence_score":1.0,"payload":{"provider":"bitflyer_ws_board","exchange":"bitflyer","transport":"websocket","channel":"lightning_board_BTC_JPY","received_ts":"2026-03-15T00:08:33.002761Z","subscription_id":null,"message_id":null,"source_sequence":null,"raw_message_meta":{"raw_channel":"lightning_board_BTC_JPY","subscription_channel":"lightning_board_BTC_JPY","recv_timeout_sec":10,"ssl_verify":false,"socket_url":"wss://ws.lightstream.bitflyer.com/json-rpc"},"source_payload":{"mid_price":11375692.0,"bids":[{"price":11330583.0,"size":0.002},{"price":11371418.0,"size":0.0109243},{"price":11372881.0,"size":0.0}],"asks":[]}}}
{"schema_version":"collector.vnext.raw","schema_contract":null,"schema_contract_version":null,"payload_contract_version":null,"record_type":"market.orderbook.diff","record_id":"collector_main-market-orderbook-diff-000000000077","collector_id":"collector_main","collector_role":"production","host_name":"MAIN-PC","session_id":"collector_main-sess-20260315T000825Z-e08d1610","stream_session_id":"collector_main-stream-bitflyer-board_ws-20260315T000832Z-8ed81adf","exchange":"bitflyer","market":"spot","symbol":"BTC_JPY","instrument_id":"bitflyer.spot.BTC_JPY","channel":"board_ws","transport":"websocket","source_event_id":null,"source_sequence":null,"sequence_id":77,"exchange_ts":null,"collector_ts":"2026-03-15T00:08:33Z","ingest_ts":"2026-03-15T00:08:33Z","event_ts":"2026-03-15T00:08:33Z","quality_flags":[],"is_partial":false,"is_reconstructed":false,"confidence_score":1.0,"payload":{"provider":"bitflyer_ws_board","exchange":"bitflyer","transport":"websocket","channel":"lightning_board_BTC_JPY","received_ts":"2026-03-15T00:08:33.109865Z","subscription_id":null,"message_id":null,"source_sequence":null,"raw_message_meta":{"raw_channel":"lightning_board_BTC_JPY","subscription_channel":"lightning_board_BTC_JPY","recv_timeout_sec":10,"ssl_verify":false,"socket_url":"wss://ws.lightstream.bitflyer.com/json-rpc"},"source_payload":{"mid_price":11375692.0,"bids":[{"price":11341841.0,"size":0.2599},{"price":11372680.0,"size":0.03332092}],"asks":[]}}}
{"schema_version":"collector.vnext.raw","schema_contract":null,"schema_contract_version":null,"payload_contract_version":null,"record_type":"market.orderbook.diff","record_id":"collector_main-market-orderbook-diff-000000000079","collector_id":"collector_main","collector_role":"production","host_name":"MAIN-PC","session_id":"collector_main-sess-20260315T000825Z-e08d1610","stream_session_id":"collector_main-stream-bitflyer-board_ws-20260315T000832Z-8ed81adf","exchange":"bitflyer","market":"spot","symbol":"BTC_JPY","instrument_id":"bitflyer.spot.BTC_JPY","channel":"board_ws","transport":"websocket","source_event_id":null,"source_sequence":null,"sequence_id":79,"exchange_ts":null,"collector_ts":"2026-03-15T00:08:33Z","ingest_ts":"2026-03-15T00:08:33Z","event_ts":"2026-03-15T00:08:33Z","quality_flags":[],"is_partial":false,"is_reconstructed":false,"confidence_score":1.0,"payload":{"provider":"bitflyer_ws_board","exchange":"bitflyer","transport":"websocket","channel":"lightning_board_BTC_JPY","received_ts":"2026-03-15T00:08:33.403663Z","subscription_id":null,"message_id":null,"source_sequence":null,"raw_message_meta":{"raw_channel":"lightning_board_BTC_JPY","subscription_channel":"lightning_board_BTC_JPY","recv_timeout_sec":10,"ssl_verify":false,"socket_url":"wss://ws.lightstream.bitflyer.com/json-rpc"},"source_payload":{"mid_price":11375608.0,"bids":[{"price":11366279.0,"size":0.045},{"price":11367031.0,"size":0.08},{"price":11371142.0,"size":0.1275}],"asks":[{"price":11544663.0,"size":0.002},{"price":11378537.0,"size":0.022}]}}}
{"schema_version":"collector.vnext.raw","schema_contract":null,"schema_contract_version":null,"payload_contract_version":null,"record_type":"market.orderbook.diff","record_id":"collector_main-market-orderbook-diff-000000000081","collector_id":"collector_main","collector_role":"production","host_name":"MAIN-PC","session_id":"collector_main-sess-20260315T000825Z-e08d1610","stream_session_id":"collector_main-stream-bitflyer-board_ws-20260315T000832Z-8ed81adf","exchange":"bitflyer","market":"spot","symbol":"BTC_JPY","instrument_id":"bitflyer.spot.BTC_JPY","channel":"board_ws","transport":"websocket","source_event_id":null,"source_sequence":null,"sequence_id":81,"exchange_ts":null,"collector_ts":"2026-03-15T00:08:33Z","ingest_ts":"2026-03-15T00:08:33Z","event_ts":"2026-03-15T00:08:33Z","quality_flags":[],"is_partial":false,"is_reconstructed":false,"confidence_score":1.0,"payload":{"provider":"bitflyer_ws_board","exchange":"bitflyer","transport":"websocket","channel":"lightning_board_BTC_JPY","received_ts":"2026-03-15T00:08:33.672174Z","subscription_id":null,"message_id":null,"source_sequence":null,"raw_message_meta":{"raw_channel":"lightning_board_BTC_JPY","subscription_channel":"lightning_board_BTC_JPY","recv_timeout_sec":10,"ssl_verify":false,"socket_url":"wss://ws.lightstream.bitflyer.com/json-rpc"},"source_payload":{"mid_price":11375650.0,"bids":[{"price":11370000.0,"size":0.01},{"price":11372764.0,"size":0.1275},{"price":11365893.0,"size":0.0}],"asks":[{"price":11378705.0,"size":0.005},{"price":11378536.0,"size":0.04293684},{"price":11378655.0,"size":0.014508},{"price":11378706.0,"size":0.0},{"price":11378537.0,"size":0.0747}]}}}
{"schema_version":"collector.vnext.raw","schema_contract":null,"schema_contract_version":null,"payload_contract_version":null,"record_type":"market.orderbook.diff","record_id":"collector_main-market-orderbook-diff-000000000083","collector_id":"collector_main","collector_role":"production","host_name":"MAIN-PC","session_id":"collector_main-sess-20260315T000825Z-e08d1610","stream_session_id":"collector_main-stream-bitflyer-board_ws-20260315T000832Z-8ed81adf","exchange":"bitflyer","market":"spot","symbol":"BTC_JPY","instrument_id":"bitflyer.spot.BTC_JPY","channel":"board_ws","transport":"websocket","source_event_id":null,"source_sequence":null,"sequence_id":83,"exchange_ts":null,"collector_ts":"2026-03-15T00:08:33Z","ingest_ts":"2026-03-15T00:08:33Z","event_ts":"2026-03-15T00:08:33Z","quality_flags":[],"is_partial":false,"is_reconstructed":false,"confidence_score":1.0,"payload":{"provider":"bitflyer_ws_board","exchange":"bitflyer","transport":"websocket","channel":"lightning_board_BTC_JPY","received_ts":"2026-03-15T00:08:33.790118Z","subscription_id":null,"message_id":null,"source_sequence":null,"raw_message_meta":{"raw_channel":"lightning_board_BTC_JPY","subscription_channel":"lightning_board_BTC_JPY","recv_timeout_sec":10,"ssl_verify":false,"socket_url":"wss://ws.lightstream.bitflyer.com/json-rpc"},"source_payload":{"mid_price":11375650.0,"bids":[],"asks":[{"price":11380156.0,"size":0.0}]}}}
{"schema_version":"collector.vnext.raw","schema_contract":null,"schema_contract_version":null,"payload_contract_version":null,"record_type":"market.orderbook.diff","record_id":"collector_main-market-orderbook-diff-000000000085","collector_id":"collector_main","collector_role":"production","host_name":"MAIN-PC","session_id":"collector_main-sess-20260315T000825Z-e08d1610","stream_session_id":"collector_main-stream-bitflyer-board_ws-20260315T000832Z-8ed81adf","exchange":"bitflyer","market":"spot","symbol":"BTC_JPY","instrument_id":"bitflyer.spot.BTC_JPY","channel":"board_ws","transport":"websocket","source_event_id":null,"source_sequence":null,"sequence_id":85,"exchange_ts":null,"collector_ts":"2026-03-15T00:08:33Z","ingest_ts":"2026-03-15T00:08:33Z","event_ts":"2026-03-15T00:08:33Z","quality_flags":[],"is_partial":false,"is_reconstructed":false,"confidence_score":1.0,"payload":{"provider":"bitflyer_ws_board","exchange":"bitflyer","transport":"websocket","channel":"lightning_board_BTC_JPY","received_ts":"2026-03-15T00:08:33.892268Z","subscription_id":null,"message_id":null,"source_sequence":null,"raw_message_meta":{"raw_channel":"lightning_board_BTC_JPY","subscription_channel":"lightning_board_BTC_JPY","recv_timeout_sec":10,"ssl_verify":false,"socket_url":"wss://ws.lightstream.bitflyer.com/json-rpc"},"source_payload":{"mid_price":11375650.0,"bids":[{"price":11371142.0,"size":0.0},{"price":11371418.0,"size":0.0},{"price":11372680.0,"size":0.0}],"asks":[]}}}
{"schema_version":"collector.vnext.raw","schema_contract":null,"schema_contract_version":null,"payload_contract_version":null,"record_type":"market.orderbook.diff","record_id":"collector_main-market-orderbook-diff-000000000087","collector_id":"collector_main","collector_role":"production","host_name":"MAIN-PC","session_id":"collector_main-sess-20260315T000825Z-e08d1610","stream_session_id":"collector_main-stream-bitflyer-board_ws-20260315T000832Z-8ed81adf","exchange":"bitflyer","market":"spot","symbol":"BTC_JPY","instrument_id":"bitflyer.spot.BTC_JPY","channel":"board_ws","transport":"websocket","source_event_id":null,"source_sequence":null,"sequence_id":87,"exchange_ts":null,"collector_ts":"2026-03-15T00:08:33Z","ingest_ts":"2026-03-15T00:08:33Z","event_ts":"2026-03-15T00:08:33Z","quality_flags":[],"is_partial":false,"is_reconstructed":false,"confidence_score":1.0,"payload":{"provider":"bitflyer_ws_board","exchange":"bitflyer","transport":"websocket","channel":"lightning_board_BTC_JPY","received_ts":"2026-03-15T00:08:33.984817Z","subscription_id":null,"message_id":null,"source_sequence":null,"raw_message_meta":{"raw_channel":"lightning_board_BTC_JPY","subscription_channel":"lightning_board_BTC_JPY","recv_timeout_sec":10,"ssl_verify":false,"socket_url":"wss://ws.lightstream.bitflyer.com/json-rpc"},"source_payload":{"mid_price":11375650.0,"bids":[{"price":11372765.0,"size":0.0357531}],"asks":[{"price":11380121.0,"size":0.0}]}}}
{"schema_version":"collector.vnext.raw","schema_contract":null,"schema_contract_version":null,"payload_contract_version":null,"record_type":"market.orderbook.diff","record_id":"collector_main-market-orderbook-diff-000000000089","collector_id":"collector_main","collector_role":"production","host_name":"MAIN-PC","session_id":"collector_main-sess-20260315T000825Z-e08d1610","stream_session_id":"collector_main-stream-bitflyer-board_ws-20260315T000832Z-8ed81adf","exchange":"bitflyer","market":"spot","symbol":"BTC_JPY","instrument_id":"bitflyer.spot.BTC_JPY","channel":"board_ws","transport":"websocket","source_event_id":null,"source_sequence":null,"sequence_id":89,"exchange_ts":null,"collector_ts":"2026-03-15T00:08:34Z","ingest_ts":"2026-03-15T00:08:34Z","event_ts":"2026-03-15T00:08:34Z","quality_flags":[],"is_partial":false,"is_reconstructed":false,"confidence_score":1.0,"payload":{"provider":"bitflyer_ws_board","exchange":"bitflyer","transport":"websocket","channel":"lightning_board_BTC_JPY","received_ts":"2026-03-15T00:08:34.094256Z","subscription_id":null,"message_id":null,"source_sequence":null,"raw_message_meta":{"raw_channel":"lightning_board_BTC_JPY","subscription_channel":"lightning_board_BTC_JPY","recv_timeout_sec":10,"ssl_verify":false,"socket_url":"wss://ws.lightstream.bitflyer.com/json-rpc"},"source_payload":{"mid_price":11375671.0,"bids":[{"price":11304836.0,"size":0.0},{"price":11372806.0,"size":0.1275}],"asks":[]}}}
{"schema_version":"collector.vnext.raw","schema_contract":null,"schema_contract_version":null,"payload_contract_version":null,"record_type":"market.orderbook.diff","record_id":"collector_main-market-orderbook-diff-000000000091","collector_id":"collector_main","collector_role":"production","host_name":"MAIN-PC","session_id":"collector_main-sess-20260315T000825Z-e08d1610","stream_session_id":"collector_main-stream-bitflyer-board_ws-20260315T000832Z-8ed81adf","exchange":"bitflyer","market":"spot","symbol":"BTC_JPY","instrument_id":"bitflyer.spot.BTC_JPY","channel":"board_ws","transport":"websocket","source_event_id":null,"source_sequence":null,"sequence_id":91,"exchange_ts":null,"collector_ts":"2026-03-15T00:08:34Z","ingest_ts":"2026-03-15T00:08:34Z","event_ts":"2026-03-15T00:08:34Z","quality_flags":[],"is_partial":false,"is_reconstructed":false,"confidence_score":1.0,"payload":{"provider":"bitflyer_ws_board","exchange":"bitflyer","transport":"websocket","channel":"lightning_board_BTC_JPY","received_ts":"2026-03-15T00:08:34.205130Z","subscription_id":null,"message_id":null,"source_sequence":null,"raw_message_meta":{"raw_channel":"lightning_board_BTC_JPY","subscription_channel":"lightning_board_BTC_JPY","recv_timeout_sec":10,"ssl_verify":false,"socket_url":"wss://ws.lightstream.bitflyer.com/json-rpc"},"source_payload":{"mid_price":11375671.0,"bids":[{"price":11367031.0,"size":0.0}],"asks":[]}}}
{"schema_version":"collector.vnext.raw","schema_contract":null,"schema_contract_version":null,"payload_contract_version":null,"record_type":"market.orderbook.diff","record_id":"collector_main-market-orderbook-diff-000000000093","collector_id":"collector_main","collector_role":"production","host_name":"MAIN-PC","session_id":"collector_main-sess-20260315T000825Z-e08d1610","stream_session_id":"collector_main-stream-bitflyer-board_ws-20260315T000832Z-8ed81adf","exchange":"bitflyer","market":"spot","symbol":"BTC_JPY","instrument_id":"bitflyer.spot.BTC_JPY","channel":"board_ws","transport":"websocket","source_event_id":null,"source_sequence":null,"sequence_id":93,"exchange_ts":null,"collector_ts":"2026-03-15T00:08:34Z","ingest_ts":"2026-03-15T00:08:34Z","event_ts":"2026-03-15T00:08:34Z","quality_flags":[],"is_partial":false,"is_reconstructed":false,"confidence_score":1.0,"payload":{"provider":"bitflyer_ws_board","exchange":"bitflyer","transport":"websocket","channel":"lightning_board_BTC_JPY","received_ts":"2026-03-15T00:08:34.344607Z","subscription_id":null,"message_id":null,"source_sequence":null,"raw_message_meta":{"raw_channel":"lightning_board_BTC_JPY","subscription_channel":"lightning_board_BTC_JPY","recv_timeout_sec":10,"ssl_verify":false,"socket_url":"wss://ws.lightstream.bitflyer.com/json-rpc"},"source_payload":{"mid_price":11375689.0,"bids":[{"price":11372765.0,"size":0.0},{"price":11372842.0,"size":0.010921}],"asks":[]}}}
{"schema_version":"collector.vnext.raw","schema_contract":null,"schema_contract_version":null,"payload_contract_version":null,"record_type":"market.orderbook.diff","record_id":"collector_main-market-orderbook-diff-000000000095","collector_id":"collector_main","collector_role":"production","host_name":"MAIN-PC","session_id":"collector_main-sess-20260315T000825Z-e08d1610","stream_session_id":"collector_main-stream-bitflyer-board_ws-20260315T000832Z-8ed81adf","exchange":"bitflyer","market":"spot","symbol":"BTC_JPY","instrument_id":"bitflyer.spot.BTC_JPY","channel":"board_ws","transport":"websocket","source_event_id":null,"source_sequence":null,"sequence_id":95,"exchange_ts":null,"collector_ts":"2026-03-15T00:08:34Z","ingest_ts":"2026-03-15T00:08:34Z","event_ts":"2026-03-15T00:08:34Z","quality_flags":[],"is_partial":false,"is_reconstructed":false,"confidence_score":1.0,"payload":{"provider":"bitflyer_ws_board","exchange":"bitflyer","transport":"websocket","channel":"lightning_board_BTC_JPY","received_ts":"2026-03-15T00:08:34.476432Z","subscription_id":null,"message_id":null,"source_sequence":null,"raw_message_meta":{"raw_channel":"lightning_board_BTC_JPY","subscription_channel":"lightning_board_BTC_JPY","recv_timeout_sec":10,"ssl_verify":false,"socket_url":"wss://ws.lightstream.bitflyer.com/json-rpc"},"source_payload":{"mid_price":11375689.0,"bids":[{"price":11372807.0,"size":0.0358226},{"price":11365893.0,"size":0.06},{"price":11326031.0,"size":0.002}],"asks":[{"price":11381762.0,"size":0.0154534}]}}}
{"schema_version":"collector.vnext.raw","schema_contract":null,"schema_contract_version":null,"payload_contract_version":null,"record_type":"market.orderbook.diff","record_id":"collector_main-market-orderbook-diff-000000000097","collector_id":"collector_main","collector_role":"production","host_name":"MAIN-PC","session_id":"collector_main-sess-20260315T000825Z-e08d1610","stream_session_id":"collector_main-stream-bitflyer-board_ws-20260315T000832Z-8ed81adf","exchange":"bitflyer","market":"spot","symbol":"BTC_JPY","instrument_id":"bitflyer.spot.BTC_JPY","channel":"board_ws","transport":"websocket","source_event_id":null,"source_sequence":null,"sequence_id":97,"exchange_ts":null,"collector_ts":"2026-03-15T00:08:34Z","ingest_ts":"2026-03-15T00:08:34Z","event_ts":"2026-03-15T00:08:34Z","quality_flags":[],"is_partial":false,"is_reconstructed":false,"confidence_score":1.0,"payload":{"provider":"bitflyer_ws_board","exchange":"bitflyer","transport":"websocket","channel":"lightning_board_BTC_JPY","received_ts":"2026-03-15T00:08:34.579491Z","subscription_id":null,"message_id":null,"source_sequence":null,"raw_message_meta":{"raw_channel":"lightning_board_BTC_JPY","subscription_channel":"lightning_board_BTC_JPY","recv_timeout_sec":10,"ssl_verify":false,"socket_url":"wss://ws.lightstream.bitflyer.com/json-rpc"},"source_payload":{"mid_price":11375689.0,"bids":[{"price":11372807.0,"size":0.0},{"price":11372843.0,"size":0.03564887}],"asks":[{"price":11390740.0,"size":0.0},{"price":11390739.0,"size":0.022}]}}}
{"schema_version":"collector.vnext.raw","schema_contract":null,"schema_contract_version":null,"payload_contract_version":null,"record_type":"market.orderbook.diff","record_id":"collector_main-market-orderbook-diff-000000000099","collector_id":"collector_main","collector_role":"production","host_name":"MAIN-PC","session_id":"collector_main-sess-20260315T000825Z-e08d1610","stream_session_id":"collector_main-stream-bitflyer-board_ws-20260315T000832Z-8ed81adf","exchange":"bitflyer","market":"spot","symbol":"BTC_JPY","instrument_id":"bitflyer.spot.BTC_JPY","channel":"board_ws","transport":"websocket","source_event_id":null,"source_sequence":null,"sequence_id":99,"exchange_ts":null,"collector_ts":"2026-03-15T00:08:34Z","ingest_ts":"2026-03-15T00:08:34Z","event_ts":"2026-03-15T00:08:34Z","quality_flags":[],"is_partial":false,"is_reconstructed":false,"confidence_score":1.0,"payload":{"provider":"bitflyer_ws_board","exchange":"bitflyer","transport":"websocket","channel":"lightning_board_BTC_JPY","received_ts":"2026-03-15T00:08:34.800417Z","subscription_id":null,"message_id":null,"source_sequence":null,"raw_message_meta":{"raw_channel":"lightning_board_BTC_JPY","subscription_channel":"lightning_board_BTC_JPY","recv_timeout_sec":10,"ssl_verify":false,"socket_url":"wss://ws.lightstream.bitflyer.com/json-rpc"},"source_payload":{"mid_price":11375689.0,"bids":[{"price":11360204.0,"size":0.32}],"asks":[]}}}
{"schema_version":"collector.vnext.raw","schema_contract":null,"schema_contract_version":null,"payload_contract_version":null,"record_type":"market.orderbook.diff","record_id":"collector_main-market-orderbook-diff-000000000101","collector_id":"collector_main","collector_role":"production","host_name":"MAIN-PC","session_id":"collector_main-sess-20260315T000825Z-e08d1610","stream_session_id":"collector_main-stream-bitflyer-board_ws-20260315T000832Z-8ed81adf","exchange":"bitflyer","market":"spot","symbol":"BTC_JPY","instrument_id":"bitflyer.spot.BTC_JPY","channel":"board_ws","transport":"websocket","source_event_id":null,"source_sequence":null,"sequence_id":101,"exchange_ts":null,"collector_ts":"2026-03-15T00:08:34Z","ingest_ts":"2026-03-15T00:08:34Z","event_ts":"2026-03-15T00:08:34Z","quality_flags":[],"is_partial":false,"is_reconstructed":false,"confidence_score":1.0,"payload":{"provider":"bitflyer_ws_board","exchange":"bitflyer","transport":"websocket","channel":"lightning_board_BTC_JPY","received_ts":"2026-03-15T00:08:34.906545Z","subscription_id":null,"message_id":null,"source_sequence":null,"raw_message_meta":{"raw_channel":"lightning_board_BTC_JPY","subscription_channel":"lightning_board_BTC_JPY","recv_timeout_sec":10,"ssl_verify":false,"socket_url":"wss://ws.lightstream.bitflyer.com/json-rpc"},"source_payload":{"mid_price":11375689.0,"bids":[{"price":11367031.0,"size":0.07}],"asks":[]}}}
{"schema_version":"collector.vnext.raw","schema_contract":null,"schema_contract_version":null,"payload_contract_version":null,"record_type":"market.orderbook.diff","record_id":"collector_main-market-orderbook-diff-000000000103","collector_id":"collector_main","collector_role":"production","host_name":"MAIN-PC","session_id":"collector_main-sess-20260315T000825Z-e08d1610","stream_session_id":"collector_main-stream-bitflyer-board_ws-20260315T000832Z-8ed81adf","exchange":"bitflyer","market":"spot","symbol":"BTC_JPY","instrument_id":"bitflyer.spot.BTC_JPY","channel":"board_ws","transport":"websocket","source_event_id":null,"source_sequence":null,"sequence_id":103,"exchange_ts":null,"collector_ts":"2026-03-15T00:08:35Z","ingest_ts":"2026-03-15T00:08:35Z","event_ts":"2026-03-15T00:08:35Z","quality_flags":[],"is_partial":false,"is_reconstructed":false,"confidence_score":1.0,"payload":{"provider":"bitflyer_ws_board","exchange":"bitflyer","transport":"websocket","channel":"lightning_board_BTC_JPY","received_ts":"2026-03-15T00:08:35.224465Z","subscription_id":null,"message_id":null,"source_sequence":null,"raw_message_meta":{"raw_channel":"lightning_board_BTC_JPY","subscription_channel":"lightning_board_BTC_JPY","recv_timeout_sec":10,"ssl_verify":false,"socket_url":"wss://ws.lightstream.bitflyer.com/json-rpc"},"source_payload":{"mid_price":11375689.0,"bids":[],"asks":[{"price":11548144.0,"size":0.002}]}}}
{"schema_version":"collector.vnext.raw","schema_contract":null,"schema_contract_version":null,"payload_contract_version":null,"record_type":"market.orderbook.diff","record_id":"collector_main-market-orderbook-diff-000000000105","collector_id":"collector_main","collector_role":"production","host_name":"MAIN-PC","session_id":"collector_main-sess-20260315T000825Z-e08d1610","stream_session_id":"collector_main-stream-bitflyer-board_ws-20260315T000832Z-8ed81adf","exchange":"bitflyer","market":"spot","symbol":"BTC_JPY","instrument_id":"bitflyer.spot.BTC_JPY","channel":"board_ws","transport":"websocket","source_event_id":null,"source_sequence":null,"sequence_id":105,"exchange_ts":null,"collector_ts":"2026-03-15T00:08:35Z","ingest_ts":"2026-03-15T00:08:35Z","event_ts":"2026-03-15T00:08:35Z","quality_flags":[],"is_partial":false,"is_reconstructed":false,"confidence_score":1.0,"payload":{"provider":"bitflyer_ws_board","exchange":"bitflyer","transport":"websocket","channel":"lightning_board_BTC_JPY","received_ts":"2026-03-15T00:08:35.345356Z","subscription_id":null,"message_id":null,"source_sequence":null,"raw_message_meta":{"raw_channel":"lightning_board_BTC_JPY","subscription_channel":"lightning_board_BTC_JPY","recv_timeout_sec":10,"ssl_verify":false,"socket_url":"wss://ws.lightstream.bitflyer.com/json-rpc"},"source_payload":{"mid_price":11375689.0,"bids":[{"price":11365893.0,"size":0.0}],"asks":[]}}}
{"schema_version":"collector.vnext.raw","schema_contract":null,"schema_contract_version":null,"payload_contract_version":null,"record_type":"market.orderbook.diff","record_id":"collector_main-market-orderbook-diff-000000000107","collector_id":"collector_main","collector_role":"production","host_name":"MAIN-PC","session_id":"collector_main-sess-20260315T000825Z-e08d1610","stream_session_id":"collector_main-stream-bitflyer-board_ws-20260315T000832Z-8ed81adf","exchange":"bitflyer","market":"spot","symbol":"BTC_JPY","instrument_id":"bitflyer.spot.BTC_JPY","channel":"board_ws","transport":"websocket","source_event_id":null,"source_sequence":null,"sequence_id":107,"exchange_ts":null,"collector_ts":"2026-03-15T00:08:35Z","ingest_ts":"2026-03-15T00:08:35Z","event_ts":"2026-03-15T00:08:35Z","quality_flags":[],"is_partial":false,"is_reconstructed":false,"confidence_score":1.0,"payload":{"provider":"bitflyer_ws_board","exchange":"bitflyer","transport":"websocket","channel":"lightning_board_BTC_JPY","received_ts":"2026-03-15T00:08:35.625791Z","subscription_id":null,"message_id":null,"source_sequence":null,"raw_message_meta":{"raw_channel":"lightning_board_BTC_JPY","subscription_channel":"lightning_board_BTC_JPY","recv_timeout_sec":10,"ssl_verify":false,"socket_url":"wss://ws.lightstream.bitflyer.com/json-rpc"},"source_payload":{"mid_price":11375689.0,"bids":[{"price":11321479.0,"size":0.002}],"asks":[]}}}
